Workbook
Name A: #REF!
Name aaa: #REF!
Name all: #REF!
Name aluminijska: #REF!
Name BE_Price: #REF!
Name betonska: #REF!
Name BETONSKI_I_ARM.BETONSKI_RADOVI: #REF!
Name BRAVARIJA_SKLONIŠTA: #REF!
Name Countr.: #REF!
Name Countr.no: #REF!
Name Country: #REF!
Name CRNA_BRAVARIJA: #REF!
Name ČELIČNA_KONSTRUKCIJA: #REF!
Name D: #REF!
Name Data_base_result: #REF!
Name DIMNJACI: #REF!
Name DIZALA: #REF!
Name EODB: #REF!
Name euro: #REF!
Name euronew: #REF!
Name FASADERSKI_RADOVI: #REF!
Name fizika_zgrade: #REF!
Name gradbena: #REF!
Name H: #REF!
Name HR: #REF!
Name I: #REF!
Name Inew: #REF!
Name INOX_BRAVARIJA: #REF!
Name IZOLATERSKI_RADOVI: #REF!
Name jj: [1]VIIIc.0.E!#REF!
Name KAMENARSKI_RADOVI: #REF!
Name keramicarska: #REF!
Name KERAMIČARSKI_RADOVI: #REF!
Name kljucavnicarska: #REF!
Name KROVOPOKRIVAČKI_RADOVI: #REF!
Name krovskokleparska: #REF!
Name Kurs: #REF!
Name l: #REF!
Name Langua.: #REF!
Name Langua.no: #REF!
Name Language: #REF!
Name Last_up_date: #REF!
Name LIMARSKI_RADOVI: #REF!
Name m: #REF!
Name mavcnokartonska: #REF!
Name min: #REF!
Name minE: #REF!
Name mr: #REF!
Name NEHRĐAJUĆA_BRAVARIJA: #REF!
Name Null: #REF!
Name obrtniska: #REF!
Name OSTALI_RADOVI: #REF!
Name p: #REF!
Name Partno: #REF!
Name PILOTI: #REF!
Name pn: [1]VIIIc.0.E!#REF!
Name PODOVI: #REF!
Name PREGRADNE_STIJENE: #REF!
Name Price_code: #REF!
Name PROTUPOŽARNA_BRAVARIJA: #REF!

Sheet NASLOVNICA
B2: TROŠKOVNIK GRAĐEVINSKO-OBRTNIČKIH RADOVA
B6: Investitor:
B7: MACAN d.o.o.
B8: Ljubljanska 52, 10000 Zagreb
B9: OIB: 66000671692
B10: Zastupano po direktoru: Božidar Macan
B12: Projekt:
B13: Rekonstrukcija postojeće poluugrađene poslovne građevine u stambeno-poslovnu polugrađenu građevinu
B15: Lokacija:
B16: k.č.br. 4139/1
B17: k.o. Dubrava, Ljubijska 52, 10000 Zagreb

Sheet REKAPITULACIJA
B2: REKAPITULACIJA
A4: A. | B4: GRAĐEVINSKI RADOVI
A5: ='A.GRAĐEVINSKI RADOVI'!A417 -> A.01. | B5: ='A.GRAĐEVINSKI RADOVI'!B417 -> PRIPREMNI I GEODETSKI RADOVI UKUPNO: | C5: ='A.GRAĐEVINSKI RADOVI'!F417 -> 0
A6: ='A.GRAĐEVINSKI RADOVI'!A418 -> A.02. | B6: ='A.GRAĐEVINSKI RADOVI'!B418 -> ZEMLJANI RADOVI UKUPNO: | C6: ='A.GRAĐEVINSKI RADOVI'!F418 -> 0
A7: ='A.GRAĐEVINSKI RADOVI'!A419 -> A.03. | B7: ='A.GRAĐEVINSKI RADOVI'!B419 -> BETONSKI I ARMIRANOBETONSKI RADOVI UKUPNO: | C7: ='A.GRAĐEVINSKI RADOVI'!F419 -> 0
A8: ='A.GRAĐEVINSKI RADOVI'!A420 -> A.04. | B8: ='A.GRAĐEVINSKI RADOVI'!B420 -> ARMIRAČKI RADOVI UKUPNO: | C8: ='A.GRAĐEVINSKI RADOVI'!F420 -> 0
A9: ='A.GRAĐEVINSKI RADOVI'!A421 -> A.05. | B9: ='A.GRAĐEVINSKI RADOVI'!B421 -> IZOLATERSKI RADOVI UKUPNO: | C9: ='A.GRAĐEVINSKI RADOVI'!F421 -> 0
A10: ='A.GRAĐEVINSKI RADOVI'!A422 -> A.06. | B10: ='A.GRAĐEVINSKI RADOVI'!B422 -> ZIDARSKO - FASADERSKI RADOVI UKUPNO: | C10: ='A.GRAĐEVINSKI RADOVI'!C422 -> 0
A11: ='A.GRAĐEVINSKI RADOVI'!A423 -> A.07. | B11: ='A.GRAĐEVINSKI RADOVI'!B423 -> LIMARSKI RADOVI UKUPNO: | C11: ='A.GRAĐEVINSKI RADOVI'!F423 -> 0
A12: A. | B12: GRAĐEVINSKI RADOVI UKUPNO: | C12: =SUM(C5:C9) -> 0
A14: B. | B14: OBRTNIČKI RADOVI
A15: ='B.OBRTNIČKI RADOVI'!A457 -> B.01. | B15: ='B.OBRTNIČKI RADOVI'!B457 -> ZAVRŠNO MONTAŽERSKI RADOVI UKUPNO: | C15: ='B.OBRTNIČKI RADOVI'!C457 -> 0
A16: ='B.OBRTNIČKI RADOVI'!A458 -> B.02. | B16: ='B.OBRTNIČKI RADOVI'!B458 -> KERAMIČARSKI RADOVI UKUPNO: | C16: ='B.OBRTNIČKI RADOVI'!C458 -> 0
A17: ='B.OBRTNIČKI RADOVI'!A459 -> B.03. | B17: ='B.OBRTNIČKI RADOVI'!B459 -> PODOPOLAGAČKI RADOVI UKUPNO: | C17: ='B.OBRTNIČKI RADOVI'!C459 -> 0
A18: ='B.OBRTNIČKI RADOVI'!A460 -> B.04. | B18: ='B.OBRTNIČKI RADOVI'!B460 -> SOBOSLIKARSKO LIČILAČKI RADOVI UKUPNO: | C18: ='B.OBRTNIČKI RADOVI'!C460 -> 0
A19: ='B.OBRTNIČKI RADOVI'!A461 -> B.05. | B19: ='B.OBRTNIČKI RADOVI'!B461 -> STOLARSKI RADOVI UKUPNO: | C19: ='B.OBRTNIČKI RADOVI'!C461 -> 0
A20: ='B.OBRTNIČKI RADOVI'!A462 -> B.06. | B20: ='B.OBRTNIČKI RADOVI'!B462 -> BRAVARSKI RADOVI UKUPNO: | C20: ='B.OBRTNIČKI RADOVI'!C462 -> 0
A21: B. | B21: GRAĐEVINSKI RADOVI UKUPNO: | C21: =SUM(C15:C16) -> 0
B23: REKAPITULACIJA SVEUKUPNO: | C23: =C21+C12 -> 0

Sheet A.GRAĐEVINSKI RADOVI
A1: r.br. | B1: opis stavke | C1: jed. mj. | D1: količina | E1: jed. cijena | F1: ukupno | G1: napomena
A4: A. | B4: GRAĐEVINSKI RADOVI
B6: Sve stavke građevinskih radova uključuju sav rad i materijal, radnu skelu, potreban spojni i pričvrsni materijal sukladno odabranom sistemu izvedbe i uputi proizvođača, sve izvedeno do potpune gotovosti i funkcionalnosti.
A8: A.01. | B8: PRIPREMNI I GEODETSKI RADOVI
A10: 1 | B10: Uklanjanje postojeće građevine
B11: Uklanjanje postojeće građevine ukupne tlocrtne površine cca P=99,00 m2. Potrebno je ukloniti sve elemente konstrukcije sa oblogama, pokrovom, prozorima, vratima itd. te postojeće opločenje u okolišu. Uklanjanje elemenata koji se nalaze neposredno uz susjednu građevinu izvesti pažljivo i po potrebi ručno ukloniti.
B12: Rušenju građevine ne smije se pristupiti dok nisu izvršene sve potrebne pripreme, sva potrebna rasterećenja, te eventualno potrebna osiguranja na pojedinim mjestima.
B13: U cijenu je uračunato i čišćenje zone izgradnje prije izvođenja radova (sakupljanje svog otpadnog materijala i sječenje grmlja, šiblja sa uklanjanjem korijena, te utovar u kamion i odvoz na gradsku deponiju, uključivo i naknada za deponiranje).
B14: Obračun po kompletu. | C14: kpl | D14: 1 | F14: =D14*E14 -> 0
A16: =IF(B16>0,MAX(A$10:A15)+1,"") -> 2 | B16: Iskolčenje i izrada izjave o iskolčenju
B17: Izrada iskolčenja i izjave o provedenom iskolčenju parcele, građevine, prometnih i hodnih površina, instalacija i elemenata krajobraznog uređenja sukladno geodetskom projektu izrađenom od strane ovlaštenog geodeta. Iskolčenje objekta obuhvaća sva geodetska mjerenja kojima se podaci s projekta prenose na teren (vertikalno i horizontalno), obnavljanje i održavanje iskolčenih oznaka na terenu za sve vrijeme građenja.
B18: Izjavu o provedenom iskolčenju građevine sukladno geodetskom projektu potrebno je izraditi u skladu s Zakonom o gradnji i Pravilnikom o geodetskom projektu.
B19: Obračun za komplet. | C19: kpl | D19: 1 | F19: =D19*E19 -> 0
A21: =IF(B21>0,MAX(A$10:A20)+1,"") -> 3 | B21: Završno čišćenje
B22: Generalno fino završno čišćenje zgrada nakon tehničkog pregleda, a prije konačne primopredaje i otklanjanja svih nedostataka građevine uključivo i komplet sva potrebna čišćenja interijera zgrade.
B23: Obračun po m2 bruto površine prostora. | C23: m2 | D23: 345 | F23: =D23*E23 -> 0
A25: A.01. | B25: PRIPREMNI I GEODETSKI RADOVI UKUPNO: | F25: =SUM(F10:F23) -> 0
A27: A.02. | B27: ZEMLJANI RADOVI
B29: Svi iskopi i nasipi moraju se izvesti prema profilima, kotama i nagibima iz projekta uz korištenje odgovarajuće mehanizacije.
B30: Dubina iskopa prema dimenzijama i pozicijama danim u izvedbenom projektu, sve prema podložnim slojevima predviđenim za ugradnju. Svo temeljno tlo potrebno je urediti i pripremiti za daljnju izvedbu.
B31: Planiranje se izvodi na kote iz izvedbenog projekta. Posteljica mora biti preuzeta u pogledu visina, padova i zbijenosti po nadzornom inženjeru.
B32: Po provedenom iskopu obaveza je izvođača da obavijesti ovlaštenog geomehaničara da pregleda temeljno tlo prije nastavka radova i da izda potvrdu o stanju tla, sukladno uvjetima iz projekta što se upisuje u građevni dnevnik od strane geomehaničara.
A34: =IF(B34>0,MAX(A$33:A33)+1,"") -> 1 | B34: Široki iskop za temeljenje građevine
B35: Široki iskop zemlje B kategorije u svrhu formiranja građevinske jame za izvedbu temeljne ploče. Materijal iz iskopa odložiti na gradilištu i iskoristiti za nasipavanje (obračun u zasebnoj stavci). U jediničnu stavku cijene je uključeno planiranje dna jame ispod temeljne ploče sa zbijanjem površine na točnost +/- 2 cm.
B36: Oznaka sloja: P1, P2
B37: Obračun po m3 u sraslom stanju. | C37: m3 | D37: 82.5 | F37: =D37*E37 -> 0
A39: =IF(B39>0,MAX(A$33:A38)+1,"") -> 2 | B39: Iskop za uređenje okoliša
B40: Iskop zemlje B kategorije za uređenje okoliša. Materijal iz iskopa odložiti na gradilištu i iskoristiti za nasipavanje (obračun u zasebnoj stavci). U jediničnu stavku cijene je uključeno planiranje dna sa zbijanjem površine na točnost +/- 2 cm.
B41: Pozicija: hodna i kolna površina
B42: Obračun po m3 u sraslom stanju. | C42: m3 | D42: 91.39 | F42: =D42*E42 -> 0
A44: =IF(B44>0,MAX(A$33:A43)+1,"") -> 3 | B44: Nasip od nabijenoga krupnog šljunka
B45: Dobava, doprema materijala i zasipavanje nasipa od krupnog šljunka d=30 cm, granulacije prema projektu. Potrebna zbijenost zamjenskog sloja je 30 MPa što se dokazuje potrebnim ispitivanjima tla. Nakon iskopa na kotu podložnog betona ispitati će se temeljno tlo, te nakon toga pristupiti eventualnoj zamjeni materijala. Stavka obuhvaća dobavu, dopremu kamenog materijala, razastiranje i valjanje u kompaktni sloj i sve ostalo potrebno za potpuno dovršenje rada. Ovaj sloj se može izvoditi tek nakon što je nadzorni inženjer primio posteljicu.
B46: Oznaka sloja: P1, P2
B47: Obračun po m3 izvedenoga nasipa u sraslome stanju. | C47: m3 | D47: 73.37 | F47: =D47*E47 -> 0
A49: =IF(B49>0,MAX(A$33:A48)+1,"") -> 4 | B49: Geotekstil 300g/m2
B50: Dobava, doprema i ugradnja geotekstila 300g/m2 pod sloj nabijenoga kamenog materijala bez veziva. U jediničnu cijenu stavke uključeni svi preklopi, te sav potreban rad te spojni i pričvrsni materijal.
B51: Pozicija: hodna i kolna površina
B52: Obračun po m2 ugrađenoga geotekstila. | C52: m2 | D52: 194.44 | F52: =D52*E52 -> 0
A54: =IF(B54>0,MAX(A$33:A53)+1,"") -> 5 | B54: Nosivi sloj od mehanički zbijenog zrnatog kamenog materijala bez veziva
B55: Stavkom je obuhvaćena dobava, dovoz i ugradnja zrnatog kamenog materijala vibracijskim sredstvom za nabijanje d=25 cm, granulacije 0-63 mm u nosivi sloj kolničke konstrukcije prema projektu.
...

Sheet B.OBRTNIČKI RADOVI
A1: r.br. | B1: opis stavke | C1: jed. mj. | D1: količina | E1: jed. cijena | F1: ukupno | G1: napomena
A4: B. | B4: OBRTNIČKI RADOVI
B6: Sve stavke obrtničkih radova uključuju sav rad i materijal, radnu skelu, potreban spojni i pričvrsni materijal sukladno odabranom sistemu izvedbe i uputi proizvođača, sve izvedeno do potpune gotovosti i funkcionalnosti.
A8: B.01. | B8: ZAVRŠNO MONTAŽERSKI RADOVI
B10: Sve stavke uključuju premaz za izjednačavanje upojnosti podloge, prema sustavu proizvođača.
B11: U cijenu uključena obrada spojeva završnog drugog sloja ploča u kvaliteti Q2 (Uniflott) + obavezno zapunjavanje spojeva prvog sloja ploča. Ostvaruje se osnovnom obradom spojeva ploča i naknadnim dodatnim zaglađivanjem područja spoja kako bi se izradio ravan prijelaz prema površini ploče. Drugi sloj ploča mora biti izveden iz ploča velikog formata (bez nastavljanja po visini) bez horizontalnih spojeva. Obavezno zapunjavanje spojeva svih slojeva ploča sa ugradnjom bandažne trake. Uključuje izradu sa završnim al.profilima, gletanje, bandažiranje, silikoniranje kutova i spojeva do potpune gotovosti kao priprema za bojanje.
B12: Sve izvesti u skladu sa uputama proizvođača.
B13: Zabilježiti s vanjske strane osi potkonstrukcije stropova pozicije rasvjete, stropne ventilacije, strojarske i elektroopreme, sprinklera, ogledala/gotove opreme, zbog bušenja otvora u stropu. Bušenja svih otvora te obrade nakon ugradnje navedene opreme je potrebno ukalkulirati u jediničnu cijenu jer se neće posebno obračunavati.
B14: Potkonstrukciju izvoditi s metalnim vilicama podloženima s plastičnim trakama za prekid toplinskog mosta
B15: Za spuštene stropove na međukatnu konstrukciju postavlja se potkonstrukcija na ovjesu (razred nosivosti prema DIN 18168 dio 2) rastera 75/100 cm. Potkonstrukcija se sastoji od tipskih CD/UD profila iz pocinčanog lima debljine 0,6 mm nosivi CD profili i montažni CD profili postavljeni su na rasteru 100/50 cm. Postavu potkonstrukcije i ploča izvesti u svemu prema uputama proizvođača. U cijenu uključeno bandažiranje i gletanje spojeva te gletanje stropa kao priprema za bojanje.
B16: Sav ovjesni i pomoćni pribor je dio svake stavke. U cijenu svih stavki je uključena i izrada dilatacija u pregradnim zidovima i stropovima. Dilatacije se izvode na maksimalnom razmaku 15 m, te kod konstruktivnih dilatacija objekta, u svemu prema uputama proizvođača. Također dilataciju u stropu je potrebno izvesti kod prelasku iz užeg u širi prostor sukladno uputama proizvođača. Izradu otvora te ojačanja oko otvora instalacija kroz suhomontažne sustave te nakon završetka obradu izvodi izvođač suhomontažnih radova, što je uključeno u cijenu. Obavezna koordinacija između podizvođača instalacija i suhomontažnih radova.
B17: Obrada spojeva vrši se specijalnom glet masom, prema preporuci proizvođača sustava, i u ovisnosti o mjestu ugradnje (suhe / važne prostorije). Izrada prema smjernicama i uputama proizvođača. Spojeve između ploča ispunjavaju se također pripadajućim ispunjačem (kod impregniranih gips kartonskih ploča koristiti impregnirani Uniflott ili impregnirani Fugenfuller) i ojačavaju perforiranom papirnatom trakom za spojnice, a izložene ivice ojačavaju se aluminijskim perforiranim Al profilima. Kvaliteta završne obrade spojeva i površine prvog sloja prema kvaliteti Q1, a kvaliteta završne obrade drugog sloja prema kvaliteti obrade površine Q2.
B18: Izvođači GK radova dužni su pregledati podloge instalacija te se koordinirati i uskladiti sa izvođačima instalacija vezano za pozicije te raspored instalacija u zidovima, oblogama i stropovima te potkonstrukciju izvesti. Naknadno rezanje profila potkonstrukcije nije dozvoljeno. Sva rezanja za prodore za instalaterske radove te obrada oko prodora nakon izvedbe instalacija, prema projektnim zahtjevima i uvjetima proizvođača uključena su u jediničnu cijenu stavki rada.
B19: U cijenu uključena sva bušenja, tiplanja, rezanja, pripasivanja i otpad materijala, kao i izrezivanje otvora sa ugradbom potrebnih ojačanja, izradu sa završnim al.profilima, gletanje, bandažiranje, silikoniranje kutova i spojeva do potpune gotovosti.
B21: PREGRADNI ZIDOVI I ZIDNE OBLOGE
A23: 1 | B23: Pregradni zid sa izolacijom, d=10 cm, GK-GK
B24: Dobava, doprema materijala i izrada lake pregradne stijene od dvostrukih gipskartonskih ploča na metalnoj potkonstrukciji. Sastav zida je:
B25: a) dvostruka gipskartonska ploča (900 kg/m3) na potkonstrukciji d=2x1,25 cm
B26: b) potkonstrukcija od limenih CW/UW 50 profila, u međuprostoru meka mineralna vuna za ispune potkonstrukcija lakih pregrada, d=5 cm
B27: c) dvostruka gipskartonska ploča (900 kg/m3) na potkonstrukciji d=2x1,25 cm
B28: Obračun po m2. | C28: m2 | D28: 9.48 | F28: =D28*E28 -> 0
A30: =IF(B30>0,MAX(A$22:A29)+1,"") -> 2 | B30: Pregradni zid sa izolacijom, d=10 cm, GK-GKI
B31: Dobava, doprema materijala i izrada lake pregradne stijene od dvostrukih gipskartonskih ploča na metalnoj potkonstrukciji. Sastav zida je:
B32: a) dvostruka gipskartonska ploča (900 kg/m3) na potkonstrukciji d=2x1,25 cm
B33: b) potkonstrukcija od limenih CW/UW 50 profila, u međuprostoru meka mineralna vuna za ispune potkonstrukcija lakih pregrada, d=5 cm
B34: c) dvostruka vodootporna gipskartonska ploča (900 kg/m3) na potkonstrukciji d=2x1,25 cm
B35: Obračun po m2. | C35: m2 | D35: 9.57 | F35: =D35*E35 -> 0
A37: =IF(B37>0,MAX(A$22:A36)+1,"") -> 3 | B37: Pregradni zid sa izolacijom, d=10 cm, GKI-GKI
B38: Dobava, doprema materijala i izrada lake pregradne stijene od dvostrukih gipskartonskih ploča na metalnoj potkonstrukciji. Sastav zida je:
B39: a) dvostruka vodootporna gipskartonska ploča (900 kg/m3) na potkonstrukciji d=2x1,25 cm
B40: b) potkonstrukcija od limenih CW/UW 50 profila, u međuprostoru meka mineralna vuna za ispune potkonstrukcija lakih pregrada, d=5 cm.
B41: c) dvostruka vodootporna gipskartonska ploča (900 kg/m3) na potkonstrukciji d=2x1,25 cm
B42: Obračun po m2. | C42: m2 | D42: 5.09 | F42: =D42*E42 -> 0
A44: =IF(B44>0,MAX(A$22:A43)+1,"") -> 4 | B44: Pregradni zid sa izolacijom, d=15 cm, GK-GKI
B45: Dobava, doprema materijala i izrada lake pregradne stijene od dvostrukih gipskartonskih ploča na metalnoj potkonstrukciji. Sastav zida je:
B46: a) dvostruka gipskartonska ploča (900 kg/m3) na potkonstrukciji d=2x1,25 cm
B47: b) potkonstrukcija od limenih CW/UW 100 profila, u međuprostoru meka mineralna vuna za ispune potkonstrukcija lakih pregrada, d=10 cm
B48: c) dvostruka vodootporna gipskartonska ploča (900 kg/m3) na potkonstrukciji d=2x1,25 cm
B49: Obračun po m2. | C49: m2 | D49: 8.56 | F49: =D49*E49 -> 0
A51: =IF(B51>0,MAX(A$22:A50)+1,"") -> 5 | B51: Pregradni zid sa izolacijom, d=15 cm, DF-DF
...

Sheet C.POTPORNI ZID I PARAPET
A3: r.br. | B3: opis stavke | C3: jed. mj. | D3: količina | E3: jed. cijena | F3: ukupno | G3: napomena
B5: AB POTPORNI ZID – POSTOJEĆA ZGRADA
A7: 1. | B7: Iskolčenje potpornog zida | C7: kpl | D7: 1 | F7: =D7*E7 -> 0
A8: 2. | B8: Rušenje postojećeg zida do visine za izradu vanjskog uređenja. | C8: m3 | D8: =(5.16+1.73+1.77+6-1.53+1.05)*0.3*0.5 -> 2.13 | F8: =D8*E8 -> 0
A9: 3. | B9: Rušenje postojećeg betonskog poda za izradu novog zida. | C9: m2 | D9: =(5.16+1.73+1.77+6-1.53+1.05)*4 -> 56.72 | F9: =D9*E9 -> 0
A10: 4. | B10: Iskop za temelje, sa utovarom i odvozom na deponiju. | C10: m3 | D10: =(5.16+1.73+1.77+6-1.53+1.05)*4*0.4 -> 22.69 | F10: =D10*E10 -> 0
A11: 5. | B11: Dobava i ugradnja betona C25/30 u temelje. | C11: m3 | D11: =(4.16+3.14*0.9/2+4+3.14*1.1*0.5+0.8+3.14*0.9*0.5+1.76)*1.3*0.5 -> 9.93 | F11: =D11*E11 -> 0
A12: 6. | B12: Oplata temelja zida, oplata temelja se izvodi u ravnim segmentima. | C12: m2 | D12: =(4.16+3.14*0.9/2+4+3.14*1.1*0.5+0.8+3.14*0.9*0.5+1.76)*0.5*2 -> 15.27 | F12: =D12*E12 -> 0
A13: 7. | B13: Dobava i ugradnja betona C25/30 u potporni zid | C13: m3 | D13: 4.9 | F13: =D13*E13 -> 0
A14: 8. | B14: Oplata zida izvedena u lukovima prema projektu | C14: m2 | D14: =(4.16+3.14*0.9/2+4+3.14*1.1*0.5+0.8+3.14*0.9*0.5+1.76)*1.5*2 -> 45.82 | F14: =D14*E14 -> 0
A15: 9. | B15: Doba i ugradnja armature prema projektu | C15: kg | D15: =375.66+314.73 -> 690.39 | F15: =D15*E15 -> 0
A16: 10. | B16: Zatrpavanje sa kamenim materijalom. | C16: m3 | D16: =(4.16+3.14*0.9/2+4+3.14*1.1*0.5+0.8+3.14*0.9*0.5+1.76)*1.5*2 -> 45.82 | F16: =D16*E16 -> 0
B18: RUŠENJE I PONOVA IZGRADNJA PARAPETNOG ZIDA SA UKLANJANJEM I MONTAŽU POSTOJEĆE OGRADE
A20: 1. | B20: Uklanjanje postojeće ograde | C20: kom. | D20: 1 | F20: =D20*E20 -> 0
A21: 2. | B21: Rušenje postojećega zida, odvoz materijala na trajnu deponiju | C21: kom. | D21: 1 | F21: =D21*E21 -> 0
A22: 3. | B22: Iskoličenje parcelne granice i novog zida | C22: kom. | D22: 1 | F22: =D22*E22 -> 0
A23: 4. | B23: iskop za temeljenje zidu | C23: m3 | D23: 16.8 | F23: =D23*E23 -> 0
A24: 5. | B24: Nosivni sloj od mehanički zbijenog zrnatog kamenog materijala 0/32, d=20cm | C24: m3 | D24: 4.8 | F24: =D24*E24 -> 0
A25: 6. | B25: Geotekstil 300g/m2, dobava i ugradnja | C25: m2 | D25: 24 | F25: =D25*E25 -> 0
A26: 7. | B26: AB temelj zida 0,50 x 0,30 x 24,00 (Š x V x L)
A27: 8. | B27: beton | C27: m3 | D27: 3.6 | F27: =D27*E27 -> 0
A28: 9. | B28: oplata | C28: m2 | D28: 14.7 | F28: =D28*E28 -> 0
A29: 10. | B29: AB zid, 0,20 x 0,75 x 22,00 (Š x V x L)
A30: 11. | B30: beton | C30: m3 | D30: 3.3 | F30: =D30*E30 -> 0
A31: 12. | B31: oplata | C31: m2 | D31: 33.3 | F31: =D31*E31 -> 0
A32: 13. | B32: Dobava i ugradnja armature | C32: kg | D32: 814.2 | F32: =D32*E32 -> 0
A33: 14. | B33: Izvedba drenažne cjevi uz dno AB zida, posip sa šljunkom i umotano u filc | C33: m1 | D33: 24 | F33: =D33*E33 -> 0
A34: 15. | B34: Izvedba revizijskog okna i spajanje drenaže na odvodni kanal | C34: kom | D34: 1 | F34: =D34*E34 -> 0
B36: PARAPETNI ZID ZA MONTAŽU PANELNE OGRADE
A38: 1. | B38: Iskoličenje parcelne granice i novog zida | C38: kom. | D38: 1 | F38: =D38*E38 -> 0
A39: 2. | B39: Iskop za temeljenje zidu | C39: m3 | D39: =(35.54*2+24.67)*1.5*0.5 -> 71.81 | F39: =D39*E39 -> 0
A40: 3. | B40: Zatrpavanje sa iskopnim materijalom do potrebne visine. | C40: m3 | D40: =(35.54*2+24.67)*1.5*1.3 -> 186.71 | F40: =D40*E40 -> 0
A41: 4. | B41: Geotekstil 300g/m2, dobava i ugradnja | C41: m2 | D41: =1.5*(2*35.54+24.67) -> 143.63 | F41: =D41*E41 -> 0
A42: 5. | B42: AB temelj zida 0,50 x 1,2 (Š x V)
A43: 6. | B43: beton | C43: m3 | D43: =1.2*(2*35.54+24.67)*0.5 -> 57.45 | F43: =D43*E43 -> 0
A44: 7. | B44: oplata | C44: m2 | D44: =1*(2*35.54+24.67) -> 95.75 | F44: =D44*E44 -> 0
A45: 8. | B45: AB zid, 1,35 x 0,20 (Š x V)
A46: 9. | B46: beton | C46: m3 | D46: =1.35*0.2*(2*35.54+24.67) -> 25.85 | F46: =D46*E46 -> 0
A47: 10. | B47: oplata | C47: m2 | D47: =1.35*2*(2*35.54+24.67) -> 258.53 | F47: =D47*E47 -> 0
A48: 11. | B48: Dobava i ugradnja armature | C48: kg | D48: =D46+D43*70 -> 4047.35 | F48: =D48*E48 -> 0
...
