Workbook

Sheet nas
A8: Investitor: | B8: Suvlasnici stambene zgrade Tijardovićeva ulica 28, 30, 32, 10000 Zagreb, koje zastupaju: Ovlašteni predstavnici suvlasnika: Lidija Drvodelić, Tijardovićeva ulica 28, 10000 Zagreb, OIB: 86734105079 Ljuba Maričić, Tijardovićeva ulica 30, 10000 Zagreb, OIB: 49358266967 Boro Brdovčak, Tijardovićeva ulica 32, 10000 Zagreb, OIB: 94821741936 Upravitelj: Gradsko stambeno komunalno gospodarstvo d.o.o., Savska cesta 1, 10000 Zagreb, OIB: 03744272526
A11: Građevina: | B11: Rekonstrukcija u svrhu energetske obnove stambene zgrade, Tijardovićeva ulica 28, 30, 32, 10000 Zagreb
A13: Lokacija: | B13: Tijardovićeva ulica 28, 30, 32, 10000 Zagreb,
B14: k.č. 5616/2, k.o. Donje Vrapče
A16: Tehnički dnevnik: | B16: 171 - 2024
A18: Zajednička oznaka projekta: | B18: SAE - 171 - 2024
A20: Razina razrade projekta: | B20: Glavni projekt
A22: Vrsta projekta: | B22: ARHITEKTONSKI PROJEKT REKONSTRUKCIJE U SVRHU ENERGETSKE OBNOVE
B23: TROŠKOVNIK GRAĐEVINSKO - OBRTNIČKIH RADOVA
A25: Projektant: | B25: Ana Miljan, mag. ing. arch.
A26: Suradnik: | B26: Martin Janković, mag.ing.arch. Andrea Banić, mag.ing.aedif.
A28: Glavni projektant: | B28: Ana Miljan, mag. ing. arch.
A30: Izradio: | B30: SAEPTUM d.o.o. za savjetovanje, arhitektonske i energetske usluge, Travnička 50/a, 40000 Čakovec, Kružna ulica 81, 10000 Zagreb
A31: Direktorica: | B31: Željka Hrs Borković, d.i.a., direktor
A33: Mjesto i datum: | B33: Zagreb, travanj 2024.
A36: SAEPTUM d.o.o. Travnička 50/A, ČK, Kružna ulica 81, ZG, T+385 98 302785, +385 1 5602505, www.saeptum.hr, OIB 00721493603, P.RAČUN HR8623600001102580265 ZABA, Temeljni kapital 50.000,00 HRK/6.636,14 EUR, Uprava Željka Hrs Borković, Toni Borković
A47: SADRŽAJ :
A51: 1. TROŠKOVNIK GRAĐEVINSKO - OBRTNIČKIH RADOVA
A56: Napomena: | B56: 1. Troškovnik obuhvaća cjelovitu obnovu.
B57: 2. U slučaju drugačijeg zahtjeva investitor je dužan naručiti izmjene i dopune predmetne dokumentacije, a projektanti se obvezuju istu i napraviti ukoliko je u skladu sa pravilima dobrog zanata i stručne etike.
B58: U tom slučaju, djelomična obnova i njeni detalji utvrđuju se pisanim zahtjevom u vidu projektnog zadatka koji potpisuje investitor.
B59: 3. U troškovniku su navedene projektantske cijene.

Sheet uk rek
A7: Investitor: | B7: Suvlasnici stambene zgrade Tijardovićeva ulica 28, 30, 32, 10000 Zagreb, koje zastupaju: Ovlašteni predstavnici suvlasnika: Lidija Drvodelić, Tijardovićeva ulica 28, 10000 Zagreb, OIB: 86734105079 Ljuba Maričić, Tijardovićeva ulica 30, 10000 Zagreb, OIB: 49358266967 Boro Brdovčak, Tijardovićeva ulica 32, 10000 Zagreb, OIB: 94821741936 Upravitelj: Gradsko stambeno komunalno gospodarstvo d.o.o., Savska cesta 1, 10000 Zagreb, OIB: 03744272526
A10: Građevina: | B10: Rekonstrukcija u svrhu energetske obnove stambene zgrade Tijardovićeva ulica 28, 30, 32, 10000 Zagreb
A12: Lokacija: | B12: Tijardovićeva ulica 28, 30, 32, 10000 Zagreb
B13: k.č. 5616/2, k.o. Donje Vrapče
A16: Izradio: | B16: SAEPTUM d.o.o. za savjetovanje, arhitektonske i energetske usluge, Travnička 50/a, Čakovec, Kružna ulica 81, 10 000 Zagreb
B19: UKUPNA REKAPITULACIJA SVIH RADOVA
B21: 1. GRAĐEVINSKI RADOVI | F21: ='rekap+stolarija'!F22 -> 0
B22: 2. OBRTNIČKI RADOVI | F22: ='rekap+stolarija'!F33 -> 0
B23: 3. ELEKTRO INSTALACIJE | F23: ='rekap+stolarija'!F39 -> 0
E24: EUR | F24: =SUM(F21:F23) -> 0
C26: SVEUKUPNO: | E26: EUR | F26: =F24 -> 0
C27: PDV 25% | E27: EUR | F27: =(F21+F22)*0.25 -> 0
C28: (PDV na elektro instalacije iznosi 0%)
C29: SVEUKUPNO S PDV-OM: | E29: EUR | F29: =F26+F27 -> 0

Sheet sve rek
A7: Investitor: | B7: Suvlasnici stambene zgrade Tijardovićeva ulica 28, 30, 32, 10000 Zagreb, koje zastupaju: Ovlašteni predstavnici suvlasnika: Lidija Drvodelić, Tijardovićeva ulica 28, 10000 Zagreb, OIB: 86734105079 Ljuba Maričić, Tijardovićeva ulica 30, 10000 Zagreb, OIB: 49358266967 Boro Brdovčak, Tijardovićeva ulica 32, 10000 Zagreb, OIB: 94821741936 Upravitelj: Gradsko stambeno komunalno gospodarstvo d.o.o., Savska cesta 1, 10000 Zagreb, OIB: 03744272526
A9: Građevina: | B9: Rekonstrukcija u svrhu energetske obnove stambene zgrade Tijardovićeva ulica 28, 30, 32, 10000 Zagreb
A11: Lokacija: | B11: Tijardovićeva ulica 28, 30, 32, 10000 Zagreb
B12: k.č. 5616/2, k.o. Donje Vrapče
A16: Izradio: | B16: SAEPTUM d.o.o. za savjetovanje, arhitektonske i energetske usluge, Travnička 50/a, 40000 Čakovec, Kružna ulica 81, 10000 Zagreb
B19: TROŠKOVNIK GRAĐEVINSKO OBRTNIČKIH RADOVA I ELEKTRO INSTALACIJE (bez zamjene stolarije stanova)
A21: SVEUKUPNA REKAPITULACIJA
A23: 1.2. | B23: GRAĐEVINSKI RADOVI: | E23: EUR | F23: =rekap!F19 -> 0
B24: OBRTNIČKI RADOVI: | E24: EUR | F24: =rekap!F28 -> 0
B25: ELEKTRO INSTALACIJA: | E25: EUR | F25: =rekap!F34 -> 0
C27: SVEUKUPNO: | E27: EUR | F27: =F23+F24+F25 -> 0
C28: PDV 25% | E28: EUR | F28: =(F23+F24)*0.25 -> 0
C29: (PDV na elektro instalacije iznosi 0%)
C30: SVEUKUPNO S PDV-OM: | E30: EUR | F30: =F27+F28 -> 0
A32: PONUDITELJ
A33: (naziv i adresa)

Sheet sve rek + stolarija
A7: Investitor: | B7: Suvlasnici stambene zgrade Tijardovićeva ulica 28, 30, 32, 10000 Zagreb, koje zastupaju: Ovlašteni predstavnici suvlasnika: Lidija Drvodelić, Tijardovićeva ulica 28, 10000 Zagreb, OIB: 86734105079 Ljuba Maričić, Tijardovićeva ulica 30, 10000 Zagreb, OIB: 49358266967 Boro Brdovčak, Tijardovićeva ulica 32, 10000 Zagreb, OIB: 94821741936 Upravitelj: Gradsko stambeno komunalno gospodarstvo d.o.o., Savska cesta 1, 10000 Zagreb, OIB: 03744272526
A9: Građevina: | B9: Rekonstrukcija u svrhu energetske obnove stambene zgrade, Tijardovićeva ulica 28, 30, 32, 10000 Zagreb
A11: Lokacija: | B11: Tijardovićeva ulica 28, 30, 32, 10000 Zagreb
B12: k.č. 5616/2, k.o. Donje Vrapče
A16: Izradio: | B16: SAEPTUM d.o.o. za savjetovanje, arhitektonske i energetske usluge, Travnička 50/a, 40000 Čakovec, Kružna ulica 81, 10000 Zagreb
B19: TROŠKOVNIK GRAĐEVINSKO OBRTNIČKIH RADOVA I ELEKTRO INSTALACIJE (sa zamjenom stolarije stanova)
A22: SVEUKUPNA REKAPITULACIJA
A24: 1.2. | B24: GRAĐEVINSK,OBRTNIČKI RADOVI I ELEKTRO INSTALACIJA: | E24: EUR | F24: ='rekap+stolarija'!F41 -> 0
C28: SVEUKUPNO: | E28: EUR | F28: =F24 -> 0
C29: PDV 25% | E29: EUR | F29: ='uk rek'!F27 -> 0
C30: (PDV na elektro instalacije iznosi 0%)
C31: SVEUKUPNO S PDV-OM: | E31: EUR | F31: =F28+F29 -> 0
A33: PONUDITELJ
A34: (naziv i adresa)

Sheet rekap
A5: 1.1. TROŠKOVNIK GRAĐEVINSKO OBRTNIČKIH RADOVA I ELEKTRO INSTALACIJE
A9: REKAPITULACIJA GRAĐEVINSKO - OBRTNIČKIH RADOVA I ELEKTRO INSTALACIJE
A12: A. | B12: GRAĐEVINSKI RADOVI
A14: A.I.1. | B14: PRIPREMNI RADOVI I SKELA (zajednički prostori) ukupno | E14: EUR | F14: =A.I.1!F71 -> 0
A15: A.II.1. | B15: RUŠENJA I DEMONTAŽE (zajednički prostori) ukupno | E15: EUR | F15: =A.II.1!F81 -> 0
A16: A.III. | B16: ZEMLJANI RADOVI ukupno | E16: EUR | F16: ='A. III. zemlj.'!F29 -> 0
A17: A.IV.1. | B17: ZIDARSKI RADOVI (zajednički prostori) ukupno | E17: EUR | F17: =A.IV.1.zid!F64 -> 0
A18: A.V. | B18: IZOLATERSKI RADOVI ukupno | E18: EUR | F18: =A.V.izo!F82 -> 0
A19: A. | B19: GRAĐEVINSKI RADOVI UKUPNO: | E19: EUR | F19: =SUM(F14:F18) -> 0
A21: B. | B21: OBRTNIČKI RADOVI
A23: B.I. | B23: LIMARSKI RADOVI ukupno | E23: EUR | F23: =B.I.lim!F62 -> 0
A24: B.II.1 | B24: VANJSKA BRAVARIJA (zajedničkih prostorija) ukupno | E24: EUR | F24: ='B.II.1. brav'!F180 -> 0
A25: B.III. | B25: ZAVRŠNI ZIDARSKO-FASADERSKI RADOVI ukupno | E25: EUR | F25: =B.III.zz!F110 -> 0
A26: B.IV. | B26: BRAVARSKI RADOVI | E26: EUR | F26: ='B.IV.brav '!F52 -> 0
A27: B.V.1. | B27: SOBOSLIKARSKO LIČILAČKI RADOVI (zajednički prostori) ukupno | E27: EUR | F27: =B.V.1.lič!F96 -> 0
A28: B. | B28: OBRTNIČKI RADOVI UKUPNO: | E28: EUR | F28: =SUM(F23:F27) -> 0
A30: C. | B30: ELEKTRO INSTALACIJE
A32: C.I.1. | B32: FOTONAPONSKA ELEKTRANA ukupno | E32: EUR | F32: ='C.I.1 '!F134 -> 0
A33: C.I.2. | B33: MJERENJE, ISPITIVANJE, PODEŠAVANJE I PUŠTANJE U POGON ukupno | E33: EUR | F33: ='C.I.2.'!F22 -> 0
A34: C. | B34: ELEKTRO INSTALACIJE UKUPNO: | E34: EUR | F34: =SUM(F32:F33) -> 0
B36: A+B+C UKUPNO: | E36: EUR | F36: =SUM(F19+F28+F34) -> 0

Sheet rekap+stolarija
A5: 1.2. TROŠKOVNIK GRAĐEVINSKO OBRTNIČKIH RADOVA I ELEKTRO INSTALACIJE
A9: REKAPITULACIJA GRAĐEVINSKO - OBRTNIČKIH RADOVA I ELEKTRO INSTALACIJE
B10: (stambenih i zajedničkih prostorija)
A12: A. | B12: GRAĐEVINSKI RADOVI
A14: A.I.1. | B14: PRIPREMNI RADOVI I SKELA ukupno (zajednički prostori) | E14: EUR | F14: =A.I.1!F71 -> 0
A15: A.I.2. | B15: PRIPREMNI RADOVI ukupno (stanovi) | E15: EUR | F15: =A.I.2!F34 -> 0
A16: A.II.1. | B16: RUŠENJA I DEMONTAŽE ukupno (zajednički prostori) | E16: EUR | F16: =A.II.1!F81 -> 0
A17: A.II.2. | B17: RUŠENJA I DEMONTAŽE ukupno (stanovi) | E17: EUR | F17: =A.II.2!F33 -> 0
A18: A.III. | B18: ZEMLJANI RADOVI | E18: EUR | F18: ='A. III. zemlj.'!F29 -> 0
A19: A.IV.1. | B19: ZIDARSKI RADOVI ukupno (zajednički prostori) | E19: EUR | F19: =A.IV.1.zid!F64 -> 0
A20: A.IV.2. | B20: ZIDARSKI RADOVI ukupno (stanovi) | E20: EUR | F20: =A.IV.2.zid!F37 -> 0
A21: A.V. | B21: IZOLATERSKI RADOVI ukupno | E21: EUR | F21: =A.V.izo!F82 -> 0
A22: A. | B22: GRAĐEVINSKI RADOVI UKUPNO: | E22: EUR | F22: =SUM(F14:F21) -> 0
A24: B. | B24: OBRTNIČKI RADOVI
A26: B.I. | B26: LIMARSKI RADOVI ukupno | E26: EUR | F26: =B.I.lim!F62 -> 0
A27: B.II.1. | B27: VANJSKA BRAVARIJA ukupno (zajedničkih prostorija) | E27: EUR | F27: ='B.II.1. brav'!F180 -> 0
A28: B.II.2. | B28: VANJSKA STOLARIJA ukupno (stanovi) | E28: EUR | F28: ='B.II.2. sto'!F230 -> 0
A29: B.III. | B29: ZAVRŠNI ZIDARSKO-FASADERSKI RADOVI ukupno | E29: EUR | F29: =B.III.zz!F110 -> 0
A30: B.IV. | B30: BRAVARSKI RADOVI ukupno | E30: EUR | F30: ='B.IV.brav '!F52 -> 0
A31: B.V.1. | B31: SOBOSLIKARSKO LIČILAČKI RADOVI (zajednički prostori) ukupno | E31: EUR | F31: =B.V.1.lič!F96 -> 0
A32: B.V.2. | B32: SOBOSLIKARSKO LIČILAČKI RADOVI (stanovi) ukupno | E32: EUR | F32: =B.V.2.lič!F32 -> 0
A33: B. | B33: OBRTNIČKI RADOVI UKUPNO: | E33: EUR | F33: =SUM(F26:F32) -> 0
A35: C. | B35: ELEKTRO INSTALACIJE
A37: C.I.1. | B37: FOTONAPONSKA ELEKTRANA ukupno | E37: EUR | F37: ='C.I.1 '!F134 -> 0
A38: C.I.2. | B38: MJERENJE, ISPITIVANJE, PODEŠAVANJE I PUŠTANJE U POGON ukupno | E38: EUR | F38: ='C.I.2.'!F22 -> 0
A39: C. | B39: ELEKTRO INSTALACIJE UKUPNO: | E39: EUR | F39: =SUM(F37:F38) -> 0
B41: A+B+C UKUPNO: | E41: EUR | F41: =SUM(F22+F33+F39) -> 0

Sheet opći
B3: OPĆI UVJETI
B5: OPĆI OPIS UZ TROŠKOVNIK
B7: 1. Glavni projekt energetske obnove i pripadni troškovnik temelje se na obavljenom uvidu na postojećoj zgradi. Slojevi konstrukcija definirani u postojećoj projektnoj tehničkoj dokumentaciji preuzeti su kao stvarno izvedeni. Nevidljivi slojevi konstrukcija, koji nisu definirani postojećom dokumentacijom, pretpostavljeni su temeljem dosadašnjeg iskustva prema vremenu gradnje zgrade. Prije izvedbe potrebno je izvršiti detaljni uvid na licu mjesta te utvrditi slojeve konstrukcije vizualnim ispitivanjem i otvaranjem konstrukcija koje se rekonstruiraju.
B9: 2. Projekt je napravljen na temelju zakonske regulative RH, pravila dobrog zanata i preporuke o cjelovitoj obnovi koju podupiru EU fondovi, u skladu sa svim hrvatskim i europskim tehničkim propisima i normama i priznatim tehničkim pravilima, ili jednakovrijedno __________________. Projekt je definiran potpisanim projektnim zadatkom. Svi materijali navedeni u projektu i troškovniku, moraju odgovarati važećim hrvatskim propisima i normama, ili jednakovrijedno __________________.
B11: 3. Grafički dio (nacrti), tekstualni dio (opći i tehnički), Projekt racionalne uporabe energije i toplinske zaštite zgrade, kao i Program kontrole i osiguranja kvalitete dijelovi su arhitektonskog glavnog projekta, koji zajedno s pripadajućim troškovnikom čine cjelinu projekta energetske obnove zgrade. Projektom energetske obnove dani su osnovni detalji izvedbe.
B13: 4. U fazi izvedbe, zbog činjenice da se radi o obnovi (rekonstrukciji), a ne izgradnji nove zgrade, bit će potrebna dodatna razrada detalja izvedbe u suradnji s izvođačem radova, te ukoliko se nakon uklanjanja pojedinih slojeva i uvida u postojeće slojeve i stanje konstrukcije utvrdi odstupanje odnosno različitost u odnosu na postojeće stanje prikazano projektom obnove, potrebno je napraviti reviziju glavnog projekta. Također, u slučaju nužnosti odstupanja od glavnog projekta iz drugih opravdanih razloga prilikom izvođenja radova potrebno je izraditi izmjene i dopune glavnog projekta.
B15: 5.Odgovarajućim upisom u građevinski dnevnik potrebno je verificirati projektno rješenje ili po potrebi izvršiti korekciju, te ukoliko je potrebno, a ovisno o postojećem stanju konstrukcije, prije izvedbe ETICS sustava, napraviti statičku provjeru vanjskih zidova koja mora biti odobrena od strane inženjera konstrukcije i nadzornog inženjera.
B17: 6. Izvođač je dužan proučiti sve gore navedene dijelove projekta, te u slučaju nejasnoća ili eventualnih odstupanja od stvarnog stanja na terenu, tražiti mišljenje projektanta i nadzornog inženjera. Prije početka radova izvođač je obavezan kontrolirati na postojećoj zgradi sve potrebne mjere za svoj rad, te obavijestiti projektanta u slučaju nedorečenosti ili nejasnoća. Prilikom izvođenja radova treba paziti da svi detalji budu riješeni u skladu s Tehničkim propisom o racionalnoj uporabi energije i toplinskoj zaštiti u zgradama (NN 128/15, NN 70/18, NN 73/18, 86/18.)
B20: 7. Preporuka projektanta je izvođenje cjelovitog rješenja energetske obnove zgrade iz sljedećih razloga: 1. tehnički ispravno izvođenje detalja, 2. tehnički ispravan redoslijed izvođenja radova, 3. suzbijanje selektivnih intervencija na pročeljima zgrade, 4. zaštita arhitektonskog djela u smislu estetske i tehničke cjelovitosti oblikovanja, 5. očuvanje i unapređenje bitnih zahtjeva građevine, 6. ušteda sredstava i vremena (u slučaju fazne gradnje pojedini radovi se umnožavaju, kao što su postava skele, limarski radovi i sl.), 7. ostvarivanje tržišnih popusta (cijena pojedinačnog proizvoda manja je što je količina veća), 8. integralna rješenja podupiru se bespovratnim sredstvima iz EU fondova. U slučaju nužnosti odstupanja od glavnog projekta prilikom izvođenja radova potrebno je izraditi izmjene i dopune glavnog projekta te ih uskladiti zahtjevima suvlasnika sukladno pravilima dobrog zanata i inženjerske etike.
B22: 8. Izvođač će se pridržavati svih važećih zakona i propisa i to: Zakona o prostornom uređenju (NN 153/13, NN 65/17, NN 114/18, NN 39/19), Zakona o gradnji (NN 153/13, 20/17, 39/19, 125/19, 145/24), Zakona o građevinskoj inspekciji (NN 153/13), Zakona o zaštiti na radu (NN 71/14, 118/14, N 154/14, 94/18, 96/18), Zakon o zaštiti od buke (NN 30/09, 55/13, 153/13, 41/16, 114/18, 41/21), Zakon o zaštiti od požara (NN 92/10), svih pravilnika koji iz tih zakona proizlaze, kao i svih drugih zakona iz područja gradnje, tehničkih propisa, priznatih tehničkih pravila i hrvatskih normi (HRN), ili jednakovrijedno __________________.
B24: 9. Izvođač će prilikom uvođenja u posao preuzeti nekretninu i obavijestiti nadležne službe o otvaranju gradilišta i početku radova. Od tog trenutka pa do primopredaje zgrade, izvođač je odgovoran za stvari i osobe koje se nalaze unutar gradilišta. Od ulaska na gradilište izvođač je obavezan voditi građevinski dnevnik u kojem bilježi opis radnih procesa i građevinsku knjigu u kojoj bilježi i dokumentira mjerenja, sve faze izvršenog posla prema stavkama troškovnika i projektu. Izvođač će na gradilištu čuvati građevnu dozvolu ukoliko je to zakonom određeno, kao i projektnu dokumentaciju i dati ih na uvid ovlaštenim inspekcijskim službama.
B26: 10. Izvođač će ugraditi projektom predviđen i prema hrvatskim normama ili jednakovrijedno __________________ atestiran materijal. Sve radove izvest će od kvalitetnog materijala prema opisu, detaljima, pismenim naređenjima, ali sve u okviru ponuđene jedinične cijene. Svi nekvalitetni radovi imaju se otkloniti i zamijeniti ispravnima, bez bilo kakve odštete od strane investitora.
... B54: 24. Izvođač će zajedno sa nadzornim inženjerom izraditi vremenski plan (terminski plan, gantogram) aktivnosti na gradilištu i njime odrediti dinamiku financiranja, dobave materijala i opreme i sl.

Sheet A.I.1
A2: TROŠKOVNIK GRAĐEVINSKO OBRTNIČKIH RADOVA I ELEKTRO INSTALACIJE
A3: A. GRAĐEVINSKI RADOVI / A.I.1 PRIPREMNI RADOVI I SKELA
A4: r.b. | B4: opis stavke | C4: jed. | D4: kol. | E4: jed.cijena | F4: ukupno
A6: A. | B6: GRAĐEVINSKI RADOVI
A9: A.I.1 | B9: PRIPREMNI RADOVI I SKELA (ZAJEDNIČKI PROSTORI)
A11: OPĆI UVJETI
B13: PRIPREMNI RADOVI
A15: Pri kalkulaciji ponuda ponuđač treba voditi računa o uvjetima investitora, da zgrada za vrijeme radova mora biti u funkciji te da se radovi moraju planirati tako da se omogući boravak u svim dijelovima zgrade uz što manje i kraće poremećaje.
A17: Izvođaču se preporuča pregledati projekt i lokaciju, mogućnosti pristupa parceli i organizacije rada na parceli kako bi mogao dati realnu cijenu za pripremne i ostale radove. Ukoliko izvođač prethodnim uvidom primijeti da je potrebno izvesti još neke pripremne radove, dužan ih je uvrstiti u cijenu putem obračuna u faktoru, jer se naknadni pripremni radovi neće posebno priznavati.
A19: Pripremni radovi koje je izvođač dužan izvesti bez posebnog iskaza troškova ulaze u cijenu zgrade kroz faktor i nisu prikazani u posebnim stavkama troškovnika: - izrada plana organizacije gradilišta, - organizacija i uređenje prilaznih i privremenih prometnica na gradilištu - izgradnja gradilišnih nastambi za radnike, upravu, skladišta, nadstrešnice, - privremeni priključci i razvod vodovoda, električne energije, telefona i ostalih instalacija na gradilištu za potrebe funkcioniranja gradilišta, - organizacija čuvarske i nadzorne službe, radovi na osiguranju gradilišta i radnika, osiguranje za obeštećenja na gradilištu i naknade štete prema trećim osobama - geodetsko snimanje visina i vanjskog terena, - ostali radovi koji po pravilu terete režiju uprave izvođača i koji se ne naplaćuju posebno - troškovi potrebnih ispitivanja materijala i konstrukcija, te ishođenje atesta. Utrošak vode i električne energije za jedinicu proizvoda uključuje se u analizu cijena proizvoda prema normativima utroška, a utrošak za potrebe ureda, gradilišta, pranje vozila i strojeva, rasvjetu gradilišta i ostalo uključuje se u faktor gradilišta.
A21: Dozvolu za korištenje javnih prometnih površina izvođač je dužan zatražiti od nadležnih službi, prema potrebama za organizaciju gradilišta i platiti eventualne takse za ishođenje odobrenja za korištenje površina što je uključeno u faktoru. Izvođač je dužan pridržavati se pravila prometa na javnim prometnicama i unutar gradilišta.
A23: SKELA
A25: Izvođaču se preporuča pregledati građevinu radi ocjene uvjeta za organizaciju izvedbe radova i stanja pojedinih dijelova građevine na kojima se radovi izvode prije izrade ponude za skelu. Oslanjanje skele na nosivu podlogu preko metalnih podložnih papuča; podloga na koju se postavlja fasadna skela mora biti čvrsta i stabilna. Minimalna širina skele iznosi 80cm.
A27: Izvođač je dužan prije postavljanja skele predočiti nacrt skele sa statičkim računom na odobrenje. Dužan je ishoditi i suglasnosnost za postavljanje skele - zauzimanje javnoprometne površine te riješiti zaštitu prolaznika i ulaza u građevinu. Ukoliko za pričvršćenje skele bude potrebno koristiti tuđi prostor, izvoditelj je dužan ishoditi suglasnost.
A29: Skelu udaljiti od ravnine gotovog pročelja za 15-20 cm. Visina zaštitne ograde iznosi 100 cm, a elemente ograde postaviti na max. razmak od 35 cm. U razini radne platforme uz zaštitinu ogradu potrebno je postaviti dasku minimalne visine 20 cm. Radnu platformu izvesti od mosnica od zdrave piljene crnogorične građe II. klase, minimalne širine 25 cm i minimalne debljine 4,8 cm. Visinski razmak između radnih platformi treba prilagoditi horizontalnim elementima pročelja.
A31: Skela mora biti opremljena penjalicama max. dužine 4 m u jednom komadu, postavljenim naizmjenično. Fasadnu skelu potrebno je sa vanjske strane prekriti jutenim zastorom, koji se učvršćuje za konstrukciju skele. Skelu treba od podnožja do vrha, kao i na krajevima, dijagonalno ukrutiti kosnicima pod 45°. Skelu je potrebno osigurati od prevrtanja sidrenjem u samu građevinu. Razmak između točki sidrenja mora biti manji od 6,0 m u horizontalnom i vetikalnom smjeru. Izvedena skela ne smije imati visinu stupova veću od 4 m. Skelu je potrebno uzemljiti i osigurati od udara groma.
A33: Sva eventualna oštećenja nastala uslijed vezivanja skele na građevinu izvođač je dužan otkloniti o svom trošku.
A35: Pješački prolaz ispod skele treba izvesti u skladu s potrebama korisnika, odnosno u skladu s dozvolom za zauzeće javne prometne površine. Sa bočnih strana prolaza se postavlja puna zaštitna ograda minimalne visine od 150cm. Iznad prolaza treba izvesti oblogu od mosnica, a na vanjskom rubu još i kosu zaštitu pod kutem od 60° visine 60cm. Pješački prolaz treba biti obilježen propisanom signalizacijom (putokazi, rasvjeta).
A36: U jediničnu cijenu treba uključiti : - sav rad oko postave i skidanja skele, - izradu statičkog računa i nacrta montaže skele, - dostavu svog potrebnog materijala za postavu skele te čišćenje i odvoz istog nakon skidanja, - postavu svjetlosne signalizacije i njeno održavanje, - amortizaciju materijala za vrijeme izvođenja svih radova na pročelju, - sve društvene obveze vezane za radnu snagu i materijal, - održavanje skele za vrijeme trajanja radova, - pripremno-završne radove, - naknada za zauzimanje javno-prometne površine. Amortizacija skele obračunava se za vrijeme gradnje, a skelu mogu koristiti svi izvođači bez posebne nadoplate. Potrebno je terminskim planom uskladiti sve aktivnosti da se izbjegne međusobno ometanje pojedinih izvođača. Svi materijali za izradu skele moraju odgovarati važećim hrvatskim propisima i normama, ili jednakovrijedno __________________.
A38: Prilikom izrade fasadnih skela potrebno se pridržavati propisa zaštite na radu po pitanjima radnih ploha, zaštitnih ograda i prilaza. Materijal za izradu skela mora biti potpuno ispravan. Odgovorna osoba dužna je izvršiti pregled materijala prije ugradnje. Skele moraju biti izvedene po mjerama i na način označen u statičkom računu i nacrtima za skele. Izvedene skele moraju biti sposobne podnijeti predviđeno opterećenje i moraju biti stabilne. Fasadne skele obračunavaju se po m² projekcije skele u ravnini pročelja, mjereno po vanjskom rubu i 1 m nad najvišom površinom.
A40: 1. | B40: Raščišćavanje terena
B41: Raščišćavanje terena oko zgrade (5m) kao radno-manipulativne površine, a prije početka radova na rušenjima i demontaži. Stavka uključuje sva čišćenja, obrezivanje grmlja i stabala koji svojom pozicijom i volumenom ometaju izvođenje radova, zajedno s utovarom, odvozom, istovarom i deponiranjem otpadnog materijala na odlagalištu udaljenom 20 km. Obračun po m² obrađene površine. | C41: m² | D41: 800 | F41: =ROUND(D41*E41,2) -> 0
A43: 2. | B43: Priprema gradilišta
B44: Priprema gradilišta obuhvaća pregled, kontrolu mjera i veličina postojećeg stanja građevinske konstrukcije zgrade, pregled postojećeg stanja opreme, instalacija, te utvrđivanje točnih koridora instalacija u objektu i izvan objekta. Pipremne radove je obavezan izvršavati izvođač radova prije nego pristupi izvođenju i za vrijeme izvođenja radova. U pripremne radove uključiti i pregled projektne dokumentacije s pripadajućim troškovnicima, a o svim nejasnoćama ili neusklađenostima pravovremeno izvjestiti investitora i projektanta. Stavka uključuje zaštitu zgrade izvana i iznutra od oštećenja tijekom radova, osiguranje koridora za prolaz korisnika zgrade s pripadajućom zaštitom od šute i prašine, te osiguranje radnog prostora od prilaza neovlaštenih osoba tijekom radova. Sav prostor za vrijeme i nakon rušenja i demontaža, te prilikom izvođenja novih konstrukcija, zaštititi od vremenskih nepogoda (vlaženja, prokišnjavanja, rashlađivanja), te osigurati i zaštititi od ostalih uvjeta koji bi mogli ometati izvođenje radova vezanih za postojeće instalacije (vodovod, odvodnja, grijanje, ventilacija, elektrika, plin i drugo). Sve radove treba izvoditi u skladu s obaveznim higijensko tehničkim mjerama zaštite na radu.
B45: Obračun za izvođenje kompletnih pripremnih radove iz opisa stavke, po paušalnoj procjeni.
C46: komplet | D46: 1 | F46: =ROUND(D46*E46,2) -> 0
A48: 3. | B48: Fasadna skela
B49: Doprema, montaža, demontaža i otprema cijevne fasadne skele, visine 1,0 m iznad gornjeg ruba ravnog krova. Skelu izraditi prema važećim propisima i općim uvjetima. Skela mora biti izvedena prema pravilima struke; u stavku su uključene radne platforme i zaštitne ograde, sva potrebna ukrućenja i sidrenja, penjalice, te uzemljenje. Cijenom je obuhvaćena dobava i postava jutenih ili plastificiranih traka na vanjski dio skele, kao zaštita od pada predmeta, prašenja i sl., sve fiksirano za konstrukciju skele. Prije izvedbe skele izvođač je dužan izraditi projekt skele, što je u cijeni stavke. Sve u skladu sa važećim propisima ZNR. Obračun po m² ortogonalne projekcije skele.
B50: fasadna skela | C50: m² | D50: 3300 | F50: =ROUND(D50*E50,2) -> 0
A52: 4. | B52: Priprema pročelja za izvedbu klasificiranog ETICS sustava
B53: Priprema podloge za izradu ETICS sustava toplinske izolacije pročelja na bazi mineralne vune: - otucanje dijela postojeće žbuke koja se odvojila od podloge, - krpanje pukotina u zidovima i stropovima te po potrebi izravnavanje većih neravnina reparaturnim polimercementnim mortom, - popravak oštećene armature odgovarajućim zaštitnim premazima (zaštita od korozije), - skraćivanje i vađenje čeličnih nosača koji nisu više u upotrebi, - saniranje nastalih oštećenja fasade reparaturnim polimercementnim mortom te - pranje i paropropusnu impregnaciju žbuke pročelja. Podloga na koju će se nanositi ETICS mora biti čista, čvrsta, nosiva, bez ostataka prljavštine, sipkih dijelova i sl. Prije nanošenja toplinske izolacije potrebno je provjeriti prionjivost morta za lijepljenje na postojeću podlogu. Stavka uključuje zaštitu stolarije i drugih elemenata koji se ne uklanjaju te prostora u zgradi PVC folijom od šute i prašine, horizontalni i vertikalni transport šute i materijala po gradilištu, prijenos i odvoz otpadnog materijala i šute na deponij udaljen 20 km. Obračun za kompletan rad, materijal i sve transporte je po m² kompletno obrađene i pripremljene površine pročelja. Otvori se odbijaju u cijeloj površini. | C53: m² | D53: 5100 | F53: =ROUND(D53*E53,2) -> 0
A55: 5. | B55: Priprema špaleta za RAL ugradnju vanjskih vrata i prozora stubišta
B56: Obrada špaleta vanjskih vrata i prozora za RAL ugradnju nakon demontaže postojeće i prije ugradnje nove stolarije: - sanacija pukotina špaleta konstrukcijskim reparaturnim polimercementnim mortom, - krpanje oštećenja na zidovima produžnim mortom, - izravnavanje većih neravnina grubom produžnom žbukom, uz adekvatnu pripremu. Špaletu pripremiti i otprašiti za pravilno ljepljenje traka za RAL ugradnju prema uputama proizvođača. Stavka uključuje horizontalni i vertikalni transport šute i materijala po gradilištu, prijenos i odvoz otpadnog materijala i šute na deponij udaljen 20 km. Obračun po komadu otvora.
B57: ZP1 - prozor 360/96 cm | C57: kom | D57: 11 | F57: =ROUND(D57*E57,2) -> 0
B58: ZP2 - prozor 300/96 cm | C58: kom | D58: 4 | F58: =ROUND(D58*E58,2) -> 0
B59: ZP3 - prozor 275/168 cm | C59: kom | D59: 3 | F59: =ROUND(D59*E59,2) -> 0
B60: ZP4 - prozor 170/168 cm | C60: kom | D60: 3 | F60: =ROUND(D60*E60,2) -> 0
B61: ZP5 - prozor 300/60 cm | C61: kom | D61: 3 | F61: =ROUND(D61*E61,2) -> 0
B62: ZP6 - prozor 100/110 cm | C62: kom | D62: 1 | F62: =ROUND(D62*E62,2) -> 0
B63: ZV1 - ulazna ostakljena stijena 335/250 cm | C63: kom | D63: 2 | F63: =ROUND(D63*E63,2) -> 0
...

Sheet A.I.2
A2: TROŠKOVNIK GRAĐEVINSKO OBRTNIČKIH RADOVA I ELEKTRO INSTALACIJE
A3: A. GRAĐEVINSKI RADOVI / A.I.2. PRIPREMNI RADOVI (STAMBENIH PROSTORIJA)
A4: r.b. | B4: opis stavke | C4: jed. | D4: kol. | E4: jed.cijena | F4: ukupno
A6: A. | B6: GRAĐEVINSKI RADOVI
A9: A.I.2. | B9: PRIPREMNI RADOVI (STANOVI)
A11: 1. | B11: Priprema špaleta za RAL ugradnju prozora i vanjskih vrata
B12: Obrada špaleta vanjskih vrata i prozora za RAL ugradnju nakon demontaže postojeće i prije ugradnje nove stolarije: - sanacija pukotina špaleta konstrukcijskim reparaturnim polimercementnim mortom, - krpanje oštećenja na zidovima produžnim mortom, - izravnavanje većih neravnina grubom produžnom žbukom, uz adekvatnu pripremu. Špaletu pripremiti i otprašiti za pravilno ljepljenje traka za RAL ugradnju prema uputama proizvođača. Stavka uključuje horizontalni i vertikalni transport šute i materijala po gradilištu, prijenos i odvoz otpadnog materijala i šute na deponij udaljen 20 km. Obračun po komadu otvora.
B13: P1 - prozor 360/168 cm | C13: kom | D13: 17 | F13: =ROUND(D13*E13,2) -> 0
B14: P2 - prozor 347,5/168 cm | C14: kom | D14: 7 | F14: =ROUND(D14*E14,2) -> 0
B15: P3 - prozor 287,5/168 cm | C15: kom | D15: 5 | F15: =ROUND(D15*E15,2) -> 0
B16: P3a - prozor 200/168 cm | C16: kom | D16: 1 | F16: =ROUND(D16*E16,2) -> 0
B17: P3b - prozor 275/168 cm | C17: kom | D17: 1 | F17: =ROUND(D17*E17,2) -> 0
B18: P4 - prozor 275/168 cm | C18: kom | D18: 8 | F18: =ROUND(D18*E18,2) -> 0
B19: P5 - prozor 120/168 cm u zidu 33 cm | C19: kom | D19: 5 | F19: =ROUND(D19*E19,2) -> 0
B20: P5 - prozor 120/168 cm | C20: kom | D20: 16 | F20: =ROUND(D20*E20,2) -> 0
B21: P5A - prozor 145/168 cm | C21: kom | D21: 2 | F21: =ROUND(D21*E21,2) -> 0
B22: P6 - prozor 60/168 cm | C22: kom | D22: 8 | F22: =ROUND(D22*E22,2) -> 0
B23: P7 - prozor 60/168 cm | C23: kom | D23: 9 | F23: =ROUND(D23*E23,2) -> 0
B24: P8 - prozor 50/168 cm | C24: kom | D24: 5 | F24: =ROUND(D24*E24,2) -> 0
... B31: V1 - garažna vrata 260/205 cm + prozor 260/105 cm | C31: kom | D31: 2 | F31: =ROUND(D31*E31,2) -> 0
F32: =SUM(F13:F31) -> 0
A34: A.I.2. | B34: PRIPREMNI RADOVI (STANOVI) UKUPNO: | E34: EUR | F34: =SUM(F32) -> 0

Sheet A.II.1
A2: TROŠKOVNIK GRAĐEVINSKO OBRTNIČKIH RADOVA I ELEKTRO INSTALACIJE
A3: A. GRAĐEVINSKI RADOVI / A.II.1. RUŠENJA I DEMONTAŽE
A4: r.b. | B4: opis stavke | C4: jed. | D4: kol. | E4: jed.cijena | F4: ukupno
A7: A.II.1. | B7: RUŠENJA I DEMONTAŽE (ZAJEDNIČKI PROSTORI)
A9: OPĆI UVJETI
A11: Projekt energetske obnove zgrade izrađen je temeljem mogućih izmjera i pretpostavljenih zidnih, stropnih i krovnih slojeva. Dužnost je izvođača da sondiranjem utvrdi stvarni sastav konstrukcija i u slučaju odstupanja sastava upozori nadzornog inženjera i investitora na odstupanje.
A13: Prije početka radova potrebno je konstrukcije u koje ne zadiru radovi zaštititi od mogućeg oštećenja. Sve otvore na pročeljima zgrade treba odmah nakon postave skele zaštititi PVC folijom debljine 0,20 mm kako ne bi došlo do njihovog oštećenja.
A15: Nakon provedenih pripremnih radova, svih potrebnih rasterećenja i potrebnih osiguranja, rušenja na građevini vrše se prema unaprijed utvrđenom redoslijedu dogovorenim s nadzornim inženjerom na način kojim se ne ugrožava stabilnost zgrade, sigurnost radnika i ljudi koji borave u zgradi. Demontaže i rušenja izvode se u pravilu od krova prema podrumu.
A17: Sva rušenja i demontaže konstruktivnih elemenata treba izvršiti pod nadzorom projektanta i statičara. Kod vršenja proboja ili vođenja instalacija u nosivim konstrukcijama zahvat vršiti maksimalno precizno bez narušavanja nosivih svojstava konstrukcije. Prilikom zahvata na nosivim konstrukcijama obavezno je podupiranje. Sva rušenja, probijanja, bušenja i dubljenja treba u pravilu izvoditi ručnim alatom bez upotrebe vibracionih uređaja, s osobitom pažnjom.
A19: Demontažu i ponovnu montažu gromobrana, uz atestiranje, izvođač treba izvoditi prema Tehničkom propisu za sustave zaštite od djelovanja munje na građevinama (NN 87/08, 33/10).
A21: U cijenu radova trebaju biti uključene sve podupore, skele i privremene (zamjenske) konstrukcije, koje osiguravaju stabilnost u toku radova, svi horizontalni i vertikalni prijenosi materijala od rušenja i demontaže, i odvoz na gradsku planirku. U cijenu radova je uključeno i sigurno zbrinjavanje opasnih materijala (azbest, freoni). Ukoliko se uklanjaju elementi koji sadrže azbest to se mora učiniti u skladu s Pravilnikom o načinu i postupcima i gospodarenjem otpadom koji sadrži azbest (NN 42/07).
A23: Demontaža i privremeno deponiranje pločica sa kućnim brojem, natpisnih ploča, vanjskih jedinica rashladnih uređaja, gromobrana, strujnih ormarića i sl. uključuje njihovu sigurnu pohranu na gradilištu ili kod vlasnika. Izvođač snosi sve troškove ponovne dobave ili izrade pojedinih elemenata u slučaju oštećenja ili otuđenja sa gradilišta. Demontažu postojećih limenih elemenata, uključujući i prozorske klupčice na pročelju obavezno izvodi limar koji je dužan uzeti mjere i uzorke te snimiti detalje izvedbe, što je uključeno u cijenu stavke. Demontažu i ponovnu montažu postojećih vanjskih jedinica rashladnih uređaja na pročelju izvodi ovlašteni instalater. Demontažu i ponovnu montažu postojećeg gromobrana, strujnih ormarića i sl. na pročelju izvodi ovlaštena osoba.
A25: U slučaju nastalih šteta, radi nepravodobno zaštićene lokacije na kojoj se vrše rušenja i demontaže, sve troškove nastalih šteta snosi izvođač. Izvođač je dužan striktno se držati mjera zaštite na radu.
A27: 1. | B27: Demontaža i ponovna montaža montažnih elemenata na pročelju i krovu
B28: Demontaža, privremeno uklanjanje i ponovna montaža postojećih TV antena, kablova i pripadajućih kanalica, rasvjetnih tijela, razvodnih ormarića, i sl. sa svih pročelja, stropa prizemlja, lođa i krova. Sve demontirane elemente potrebno je sigurno pohraniti na gradilištu. Nakon radova rušenja i demontaže kablove je potrebno ugraditi podžbukno u nove kanalice, a nakon izvedbe pročelja upotrebljive demontirane elemente potrebno je ponovno montirati, a neupotrebljive elemente odvesti na deponij udaljen 20 km. Otpajanje i ponovno spajanje svih vodova, uzemljenja i sl. vrši ovlaštena stručna osoba. Obračun po komadu.
B29: ploče sa oznakama objekta, kućni broj | C29: kom | D29: 3 | F29: =ROUND(D29*E29,2) -> 0
B30: rukohvat | C30: m' | D30: 4.5 | F30: =ROUND(D30*E30,2) -> 0
B31: antene | C31: kom | D31: 7 | F31: =ROUND(D31*E31,2) -> 0
B32: kablovi i kanalice | C32: m1 | D32: 100 | F32: =ROUND(D32*E32,2) -> 0
B33: portafon, vatrodojava | C33: kom | D33: 5 | F33: =ROUND(D33*E33,2) -> 0
B34: rasvjetni elementi, prekidači, svjetleće reklame | C34: kom | D34: 30 | F34: =ROUND(D34*E34,2) -> 0
B35: tende, sjenila, nosači, hidrantski ormarići | C35: kom | D35: 15 | F35: =ROUND(D35*E35,2) -> 0
A38: 2. | B38: Demontaža i zbrinjavanje postojećih slojeva ravnog krova
B39: Skidanje zaštitnog sloja šljunka debljine u sloju debljine cca 2 cm, te hidroizolacije ravnog krova od bitumenske hitroizolacijske trake ili polimerne izolacijske trake. Hidroizolaciju skidati mahaničkim, termičkim ili kemijskim postupcima, bez oštećivanja zdrave betonske podloge. Stavkom je ubuhvaćeno i skidanje opšavnih limova, te vertikalno uzdignutih rubova izolacije na obodne zidove i konstrukcije. Stavka uključuje demontažu vodolovnih grla i rešetki, te odzračnih cijevi kanalizacije, te sve potrebne radove za kvalitetnu postavu novih slojeva ravnog krova. | C39: m² | D39: 750 | F39: =ROUND(D39*E39,2) -> 0
A41: 3. | B41: Demontaža i zbrinjavanje limenih opšava
B42: Demontaža limenih opšava dimnjaka, ventilacijskih kanala, nosača antena, prozorskih klupčica i ostalih sudarnih i opšavnih limova te opšava krova prosječne razvijene širine 66 cm. Obračun po m' opšava. | C42: m' | D42: 750 | F42: =ROUND(D42*E42,2) -> 0
A44: 4. | B44: Demontaža i ponovna montaža gromobrana
B45: Demontaža i ponovna montaža gromobranske instalacije na krovu sa zamjenom oštećenih i dotrajalih djelova s plastičnim stopama. | C45: m' | D45: 450 | F45: =ROUND(D45*E45,2) -> 0
A47: 5. | B47: Demontaža vrata i prozora zajedničkih prostora
B48: Demontaža postojećih ulaznih vrata, vrata toplinskih podstanica i prozora stubišta i zajedničkih prostorija. Dimenzije su izražene u zidarskim (građevinskim mjerama). Obračun po komadu stolarske stavke.
B49: ZP1 - prozor 360/96 cm | C49: kom | D49: 11 | F49: =ROUND(D49*E49,2) -> 0
B50: ZP2 - prozor 300/96 cm | C50: kom | D50: 4 | F50: =ROUND(D50*E50,2) -> 0
B51: ZP3 - prozor 275/168 cm | C51: kom | D51: 3 | F51: =ROUND(D51*E51,2) -> 0
B52: ZP4 - prozor 170/168 cm | C52: kom | D52: 3 | F52: =ROUND(D52*E52,2) -> 0
B53: ZP5 - prozor 300/60 cm | C53: kom | D53: 3 | F53: =ROUND(D53*E53,2) -> 0
B54: ZP6 - prozor 100/110 cm | C54: kom | D54: 1 | F54: =ROUND(D54*E54,2) -> 0
B55: ZV1 - ulazna ostakljena stijena 335/250 cm | C55: kom | D55: 2 | F55: =ROUND(D55*E55,2) -> 0
B56: ZV2 - ulazna ostakljena stijena 153,5/260 cm | C56: kom | D56: 3 | F56: =ROUND(D56*E56,2) -> 0
B57: ZV3 - ulazna stijena 271/205 cm s prozorom 271/105 cm | C57: kom | D57: 3 | F57: =ROUND(D57*E57,2) -> 0
B58: ZV4 - ostakljena vrata s nadsvjetlom 135,5/260 cm | C58: kom | D58: 35 | F58: =ROUND(D58*E58,2) -> 0
...

Sheet A.II.2
A2: TROŠKOVNIK GRAĐEVINSKO OBRTNIČKIH RADOVA I ELEKTRO INSTALACIJE
A3: A. GRAĐEVINSKI RADOVI / A.II.2. RUŠENJA I DEMONTAŽE (STAMBENIH PROSTORIJA)
A4: r.b. | B4: opis stavke | C4: jed. | D4: kol. | E4: jed.cijena | F4: ukupno
A7: A.II.2. | B7: RUŠENJA I DEMONTAŽE (STANOVI)
A10: 1. | B10: Demontaža i zbrinjavanje postojećih prozora grijanih prostorija
B11: Demontaža postojećih prozora i vrata s pripadajućim okvirima, uključujući i prozorske klupčice i pragove. Dimenzije su izražene u zidarskim (građevinskim mjerama). Uključen sav transport i zbrinjavanje otpada na deponiju udaljenom 20 km. Obračun po komadu stolarske stavke.
B12: P1 - prozor 360/168 cm | C12: kom | D12: 17 | F12: =ROUND(D12*E12,2) -> 0
B13: P2 - prozor 347,5/168 cm | C13: kom | D13: 7 | F13: =ROUND(D13*E13,2) -> 0
B14: P3 - prozor 287,5/168 cm | C14: kom | D14: 5 | F14: =ROUND(D14*E14,2) -> 0
B15: P3a - prozor 200/168 cm | C15: kom | D15: 1 | F15: =ROUND(D15*E15,2) -> 0
B16: P3b - prozor 275/168 cm | C16: kom | D16: 1 | F16: =ROUND(D16*E16,2) -> 0
B17: P4 - prozor 275/168 cm | C17: kom | D17: 8 | F17: =ROUND(D17*E17,2) -> 0
B18: P5 - prozor 120/168 cm u zidu 33 cm | C18: kom | D18: 5 | F18: =ROUND(D18*E18,2) -> 0
B19: P5 - prozor 120/168 cm | C19: kom | D19: 16 | F19: =ROUND(D19*E19,2) -> 0
B20: P5A - prozor 140/168 cm | C20: kom | D20: 2 | F20: =ROUND(D20*E20,2) -> 0
B21: P6 - prozor 60/168 cm | C21: kom | D21: 8 | F21: =ROUND(D21*E21,2) -> 0
B22: P7 - prozor 60/168 cm | C22: kom | D22: 9 | F22: =ROUND(D22*E22,2) -> 0
B23: P8 - prozor 50/168 cm | C23: kom | D23: 5 | F23: =ROUND(D23*E23,2) -> 0
... B30: V1 - garažna vrata 260/205 cm + prozor 260/105 cm | C30: kom | D30: 2 | F30: =ROUND(D30*E30,2) -> 0
F31: =SUM(F12:F30) -> 0
A33: A.II.2. | B33: RUŠENJA I DEMONTAŽE UKUPNO (STANOVI): | E33: EUR | F33: =SUM(F31) -> 0

Sheet A. III. zemlj.
A2: TROŠKOVNIK GRAĐEVINSKO OBRTNIČKIH RADOVA I ELEKTRO INSTALACIJE
A3: A. GRAĐEVINSKI RADOVI / A.III. ZEMLJANI RADOVI
A4: r.b. | B4: opis stavke | C4: jed. | D4: kol. | E4: jed.cijena | F4: ukupno
A7: A.III. | B7: ZEMLJANI RADOVI
A9: OPĆI UVJETI
A11: Prije početka radova potrebno je provjeriti da li trase postojećih instalacijskih vodova na gradilištu i u blizini kolidiraju s iskopom ili radnim prostorom potrebne mehanizacije. Prije početka zemljanih radova, teren treba očistiti od šiblja i korova. Ovi radovi kao i radovi oko razmjeravanja terena i obilježavanja zgrade uračunati su u jedinične cijene.
A13: Dužnost je izvođača da utvrdi pravi sastav tla. Ukoliko izvođač prilikom iskopa zemlje naiđe na bilo kakve predmete, objekte ili instalacije, dužan je na tom mjestu obustaviti radove i o tome obavijestiti projektanta i nadzornog inženjera.
A15: Iskopani materijal treba odlagati na dovoljnom odstojanju od ruba iskopa da ne dođe do urušavanja. Podupiranja, razupiranja i zaštita iskopa od oborinskih voda prekrivanjem PVC folijama i izvedbom površinske odvodnje kanalima i muljnim crpkama, obuhvaćena su jediničnim cijenama. Potrebna građa za podupiranje mora biti pripremljena na gradilištu prije početka iskopa. Ako se iskopane jame oštete, odrone ili zatrpaju nepažnjom ili uslijed nedovoljnog podupiranja, izvođač ih dovodi u ispravno stanje bez posebne naknade. Ukoliko je izvođač otkopao tlo ispod projektom predviđene temeljne ravnine obavezan je bez naknade popuniti tako nastale šupljine betonom C 8/10, do projektirane kote. Zabranjeno je popunjavanje prekopa nasipom šljunka.
A17: Količine iskopa, transporta i nasipa zemlje obračunavaju se prema sraslom stanju tla. Iskopani materijal upotrijebiti za nasipavanje i zatrpavanje. Isti treba prevesti na gradilišni deponij, uskladištiti te poslije upotrijebiti. Višak iskopanog materijala odvesti na gradski deponij udaljen 20 km.
A19: Jedinična cijena uključuje sav rad za iskop (ručni ili strojni), potrebne razupore, podupore (osiguranje od urušavanja), sva potrebna planiranja (do točnosti ±3 cm), niveliranje i nabijanja površina, crpljenje površinske i/ili procjedne vode, rasprostiranje i oblikovanje tla (ručno ili specijalnim strojevima), utovar u kamion, prijevoz na gradilišni deponij udaljen 20 km i istovar zemlje ukoliko je to potrebno.
A21: 1. | B21: Iskop zemlje uz rub vanjskih zidova u kontaktu s terenom
B22: NAPOMENA: Sve mjere izvedbe, kao i postojeću dubinu temeljenja provjeriti na licu mjesta prije planiranja i organizacije radova. Postojeća dubina temeljenja je pretpostavljena (na osnovu arhivskih nacrta) i može odstupati od ovdje navedene.
B23: Ručni iskop dubine cca 20 cm. Iskop zemlje širine 30-70 cm uz rub vanjskog zida pročelja vrši se sa pokosom 1:2. Izvesti pažljivo kako se ne bi oštetili dijelovi postojeće konstrukcije. Izložene dijelove konstrukcije očistiti od zemlje i raslinja.
C24: m3 | D24: 50 | F24: =ROUND(D24*E24,2) -> 0
A25: 2. | B25: Nasipavanje materijala iz iskopa oko zgrade i fino poravnanje
B26: Obračun po m³ materijala u sraslom stanju.
C27: m3 | D27: 50 | F27: =ROUND(D27*E27,2) -> 0
A29: A.III. | B29: ZEMLJANI RADOVI UKUPNO: | E29: EUR | F29: =SUM(F23:F28) -> 0

Sheet A.IV.1.zid
A2: TROŠKOVNIK GRAĐEVINSKO OBRTNIČKIH RADOVA I ELEKTRO INSTALACIJE
A3: A. GRAĐEVINSKI RADOVI / A.IV.1. ZIDARSKI RADOVI (ZAJEDNIČKIH PROSTORIJA)
A4: r.b. | B4: opis stavke | C4: jed. | D4: kol. | E4: jed.cijena | F4: ukupno
A7: A.IV.1 | B7: ZIDARSKI RADOVI (ZAJEDNIČKI PROSTORI)
A9: OPĆI UVJETI
A11: Opći uvjeti su sastavni dio svake pojedine stavke. Sve što je navedeno u njima, a nije u pojedinačnom opisu stavke smatra se uključenim u jediničnu cijenu.
A13: Sve radove izvođač mora izvoditi prema troškovniku i glavnom projektu, solidno i stručno, prema pravilima dobrog zanata, Pravilniku o ocjenjivanju sukladnosti, ispravama o sukladnosti i označavanju građevinskih proizvoda (NN 103/08, 147/09, 87/10, 129/11), Pravilniku o tehničkim mjerama i uvjetima za završne radove u zgradarstvu (Sl.list br. 21/90), Tehničkim propisom za građevinske konstrukcije (NN 17/17 - uz prikladne norme HRN EN 1990 ili jednakovrijedno __________________,HRN EN 1991 ili jednakovrijedno __________________, HRN EN 1996 ili jednakovrijedno __________________, HRN EN 1997 ili jednakovrijedno __________________ i HRN EN 1998 ili jednakovrijedno __________________), Tehničkim propisom o racionalnoj uporabi energije i toplinskoj zaštiti u zgradama („Narodne novine“ broj 128/15, 70/18., 73/18.) sa pripadajućim normama, Tehničkim propisom o građevnim proizvodima (NN 35/18), te svim ostalim hrvatskim i europskim tehničkim propisima i normama i priznatim tehničkim pravilima, ili jednakovrijedno __________________, a osobito :
A14: EN 1015-7 ili jednakovrijedno __________________, zapreminska masa i poroznost svježeg morta EN 1015-3 ili jednakovrijedno __________________, konzistencija svježeg morta EN 1015-11 ili jednakovrijedno __________________, tlačna i savojna vlačna čvrstoća morta EN 771-1 ili jednakovrijedno __________________, EN 772-1 ili jednakovrijedno __________________, EN 7723 ili jednakovrijedno __________________, EN 772-13 ili jednakovrijedno __________________, EN 772-16 ili jednakovrijedno __________________, HRN EN 14063-1:2008 ili jednakovrijedno __________________, tlačna čvrstoća opeke, na mjestu primjene oblikovani proizvodi od lakoagregatne eksp. gline
A15: HRN B.C1.030 ili jednakovrijedno __________________, B.C8.030 ili jednakovrijedno __________________, građevinski gips HRN B.C1.020 ili jednakovrijedno __________________, B.C8.030 ili jednakovrijedno __________________, građevinsko vapno HRN B.C8.015,022 – 026 ili jednakovrijedno __________________, cement HRN B.C8.011 ili jednakovrijedno __________________, portland cement HRN B.C8.030 ili jednakovrijedno __________________, pijesak HRN U.M2.010 ili jednakovrijedno __________________, U.M2.012 ili jednakovrijedno __________________, mortovi HRN U.F2.010 ili jednakovrijedno __________________, tehnički normativi za izvođenje fasaderskih radova
A16: HRN EN 1008 ili jednakovrijedno __________________, HRN EN 13139;2003+AC;2006 ili jednakovrijedno __________________, voda i pijesak HRN EN 197-1:2012 ili jednakovrijedno __________________, cement HRN EN 459-1:2015 ili jednakovrijedno __________________, vapno
A18: Svi upotrebljeni materijali za izvedbu zidarskih radova moraju odgovarati navedenim propisima i normama. Izvođač mora prije izvedbe izvršiti pregled podloge te prodora u zidu prema nacrtu u prisutnosti nadzornog inženjera te upisati napomenu u građevinski dnevnik. Navedene radnje uključene su u jediničnu cijenu.
A20: Izvođač je dužan osigurati i zaštititi sve dijelove građevine na kojima se izvode radovi, radi sprečavanja oštećenja tijekom izvedbe. Sva oštećenja na dijelovima na kojima se ne izvode radovi ili koja su nastala nepažnjom izvođača isti je dužan otkloniti o vlastitom trošku.
A22: Sav rad i transport vrši se isključivo sa vanjske strane građevine, tj. preko skele. Zidarsko-fasaderski radovi se izvode na dobro očišćenoj i otprašenoj površini zida te ih treba izvoditi samo u povoljnim vremenskim uvjetima, uz odgovarajuće osiguranje i zaštitu svježe ožbukanih površina od štetnog utjecaja djelovanja sunca i oborina. Sve detalje izvedbe na pročelju potrebno je dogovoriti i na njih ishoditi suglasnost nadzornog inženjera, a prije pristupanja izvedbi radova. Obračun svih radova vršiti kako je to naznačeno u opisu stavke.
A24: Prilikom izvođenja zidova zgrada izvođač se mora pridržavati slijedećih mjera: - zidanje se mora izvoditi sa pravilnim zidarskim vezovima, a preklop mora iznositi najmanje jednu četvrtinu dužine zidnog elementa, - debljina ležajnica ne smije biti veća od 15 mm, a širina sudarnica ne smije biti manja od 10 mm niti veća od 15 mm, - ako se zida za vrijeme zime treba zidove zaštiti od mraza, - zidovi čije izvođenje nije završeno prije nastupanja zimskih mrazova moraju se zaštiti na odgovarajući način, - svako naknadno bušenje ili izrada užljebina u zidovima zgrade koje nije bilo predviđeno projektom, može se izvoditi samo ako je prethodnim statičkim proračunom utvrđeno da nosivost zida poslije tog bušenja odnosno izrade žlijeba nije manja od propisane nosivosti. - poprečni i uzdužni zidovi moraju na spoju biti međusobno povezani zidarskim vezom, tj. za pregradne zidove treba ispustiti zupce u masivnom zidu na svaki drugi red za ½ opeke. - zidove uz vertikalni serklaž također zupčasto izvesti. - vanjske fuge ostaviti prazne od 1,5 do 2 cm za vezu žbuke prigodom žbukanja zidova. - za vrijeme zidanja opeku kvasiti vodom, a pri zidanju cementnim mortom opeka mora ležati u vodi neposredno prije zidanja - reške dimnjaka i ventilacionih kanala zagladiti. - prilikom zidanja pravovremeno ostaviti otvore prema zidarskim mjerama, voditi računa o uzidavanju pojedinih građevinskih elemenata, o ostavljanju žljebova za kanalizaciju, za centralno grijanje ako su ucrtani (ne plaća se posebno, ulazi u jediničnu cijenu)
A26: Posebno se ne naplaćuje ni zatvaranje (žbukanje šliceva, žljebova i sl.) iza položene instalacije. Zazidavanje (zatvaranje) žljebova u zidovima ostavljenih za instalacije kanalizacije i grijanja nakon izvođenja tih instalacija, opekom, rabicom ili na drugi način, ne plaća se posebno, ukoliko troškovnikom nije posebno propisano. Obračun nosivih zidova, stupova i dimnjaka je zapreminski (m3), pregradnih zidova i žbuka površinski (m2).
A28: Žbukati tek kada se zidovi osuše i slegne zgrada. Ne smije se žbukati kad postoji opasnost od smrzavanja ili ekstremno visokih temperatura 30° ili više. Zidovi moraju biti prije žbukanja čisti, a fuge udubljene, da se žbuka može dobro primiti.
... A38: Jedinična cijena uključuje sve pripremne i završne radove, posredne i neposredne troškove za rad, materijal, alat, otežani rad na izvedbi, potrebni horizontalni i vertikalni transport, čišćenje tokom rada, odvoz i zbrinjavanje smeća na deponiju udaljenom 20 km, završno čišćenje prije primopredaje radova, nadoknadu eventualne štete nastale iz nepažnje na svojim ili tuđim radovima, usklađenje organizacije rada s operativnim planom, primjenu svih mjera zaštite na radu.
A40: 1. | B40: Popravci žbuke nakon ugradnje nove stolarije
B41: Stavka obuhvaća sve popravke oštećene unutarnje žbuke zidova, stropova i špaleta oko otvora koji su oštećeni prilikom izvođenja radova rušenja i demontaže fasadnih stavki, instalacija i sl, nakon ugradnje novih stolarskih stavki. Postojeću podlogu potrebno je prethodno impregnirati i obraditi reparaturnim mortom.
B42: Sve kuteve i bridove učvrstiti kutnim profilima. Sve betonske površine prethodno premazati sredstvom za povećanje prionjivosti. Sve spojeve različitih materijala potrebno je rabicirati. Kod popravaka postojeće žbuke, za zapunjavanje otvora, reški i šliceva upotrijebiti prikladan materijal (polistiren, gips ploče, opeka, porobeton ili sl.) što je uključeno u stavku.
B43: Stavkom je obuhvaćeno žbukanje površina od opeke, porobetona i od armiranog betona. Žbukanje se vrši grubom produžnom podložnom žbukom i finom žbukom. Žbuka mora biti potpuno ravna, ukupna debljina žbuke mora biti u istoj ravnini sa postojećom žbukom, a završni sloj fino zaglađen.
B44: ZP1 - prozor 360/96 cm | C44: kom | D44: 11 | F44: =ROUND(D44*E44,2) -> 0
B45: ZP2 - prozor 300/96 cm | C45: kom | D45: 4 | F45: =ROUND(D45*E45,2) -> 0
B46: ZP3 - prozor 275/168 cm | C46: kom | D46: 3 | F46: =ROUND(D46*E46,2) -> 0
B47: ZP4 - prozor 170/168 cm | C47: kom | D47: 3 | F47: =ROUND(D47*E47,2) -> 0
B48: ZP5 - prozor 300/60 cm | C48: kom | D48: 3 | F48: =ROUND(D48*E48,2) -> 0
B49: ZP6 - prozor 100/110 cm | C49: kom | D49: 1 | F49: =ROUND(D49*E49,2) -> 0
B50: ZV1 - ulazna ostakljena stijena 335/250 cm | C50: kom | D50: 2 | F50: =ROUND(D50*E50,2) -> 0
B51: ZV2 - ulazna ostakljena stijena 153,5/260 cm | C51: kom | D51: 3 | F51: =ROUND(D51*E51,2) -> 0
B52: ZV3 - ulazna stijena 271/205 cm s prozorom 271/105 cm | C52: kom | D52: 3 | F52: =ROUND(D52*E52,2) -> 0
B53: ZV4 - ostakljena vrata s nadsvjetlom 135,5/260 cm | C53: kom | D53: 35 | F53: =ROUND(D53*E53,2) -> 0
B54: ZV5 - puna vrata 100/260 cm | C54: kom | D54: 5 | F54: =ROUND(D54*E54,2) -> 0
B55: ZV6 - puna vratašca 100/140 cm | C55: kom | D55: 1 | F55: =ROUND(D55*E55,2) -> 0
F56: =SUM(F44:F55) -> 0
A58: 2. | B58: Razna zidarska pripomoć, krpanja i popravci žbuke i prodora prilikom izvođenja radova. Obračun po m2 obrađene plohe. | C58: m² | D58: =250 -> 250 | F58: =ROUND(D58*E58,2) -> 0
A60: 3. | B60: Zidanje nadvišenja nadozida ravnog krova stubišta
B61: Zidanje nadvišenja nadozida od porobetonskih blokova (ρ 400 kg/m³) debljine 16 cm, visine 25 cm. Porobetonski zid izvesti od bloka, marke 2,50/0,40 kvalitete proizvoda I. razreda zidnih elemenata s tankoslojnim mortom minimalne marke M10 kvalitete morta tipa B. Prvi red blokova potrebno je postaviti na sloj cementnog morta 1:2 debljine 2-5 cm ovisno o točnosti izvedene podloge, idealno ravan u oba smjera . Sve ostale horizontalne i vertikalne sljubnice (fuge) potrebno je ispuniti po cijeloj površini tankoslojnim mortom max. debljine 3 mm. Prilikom zidanja nije dozvoljeno preklapanje vertikalnih sljubnica. Min. razmak između vertikalnih sljubnica dva susjedna reda smije biti 10 cm. Prilikom ugradnje, prethodno pripremiti podlogu. U cijeni sav rad i materijal po uputi proizvođača do potpune gotovosti.
B62: d = 16 cm | C62: m² | D62: 27.5 | F62: =ROUND(D62*E62,2) -> 0
A64: A.IV.1. | B64: ZIDARSKI RADOVI UKUPNO (ZAJEDNIČKI PROSTORI): | E64: EUR | F64: =SUM(F56+F58+F62) -> 0

Sheet A.IV.2.zid
A2: TROŠKOVNIK GRAĐEVINSKO OBRTNIČKIH RADOVA I ELEKTRO INSTALACIJE
A3: A. GRAĐEVINSKI RADOVI / A.IV.2. ZIDARSKI RADOVI (STAMBENIH PROSTORIJA)
A4: r.b. | B4: opis stavke | C4: jed. | D4: kol. | E4: jed.cijena | F4: ukupno
A7: A.IV.2. | B7: ZIDARSKI RADOVI (STANOVI)
A10: 1.
B11: Stavka obuhvaća sve popravke oštećene unutarnje žbuke zidova, stropova i špaleta oko otvora koji su oštećeni prilikom izvođenja radova rušenja i demontaže fasadnih stavki, instalacija i sl, nakon ugradnje novih stolarskih stavki. Postojeću podlogu potrebno je prethodno impregnirati i obraditi reparaturnim mortom.
B12: Sve kuteve i bridove učvrstiti kutnim profilima. Sve betonske površine prethodno premazati sredstvom za povećanje prionjivosti. Sve spojeve različitih materijala potrebno je rabicirati. Kod popravaka postojeće žbuke, za zapunjavanje otvora, reški i šliceva upotrijebiti prikladan materijal (polistiren, gips ploče, opeka, porobeton ili sl.) što je uključeno u stavku.
B13: Stavkom je obuhvaćeno žbukanje površina od opeke i od armiranog betona. Žbukanje se vrši grubom produžnom podložnom žbukom i finom žbukom. Žbuka mora biti potpuno ravna, ukupna debljina žbuke mora biti u istoj ravnini sa postojećom žbukom, a završni sloj fino zaglađen.
B14: P1 - prozor 360/168 cm | C14: kom | D14: 17 | F14: =ROUND(D14*E14,2) -> 0
B15: P2 - prozor 347,5/168 cm | C15: kom | D15: 7 | F15: =ROUND(D15*E15,2) -> 0
B16: P3 - prozor 287,5/168 cm | C16: kom | D16: 5 | F16: =ROUND(D16*E16,2) -> 0
B17: P3a - prozor 200/168 cm | C17: kom | D17: 1 | F17: =ROUND(D17*E17,2) -> 0
B18: P3b - prozor 275/168 cm | C18: kom | D18: 1 | F18: =ROUND(D18*E18,2) -> 0
B19: P4 - prozor 275/168 cm | C19: kom | D19: 8 | F19: =ROUND(D19*E19,2) -> 0
B20: P5 - prozor 120/168 cm u zidu 33 cm | C20: kom | D20: 5 | F20: =ROUND(D20*E20,2) -> 0
B21: P5 - prozor 120/168 cm | C21: kom | D21: 16 | F21: =ROUND(D21*E21,2) -> 0
B22: P5A - prozor 140/168 cm | C22: kom | D22: 2 | F22: =ROUND(D22*E22,2) -> 0
B23: P6 - prozor 60/168 cm | C23: kom | D23: 8 | F23: =ROUND(D23*E23,2) -> 0
B24: P7 - prozor 60/168 cm | C24: kom | D24: 9 | F24: =ROUND(D24*E24,2) -> 0
B25: P8 - prozor 50/168 cm | C25: kom | D25: 5 | F25: =ROUND(D25*E25,2) -> 0
... B32: V1 - garažna vrata 260/205 cm + prozor 260/105 cm | C32: kom | D32: 2 | F32: =ROUND(D32*E32,2) -> 0
A34: 2. | B34: Razna zidarska pripomoć, krpanja i popravci žbuke i prodora prilikom izvođenja radova. Obračun po m2 obrađene plohe. | C34: m2 | D34: 50 | F34: =ROUND(D34*E34,2) -> 0
A37: A.IV.2. | B37: ZIDARSKI RADOVI UKUPNO (STANOVI): | E37: EUR | F37: =SUM(F14:F34) -> 0

Sheet A.V.izo
A2: TROŠKOVNIK GRAĐEVINSKO OBRTNIČKIH RADOVA I ELEKTRO INSTALACIJE
A3: A. GRAĐEVINSKI RADOVI / A.V. IZOLATERSKI RADOVI
A4: r.b. | B4: opis stavke | C4: jed. | D4: kol. | E4: jed.cijena | F4: ukupno
A7: A.V. | B7: IZOLATERSKI RADOVI
A9: OPĆI UVJETI
A11: Sve radove izvođač mora izvoditi prema projektu, pravilima dobrog zanata, Pravilniku o ocjenjivanju sukladnosti, ispravama o sukladnosti i označavanju građevinskih proizvoda (NN 103/08, 147/09, 87/10, 129/11), Pravilniku o tehničkim mjerama i uvjetima za završne radove u zgradarstvu (Sl.list br. 21/90), Tehničkim propisom o racionalnoj uporabi energije i toplinskoj zaštiti u zgradama(„Narodne novine“ broj 128/15, 70/18, 73/18, 86/18.) sa pripadajućim normama, Tehničkim propisom o građevnim proizvodima (NN 35/18), Tehničkim uvjetima za projektiranje i građenje zgrada - Akustika u građevinarstvu (HRN U.J6.201/89 ili jednakovrijedno __________________), te svim ostalim tehničkim propisima, priznatim tehničkim pravilima i HR normama, ili jednakovrijedno __________________.
A13: Izvođač radova mora za sve materijale koje će upotrijebiti za izvedbu izolacije pribaviti odgovarajuće dokaze o sukladnosti. Hidroizolaciju, toplinsku ili zvučnu izolaciju treba izvoditi prema specifikaciji radova i tehničkim uvjetima izvođenja.
A15: Površine na koje se polaže izolacija trebaju biti ravne i očišćene od prašine ili drugih nečistoća. Toplinsku i zvučnu izolaciju potrebno je izvesti kontinuirano bez reški kako bi se spriječili toplinski ili zvučni mostovi.
A17: Nakon izvedbe svakog sloja izolacije nadzorni organ treba izvršiti pregled, a tek nakon pozitivnog mišljenja i upisa u građevinski dnevnik može se nastaviti sa radom.
A19: Skladištenje materijala na gradilištu mora biti stručno kako bi se isključila bilo kakva mogućnost propadanja. Nepravilno i nekvalitetno izvedene radove izvođač mora na svoj trošak ukloniti i izvesti pravilno.
A21: Izvođač je dužan sve izvoditi prema uputama proizvođača, isporučitelja materijala te ovjerenih detalja. Izvođač će pristupiti izvedbi tek nakon što projektant potpisom potvrdi tehnološku razradu svih detalja. Izrada rješenja neće se posebno naplatiti već predstavlja trošak i obavezu izvođača.
A24: HIDROIZOLACIJA Sve hidroizolaterske radove treba izvesti solidno i stručno držeći se projektne dokumentacije, propisa, opisa iz troškovnika, uputa proizvođača i pravila dobrog zanata. Prije početka radova izvođač mora ustanoviti kvalitetu podloge na kojoj se izvodi izolacija i ako nije pogodna za rad mora o tome izvijestiti naručitelja radova kako bi se podloga na vrijeme popravila i pripremila za izvođenje izolacije.
A26: Sav materijal za izolaciju treba odgovarati propisima i normativima. Izolacijsku ljepenku i ostale vrste izolacijskih traka i ploča treba rezati ravno i pravokutno. Zaderani i krpani komadi ne smiju se ugrađivati. Svi preklopi moraju biti najmanje 10 cm široki i lijepljeni varenjem. Kod polaganja dvaju ili više slojeva izolacijskih traka ili ploča preklopi ne smiju ležati jedan na drugom, već moraju biti pomaknuti.
A28: Kod hidroizolacije zidova ljepenka treba na svaku stranu zida imati prihvat širine od 10 cm, koji treba spojiti s horizontalnom izolacijom podova. Površine na koje se polaže izolacija, trebaju biti posve ravne, suhe, očišćene od prašine i nečistoće i dovoljno glatke kako bi izolacija dobro prionula. Izolacija treba prilegnuti na površinu ravno, bez nabora i mjehura. U cijeni također treba uključiti obradu slojeva izolacije i izvedbu holkera uz vertikalne zidove, oko raznih prodora kroz slojeve izolacije (instalacije), kao i ugradnje završnih profila i sl.
A30: Posebnu pažnju obratiti na zaštitu od požara kod rada s vrućim bitumenskim premazima i varenim ljepenkama zbog velike zapaljivosti bitumena. U slučaju požara gasiti pijeskom ili pjenom. Gašenje vodom je opasno zbog prskanja vrelog bitumena.
A32: Svi materijali za izvedbu hidroizolaterskih radova moraju u pogledu kvalitete odgovarati HR normama ili jednakovrijedno __________________ koje propisuje Tehnički propis o građevnim proizvodima (NN 35/18), sukladno normi koja se odnosi na određeni proizvod, ili jednakovrijedno __________________, a osobito:
... A54: Sve mjere provjeriti na terenu. Ukoliko je to moguće izvršiti provjeru postojećeg stanja konstrukcije prije nuđenja. Nakon demontaže i uvida u postojeće stanje nosive konstrukcije napraviti provjeru opterećenja, izračun opterečenja uklonjenih slojeva u odnosu na slojeve novog krova mora biti odobren od strane inženjera konstrukcije. U slučaju potrebe za odstupanjem od predviđenih slojeva, isti se neće obračunavati kao dodatni rad. U cijeni predvidjeti eventualno potrebne izmjene na licu mjesta zbog specifičnosti zadatka (sanacija). Izvoditelj treba imati radnike s odgovarajućim iskustvom, obučene i ovlaštene od proizvođača materijala.
A57: 1. | B57: Izvedba toplinske i hidroizolacije ravnog neprohodnog krova
B58: NAPOMENA: Sve mjere izvedbe, kao i postojeće konstukcije provjeriti na licu mjesta prije planiranja i organizacije radova.
