Workbook
Name AUTOR: N!$D$15
Name AUTOR_ADRESA: N!$D$16
Name AUTOR_GRAD: N!$D$17
Name AUTOR_NAZIV: N!$D$15
Name AUTOR_OIB: N!$D$18
Name AUTOR_PROJEKTANT: N!$D$20
Name dadad: #REF!
Name DATUM: #REF!
Name DATUM: #REF!
Name DATUM: #REF!
Name DATUM: #REF!
Name DATUM: #REF!
Name DATUM: N!$C$43
Name INVESTITOR_ADRESA: #REF!
Name INVESTITOR_ADRESA: #REF!
Name INVESTITOR_ADRESA: #REF!
Name INVESTITOR_ADRESA: #REF!
Name INVESTITOR_ADRESA: #REF!
Name INVESTITOR_ADRESA: N!$D$8
Name INVESTITOR_NAZIV: #REF!
Name INVESTITOR_NAZIV: #REF!
Name INVESTITOR_NAZIV: #REF!
Name INVESTITOR_NAZIV: #REF!
Name INVESTITOR_NAZIV: #REF!
Name INVESTITOR_NAZIV: N!$D$7
Name INVESTITOR_OIB: #REF!
Name INVESTITOR_OIB: #REF!
Name INVESTITOR_OIB: #REF!
Name INVESTITOR_OIB: #REF!
Name INVESTITOR_OIB: #REF!
Name INVESTITOR_OIB: N!$D$9
Name OIB: N!$D$9
Name Print_Area_MI: #REF!
Name Print_Area_MI: #REF!
Name Print_Area_MI: #REF!
Name Print_Area_MI: #REF!
Name Print_Area_MI: #REF!
Name PROJEKT_LOKACIJA: #REF!
Name PROJEKT_LOKACIJA: #REF!
Name PROJEKT_LOKACIJA: #REF!
Name PROJEKT_LOKACIJA: #REF!
Name PROJEKT_LOKACIJA: #REF!
Name PROJEKT_LOKACIJA: N!$D$13
Name PROJEKT_NAZIV: #REF!
Name PROJEKT_NAZIV: #REF!
Name PROJEKT_NAZIV: #REF!
Name PROJEKT_NAZIV: #REF!
Name PROJEKT_NAZIV: #REF!
Name PROJEKT_NAZIV: N!$D$11
Name PROJEKT_ZOP: #REF!
Name PROJEKT_ZOP: #REF!
Name PROJEKT_ZOP: #REF!
Name PROJEKT_ZOP: #REF!
Name PROJEKT_ZOP: #REF!
Name PROJEKT_ZOP: N!#REF!

Sheet N
C7: Investitor: | D7: Suvlasnici stambene zgrade
C11: Građevina: | D11: Stambena zgrada - obnova fasade i stubišnog prostora
C13: Lokacija: | D13: Tratinska 13, 10000 Zagreb
C15: Autor: | D15: NFO d.o.o.
D16: Ksaver 152
D17: 10000 Zagreb
D18: OIB:19590727564
C20: Glavni projektant: | D20: Nenad Ravnić, dipl.ing.arh.
C22: Dokument: | D22: TROŠKOVNIK
C43: Zagreb, studeni 2025.

Sheet R
B2: RB | C2: Opis stavke | D2: UKUPNO
C4: REKAPITULACIJA
B6: ='S.0.'!B4 -> S. | C6: ='S.0.'!C4 -> STUBIŠTE
B7: ='S.1.PRIPREMNI'!B12 -> S.1. | C7: ='S.1.PRIPREMNI'!C12 -> PRIPREMNI I ZAVRŠNI RADOVI | D7: ='S.1.PRIPREMNI'!G64 -> 8340
B8: ='S.2.ZIDARSKI'!B6 -> S.2. | C8: ='S.2.ZIDARSKI'!C6 -> ZIDARSKI RADOVI | D8: ='S.2.ZIDARSKI'!G71 -> 9760
B9: ='S.3.LIČILAČKI'!B8 -> S.3. | C9: ='S.3.LIČILAČKI'!C8 -> LIČILAČKI RADOVI | D9: ='S.3.LIČILAČKI'!G151 -> 17740
B10: ='S.4.STOLARSKI'!B8 -> S.4. | C10: ='S.4.STOLARSKI'!C8 -> STOLARSKI RADOVI | D10: ='S.4.STOLARSKI'!G20 -> 2000
B11: =B6 -> S. | C11: =C6&" UKUPNO" -> STUBIŠTE UKUPNO | D11: =SUM(D7:D10) -> 37840
B13: ='F.0.'!B4 -> F. | C13: ='F.0.'!C4 -> FASADA
B14: ='F.1.PRIPREMNI'!B6 -> F.1. | C14: ='F.1.PRIPREMNI'!C6 -> PRIPREMNI I ZAVRŠNI RADOVI | D14: ='F.1.PRIPREMNI'!G46 -> 0
B15: ='F.2.FASADERSKI'!B8 -> F.2. | C15: ='F.2.FASADERSKI'!C8 -> FASADERSKI RADOVI | D15: ='F.2.FASADERSKI'!G46 -> 4530
B16: ='F.3.STOLARSKI'!B6 -> F.3. | C16: ='F.3.STOLARSKI'!C6 -> STOLARSKI RADOVI | D16: ='F.3.STOLARSKI'!G18 -> 2000
B17: =B13 -> F. | C17: =C13&" UKUPNO" -> FASADA UKUPNO | D17: =SUM(D13:D16) -> 6530
C19: UKUPNO | D19: =D11+D17 -> 44370

Sheet A.0.
C2: =PROJEKT_NAZIV -> Stambena zgrada - obnova fasade i stubišnog prostora
B4: A. | C4: OPĆI TEHNIČKI UVJETI
B5: =B4&"0." -> A.0. | C5: NASLOVNICA
C9: Investitor: | D9: =INVESTITOR_NAZIV -> Suvlasnici stambene zgrade
C13: Građevina: | D13: =PROJEKT_NAZIV -> Stambena zgrada - obnova fasade i stubišnog prostora
C15: Lokacija: | D15: =PROJEKT_LOKACIJA -> Tratinska 13, 10000 Zagreb
C18: Dio: | D18: ARHITEKTURA I KONSTRUKCIJA
C26: Izrađivač:
C27: =AUTOR_NAZIV -> NFO d.o.o.
C28: =AUTOR_ADRESA -> Ksaver 152
C29: =AUTOR_GRAD -> 10000 Zagreb
C33: Projektant:
C34: =AUTOR_PROJEKTANT -> Nenad Ravnić, dipl.ing.arh.
C44: =DATUM -> Zagreb, studeni 2025.

Sheet A.1.PRIPREMNI
B2: RB | C2: OPIS STAVKE | D2: JEDINIČNA MJERA | E2: OBRAČUN KOLIČINA | F2: JEDINIČNA CIJENA | G2: UKUPNA CIJENA | H2: NAPOMENE
B4: ='A.0.'!B4 -> A. | C4: ='A.0.'!C4 -> OPĆI TEHNIČKI UVJETI
C6: PRIPREMNI I ZAVRŠNI RADOVI
C8: Pripremnim radovima mora se prići s velikim oprezom, sa svim potrebnim osiguranjima i mjerama zaštite okoliša i štetnog utjecaja na susjedne objekte. Sve radove treba izvesti uz obveznu primjenu važećih propisa zaštite na radu za ovu vrstu radova.
C9: Prije početka radova potrebno je provjeriti i u slučaju potrebe i isključiti sve instalacije unutar zone obuhvata gdje se radovi obavljaju: plin, vodu, struju, kanalizaciju od strane ovlaštenih službi. Isključenje instalacija evidentira se građevinskim dnevnikom. Eventualni trošak ovih radova treba uključiti u ukupnu ponudu jer se neće zasebno obračunavati.
C10: Dobava, doprema i montaža gradilišnih kontejnera sa svom pripadajućom opremom, montažnih WC-ova za radnike i ostalih potrebnih pomoćnih privremenih objekata (spremišta materijala i mehanizacije i slično), uključivo potrebni priključci instalacija, te po završetku radova demontaža i odvoz istih također uključena u cijenu.
C12: OSIGURANJE GRAĐEVINE I TEHNIČKA ZAŠTITA
C13: Prije početka izvođenja radova izvođač je dužan osigurati objekt, odnosno zonu zahvata, dok će investitor prijaviti početak građenja te o tome dati izvođaču pismeni dokaz. Tijekom građenja izvođač je dužan održavati sigurnost gradilišta od provale i krađe.
C15: ČIŠĆENJE TERENA
C16: Radove izvoditi uz primjenu higijensko-tehničkih zaštitnih mjera propisanih u važećoj zakonskoj regulativi, bez nanošenja štete susjednim objektima, posjedima uz trasu i imovini uopće.
C17: Generalno početno i završno čišćenje iskazani su u zasebnim stavkama. Svo ostalo čišćenje gradilišta (građevine i ostalog prostora zahvata) tijekom izvođenja radova uključeno je u cijene stavaka i neće se posebno obračunavati.
C18: Čišćenje tijekom izvođenja radova izvoditi sukladno uputama proizvođača za određenu vrstu radova, osobito važno zbog zaštite osjetljivijih materijala (npr. podne obloge, boje i slično), te treba posvetiti posebnu pažnju zaštiti i očuvanju istih. Svako oštećenje nastalo prilikom čišćenja gradilišta izvođač je dužan sanirati o svom trošku.
C20: ORGANIZACIJA GRADILIŠTA
C21: Obveza izvođača je čuvanje i održavanje gradilišta.
... C37: Obračun radova vršit će se prema opisu troškovničke stavke, uvažavajući sve odredbe iz gore navedenih uvjeta za predmetnu grupu radova.

Sheet A.2.ZIDARSKI
B2: RB | C2: OPIS STAVKE | D2: JEDINIČNA MJERA | E2: OBRAČUN KOLIČINA | F2: JEDINIČNA CIJENA | G2: UKUPNA CIJENA | H2: NAPOMENE
B4: ='A.0.'!B4 -> A. | C4: ='A.0.'!C4 -> OPĆI TEHNIČKI UVJETI
C6: ZIDARSKI RADOVI
C8: NORMATIVI I PROPISI
C9: Za projektiranje zidanih konstrukcija primjenjuje se:
C10: HRN EN 1990 | D10: ili jednakovrijedno:
C11: HRN EN 1996 | D11: ili jednakovrijedno:
C12: s pripadajućim nacionalnim dodacima te norme na koje ove norme upućuju.
C14: Prilikom izvedbe zidarsko-fasaderskih radova i za korištenje materijala opisanih u troškovniku izvođač radova mora se pridržavati uvjeta i opisa iz projektne dokumentacije kao i važećih propisa i normi na koje tehnički propisi upućuju te vezanih normi:
C16: Građevno vapno:
C17: HRN EN 459-1:2015 | D17: ili jednakovrijedno:
C19: Žbuke:
C20: HRN EN 998-1: 2016 | D20: ili jednakovrijedno:
C22: Pomoćni dijelovi ziđa:
C23: HRN EN 845-1:2016 | D23: ili jednakovrijedno:
C24: HRN EN 845-2:2016 | D24: ili jednakovrijedno:
C25: HRN EN 845-3:2016 | D25: ili jednakovrijedno:
C27: Dodaci mortu za zidanje:
C28: HRN EN 934-3:2012 | D28: ili jednakovrijedno:
C30: Estrih:
C31: HRN EN 13813:2003 | D31: ili jednakovrijedno:
C33: KVALITETA IZVEDBE RADOVA
C35: Žbukanje
C36: Pijesak za žbukanje mora biti čist od organskih primjesa, oštar i prosijan, a vapno hidratizirano.
C37: Žbukanje zidova, stropova te stupova vršiti u pogodno vrijeme, kad su isti potpuno suhi. Po velikoj zimi i vrućini treba izbjegavati žbukanje, jer tada može doći do smrzavanja odnosno pucanja uslijed prebrzog sušenja.
C38: Prije žbukanja treba plohe dobro očistiti, a naročito spojnice koje moraju biti udubljene cca 2 cm od plohe zida. Prije početka žbukanja plohe dobro navlažiti, a naročito kad se žbuka sa cementnim mortom. Betonske i armirano betonske dijelove prije žbukanja treba poprskati sa rijetkim cementnim mortom. Isto vrijedi za fasadne plohe koje se žbukaju.
C39: Finu žbuku izraditi tako, da površina bude posve ravna i glatka, a uglove i bridove, te spojeve zida i stropa izvesti oštro, ukoliko u troškovniku nije drugačije označeno. Na svim bridovima koji se žbukaju produžnom žbukom ugrađuju se kutni štitnici od aluminija, na vanjskoj žbuci od nehrđajućeg čelika, koji su uključeni u jediničnu cijenu.
C40: Staklene mrežice koje se rabe u graditeljstvu moraju zadovoljavati uvjete propisane Tehničkim propisom o građevnim proizvodima ( prilog II.)
C41: Strojno žbukanje gips-vapnenom žbukom:
C42: Kod strojnog žbukanja prskanjem nanosi se samo jedan sloj žbuke ukupne debljine cca 1,5 cm. Da bi se postigla ravna površina ožbukanih zidova potrebno je predhodno na zid pričvrstiti vodilice i kutnike za bridove od pocinčanog lima, koji ujedno služe za formiranje ravnih i pravilnih bridova. Vodilice i kutni profili uključeni su u jediničnu cijenu žbukanja zidova.
C43: Nepropisno ožbukani zidovi i stropovi moraju se ispraviti bez prava naplate.
C44: Betonske plohe moraju prije žbukanja biti obrađene tako da se žbuka dobro prihvati na betonsku površinu.
C46: Napomena: izvođač je dužan osigurati izvođenje na način da ugrađeni materijal bude trajan i otporan te po svemu u skladu s normama i tehničkim propisima. Svi potrebni kutni profili u žbuci za zaštitu od otkrhavanja i lomova, odnosno ojačanje bridova žbukanih ploha, uključeni su u cijenu stavaka žbukanja.
... C79: Gletanje i ličenje iskazani zasebno u ličilačkim radovima.

Sheet A.3.LIČILAČKI
B2: RB | C2: OPIS STAVKE | D2: JEDINIČNA MJERA | E2: OBRAČUN KOLIČINA | F2: JEDINIČNA CIJENA | G2: UKUPNA CIJENA | H2: NAPOMENE
B4: ='A.0.'!B4 -> A. | C4: ='A.0.'!C4 -> OPĆI TEHNIČKI UVJETI
C6: LIČILAČKI RADOVI
C8: NORMATIVI I PROPISI:
C9: Prilikom izvedbe soboslikarsko - ličilačkih radova te za korištenje i ispitivanje materijala opisanih u troškovniku izvođač radova mora se pridržavati uvjeta i opisa iz projektne dokumentacije kao i važećih propisa i normama na koje tehnički propisi i norme upućuju.
C11: KVALITETA IZVEDBE RADOVA
C13: Ličenje žbukanih/gletanih/GK podloga
C14: Ukoliko na zidovima i ostalim površinama koje se boje ima nekih značajnih pogrešaka, koje bi kvarile kvalitetu nakon izvršenog soboslikarskog rada, soboslikar je dužan upozoriti na pogreške voditelja građevinskih radova, da se odstrane prije bojenja.
C15: Podloga mora biti čvrsta i čista (bez masnih mrlja i druge prljavštine, bez slabo vezanih dijelova, praha te drugih nečistoća) nosiva, suha, nesmrznuta, te prije prvog bojanja impregnirana impregnacijom. Prije dodavanja vode boju treba dobro promiješati. Po prekidu rada ambalažu s bojom dobro zatvoriti, a nakon ličenja pribor oprati vodom.
C16: Kod napada gljivica potrebno je izvršiti specijalno temeljito čišćenje te naknadnu obradu odgovarajućim sredstvom. Odstraniti postojeće slojeve boja ili obloga, nepričvršćene i trusne dijelove te nenosive slojeve i očistiti površinu strojno ili odgovarajućim sredstvima.
C17: Prilikom primjene i sušenja temperatura podloge i zraka ne smije biti niža od +5°C ni viša od +30°C.
C18: Starost podložnih žbuka najmanje 3-4 tjedna. Starost masa za izravnavanje najmanje 14 dana. Gipskartonske, nove i nejednoliko upojne podloge obavezno impregnirati.
C19: Osnovni premazi moraju se tako odabrati da su podesni za slijedeće premaze koji se predviđaju.
C20: Probni premazi moraju se po želji investitora izvesti za sve vrste premaza.
... C36: Prionljivost boje na površinu potrebno je kontrolirati u skladu sa:
C37: HRN EN ISO 4624:2016 | D37: ili jednakovrijedno:
C39: ODRŽAVANJE I PREGLEDI RADOVA
C40: Pregledi i održavanje soboslikarskih i ličilačkih radova izvode se sukladno Tehničkom propisu za građevinske konstrukcije i Pravilnikom o održavanju građevina ili u razmacima i na način određen projektom građevine i pisanom izjavom izvođača o izvedenim radovima i o uvjetima održavanja građevine.
C42: Ukoliko nije drugačije iskazano stavkom, sve obračunske količine odnose se na netto veličine ugrađenog materijala, odnosno proizvoda (m3, m2, m1, ...). Sva povećanja količine rada, odnosno materijala zbog izvedbe otvora i prodora i slično izvođač je dužan uvrstiti u jediničnu cijenu stavke.
C44: Odbitak otvora i obračun špaleta: količine se NE računaju prema normi već su mjerodavne NETTO ugrađene mjere:
C45: - za plohu se kao mjerodavna količina računa netto površina elementa (zid, strop), svi otvori su odbijeni, špalete su iskazane zasebno
C46: - za špalete se kao mjerodavna količina računa netto duljina obrađene špalete, razdvojeno po širini, odnosno po razredima širine (od - do cm)
C48: GLETANJE UNUTARNJIH PROSTORA
C50: ZIDOVI I STUPOVI: Dobava, doprema materijala i gletanje AB, opečnih i porobetonskih te žbukanih zidova i stupova.
C51: STROPOVI I GREDE: Dobava, doprema materijala i gletanje podgleda AB ravnih i kosih stropnih ploča te žbukanih podgleda.
C52: Gletanje GK zidova i stropova uključeno je u stavke suhomontažnih radova, kako je raspisano tim stavkama.
C53: U stavke je uključena sva potrebna obrada isturenih bridova kako bi se postigao ravan i čvrst rub, uključivo mrežice, kutne šine i ostali pomoćni i spojni materijal.
C54: Sve podloge prije nanošenja mase moraju biti čiste, čvrste, suhe, nesmrznute, bez masnih i drugih nečistoća, pukotina i drugih oštećenja, temeljito otprašene. Ukoliko podloga ne zadovoljava svojstvima, izvođač je obavezan obavijestiti o nedostacima u najkraćem roku. Izvođenje ličilačkih radova nije dopušteno dok se podloga ne dovede u ispravno stanje.
... C74: Upotrijebiti boju niskog sadržaja lako hlapivih organskih tvari, koja ne sadrži omekšivače ni teške metale. Film boje mora biti dobro paropropustan te otporan na suho trljanje.
C76: Tehnički podaci: | D76: DIN EN 13300 ili jednakovrijedno: ____
C77: Gustoća [kg/dm3]: cca 1.45 - 1.50
C78: Sadžaj HOS (VOC): < 1 (zahtjev kategorija A/a <30)
C79: Otpornost na mokro čišćenje: razred 2 (mat, otporno na ribanje)
C80: Pokrivnost: razred 2 pri izdašnosti 7-8 m2/L
C81: Veličina zrna: fina (< 90-100 μm)
C82: Izgled: mat
C84: Vrijednost Sd: <0.08-0.1 (razred I, visoka paropropusnost) | D84: EN 12572 ili jednakovrijedno: ____
C86: BOJA ZA JAČE OPTEREĆENE PROSTORE - TIP B
C87: Dobava materijala i ličenje unutarnjom bojom na osnovi vodene disperzije specijalnih polimernih veziva.
C88: Upotrijebiti boju niskog sadržaja lako hlapivih organskih tvari, koja ne sadrži omekšivače ni teške metale. Film boje mora biti dobro paropropustan i otporan na mokro trljanje tako da je moguće ne pretjerano prihvaćeno zaprljanje prebojanih površina obrisati krpom namočenom u otopinu univerzalnih sredstava za čišćenje.
...

Sheet A.4.FASADERSKI
B2: RB | C2: OPIS STAVKE | D2: JEDINIČNA MJERA | E2: OBRAČUN KOLIČINA | F2: JEDINIČNA CIJENA | G2: UKUPNA CIJENA | H2: NAPOMENE
B4: ='A.0.'!B4 -> A. | C4: ='A.0.'!C4 -> OPĆI TEHNIČKI UVJETI
C6: FASADERSKI RADOVI
C8: Kod izrade bilo kojeg sustava fasade potrebno je koristiti sistemske komponente i sistemska rješenja prema uputama proizvođača. Fasada se u skladu sa propisima izvodi u sistemu jednog proizvođača fasadnog sustava što se dokazuje pripadajućom izjavom o svojstvima za odabrani fasadni sustav. Nije dozvoljeno miješanje komponenti sustava različitih proizvođača izvan odabranog sustava. Izvođač je dužan u jediničnu cijenu uključiti sve potrebne profile za kvalitetno izvođenje radova na fasadi (okapni i kutni profil, završetak podnožja fasade i sl.). Sve komponente moraju ispunjavati projektne zahtjeve u vidu koeficijenta toplinske provodlijivosti. Uz pravilno korištenje i ugradbu materijala izvođač je dužan pridržavati se svih važećih propisa za izvođenje fasadnih sustava i smjernica za izvedbu istih.
C9: Izvođač je dužan ostvariti zadovoljavajući estetski izgled fasade, u protivnom je isto dužan sanirati o svom trošku. Naknadno izravnavanje izvedenog fasadnog sustava nije dozvoljeno.
C10: Prije početka radova na izvedbi fasade klupčice, metalne dijelove, drvo i staklo Izvođač je dužan zaštititi, što je iskazano stavkom.
C12: Fasadna skela potrebne visine ulazi u jedinične cijene stavaka i ne naplaćuje se posebno. Skela mora biti na vrijeme postavljena.
C14: Fasada za primopredaju mora biti u cijelosti čista, bez ostataka građevinskih materijala i drugih zaprljanja.
C15: Čišćenje se mora izvršavati sukladno uputama proizvođača za odabrane fasadne sustave. Ukoliko čišćenjem nije moguće otkloniti nedostatke, izvođač je iste dužan otkloniti o svom trošku.
C17: Ukoliko nije drugačije iskazano stavkom, sve obračunske količine odnose se na netto veličine ugrađenog materijala, odnosno proizvoda (m3, m2, m1, ...). Sva povećanja količine rada, odnosno materijala zbog izvedbe otvora i prodora i slično izvođač je dužan uvrstiti u jediničnu cijenu stavke.
C19: Odbitak otvora i obračun špaleta: količine se NE računaju prema normi već su mjerodavne NETTO ugrađene mjere:
C20: - za plohu se kao mjerodavna količina računa netto obrađena površina, svi otvori su odbijeni, špalete su iskazane zasebno
C21: - za špalete se kao mjerodavna količina računa netto duljina obrađene špalete, razdvojeno po širini, odnosno po razredima širine (od - do cm)

Sheet A.5.STOLARSKI
B2: RB | C2: OPIS STAVKE | D2: JEDINIČNA MJERA | E2: OBRAČUN KOLIČINA | F2: JEDINIČNA CIJENA | G2: UKUPNA CIJENA | H2: NAPOMENE
B4: ='A.0.'!B4 -> A. | C4: ='A.0.'!C4 -> OPĆI TEHNIČKI UVJETI
C6: STOLARSKI RADOVI
C8: NORMATIVI I PROPISI
C9: Prilikom izvedbe stolarskih radova te za korištenje i ispitivanje materijala opisanih u troškovniku izvođač radova mora se pridržavati uvjeta i opisa iz projektne dokumentacije kao i važećih propisa i normama na koje tehnički propisi upućuju.
C11: KVALITETA IZVEDBE RADOVA
C12: Izvođač je dužan provjeriti sve dimenzije na licu mjesta, bilo kakva pogreška, propust ili neslaganja između nacrta arhitekture i eventualnih dodatnih nacrta i projektnih detalja moraju se prijaviti voditelju projekta, nadzornom inženjeru i projektantu.
C13: U slučaju neslaganja između nacrta, mjerodavan je detaljniji nacrt.
C15: RADIONIČKA DOKUMENTACIJA
C16: Prije početka izvedbe stolarskih elemenata sve potrebne radioničke nacrte izrađuje izvođač stolarskih radova te s predloženim okovom dostavlja ih na usuglašavanje projektantu-investitoru.
C17: Svi detalji potrebni za radionički nacrt dogovaraju se s glavnim projektantom, a ugradnja slijedi nakon što projektant odobri radioničke nacrte, a izvođač točno provjeri sve dimenzije na licu mjesta.
C18: Svi pripremni radionički nacrti izvođača moraju se predati projektantu na odobrenje prije izrade stavke.
C19: Za svaki element je potrebno izraditi uzorak u detaljnom mjerilu, kojega odobrava projektant prije narudžbe materijala.
C20: Na zahtjev projektanta ili odgovorne osobe izvođač je dužan testirati određene detalje sa prototipovima, a prije same izvedbe.
... C42: Obračun radova vršit će se prema opisu troškovničke stavke.

Sheet S.0.
C2: =PROJEKT_NAZIV -> Stambena zgrada - obnova fasade i stubišnog prostora
B4: S. | C4: STUBIŠTE
B5: =B4&"0." -> S.0. | C5: NASLOVNICA
C9: Investitor: | D9: =INVESTITOR_NAZIV -> Suvlasnici stambene zgrade
C13: Građevina: | D13: =PROJEKT_NAZIV -> Stambena zgrada - obnova fasade i stubišnog prostora
C15: Lokacija: | D15: =PROJEKT_LOKACIJA -> Tratinska 13, 10000 Zagreb
C18: Dio: | D18: ARHITEKTURA I KONSTRUKCIJA
C26: Izrađivač:
C27: =AUTOR_NAZIV -> NFO d.o.o.
C28: =AUTOR_ADRESA -> Ksaver 152
C29: =AUTOR_GRAD -> 10000 Zagreb
C33: Projektant:
C34: =AUTOR_PROJEKTANT -> Nenad Ravnić, dipl.ing.arh.
C44: =DATUM -> Zagreb, studeni 2025.

Sheet S.1.PRIPREMNI
B2: RB | C2: OPIS STAVKE | D2: JEDINIČNA MJERA | E2: OBRAČUN KOLIČINA | F2: JEDINIČNA CIJENA | G2: UKUPNA CIJENA | H2: NAPOMENE
B4: ='S.0.'!B4 -> S. | C4: ='S.0.'!C4 -> STUBIŠTE
C6: NAPOMENA: skela uključena u cijene pripadajućih radova za koje se koristi.
C8: NAPOMENA: u sve cijene troškovničkih stavaka uključeno grubo čišćenje tijekom trajanja radova
C9: Sa svih površina potrebno je ukloniti šutu i građevinski otpad, smeće, ... te prostor držati urednim kako bi ga korisnici zgrade mogli uporabljivati.
C10: U stavku uključeno redovito čišćenje stuba, ulaza u stanove, uličnog i dvorišnog ulaza u zgradu, ... kako bi predmetne zone ostale pristupačne.
B12: =B4&"1." -> S.1. | C12: PRIPREMNI I ZAVRŠNI RADOVI
B14: =$B$12&COUNTA($B$12:INDEX(B:B,ROW()-1)) -> S.1.1 | C14: Zaštita postojećih građevinskih elemenata
C16: Zaštita svih horizontalnih i vertikalnih površina te elemenata unutar stubišta od oštećenja: stube, podesti, ograda, rukohvat, vrata, prozor, instalacije, ...
C17: Za svaki element primjeniti adekvatnu zaštitu sukladno radovima koji se izvode: valoviti karton, folija, platno, ... ili slično.
C18: Za elemente uz koje se neposredno izvode radovi - vrata, instalacije, ... - zaštitu izvesti tako da omogući izvedbu, npr. rabiciranje prijelaza i slično.
C19: U stavku uključeno održavanje zaštite te uklanjanje zaštite nakon izvedenih radova, kao i odvoz i eventualno deponiranje zaštitnih elemenata.
C21: Obračun za komplet | D21: komplet | E21: 1 | F21: 2000 | G21: =IF(ISNUMBER(F21),ROUND(E21*ROUND(F21,2),2),"") -> 2000
B23: =$B$12&COUNTA($B$12:INDEX(B:B,ROW()-1)) -> S.1.2 | C23: OPCIJA: Demontaža elemenata u stubištu
C25: Izvlačenje elemenata u svrhu izvedbe kontinuirane plohe.
C26: U stavku uključeno privremeno skladištenje na lokaciji elemenata koji se demontiraju, zaštita instalacije i elemenata koji se samo izvlače za vrijeme trajanja radova, te ponovna montaža nakon izvedbe radova.
C27: Potrebno je primjeniti povećanu pažnju prilikom uklanjanja i zaštite instalacija kako se ne bi tijekom izvedbe narušila funkcija.
C28: Prethodno radu na instalacijama izvršiti nadzor nad stanjem istih kako bi se utvrdili mogućnosti i načini izvlačenja te, po potrebi nadzor nadležnih službi i isporučitelja usluge u čijem su instalacije vlasništvu (HEP, HT, ...).
C29: Prethodno izvođenju stavke izvlačenja ormara provjeriti je li isto moguće zbog duljine pripadajućih kabela. Ako nije, anulirati odgovarajuću stavku.
C31: 1) poštanski ormarići (18 kom) | D31: komplet | E31: 1 | F31: 120 | G31: =IF(ISNUMBER(F31),ROUND(E31*ROUND(F31,2),2),"") -> 120
C32: 2) vratašca zidnog ormarića cca 40x40 | D32: kom | E32: 1 | F32: 30 | G32: =IF(ISNUMBER(F32),ROUND(E32*ROUND(F32,2),2),"") -> 30
C33: 3) stropna rasvjetna tijela | D33: kom | E33: 10 | F33: 45 | G33: =IF(ISNUMBER(F33),ROUND(E33*ROUND(F33,2),2),"") -> 450
C34: 4) zidna elektrooprema (pretežno sklopke) | D34: kom | E34: 20 | F34: 45 | G34: =IF(ISNUMBER(F34),ROUND(E34*ROUND(F34,2),2),"") -> 900
C35: 5) razvodne kutije | D35: kom | E35: 20 | F35: 45 | G35: =IF(ISNUMBER(F35),ROUND(E35*ROUND(F35,2),2),"") -> 900
C36: 6) kanalice slabe struje | D36: m1 | E36: 70 | F36: 1 | G36: =IF(ISNUMBER(F36),ROUND(E36*ROUND(F36,2),2),"") -> 70
C37: 7) nadgradni ormari slabe struje | D37: kom | E37: 2 | F37: 150 | G37: =IF(ISNUMBER(F37),ROUND(E37*ROUND(F37,2),2),"") -> 300
C38: 8) ugradbeni ormari jake struje | D38: kom | E38: 2 | F38: 150 | G38: =IF(ISNUMBER(F38),ROUND(E38*ROUND(F38,2),2),"") -> 300
B40: =$B$12&COUNTA($B$12:INDEX(B:B,ROW()-1)) -> S.1.3 | C40: OPCIJA: Podžbukna ugradnja instalacije slabe struje
C42: NAPOMENA: SAMO ukoliko se demontiraju kanalice i nadgradni ormari slabe struje u stubišnom prostoru. Uskladiti radove s otucanjem žbuke!
C43: U stavku uključeno šlicanje nosive konstrukcije u potrebnoj dimenziji za izvedbu instalacije te svo potrebno krpanje nakon ugradnje instalacije.
C44: Budući da se instalacija ne odspaja, postojeći kabeli se polažu u podžbukne kanalice, odnosno cijevi s prorezom koje štite instalaciju
C45: Ukoliko se stavka izvodi nužno je prethodno ishoditi potvrdu od pružatelja usluge (vlasnika infrastukture) koja se vrši putem predmetne instalacije.
C47: Obračun po m1 duljine instalacije koja se ugrađuje podžbukno. | D47: m1 | E47: 70 | F47: 20 | G47: =IF(ISNUMBER(F47),ROUND(E47*ROUND(F47,2),2),"") -> 1400
B49: =$B$12&COUNTA($B$12:INDEX(B:B,ROW()-1)) -> S.1.4 | C49: Ispitivanje podloge kao priprema za žbukanje
C51: Ispitivanje podloge zidova i stropova radi otkrivanja loše žbuke.
C52: U stavku uključeno sondiranje elemenata kako bi se utvrdila vrsta ugrađene žbuke te konačna količina žbuke koju je potrebno ukloniti u svrhu postizanja kvalitetne, čvrste i trajne plohe zida, odnosno stropa.
C53: U stavku uključena zaštita svih okolnih elemenata od oštećenja ukoliko nisu već adekvatno zaštićeni izvođenjem prethodne stavke.
C55: Obračun za komplet | D55: komplet | E55: 10 | F55: 110 | G55: =IF(ISNUMBER(F55),ROUND(E55*ROUND(F55,2),2),"") -> 1100
B57: =$B$12&COUNTA($B$12:INDEX(B:B,ROW()-1)) -> S.1.5 | C57: Završno čišćenje obuhvata za primopredaju i odvoz
C59: Stavka uključuje završno fino čišćenje kao pripremu za primopredaju, uključivo sva gruba i fina čišćenja prostora stubišta, skupljanje te završni odvoz uklonjenog materijala i deponiranje, uključivo takse deponije.
...

Sheet S.2.ZIDARSKI
B2: RB | C2: OPIS STAVKE | D2: JEDINIČNA MJERA | E2: OBRAČUN KOLIČINA | F2: JEDINIČNA CIJENA | G2: UKUPNA CIJENA | H2: NAPOMENE
B4: ='S.0.'!B4 -> S. | C4: ='S.0.'!C4 -> STUBIŠTE
B6: =B4&"2." -> S.2. | C6: ZIDARSKI RADOVI
C8: NAPOMENA: skela uključena u cijene pripadajućih radova za koje se koristi.
B10: =$B$6&COUNTA($B$6:INDEX(B:B,ROW()-1)) -> S.2.1 | C10: OTUCANJE STARE I TROŠNE ŽBUKE
C12: Uklanjanje stare i trošne žbuke sa zidova i stropova do nosive konstrukcije.
C13: U stavku uključeni svi potrebni radovi skidanja, otucanja i šlicanja kako bi se ploha dovela u stanje pripravno za izvođenje nove žbuke.
C14: Uskladiti radove s izvođenjem zaštite elemenata koji se zadržavaju!
C15: Skupljanje, odvoz i deponiranje šute, smeća i drugog otpada nastalog ovim radovima iskazan u pripremnim radovima.
C17: 1) otucanje s plohe | D17: m2 | E17: 130 | F17: 15 | G17: =IF(ISNUMBER(F17),ROUND(E17*ROUND(F17,2),2),"") -> 1950
C18: Obračun po m2 površine elementa koji se obrađuje.
C20: U stavku je uključeno npr:
C21: 1.1) unutarnji zidovi
C22: 1.2) unutarnji stropovi i grede
C23: 1.3) kosi podgled stubišta
C24: Uključivo naknada za otežan rad (postavljanje pokretne skele na stube, rad na visini u zoni otvorenog ruba stubišta, postavljanje skele uz ogradu, ...).
C26: 2) špalete i bridovi | D26: m1 | E26: 70 | F26: 8 | G26: =IF(ISNUMBER(F26),ROUND(E26*ROUND(F26,2),2),"") -> 560
C27: Obračun po m1 duljine elementa koji se obrađuje.
C29: Stavka se odnosi pretežno na špalete otvora, isturene bridove greda i rubove ploča, otvoreni rub stubišta i slične istake.
C30: U stavku uključena primjena povećane pažnje kako se okolni dijelovi ne bi oštetili prilikom izvođenja radova.
C32: U stavku je uključeno npr:
C33: 2.1) špaleta prozora
C34: 2.2) rub prema vratima
C35: 2.3) rub prema kamenoj oblozi zida
C36: 2.4) otvoreni rub ploče podesta
C37: 2.5) otvoreni rub stubišta
C38: 2.6) bridovi stropnih greda
B40: =$B$6&COUNTA($B$6:INDEX(B:B,ROW()-1)) -> S.2.2 | C40: ŽBUKANJE - AB I ZIDANI ZIDOVI I STROPOVI
C42: Dobava materijala i žbukanje ploha AB i zidanih zidova i stropova VC podložnom i finom žbukom.
C43: Žbuka se nanosi na zidove i stropove u sloju debljine ukupno cca 20 mm te se obrađuju bridovi i rubovi.
C44: U stavku uključen odgovarajući predšpric prema uputi proizvođača žbuke.
C45: Alternativno, ovisno o rezultatima sondiranja žbukanih zidova, dopušta se žbukanje GV žbukom ukoliko će se upotrebom iste ostvariti kvalitetniji spoj s postojećim elementima.
C47: 1) žbukanje plohe | D47: m2 | E47: 130 | F47: 45 | G47: =IF(ISNUMBER(F47),ROUND(E47*ROUND(F47,2),2),"") -> 5850
C48: Obračun po m2 površine ožbukanog elementa.
C50: U stavku je uključeno npr:
C51: 1.1) unutarnji zidovi
C52: 1.2) unutarnji stropovi i grede
C53: 1.3) kosi podgled stubišta
C54: Uključivo naknada za otežan rad (postavljanje pokretne skele na stube, rad na visini u zoni otvorenog ruba stubišta, postavljanje skele uz ogradu, ...).
C56: 2) špalete i bridovi | D56: m1 | E56: 70 | F56: 20 | G56: =IF(ISNUMBER(F56),ROUND(E56*ROUND(F56,2),2),"") -> 1400
...

Sheet S.3.LIČILAČKI
B2: RB | C2: OPIS STAVKE | D2: JEDINIČNA MJERA | E2: OBRAČUN KOLIČINA | F2: JEDINIČNA CIJENA | G2: UKUPNA CIJENA | H2: NAPOMENE
B4: ='S.0.'!B4 -> S. | C4: ='S.0.'!C4 -> STUBIŠTE
C6: NAPOMENA: skela uključena u cijene pripadajućih radova za koje se koristi.
B8: =B4&"3." -> S.3. | C8: LIČILAČKI RADOVI
B10: =$B$8&COUNTA($B$8:INDEX(B:B,ROW()-1)) -> S.3.1 | C10: STRUGANJE STARE I TROŠNE BOJE
C12: Skidanje boje sa zidova i stropova na pozicijama na kojima se zadržava postojeća žbuka. Uskladiti radove s ispitivanjem žbuke i sa radovima uklanjanja te žbukanja.
C13: U stavku uključeno svo potrebno brušenje i ravnanje kako bi se ploha dovela do razine pripravne za gletanje.
C15: 1) struganje | D15: m2 | E15: 260 | F15: 4 | G15: =IF(ISNUMBER(F15),ROUND(E15*ROUND(F15,2),2),"") -> 1040
C16: Obračun po m2 plohe koja se obrađuje.
C18: U stavku je uključeno npr:
C19: 1.1) unutarnji zidovi
C20: 1.2) unutarnji stropovi i grede
C21: 1.3) kosi podgled stubišta
C22: Uključivo naknada za otežan rad (postavljanje pokretne skele na stube, rad na visini u zoni otvorenog ruba stubišta, postavljanje skele uz ogradu, ...).
C24: 2) špalete i bridovi | D24: m1 | E24: 140 | F24: 2 | G24: =IF(ISNUMBER(F24),ROUND(E24*ROUND(F24,2),2),"") -> 280
C25: Obračun po m1 duljine elementa koji se obrađuje.
C27: Stavka se odnosi pretežno na špalete otvora, isturene bridove greda i rubove ploča, otvoreni rub stubišta i slične istake.
C28: U stavku uključena primjena povećane pažnje kako se okolni dijelovi ne bi oštetili prilikom izvođenja radova.
C30: U stavku je uključeno npr:
C31: 2.1) špaleta prozora
C32: 2.2) rub prema vratima
C33: 2.3) rub prema kamenoj oblozi zida
C34: 2.4) otvoreni rub ploče podesta
C35: 2.5) otvoreni rub stubišta
C36: 2.6) bridovi stropnih greda
B38: =$B$8&COUNTA($B$8:INDEX(B:B,ROW()-1)) -> S.3.2 | C38: PREMAZIVANJE MRLJA NA ZIDOVIMA I STROPOVIMA
C40: Impregnacija oštećenih zona (masne mrlje, mrlje od procurijevanja vode i slično) na pozicijama na kojima se zadržava postojeća žbuka. Mrlje se premazuju premazom za zaštitu od gljivica koji odstranjuje postojeće naslage i sprječava nastanak novih.
C41: U stavku uključena dobava, materijala, premazivanje i ostali potrebni radovi za izvedbu impregnacije.
C42: U stavku uključeno pravovremeno informiranje korisnika prostora o izvedbi rada budući da premazi sadrže tvari potencijalno opasne za zdravlje te je potrebno adekvatno provjetravanje prostora tijekom sušenja.
C44: 1) premazivanje mrlja | D44: m2 | E44: 20 | F44: 8 | G44: =IF(ISNUMBER(F44),ROUND(E44*ROUND(F44,2),2),"") -> 160
C45: Obračun po m2 plohe koja se obrađuje.
C47: U stavku je uključeno npr:
C48: 1.1) unutarnji zidovi
C49: 1.2) unutarnji stropovi i grede
C50: 1.3) kosi podgled stubišta
C51: Uključivo naknada za otežan rad (postavljanje pokretne skele na stube, rad na visini u zoni otvorenog ruba stubišta, postavljanje skele uz ogradu, ...).
B53: =$B$8&COUNTA($B$8:INDEX(B:B,ROW()-1)) -> S.3.3 | C53: GLETANJE UNUTARNJIH PROSTORA
C55: Dobava materijala i gletanje unutarnjih zidova i stropova.
C57: 1) gletanje plohe | D57: m2 | E57: 390 | F57: 12 | G57: =IF(ISNUMBER(F57),ROUND(E57*ROUND(F57,2),2),"") -> 4680
C58: Obračun po m2 površine plohe koja se gleta.
...

Sheet S.4.STOLARSKI
B2: RB | C2: OPIS STAVKE | D2: JEDINIČNA MJERA | E2: OBRAČUN KOLIČINA | F2: JEDINIČNA CIJENA | G2: UKUPNA CIJENA | H2: NAPOMENE
B4: ='S.0.'!B4 -> S. | C4: ='S.0.'!C4 -> STUBIŠTE
C6: NAPOMENA: skela uključena u cijene pripadajućih radova za koje se koristi.
B8: =B4&"4." -> S.4. | C8: STOLARSKI RADOVI
B10: =$B$8&COUNTA($B$8:INDEX(B:B,ROW()-1)) -> S.4.1 | C10: Obrada vrata vjetrobrana i nadsvjetla
C12: U stavku uključeno skidanje boje, sanacija oštećenja (kitanje), brušenje, ličenje ploha bojom za drvo, ličenje čeličnih elemenata bojom za metal.
C13: U cijenu uključeni svi potrebni pretpremazi, odnosno premazi i impregnacije sukladno uputama proizvođača.
C15: Dimenzije vrata: 140x220
C16: Dimenzije nadsvjetla: 140x50
C18: Obračun za komplet obnovljena vrata vjetrobrana | D18: komplet | E18: 1 | F18: 2000 | G18: =IF(ISNUMBER(F18),ROUND(E18*ROUND(F18,2),2),"") -> 2000
B20: =B8 -> S.4. | C20: =C8&" UKUPNO" -> STOLARSKI RADOVI UKUPNO | G20: =SUM($G$8:INDEX(G:G,ROW()-1)) -> 2000

Sheet F.0.
C2: =PROJEKT_NAZIV -> Stambena zgrada - obnova fasade i stubišnog prostora
B4: F. | C4: FASADA
B5: =B4&"0." -> F.0. | C5: NASLOVNICA
C9: Investitor: | D9: =INVESTITOR_NAZIV -> Suvlasnici stambene zgrade
C13: Građevina: | D13: =PROJEKT_NAZIV -> Stambena zgrada - obnova fasade i stubišnog prostora
C15: Lokacija: | D15: =PROJEKT_LOKACIJA -> Tratinska 13, 10000 Zagreb
C18: Dio: | D18: ARHITEKTURA I KONSTRUKCIJA
C26: Izrađivač:
C27: =AUTOR_NAZIV -> NFO d.o.o.
C28: =AUTOR_ADRESA -> Ksaver 152
C29: =AUTOR_GRAD -> 10000 Zagreb
C33: Projektant:
C34: =AUTOR_PROJEKTANT -> Nenad Ravnić, dipl.ing.arh.
C44: =DATUM -> Zagreb, studeni 2025.

Sheet F.1.PRIPREMNI
B2: RB | C2: OPIS STAVKE | D2: JEDINIČNA MJERA | E2: OBRAČUN KOLIČINA | F2: JEDINIČNA CIJENA | G2: UKUPNA CIJENA | H2: NAPOMENE
B4: ='F.0.'!B4 -> F. | C4: ='F.0.'!C4 -> FASADA
B6: =B4&"1." -> F.1. | C6: PRIPREMNI I ZAVRŠNI RADOVI
C8: NAPOMENA: skela uključena u cijene pripadajućih radova za koje se koristi.
C10: NAPOMENA: u sve cijene troškovničkih stavaka uključeno grubo čišćenje tijekom trajanja radova
C11: Sa svih površina potrebno je ukloniti šutu i građevinski otpad, smeće, ... te prostor držati urednim kako bi se prostor mogao uporabljivati te kako se ne bi nakupljao otpad u javnom prostoru.
C12: U stavku uključeno redovito čišćenje nogostupa, ulaza u zgradu, ulaza u prostor u prizemlju, ... kako bi predmetne zone ostale pristupačne.
B14: =$B$6&COUNTA($B$6:INDEX(B:B,ROW()-1)) -> F.1.1 | C14: Zaštita postojećih građevinskih elemenata
C16: Zaštita svih horizontalnih i vertikalnih površina te elemenata uz zonu obuhvata na pročelju od oštećenja: nogostup, kontaktna zona sa susjednim zgradama, dio pročelja koji se ne obrađuje, prozori, ulazna vrata, ...
C17: Za svaki element primjeniti adekvatnu zaštitu prikladnu za vanjske prostore sukladno radovima koji se izvode: OSB i slične ploče, folije, platno, ...
C18: Za elemente uz koje se neposredno izvode radovi - vrata, prozori, ... - zaštitu izvesti tako da omogući izvedbu, npr. ličenje i slično.
C19: U stavku uključeno održavanje zaštite te uklanjanje zaštite nakon izvedenih radova, kao i odvoz i eventualno deponiranje zaštitnih elemenata.
C21: Obračun za komplet | D21: komplet | E21: 1 | G21: =IF(ISNUMBER(F21),ROUND(E21*ROUND(F21,2),2),"")
B23: =$B$6&COUNTA($B$6:INDEX(B:B,ROW()-1)) -> F.1.2 | C23: Zaštitna ograda
C25: U stavku uključeno definiranje perimetra na nogostupu te postavljanje zaštitne ograde kako bi se radovi mogli odvijati na siguran način.
C26: Postavlja se zaštitna ograda na mobilnim temeljima s ispunom prikladna za vanjski prostor, s adekvatnim ulazima za korisnike zgrade i radnike.
C27: Na nogostupu je potrebno osigurati dostatan prostor za prolaz pješaka.
C28: Visina ograde sukladno potrebama radova, ne manje od 2.5 m1.
C30: Obračun po m2 razvijene površine zaštitne ograde | D30: m2 | E30: 60 | G30: =IF(ISNUMBER(F30),ROUND(E30*ROUND(F30,2),2),"")
B32: =$B$6&COUNTA($B$6:INDEX(B:B,ROW()-1)) -> F.1.3 | C32: Čišćenje pročelja prije početka radova
C34: U stavku uključeno otprašivanje, čišćenje i pranje visokotlačnim peračem cijele površine predmetnog dijela fasade.
C35: U stavku uključena sva potrebna zaštita susjednih zgrada te nogostupa od prskanja te kanaliziranje onečišćene vode prema odvodu.
C37: Obračun po m2 razvijene površine zone obuhvata pročelja. | D37: m2 | E37: 90 | G37: =IF(ISNUMBER(F37),ROUND(E37*ROUND(F37,2),2),"")
B39: =$B$6&COUNTA($B$6:INDEX(B:B,ROW()-1)) -> F.1.4 | C39: Završno čišćenje obuhvata za primopredaju i odvoz
C41: Stavka uključuje završno fino čišćenje kao pripremu za primopredaju, uključivo sva gruba i fina čišćenja pročelja i nogostupa, skupljanje te završni odvoz uklonjenog materijala i deponiranje, uključivo takse deponije.
C42: Čišćenje obuhvaća otklanjanje zaprljanja sa svih ploha u prostorima iskazanim u stavci - s pročelja, nogostupa i eventualno drugih zaprljanih dijelova. Prostor za primopredaju mora biti u cijelosti čist.
C44: Obračun po m2 poda stubišnog prostora. | D44: m2 | E44: 90 | G44: =IF(ISNUMBER(F44),ROUND(E44*ROUND(F44,2),2),"")
B46: =B6 -> F.1. | C46: =C6&" UKUPNO" -> PRIPREMNI I ZAVRŠNI RADOVI UKUPNO | G46: =SUM($G$6:INDEX(G:G,ROW()-1)) -> 0

Sheet F.2.FASADERSKI
B2: RB | C2: OPIS STAVKE | D2: JEDINIČNA MJERA | E2: OBRAČUN KOLIČINA | F2: JEDINIČNA CIJENA | G2: UKUPNA CIJENA | H2: NAPOMENE
B4: ='F.0.'!B4 -> F. | C4: ='F.0.'!C4 -> FASADA
C6: NAPOMENA: skela uključena u cijene pripadajućih radova za koje se koristi.
B8: =B4&"2." -> F.2. | C8: FASADERSKI RADOVI
B10: =$B$8&COUNTA($B$8:INDEX(B:B,ROW()-1)) -> F.2.1 | C10: Prekrivanje grafita prije bojanja fasade
C12: Dobava materijala i ličenje dijela pročelja prekrivenog grafitima.
C13: Predmetna zona prekriva se gustom fasadnom bojom kako bi se spriječilo prodiranje grafita kroz završnu boju.
C14: Prekrivna boja istog tona kao postojeća boja pročelja.
C16: Obračun po m2 prekrivenih grafita | D16: m2 | E16: 30 | F16: 35 | G16: =IF(ISNUMBER(F16),ROUND(E16*ROUND(F16,2),2),"") -> 1050
B18: =$B$8&COUNTA($B$8:INDEX(B:B,ROW()-1)) -> F.2.2 | C18: Bojanje fasade
C20: Dobava materijala i bojanje fasade završnom pročeljnom bojom.
C21: U stavku uključeno završno premazivanje bojom otpornom na grafite.
C22: Pročeljna boja mora biti postojana na čišćenje pod visokim pritiskom.
C23: U stavku uključen pretpremaz za bolju prionjivost te svi potrebni radovi za izvedbu uredne plohe pročelja.
C25: Visina dijela fasade koji se obrađuje: cca 4 m od poda nogostupa.
C27: 1) bojanje plohe | D27: m2 | E27: 60 | F27: 25 | G27: =IF(ISNUMBER(F27),ROUND(E27*ROUND(F27,2),2),"") -> 1500
C28: Obračun po m2 površine plohe koja se boja.
C30: 2) špalete i bridovi | D30: m1 | E30: 110 | F30: 18 | G30: =IF(ISNUMBER(F30),ROUND(E30*ROUND(F30,2),2),"") -> 1980
C31: Obračun po m1 špalete i brida koji se boja.
C33: Stavka se odnosi pretežno na špalete otvora, isturene bridove greda i rubove ploča, otvoreni rub stubišta i slične istake.
C34: U stavku uključene kutne šine i ostala obrada potrebna da se dobije čvrst i uredan spoj na uglu, odnosno na rubu prema drugom elementu.
C36: U stavku je uključeno npr:
C37: 2.1) špaleta prozora
C38: 2.2) špaleta glavnog ulaza
C39: 2.3) špaleta nadsvjetla glavnog ulaza
C40: 2.4) ukrasni okvir glavnog ulaza
C41: 2.5) profilirana linija u razini klupčica
C42: 2.6) rub prema gornjem dijelu pročelja
C43: 2.7) rub prema susjednoj zgradi
C44: 2.8) rub prema malom stubištu
C45: Skela nije u cijeni, ne zna se što je obuhvat radova na fasadi
B46: =B8 -> F.2. | C46: =C8&" UKUPNO" -> FASADERSKI RADOVI UKUPNO | G46: =SUM($G$8:INDEX(G:G,ROW()-1)) -> 4530

Sheet F.3.STOLARSKI
B2: RB | C2: OPIS STAVKE | D2: JEDINIČNA MJERA | E2: OBRAČUN KOLIČINA | F2: JEDINIČNA CIJENA | G2: UKUPNA CIJENA | H2: NAPOMENE
B4: ='F.0.'!B4 -> F. | C4: ='F.0.'!C4 -> FASADA
B6: =B4&"3." -> F.3. | C6: STOLARSKI RADOVI
B8: =$B$6&COUNTA($B$6:INDEX(B:B,ROW()-1)) -> F.3.1 | C8: Obrada ulaznih vrata i nadsvjetla
C10: U stavku uključeno skidanje boje, sanacija oštećenja (kitanje), brušenje, ličenje ploha bojom za drvo, ličenje čeličnih elemenata bojom za metal.
C11: U cijenu uključeni svi potrebni pretpremazi, odnosno premazi i impregnacije sukladno uputama proizvođača.
C13: Dimenzije vrata: 140x270
C14: Dimenzije nadsvjetla: 140x80
C16: Obračun za komplet obnovljena ulazna vrata | D16: komplet | E16: 1 | F16: 2000 | G16: =IF(ISNUMBER(F16),ROUND(E16*ROUND(F16,2),2),"") -> 2000
B18: =B6 -> F.3. | C18: =C6&" UKUPNO" -> STOLARSKI RADOVI UKUPNO | G18: =SUM($G$6:INDEX(G:G,ROW()-1)) -> 2000
