Workbook

Sheet BOQ
I1: =SUBTOTAL(9,I3:I17137) -> 0
A2: Package | B2: Objekt | C2: Vrsta radova | D2: Poz | E2: Opis | F2: Jedinica | G2: Količina | H2: Jedinična cijena | I2: Ukupno
A3: Package 1 | B3: Sports Area | C3: 02.00 Preparatory work | E3: SPORTSKI TERENI | I3: =IF(AND(G3<>"",H3<>""),G3*H3,"")
A4: Package 1 | B4: Sports Area | C4: 02.00 Preparatory work | E4: PRETHODNI RADOVI OBUHVAT | I4: =IF(AND(G4<>"",H4<>""),G4*H4,"")
A5: Package 1 | B5: Sports Area | C5: 02.00 Preparatory work | E5: Napomena: Sastavni dio opisa i jednične ugovorene cijene svih stavaka troškovnika su svi opći uvjeti dati na posebnom (prvom) listu ovog excel dokumenta. | I5: =IF(AND(G5<>"",H5<>""),G5*H5,"")
A6: Package 1 | B6: Sports Area | C6: 02.00 Preparatory work | E6: PRETHODNI RADOVI | I6: =IF(AND(G6<>"",H6<>""),G6*H6,"")
A7: Package 1 | B7: Sports Area | C7: 02.00 Preparatory work | D7: 02.00.11.1 | E7: UREĐENJE GRADILIŠTA | I7: =IF(AND(G7<>"",H7<>""),G7*H7,"")
A8: Package 1 | B8: Sports Area | C8: 02.00 Preparatory work | E8: Uspostavljanje funkcionalnog stanja | I8: =IF(AND(G8<>"",H8<>""),G8*H8,"")
A9: Package 1 | B9: Sports Area | C9: 02.00 Preparatory work | D9: 02.00.11.1.A | E9: Obračun po kompletu | F9: pa | G9: 1 | I9: =IF(AND(G9<>"",H9<>""),G9*H9,"")
A10: Package 1 | B10: Sports Area | C10: 02.00 Preparatory work | E10: Čiščenje gradilišta | I10: =IF(AND(G10<>"",H10<>""),G10*H10,"")
A11: Package 1 | B11: Sports Area | C11: 02.00 Preparatory work | D11: 02.00.11.2 | E11: Rastavljanje i odvoženje | I11: =IF(AND(G11<>"",H11<>""),G11*H11,"")
A12: Package 1 | B12: Sports Area | C12: 02.00 Preparatory work | E12: Čišćenje prostora u tijeku radova te odvoz šute i viška materijala s gradilišta. Izvođač je dužan gradilište sa svim prostorijama i cijelim inventarom nakon izvedbe svih radova generalano očistiti, uključujući pranje, čišćenje svih podova, opločenja, bravarije, sa čišćenjem okova, ostakljenja, pregrada i bazena. Uključivo sa odnosom i odvozom smeća. | I12: =IF(AND(G12<>"",H12<>""),G12*H12,"")
A13: Package 1 | B13: Sports Area | C13: 02.00 Preparatory work | D13: 02.00.11.2.A | E13: Obračun po kompletu | F13: pa | G13: 1 | I13: =IF(AND(G13<>"",H13<>""),G13*H13,"")
A14: Package 1 | B14: Sports Area | C14: 02.00 Preparatory work | E14: VREMENSKI UVJETOVANI PROSJEČNI PAUŠALNI TROŠKOVNI GRADILIŠTA | I14: =IF(AND(G14<>"",H14<>""),G14*H14,"")
A15: Package 1 | B15: Sports Area | C15: 02.00 Preparatory work | D15: 02.00.11.3 | E15: Paušalni troškovi za vlastite građevinske radove | I15: =IF(AND(G15<>"",H15<>""),G15*H15,"")
A16: Package 1 | B16: Sports Area | C16: 02.00 Preparatory work | E16: Uređenja za vlastite potrebe s iznimkom korištenja utvrđenog u Planu za sigurnost i zaštitu zdravlja tijekom vremena građenja. | I16: =IF(AND(G16<>"",H16<>""),G16*H16,"")
A17: Package 1 | B17: Sports Area | C17: 02.00 Preparatory work | D17: 02.00.11.3.A | E17: Obračun po | F17: pa | G17: 1 | I17: =IF(AND(G17<>"",H17<>""),G17*H17,"")
A18: Package 1 | B18: Sports Area | C18: 02.00 Preparatory work | D18: 02.00.11.4 | E18: Paušalni troškovi vlastitog prekida rada | I18: =IF(AND(G18<>"",H18<>""),G18*H18,"")
A19: Package 1 | B19: Sports Area | C19: 02.00 Preparatory work | E19: Uređenje za vlastite potrebe s iznimkom korištenja utvrđenog u Planu za sigurnost i zaštitu zdravlja tijekom prekida rada. | F19: pa | G19: 1 | I19: =IF(AND(G19<>"",H19<>""),G19*H19,"")
A20: Package 1 | B20: Sports Area | C20: 02.00 Preparatory work | D20: 02.00.11.5 | E20: Paušalni troškovi građenja | I20: =IF(AND(G20<>"",H20<>""),G20*H20,"")
A21: Package 1 | B21: Sports Area | C21: 02.00 Preparatory work | D21: 02.00.11.5.A | E21: Mjere prema Planu za sigurnost i zaštitu zdravlja, paušalni troškovi tijekom vremena građenja. | F21: pa | G21: 1 | I21: =IF(AND(G21<>"",H21<>""),G21*H21,"")
A22: Package 1 | B22: Sports Area | C22: 02.00 Preparatory work | D22: 02.00.11.6 | E22: Troškovni prekida rada | I22: =IF(AND(G22<>"",H22<>""),G22*H22,"")
A23: Package 1 | B23: Sports Area | C23: 02.00 Preparatory work | D23: 02.00.11.6.A | E23: Paušalni troškovi prekida rada prema Planu za sigurnost i zaštitu zdravlja, Mjere prema Planu za sigurnost i zaštitu zdravlja, korištenje tijekom prekida rada. | F23: pa | G23: 1 | I23: =IF(AND(G23<>"",H23<>""),G23*H23,"")
A24: Package 1 | B24: Sports Area | C24: 02.00 Preparatory work | D24: 02.00.11.7 | E24: ČUVANJE GRADILIŠTA | I24: =IF(AND(G24<>"",H24<>""),G24*H24,"")
A25: Package 1 | B25: Sports Area | C25: 02.00 Preparatory work | E25: Čuvanje gradilišta tijekom radnog vremena stalno. | I25: =IF(AND(G25<>"",H25<>""),G25*H25,"")
A26: Package 1 | B26: Sports Area | C26: 02.00 Preparatory work | D26: 02.00.11.8 | E26: Unutar uobičajenog radnog vremena stalno prisutno čuvanje. | I26: =IF(AND(G26<>"",H26<>""),G26*H26,"")
A27: Package 1 | B27: Sports Area | C27: 02.00 Preparatory work | D27: 02.00.11.8.A | E27: Obračun po mjesecu | F27: pa | G27: 1 | I27: =IF(AND(G27<>"",H27<>""),G27*H27,"")
A28: Package 1 | B28: Sports Area | C28: 02.00 Preparatory work | D28: 02.00.11.9 | E28: Čuvanje gradilišta nakon radnog vremena stalno. | I28: =IF(AND(G28<>"",H28<>""),G28*H28,"")
A29: Package 1 | B29: Sports Area | C29: 02.00 Preparatory work | D29: 02.00.11.10 | E29: Izvan uobičajenog radnog vremena stalno prisutno čuvanje. | I29: =IF(AND(G29<>"",H29<>""),G29*H29,"")
A30: Package 1 | B30: Sports Area | C30: 02.00 Preparatory work | D30: 02.00.11.10.A | E30: Obračun po mjesecu | F30: pa | G30: 1 | I30: =IF(AND(G30<>"",H30<>""),G30*H30,"")
A31: Package 1 | B31: Sports Area | C31: 02.00 Preparatory work | E31: ŠIROKOKUTNI OUTDOOR-WEBCAM UREĐAJ | I31: =IF(AND(G31<>"",H31<>""),G31*H31,"")
A32: Package 1 | B32: Sports Area | C32: 02.00 Preparatory work | D32: 02.00.11.11 | E32: Outdoor-Webcam | I32: =IF(AND(G32<>"",H32<>""),G32*H32,"")
A33: Package 1 | B33: Sports Area | C33: 02.00 Preparatory work | E33: Širokokutni Outdoor-Webcam-uredaj, montiran i uperen na stupu visokom 15 m.Položaj se mora utvrditi u suglasnosti s Nalogodavcem, no, ulaz mora biti vidljiv.Korištenje Webcama mora se omogućiti pomoću slobodnog pristupa putem Explorer Internet- Browsera. Uređaj mora u razmacima od maks. 5-15 minuta automatski aktualizirati sliku i prikazati minimalnu rezoluciju od 800x600 piksela.Moraju se napraviti filmovi s 5-10 minuta ukupnog trajanja. Svi pohranjeni podaci moraju se na završetku gradilišta predati Investitoru na prikladnom podatkovnom mediju. Radi osiguranja funkcije kamera se mora opremiti uređajem s neprekidnom opskrbom struje (USV). | I33: =IF(AND(G33<>"",H33<>""),G33*H33,"")
A34: Package 1 | B34: Sports Area | C34: 02.00 Preparatory work | E34: Montiranje i korištenje Outdoor Webcama stavljene na raspolaganje od strane Nalogodavca, uključujuci stup visok 7-8 m za pričvršćenje, dovoljno stabilno podzidan na mjestu dogovorenom s Investitorom, a nakon završetka građenja ukloniti i preostali materijal zbrinuti. Stavka obuhvaća kompletnu izradu potrebnih priključnih vodova, službena odobrenja, zemljane radove i radove temeljenja, troškove pružatelja internetskih usluga (Provider). | I34: =IF(AND(G34<>"",H34<>""),G34*H34,"")
A35: Package 1 | B35: Sports Area | C35: 02.00 Preparatory work | D35: 02.00.11.11.A | E35: Outdoor-Webcam, obračun po kompletu. | F35: pa | G35: 1 | I35: =IF(AND(G35<>"",H35<>""),G35*H35,"")
A36: Package 1 | B36: Sports Area | C36: 02.00 Preparatory work | E36: Pribrajanje na stavku A.01.05.01. Ograda gradilišta, za ponovno premještanje Webcama tijekom građenja, uključujući stup za pričvršćenje Webcama na novi položaj, sa svim zemljanim radovima i radovima temeljenja i prikljucnim vodovima | I36: =IF(AND(G36<>"",H36<>""),G36*H36,"")
A37: Package 1 | B37: Sports Area | C37: 02.00 Preparatory work | D37: 02.00.11.11.B | E37: Premještanje Outdoor-Webcam, obračun po kompletu. | F37: pa | G37: 1 | I37: =IF(AND(G37<>"",H37<>""),G37*H37,"")
A38: Package 1 | B38: Sports Area | C38: 02.00 Preparatory work | E38: OPERATIVNI TROŠKOVNI GRADILIŠTA U POJEDINOSTIMA | I38: =IF(AND(G38<>"",H38<>""),G38*H38,"")
A39: Package 1 | B39: Sports Area | C39: 02.00 Preparatory work | E39: Prethodne napomene: Izrada, uređivanje: Ako nije drukčije navedeno, usluga Izrada, doprema, postavljanje i/ili montiranje ili drugo uspostavljanje stanja spremnog za uporabu kao i demontiranje ili uklanjanje i odvoženje s gradilišta nakon završetka vremena korištenja. Ako nije drukčije dogovoreno, procjenjuje se djelomična usluga uspostavljanja stanja spremnog za uporabu s 60%, djelomična usluga čišćenja s 40% ukupne usluge. Korištenje: Ako nije drukčije navedeno, korištenje obuhvaća i sve provjere, mjere uzdržavanja. Mozebitni potrošni materijal i potrebno čišćenje. | I39: =IF(AND(G39<>"",H39<>""),G39*H39,"")
A40: Package 1 | B40: Sports Area | C40: 02.00 Preparatory work | E40: Ograda gradilišta prema podatku Nalogodavca za dodatne usluge koje se ne ukalkuliraju u stavku 01.02.00Z (zaštitne mjere prema Planu za sigurnost i zaštitu zdravlja). Ograda visine od 1,5 do 2,5 m iznad zemljista Izvedba po izboru Izvođača, bez razlike, da li na pričvršćenoj i/ili nepričvršćenoj podlozi. Vrata i vanjska ulazna vrata se posebno ne obračunavaju. Obračunava se dužina ograde. | I40: =IF(AND(G40<>"",H40<>""),G40*H40,"")
...

Sheet RECAP
A2: Aktivni paket | B2: Rekapitulacija - sveukupno | C2: Ukupno
A3: =IF(LEFT(B3,7)="Package",B3,A2) -> Package 1 | B3: Package 1 | C3: =IF(B3="","",IF(LEFT(B3,7)="Package",SUMIFS(BOQ!$I:$I,BOQ!$A:$A,B3),SUMIFS(BOQ!$I:$I,BOQ!$A:$A,$A3,BOQ!$B:$B,B3))) -> 0
A4: =IF(LEFT(B4,7)="Package",B4,A3) -> Package 1 | B4: Camp_Falky Land | C4: =IF(B4="","",IF(LEFT(B4,7)="Package",SUMIFS(BOQ!$I:$I,BOQ!$A:$A,B4),SUMIFS(BOQ!$I:$I,BOQ!$A:$A,$A4,BOQ!$B:$B,B4))) -> 0
A5: =IF(LEFT(B5,7)="Package",B5,A4) -> Package 1 | C5: =IF(B5="","",IF(LEFT(B5,7)="Package",SUMIFS(BOQ!$I:$I,BOQ!$A:$A,B5),SUMIFS(BOQ!$I:$I,BOQ!$A:$A,$A5,BOQ!$B:$B,B5)))
A6: =IF(LEFT(B6,7)="Package",B6,A5) -> Package 1 | B6: Camp_Infra | C6: =IF(B6="","",IF(LEFT(B6,7)="Package",SUMIFS(BOQ!$I:$I,BOQ!$A:$A,B6),SUMIFS(BOQ!$I:$I,BOQ!$A:$A,$A6,BOQ!$B:$B,B6))) -> 0
A7: =IF(LEFT(B7,7)="Package",B7,A6) -> Package 1 | C7: =IF(B7="","",IF(LEFT(B7,7)="Package",SUMIFS(BOQ!$I:$I,BOQ!$A:$A,B7),SUMIFS(BOQ!$I:$I,BOQ!$A:$A,$A7,BOQ!$B:$B,B7)))
A8: =IF(LEFT(B8,7)="Package",B8,A7) -> Package 1 | B8: Camp_Kids Bar | C8: =IF(B8="","",IF(LEFT(B8,7)="Package",SUMIFS(BOQ!$I:$I,BOQ!$A:$A,B8),SUMIFS(BOQ!$I:$I,BOQ!$A:$A,$A8,BOQ!$B:$B,B8))) -> 0
A9: =IF(LEFT(B9,7)="Package",B9,A8) -> Package 1 | C9: =IF(B9="","",IF(LEFT(B9,7)="Package",SUMIFS(BOQ!$I:$I,BOQ!$A:$A,B9),SUMIFS(BOQ!$I:$I,BOQ!$A:$A,$A9,BOQ!$B:$B,B9)))
A10: =IF(LEFT(B10,7)="Package",B10,A9) -> Package 1 | B10: Camp_Kitchen | C10: =IF(B10="","",IF(LEFT(B10,7)="Package",SUMIFS(BOQ!$I:$I,BOQ!$A:$A,B10),SUMIFS(BOQ!$I:$I,BOQ!$A:$A,$A10,BOQ!$B:$B,B10))) -> 0
A11: =IF(LEFT(B11,7)="Package",B11,A10) -> Package 1 | C11: =IF(B11="","",IF(LEFT(B11,7)="Package",SUMIFS(BOQ!$I:$I,BOQ!$A:$A,B11),SUMIFS(BOQ!$I:$I,BOQ!$A:$A,$A11,BOQ!$B:$B,B11)))
A12: =IF(LEFT(B12,7)="Package",B12,A11) -> Package 1 | B12: Camp_MH / GH | C12: =IF(B12="","",IF(LEFT(B12,7)="Package",SUMIFS(BOQ!$I:$I,BOQ!$A:$A,B12),SUMIFS(BOQ!$I:$I,BOQ!$A:$A,$A12,BOQ!$B:$B,B12))) -> 0
A13: =IF(LEFT(B13,7)="Package",B13,A12) -> Package 1 | C13: =IF(B13="","",IF(LEFT(B13,7)="Package",SUMIFS(BOQ!$I:$I,BOQ!$A:$A,B13),SUMIFS(BOQ!$I:$I,BOQ!$A:$A,$A13,BOQ!$B:$B,B13)))
A14: =IF(LEFT(B14,7)="Package",B14,A13) -> Package 1 | B14: Camp_Pool Area | C14: =IF(B14="","",IF(LEFT(B14,7)="Package",SUMIFS(BOQ!$I:$I,BOQ!$A:$A,B14),SUMIFS(BOQ!$I:$I,BOQ!$A:$A,$A14,BOQ!$B:$B,B14))) -> 0
A15: =IF(LEFT(B15,7)="Package",B15,A14) -> Package 1 | C15: =IF(B15="","",IF(LEFT(B15,7)="Package",SUMIFS(BOQ!$I:$I,BOQ!$A:$A,B15),SUMIFS(BOQ!$I:$I,BOQ!$A:$A,$A15,BOQ!$B:$B,B15)))
A16: =IF(LEFT(B16,7)="Package",B16,A15) -> Package 1 | B16: Camp_Rezeption | C16: =IF(B16="","",IF(LEFT(B16,7)="Package",SUMIFS(BOQ!$I:$I,BOQ!$A:$A,B16),SUMIFS(BOQ!$I:$I,BOQ!$A:$A,$A16,BOQ!$B:$B,B16))) -> 0
A17: =IF(LEFT(B17,7)="Package",B17,A16) -> Package 1 | C17: =IF(B17="","",IF(LEFT(B17,7)="Package",SUMIFS(BOQ!$I:$I,BOQ!$A:$A,B17),SUMIFS(BOQ!$I:$I,BOQ!$A:$A,$A17,BOQ!$B:$B,B17)))
A18: =IF(LEFT(B18,7)="Package",B18,A17) -> Package 1 | B18: Camp_Sanitary 1 | C18: =IF(B18="","",IF(LEFT(B18,7)="Package",SUMIFS(BOQ!$I:$I,BOQ!$A:$A,B18),SUMIFS(BOQ!$I:$I,BOQ!$A:$A,$A18,BOQ!$B:$B,B18))) -> 0
A19: =IF(LEFT(B19,7)="Package",B19,A18) -> Package 1 | C19: =IF(B19="","",IF(LEFT(B19,7)="Package",SUMIFS(BOQ!$I:$I,BOQ!$A:$A,B19),SUMIFS(BOQ!$I:$I,BOQ!$A:$A,$A19,BOQ!$B:$B,B19)))
A20: =IF(LEFT(B20,7)="Package",B20,A19) -> Package 1 | B20: Camp_Sanitary 2 | C20: =IF(B20="","",IF(LEFT(B20,7)="Package",SUMIFS(BOQ!$I:$I,BOQ!$A:$A,B20),SUMIFS(BOQ!$I:$I,BOQ!$A:$A,$A20,BOQ!$B:$B,B20))) -> 0
A21: =IF(LEFT(B21,7)="Package",B21,A20) -> Package 1 | C21: =IF(B21="","",IF(LEFT(B21,7)="Package",SUMIFS(BOQ!$I:$I,BOQ!$A:$A,B21),SUMIFS(BOQ!$I:$I,BOQ!$A:$A,$A21,BOQ!$B:$B,B21)))
A22: =IF(LEFT(B22,7)="Package",B22,A21) -> Package 1 | B22: Camp_Sanitary 3 | C22: =IF(B22="","",IF(LEFT(B22,7)="Package",SUMIFS(BOQ!$I:$I,BOQ!$A:$A,B22),SUMIFS(BOQ!$I:$I,BOQ!$A:$A,$A22,BOQ!$B:$B,B22))) -> 0
A23: =IF(LEFT(B23,7)="Package",B23,A22) -> Package 1 | C23: =IF(B23="","",IF(LEFT(B23,7)="Package",SUMIFS(BOQ!$I:$I,BOQ!$A:$A,B23),SUMIFS(BOQ!$I:$I,BOQ!$A:$A,$A23,BOQ!$B:$B,B23)))
A24: =IF(LEFT(B24,7)="Package",B24,A23) -> Package 1 | B24: Sports Area | C24: =IF(B24="","",IF(LEFT(B24,7)="Package",SUMIFS(BOQ!$I:$I,BOQ!$A:$A,B24),SUMIFS(BOQ!$I:$I,BOQ!$A:$A,$A24,BOQ!$B:$B,B24))) -> 0
A25: =IF(LEFT(B25,7)="Package",B25,A24) -> Package 1 | C25: =IF(B25="","",IF(LEFT(B25,7)="Package",SUMIFS(BOQ!$I:$I,BOQ!$A:$A,B25),SUMIFS(BOQ!$I:$I,BOQ!$A:$A,$A25,BOQ!$B:$B,B25)))
A26: =IF(LEFT(B26,7)="Package",B26,A25) -> Package 1 | B26: (prazno) | C26: =IF(B26="","",IF(LEFT(B26,7)="Package",SUMIFS(BOQ!$I:$I,BOQ!$A:$A,B26),SUMIFS(BOQ!$I:$I,BOQ!$A:$A,$A26,BOQ!$B:$B,B26))) -> 0
A27: =IF(LEFT(B27,7)="Package",B27,A26) -> Package 1 | C27: =IF(B27="","",IF(LEFT(B27,7)="Package",SUMIFS(BOQ!$I:$I,BOQ!$A:$A,B27),SUMIFS(BOQ!$I:$I,BOQ!$A:$A,$A27,BOQ!$B:$B,B27)))
A28: =IF(LEFT(B28,7)="Package",B28,A27) -> Package 2 | B28: Package 2 | C28: =IF(B28="","",IF(LEFT(B28,7)="Package",SUMIFS(BOQ!$I:$I,BOQ!$A:$A,B28),SUMIFS(BOQ!$I:$I,BOQ!$A:$A,$A28,BOQ!$B:$B,B28))) -> 0
A29: =IF(LEFT(B29,7)="Package",B29,A28) -> Package 2 | B29: Camp Pila | C29: =IF(B29="","",IF(LEFT(B29,7)="Package",SUMIFS(BOQ!$I:$I,BOQ!$A:$A,B29),SUMIFS(BOQ!$I:$I,BOQ!$A:$A,$A29,BOQ!$B:$B,B29))) -> 0
A30: =IF(LEFT(B30,7)="Package",B30,A29) -> Package 2 | C30: =IF(B30="","",IF(LEFT(B30,7)="Package",SUMIFS(BOQ!$I:$I,BOQ!$A:$A,B30),SUMIFS(BOQ!$I:$I,BOQ!$A:$A,$A30,BOQ!$B:$B,B30)))
A31: =IF(LEFT(B31,7)="Package",B31,A30) -> Package 2 | B31: Camp_Falky Land | C31: =IF(B31="","",IF(LEFT(B31,7)="Package",SUMIFS(BOQ!$I:$I,BOQ!$A:$A,B31),SUMIFS(BOQ!$I:$I,BOQ!$A:$A,$A31,BOQ!$B:$B,B31))) -> 0
A32: =IF(LEFT(B32,7)="Package",B32,A31) -> Package 2 | C32: =IF(B32="","",IF(LEFT(B32,7)="Package",SUMIFS(BOQ!$I:$I,BOQ!$A:$A,B32),SUMIFS(BOQ!$I:$I,BOQ!$A:$A,$A32,BOQ!$B:$B,B32)))
A33: =IF(LEFT(B33,7)="Package",B33,A32) -> Package 2 | B33: Camp_Infra | C33: =IF(B33="","",IF(LEFT(B33,7)="Package",SUMIFS(BOQ!$I:$I,BOQ!$A:$A,B33),SUMIFS(BOQ!$I:$I,BOQ!$A:$A,$A33,BOQ!$B:$B,B33))) -> 0
A34: =IF(LEFT(B34,7)="Package",B34,A33) -> Package 2 | C34: =IF(B34="","",IF(LEFT(B34,7)="Package",SUMIFS(BOQ!$I:$I,BOQ!$A:$A,B34),SUMIFS(BOQ!$I:$I,BOQ!$A:$A,$A34,BOQ!$B:$B,B34)))
A35: =IF(LEFT(B35,7)="Package",B35,A34) -> Package 2 | B35: Camp_Kids Bar | C35: =IF(B35="","",IF(LEFT(B35,7)="Package",SUMIFS(BOQ!$I:$I,BOQ!$A:$A,B35),SUMIFS(BOQ!$I:$I,BOQ!$A:$A,$A35,BOQ!$B:$B,B35))) -> 0
A36: =IF(LEFT(B36,7)="Package",B36,A35) -> Package 2 | C36: =IF(B36="","",IF(LEFT(B36,7)="Package",SUMIFS(BOQ!$I:$I,BOQ!$A:$A,B36),SUMIFS(BOQ!$I:$I,BOQ!$A:$A,$A36,BOQ!$B:$B,B36)))
A37: =IF(LEFT(B37,7)="Package",B37,A36) -> Package 2 | B37: Camp_Kitchen | C37: =IF(B37="","",IF(LEFT(B37,7)="Package",SUMIFS(BOQ!$I:$I,BOQ!$A:$A,B37),SUMIFS(BOQ!$I:$I,BOQ!$A:$A,$A37,BOQ!$B:$B,B37))) -> 0
A38: =IF(LEFT(B38,7)="Package",B38,A37) -> Package 2 | C38: =IF(B38="","",IF(LEFT(B38,7)="Package",SUMIFS(BOQ!$I:$I,BOQ!$A:$A,B38),SUMIFS(BOQ!$I:$I,BOQ!$A:$A,$A38,BOQ!$B:$B,B38)))
A39: =IF(LEFT(B39,7)="Package",B39,A38) -> Package 2 | B39: (prazno) | C39: =IF(B39="","",IF(LEFT(B39,7)="Package",SUMIFS(BOQ!$I:$I,BOQ!$A:$A,B39),SUMIFS(BOQ!$I:$I,BOQ!$A:$A,$A39,BOQ!$B:$B,B39))) -> 0
A40: =IF(LEFT(B40,7)="Package",B40,A39) -> Package 2 | B40: Camp_MH / GH | C40: =IF(B40="","",IF(LEFT(B40,7)="Package",SUMIFS(BOQ!$I:$I,BOQ!$A:$A,B40),SUMIFS(BOQ!$I:$I,BOQ!$A:$A,$A40,BOQ!$B:$B,B40))) -> 0
A41: =IF(LEFT(B41,7)="Package",B41,A40) -> Package 2 | C41: =IF(B41="","",IF(LEFT(B41,7)="Package",SUMIFS(BOQ!$I:$I,BOQ!$A:$A,B41),SUMIFS(BOQ!$I:$I,BOQ!$A:$A,$A41,BOQ!$B:$B,B41)))
...
