Workbook
Name _Fill: #REF!

Sheet NASL
A3: Projekt izradio: | B3: SAGRADA d.o.o.
B4: Bukovačka cesta 188
B5: 10000 Zagreb
B6: stipan.dolic@gmail.com
A13: Građevina: | B13: IZGRADNJA STAMBENE ZGRADE
A16: Lokacija: | B16: Zagreb, Gornji Bukovac, k.č. 2269, k.o. Remete
A19: Investitor: | B19: Josip i Nina Drinovac, Gornji Bukovac 150, 10000 Zagreb
A23: Sadržaj: | B23: TROŠKOVNIK GRAĐEVINSKO - OBRTNIČKIH RADOVA
A27: Zajednička oznaka: | B27: GP 2/22
A30: Broj projekta: | B30: A-2/2022
A33: Izrada troškovnika: | B33: Stipan Dolić, dipl.ing.arh.
A36: Glavni projektant: | B36: Stipan Dolić, dipl.ing.arh.
A39: Direktor: | B39: Stipan Dolić, dipl.ing.arh.
A44: Mjesto i datum izrade: | B44: Zagreb, rujan 2022.

Sheet REKAPITULACIJA
B1: UKUPNA REKAPITULACIJA
F3: kn | G3: €
A4: A. | B4: GRAĐEVINSKO-OBRTNIČKI RADOVI - ZGRADA UKUPNO | F4: =SUM(F5:F15) -> 305602.28 | G4: =F4/7.5345 -> 40560.393
A5: ='A.1.ZEMLJANI'!A88 -> A.1. | B5: ='A.1.ZEMLJANI'!B88 -> ZEMLJANI RADOVI UKUPNO | F5: ='A.1.ZEMLJANI'!F88 -> 36409.75 | G5: =F5/7.5345 -> 4832.4043
A6: ='A.2.BETONSKI I AB'!A178 -> A.2. | B6: ='A.2.BETONSKI I AB'!B178 -> BETONSKI I AB RADOVI UKUPNO | F6: ='A.2.BETONSKI I AB'!F178 -> 204652.65 | G6: =F6/7.5345 -> 27162.075
A7: ='A.3.ZIDARSKI'!A106 -> A.3. | B7: ='A.3.ZIDARSKI'!B106 -> ZIDARSKI RADOVI UKUPNO | F7: ='A.3.ZIDARSKI'!F106 -> 15816.875 | G7: =F7/7.5345 -> 2099.2601
A8: ='A.4.IZOLATERSKI'!A140 -> A.4. | B8: ='A.4.IZOLATERSKI'!B140 -> IZOLATERSKI RADOVI UKUPNO | F8: ='A.4.IZOLATERSKI'!F140 -> 0 | G8: =F8/7.5345 -> 0
A9: ='A.5.FASADERSKI'!A62 -> A.5. | B9: ='A.5.FASADERSKI'!B62 -> FASADERSKI RADOVI UKUPNO | F9: ='A.5.FASADERSKI'!F62 -> 48723 | G9: =F9/7.5345 -> 6466.6534
A10: ='A.6.LIMARSKI'!A34 -> A.6. | B10: ='A.6.LIMARSKI'!B34 -> LIMARSKI RADOVI UKUPNO | F10: ='A.6.LIMARSKI'!F34 -> 0 | G10: =F10/7.5345 -> 0
A11: ='A.7.BRAVARSKI I STOLARSKI'!A313 -> A.7. | B11: ='A.7.BRAVARSKI I STOLARSKI'!B313 -> BRAVARSKI I STOLARSKI RADOVI UKUPNO | F11: ='A.7.BRAVARSKI I STOLARSKI'!F313 -> 0 | G11: =F11/7.5345 -> 0
A12: ='A.8.GIPSKART. I SOBOSL.'!A169 -> A.8. | B12: ='A.8.GIPSKART. I SOBOSL.'!B169 -> GIPSKARTONSKI I SOBOSLIKARSKI RADOVI UKUPNO | F12: ='A.8.GIPSKART. I SOBOSL.'!F169 -> 56.931,90 | G12: =F12/7.5345 -> 7556.1617
A13: ='A.9.PODOPOLAGAČKI'!A173 -> A.9. | B13: ='A.9.PODOPOLAGAČKI'!B173 -> PODOPOLAGAČKI RADOVI UKUPNO | F13: ='A.9.PODOPOLAGAČKI'!F173 -> 0 | G13: =F13/7.5345 -> 0
A16: =B.GRAĐ.OBRT.VANJSKI!A754 -> B. | B16: =B.GRAĐ.OBRT.VANJSKI!B754 -> GRAĐEVINSKO-OBRTNIČKI RADOVI - VANJSKI UKUPNO | F16: =B.GRAĐ.OBRT.VANJSKI!F754 -> 0 | G16: =F16/7.5345 -> 0
A19: C. | B19: INSTALACIJA VODOVODA I KANALIZACIJE | F19: ='C.VODOVOD I KANALIZACIJA'!F44 -> 0 | G19: =F19/7.5345 -> 0
A22: D. | B22: ELEKTROINSTALATERSKI RADOVI | F22: =D.ELEKTROINST.RADOVI!F252 -> 0 | G22: =F22/7.5345 -> 0
A25: E. | B25: STROJARSKI RADOVI | F25: ='E.STROJARSKI RADOVI'!F495 -> 0 | G25: =F25/7.5345 -> 0
B28: UKUPNO | F28: =SUM(F4+F19+F22+F16+F25) -> 305602.28
B31: UKUPNO S PDVom (25%) | F31: =F28*1.25 -> 382002.85

Sheet OPĆI UVJETI
B1: OPĆI UVJETI
B4: NAPOMENA
B6: Troškovnik je izrađen na temelju dijela glavnog projekta za potrebe dobivanja ponuda i odabira izvođača.
B9: OPĆI UVJETI KAO I PRILOŽENI NACRTI I STAVKE SU SASTAVNI DIO TROŠKOVNIKA
B11: OPĆI UVJETI IZVOĐENJA I UGOVARANJA
B13: Svi radovi moraju se izvoditi prema tehničkoj dokumentaciji - nacrtima i prema opisima pojedinih troškovničkih stavki te programu kontrole i osiguranja kvalitete iz Glavnog projekta uz obvezu prihvaćanja općih uvjeta svake pojedine grupe radova. Ovi opći uvjeti su sastavni dio troškovnika i u svemu ih se treba pridržavati, osim ako u stavci troškovnika to nije drugačije navedeno.
B15: Izvođač je dužan pregledati uvjete koje su nadležne službe i javna poduzeća dali u postupku ishođenja lokacijske dozvole te izvođenje izvršiti sukladno njima.
B17: Sve radove po opisima troškovnika i nacrtanoj tehničkoj dokumentaciji izvođač je dužan izvoditi sa stručnim radnicima koji su kvalificirani za pojedine vrste radova koje izvode.
B19: Prije dostave ponude izvođač je obvezan pregledati gradilište te utvrditi mogućnost pristupa, mogućnost transporta, način osiguranja gradilišta od pristupa neovlaštenih osoba, način postave skela i sl.te dogovoriti način snabdjevanja energijom i vodom tijekom građenja.
B21: Izvođač je obvezan voditi građevinski dnevnik, te prije početka radova izvršiti prijavu kod nadležnih tijela, te o tome dati investitoru pisani dokaz.
B23: Izvođač je dužan otkloniti svu eventualnu štetu nastalu pri radovima te održavati čistoću na gradilištu i pristupnim putevima, a sav otpad blato i nečistoću dnevno odvoziti.
B25: Izvođač se mora pobrinuti i o svom trošku osigurati sve dodatne priključke koji su potrebni za izvođenje radova i normalno funkcioniranje gradilišta.
... B767: - čišćenje po završenom radu uključivo odvoz viška materijala na gradsku deponij

Sheet A.1.ZEMLJANI
A1: A.1. | B1: PRIPREMNI I ZEMLJANI RADOVI
A2: R.br. | B2: Opis stavke | C2: J.m. | D2: Kol. | E2: Jed.cijena | F2: Uk. Cijena
B4: OPĆI UVJETI UZ TROŠKOVNIK
B6: Uvodne napomene: Cijena za sve stavke mora uključivati sav dobavu, transport i montažu sa svim materijalom i pomoćnim materijalom, radom i horizontalnim i vertikalnim transportom na gradilištu potrebne za dovršenje radova do potpune funkcionalne ili estetske gotovosti. Cijena za sve stavke mora biti ponuđena za viđeno stanje na predmetnoj lokaciji. Cijena izvođenja betonskih i čeličnih konstrukcija mora obuhvatiti i razrede izloženosti konstrukcija koji se mogu pojaviti na unutar teritorija Republike Hrvatske.
B7: Sva demontirana oprema i svi dijelovi konstrukcije i otpad nastao uklanjanjem građevina ili dijelova građevina se zbrinjava sukladno važečim propisima Republike Hrvatske. Sav materijal, opremu i uređaje kod dopreme na gradilište, a prije ugradnje, izvođač je dužan upisati u dnevnik građenja, te nadzornom organu dostaviti ateste i uvjerenja o kvaliteti, kao i garancijske listove i tehničku dokumentaciju sa podacima o uređajima i opremi. Bez istog materijali, oprema i uređaji ne smiju biti ugrađeni.
A9: A.1. | B9: ZEMLJANI RADOVI
B11: Napomena: Svi iskopi računati su u sraslom stanju. Iskopi su računati s dodatnim potrebnim proširivanjima ovisno o iskopu, ali bez količina potrbnih za formiranje pokosa iskopa koji ovisi o dubini iskopa i zemljanom materijalu u kojem se vrši iskop. U svim stavkama uračunat utovar i odvoz iskopanog materijala na deponij, te plačanje takse deponiranja, ukoliko u stavci nije drugačije navedeno.
B12: UKLJUČIVO GEODETSKO PRAĆENJE NA LOKACIJI
A15: A 1.1. | B15: ISKOLČENJE
B16: Iskolčenje osi i rubova novih objekata:
B17: - iskolčenje trase, poligonih točaka i repera sa svim potrebnim geodetskim podacima
B18: - osiguranje iskolčene osi
B19: - postavljanje poprečnih profila sa svim potrebnim obilježavanjima prema nacrtima
B20: - rekonstrukcija osovine i visine objekata kroz cijelo vrijeme izvođenja radova
B21: - potrebne geodetske izmjere tijekom radova potrebne za obračun izvršenih radova
B22: - izrada izvještaja.
B23: Obračun po kompletu (uključivo iskolčene osi i postavljeni profil, uključivo sav rad i materijal) | C23: komplet | D23: 1 | F23: =D23*E23 -> 0
A26: A.1.2. | B26: ŠIROKI ISKOP
B27: Široki iskop na mjestu izvedbe zgrade u tlu C/D kategorije. Normativ U.E1.0100. Strojnim putem, na mjestu izvedbe objekta s odbacivanjem iskopanog materijala izvan jame na udaljenost 2-3m od ruba iskopa.
B28: Iskop se vrši do kote cca -4,30 m (kota dna šljunka ispod temeljne ploče).
B29: Stavka uključuje i eventualno potrebno ispumpavanje vode iz jame muljnom crpkom uslijed oborina ili podzemnih voda, kao i sva potrebna osiguranja jame. U cijenu sata rada crpke uključena je i cijena rada ekipe, te sve potrebne radnje u svezi s prescrpljivanjem.
B30: Iskopani materijal privremeno odložiti na stranu (privremeno odlagalište na gradilištu) radi eventualne potrebe korištenja iskopanog materijala za zatrpavanje. Utovar i odvoz u posebnoj stavci.
B31: NAPOMENA: iskop se nalazi blizu ruba čestice. Potrebno poduzeti sve mjere osiguranja jame, radi sprječavanja urušavanja susjednog terena i susjednih objekata. Sve uračunati u stavku.
B32: Obračun po m3 materijala u sraslom stanju. | C32: m3 | D32: 1065 | E32: 14 | F32: =D32*E32 -> 14910
A35: A.1.2a. | B35: IZRADA GLAVNOG PROJEKTA ZAŠTITE GRAĐEVINSKE JAME
B36: Izrada glavnog projekta zaštite građevinske jame za zgradu.
B37: Stavka se izvodi isključivo uz odobrenje glavnog nadzornog inženjera ili investitora. | C37: kom | D37: 1 | F37: =D37*E37 -> 0
A40: A.1.2b. | B40: POSTAVA I IZVLAČENJE TALPI (ČELIČNOG ŽMURJA)
B41: Doprema, istovar i ugradnja čeličnih talpi duljine 6,0m tipa Larsen 605 (istih ili boljih karakteristika) novo ili rabljeno zadovoljavajuće kvalitete.
B42: Stavka uključuje svu potrebnu opremu, rad i materijal na dopremi i ugradnji (nabijanju) talpi.
B43: Stavka uključuje korištenje talpi do prestanka potrebe i vađenje talpi korištenjem visećeg vibratora i auto dizalice.
B44: Stavka se izvodi isključivo uz odobrenje glavnog nadzornog inženjera ili investitora.
B45: Obračun po metru dužnom ugrađene talpe -m1
B46: -zapadni rub iskopa (duljina talpi 4,0m) | C46: m1 | D46: 25 | F46: =D46*E46 -> 0
A49: A.1.3. | B49: NASIP
B50: Izrada nasipa ispod temeljne ploče šljunkom prirodne granulacije ili drobljenim kamenom s razastiranjem, finim planiranjem i nabijanjem u sloju w=60cm, min Ms=50MPa.
B51: Dobava materijala i izrada. | C51: m3 | D51: 130 | E51: 55 | F51: =D51*E51 -> 7150
A54: A.1.4. | B54: ZATRPAVANJE
B55: Zatrpavanje oko temelja zemljom iz iskopa, a nakon skidanja oplate temelja podrum. Modul stišljivosti Ms=50Mpa. Obračun po m3 zemlje u zbijenom stanju. | C55: m3 | D55: 130 | E55: 10 | F55: =D55*E55 -> 1300
A58: A.1.5. | B58: ODVOZ ZEMLJE NA TRAJNU DEPONIJU
...

Sheet A.2.BETONSKI I AB
A1: A.2. | B1: BETONSKI I AB RADOVI
A2: R.br. | B2: Opis stavke | C2: J.m. | D2: Kol. | E2: Jed.cijena | F2: Uk. Cijena
A5: A.2. | B5: BETONSKI I AB RADOVI
B7: Napomena:
B8: Oplata: glatka, prema tehnologiji izvoditelja radova.
B9: Obavezno ugraditi u oplatu sve otvore i prodore za cijevi instalacija radi izbjegavanja naknadnog štemanja i drugih naknadnih radova,
B10: a nakon skidanja oplate odstraniti površinska oštećenja i neravnine te zatvoriti poprečne spojeve u zidu od vezivanja oplate plastičnim čepovima ili na drugi način radi hidroizolacije i zvučne izolacije.
B11: Armatura iskazana aproksimativno.
A14: A.2.1. | B14: BETONSKA PODLOGA
B15: Dobava materijala, prijevoz, ugradnja podložnog betona C12/15, d=10cm, kao podloga temelja i podne ploče. U cijenu uračunata i građevinska mreža Q-188. Obračun je po m2.
B16: a) beton | C16: m2 | D16: 185 | E16: 13.55 | F16: =D16*E16 -> 2506.75
B17: b) oplata | C17: m2 | D17: 13 | E17: 21.2 | F17: =SUM(D17*E17) -> 275.6
B18: c) armatura | C18: kg | D18: 1300 | E18: 1.6 | F18: =D18*E18 -> 2080
A21: A.2.2. | B21: BETONSKA PODLOGA -ZAŠTITA HIDROIZOLACIJE
B22: Dobava materijala, prijevoz, izrada zaštite hidroizolacije betonom C 25/30, debljine d=5cm uz prethodnu postavu PE folije. U cijeni uračunata potrebana oplata i armatura. Obračun m2.
B23: a) beton | C23: m2 | D23: 185 | E23: 7.15 | F23: =SUM(D23*E23) -> 1322.75
B24: b) oplata | C24: m2 | D24: 10 | E24: 22 | F24: =SUM(D24*E24) -> 220
B25: c) armatura | C25: kg | D25: 650 | E25: 1.6 | F25: =D25*E25 -> 1040
B26: d) PE folija 0,015 cm | C26: m2 | D26: 185 | E26: 1 | F26: =SUM(D26*E26) -> 185
A29: A.2.3. | B29: TEMELJNA PLOČA PODRUMA
B30: Podna ploča podruma debljine 50cm.
B31: Armirana ploča beton klase C30/37, XC1, XC2, XC3, XC4, debljine 50cm, sa sitnozrnim agregatom max. veličine zrna 8mm.
B32: U cijenu uključiti dobavu i ugradnju armaturne mreže, dobava i strojnu ugradnju betona i zaštitu, te rubnu oplatu.
B33: a) beton | C33: m3 | D33: 89 | E33: 135.15 | F33: =D33*E33 -> 12028.35
B34: b) oplata | C34: m2 | D34: 30 | E34: 22.25 | F34: =D34*E34 -> 667.5
B35: c) armatura | C35: kg | D35: 8900 | E35: 1.65 | F35: =D35*E35 -> 14685
A38: A.2.4. | B38: ARMIRANOBETONSKI ZIDOVI
B39: Dobava materijala i betoniranje arm.betonskog zida debljine 20cm, betonom C30/37, XC1, XC2, XC3, XC4 u dvostranoj glatkoj oplati. Presjek betona 0,20 m3/m2. Prilikom betoniranja ostaviti otvore (proboje) za prolaz elektro i termotehničkih instalacija.
B40: Visina zida podruma h=2.755m, visina zida ostalih etaža h=3.105m.
B41: Obračun po m3 ugrađenog betona.
B42: PODRUM
B43: -beton | C43: m3 | D43: 32.5 | E43: 137.65 | F43: =D43*E43 -> 4473.625
B44: -oplata | C44: m2 | D44: 308 | E44: 23.25 | F44: =D44*E44 -> 7161
B45: -armatura | C45: kg | D45: 3250 | E45: 1.65 | F45: =D45*E45 -> 5362.5
B46: PRIZEMLJE
B47: -beton | C47: m3 | D47: 35 | E47: 137.65 | F47: =D47*E47 -> 4817.75
B48: -oplata | C48: m2 | D48: 456 | E48: 23.25 | F48: =D48*E48 -> 10602
B49: -armatura | C49: kg | D49: 3500 | E49: 1.65 | F49: =D49*E49 -> 5775
B50: KAT
B51: -beton | C51: m3 | D51: 34 | E51: 139.55 | F51: =D51*E51 -> 4744.7
...

Sheet A.3.ZIDARSKI
A1: A.3. | B1: ZIDARSKI RADOVI
A2: R.br. | B2: Opis stavke | C2: J.m. | D2: Kol. | E2: Jed.cijena | F2: Uk. Cijena
A5: A.3. | B5: ZIDARSKI RADOVI
A8: A.3.1. | B8: PREGRADNI ZIDOVI OD POROBETONA d=10cm
B9: Dobava potrebnog materijala te izvedba pregradnih zidova od blokova od porobetona u širini od 10cm. Zid se izvodi prema uputama proizvođača sa odgovarajućim tankoslojnim cementnim mortom. Stavka uključuje sav potreban materijal, transport te skelu. Obračun po m2.
B10: -podrum -otpornost zida na požar EI 90 | C10: m2 | D10: 43 | E10: 75.65 | F10: =D10*E10 -> 3252.95
B11: -kat -balkon spremišta | C11: m2 | D11: 6.5 | E11: 75.65 | F11: =D11*E11 -> 491.725
B12: -krov -obzidavanje vertikala | C12: m2 | D12: 17 | E12: 110.25 | F12: =D12*E12 -> 1874.25
A15: A.3.2. | B15: NADVOJI ZA PREGRADNE ZIDOVE
B16: Dobava i ugradba gotovih prednapregnitih montažnih nadvoja otvora vratiju pregradnih zidova. Obračun po m1 ugrađenog nadvoja širine 10cm i dužine do 120 cm.
B17: Obračun po kom ugrađenog nadvoja.
B18: -podrum | C18: kom | D18: 4 | E18: 25 | F18: =D18*E18 -> 100
B19: -kat | C19: kom | D19: 2 | E19: 25 | F19: =D19*E19 -> 50
A22: A.3.3. | B22: OBZIDAVANJE KADA
B23: Dobava materijala te obzidavanje kada porobetonom debljine 5cm. Obračun po m2. | C23: m2 | D23: 7.5 | F23: =D23*E23 -> 0
A26: A.3.4. | B26: DIMNJAK SCHIEDEL Ø=25 cm
B27: Dobava i zidanje dimnjaka tipa kao SCHIEDEL UNI plus 25 dimenzija 48x48 cm ili jednakovrijedan. Svijetli otvor dimnjaka je promjera Ø20 cm.
B28: Izvedba u svemu prema uputama proizvođača. U cijenu uključiti sve potrebne početne i završne elemente, sve priključke, vratašca za čišćenje i završne tipske manžete i konosni krovni tuljac i tipska dimnjačka kapa. Obračun po m1 kompletno izvedenog dimnjaka.
B29: Ukupno 4 dimnjaka, 2x12m, 1x8m, 1x5m
B30: a) dimnjak | C30: m | D30: 37 | E30: 255.35 | F30: =D30*E30 -> 9447.95
B31: b) kapa | C31: kom | D31: 4 | E31: 150 | F31: =D31*E31 -> 600
A34: A.3.5. | B34: KRPANJE KANALA U PODU NAKON UGRADNJE INSTALACIJA
B35: Dobava materijala i popravak i zapunjavanje raznih kanala instalacija te manjih oštećenja podova produžnim mortom.
B36: Obračun po m1. Količina je pretpostavljena, a stvarna će se količina ovjeriti upisom u građevinsku knjigu od strane nadzornog inženjera. | C36: m1 | D36: 200 | F36: =D36*E36 -> 0
A39: A.3.6. | B39: KRPANJE UTORA (ŠLICEVA) U ZIDU NAKON UGRADNJE INSTALACIJA
B40: Krpanje šliceva u zidovima produžnim cementnim mortom. Širine šliceva do 20 cm. Dobava materijala, potrebna radna skela i žbukanje.
B41: Obračun po m1. Količina je pretpostavljena, a stvarna će se količina ovjeriti upisom u građevinsku knjigu od strane nadzornog inženjera. | C41: m1 | D41: 200 | F41: =D41*E41 -> 0
A44: A.3.7. | B44: GLETANJE ZIDOVA PODRUMA
B45: Gletanje zidova podruma u dvije ruke te priprema za bojanje. Obračun u m2.
B46: -podrum | C46: m2 | D46: 130 | F46: =D46*E46 -> 0
B47: -podrum -pregradni zidovi porobeton | C47: m2 | D47: 62 | F47: =D47*E47 -> 0
A50: A.3.8. | B50: GLETANJE STROPA PODRUMA
B51: Gletanje stropa podruma u dvije ruke te priprema za bojanje. Obračun u m2.
B52: -podrum -gletanje na toplinskoj izolaciji | C52: m2 | D52: 128 | F52: =D52*E52 -> 0
A55: A.3.9. | B55: ŽBUKANJE UNUTARNJIH ZIDOVA OD BETONA
B56: Dobava i dostava potrebnog materijala, izrada morta, te žbukanje unutarnjih zidova od betona i porobetona jednoslojnom bijelom žbukom debljine 8 mm.
B57: Izmješana žbuka nanosi se ručno ili strojno i nakon 2-6sati izravnava, odnosno fino zaglađuje.
B58: Uključivo potrebna varena mrežica 4 x 4mm na spojevima dva različita materijala.
B59: Obrada špaleta u stavci. Priprema i nanošenje žbuke točno po uputstvu proizvođača žbuke.
B60: U cijenu je uključena radna skela, sve pripremne radnje, obrada špaleta s obaveznom ugradnjom kutne letve od pocinčanog čelika za unutrašnje žbukanje kao i kutni profili od pocinčanog čelika na rubovima izbočenim završecima ili sudarima zidova.
...

Sheet A.4.IZOLATERSKI
A1: A.4. | B1: IZOLATERSKI RADOVI
A2: R.br. | B2: Opis stavke | C2: J.m. | D2: Kol. | E2: Jed.cijena | F2: Uk. Cijena
A5: A.4. | B5: IZOLATERSKI RADOVI
A8: A.4.1. | B8: HIDROIZOLACIJA TEMLJNE PLOČE
B9: Dobava materijala i izrada hidroizolacije poda koja se sastoji od: - jednog hladnnog premaza bitumenskom emulzijom (Resitol ili sl.) - elastomerne zavarljive bitumenske trake kvalitete kao Flex Bitufix GV-5 koja se za podlogu i međusobno učvršćuje ljepljenjem trake plamenikom, sa preklopom najmanje 10cm. Dva sloja po 5mm, ukupno 10mm. Prilikom rada obratiti pažnju na ugrađene instalacije, zaštitne plastične cijevi i sl. Hidroizolaciju treba položiti na posve suhu, ravnu i čistu zaglađenu podlogu.
B10: PODRUM
B11: a) horizontalna postava | C11: m2 | D11: 190 | F11: =D11*E11 -> 0
B12: b) vertiklana postava | C12: m2 | D12: 30 | F12: =D12*E12 -> 0
A15: A.4.2. | B15: VERTIKLANA HIDROIZOLACIJA PODRUMA
B16: a) BITUMENSKA TRAKA S UKOŠKOM OD STAKL.VOALA -vertikalna hidroizolacija sastoji se od: - jednog hladnnog premaza bitumenskom emulzijom (Resitol ili sl.) - elastomerne zavarljive bitumenske trake kvalitete kao Flex Bitufix GV-5 koja se za podlogu i međusobno učvršćuje ljepljenjem trake plamenikom, sa preklopom najmanje 10cm. Dva sloja po 5mm, ukupno 10mm. Prilikom rada obratiti pažnju na ugrađene instalacije, zaštitne plastične cijevi i sl. Hidroizolaciju treba položiti na posve suhu, ravnu i čistu zaglađenu podlogu. | C16: m2 | D16: 145 | F16: =D16*E16 -> 0
B17: b) GEOTEKSTIL -dobava materijala i izrada razdijelnog sloja od geotekstila 300 g/m² s preklopima min. 15cm. Postavlja se između hidroizolacijske trake i toplinske izolacije. | C17: m2 | D17: 145 | F17: =D17*E17 -> 0
B18: c) XPS debljine 15cm -Dobava i ugradnja toplinske izolacije od ploča ekstrudiranog neupojnog polistirena (XPS) ploče na preklop, kakvoće i tehničkih karakteristika klasa negorivosti - teško zapaljiv gustoće 32-35 kg/m3, debljine 15cm s prekriženim i izmaknutim spojevima. | C18: m2 | D18: 145 | F18: =D18*E18 -> 0
B19: d) ČEPASTA FOLIJA -dobava i ugradnja čepasta membrana Guttabeta ili jednakovrijedno proizvedena od HDEP plastike kao zaštite toplinskoj izolaciji. Radove u svim fazama izvesti prema uputsvu proizvođača materijala. | C19: m2 | D19: 145 | F19: =D19*E19 -> 0
A22: A.4.3. | B22: TROKUTASTI KUTNI ULOŽAK
B23: Dobava materijala i izrada trokutastog kutnog uložka od samogasivog ekspandiranog polistirena gustoće 20kg/m3. Postavlja se suho, u svim uglovima na prelazu iz horizontale u vertikalu i prekriva bitumenskom trakom debljine 3mm, s uloškom staklenog voala. Traka je širine 20cm i lijepi se točkasto vrućim bitumenom samo na ekspandirani polistiren. Katete pravokutnog trokuta uloška su duljine 7 cm.
B24: -podrum | C24: m1 | D24: 56 | F24: =D24*E24 -> 0
A27: A.4.4. | B27: HIDROIZLACIJA SOKLA
B28: Dobava materijala i izrada vertikalne hidroizolacije u razini sokla. Hidroizolacija se sastoji od: - hladni premaz bitumenskom emulzijom (Resitol ili sl.) - elastomerne zavarljive bitumenske trake kvalitete kao Flex Bitufix GV-5 koja se za podlogu i međusobno učvršćuje ljepljenjem trake plamenikom, s preklopom najmanje 10cm. Dva sloja po 5mm, ukupno 10mm. Prilikom rada obratiti pažnju na ugrađene instalacije, zaštitne plastične cijevi i sl. Hidroizolaciju treba položiti na posve suhu, ravnu i čistu zaglađenu podlogu. Stavka obuhvaća i izradu detalja na spoju s metalnim profilom sokla.
B29: Obračun po m2 izvedene hidroizolacije sokla. | C29: m2 | D29: 55 | F29: =D29*E29 -> 0
A32: A.4.5. | B32: IZRADA DRENAŽE
B33: Cijenom je obuhvaćena nabava, transport i ugradnja drenažnih cijevi ø15cm na betonsku tajaču prema nacrtima.
B34: Obračun po m1 ugrađene cijevi.
B35: -PODRUM ZGRADE | C35: m1 | D35: 45 | F35: =D35*E35 -> 0
A38: A.4.6. | B38: IZVEDBA SPOJA DRENAŽE NA SLIVNIKE
B39: Cijenom je obuhvaćena nabava, transport i ugradnja betonskih cijevi ø15cm za spoj drenaže sa slivnicima.
B40: Cijenom je obuhvaćeno postavljanje cijevi i brtvljenje spojeva cementim mortom.
B41: Obračun po m’ ugrađene cijevi.
B42: -PODRUM ZGRADE | C42: m1 | D42: 5 | F42: =D42*E42 -> 0
A45: A.4.7. | B45: UGRADNJA "FILTER PASICE"
B46: Nabava materijala, transport i ugradnja "filter pasice" oko butude cca 4m2/1m
B47: Obračun po m2 ugrađenog tekstila.
B48: -PODRUM ZGRADE | C48: m2 | D48: 170 | F48: =D48*E48 -> 0
A51: A.4.8. | B51: HIDROIZOLACIJA TERASA I BALKONA
B52: Dobava materijala i izrada hidroizolacije poda koja se sastoji od: - jednog hladnnog premaza bitumenskom emulzijom (Resitol ili sl.) - elastomerne zavarljive bitumenske trake kvalitete kao Flex Bitufix GV-5 koja se za podlogu i međusobno učvršćuje ljepljenjem trake plamenikom, sa preklopom najmanje 10cm. Dva sloja po 5mm, ukupno 10mm. Prilikom rada obratiti pažnju na ugrađene instalacije, zaštitne plastične cijevi i sl. Hidroizolaciju treba položiti na posve suhu, ravnu i čistu zaglađenu podlogu.
B53: PODRUM
B54: -hidroizolacija podruma -gornja strana -po dogovoru s investitorom | C54: m2 | D54: 165 | F54: =D54*E54 -> 0
B55: PRIZEMLJE
B56: -podovi kupaonica + prijelaz 20cm na zidove | C56: m2 | D56: 14 | F56: =D56*E56 -> 0
B57: KAT
B58: -podovi kupaonica + prijelaz 20cm na zidove | C58: m2 | D58: 24 | F58: =D58*E58 -> 0
...

Sheet A.5.FASADERSKI
A1: A.5. | B1: FASADERSKI RADOVI
A2: R.br. | B2: Opis stavke | C2: J.m. | D2: Kol. | E2: Jed.cijena | F2: Uk. Cijena
A5: A.5. | B5: FASADERSKI RADOVI
B7: Izvođač je dužan radove izvoditi prema specifikaciji proizvođača, općim uvjetima za tu vrstu radova, originalnim materijalom i od proizvođača obučenim i licenciranim izvođačima. Za radove je Izvođač dužan dati garanciju (min 10 god).
A9: A.5.1. | B9: DEMIT FASADA
B10: Dobava materijala i izvedba obloge pročelja od kote +0.15 do kote +10.675 (vrha zgrade) sistemom toplinske zaštite vanjskih zidova (demit fasada).
B11: Podloga mora biti ravna, suha, čista, nesmrznuta i bez ostataka oplatnog ulja s izravnavanjem grubih neravnina.
B12: Demit fasada se postavlja na: - armiranobetonske zidove - armiranobetonske nadvoje
B13: Stavka uključuje toplinsku izolaciju zidova koja se izvodi od ploča kamene vune TERVOL FPL (100 kg/m3), debljina 15cm.
B14: Izolacija dodatno ojačana na mjestima otvora te armirano staklenom mrežicom debljine sloja 0,2cm. Stavka uključuje završnu tankoslojnu akrilnu fasadnu žbuku.
B15: Boja i struktura u dogovoru s investitorom.
B16: Sav materijal, skela i završni kao i prelazni metalni profili prema proizvođačkoj specifikaciji uključeni u cijenu.
B17: Obračun po m2 izvedenog pročelja. U stavku uključene špalete i podgledi.
B18: Fasadni sustav kao StoTherm Classic.
B19: U stavku uključne dobava i montaža skele.
B20: a) debljina toplinske izolacije 15cm:
B21: -fasada -svijetla boja | C21: m2 | D21: 398 | E21: 78 | F21: =D21*E21 -> 31044
B22: b) debljina toplinske izolacije 10cm:
B23: -fasada -SVJETLI boja (balkoni) | C23: m2 | D23: 54 | E23: 69 | F23: =D23*E23 -> 3726
B24: -fasada -SVJETLA boja (balkoni) -podgled | C24: m2 | D24: 44 | E24: 69 | F24: =D24*E24 -> 3036
B25: Nudimo: STO THERM MINERAL sustav
B26: Napomena: fasadna skela nije u cijeni
A27: A.5.2. | B27: DEMIT FASADA -SOKL
B28: Isto kao prethodna stavka, ali izvedba završne obrade pročelja od kote -2.975 do kote +0.15 sistemom toplinske zaštite sokla vanjskih zidova.
B29: Stavka uključuje toplinsku izolaciju sokla koja se izvodi od ekstrudiranog polistirena (XPS debljine 15cm). Ploče od XPS-a se polažu preko vertikalne hidroizolacije.
B30: Završni sloj od plemenite epoxy žbuke - nanosi se originalnim materijalom i alatom u svemu prema proizvođačkoj specifikaciji.
B31: Boja i struktura u dogovoru s projektantom.
B32: Fasadni sustav kao StoTherm Classic.
B33: Obračun po m2 izvedenog pročelja.
B34: U stavku uključne dobava i montaža skele.
B35: a) debljina toplinske izolacije 15cm:
B36: -fasada | C36: m2 | D36: 47 | E36: 76 | F36: =D36*E36 -> 3572
B37: b) na stiroporu d=2cm:
B38: -fasada | C38: m2 | D38: 91 | F38: =D38*E38 -> 0
B39: -fasada -podgled garaže | C39: m2 | D39: 35 | F39: =D39*E39 -> 0
A42: A.5.3. | B42: FASADNI PANELI -kao FUNDERMAX
B43: Dobava i postava materijala za izvedbu obloge ventilirane fasade kao FUNDERMAX compact NT ploča -obostrano oplemenjene, na tipsku potkonstrukciju. Na gornjim i donjim rubovima fasade se postavlja aluminijska mrežica.
B44: Upotrebljavaju se kao FUNDERMAX compact NT ploče izvedene na bazi visokotlačnog prešanog laminata debljine 6mm u dekoru po izboru investitora.
B45: Srednjica ploče izrađena je od visoko kvalitetnih celuloznih papira oplemenjenih fenolnim smolama. Vanjski i unutarnji dekorativni sloj zaštićeni su akrilno-poliuretanskim smolama po NT tehnoloziji koja svojom strukturom štiti ploče od UV zraka, te Euroklase B-s2,d0 (EN 13501-1) vatrootpornosti.
B46: Izolacija se izvodi od kamene vune kaširane crnim voalom, na koju još dolazi paropropusna-vodonepropusna folija. Ploče se učvršćuju na aluminijsku potkonstrukciju ljepljenjem.
...

Sheet A.6.LIMARSKI
A1: A.6. | B1: LIMARSKI RADOVI
A2: R.br. | B2: Opis stavke | C2: J.m. | D2: Kol. | E2: Jed.cijena | F2: Uk. Cijena
A5: A.6. | B5: LIMARSKI RADOVI
A8: A.6.1. | B8: OPŠAV NADOZIDA KROVA
B9: Dobava, izrada i montaža profiliranog opšava (klupčice) nadozida ravnog krova (zaštita hidroizolacije), od al lima d=0.62 mm, razvijene širine 66cm, uključivo sve elemente spajanja i brtvljenja te vodonepropusni spoj s nadozidom.
B10: Plastificiranje lima u boji po dogovoru s investotorm uključiti u cijenu.
B11: Obračun po m1 izvedenog opšava sa plastificiranjem.
B12: -atika krova razvijene širine 66cm. | C12: m1 | D12: 50 | F12: =D12*E12 -> 0
A15: A.6.2. | B15: OPŠAV I OBLOGA DIMNJAKA
B16: Dobava materijala i ugradnja opšava dimnjaka i instalacijskih otvora od pocinčanog plastificiranog lima d=1,0mm, razvijene širine 66cm.
B17: U tonu po izboru investitora.
B18: U cijeni je uključena radionička izrada, prijevoz i montaža limarije, sve pomoćne konstrukcije i nosači, sva učvršćenja s horizontalama, te spojevi zakovicama i lemljenjem.
B19: Uključivo sve elemente spajanja i brtvljenja te vodonepropusni spoj.
B20: Obračun po m1 izvedenog opšava.
B21: -opšav dimnjaka | C21: m1 | D21: 18 | F21: =D21*E21 -> 0
B22: -obloga dimnjaka | C22: m2 | D22: 22 | F22: =D22*E22 -> 0
B23: -opšav krovne kupole | C23: m1 | D23: 7.2 | F23: =D23*E23 -> 0
A26: A.6.3. | B26: KAPA DIMNJAKA
B27: Dobava materijala i ugradnja kape dimnjaka i instalacijskih otvora, od pocinčanog plastificiranog lima.
B28: Opseg dimnjaka i instalacijskih otvora do 2,8m
B29: U tonu po izboru investitora.
B30: U cijeni je uključena radionička izrada, prijevoz i montaža limarije, sve pomoćne konstrukcije i nosači, sva učvršćenja s horizontalama, te spojevi zakovicama i lemljenjem.
B31: Obračun po kompletu izvedenog opšava. | C31: kom | D31: 7 | F31: =D31*E31 -> 0
A34: A.6. | B34: LIMARSKI RADOVI UKUPNO | F34: =SUM(F6:F33) -> 0

Sheet A.7.BRAVARSKI I STOLARSKI
A1: A.7. | B1: BRAVARSKI I STOLARSKI RADOVI
A2: R.br. | B2: Opis stavke | C2: J.m. | D2: Kol. | E2: Jed.cijena | F2: Uk. Cijena
A5: A.7.1. | B5: BRAVARSKI RADOVI
A8: A.7.1.1. | B8: GARAŽNA ROLO VRATA
B9: Dobava i ugradnja garažnih vrata u podrumu.
B10: Vanjska garažana vrata -svu opremu predvidjeti za vanjsku upotrebu.
B11: Rolo pocinčana čelična rešetkasta vrata.
B12: -prozračnost 80%, pocinčane čelične rešetke TUB 120, izrađene iz ravnih čel. pocinčanih cijevi promjera 18mm, debljine 1mm povezane poveznicama visine 120mm
B13: -potreban slobodan prostor iznad vrata za rolo 500mm
B14: -potreban slobodan prostor bočno s obje strane za vodilicu min. 80 mm
B15: -elektromotor centralni sa elektrokočnicom
B16: -centralni motor 220V, 1-fazni otvaranje pomoću tastera na ključ uz prisustvo osobe i na daljinske upravljače -uključivo kontolna kutija za daljinske upravljače
B17: -brzina otvaranja i zatvaranja vrata v=0,25m/s
B18: -deblokada motora u slučaju nestanka struje ili kvara
B19: -vrata u skladu sa svim sigurnosnim standardima EU i RH
B20: Otvaranje vrata na daljinski upravljač. Motor i mehanizam uključeno u cijenu.
... B22: Prije narudžbe i montaže provjeriti sve s investitorom i provjeriti mjere u stvarnosti.
B23: -širina x visina svjetlog otvora 550x217.5cm | C23: kom | D23: 1 | F23: =D23*E23 -> 0
A26: A.7.1.2. | B26: VANJSKA PUNA VRATA -PODRUM
B27: Dobava i ugradnja punih vanjskih vrata zaokretna.
B28: Vrata od plastif. AL profila, ispuna: alu panel d=3cm, s prekinutim toplinskim mostom.
B29: Vratno krilo puno od plast.alu.profila, boja po odabiru investitora.
B30: Uključivo cilindar bravu, priprema za otvaranje na portafon i žeton/token.
B31: Uključivo pumpa za automatsko zatvaranje vrata.
B32: Obračun po komadu ugrađenih vrata komplet (obrađena, obojena i opremljena).
B33: Ugradnja u pregradni zid od porobetona d=10cm
B34: Protupožarna svojstva EI 30-C-Sm
B35: -vrata svijetlih dim 75x220 -lijeva | C35: kom | D35: 1 | F35: =D35*E35 -> 0
A38: A.7.1.3. | B38: VANJSKA PUNA VRATA -PODRUM -SPREMIŠTE
B39: Dobava i ugradnja punih vanjskih vrata zaokretna.
B40: Vratno krilo puno od plast.alu.profila, boja po odabiru investitora. Kvaka Hoppe, polirani aluminij, cilindar brava.
B41: Obračun po komadu ugrađenih vrata komplet (obrađena, obojena i opremljena).
B42: Ugradnja u pregradni zid od porobetona d=10cm
B43: Protupožarna svojstva EI 30-C
B44: -vrata svijetlih dim 80x210 -lijeva | C44: kom | D44: 2 | F44: =D44*E44 -> 0
B45: -vrata svijetlih dim 80x210 -desna | C45: kom | D45: 2 | F45: =D45*E45 -> 0
A48: A.7.1.4. | B48: VANJSKA PUNA VRATA -BALKON KAT
B49: Dobava i ugradnja punih vanjskih vrata zaokretna.
B50: Vratno krilo puno od plast.alu.profila, boja po odabiru investitora. Kvaka Hoppe, polirani aluminij, cilindar brava.
B51: Obračun po komadu ugrađenih vrata komplet (obrađena, obojena i opremljena).
...

Sheet A.8.GIPSKART. I SOBOSL.
A1: A.8. | B1: GIPSKARTONSKI I SOBOSLIKARSKI RADOVI
A2: R.br. | B2: Opis stavke | C2: J.m. | D2: Kol. | E2: Jed.cijena | F2: Uk. Cijena
A5: A.8.1. | B5: GIPSKARTONSKI RADOVI
A8: A.8.1.1. | B8: GK ZID 10cm
B9: Dobava i montaža pregradnog zida sistem kao Knauf W112, pregradni zid- obostrano po dvije vlagootporne ploče. Ukupna debljina 100mm.
B10: Obračun po m2 izvedenog zida.
B11: Visina zida do bet ploče 310.5cm
B12: a) prizemlje | C12: m2 | D12: 192 | E12: 43 | F12: =D12*E12 -> 8256
B13: b) kat | C13: m2 | D13: 182 | E13: 43 | F13: =D13*E13 -> 7826
B14: c) uvučeni kat | C14: m2 | D14: 129 | E14: 43 | F14: =D14*E14 -> 5547
A17: A.8.1.2. | B17: GK SPUŠTENI STROP
B18: Dobava materijala i izvedba spuštenog stropa sistem Knauf od punih GK vlagootpornih ploča.
B19: Ploče ravne na tipskoj čeličnoj podkonstrukciji, djelomično kaskadno, ovješeno o postojeću krovnu betonsku ploču.
B20: Visina ovjesa prosječno do 20cm. Obračun po m2 izvedene površine (za plohe preko 30 cm širine).
B21: Pozicija -spušteni strop na mjestu stropne izolacije terase i balkona
B22: -prizemlje -horizontalno | C22: m2 | D22: 26 | E22: 38 | F22: =D22*E22 -> 988
B23: -prizemlje -vertikalno h=20cm | C23: m1 | D23: 2.8 | E23: 38 | F23: =D23*E23 -> 106.4
B24: -kat -horizontalno | C24: m2 | D24: 47 | E24: 38 | F24: =D24*E24 -> 1786
B25: -kat -vertikalno h=20cm | C25: m1 | D25: 3 | E25: 38 | F25: =D25*E25 -> 114
A28: A.8.1.3. | B28: GK OBLOGE INSTALACIJSKIH KANALA
B29: Dobava i montaža obloge instalcijskih kanala u visini etaže 3.105m sistem kao Knauf W112- jednostrano dvije vlagootporne ploče. Ukupna debljina 75 mm.
B30: Obračun po m2 obloge.
B31: -prizemlje | C31: m2 | D31: 25 | E31: 30 | F31: =D31*E31 -> 750
B32: -kat | C32: m2 | D32: 35 | E32: 30 | F32: =D32*E32 -> 1050
B33: -uvučeni kat | C33: m2 | D33: 32 | E33: 30 | F33: =D33*E33 -> 960
A36: A.8.1.4. | B36: OJAČANJE U ZIDU
B37: Dobava i ugradnja ukruta za ojačanje od OSB ploča min.debljine 2cm za ovješenje opreme. Po dogovoru s investitorom.
B38: Obračun po m2 izvedenog ojačanja.
B39: -prizemlje u visini od 140 do 180cm | C39: m2 | D39: 20 | E39: 16 | F39: =D39*E39 -> 320
B40: -prizemlje u visini od 160 do 270cm | C40: m2 | D40: 7 | E40: 16 | F40: =D40*E40 -> 112
B41: -kat u visini od 140 do 180cm | C41: m2 | D41: 15 | E41: 16 | F41: =D41*E41 -> 240
B42: -kat u visini od 160 do 270cm | C42: m2 | D42: 7 | E42: 16 | F42: =D42*E42 -> 112
B43: -uvučeni kat u visini od 140 do 180cm | C43: m2 | D43: 11 | E43: 16 | F43: =D43*E43 -> 176
B44: -uvučeni kat u visini od 160 do 270cm | C44: m2 | D44: 3.5 | E44: 16 | F44: =D44*E44 -> 56
A47: A.8.1.5. | B47: OBLOGA GEBERIT ELEMENATA
B48: Dobava materijala i izrada obloge geberita i instalacijskog kanala sa od gips-kartonskih vodoodbojnih "Knauf" ploča u dva sloja na metalnu nosivu pocinčanu podkonstrukciju -sistem W112 -jednostrano dvije zelene ploče.
B49: Između podkonstrukcije i gips-kartonskih ploča postaviti PE foliju te ugraditi sloj termoizolacije od 5,0 cm mineralne vune između profila.
B50: U cijeni stavke sav potreban ovjes, pribor, spojna sredstva, uglovni profil na sudaru s obodnim zidovima i izrezivanje svih potrebnih otvora, bandažiranje i zapunjavanje sljubnica te gletanje pune površine ploča.
B51: Sanitarne jedinice obložiti impregniranim gips-kartonskim "Knauf" pločama (H2 13) otpornim na vlagu. Izvedba strogo prema uputi proizvođača.
B52: Visina obloge do 120cm.
...

Sheet A.9.PODOPOLAGAČKI
A1: A.9. | B1: PODOPOLAGAČKI RADOVI
A2: R.br. | B2: Opis stavke | C2: J.m. | D2: Kol. | E2: Jed.cijena | F2: Uk. Cijena
A5: A.9.1. | B5: KERAMIČARSKI RADOVI
B7: OPĆI UVJETI
B9: Sve horizontalne i vertikalne reške moraju biti posve ravne, iste širine i dobro ispunjene. Cijela ploha mora biti ravna.
B10: Kvaliteta pločica treba odgovarati važećim standardima: HRN B.D1.301, 310, 320, 322, 325, 330, 334, 335, 460 HRN B.D8.001, 050, 060, 080, 090, 302, 307
B11: Prilikom davanja ponude izvođač je dužan dati uzorke pločica i mase za fugiranje.
B12: U jediničnim cijenama sadržane su sve radnje i dobava zajedno s veznim materijalaom kao i rad na izrezivanju pločica za razne instalacije ili sl.
B13: U slučaju kada kod rada neka pločica pukne ima se zamijeniti cijelom bez posebne naplate. Obračun opločenja vrši se po m2 razvijene površine opločenja.
B14: Jedinična cijena mora sadržavati: - sav potreban materijal; pločice, ljepilo i masa za fugiranje - kutne lajsne na otvorenim uglovima (al.profil 5mm) al.lajsne na prijelazu podova te dilatacijone reške koje će se izvoditi elastičnim silikonom. - sav potreban rad
B15: - transportne troškove - čišćenje prostorija po završenom radu sa uklanjanjem šute i otpada uključivo odvoz na deponiju - popravak štete učinjene na svojim ili tuđim radovima pri radu iz nepažnje. - potrebnu radnu skelu
B17: OPĆA NAPOMENA: Prilikom naručivanja pločica izvođač treba izvršiti izmjeru, napraviti izračun, naručiti potrebnu količinu te uvećati za određeni postotak zbog otpada, lomova, rezanja i sl.
B18: Odvojeno iskazati cijenu rada i materijala (materijal - nabavna cijena pločica bez PDV - ukoliko nije naznačena kao mjerodavna će se uzeti cijena pločica iz troškovnika te će se u slučaju razlike u nabavnoj cijeni jedinična cijena korigirati za razliku.
B19: Kod izvedbe zidnog opločenja u jediničnu cijenu pojedine stavke ukalkulirati i brtvljenje sudara keramičkog opločenja s dovratnicima, sanitarnim uređajima, oblogom druge vrste i sl. silikonskim kitom.
B20: Obračun prema stvarno izvedenoj jedinici mjere - neće se priznati obračun radova s faktorom.
... B30: Prije narudžbe provjeriti vrstu pločica s projektantom, a količinu uskladiti sa stvarnim stanjem i ukalkulirati potrebnu btto količinu.
A33: A.9.1.1. | B33: KERAMIČKE PLOČICE
B34: Dobava i postava podnih keramičkih pločica koristeći fleksibilno ljepilo na bazi cementa tipa kao Sika Ceram-255 Starflex LD ili jednakovrijedno, klase C2TES1 prema HRN EN 12002 / 12004.
B35: Fugiranje koristeći masu za fugiranje na bazi cementa tipa kao Sika Ceram CleanGrout ili jednakovrijednog, obogaćenu sa polimerom tipa kao Sika Ceram LatexGrout ili jednakovrijednim, klase CG2 prema HRN EN 13888.
B36: Na kutovima i oko prodora fuge se zapunjavaju sa sanitanim silikonskim brtvilom na bazi acetatnog zamreženja tipa kao Sanisil ili jednakovrijedan.
B37: Pločice po cijeni do 300 kn fco gradilišta.
B38: PRIZEMLJE
B39: KERAMIKA KUPAONICE
B40: - podne pločice | C40: m2 | D40: 13 | F40: =D40*E40 -> 0
B41: - zidne pločice h=220cm | C41: m2 | D41: 66 | F41: =D41*E41 -> 0
B42: KERAMIKA KUHINJA, GOSPODARSTVO
B43: - podne pločice | C43: m2 | D43: 23 | F43: =D43*E43 -> 0
B44: - sokl h=8cm | C44: m1 | D44: 22 | F44: =D44*E44 -> 0
B45: - zidne pločice | C45: m2 | D45: 7.6 | F45: =D45*E45 -> 0
B46: KAT
B47: KERAMIKA KUPAONICE
B48: - podne pločice | C48: m2 | D48: 23 | F48: =D48*E48 -> 0
B49: - zidne pločice h=220cm | C49: m2 | D49: 88 | F49: =D49*E49 -> 0
B50: KERAMIKA KUHINJA, GOSPODARSTVO
B51: - podne pločice | C51: m2 | D51: 19 | F51: =D51*E51 -> 0
B52: - sokl h=8cm | C52: m1 | D52: 26.3 | F52: =D52*E52 -> 0
B53: - zidne pločice | C53: m2 | D53: 7.8 | F53: =D53*E53 -> 0
B54: UVUČENI KAT
B55: KERAMIKA KUPAONICE
B56: - podne pločice | C56: m2 | D56: 12 | F56: =D56*E56 -> 0
...

Sheet B.GRAĐ.OBRT.VANJSKI
A1: B. | B1: GRAĐEVINSKO-OBRTNIČKI RADOVI - VANJSKI
A2: R.br. | B2: Opis stavke | C2: J.m. | D2: Kol. | E2: Jed.cijena | F2: Uk. Cijena
B4: OPĆI UVJETI UZ TROŠKOVNIK
B6: Uvodne napomene: Cijena za sve stavke mora uključivati sav dobavu, transport i montažu sa svim materijalom i pomoćnim materijalom, radom i horizontalnim i vertikalnim transportom na gradilištu potrebne za dovršenje radova do potpune funkcionalne ili estetske gotovosti. Cijena za sve stavke mora biti ponuđena za viđeno stanje na predmetnoj lokaciji. Cijena izvođenja betonskih i čeličnih konstrukcija mora obuhvatiti i razrede izloženosti konstrukcija koji se mogu pojaviti na unutar teritorija Republike Hrvatske.
B7: Sva demontirana oprema i svi dijelovi konstrukcije i otpad nastao uklanjanjem građevina ili dijelova građevina se zbrinjava sukladno važečim propisima Republike Hrvatske. Sav materijal, opremu i uređaje kod dopreme na gradilište, a prije ugradnje, izvođač je dužan upisati u dnevnik građenja, te nadzornom organu dostaviti ateste i uvjerenja o kvaliteti, kao i garancijske listove i tehničku dokumentaciju sa podacima o uređajima i opremi. Bez istog materijali, oprema i uređaji ne smiju biti ugrađeni.
A9: B.1. | B9: PRIPREMNI RADOVI
A12: B.1.1. | B12: PRIPREMNI RADOVI
B13: Organizacija i priprema gradilišta, koja obuhvaća: Dobava, postava i montaža ograde oko gradilišta.
B14: Dobava, postava i montaža metalnih ploča na bravarskoj konstrukciji: ploča sa svim potrebnim informacijama:.
B15: (investitor, projektant, izvođač, nadzor, broj građevne dozvole itd.) te ploča sa znakovima upozorenjana.
B16: Dobava, postava i montaža kontejnera za gradilište - uredski kontejner standardnih dimenzija cca 6,0x2,4m postavljen na oslonce 15,0cm od podloge.
B17: Dobava i postava montažnih priručnih kemijskih WC kabina za potrebe gradilišta. Izrada sheme organizacije gradilišta.
B18: U stavci uključeno osiguranje privremenog priključka struje i vode, izrada plana transportnih putova i sheme gradilišta, odnosno svu potrebnu pripremu i predradnje za pravovaljano i sigurno izvođenje radova gradnje i radova uklanjanja. | C18: komplet | D18: 1 | F18: =D18*E18 -> 0
A21: B.1.2. | B21: UKLANJANJE RASLINJA
B22: Uklanjanje raslinja, grmlja i šikarja promjera do 10cm, vađenje korijenja, utovar i prijevoz na deponiju. Pregledati teren radi stvarnog stanja. Obračun po m2 stvarno iskrčene površine. | C22: m2 | D22: 615 | F22: =D22*E22 -> 0
A25: B.1. | B25: PRIPREMNI RADOVI UKUPNO | F25: =SUM(F10:F24) -> 0
A28: B.2. | B28: ZEMLJANI RADOVI - ISKOPI
A31: B.2.1. | B31: ISKOP HUMUSA
B32: Ova stavka obuhvaća:
B33: a) otkop površinskog sloja u debljini 20cm,
B34: b) utovar otkopanog materijala u vozilo, te prijevoz i razastiranje na deponiji na udaljenosti do 10km,
B35: c) ručni otkop uz komunalne instalacije.
B36: Obračun po m3 otkopanog materijala mjereno u sraslom stanju prema poprečnim profilima. Dio (50m3) se privremeno deponira na gradilištu za kasnije nasipavanje.
B37: a) samo iskop ukupno | C37: m3 | D37: 125 | F37: =D37*E37 -> 0
B38: b) prijevoz iskopanog mat.na deponiju do 10km | C38: m3 | D38: 75 | F38: =D38*E38 -> 0
A41: B.2.2. | B41: ŠIROKI ISKOP
B42: Široki iskop tla C/D kategorije u sloju min. 20cm. Iskop vršiti isključivo strojno, a ručno samo tamo gdje strojevi to ne bi mogli obaviti na zadovoljavajući način. Obračun po m3 stvarno izvršenog iskopa.
B43: Iskop se izvodi strojno: bagerima u zemljanom sloju, i drugim strojevima koje zahtijeva kategorija terena i pneumatskim čekićima i ostalim strojevima u stijenskoj masi.
B44: U cijenu uključiti sve potrebne radove: iskop, crpljenje procjedne vode.
B45: Iskopani materijal privremeno odložiti na stranu (privremeno odlagalište na gradilištu) radi eventualne potrebe korištenja iskopanog materijala za zatrpavanje. Utovar i odvoz u posebnoj stavci.
B46: Obračun po m3 iskopa u sraslom stanju.
B47: -parkiralište i rampa | C47: m3 | D47: 340 | F47: =D47*E47 -> 0
B48: -zelene površine | C48: m3 | D48: 192 | F48: =D48*E48 -> 0
A51: B.2.3. | B51: ZATRPAVANJE
B52: Zatrpavanje oko temelja zemljom iz iskopa, a nakon skidanja oplate temelja podrum. Modul stišljivosti Ms=50Mpa. Obračun po m3 zemlje u zbijenom stanju. | C52: m3 | D52: 100 | F52: =D52*E52 -> 0
A55: B.2.4. | B55: ODVOZ ZEMLJE NA TRAJNU DEPONIJU
B56: Odvoz zemlje na trajnu deponiju. U cijenu stavke uključeno je ručni ili strojni utovar, prijevoz, istovar, sve naknade i troškovi gradske deponije. Obračun po m3 zemlje u rastresitom stanju. | C56: m3 | D56: 432 | F56: =D56*E56 -> 0
A59: B.2.5. | B59: OBNOVA ISKOLČENJA OSI
B60: Obnova iskolčenja osi i profila trase putem geodetske radne organizacije osiguranjem glavnih točaka. Iskolčenje obuhvaća sve geodetska mjerenja tj. prenošenje podataka sa projekta na teren, osiguranje osi iskolčenja trase, profiliranje, obnavljanje i održavanje iskolčenih oznaka na terenu za sve vrijeme građenja odnosno do predaje radova investitoru. U cijenu koštanja ulaze svi gore navedeni radovi, potrebni materijali i prijevoz vezan uz ovaj rad. Obračun po m1 iskolčene trase i m2 iskolčene površine.
B61: Obračun po m2-površina vanjskog uređenja | C61: m2 | D61: 612 | F61: =D61*E61 -> 0
...

Sheet C.VODOVOD I KANALIZACIJA
D2: Gradečak desni 4, 10000 Zagreb
E3: OIB 06323248263
E4: mob. 099/788 7887
B7: INVESTITOR:
B8: Josip Drinovac, Gornji Bukovac 150, 10000 Zagreb
B9: i Nina Drinovac, Gundulićeva ulica 61, 10000 Zagreb
B12: NAZIV GRAĐEVINE:
B13: STAMBENA ZGRADA
B15: LOKACIJA:
B16: Gornji Bukovac bb, Zagreb
B17: k.č.br. 2269, k.o. Remete
A20: R E K A P I T U L A C I J A
A21: INSTALACIJA VODOVODA I ODVODNJE
A23: A | B23: PRIPREMNI RADOVI | F23: =F86 -> 0
A25: B | B25: GRAĐEVINSKI RADOVI | F25: =F132 -> 0
A27: C | B27: VANJSKI VODOVOD | F27: =F170 -> 0
A29: D | B29: VANJSKA ODVODNJA | F29: =F240 -> 0
A31: E | B31: UNUTARNJI VODOVOD | F31: =F312 -> 0
A33: F | B33: UNUTARNJA ODVODNJA | F33: =F432 -> 0
A35: G | B35: SANITARNI UREĐAJI | F35: =F485 -> 0
A37: H | B37: OSTALI RADOVI | F37: =F530 -> 0
A39: I | B39: NEPREDVIĐENI RADOVI | F39: =F538 -> 0
B44: UKUPNO | F44: =SUM(F23:F41) -> 0
B46: PDV 25 % | F46: =F44*0.25 -> 0
B48: SVEUKUPNO Kn | F48: =SUM(F44:F46) -> 0
B59: INSTALACIJE VODOVODA I ODVODNJE | F59: TD: 17822-102
F60: ZOP: GP 2/22
A62: r.b. | B62: Opis stavke | C62: jed. mj. | D62: Količina | E62: Jedinična cijena | F62: Ukupna cijena
B64: TROŠKOVNIK INSTALACIJA VODOVODA I ODVODNJE
A66: OPĆE NAPOMENE: Prije davanja ponude ponuđač može pregledati projekt te mjesto izgradnje i upisati radove koji eventualno nisu obuhvaćeni ovim troškovnikom, a smatra da su bitni za izvođenje. Izvođač je prilikom nuđenja obavezan provjeriti sve količine i radove vezane za kvalitetno izvođenje instalacija vodovoda i odvodnje u potpunosti. Ukoliko izvođač smatra da u troškovniku nedostaju radovi ili da količine nisu dovoljne za izvođenje instalacija u potpunosti, obavezan je iste unijeti u ponudu. Naknadna potraživanja izvođača neće se odobriti. Stavke sadrže nabavu, dopremu, montažu i ugradnju sa svim potrebnim radom, strojevima, alatom kao i materijalom i priborom. Radove na vodovodu, kanalizaciji i drugim uređajima potrebno je izvoditi uz striktno poštivanje pravila i normi za kvalitetno izvršenje radova kao i zaštite na radu, a sve u dogovoru s nadzornim inženjerom, projektantom, nadležnim prestavnicima komunalnih instalacija, geomehaničkim inženjerom i inženjerom konstrukcije kod otežanih uvjeta izvođenja. Ukoliko se tijekom građenja pojavi opravdana potreba za određenim odstupanjima ili manjim izmjenama projekta, Izvođač je dužan za to prethodno pribaviti suglasnost Nadzornog inženjera. Veće izmjene i odstupanja od projektiranog rješenja mogu se provesti samo uz odobrenje Projektanta i suglasnost Investitora, te pribavljanjem dopune građevne dozvole na nastalu promjenu ukoliko su odstupanja takve prirode. "Nabava" ("dobava") obuhvaća troškove utovara, istovara, transporta do izvoditeljevog stovarišta – privremene deponije, te carinske i sve druge zakonom propisane pristojbe i poreze. "Ugradnja", ("ugradba") obuhvaća utovar na izvoditeljevom stovarištu – privremenoj deponiji, lokalni transport i istovar na mjestu ugradnje, kao i sve radove, materijal, te opremu potrebnu za potpuno izvršenje posla. "Izrada" ("izvedba") obuhvaća radove na nabavi i ugradnji. "Odvoz na trajnu deponiju" obuhvaća utovar, transport do trajne deponije, istovar, razastiranje, planiranje i sve eventualne ostale radove na deponiji preme uvjetima vlasnika deponije, te taksu (naknadu) za deponiranje. Sve radove izvoditi u skladu s tehničkim uvijetima koji su sastavni dio ove projektne dokumentacije. Napomena // Predmetni troškovnik je izrađen u svrhu procjene troškova građenja. Troškovnik za ugovaranje i odabir izvođača izradit će se u sklopu izvedbenog projekta.
A68: A | B68: PRIPREMNI RADOVI
A70: A.1 | B70: ISKOLČENJE VANJSKE TRASE VODOVODA
B71: Iskolčenje trase vodovoda prenošenjem podataka iz projekta i osiguranje iskolčenja osi, te geodetsko praćenje svih radova na izvedbi mreže vodovoda. Opseg radova mora u svemu zadovoljiti potrebe građenja, kontrole radova i obračuna. Obračun po kompletu.
C72: kpl. | D72: 1 | F72: =$D72*E72 -> 0
A74: A.2 | B74: ISKOLČENJE VANJSKE TRASE KANALIZACIJE
B75: Iskolčenje trase kanalizacije prenošenjem podataka iz projekta i osiguranje iskolčenja osi, te geodetsko pračenje svih radova na izvedbi kanalizacije. Opseg radova mora u svemu zadovoljiti potrebe građenja, kontrole radova, obračuna i drugoga. Obračun po kompletu.
C76: kpl. | D76: 1 | F76: =$D76*E76 -> 0
A78: A.3 | B78: ISKOLČENJE UNUTARNJE TRASE VODOVODA
B79: Označavanje i iskolčenje trase instalacije vodovoda sa nanošenjem najvažnijih točaka. Obračun po kompletu.
C80: kpl. | D80: 1 | F80: =$D80*E80 -> 0
...

Sheet D.ELEKTROINST.RADOVI
A1: ELEKTROINSTALACIJE
A3: R.br. | B3: Opis stavke | C3: Jed. | D3: Količina | E3: Cijena(HRK) | F3: Ukupno (HRK)
B5: Troškovnikom se predviđa nabava potrebnog materijala, postavljanje kako je to navedeno u pojedinim stavkama, ispitivanje i puštanje u ispravan rad.
A7: 1. | B7: VANJSKI PRIKLJUČAK
A8: 1. | B8: Vanjski priključak izvesti podzemno s novog KRO sa četiri (4) vodna polja, kojega je potrebno napojti s NN mreže kabelom NAYY-O 4x70SM+1,5RE 0,6/1 (1,2) kV. Napajanje mjesta priključenja je: 1TS 1303, Gornji Bukovac III odvojak SK 5. Priključak građevine od KRO do KPO izvesti kabelom NAYY-O 4x70SM+1,5RE 0,6/1 (1,2) kV s vodnog polja 2. KPO postaviti na fasadu građevine pored ulaza (predviđeno glavnim projektom). U KPO ugraditi opremu prema uvjetima distributera.Isporuka potrebnog materijala i rad biti će specifiran u el. tehničkom rešenju nadležnog el. distributivnog poduzeća prema konačnoj el. energetskoj suglasnosti. Ormar KRO i KPO sa svom potrebnom opremom i spojnim materijalom je u nadležnosti | C8: kpl | D8: 1 | E8: ISPORUČUJE HEP
A10: 2. | B10: Isporučiti, montirati u zid i spojiti mjerni ormar EMO. Ormar mora biti izrađen od dekapiranog lima s bravicom na vratima. Ormar mora sadržavati osim specificirane opreme, N i PE sabirnice, te sitni spojni i montažni materijal. U ormar se ugrađuje sljedeća oprema: | C10: kom | D10: 1 | F10: 2500
B11: -uređaj za komunikaciju | C11: kom | D11: 1 | E11: ISPORUČUJE HEP
B12: -monofazno električno brojilo | C12: kom | D12: 1 | E12: ISPORUČUJE HEP
B13: -trofazno električno brojilo | C13: kom | D13: 1 | E13: ISPORUČUJE HEP
B14: -odvodnik prenapona klase II, 0,5 kV | C14: kom | D14: 4 | F14: =D14*E14 -> 0
B15: -osigurač NVO 00 35 A | C15: kom | D15: 13 | F15: =D15*E15 -> 0
B16: -postolje osigurača | C16: kom | D16: 5 | F16: =D16*E16 -> 0
B17: - ostali montažni materijal za potrebe razvoda i zaštite (vodovi, odgovarajuće stezaljke i sl.) | C17: kom | D17: 1 | F17: =D17*E17 -> 0
B18: Komplet ormar EMO sa svim potrebnim radom i materijalom. | C18: kpl | D18: 1 | F18: =D18*E18 -> 0
B20: Ukupno vanjski priključak | F20: =F18 -> 0
A22: 2. | B22: RAZVODNI ORMARI
A23: 1. | B23: Isporučiti, montirati u zid i spojiti razdjelnicu RZ. Razdjelnica treba biti izrađena od dekapiranog lima zaštičena bojanjem ili plastificiranjem s bravicom korisnika Razdjelnica mora sadržavati osim specificirane opreme, N i PE sabirnice, te sitni spojni i montažni materijal. Razdjelnica je sa slijedećom opremom:
B24: Limitator OSO 1x25 - isporučuje HEP | C24: kom | D24: 1 | E24: ISPORUČUJE HEP
B25: -FID (RCD) strujna zaštitna sklopka 40 A / 30 mA / 2P | C25: kom | D25: 1
B26: -automatski prekidači B 16/1 | C26: kom | D26: 4
B27: -automatski prekidači B 10/1 | C27: kom | D27: 9
B28: -automatski prekidači C 25/1 | C28: kom | D28: 1
B29: -odvodnik prenapona 20kV, 255V | C29: kom | D29: 1
B30: -stubišni automat | C30: kom | D30: 2
B31: -luksomat | C31: kom | D31: 1
B32: -sklopka 1-0-2 16A 1P | C32: kom | D32: 1
B33: - ostali montažni materijal za potrebe razvoda i zaštite (vodovi, odgovarajuće stezaljke i sl.) | C33: kom | D33: 1
B34: Komplet razdjelnica RZ sa svim potrebnim radom i materijalom. | C34: kom | D34: 1 | F34: =D34*E34 -> 0
A36: 2. | B36: Isporučiti, montirati u zid i spojiti razdjelnicu RS1. Razdjelnicu čini univerzalni kućni ugradni razdjelnik "Schrack" sa vratima ili sličan. Razdjelnica mora sadržavati osim specificirane opreme, N i PE sabirnice, te sitni spojni i montažni materijal. Razdjelnica je sa slijedećom opremom:
B37: Limitator OSO 1x25, 2x20A - isporučuje HEP | C37: kom | D37: 1 | E37: ISPORUČUJE HEP
B38: -FID (RCD) strujna zaštitna sklopka 40 A / 30 mA / 4P | C38: kom | D38: 1
B39: -FID (RCD) strujna zaštitna sklopka 25 A / 30 mA / 4P | C39: kom | D39: 1
B40: -kombinirana zaštitna sklopka B 20 A / 30 mA | C40: kom | D40: 1
B41: -automatski prekidači B 25/1 | C41: kom | D41: 1
B42: -automatski prekidači B 20/1 | C42: kom | D42: 1
B43: -automatski prekidači B 16/1 | C43: kom | D43: 13
B44: -automatski prekidači B 16/3 | C44: kom | D44: 1
B45: -automatski prekidači B 10/1 | C45: kom | D45: 4
B46: -automatski prekidači C 25/1 | C46: kom | D46: 1
B47: -automatski prekidači C 32/3 | C47: kom | D47: 1
...

Sheet E.STROJARSKI RADOVI
D2: Cijena: | E2: PDV (25%) | F2: Ukupno s PDV-om:
A3: 1. | B3: =B24 -> INSTALACIJA SUSAVA ZA GRIJANJE I PRIPREMU PTV-A, DIZALICA TOPLINE ZRAK/VODA | D3: =F212 -> 0 | E3: =D3*25% -> 0 | F3: =E3+D3 -> 0
A4: 2. | B4: =B214 -> INSTALACIJA SUSTAVA KLIMATIZACIJE, MULTI SPLIT DIZALICA TOPLINE ZRAK/ZRAK | D4: =F395 -> 0 | E4: =D4*25% -> 0 | F4: =E4+D4 -> 0
A5: 4. | B5: =B397 -> INSTALACIJA TOPLOVODNOG POVRŠINSKOG GRIJANJA | D5: =F461 -> 0 | E5: =D5*25% -> 0 | F5: =E5+D5 -> 0
A6: 5. | B6: =B463 -> VENTILACIJA | D6: =F493 -> 0 | E6: =D6*25% -> 0 | F6: =E6+D6 -> 0
B7: SVEUKUPNO: | D7: =SUM(D3:D6) -> 0 | E7: =SUM(E3:E6) -> 0 | F7: =SUM(F3:F6) -> 0
B9: OPĆI I TEHNIČKI UVJETI
A11: * | B11: Jedinične cijene pojedinih stavaka zaračunate su sa cjelokupnom vrijednosti materijala uključujući montažu, transport, prijenos, skele, izradu i zatvaranje zidnih i podnih usjeka, prodora, zaštitnu ogradu pri izradi iskopa i sl..
A12: * | B12: Izvođač je dužan održavati gradilište čistim uz svakodnevno čišćenje od ostataka materijala i smeća.
A13: * | B13: Prije davanja ponude obavezno pročitati tehnički opis i pregledati grafički dio projekta.
A14: * | B14: Za sve eventualne primjedbe u pogledu izvođenja i troškovnika, obratiti se projektantu prije davanja ponude.
A15: * | B15: Ponuđač radova mora ponuditi sve stavke iz ovog troškovnika. Ukoliko neke od stavki ne ponudi ili predlaže alternativu, to u svojoj ponudi mora posebno naglasiti.
A16: * | B16: Za svu ugrađenu opremu i materijal podrazumijeva se pribavljenje svih potrebnih atesta, certifikata te ostalih dokaznica kvalitete i sveg ostalog potrebnog za validaciju.
A17: * | B17: Za sve parametre koju su točno navedenih vrijednosti mogu se nuditi odstupanja +/- 5% od navedenih vrijednosti
A18: * | B18: U ponudi nisu uračunati troškovi putnog troška izvođača radova, smještaj i slično
A20: St. | B20: O P I S S T A V K E | C20: Jed. | D20: Kol. | E20: CIJENA | F20: IZNOS
C21: mj. | E21: (kn) | F21: (kn)
B22: STROJARSKE INSTALACIJE
A24: 1. | B24: INSTALACIJA SUSAVA ZA GRIJANJE I PRIPREMU PTV-A, DIZALICA TOPLINE ZRAK/VODA
A26: 1.1. | B26: Dobava i ugradnja dizalice topline zrak/voda
B27: Dizalica topline za grijanje prostora i potrošne tople vode. Uređaj je optimiziran za niskoenergetske objekte sa širokim rasponom modulacije inverterskog kompresora. Sastoji se od unutarnje i vanjske jedinice. U cijenu uračunata dobava vanjske jedinice na ravni krov.
B28: Unutarnja jedinica predstavlja hydrobox smješten u kućište elegantnog i glatkog design-a kao i spremnik PTV-a u kojemu je uključena višebrzinska pumpa s PMW regulacijom, izmjenjivač topline voda-rashladni medij, dodatni elektrogrijač , siguronosni ventil, odzračni lončić, el.ormarić, ekspanzijska posuda 10 l, manometar, montiran magnetno-ciklonski filter i upravljač. Nova unutarnja jedinica opremljena je s opcijom DAIKIN EYE koja prikazuje status uređaja. Minimalna količina vode u instalaciji je 0L zbog nove logike defrosta. Smanjeni promjeri cjevovoda i integrirane ručke omogućuju jednostavniju i bržu ugradnju.
B29: Vanjska jedinica namjenjena je za vanjsku montažu - s ugrađenim hermetičkim scroll inverterskim kompresorom, zrakom hlađenim izmjenjivačem i svim potrebnim elementima za zaštitu, kontrolu i regulaciju uređaja (Inverter Control) i funkcionalni rad. Upload postavki je moguć s USB-a ili SD kartice. Temperatura POLAZA vode je do 65°C, te kondenzator vanjske jedinice ima predinstaliranu zaštitu u svrhu duljeg trajanja uređaja.
B30: Rashladni medij je R32. Jedinica ima ugrađen dodatni elektro ekspanzijski ventil optimiziran za ubacivanje tekuće faze, HOT GAS cijev za održavanje pozitivne temperature prije i za vrijeme defrosta, SUB COOL pass - dodatno brtvljenje dna izmjenjivača koje sprječava hlađenje protokom zraka.
B31: Sustav uključuje isporuku svih senzora, izolacijsku posudu za prikupljanje kondenzata i cijevnu izolaciju (proizvod Daikin tip: EKHBDP) te senzor spremnika potrošne tople vode i troputog motornog i prestrujnog ventila.
B32: Proizvod sljedećih teh. karakteristika:
B33: Površinsko grijanje
B34: Gr: To=7°C, Tpol=35°C, ΔT=5°C
B35: Qg(nom/max) = 6/7,74 kW
B36: N = 1,24 kW / 230 V - 50 Hz
B37: COP=4,85
B38: Gr: To=2°C, Tpol=35°C, ΔT=5°C
... B69: U sklopu isporuke jedinice dolazi i komunikacijski modul za online upravljanje.
B70: Proizvod Daikin Altherma 3 R ERGA06EV + EHVH08S23E6V ili jednakovrijedno | C70: kom | D70: 2 | F70: =E70*D70 -> 0
A72: 1.2. | B72: Dobava i ugradnja dizalice topline zrak/voda
B73: Dizalica topline za grijanje i grijanje potrošne tople vode. Uređaj je optimiziran za niskoenergetske objekte sa širokim rasponom modulacije inverterskog kompresora. Sastoji se od unutarnje i vanjske jedinice. U cijenu uračunata dobava vanjske jedinice na ravni krov.
B74: Unutarnja jedinica predstavlja hydrobox u kojemu je uključena višebrzinska pumpa, izmjenjivač topline voda-rashladni medij, dodatni elektrogrijač, sigurnosni ventil, odzračni lončić, el.ormarić, ekspanzijska posuda 10 l, manometar, hvatač nečistoće i upravljač.
B75: Vanjska jedinica namjenjena je za vanjsku montažu - s ugrađenim hermetičkim scroll inverterskim kompresorom, zrakom hlađenim izmjenjivačem i svim potrebnim elementima za zaštitu, kontrolu i regulaciju uređaja (Inverter Control) i funkcionalni rad. Rashladni medij je R32.
B76: Jedinica ima ugrađen dodatni elektro ekspanzijski ventil optimiziran za injektiranje tekuće faze, HOT GAS cijev za održavanje pozitivne temperature prije i za vrijeme defrosta, SUB COOL pass - dodatno brtvljenje dna izmjenjivača koje sprječava hlađenje protokom zraka."
B77: Sustav uključuje isporuku svih senzora, izolacijsku posudu za prikupljanje kondenzata unutarnje jedinice i cijevnu izolaciju, osim senzora spremnika potrošne tople vode i troputog motornog ventila.
...
