Workbook

Sheet NASLOVNICA
A3: Investitor: (u ime suvlasnika stambene zgrade) DAVID ZAJC (OIB 17917819457), Ilica 155, 10000 Zagreb
A4: Građevina: STAMBENA ZGRADA, Ilica 155, 10000 Zagreb Povijesno urbana cjelina Grad Zagreb, REGISTRIRANO KULTURNO DOBRO RH, zaštićeno kulturno dobro pod brojem Z-1525 (NN br 92/11) Klasa: 612-08/02-01/135, od 18. ožujka 2010.
A5: Lokacija: k.č. 3328; K.O. ČRNOMEREC
A8: TROŠKOVNIK ZA OBRTNIČKE I ZAVRŠNE RADOVE
A9: obnove kulturnog dobra
A10: ulično pročelje
A33: Projektant: ovl. arh. Damir Foretić, ing.građ.
A35: Projektant suradnik: Gabrijela Škrabo Žulj, bacc. ing. arch.
A37: Projektant suradnik: Tin Čop, mag. ing. arch.
A39: Direktor: Damir Foretić, ing.građ.
A41: Zagreb, prosinac 2025.
A42: koeficijent inflacije
A43: 0.351

Sheet OPĆI UVJETI
A2: OPĆI UVJETI
A4: Napomena:
A5: Umjesto svih ovdje navedenih normi mogu se koristiti jednakovrijedne norme, a u cilju ispunjenja temeljnih zahtjeva iz važećeg Zakona o gradnji i odredbi propisa na koji Zakon upućuje.
A7: OPĆI UVJETI - NADZOR
A8: Konzervatorski nadzor cijelo vrijeme izvođenja radova vrši predstavnik Konzervatorskog odjela u Zagrebu MKIM RH.
A10: OPĆI UVJETI - GRAĐEVINSKO-OBRTNIČKI RADOVI
A11: Izvođač je dužan izraditi izvedbenu dokumentaciju, te prije samog ugovaranja i izvođenja radova upozoriti glavnog projektanta na eventualne nejasnoće u Glavnom projektu ili neusklađenosti prije ugovaranja i izvođenja, odnosno iznijeti svoje primjedbe već u fazi davanja ponude.
A12: Izrada tipskih primjeraka i uzoraka svih ugrađenih materijala (npr. ograde, pregradne stijene, bravarija, opločenja i sl.), te ovjera istih kod glavnog projektanta u cijeni je stavki i u obvezi je izvođača.
A13: Cijene upisane u ovaj troškovnik sadrže svu odštetu za pojedine radove i dobave u odnosnim stavkama troškovnika i to u potpuno dogotovljenom stanju, tj. sav rad, naknadu za alat, materijal, sve pripremne, sporedne i završne radove, horizontalne i vertikalne transporte.
A14: Pod unesenim cijenama podrazumijevaju se također i sva zakonska davanja, kao i pripomoć kod izvedbe obrtničkih radova (zaštita obrtničkih proizvoda: stolarije, bravarije, limarije, restauratorskih elemenata i slično), sva potrebna ispitivanja građevinskih materijala.
A15: Sav materijal koji se upotrebljava mora odgovarati postojećim tehničkim propisima i normama. Ukoliko se upotrebljava materijal za koji ne postoji odgovarajući standard, njegovu kvalitetu treba dokazati dokaza o kvaliteti i izjava o svojstvima.
A16: Davanjem ponude izvođač se obvezuje da će pravovremeno nabaviti sav materijal opisan u pojedinim stavkama troškovnika. U slučaju nemogućnosti nabave opisanog materijala tijekom izvođenja radova, za svaku će se izmjenu prikupiti ponude i u prisutnosti naručitelja i nadzornog inženjera evaluirati ponude i odabrati zamjenski materijal.
... A109: Prije početka radova obavezno je potrebno odvojiti sve instalacije prisutne na građevini, tj. isključiti el. energiju, vodu, kanalizaciju, plin i razne telekomunikacijske vodove osobito za radove razgradnje zidova i sl. koji se izvode na području postojećih instalacija.

Sheet I. a. PRIPREMNI RADOVI I SKELA
A1: sub. | B1: R.B. | C1: OPIS STAVKE | D1: JM | E1: KOLIČINA | G1: JEDINIČNA CIJENA | H1: CIJENA UKUPNO
B3: 1 | C3: Pripremna dokumentacija i organizacija gradilišta
C4: Izrada plana aktivnosti i sheme gradilišta, organizacija pristupa gradilištu i određivanje pozicije dnevne gradilišne deponije, iskolčenje elemenata rekonstrukcije, određivanje točnih geodetskih visina i osi s povezivanjem na najbliži reper.
C5: Izvođač treba izvršiti sve pripremne radove prije nego pristupi izvođenju.
C6: Izrada sheme organizacije gradilišta prema predviđenoj mehanizaciji Izvoditelja unutar zaštitne zone i uz suglasnost koordinatora II, kojeg imenuje Investitor; prijava početka radova nadležnim službama, postava propisanih natpisa upozorenja - sve sukladno zakonu o Zaštiti na radu i dr. propisima. Prema potrebi ishođenje dozvola za privremeno korištenje javnih površina. Obračun po kompletu.
A7: UL | B7: a | C7: Terminski plan aktivnosti | D7: kpl | E7: 1 | F7: x
A8: UL | B8: b | C8: Organizacija gradilišta | D8: kpl | E8: 1 | F8: x
A9: UL | B9: c | C9: Geodetski radovi za cijelo vrijeme izvođenja | D9: kpl | E9: 1 | F9: x
B11: 2 | C11: Izvedbena dokumentacija
C12: Izrada i ovjera radioničkih nacrta i radioničke dokumentacije (Izvedbena dokumentacija) za sve detalje projekta. Izrada i ovjera ove dokumentacije dužnost je izvođača i smatra se da je sve kompletno uključeno u cijenu stavke. Dokumentaciju mora odobriti projektant konstruktivnog dijela projekta i glavni projektant.
A13: UL | C13: Obračun po kompletu. | D13: kpl | E13: 1 | F13: x
B15: 3 | C15: Ograde i table gradilišta, sanitarije
C16: Dobava, montaža i demontaža montažne gradilišne pune ograde oko zone zahvata s ulaznim kolnim i pješačkim vratima, te dobava i postavljanje table gradilišta s natpisom na kojoj se ističe da se operacija sufinancira iz FSEU, amblem Europske unije, te tekst „Europska unija“ - sve prema uvjetima tijela koje sufinancira.
C17: Ograda visine minimalno 2,20 m sa uključivo jednim pješačkim vratima vel. 1,00/2,20 m i dvoja kolna dvokrilna ili klizna ulazna vrata vel. 3,00/2,20 m u svemu prema shemi organizacije gradilišta. Ograda mora biti učvršćena na propisan način i dobro osigurana od prevrtanja. Ogradom ograditi čitavo područje gradilišta i manipulativne površine.
C18: Stavkom se predviđa uređenje prostora za boravak radnika te osiguranje privremenih sanitarnih čvorova - količina prema broju radnika na gradilištu. Izrada Projekta privremenih građevina na gradilištu i ishođenje svih potrebnih dozvola (rezervacija javne površine i dr.) i suglasnosti dužnost je izvođača i smatra se da je sve kompletno uključeno u cijenu stavke za cijelo vrijeme izvođenja radova.
C19: Obračun po m' i po komadu.
A20: UL | B20: a | C20: Ograda gradilišta | D20: m' | E20: =25+30 -> 55 | F20: x | G20: 35 | H20: =E20*G20 -> 1925
A21: UL | B21: b | C21: Rezervacija javne površine | D21: kpl | E21: 1 | F21: x | G21: 12000 | H21: =E21*G21 -> 12000
A22: UL | B22: c | C22: Tabla gradilišta | D22: kom | E22: 1 | F22: x | G22: 150 | H22: =E22*G22 -> 150
A23: UL | B23: d | C23: Privremeni prostor za boravak radnika (''kontejner'') | D23: kom | E23: 1 | F23: x
A24: UL | B24: e | C24: Tipski prijenosni sanitarni čvor | D24: kom | E24: 1 | F24: x | G24: 1800 | H24: =E24*G24 -> 1800
B26: 4 | C26: Privremeni priključci
C27: Ishođenje, izvedba i osiguravanje svih potrebnih privremenih atestiranih priključaka potrebnih za izvođenje radova na/po čitavom gradilištu i mjestima izvođenja radova (npr. struje, vode/odvodnje, plina za zavarivanje, agregati i sl.), za izvođenje svih radova ovog troškovnika.
C28: U ovu stavku ulazi i osiguranje svih potrebnih priključaka i energenata na svim potrebnim mjestima gdje se vrše radovi (pročelja zgrade, po pločniku i cesti i dr.). Osigurati priključke struje produžnim kablovima, pomičnim agregatima, a priključke plina prijenosnim plinskim bocama, spremnicima i sl. - sve osigurati prema važećim propisima, uključeno u cijenu stavke.
A29: UL | C29: Obračun po kompletu. | D29: kpl | E29: 1 | F29: x
C31: Skela
B32: 5 | C32: Dobava, postava, prepravci tijekom gradnje, skidanje i otprema skele u unutrašnjosti crkve i zvonika, te na pročeljima crkve i zvonika, uključivo s tunelskim dijelom u najdonjoj zoni - prolazom za pješake. Skela se izvodi od bešavnih cijevi skele, slobodnog sastava i potrebnih spojnih elemenata, sa svim potrebnim ukrućenjima i sidrenjima, zaštitnim daskama na podnicama za zaštitu od pada predmeta s visine.
C33: Skele na pročeljima oslanjaju se slobodno na tlo, dok je dvorišnu skelu potrebno prema projektu skele premostiti na svim nedostupnim dijelovima. Oslanjanje skele na krovište ili u tavanski prostor nije predviđeno.
C34: Sve isturene i oštre dijelove zaštiti za siguran prolaz pješaka te rad radnika. Pokrov tunela izraditi od mosnica položenih jedna do druge, a preko njih postaviti PVC foliju s preklopima min. 15 cm. Prema ulici izvesti ogradu tunela od pune, glatke oplate visine 1,0-1,2 m, u svrhu zaštita pješaka od prometa u kretanju.
C35: U jediničnu cijenu uključiti i zaštitni zastor od jutenih ili plastičnih traka, koje se postavljaju s vanjske strane po čitavoj površini skele.
C36: Skelu je potrebno osigurati od udara groma uzemljenjem, uključiti u cijenu stavke. Potrebno je izvesti ljestve za vertikalnu komunikaciju po skeli. Izvođač radova dužan je na terenu izvesti ograđeni prostor za odlaganje potrebnih materijala, a u skladu s rješenjem o zauzimanju javno-prometne površine - ishođenje svih potrebnih rješenja i odobrenja o zauzimanju javno-prometne površine je uključeno u cijenu skele.
C37: Skela se oslanja na plohu od betonskih opločnika i asfalta, a na zemlju preko tipskih širokoplošnih stopa i vijčanim prihvatnim elementima u pročelje.
C38: Posebnu pažnju posvetiti stopama koje stoje na zemlji i pločniku i spriječiti utonuće stopa u zemlju/pločnik.
C39: Prije izvedbe skele izvođač je dužan izraditi Projekt skele što je u potrebno uključiti u cijenu ove stavke.
C40: Projekt skele izvođač je dužan dati na uvid i odobrenje nadležnom konzervatorskom tijelu.
C41: Nakon skidanja skele Izvođač je dužan potpuno sanirati sva prihvatna i stajaća mjesta skele. Nakon postave skele potrebno je izvesti svu signalizaciju (rasvjeta, putokazi i sl.) kako to nalažu postojeći HTZ propisi.
C42: U cijenu skele potrebno je uključiti stroj (dizalicu) i mjesto za vertikalni transport materijala - snaga, tip i pozicija stroja (dizalice) za vertikalni transport mora biti u skladu s ostalim radovima ovog troškovnika i projekta, a definira se Projektom skele. Dimenzije i visina skele je dana u nastavku stavke.
C43: Obračun se vrši po m² vertikalne projekcije skele na plohu zida.
A44: UL | B44: a | C44: tunelska skela uličnog pročelja na nogostupu (h=3m) | D44: m2 | E44: =101+103+11 -> 215 | F44: x | G44: 40 | H44: =E44*G44 -> 8600
A45: UL | B45: b | C45: ulična pročelja (h=12,5) | D45: m2 | E45: =296+32+278 -> 606 | F45: x | G45: 20 | H45: =E45*G45 -> 12120
...

Sheet OPĆI UVJETI RUŠENJA I DEMONTAŽE
B2: I. b. RUŠENJA I DEMONTAŽE OPĆI UVJETI Sva rušenja, probijanja, bušenja i dubljenja treba u pravilu izvoditi ručnim alatom, s osobitom pažnjom. Prije rušenja ili skidanja žbuke s raznih vučenih profilacija navedenih elemenata i na njih ishoditi suglasnost odgovorne osobe za nadzor, snimke treba ishoditi suglasnost GZZZSKP. Izmjere i otisci uzimaju se s očuvanih profila, s kojih prethodno treba ukloniti sve slojeve prašine, smoga i drugih nečistoća, slojeve starih naličja, a u pojedinim slučajevima i slojeve naknadna nanesene žbuke. Ukoliko pojedini karakteristični profil nije sačuvan potrebno ga je rekonstruirati. Prema izrađenim otiscima rade se drvene ili metalne šablone. Drvene šablone treba izvesti iz zdrave i čvrste građe, a da se spriječe deformacije treba ih okovati. Sve otvore na pročelju treba odmah nakon postave skele zaštititi PVC folijom debljine 0,20 mm, kako prilikom obijanja žbuke ne bi došlo do oštećenja. Nakon provedenih pripremnih radova, rušenja na građevini vrše se prema unaprijed utvrđenom redoslijedu dogovorenim s nadzornim inženjerom investitora. Demontaže i rušenja izvode se u pravilu od krova prema podrumu. Skidanje – obijanje žbuke vrši se do nosivog dijela zida, uključujući i čišćenje sljubnica skobama i uz stalno kvašenje vodom zbog manjeg prašenja. Obijanje žbuke oko elemenata dekorativne plastike treba izvoditi naručio pažljivo kako se ne bi dodatno oštetili ili ispali iz ležaja. Eventualna demontaža elemenata dekorativne plastike predviđena je kiparsko-restauratorskim radovima. Jedinična cijena iz ponude izvoditelja treba obuhvatiti kompletno rušenje , uključivo sve pripremno-završne radove sadržane u faktorskim troškovima. Svi prijenosi materijala dobiveni rušenjem i demontažom , odvoze se na privremeni gradilišni deponij ili gradsku planirku, s čišćenjem gradilišta i dovođenjem javne površine u prvobitno stanje, treba biti uključen u jediničnoj cijeni radova i neće se naknadno priznavati. Prije početka radova treba ispitati sve instalacije koje se nalaze na pročelju ili krovu građevine, te ih po stručnoj osobi zaštititi u skladu s propisima. Sve elemente s pročelja (tablice s kućnim brojem i sl.) treba skinuti i privremeno –do završetka radova kada će se ponovno postaviti- pohraniti na gradilištu ili mjestu koje se dogovori s nadzornim inženjerom investitora. Izvoditelj će snositi troškove ukoliko se navedeni elementi oštete ili otuđe. Jediničnom cijenom treba obuhvatiti: - sav rad i materijal za izvedbu radova iz pojedine stavke, - sav transport, - sve društvene obveze vezane za radnu snagu i materijal, - pripremno - završne radove.

Sheet I. b. RUŠENJA I DEMONTAŽE
A1: sub. | B1: R.B. | C1: OPIS STAVKE | D1: JM | E1: KOLIČINA | G1: JEDINIČNA CIJENA | H1: CIJENA UKUPNO
B2: * za sve radove koristiti skelu
B4: 1 | C4: Demontaža manjih elemenata s pročelja koji se moraju demontirati prije izvođenja radova (natpisanih ploča, pločica kućnog broja, nosača zastava, reklama, poštanskih sandučića, zaštitne maske gromobrana, rasvjetnih tijela i sl.) s privremenim deponiranjem na gradilištu ili kod korisnika/vlasnika/zakupca, pranjem i čišćenjem te ponovnom montažom. Kod demontaže rasvjetnih tijela, isto komunicirati s nadležnim gradskim službama, a demontažu vršiti tako da se osigura siguran nastavak radova. Izvoditelj snosi sve troškove ponovne dobave ili izrade pojedinih elemenata u slučaju oštećenja ili otuđenja sa gradilišta. U cijenu uračunati i nabavu novih tipli i vijaka za montažu po završetku radova onih elemenata koji će se vratiti po odluci GZZZSKP. Obračun po kom.
A5: UL | C5: ploče s nazivima ulice, kč.br. i sl. - s naknadnom ugradnjom | D5: kom | E5: 8 | F5: x | G5: 40 | H5: =E5*G5 -> 320
A6: UL | C6: ulična rasvjeta - s naknadnom ugradnjom | D6: kom | E6: 2 | F6: x | G6: 80 | H6: =E6*G6 -> 160
A7: UL | C7: nosači antena i reklama, kamere i alarmi, razne kuke, sušenje rubalja i sl. - bez naknadne ugradnje | D7: kom | E7: =1+9+4 -> 14 | F7: x | G7: 30 | H7: =E7*G7 -> 420
A9: UL | B9: 2 | C9: Demontaža postojećih antenskih kablova s pročelja prije izvođenja radova s privremenim deponiranjem na gradilištu ili kod korisnika/vlasnika/zakupca, pranjem i čišćenjem te ponovnom montažom. Prije demontaže provjeriti ispravnost, odnosno režim uporabe istih. U cijenu uračunati i nabavu novih s ugradnjom bužira za montažu za one elemenate koji će se vratiti po odluci GZZZSKP. Obračun po m¹. | D9: m¹ | E9: =(16+4)*(5+3+3+3+5) -> 380 | F9: x | G9: 1.5 | H9: =E9*G9 -> 570
C10: NAPOMENA: bez ugradnje novih
B11: 3 | C11: Demontaža postojećih opšava vijenaca, prozorskih klupčica i cijevi za odvodnju oborinskih voda, od pocinčanog lima. Prije demontaže limar je dužan uzeti sve mjere i detalje postojeće limarije za izvedbu nove limarije, čije nacrte je dužan dati na pregled nadzornom inženjeru i predstavniku GZZSKP; kod pojedinih usčuvanih elemenata moguće iste vratiti. U stavku uključen sav vertikalni i horizontalni prijenos na gradilišni deponij odnosno mjesni deponij i zbrinjavanje građevinskog otpada sukladno Pravilniku NN 38/08. Obračun po m'.
A12: UL | B12: 3.1. | C12: cijevi, vertikale oborinske vode s tuljcem na spoju sa 'škotskom cijevi', obujmicama - Ø 12 cm | D12: m¹ | E12: =(15.5*4) -> 62 | F12: x | G12: 0 | H12: =E12*G12 -> 0
A13: UL | B13: 3.2. | C13: opšav vijenca iznad prizemlja - r.š. do 25 cm | D13: m¹ | E13: =ROUNDUP(47.4,0) -> 48 | F13: x | G13: 11 | H13: =E13*G13 -> 528
A14: UL | B14: 3.3. | C14: prozorske klupčice - r.š. do 45 cm | D14: m¹ | E14: =ROUNDUP(51*1+1.4,0) -> 53 | F14: x | G14: 15 | H14: =E14*G14 -> 795
A15: UL | B15: 3.4. | C15: prozorske klupčice - r.š. do 25 cm | D15: m¹ | E15: =ROUNDUP(65.25,0) -> 66 | F15: x | G15: 11 | H15: =E15*G15 -> 726
B17: 4 | C17: Ručno otucanje stare trošne žbuke debljine 2 - 7 cm s ravnih ploha, vijenaca i profilacija na uličnom i dvorišnom pročelju. Prije otucanja žbuke izvođač je dužan snimiti sve profilacije, izraditi nacrte u mjerilu 1:1 i dati ih na ovjeru predstavniku GZZSKP i nadzornom inženjeru, te prema tome izraditi šablone. Predviđa se po jedna šablona za vijenac r.š. do 50 cm, za svakih, cca 6-8 m' vijenca - sve kako bi se pročelje izvelo prema postojećem odnosno prema sloju koji odredi predstavnik GZZSKP. Prema potrebi, izraditi i više šablona te uzeti otiske i izraditi gipsane odljeve.
C18: Profilacije se snimaju prema žbuci koju odredi predstavnik GZZSKP te prije uzimanja mjera ili otiska, prema potrebi, pažljivo skinuti novije slojeve žbuke i boje, što je u cijeni izrade šablone. Zid pročelja je od opeke. Nakon otucanja žbuke zid očistiti čeličnim četkama, reške iščistiti do 1 cm dubine, te cijelu površinu otprašiti. U cijenu uračunati i otežan rad oko profilacija i reljefa. Obračun prema popisu u nastavku - šablone se obračunavaju po jednom kompletu za jednu profilaciju, za grubu i finu žbuku, bez obzira na broj pomoćnih šablona zbog duljine profilacije.
C19: *ukupna ortogonalna projekcija plašta uličnog pročelja, bez dodataka i razvijenih širina, je cca 748 m² s otvorima. *ukupna ortogonalna projekcija plašta dvorišnog pročelja, bez dodataka i razvijenih širina, je cca 696 m² s otvorima.
A20: UL | B20: 4.1. | C20: Profilirani vijenac, iznad prizemlja, s okapnicom na vanjskom rubu, r.š. do 50 cm. Obračun po kompletu šablona i m'. | D20: m' | E20: 47 | F20: x | G20: 30 | H20: =E20*G20 -> 1410
A21: UL | C21: šablona | D21: kompl. | E21: 1 | F21: x | G21: 320 | H21: =E21*G21 -> 320
A23: UL | B23: 4.2. | C23: Ravni dio zida s pravokutno profiliranim horizontalnim kanelurama. Uračunati uzimanje mjera, iscrtavanje, postavu letvica za izradu kanelura i završna zidarska obrada bridova i unutarnje površine kanelura. Obračun po kompletu šablona i m² plohe zida, s odbijenim otvorima. * (površina bez odbitaka otvora 733 m²) | D23: m² | E23: =748-ROUNDUP(0.15*E20*2,0)-ROUNDUP((12*4+6)*1.8*1+11*0.8*0.5+1.35*2.85+1.4*2.75+1.4*3.9,0) -> 618 | F23: x | G23: 17 | H23: =E23*G23 -> 10506
A24: UL | C24: šablona za izvlačenje kanelura | D24: kpl | E24: 1 | F24: x | G24: 250 | H24: =E24*G24 -> 250
A26: UL | B26: 4.3. | C26: Profilirani vijenac u zoni prizemlja, iznad dopodnika, r.š. do 20 cm. Obračun po kompletu šablona i m'. | D26: m' | E26: =ROUNDUP(E20-2*1.4,0) -> 45 | F26: x | G26: 30 | H26: =E26*G26 -> 1350
A27: UL | C27: šablona | D27: kpl | E27: 1 | F27: x | G27: 300 | H27: =E27*G27 -> 300
A29: UL | B29: 4.4. | C29: Profilirani okviri prozora sa špaletama u zoni dopodnika, r.š. do 20 cm. Dim. prozora cca 85/95 x 55 cm. Obračun po kompletu šablona i m'. | D29: m' | E29: =ROUNDUP(2.4*(6+5),0) -> 27 | F29: x | G29: 30 | H29: =E29*G29 -> 810
A30: UL | C30: šablona | D30: kpl | E30: 1 | F30: x | G30: 250 | H30: =E30*G30 -> 250
A32: UL | B32: 4.5. | C32: Profilirani dio sokla između podrumskih prozora, r.š. 30-70 cm. Obračun po kompletu šablona i m'. | D32: m' | E32: =E26+1.4 -> 46.4 | F32: x | G32: 8 | H32: =E32*G32 -> 371.2
A33: UL | C33: šablona | D33: kompl. | E33: 1 | F33: x
C34: U cijeni pranje kamenog sokla
B35: 5 | C35: Čišćenje sljubnica i priprema podloge zidova
C36: Razgradnja morta sljubnica, pranje površine zidova i podgleda vodom pod visokim tlakom kako bi se odstranila prašina, cementna skramica, ulje, masnoće, nepoznate tvari, hrđa, slabo prionjivi i svi kontaminirani dijelovi konstrukcije (razgradnja žbuke zasebna je stavka). Uklanjanje slaboveznog i trošnog materijala iz sljubnica.
C37: Potrebno je ukloniti minimalno 30 mm materijala iz sljubnica.
C38: U cijenu uključen rad, gradilišni transporti, odvoz i zbrinjavanje građevinskog otpada, sva privremena podupiranja, a skela je zasebna stavka.
C39: Obračun po m2 obrađene površine zida.
A40: UL | B40: 5.1. | C40: ulično pročelje | D40: m² | E40: ='I. b. RUŠENJA I DEMONTAŽE'!E23+'I. b. RUŠENJA I DEMONTAŽE'!E20*0.5+'I. b. RUŠENJA I DEMONTAŽE'!E26*0.2+'I. b. RUŠENJA I DEMONTAŽE'!E29*0.2+'I. b. RUŠENJA I DEMONTAŽE'!E32*0.5 -> 679.1 | F40: x | G40: 6 | H40: =E40*G40 -> 4074.6
A41: UL | B41: 5.2. | C41: ulično pročelje - oko pukotina | D41: m² | E41: 25 | F41: x | G41: 6 | H41: =E41*G41 -> 150
C42: U cijeni pranje fasade, bez produbljivanja sljubnica
A43: UL | B43: 6 | C43: Odvoz demontirane limarije i raznih nosača uključivo ručni utovar u kamion te prevoz na gradski deponij udaljen do 20 km i istovarom izvrtanjem i planiranjem na gradskoj planirki. U cijenu uključiti sve pristojbe na deponiju. Zbrinjavanje građevinskog otpada sukladno Pravilniku NN 38/08. Obračun po kg (4,25 kg/m²). | D43: kg | E43: =ROUNDUP(4.25*(0.45*E13),0)+20 -> 112 | F43: x
C44: u cijeni demontaže
A45: UL | B45: 7 | C45: Čišćenje skele i gornje površine tunelske skele od građevinske šute, s utovarom u kante te svim horizontalnim i vertikalnim prijenosom do gradilišnog odlagališta. Ručni utovar građevinske šute u kamion, s prijevozom do 20 km i istovarom izvrtanjem i planiranjem na gradskoj planirki, sa svim pristojbama. Obračun po m³ uz dodatak na rastresitost. Zbrinjavanje građevinskog otpada sukladno Pravilniku NN 38/08. | D45: m³ | E45: ='I. a. PRIPREMNI RADOVI I SKELA'!E44/5 -> 43 | F45: x | G45: 110 | H45: =E45*G45 -> 4730
A47: UL | B47: 8 | C47: Čišćenje i pranje pločnika više puta tijekom izvođenja radova, te po završetku svih radova. Obračun po m². | D47: m² | E47: =130 -> 130 | F47: x | G47: 5 | H47: =E47*G47 -> 650
B49: 9 | C49: Čišćenje i pranje kompletnih prozora i vrata više puta tijekom izvođenja radova, te finalno staklenih ploha po završetku svih radova. Obračun po m².
...

Sheet Ic. KONZERVATORSKA ISTRAŽIVANJA
A1: sub. | B1: R.B. | C1: OPIS STAVKE | F1: JM | G1: KOLIČINA | I1: JEDINIČNA CIJENA | J1: CIJENA UKUPNO
B2: * za sve radove koristiti skelu
A3: UL | B3: 1. | C3: Konzervatorska istraživanja žbuke i boje pročelja nakon postave skele, a prije rušenja i demontaža, radi utvrđivanja izgleda pročelja u raznim povijesnim razdobljima, te radi utvrđivanja stanja obrada i konstrukcija. Prema odredbama GZZZSKP otvoriti konzervatorske sonde na ravnim površinama prizemlja, katova, podnožja zgrade, na vučenim profilacijama vijenaca, nadprozornika, doprozornika te na stolariji i bravariji. Prema potrebi izvesti i veći broj sondi, od predviđenog, sve u dogovoru s nadzornim inženjerom i predstavnikom GZZZSKP. Obračun po broju sondi. | F3: sondi | G3: =3+3+2+1 -> 9 | H3: x | I3: 260 | J3: =G3*I3 -> 2340
A5: UL | B5: 2. | C5: Izrada nacrta istraživanja i sondiranja s ucrtanim i opisanim nalazima te kompletiranje nalaza u vidu elaborata. Predaja digitalno, a tiskanih primjeraka je minimalno pet (5). Uključena je i izrada nacrta prezentacije nalaza. | F5: kpl | G5: 1 | H5: x | I5: 2800 | J5: =G5*I5 -> 2800
C8: I. c. KONZERVATORSKA ISTRAŽIVANJA UKUPNO: | J8: =SUM(J3:J5) -> 5140

Sheet OPĆI UVJETI ZID.-FASAD. RADOVI
B2: ZIDARSKO-FASADERSKI RADOVI OPĆI UVJETI
B3: Zidarsko-fasaderski radovi izvode se isključivo prema opisanim stavkama troškovnika, kao i prema važećim propisima za ovu vrstu radova. Kvaliteta svog upotrjebljenog materijala mora odgovarati propisima i važećim normama, što izvoditelj mora dokazati potrebnim atestima. Izvoditelj je dužan osigurati i zaštititi sve dijelove građevine na kojima se ne izvode radovi, radi sprečavanja oštećenja tokom izvedbe. Pojava svih oštećenja na dijelovima na kojima se radovi ne izvode ili koji su nastali nepažnjom izvoditelj isti je dužan otkloniti o vlastitom trošku. Sav rad, sve komunikacije i sav transport vrši se isključivo s vanjske strane građevine , tj. preko skele. Žbukanje se izvodi na dobro očišćenoj, oprašenoj i vodom ispranoj površini. Radove na žbukanju izvoditi samo u povoljnim vremenskim uvjetima, uz odgovarajuće osiguranje i zaštitu svježe ožbukanih površina od štetnog utjecaja djelovanja sunca i oborina. Prije samog pristupanja žbukanju, površinu zida potrebno je dobro navlažiti. Kvalitetu žbuke izvoditelj je dužan dokazati pribavljanjem stručnih nalaza i mišljenja Građevinskog instituta u Zagrebu. Obračun svih radova vršiti kako je to naznačeno u opisu stavaka. U jediničnu cijenu radova potrebno je uračunati: - sve pripremne i završne radove - sav rad i materijal potreban za izvođenje pojedine stavke opisa - ispiranje i kvašenje površine zida - sav otežani rad na izradi profilacije - zaštita izvedenog djela obrade pročelja - sav potrebni horizontalni i vertikalni transport, kao i transport do gradilišta - primjena svih mjera zaštite na radu - sve društvene obaveze Popis normativa za materijale koji se treba pridržavati kod žbukanja: -HRN B.C1. 030, B.C8.030.-građevinski gips. - HRN B.C1. 020, B.C8.042.-građevinsko vapno - HRN B.C8.015, 022-026.-cement -HRN B.C8.011.-portland cement - HRN B.C8.030-pijesak - HRN U.M2.010.,U.M2.012.-mortovi - HRN U.F2.010.-tehnički normativi za izvođenjem fasaderskih radova
B37: TOPLINSKE IZOLACIJE U ZIDARSKO-FASADERSKI RADOVIMA OPĆI UVJETI
B38: Izvoditi prema Tehničkim propisima za zidane konstrukcije NN 01/07 , Tehničkom propisu o racionalnoj uporabi energije i toplinskoj zaštiti u zgradama (NN 97/14) i Tehničkim propisima o građevnim proizvodima NN 33/10 i 87/10 s pripadajućim normama za materijale koji se ugrađuju te primijeniti norme za toplinske i zvučne izolacije: • mineralna vuna MW HRN EN 13162:2002 • ekspandirani polistiren HRN EN 13163:2002; HRN EN 13163/A1:2004; • ekstrudirani polistiren HRN EN 13164:2002 • tvrda poliuretanska pjena (PUR) HRN EN 13165:2002; HRN EN 13165/A1/A2:2004; Završni zidarski radovi u ovom projektu obuhvaćaju: • unutarnje i vanjske žbuke • dobave i ugradnje • izrada vanjske fasade (ETICS sustav) Prilikom izvođenja završnih zidarskih radova izvođač se mora pridržavati slijedećih mjera: - žbukanja, etics sustav Žbukati tek kada se zidovi osuše i slegne zgrada. Ne smije se žbukati kad postoji opasnost od smrzavanja ili ekstremno visokih temperatura 30° ili više. Zidovi moraju biti prije žbukanja čisti, a fuge udubljene, da se žbuka može dobro primiti. Prije žbukanja dobro je da se zidovi navlaže, a osobito kod cementnog morta. Ukoliko na zidovima izbija salitra – treba ih četkom očistiti i oprati rastvorom solne kiseline u vodi (omjer 1:10) o trošku izvođača i dodavati sredstvo protiv izbijanja salitre u mort. Rabiciranje žbuke izvodi se pomoću tekstilno staklene mrežice otporne na alkalije ili sitno pletene mreže od nehrđajućeg čelika. Kod obrade fasade plemenitom žbukom bila to šerana ili prskana (hirofa), žbuka mora biti kvalitetna, tvorničke izvedbe u izabranoj boji i kvaliteti. Kod izrade fasadnih žbuka raditi prema uputstvu proizvođača. Grebana se žbuka zove i šerana, a prskana hirofa. Etics sustav (the external thermal insulation composite system), odnosno povezani sustav za vanjsku toplinsku izolaciju sastoji se od ljepila, toplinske izolacije (EPS, kamena vuna), polimercementne armirane žbuke, impregnacijskog premaza i završne žbuke u odabranoj boji i teksturi (silikatna, akrilna). Ukoliko je predviđeno ugrađuju se i pričvrsnice za toplinsko izolacijski sloj. ETICS sustav izvoditi komponentama jednog, odabranog sustava. Kod ugradnje svih komponenti pridržavati se uputa proizvođača (način ugradnje, sušenje). Izvođač će pristupiti izvedbi završnih zidarskih radova tek nakon što projektant potpisom potvrdi tehnološku razradu svih detalja. Jedinična cijena uključuje • tehnološku razradu svih detalja, • sve posredne i neposredne troškove za rad, materijal, alat i građevinske strojeve • sve transporte • čišćenje tokom rada • odvoz i zbrinjavanje smeća • završno čišćenje prije primopredaje radova • nadoknadu eventualne štete nastale iz nepažnje na svojim ili tuđim radovima • usklađenje organizacije rada s operativnim planom Obračun: • fasade po površini pročelja izraženoj u m2 • zatvaranje reški dužinski u m1

Sheet II. ZIDARSKO-FASADNI RADOVI
A1: sub. | B1: R.B. | C1: OPIS STAVKE | D1: JM | E1: KOLIČINA | G1: JEDINIČNA CIJENA | H1: CIJENA UKUPNO
B2: * za sve radove koristiti skelu
A3: UL | B3: 1 | C3: Popravak oštećenih dijelova zida i istaka nastalih ispadanjem opeke. Stavkom je obuhvaćeno vađenje iz ležajeva dotrajale opeke i ponovno zidanje novom punom opekom u produžnom mortu. Prilikom zidanja poštovati postojeći vez opeke i odsijecanjem prilagoditi izvornom obliku. Obračun po m² saniranog zida, a prema prethodnom pregledu i upisu nadzornog inženjera u građevinski dnevnik. | D3: m² | E3: 1 | F3: x | G3: 250 | H3: =E3*G3 -> 250
A5: UL | B5: 2 | C5: Nabacivanje sloja produžnog morta na većim uleknućima površine zidova kako bi se doveli u okomitost. Izravnanje zidova izvesti na mjestima ustanovljenim mjerenjem okomitosti zidova, a uz suglasnost nadzornog inženjera. Debljina morta do 5 cm. Prema potrebi ojačavati adekvatnim mrežicama dovoljno velikog okna za granulaciju žbuke, ankeriranih u ziđe. Obračun po m² ožbukanog zida, a prema prethodnom pregledu i upisu nadzornog inženjera u građevinski dnevnik. | D5: m² | E5: =(ROUNDUP(364+39+345,0)+((293+34+71)+(194+18+85)))*0.3/2 -> 216.45 | F5: x | G5: 35 | H5: =E5*G5 -> 7575.75
B7: 3 | C7: Obnova sljubnica zidova
C8: Nabava svih materijala i ugradnja morta za zapunjavanje sljubnica, mortom na bazi pucolana i vapnenih veziva (ili jednakovrijedno).
C9: Prije nanošenja morta potrebno je zasititi podlogu vodom (uključeno u prethodne stavke), u svrhu spriječavanja upijanja vode od strane podloge. Višak slobodne vode mora ispariti, tako da je površina zasićena, a suha.
C10: Mort se između elemenata ziđa nanosi lopaticom uz lagani pritisak kako bi se poboljšala prionjivost. Višak morta potrebno je ukloniti odmah nakon ugradnje.
C11: U cijenu stavke uključiti (ako bude potrebno) i čišćenje sljubnica vlažnom spužvom ili četkom.
C12: Istim mortom potrebno je poravnati udubine, a izbočine je potrebno otući kako bi se dobila zadovoljavajuća ravnost površine.
C13: U cijenu uključiti sav materijal, rad, transporte, čišćenja tijekom i po završetku radova, te odvoz viška materijala na deponiju i propisno zbrinjavanje.
C14: Obračun po m2.
A15: UL | B15: 3.1. | C15: ulično pročelje | D15: m² | E15: ='I. b. RUŠENJA I DEMONTAŽE'!E40 -> 679.1 | F15: x | G15: 19 | H15: =E15*G15 -> 12902.9
A16: UL | B16: 3.2. | C16: ulično pročelje - oko pukotina | D16: m² | E16: 25 | F16: x | G16: 19 | H16: =E16*G16 -> 475
B18: 4 | C18: Injektiranje svih pukotina širih od 1,5 mm.
C19: Dobava i ugradnja gotove injekcijske smjese na bazi cementa te injektiranje pukotina na zidovima.
C20: Karakteristike morta: gustoća svježeg morta: 2,3 kg/L, maksimalna veličina zrna 4,0mm, tlačna čvrstoća nakon 24 sata : >20 N/mm2, čvrstoća na savijanje nakon 24 sata : 5,5 N/mm2, statički modul elastičnosti : 37.000 N/mm2.
C21: Smjesa se injektira pod pritiskom 0,03 MPa kroz cjevčice unutarnjeg promjera min. 12 mm u prethodno izbušene otvore promjera min. 50 mm.
C22: Postavljanje min. 3 cjevčice po m' pukotine. Dodatno pričvršćenje cjevčica koristeći brzovezujući cementni mort. Cjevčice duljine cca 15 cm, na dubini od cca 5 cm.
C23: Pukotina se zapunjava cementnim mortom po cijeloj dužini između cjevčica, nakon čega se cjevčice začepe, a zatim se otvaranjem čepova u parovima po dva, pukotina između dvije cjevčice ispire vodom i ispuhuje zrakom. Nakon toga se vrši injektiranje, odozdo prema gore.
C24: Radove je potrebno izvoditi pažljivo kako ne bi došlo do izbijanja blokova uslijed tlaka injektiranja, izbijanja injektirajuće mase na površinu i sl.
C25: U cijenu stavke uključiti sav materijal, rad, transporte, čišćenja tijekom i po završetku radova.
C26: Uključiti i obostrano zapunjavanje sljubnica uzduž pukotina reparaturnim mortom (uz prethodno čišćenje sljubnica minimalno 3 cm dubine) na pozicijama gdje injektiranje neće biti potrebno.
C27: Obračun po m'. Nudimo ojačanje sa Roefix Sismadur i Sismaprotect mrežica
A28: UL-K | B28: 4.1. | C28: ulično pročelje | D28: m' | E28: 100 | F28: x | G28: 60 | H28: =E28*G28 -> 6000
A30: UL-K | B30: 4.2. | C30: zapunjavanje sljubnica uzduž pukotina mortom - ul | D30: m' | E30: 100 | F30: x | G30: 30 | H30: =E30*G30 -> 3000
B33: 5 | C33: Injektiranje pukotina epksidnom smolom
C34: Dobava svih materijala, priprema podloge obilježavanjem pukotine te čišćenjem područja rada zrakom pod pritiskom. Ugradnja epoksidnog morta kojim se pukotina zatvara na strani s koje se provodi injektiranje.
C35: Pakeri se postavljaju na međusobnom razmaku od 20 do 25 cm (4 do 5 kom/m' pukotine). Injektiranje se vrši pod pritiskom koji se ostvaruje pumpama. Miješanje smjese za injektiranje vrši se prema uputama proizvođača na mjestu ugradnje.
C36: Koristi se dvokompnentna epoksidana smola za injektiranje niske viskoznosti, certificiran i sa navedenom namjenom
C37: U stavku uračunati sav pripremni rad, sve materijale, izvedbu injektiranja, pomoćne dodatne radne skele, odvoz i zbrinjavanje viška materijala, čišćenje tijekom i po završetku radova.
C38: Injektiranje epoksidnom smolom radi se samo na horizontalnoj pukotini između 1.i 2. kata uličnog pročelja.
A39: UL-K | C39: Obračun po m' sanirane pukotine. | D39: m' | E39: 40 | F39: x
B41: 6 | C41: Karbonsko platno sa sidrenjem
C42: Vršiti nakon čišćenja i pranja površine za obradu što je obračunato zasebno.
C43: Dobava i ugradnja FRP tkanina (širina traka 15 cm - vidi nacrte) od karbonskih vlakana nosive u dva smjera i težine 360 g/m2.
C44: Na očišćenu i pripremljenu podlogu se nanosi epoxi primer, zatim se tkanina utiskuje u epoxi mort za zaglađivanje te se sve impregnira epoxi mortom za impregniranje.
C45: Prionjivost završne obloge / žbuke na epoksidnu smolu osigurati posipavanjem suhog kvarcnog pijeska granulacije 0.7 - 1.2 mm.
C46: Sidrenje traka izvesti u uglovima građevine s užadi prema uputama proizvođača, a što je uključeno u cijenu stavke.
C47: Trake su širine 15 cm, a obračun je po m2. Trake se ugrađuju lokalno prema pozicijama u projektu. Sve plohe ojačane trakama sidre se u zidove užadima od karbonskog vlakna.
...

Sheet OPĆI UVJETI STOL.-STAKL. RADOVI
B2: STOLARSKI RADOVI OPĆI UVJETI Prije pristupa izvođenju radova izvoditelj je dužan izvršiti detaljan pregled svih stolarskih elemenata, prozora i vrata, na uličnom pročelju i krovu. Stolarski elementi ili njihovi dijelovi, kao i pripadajući okov, koji su oštećeni, moraju se zamijeniti novim, prema opisima stavaka troškovnika i mjerama uzetim na licu mjesta. Sav rad mora biti izveden kvalitetno, a za sve detalje i predložene elemente izvoditelj mora pribaviti suglasnost predstavnika GZZZSKP i nadzornog inženjera. Pri izradi novog elementa, u jediničnu cijenu uračunat je gotov stolarski gotov stolarski element sa pripadajućim okovom, ugradnja na građevini, ostakljenjem i završnom obradom onog dijela elementa koji ostavlja vidljive teksture drveta. Osobito pažnju potrebno je posvetiti čišćenju postojećih stolarskih elemenata i njihovom popravku. Jedinična cijena mora obuhvatiti sav rad i materijal, sav transport do i unutar gradilišta i do mjesta gradbe, zaštitni premaz lanenim uljem, sav potreban okov, kao i sve pomoćne radove i materijale. Sav rad, ugrađeni materijal kao i finalni proizvod mora odgovarati važećim tehničkim uvjetima i normama. Popis propisa i normi kojih se treba pridržavati: - HRN M.B1.024 i 510.-vijci za drvo - HRN D.E1.012.-vanjska stolarija - HRN D. E8.193. i 235.-vodonepropusnost i hermetičnost Napomena: Eventualne izmjene mogu se izvoditi samo u skladu s konzervatorskim istraživanjima uz odobrenje predstavnika GZZZZSK i nadzornog inženjera. STAKLARSKI RADOVI OPĆI UVJETI Sav upotrjebljeni materijal i finalni proizvod moraju odgovarati važećim propisima i normama. Ostakljenje mora biti izvedeno propisno i kvalitetno. Polaganje stakla i kita odnosno brtvi na ostakljenoj površini mora osiguravati vodonepropusnost. Jediničnom cijenom obuhvaćen je sav rad, materijal, transport vanjski i unutar gradilišta, sav pomoćni materijal, kao i sve navedeno u stavkama troškovnika i u tehničkim uvjetima za izvođenje staklarskih radova, te svi prateći radovi koji nisu navedeni , a spadaju u staklarske radove i obvezni su za izvoditelja. Sav rad mora bit izveden po važećim propisima i pravilima dobrog zanata. Popis propisa i normi kojih se treba pridržavati: - HRN S.B.E.011.- ravno vučeno staklo - HRN S.H.050.- staklarski kit.

Sheet III. STOLARSKO-STAKL. RADOVI
A1: sub. | B1: R.B. | C1: OPIS STAVKE | D1: JM | E1: KOLIČINA | G1: JEDINIČNA CIJENA | H1: CIJENA UKUPNO
B2: * za sve radove koristiti skelu
A3: UL | B3: 1 | C3: Detaljan pregled vanjskih dijelova dvostrukih prozora i vrata na uličnom pročelju, kako bi se odredio način i obim sanacije ili zamjene dotrajalih dijelova, te prikupili podaci o materijalu, detaljima, profilacijama i obradama. Obračun po stvarno utrošenim satima (prosječno 1h/stolarskoj stavci) odobrenih i ovjerenih od strane nadzornog inženjera. | D3: sati | E3: =1*(67) -> 67 | F3: x
B5: 2 | C5: Sanacija prozora, na uličnom pročelju
C6: Demontaža prozorskih krila trulih i dotrajalih dijelova prozora. Zamjena oštećenih okapnica na krilima prozora, novim okapnicama. Saniranje površinskih oštećenja na doprozornicima i dovratnicima, klupčicama i krilima prozora i vrata nastalih rasušivanjem ili mehaničkim oštećenjem, dvokomponentnim punilom na bazi epoksidne smole (kao voodfill punilo). Plohe nakon sušenja završno obraditi brušenjem ili profiliranjem prema postojećem detalju. Ugradnja suhog uloška za konzervaciju i sprečavanje truljenja (kao voodpill uložak).
C7: Ugrađuju se 4-6 uložaka po prozoru u donjem dijelu na spoju donjeg i okomitih dijelova doprozornika. Čišćenje starog ispucalog molerskog kita na spoju doprozornika i drvenih klupčica te zapunjavanje iste dvokomponentnim punilom na bazi epoksidne smole (kao voodflex punilo). Širina reške cca 10 mm. Dobava i ugradnja silikonske elastične brtve/kita na spoju doprozornika/dovratnika i izvitoperenih krila, radi spriječavanja prodora oborinskih voda, poboljšavanja toplinske i zvučne izolacije. Širina otklona od 2-11 mm. Zahvate sanacije u m' uključiti u ukupnu cijenu stavke.
C8: Prethodno stolar treba uzeti sve potrebne mjere i detalje potrebne za izradu i montažu nove stolarije odnosno, prema uputi nadzornog inženjera i predstavnika nadležnog tijela za zaštitu spomenika kulture, zdrave dijelove sačuvati te ih koristiti, djelomično ili potpuno, u izradi novih dijelova. U slučaju krajnje dotrajalosti elementa, potrebno je predvidjeti nužne stolarske radove, što uključuje premazivanje zaštitnim slojevima, ili izradu potpuno novih prozorskih elemenata kao replike postojećih, sve u komunikaciji s nadležnim konzervatorkskim zavodom i nadzornim inženjerom.
C9: U tom slučaju predvidjeti dobavu materijala, izradu prozora, spojna sredstva i okove, zaštitne premaze, ugradnju, sve potrebne materijale, transporte i rad. Pohrana elemenata na gradilištu ili gdje vlasnik odredi. Izvođač snosi sve troškove ponovne dobave ili izrade pojedinih elemenata u slučaju oštećenja ili otuđenja s gradilišta. Uključen sav vertikalni i horizontalni transport te odvoz viška materijala na mjesni deponij i zbrinjavanje građevinskog otpada sukladno važećim propisima.
C10: Za vrijeme izvedbe radova ojačanja prozorskih otvora voditi računa o izradi zaštitnih oplata (koje su zasebna stavka) radi sprječavanja prodora atmosferilija u unutrašnjost, negativnih utjecaja i dodatnih oštećenja konstrukcije i kulturnog dobra. Procjenjuje se količina dotrajalih elemenata i potpuno dotrajalih elemenata. Obračun po komadu.
A11: UL | C11: Dvokrilni zaokretni prozor, s nadsvjetlom 100 x 180 cm | D11: kom | E11: 10 | F11: x
B13: 3 | C13: Sanacija vrata, na uličnom pročelju
C14: Detaljan popravak dvokrilnih masivnih, uklađenih, urešenih ulaznih vrata od hrastovine, s nadsvjetlom (dim. cca 140 x 390 cm). Stavka obuhvaća izradu i ugradnju novog gornjeg dijela krila na kontaktu s profiliranom sudarnom letvom i novog sokla od hrastovine, čišćenje brušenjem, zapunjavanje svih reški i raspuklina i oštećenja dvokomponentnim punilom na bazi epoksidnih smola te izmjenu dotrajalih okova, u svemu prema izvornom.
C15: Minimalno 60% površine krila s nadsvjetlima za obnovu. U cijenu uračunati kompletan materijal, rad i potreban okov u svemu prema postojećem.
C16: Saniranje površinskih oštećenja na ulaznim vratima i dovratnicima, nastalih rasušivanjem ili mehaničkim oštećenjem, dvokomponentnim punilom na bazi epoksidne smole (kao voodfill punilo). Zamjena istrošenog kamenog praga ulaznih vrata, izrezivanjem dijela i umetanjem novog ili komplet ubacivanjem novog praga.
C17: Plohe nakon sušenja završno obraditi brušenjem ili profiliranjem prema postojećem detalju. Obračun po m' saniranog elementa. Zahvate sanacije u m' uključiti u ukupnu cijenu stavke. Obračun po komadu.
A18: UL | B18: a | C18: dim. cca 140 x 390 cm | D18: kom | E18: 1 | F18: x
A19: UL | B19: b | C19: dim. cca 135 x 285 cm | D19: kom | E19: 1 | F19: x
B21: 4 | C21: Dobava, izrada i ugradnja novih podrumskih jednostrukih, jednokrilnih, otklopnih prozora dimenzije 85/95 x 55 cm. Sva krila se otklopno otvaraju prema unutra. Prozore izraditi od smrekove građe I. klase vlažnosti do max.18%, u svemu prema postojećima, ponavljajući izvorne profilacije i dimenzije, odnosno prema radioničkim nacrtima pregledanim od nadzornog inženjera i prestavnika GZZSKP.
A22: UL | B22: a | C22: Mjere za radioničke nacrte i izvedbu uzeti na gradilištu. Ostakljenje mutnim izo staklom (4-16-4) s Low-E folijom. U cijenu uračunat sav materijal, svi potrebni kompleti okova (u svemu prema izvornom), lajsne, ostakljenje te sva potrebna ukrućenja i kitanja. Dimenzije, profilacije i okov treba odobriti predstavnik GZZSKP. Obračun po komadu i m2 ostakljene površine. | D22: kom | E22: =6+5 -> 11 | F22: x
A23: UL | B23: b | C23: ukupno ostakljenja | D23: m² | E23: =ROUNDUP(E22*0.9*0.55*0.9,1) -> 5 | F23: x
B25: 5 | C25: Dobava, izrada i ugradnja novih drvenih, dvostrukih višekrilnih prozora s nadsvjetlima, pošvama širine cca 30 cm, šprljcima i profiliranim sudarnim letvama te ostakljenjem. Sva krila i nadsvjetla se zaokretno otvaraju prema unutra, zaokretno. Okvire i krila izraditi od bora ili ariša I.klase, vlažnosti do max 18 %, u svemu prema postojećima, ponavljajući izvorne profilacije i dimenzije, odnosno prema radioničkim nacrtima pregledanim od nadzornog inženjera i prestavnika GZZSKP.
C26: Mjere za radioničke nacrte i izvedbu uzeti na gradilištu. Ostakljenje izo staklom (4-16-4) mm. Ugraditi ojačanja za izo paket !; uzeti u obzir dvostruka krila prozora. U cijenu uračunat sav materijal, svi potrebni kompleti okova (u svemu prema izvornom), ukrasne lajsne, rolete s vodilicama, gurtnama i mehanizmom, ostakljenje, sva potrebna ukrućenja i kitanja te sav vertikalni i horizontalni transport. Dimenzije, profilacije i okov treba odobriti predstavnik GZZSKP. Obračun po komadu i m² ostakljene površine.
A27: UL-S | B27: 5.1. | C27: Dvokrilni zaokretni prozor, s nadsvjetlom 100 x 180 cm | D27: kom | E27: 48 | F27: x
A28: UL-S | C28: ukupno ostakljenja | D28: m² | E28: =ROUNDUP(1*1.8*0.95*E27,0) -> 83 | F28: x
A29: UL | C29: radovi | D29: kpl | E29: =E27 -> 48 | F29: x
A30: UL-S | B30: 5.2. | C30: fiksna stijena (izlog) s nadsvjetlom, s otklopnim nadsvjetlom 140 x 275 cm | D30: kom | E30: 1 | F30: x
A31: UL-S | C31: ukupno ostakljenja | D31: m² | E31: =ROUNDUP(1.4*2.75*0.95*E30,0) -> 4 | F31: x
A32: UL | C32: radovi | D32: kpl | E32: =E30 -> 1 | F32: x
C34: III. STOLARSKO - STAKLARSKI UKUPNO: | H34: =SUM(H3:H20) -> 0

Sheet OPĆI UVJETI BRAV.-LIM. RADOVI
B1: BRAVARSKI RADOVI OPĆI UVJETI Sav upotrijebljeni materijal i finalni građevinski proizvodi moraju odgovarati važećim tehničkim propisima i normama. Popis propisa i normi kojih se treba pridržavati: - HRN C.B3.025.-plosnato željezo - HRN C.B.024.-kvadratno željezo Sva nova bravarija mora biti u potpunosti izvedena kao i postojeća i prije dostave na gradilište treba biti zaštićena antikorozivnim premazom. Svi detalji izvedbe i ugradbe bravarije moraju biti odobreni od predstavnika GZZZSKP i nadzornog inženjera investitora. Snimanje postojeće bravarije i uzimanje uzoraka uključeno je u cijenu pojedine stavke i ne iskazuje se posebno. U cijenu pojedine stavke treba uključiti: - snimanje, uzimanje mjera i uzoraka postojeće bravarije - izrada i ugradnja bravarskih elemenata - sav vanjski i unutarnji, vertikalni i horizontalni transport, - okov i spojna sredstva, - ličenje i bojanje sa svim predradnjama, - sav sitni i spojni materijal i naknada za strojeve i alate. Napomena: Eventualne izmjene mogu se izvoditi samo u skladu s konzervatorskim istraživanjima uz odobrenje predstavnika GZZZSK i nadzornog inženjera LIMARSKI RADOVI OPĆI UVJETI ZA Svi radovi moraju se izvoditi prema izvedbenoj projektnoj dokumentaciji i prema važećim tehničkim propisima i HR normama: - Pravilnik o tehničkim normativima za projektiranje i izvođenje završnih radova u građevinarstvu Sl. list SFRJ 21/90 - odvodnjavanje krovova i otvorenih dijelova zgrade limenim elementima - Tehnički uvjeti za izvođenje limarskih radova - HRN U.N9.052 -Građ.prefabr.elementi: Prozorska limena klupčica, - HRN U.N9.053 -Građ.prefabr.elementi: Odvodnjavanje krovova i dijelova zgrada limenim elementima - HRN U.N9.054 -Građ.prefabr.elementi: Pokrivanje krovnih ravnina limom - HRN U.N9.055 -Građ.prefabr.elementi: Opšivanja vanjskih dijelova zgrada limom Sav upotrebljeni materijal i finalni građevinski proizvodi moraju odgovarati postojećim tehničkim propisima i HR normama. Prilikom izvedbe limarskih radova treba se u svemu pridržavati postojećih propisa i normi. Izvođač je dužan prije početka radova: • predočiti projektantu detalje izvedbe i savijanja limova • tek po odobrenju i nakon ovjere istih od strane projektanta radovi može pristupitit izvedbi radova • provjeriti sve građevinske elemente na koje se pričvršćuje limarija • pismeno dostaviti naručitelju svoje primjedbe u vezi eventualnih nedostataka, naročito u slučaju: neodgovarajućeg izbora projektiranog materijala i loše riješenog načina vezivanja limarije za građevinske radova. Izrada rješenje neće se posebno platiti već predstavlja trošak i obvezu izvoditelja. Prilikom izvođenja limarije mora se izvoditelj striktno pridržavati usvojenih i od strane projektanta ovjerenih detalja. Cijenom izvedbe radova treba obvezno uključiti sve materijale koji se ugrađuju i koriste (osnovne i pomoćne materijale), sav potrebna rad (osnovni i pomoćni) na izvedbi radova do potpune gotovosti i funkcionalnosti istih, sve transporte i prijenose do i na gradilištu sve do mjesta ugradbe, sva potrebna uskladištenja i zaštite, sve potrebne zaštitne konstrukcije i skele, kao i sve drugo predviđeno mjerama zaštite na radu i pravilima struke. U cijeni treba također uključiti izvedbu i obradu raznih detalja limarije kod spojeva, prijelaza, lomova i sudara ploha, završetaka limarije i drugo, sve obvezno usklađeno sa drugim različitim materijalima i radovima uz limariju, do potpune gotovosti i funkcionalnosti. Dijelovi različitog materijala ne smiju se dodirivati jer bi uslijed toga moglo doći do korozije. Elementi od čelika za pričvršćivanje cinčanog ili pocinčanog lima moraju se pocinčati, ako u opisu radova nije predviđena neka druga zaštita (postavljanje podmetača od olova ili plastike otpornih na kiseline ili lužine). Za bakreni lim treba primijeniti učvršćivanje od bakra ili bakrenog čelika. Na spoju lima i podloge (beton, žbuka, drvo i dr.) treba postaviti razdjelni sloj (npr. krovna ljepenka) po cijeloj površini spoja. Sve vidljive spojeve lima i betonskih ili ožbukanih fasadnih ploha treba brtviti po cijeloj dužini spoja trajno elastičnim (plastičnim) bezbojnim kitom. Sve spojeve lima treba obvezno izvesti nepropusno. Plohe izvedene limom moraju biti izvedene pravilno i u ravnini, po nagibima odvodnje i kosinama definiranim u projektu. Sastav i učvršćenja moraju biti tako izvedeni da elementi pri toplotnim promjenama mogu nesmetano dilatirati, a da pri tom ostanu nepropusni. Moraju se osigurati od oštećenja koje može izazvati vjetar i sl. Ispod lima koji se postavlja na beton, drvo ili žbuku treba postaviti sloj bitumenske ljepenke, čija su dobava i postava uključene u jediničnu cijenu. Probijanja u metalnom pokrivaču (učvršćivanje dimnjaka, cijevi kupola itd.) moraju biti pažljivo izvedena kod pocinčanog lima pomoću lemljenja, a kod bakrenog pomoću dvostruko položenog ruba vezanog vodonepropusno s pokrovom. Izvođač će pristupiti izvedbi tek nakon što projektant potpisom potvrdi radioničke nacrte i tehnološku razradu svih detalja. Jedinična cijena uključuje : • uzimanje mjera na gradilištu i definiranje ugradbenih dimenzija • tehnološku razradu svih detalja • pripremu podloga • izradu radioničkih nacrta • sav spojni materijal • postavu i skidanje radne skele • sve posredne i neposredne troškove za rad, materijal, alat i građevinske strojeve • sve transporte • čišćenje tokom rada, odvoz i zbrinjavanje smeća • završno čišćenje prije primopredaje radova • nadoknadu eventualne štete nastale iz nepažnje na svojim ili tuđim radovima • sva manja potrebna usijecanja utora nužna za ugradbu i savijanje lima i izvedbu detalja, kao i sva sitnija usijecanja ploha te potrebne popravke i zapunjavanja nastalih međuprostora i pukotina cem. mortom Obračun: • žljebovi, cijevi, opšavi i sl. definirani razvijenom širinom lima u dužinama izraženim u m1 • limeni krovni pokrovi u površini izraženoj u m2 • limene fasade u površini izraženoj u m2

Sheet IV. BRAVARSKO-LIMARSKI RADOVI
A1: sub. | B1: R.B. | C1: OPIS STAVKE | D1: JM | E1: KOLIČINA | G1: JEDINIČNA CIJENA | H1: CIJENA UKUPNO
B2: * za sve radove koristiti skelu ** kod limova i ostalih metalnih elemenata koristiti opremu isključivo od istog materijala ili sličnog (radi izbjegavanja pojave galvanskih struja)
B3: 1 | C3: Dobava, izrada i ugradnja limenih opšava prema opisu u nastavku, od pocinčanog lima 0,6 mm razvijene širine prema opisu. Postava limova na vijencima i prozorskim klupčicama. Dimenzije uzeti na gradilištu, a način polaganja i savijanja izvoditi prema radioničkim nacrtima koje odobrava nadzorni inženjer i predstavnik GZZSKP; posebnu pažnju obratiti na rješenje spoja s drvenom stolarijom i prozorskim špaletama.
C4: Spajanje opšava se vrši sa stojećim prijevojima okomito na okaps te zakovicama, vijcima s gumenim podloškama i lemljenjem - sve od istog materijala, prema pravilima struke. Između lima i podloge postaviti krovnu ljepenku, koja je uključena u jediničnu cijenu. Okapnice opšava dilatirati min. 3 cm od gotove fasade. Na strani zida opšav podvući pod žbuku u visini min. 5 cm. Opšav izvesti u padu, od pročelja. U cijenu je uključena izrada i postava limarije, sve pomoćne konstrukcije, podložna ljepenka i sva učvršćenja. Obračun po m' opšava. | E4: Nudimo pocinčani i plastificirani lim debljine 0,50 mm
A5: UL | C5: opšav vijenca iznad prizemlja - r.š. do 25 cm | D5: m¹ | E5: ='I. b. RUŠENJA I DEMONTAŽE'!E13 -> 48 | F5: x | G5: 55 | H5: =E5*G5 -> 2640
A6: UL | C6: prozorske klupčice - r.š. do 45 cm | D6: m¹ | E6: =ROUNDUP(62.65,0) -> 63 | F6: x | G6: 65 | H6: =E6*G6 -> 4095
B8: 2 | C8: Cijevi oborinske vertikale
C9: Dobava i ugradnja okruglih cijevi od pocinčanog lima 0,60 mm, za odvodnju krovnih voda, okruglog presjeka ¤ 125 mm, razvijene širine cca 40 cm., zajedno s izvedbom koljena odnosno priključcima na žlijebove (preko sabirnih kotlića) i vertikalnu odvodnu cijev (od ljevanog željeza) u zoni prizemlja. Cijevi se učvršćuju prihvatnicama na svaka 2 m, u istom materijalu cijevi. Spajanje cijevi se vrši zakovicama i lemljenjem. Na mjestima prolaza oluka kroz konstrukciju vijenaca, potrebno je oluk izolirati hladnim bitumenskim premazom te krovnom ljepenkom.
C10: Spoj bakrene cijevi na ljevano željeznu cijev u zoni prizemlja izvršiti postavom tuljka te omatanjem užeta, nabijanjem i zalijevanjem olovom - do potpunog brtvljenja. U cijenu uračunati i eventualna spajanja postojećih kondenzata u limene vertikale (spoj različitih materijala tretirati u svrhu izbjegavanja pojave galvanskih struja). U cijenu je uključena izrada i postava limarije, sve pomoćne konstrukcije i sva učvršćenja. Obračun po m', broju obujmica, prodora kroz vijence i spojeva na ljevano željeznu cijev.
C11: * Po odluci odluci nadzornog inženjera i predstavnika GZZSKP, ovu stavku je moguće izvesti od postojećih elemenata ukoliko se demontiraju i privremeno deponiraju na gradilištu ili kod korisnika/vlasnika/zakupca, operu i očiste te ponovnom montiraju do pune ispravnosti.
A12: UL | B12: 2.1. | C12: - prodor oluka kroz vijence | D12: kom | E12: 4 | F12: x
A13: UL | B13: 2.2. | C13: - pocinčane cijevi | D13: m¹ | E13: =2*15.5 -> 31 | F13: x
A14: UL | B14: 2.3. | C14: obujmica | D14: kom | E14: =E13/2 -> 15.5 | F14: x
A15: UL | B15: 2.4. | C15: - ljevano željezo; vertikala kom 4 | D15: m¹ | E15: ='I. b. RUŠENJA I DEMONTAŽE'!E63 -> 6 | F15: x
A16: UL | B16: 2.5. | C16: obujmica | D16: kom | E16: =ROUNDUP(E15/0.8,0) -> 8 | F16: x
A17: UL | B17: 2.6. | C17: - spoj u ljevano željeznu cijev | D17: kom | E17: 4 | F17: x
B19: 3 | C19: Pregled, prema potrebi demontaža i popravak postojećih metalnih elemenata (balkonske ograde, konstrukcija nadstrešnica balkona). Ravnanje, izmjena elemenata u lošem stanju te priprema za daljnju obradu - sve kako bi se vratilo u izvorno stanje. Priprema prihvata/učvršćenja elemenata za zidanu/betonsku konstrukciju zgrade te ponovna ugradnja s novim prihvatnim elementima, u svemu prema postojećim.
C20: U cijenu je uključen sav opisani rad, izmjenjen materijal, pomoćne konstrukcije, sva učvršćenja i sav horizontalni i vertikalni transport. Obračun po komadu.
A21: UL | C21: - rešetke/vrata podrumskih prozora u podnožju zgrade (ugrađene u kamenu žbuku), dim. cca 85/95 x 55 cm | D21: kom | E21: 11 | F21: x
B23: 4 | C23: Čišćenje od stare boje i pjeskarenje metalnih dijelova postojećih elemenata od željeza. Pjeskarenje različitim abrazivima i granulatima – prema standardima ISO 8501-1. Priprema površina mlazom abraziva (prema ISO 8501-1) oznaka: Sa 2; obuhvaća - Temeljito čišćenje mlazom „Površina mora biti, gledano bez povećala, čista bez vidljivih tragova ulja, masti i prljavštine i skoro potpuno bez cakline, hrđe, premaza i stranih nečistoća. Svi preostali ostaci moraju čvrsto prianjati“.
C24: Tijekom izvođenja radova treba se pridržavati svih propisanih pravila ZNR. Stavka obuhvaća i svu zaštitu zgrade i osoba kao i svo čišćenje nakon obavljenog posla. U cijenu je uključen sav rad, materijal, pomoćne konstrukcije i sav horizontalni i vertikalni transport. Obračun po komadu.
A25: UL | C25: - rešetke prozora prizemlja (ugrađene u žbuku), dim. cca 100 x 160 cm | D25: kom | E25: 1 | F25: x
B27: 5 | C27: Ojačanja spojeva glavnog krovišta.
C28: Pojačanje spoja/čvora drvene konstrukcije glavnog krovišta izvesti prema projektu konstrukcije. Pojačanje čvora izvesti pomoću čeličnih limova.
C29: Složeno ojačavanje čvora podrazumijeva ojačanje spoja čeličnim limovima, te vijčanim i zavarenim vezama (pozicije prema projektu).
C30: U cijenu uključiti i izvedbu svih spojeva prema projektu. U cijenu uračunat sav potreban materijal, spajala, završna obrada, rad, transporte, čišćenje radne okoline tijekom i nakon ugradnje.
A31: KR | C31: Obračun po komadu ojačanog čvora. | D31: kom | E31: 12 | F31: x
B33: 6 | C33: Ojačanje veznih greda i podrožnica.
C34: Pojačanje spojeva veznih greda s podrožnicama/nazidnicama u krovištu. Pojačanje izvesti ugradnjom UNP 140 profila, S 235, način ojačanja izvesti prema projektu konstrukcije.
C35: Ojačanje se izrađuje u zavarenoj te vijčanoj izvedbi; zavari kvalitete prema normi HRN EN ISO 5817. Vijci M12 koriste se za međusobno povezivanje profila, sve prema projektu.
C36: U cijenu uračunata antikorozivna zaštita u dva premaza temeljnom bojom za profile unutar objekta, te sva potrebna spojna i pričvrsna sredstva.
A37: KR | C37: U cijenu uključiti i izvedbu svih spojeva prema projektu. U cijenu uračunat sav potreban materijal, spajala, rad, transporte, čišćenje radne okoline tijekom i nakon ugradnje. Obračun po kg izvedenog ojačanja. | D37: kg | E37: 65 | F37: x
C40: IV. BRAVARSKO-LIMARSKI RADOVI UKUPNO: | H40: =SUM(H3:H38) -> 6735

Sheet OPĆI UVJETI SOBOSL. I LIČ. RAD
B2: SOBOSLIKARSKO-LIČILAČKI RADOVI OPĆI UVJETI Sav upotrijebljeni materijal kao i finalni proizvod moraju odgovarati važećim tehničkim propisima i normama. Popis propisa i normi kojih se treba pridržavati: - pravilnik o zaštiti na radu u građevinarstvu, - pravilnik o tehničkim mjerama i uvjetima za završne radove u građevinarstvu, - HRN U.F2.013.-tehnički uvjeti za izvođenje soboslikarskih radova, - HRN U.F2.012.- tehnički uvjeti za izvođenje ličilačkih radova, - HRN B.C1.030.-gips neutralan i čist, - HRN H.K2.015.-kalijev sapun, - HRN B.C1.020.-hidratizirani vapno, - HRN B.C5.020.-firnis lanenog ulja, - HRN H.C1.034.-cinkov kromat - HRN H.C1.002.-uljene boje i lakovi Svi radovi moraju se izvoditi po izabranom uzorku i tonu, koje je ličilac dužan izvesti prije početka radova od materijala od kojih se radovi izvode, a u svemu prema uputama proizvođača i GZZZSKP. Na tako izvedene uzorke izvoditelj mora ishodovati suglasnost predstavnika GZZZSKP i nadzornog inženjera investitora, pa tek onda početi sa izvođenjem radova. Ukoliko se bojanje pročelja izvodi preko potpuno nove žbuke, tj. homogene površine, upotrijebit će se silikatni premaz sa svim potrebnim predradnjama u skladu s uputama proizvođača, kao što je impregniranje površine pročelja. Ukoliko se bojanje pročelja izvodi preko žbuke koja je samo djelomično sanirana tj. površina nije homogena već se sastoji od dijelova stare i nove žbuke, upotrijebit će se također silikatni premaz, ali tako da se najprije nanese temeljni sloj koji će izjednačiti strukturu,upojnost i kemijsku reakciju podloge. Bojanje mora biti kvalitetno i dobro izvedeno. Na obojenim površinama ne smije biti mrlja, površine moraju biti jednolične i čiste i ne smiju se ljuštiti. Kit za ispunjenje udubina i pukotina mora biti srodnog sastava podlozi i boji. Ličenje bravarskih dijelova izvodi se nakon čišćenja rđe, premazom temeljne boje i potom liči vanjskom bojom za željezo u dva sloja. Ličenje stolarije se izvodi nakon skidanja starog naličja otapalima ili paljenjem. Potom je potrebno stolariju obrusiti , natopiti firnisom, kitati te ponovno brusiti. Na tako pripremljenu podlogu nanosi se dvostruki nalič, te lakira lakom otpornim na atmosferilije. Izbor tona, vrši se prema postojećem, a u suglasnosti s predstavnikom GZZZSKP i nadzornim inženjerom. Jedinična cijena obuhvaća sav rad, materijal, sve troškove nabave i dopreme, skidanje i ponovno postavljanje vanjske stolarije (vratna i prozorska krila), izradu uzoraka i sva čišćenja po završetku radova. Prije početka radova izvođač mora ustanoviti kvalitetu podloge za izvođenje soboslikarskih i ličilačkih radova i ako ona nije pogodna za taj rad mora o tome pismeno obavijestiti svog naručioca radova, kako bi se na vrijeme mogla podloga popraviti i prirediti za soboslikarsko ličilačke radove. Kasnije pozivanja i opravdanja da kvaliteta nije dobra radi loše podloge neće se uzimati u obzir.

Sheet V. SOBOSLIK.-LIČILAČKI RADOVI
A1: sub. | B1: R.B. | C1: OPIS STAVKE | D1: JM | E1: KOLIČINA | G1: JEDINIČNA CIJENA | H1: CIJENA UKUPNO
B2: * za sve radove koristiti skelu ** Obračun i izmjere vršiti prema tehničkim uvjetima za soboslikarsko-ličilačke radove
A3: UL | B3: 1 | C3: Bojanje pročelja u zoni prizemlja i sokla uličnog pročelja, obnovljenog kompletno novom žbukom, prozirnim antigrafitnim premazom u potrebnom broju slojeva, ovisno o odabranom proizvođaču (voditi računa o kompatibilnosti slojeva, vidi ostale stavke). Bojanje izvesti u skladu sa zahtjevima proizvođača. Jediničnom cijenom obuhvatiti: potrebnu impregnaciju odgovarajućim sredstvom i bojanje u broju zahtjevanih slojeva. Obračun po m² ortogonalne projekcije pročelja (pročelje je površine zone prizemlja 117 m² bez odbitka prozora). (U količinu uračunat dodatak na složenost pročelja od 33%, i nikakav drugi dodatak u obračunu neće se priznati.) | D3: m² | E3: =ROUNDUP(47*2.5*3/2,0) -> 177 | F3: x
