Workbook

Sheet Opći uvjeti i napomene
B2: INVESTITOR: MINISTARSTVO UNUTARNJIH POSLOVA RH
B3: LOKACIJA: JASTREBARSKO, ZRINSKI-FRANKOPANSKA ULICA BB
B4: GRAĐEVINA: ZGRADE BR. 11, 12, 13, 14, 15, 20, 21, 61, 62 I VANJSKI PROSTOR
B5: RADOVI: UREĐENJE GRAĐEVINA, VANJ. PROSTORA I INFRASTRUKTURE
B6: PROJEKTANT: APG-INŽENJERING d.o.o. DUGO SELO
B33: TROŠKOVNIK GRAĐEVINSKO-OBRTNIČKIH I INSTALATERSKIH RADOVA
B62: ožujak 2026. godine
A64: stavka | B64: opis stavke | C64: jedin. mjere | D64: količina | E64: edinična cijena (euro) | F64: ukupno (euro)
B66: OPĆI UVJETI I NAPOMENE
B68: JEDINIČNA CIJENA
B69: U jediničnim cijenama za sve stavke troškovnika, ponuda mora sadržavati ukupne troškove materijala i rada do potpunog dovršenja cjelokupnog posla odnosno do pune funkcionalnosti. Jedinična cijena, također, uključuje sva potrebna ispitivanja, kontrole i mjerenja za sve izvedene radove, ugrađene materijale i opremu. Sve predmetno je obuhvaćeno jediničnom cijenom i ne navodi se kao zasebna stavka. Trošak pribavljanja sve atestne dokumentacije uključiti u cijenu nuđenih stavki, jer se posebni troškovi neće priznati. Izvođač treba kvalitetu ugrađenih materijala i stručnosti radnika dokazati odgovarajućim atestima i uvjerenjima izdanim od strane za to ovlaštene organizacije i to uračunati u cijenu pojedinih stavaka. Kod cijene nuđenja voditi računa da je za vrijeme građenja raskriveni dio građevine zaštićen od oborina.
B70: Izvođač je dužan kod nuđenja voditi računa da otpad mora razvrstati i takav razvrstan deponirati na specijaliziranim odlagalištima, pa kod izrade ponude ponuditelj treba voditi računa o udaljenostima za najbliže specijalizirane deponije kao i troškove taksi na njima (deponija metal-staklo-građevinska plastika-stiropor i drugo), uključiti u pojedinoj stavci. Sve navedene radnje uključiti s cijenom u pojedinim stavkama, jer se posebna plaćanja neće priznati. U svim stavkama uključiti i sav potreban horizontalni i vertikalni transport do mjesta ugradnje. Za sve stavke građevinsko-obrtničkih i instalaterskih radova potrebno je uključiti sva gruba i fina čišćenja prilikom i nakon izvođenja radova, jer se dodatni troškovi neće dodatno naplaćivati.
B72: OBILAZAK PREDMETNE LOKACIJE
B73: Ponuditelj može obići i detaljno pregledati lokaciju (građevinsku česticu, građevinu/e, zonu obuhvata). Neovisno o tome je li ponudtitelj obišao lokaciju, naručitelj će smatrati da je ponuditelj obišao i detaljno pregledao lokaciju (građevinsku česticu, građevinu/e, zonu obuhvata), te je dobro upoznat sa svim uvjetima, faktorima i resursima u odnosu i u vezi s lokacijom ili onim koji mogu utjecati na izvršenje radova, te da je na temelju navedenog podnio svoju ponudu. Stoga odabrani ponuditelj nema pravo zahtjevati povećanje cijene ili drugu naknadu, pozivajući se da u vrijeme davanja ponude nije bio upoznat s okolnostima vezanim uz lokaciju (građevnu česticu, građevinu/e, zonu obuhvata). U slučaju kakvih nejasnoća illi ocijene ponuditelja da je neko od rješenja neprihvatljivo, postaviti upit naručitelju radi razrješenja detalja. U protivnom od izvođača će se zahtjevati izvođenje detalja kao što je projektant predložio.
B74: Za pojedine elemente dani su normativi važeći na dan pisanja ovog troškovnika. U slučaju da isti u razdoblju do početka realizacije ovih radova ili u njihovom tijeku budu izmijenjeni, primjenjuju se normativi važeći u vrijeme izvođenja radova. Sav ugrađeni materijal treba odgovarati uvjetima iz opisa troškovnika i nacrta, te odgovarajućim normama ili tehničkim uvjetima za izvođenje istih radova, a ukoliko se to posebno traži opisom i drugim propisima. Ugrađeni materijali se mogu razlikovati od predviđenih tehničkih uvjeta ili normi ukoliko zadovoljavaju tehničke uvjete i norma koje su jednakovrijedne ili slične navedenima. Prije početka izvođenja pojedine vrste radova izvođač mora dokumentacijom dokazati da je ovlašten za izvođenje tih radova odnosno ugradnju materijala odabranog proizvođača.
B75: Prije početka radova potrebno je izvesti pripremne radove sve u skladu sa zakonskom regulativom s područja zaštite na radu i područja kompletne građevinske regulative, a naročito radove niže navedene. Trošak ovih radova potrebno ukalkulirati u cijenu građenja jer se isti neće posebno obračunavati. - Dobava i montaža privremene ograde u svrhu zaštite prostora samoga gradilišta vizualno i sigurnosno od prostora ostatka parcele, koja mora udovoljavati svim uvjetima važećeg zakona o zaštiti na radu - Izrada plana organizacije gradilišta.
B76: Izvođač je sukladno važećem Zakonu o zaštiti na radu dužan poduzimati sve propisane mjere i radnje tijekom izvođenja radova proizašle iz tog zakona i cijelokupne pozitivne regulative s područja zaštite na radu, a naročito sljedeće: 1. Osigurati kontenjere na gradilištu za: a/ kontenjer - garderobni za radnike b/ kontenjer - za odmor radnika c/ kontenjeri - za sanitarne potrebe radnika sa suhim WC-ima d/ kontenjer - za tehničku službu gradilišta e/ kontenjer - za nadzornu službu Kontenjeri moraju biti izrađeni i postavljeni u skladu s regulativom s područja zaštite na radu. 2. Postaviti sve potrebne znakove. 3. Postaviti sve zaštitne ograde u svrhu zaštite prostora gradilišta (vizualna i sigurnosna zaštita). 4. Adekvatno razupirati, osigurati i zaštititi sve iskope. 5. Osigurati i zaštititi sve okolne građevine kao cijeline i pojedine njihove dijelove. 6. Plan organizacije gradilišta. Sve navedeno uključiti u pojedine stavke jer se isto neće posebno naplaćivati.
B77: Za potrebe izvođenja radova izvođač je dužan osigurati privremene priključke na infrastrukturu po na osob niskonaponsku električnu mrežu i vodovodnu mrežu, te isto mora biti uključeno u jediničnu cijenu. Odabir za sve materijale gdje će to biti potrebno odabir dezena boja i slično vršit će projektan uz suglasnost korisnika i odobrenje investitora. Prije nabave i ugradnje svih materijala, proizvoda i opreme, karakteristike istih moraju biti pregledane i odobrene od strane stručnog nadzora (kako bi se utvrdilo da iste odgovaraju traženim karakteristikama u predmetnoj stavci troškovnika).
B79: POPIS PRIMJENJENIH ZAKONA, PRAVILNIKA I TEHNIČKIH PROPISA
B80: 1. Zakon o gradnji (NN 153/13, 20/17, 39/19, 125/19, 145/24) 2. Zakon o prostornom uređenju (NN 153/13, 65/17, 114/18, 39/19, 98/19, 67/23) 3. Zakon o komori arhitekata i komorama inženjera u graditeljstvu i prostornom uređenju (NN 78/15, 114/18, 110/19) 4. Zakon o poslovima i djelatnostima prostornog uređenja i gradnje (NN RH 78/15, 118/18, 110/19) 5. Zakon o građevnim proizvodima (NN 76/13, 30/14, 130/17, 39/19, 118/20) 6. Zakon o normizaciji (NN 80/13) 7. Zakon o tehničkim zahtjevima za proizvode i ocjenjivanju sukladnosti (NN 80/13, 14/14, 32/19) 8. Zakon o zaštiti okoliša (NN 80/13, 153/13, 78/15, 12/18, 118/18) 9. Zakon o zaštiti od požara (NN 92/10) 10. Zakon o energetskoj učinkovitosti (NN 127/14, 116/18, 25/20) 11. Zakon o zaštiti od buke (NN 30/09, 55/13, 153/13, 41/16, 114/18) 12. Zakon o zaštiti na radu (NN 71/14, 118/14, 154/14, 94/18, 96/18) 13. Zakon o zaštiti na radu na privremenim gradilištima (NN 48/18)
... B475: NAČELA DNSH KOJA SE OBAVEZNO MORAJU POŠTIVATI:
A476: 1. | B476: Tijekom gradnje građevine potrebno je posebnu pažnju posvetiti rješenjima za gospodarenje građevnim otpadom. Tijekom građenja građevine izvođač je dužan gospodariti građevnim otpadom nastalim tijekom građenja i/ili pri uklanjanju građevine ili njezinog dijela na gradilištu, te oporabiti i/ili zbrinuti građevni otpad nastao tijekom građenja na gradilištu te o tome na gradilištu imati propisanu dokumentaciju sukladno propisima koji uređuju gospodarenje otpadom. Materijal nastao rušenjem izvođač je dužan privremeno deponirati u neposrednoj blizini objekta, te ga po završetku radova zbrinuti u skladu s hijerarhijom otpada i EU Protokolom o gospodarenju građevinskim otpadom i rušenjem. Izvođač je dužan najmanje 70% neopasnog građevinskog otpada i otpada od rušenja nastalog na gradilištu pripremiti za ponovnu uporabu, recikliranje i korištenje drugog materijala, uključujući operacije zatrpavanja za otpad koji zamjenjuje druge materijale. Prema karakteristikama dijelova građevine koji se uklanjaju, ocjenjuje se da će nakon uklanjanja u najvećoj mjeri nastati neopasni i/ili inertni građevinski materijal. Nakon uklanjanja građevine potrebno je sav nastali otpad od uklanjanja zbrinuti po ključnim brojevima otpada, u skladu s odredbama Zakona o gospodarenju otpadom (NN 84/21). Sav otpad, građevinski i ostali, koji ostaje na lokaciji objekta nakon rušenja potrebno je pohraniti i odložiti na prostorima predviđenim za to. Otpad je potrebno sortirati prema ključnim brojevima. Sve ukalkulirati u jedinične cijene kod nuđenja.
B477: Propisi: Zakon o održivom gospodarenju otpadom (NN 94/13, 73/17, 14/19, 98/19), Pravilnik o gospodarenju otpadom (NN 106/22), Pravilnik o građevinskom otpadu i otpadu koji sadrži azbest (NN 69/16)
A478: 2. | B478: Za ugrađene materijale potrebna je dostava CO2 otiska.
A479: 3. | B479: Kod izvođenja radova gdje god je to moguće koristiti se sivom vodom za koju je potrebno kod organizacije gradilišta predvidjeti spremnike. Sve ukalkulirano u režijske troškove gradilišta.

Sheet Zgrada 11
A1: stavka | B1: opis stavke | C1: jedin. mjere | D1: količina | E1: jedinična cijena (euro) | F1: ukupno (euro)
A3: I. | B3: ZGRADA 11
A5: A. | B5: GRAĐEVINSKO-OBRNIČKI RADOVI
A7: 1. | B7: SKELA
A8: 1.1. | B8: Dobava, postava, skidanje i otprema cijevne fasadne skele, od bešavnih cijevi. Skelu izvesti prema važećim HTZ propisima. Skelu je potrebno osigurati od prevrtanja, sidrennjem u građevinu, a od udara munje uzemljenjem. Potrebno je izvesti pomične željezne ili drvene ljestve – penjalice u svrhu osiguranja vertikalne komunikacije po skeli. Prije izvedbe skele izvođač je dužan izraditi projekt skele, što je u cijeni stavke. Obračun se vrši po m² vertikalne projekcije površine skele. Stavka uključuje rad i materijal osnovni i pomoćni, sve do potpune funkcionalnosti. | C8: m2 | D8: 698 | E8: 11.55 | F8: =D8*$E8 -> 8061.9
B9: 1. Skela ukupno: | F9: =SUM(F8) -> 8061.9
A15: 8. | B15: ZIDARSKI RADOVI
A16: 8.9. | B16: Izrada i ugradnja grube žbuke pročelja zgrade od opeke. Prije žbukanja podlogu špricati rijetkim cementnim mortom. Žbuka se produžnim mortom M-10 debljine do 4 cm. Visina žbukanja do 5,0 m. Stavka uključuje sav materijal, rad i upotrebu radne skele. | C16: m2 | D16: 479 | E16: 55 | F16: =D16*$E16 -> 26345
A17: 8.10. | B17: Izrada i ugradnja grube i fine žbuke s vanjske strane temelja i sokla prije postavljanje hidroizolacije. Prije žbukanja podlogu špricati rijetkim cementnim mortom. Žbuka se produžnim mortom M-10 debljine do 4 cm. Visina žbukanja do 5,0 m. Stavka uključuje sav materijal, rad. | C17: m2 | D17: 194 | E17: 55 | F17: =D17*$E17 -> 10670
B18: 8. Zidarski radovi ukupno: | F18: =SUM(F16:F17) -> 37015
A20: 9. | B20: RAZNI ZIDARSKI RADOVI
A21: 9.1. | B21: Brtvljenje fasadnih otvora (prozora, stijena i vrata) samoljepljivom trakom. Dobava i ugradnja samoljepljive gumirane trake za fiksiranje. Tehničke karakteristike koje proizvod mora zadovoljiti: - Širina min. 5cm - Otpornost na trganje: ≥150 N/50 mm - Izduženje do sloma: ≥20% Trake se lijepe na prethodno otprašenu podlogu, otprašivanje uključeno u stavci. Stavka uključuje sav rad i materijal osnovni i pomoćni. Sve izvesti prema pravilima struke i po uputi proizvođača. Obračun po m'.
A22: a) | B22: postava s vanjske strane | C22: m' | D22: 175.2 | F22: =D22*$E22 -> 0
A23: b) | B23: postava s unutarnje strane | C23: m' | D23: 175.2 | F23: =D23*$E23 -> 0
A24: 9.2. | B24: Obrada špaleta oko otvora u vanjskom zidu. Krpanje i nanos izravnavajućeg sloja produžnim mortom M-5. Stavka uključuje sav materijal i rad, te upotrebu radne skele.
A25: a) | B25: vanjska obrada špalete | C25: m' | D25: 170 | E25: 16 | F25: =D25*$E25 -> 2720
A26: b) | B26: unutarnja obrada špalete | C26: m' | D26: 170 | E26: 16 | F26: =D26*$E26 -> 2720
A27: 9.3. | B27: Zidarski popravak površina ispod prozorskih klupčica koji obuhvaća: - nabavu nedostajućih cigli - nabavu i pripremu veznog materijala - zidarsko zatvaranje i dopunjavanje rupa. Stavka uključuje sav materijal i rad, te upotrebu radne skele. | C27: m2 | D27: 13 | F27: =D27*$E27 -> 0
A28: 9.4. | B28: Nabava materijala i izrada izravnavajućeg sloja cementne glazure debljine 4-6 cm s gornje strane prozorskih klupčica, a prije postave limenog opšava i prozorskih klupčica. Pad izvesti od građevine. Stavka uključuje sav materijal i rad, te upotrebu radne skele. Obračun po m² površine. | C28: m2 | D28: 13 | F28: =D28*$E28 -> 0
A29: 9.5. | B29: Zidarska obrada nakon postave limarije. Krpanje žbuke po postavi limarskih opšava vijenaca i prozorskih klupčica s produžnim mortom. Krpanje izvesti na način da se između zida i horizontalnog dijela limarskih opšava izvodi uvučena reška širine 1-2 cm. Stavka uključuje sav materijal i rad, te upotrebu radne skele. Obračun po m² površine. | C29: m2 | D29: 256 | E29: 60 | F29: =D29*$E29 -> 15360
A30: 9.6. | B30: Dobava, horizontalna i vertikalna (uz unutarnje zidove) postava PE folije d = 0,25 mm kao zaštita od međukontakta toplinske izolacije i hidroizolacije, slojevi poda na tlu. Stavka uključuje rad i materijal osnovni i pomoćni i preklop od 20 cm. | C30: m2 | D30: 611.8 | F30: =D30*$E30 -> 0
B31: 9. Razni zdarski radovi ukupno: | F31: =SUM(F22:F30) -> 20800
A36: 13. | B36: TERMOIZOLACIJSKI RADOVI
B37: NAPOMENA: Kod svih stavaka u cijenu uključiti detaljan pregled površine na koju se hidroizolacija postavlja i njeno eventualno potrebno pranje, odmašćivanje, čišćenje od neravnina.
A38: 13.3. | B38: Dobava i ugradnja materijala za izolaciju stropa prizemlja između veznih greda na način da se između greda ispunjava kompaktnim pločama od kamene mineralne vune specifične gustoće 30 kg/m³, vrijednosti toplinske provodljivosti λ ≤ 0,037 W/mK. Potrebna debljina izolacije između rogova je 12,00 cm. Sve izvesti prema pravilima struke i prema uputama proizvođača. U stavku uključen sav rad i materijal osnovni i pomoćni, sve do potpune gotovosti. | C38: m2 | D38: 536 | F38: =D38*$E38 -> 0
A39: 13.4. | B39: Dobava i ugradnja materijala za izolaciju stropa prizemlja, na način da se ispod veznih greda postavlja višenamjenska izolacijska ploča od kamene vune kaširana s alu folijom s donje strane. Potrebna debljina izolacije ispod rogova je d = 4,0 cm. Karakteristike tražene izolacije su: - gustoća 30 kg/m³ - toplinske provodljivosti λ ≤ 0,037 W/mK prema normi HRN EN 12667 ili jednakovrijednoj - HRN EN 13162: MW-EN13162-T5-DS(TH)-WS-AF5 ili jednakovrijednoj - klasa gorivosti prema normi HRN EN 13501-1: A1 ili jednakovrijednoj Sve izvesti prema pravilima struke i prema uputama proizvođača. U stavku uključen sav rad i materijal osnovni i pomoćni, sve do potpune gotovosti. | C39: m2 | D39: 536 | F39: =D39*$E39 -> 0
A40: 13.7. | B40: Dobava i ugradnja ekstrudiranog polistirena (XPS) debljine 10 cm glatke površine i stepenastog ruba, koeficijenta toplinske provodljivosti λ≤0,035W/mK, tlačne čvrstoće 300 kPa. Ploče se postavljaju vertikalno kao toplinska izolacija nadtemeljnog zida i temelja. Izolaciju je potrebno zaljepiti za podlogu koristeći polimer-bitumensko ljepilo (1,6 kg/m²), uključeno u cijenu stavke. Sve izvesti pravilima struke i uputama proizvođača. U stavku uključen sav rad i materijal osnovni i pomoćni, sve do potpune gotovosti. | C40: m2 | D40: 159.2 | F40: =D40*$E40 -> 0
B41: 13. Termoizolaterski radovi ukupno: | F41: =SUM(F38:F40) -> 0
A45: 23. | B45: FASADERSKI RADOVI
B46: FASADA SVJETLOSNE GRANICE 20≥HBW≥8
A47: 23.1. | B47: Dobava i ugradnja potrebnih materijala za izvedbu sokla fasadnog toplinsko izolacijskog sustava (svjetlosna granica 20≥HBW≥8) sa namjenskim izolacijskim pločama XPS namijenjenih za izolaciju sokla, d= 10 cm, armirnog sloja ojačanog karbonskim vlaknima, završne silikonske žbuke ojačane karbonskim vlaknima, te završnog bojanja fasadnom bojom ojačanom karbonskim vlaknima u tamnoj nijansi (svjetlosna granica HBW≥8). Cijena stavke uključuje dobavu i postavu komponenti prema uputama proizvođača. Sve elemente fasade ponuditi u okviru atestiranog sustava proizvođača fasade. Prije izvođenja dužnost je izvođača i obračunato je u stavci pripremiti i po potrebi očistiti podlogu, provjeriti stanje i nosivost podloge, ukloniti sve nenosive dijelove, ukoniti sve masnoće i tvari koje razdvajaju. Sokl se izvodi u nastavku i ravnini sa gornjim dijelom fasade, bez vidljivog prijelaza, bez izvedbe razvajajuće šine, sa istim slojem završne žbuke ojačane karbonskim vlaknima. Završni sloj žbuke dodtano se zaštićuje na dijelu netom ispod razine tla i 5 cm iznad tla sa vodoodbojnim premazom i premazuje završnom fasadnom bojom ojačanom karbonskim vlaknima. Detalj izvesti prema projektu i prema tipskom detalju odabranog proizvođača fasadnog sustava. Redoslijed izvođenja:
B48: 1) U zoni podnožja, ljepljenje izolacijskih XPS namjenskih ploča za podnožje (do max 20 cm ispod razine tla) iz atestiranog sustava proizvođača fasade isključivo namjenjenih za izolaciju sokla, koeficijenta toplinske provodljivosti λ≤0,035, tlačne čvrstoće CS (10)150≥ 150 kPa, difuzijskog upijanja vode EN12088 WD(V)5≤5%, vodoupojnosti kod potpunog uranjanja EN12087 WL(T)3≤3%. Debljina ploče d= 10 cm. Lijepljenje se izvodi vapno/cementnim suhim mortom, s hidrauličkim vezanjem, namijenjen za lijepljenje fasadnih izolacijskih ploča i ploča za sokl, posebno na bitumenskim podlogama, isključivo iz atestiranog sustava proizvođača fasade, uz ostvarivanje kontaktne površine od min. 40%. Tehničke karakteristike koje mort mora zadovoljit: • gustoća svježeg morta prema EN 1015-10 ili jednakovrijedno: 1,70 g/cm³ • prionjivost prema EN 1015-12 ili jednakovrijedno: 0,5 N/mm²
B49: 2) Mehaničko pričvršćivanje odgovarajućim pričvrsnicama, u iz atestiranog sustava proizvođača, samo u zoni više od 30 cm iznad razine tla, a njihov broj po m² površine potrebno je dokazati statičkim proračunom (u praksi min. 6 kom/m²). Upuštene pričvrsnice zatvoriti odgovarajućim rondelama iz sustava proizvođača. Tip pričvrsnice obavezno uskaditi sa traženom nosivosti i vrstom podloge na koju se postavljaju. Obaveza je izvođača provjeriti razinu izvedene hidroizolacije kako se prilikom izvedbi pričvrsnica hidroizolacija ne bi oštetila.
B50: 3) Kompletno armiranje postavljenih izolacijskih ploča nanošenjem, mineralnog, karbonskim vlaknima ojačanog, bijelog vapnenocementnog morta za armiranje. Debljina prvog sloja je 3 mm u koji se utiskuje tekstilno-staklena, alkalno otporna mrežica, veličine otvora 4×4 mm s preklopom od minimalno 10 cm. Po izvedenom utiskivanje mrežice nanosi se drugi izravnavajući sloj armirne mase. Ukupna debljina armirnog sloja treba biti min 5 mm. Položaj mrežice u gornjoj trećini sloja. Tehničke karakteristike armirne mase: • Gustoća čvrstog morta (ÖN EN 1015-10): 1,40 g/cm³ • Klasa morta ÖN EN 998-1: CS IV • Toplinska provodljivost: λ10, suho EN 1745: 0,464W/(m.K) Tablična srednja vrijednost (P=50%) • Difuzijski otpor μ (H2O): μ=ca. 50 (EN ISO 7783) • Ponašanje u požaru: Klasa A1 • Koeficijent apsorpcije vode: ÖN EN 998-1: Klasa Wc 2 ETAG 004: ≤ 0,15 kg/m²/24h • Konzistentnost: prah • Vlačna čvrstoća: ÖN EN 1015-12: ≥ 0,5 N/mm2, EPS-F / ETAG 004: ≥0,08N/mm² ili lom izolacijskog materijala
B51: 4) Po izvedbi armirnog sloja nakon odgovarajućeg sušenja a prije izvedbe završnih slojeva izvodi se specijalni pigmentirani temeljni premaz iz sustava proizvođača fasadnog sustava. Temeljni premaz protiv IR zraka, namijen je za premazivanje mineralnih i pastoznih armirnih masa – umjesto temeljnih premaza – za smanjenje termičkog zagrijavanja na visokoizoliranim podlogama pod pastoznim strukturnim žbukama. Premaz se nanosi nerazrijeđen.
B52: 5) Nakon adekvatnog sušenja na naneseni temeljni premaz nanosi se sloj završne žbuke, vrlo difuzivne, ojačane karbonskim vlaknima, s istaknutim efektom vodenih perli i fotokatalitičkim djelovanjem, u veličini zrna d=2 mm i tamnoj nijansi (svjetlosna granica HBW≥8) prema izboru projektanta (u nijansi završne boje). • Stopa propusnosti vode w prema ÖN EN 1062-3: ≤ 0,05 [kg/(m2xh0,5)] W3 niska • Difuzijski otpor µ prema EN ISO 7783: 65 V1 visok • Toplinska provodljivost λ10,suho prema EN 1745: 1,09 W/(m.K) Tablična srednja vrijednost (P=50 %) • Reakcija na požar prema ÖN EN 13501-1: Euroklasa A2
B53: 6) Po adekvatnom sušenju, na izvedeni sloj žbuke u podnožju se izvodi zaštitni premaz 2-komponentnom masa za lijepljenje i armiranje, ojačanom karbonskim vlaknima kao zaštitni brtveni premaz u podnožju / području dodira s tlom (izvodi se ispod razine tla dokle seže završna žbuka i 5 cm iznad razine tla). Služi kao prikladna zaštita od vlage u vidu predpremaza ili izravnavajućeg sloja na armirnim masama ispod razine zemlje i 30 cm iznad. Premaz se izvodi 5 cm iznad razine tla. Nanosi se kistom ili četkom razrijeđen s maks. 5% čiste vode. Premazom obavezno temeljito zaštititi završnu površinu žbuke ispod zemlje. Prije upotrebe materijal se miješa sa cementom prema uputi iz tehničke informacije. Karekteristike premaza: • Difuzijski otpor µ (H2 O): 1350 • Difuzivno ekvivalentna debljina zračnog sloja Sd H2O: 2,7 m (DIN 52615 ili jednakovrijedno) • Koeficijent apsorpcije vode: razred III, nizak, prema DIN EN 1062-3 ili jednakovrijedno • Kapilarno upijanje vode:Kapilarno upijanje vode < 0,02 kg/m2 h 0,5 prema DIN EN 1062 ili jednakovrijedno zajamčena granična vrijednost: 0,1 kg/m2 h0,5
B54: 7) Nakon sušenja završne žbuke i izvedenog vodoodbojnog premaza, dodatni zaštitni premaz visokokvalitetnom nanohibridnom fasadnom bojom za optimalnu solarnu refleksiju kod tamnih tonova, ojačanom karbonskim vlaknima hidrofobne, velike paropropusnosti, s efektom vodenih perli, efektom samočišćenja i otporne na atmosferilije i mikroorganizme. Boju tonirati u tamnoj nijansi prema izboru projektanta (svjetlosna granica HBW≥8). • vodoupropusnost (w vrijednost): < 0,06 [kg/(m2 x h0,5 )], razred "niska vodopropusnost” prema normi DIN EN 1062 ili jednakovrijednoj • paropropusnost (sd-H20): < 0,03 m, razred "visoki stupanj difuzije vodene pare” prema normi DIN EN 1062-2 ili jednakovrijednoj
B55: U stavci je obračunata dobava i postava svog ostalog pribora iz atestiranog sustava proizvođača (kutni profili, okapni profili, i dr). Obaveza je izvođača sve navedene elemente izvesti u sustavu odabranog proizvođača fasadnog sustava. Sve radove izvesti prema tehničkim uputama proizvođača fasadnog sustava te u skladu s važećim tehničkih propisima i zakonskom regulativom poštujući smjernice za ugradnju fasadnih sustava. Stavka uključuje sav rad i materijal osnovni i pomoćni sve do potpune gotovosti. | C55: m2 | D55: 388.2 | E55: 130 | F55: =D55*$E55 -> 50466
A56: 23.2. | B56: Dobava i ugradnja potrebnih materijala za izvedbu ETICS fasadnog toplinsko izolacijskog sustava za tamne fasade (svjetlosna granica 20≥HBW≥8) s izolacijskim pločama od mineralne vune, koeficijenta toplinske provodljivosti λ≤0,035, d= 5-14 cm, armirnih slojeva ojačanim karbonskim vlaknima, završne žbuke ojačane karbonskim vlaknima te završnog bojanja nanohibridnom fasadnom bojom ojačanom karbonskim vlaknima za optimalnu refleksiju kod tamnih tonova kao u tamnoj nijansi (svjetlosna granica HBW≥8). Prije izvođenja obaveza je izvođača prema zahtjevima iz projekta u svrhu ispravno riješenih detalja te osiguranja trajnosti izvedenog fasadnog sustava definirati sve detalje izvedbe unutar odabranog ponuđača fasadnog sustava. To se naročito odnosi na sve spojeve sa bravarijom, stolarijom i limarijom, uskladiti postavu kutnih, rubnih i ostalih pribora prema zahtjevima na samoj fasadi. Obaveza je također provjeriti stanje podloge te prema potrebi podlogu adekvatno pripremiti pranjem, čišćenjem i nanošenjem odgovarajućeg temeljnog premaza. Sokl se izvodi u nastavku i ravnini sa gornjim dijelom fasade, bez vidljivog prijelaza, bez izvedbe razvajajuće šine, sa istim slojem završne silikonske žbuke ojačane karbonskim vlaknima i premazuje završnom fasadnom bojom ojačanom karbonskim vlaknima. Cijena stavke uključuje dobavu i postavu komponenti prema uputama proizvođača. Sve elemente fasade ponuditi u okviru atestiranog sustava proizvođača fasade. Redoslijed izvođenja:
...

Sheet Zgrada 12
A1: stavka | B1: opis stavke | C1: jedin. mjere | D1: količina | E1: jedinična cijena (euro) | F1: ukupno (euro)
A3: II. | B3: ZGRADA 12
A5: A. | B5: GRAĐEVINSKO-OBRNIČKI RADOVI
A7: 1. | B7: SKELA
A8: 1.1. | B8: Dobava, postava, skidanje i otprema cijevne fasadne skele, od bešavnih cijevi. Skelu izvesti prema važećim HTZ propisima. Skelu je potrebno osigurati od prevrtanja, sidrennjem u građevinu, a od udara munje uzemljenjem. Potrebno je izvesti pomične željezne ili drvene ljestve – penjalice u svrhu osiguranja vertikalne komunikacije po skeli. Prije izvedbe skele izvođač je dužan izraditi projekt skele, što je u cijeni stavke. Obračun se vrši po m² vertikalne projekcije površine skele. Stavka uključuje rad i materijal osnovni i pomoćni, sve do potpune funkcionalnosti. | C8: m2 | D8: 698 | E8: 11.55 | F8: =D8*$E8 -> 8061.9
B9: 1. Skela ukupno: | F9: =SUM(F8) -> 8061.9
A12: 3. | B12: RUŠENJE I RAZGRADNJA
A13: 3.36. | B13: Otucanje preostale žbuke fasade prizemlja, zidovi od opeke. U stavci uračunata upotreba radne skele. Stavka uključuje i skidanje keramičkih pločica sa zidova gdje je ista postavljena. U cijenu stavke uračunat utovar i odvoz razgrađenog materijala (razvrstanog po vrstama) na najbližu odgovarajuću deponiju, kao i svi troškovi istovara i korištenja odgovarajuće deponije. | C13: m2 | D13: 500.4 | F13: =D13*$E13 -> 0
A14: 3.37. | B14: Čišćenje reški fasade prizemlja, do dubine od 5 cm u zidu od opeke sa temeljitim otprašivanjem i ispiranjem, sve uz upotrebu odgovarajuće skele. Uključeno čišćenje spojnica sa otprašivanjem. U cijenu stavke uračunat utovar i odvoz razgrađenog materijala (razvrstanog po vrstama) na najbližu odgovarajuću deponiju, kao i svi troškovi istovara i korištenja odgovarajuće deponije. | C14: m2 | D14: 500.4 | F14: =D14*$E14 -> 0
B15: 3. Rušenje i razgradnja ukupno: | F15: =SUM(F13:F14) -> 0
A21: 8. | B21: ZIDARSKI RADOVI
A22: 8.9. | B22: Izrada i ugradnja grube žbuke pročelja zgrade od opeke. Prije žbukanja podlogu špricati rijetkim cementnim mortom. Žbuka se produžnim mortom M-10 debljine do 4 cm. Visina žbukanja do 5,0 m. Stavka uključuje sav materijal, rad i upotrebu radne skele. | C22: m2 | D22: 479 | E22: 55 | F22: =D22*$E22 -> 26345
A23: 8.10. | B23: Izrada i ugradnja grube i fine žbuke s vanjske strane temelja i sokla prije postavljanje hidroizolacije. Prije žbukanja podlogu špricati rijetkim cementnim mortom. Žbuka se produžnim mortom M-10 debljine do 4 cm. Visina žbukanja do 5,0 m. Stavka uključuje sav materijal, rad. | C23: m2 | D23: 194 | E23: 55 | F23: =D23*$E23 -> 10670
B24: 8. Zidarski radovi ukupno: | F24: =SUM(F22:F23) -> 37015
A26: 9. | B26: RAZNI ZIDARSKI RADOVI
A27: 9.1. | B27: Brtvljenje fasadnih otvora (prozora, stijena i vrata) samoljepljivom trakom. Dobava i ugradnja samoljepljive gumirane trake za fiksiranje. Tehničke karakteristike koje proizvod mora zadovoljiti: - Širina min. 5cm - Otpornost na trganje: ≥150 N/50 mm - Izduženje do sloma: ≥20% Trake se lijepe na prethodno otprašenu podlogu, otprašivanje uključeno u stavci. Stavka uključuje sav rad i materijal osnovni i pomoćni. Sve izvesti prema pravilima struke i po uputi proizvođača. Obračun po m'.
A28: a) | B28: postava s vanjske strane | C28: m' | D28: 165 | F28: =D28*$E28 -> 0
A29: b) | B29: postava s unutarnje strane | C29: m' | D29: 165 | F29: =D29*$E29 -> 0
A30: 9.2. | B30: Obrada špaleta oko otvora u vanjskom zidu. Krpanje i nanos izravnavajućeg sloja produžnim mortom M-5. Stavka uključuje sav materijal i rad, te upotrebu radne skele.
A31: a) | B31: vanjska obrada špalete | C31: m' | D31: 160.5 | E31: 16 | F31: =D31*$E31 -> 2568
A32: b) | B32: unutarnja obrada špalete | C32: m' | D32: 160.5 | E32: 16 | F32: =D32*$E32 -> 2568
A33: 9.3. | B33: Zidarski popravak površina ispod prozorskih klupčica koji obuhvaća: - nabavu nedostajućih cigli - nabavu i pripremu veznog materijala - zidarsko zatvaranje i dopunjavanje rupa. Stavka uključuje sav materijal i rad, te upotrebu radne skele. | C33: m2 | D33: 12.6 | F33: =D33*$E33 -> 0
B34: 9. Razni zdarski radovi ukupno: | F34: =SUM(F28:F33) -> 5136
A39: 13. | B39: TERMOIZOLACIJSKI RADOVI
B40: NAPOMENA: Kod svih stavaka u cijenu uključiti detaljan pregled površine na koju se hidroizolacija postavlja i njeno eventualno potrebno pranje, odmašćivanje, čišćenje od neravnina.
A41: 13.2. | B41: Dobava i postava rubne trake od kamene vune uz pregradne i nosive zidove u debljini od 2 cm u visini slojeva poda. Tehničke karakteristike koje kamena vuna mora zadovoljiti su: • reakcija na požar: razred A1 prema HRN EN 13501-1 ili jednakovrijednoj • toplinska provodljivost ʎ ≤ 0,038 W/mK prema HRN EN 12667 ili jednakovrijednoj • razina stišljivosti CP2 prema HRN EN 12431 ili jednakovrijednoj • dinamička krutost SD ≤ 48 MN/m³ prema HRN EN 29052-1 ili jednakovrijednoj Stavka uključuje rad i materijal osnovni i pomoćni, sve prema nacrtu projektanta. | C41: m' | D41: 340 | F41: =D41*$E41 -> 0
A42: 13.3. | B42: Dobava i ugradnja materijala za izolaciju stropa prizemlja između veznih greda na način da se između greda ispunjava kompaktnim pločama od kamene mineralne vune specifične gustoće 30 kg/m³, vrijednosti toplinske provodljivosti λ ≤ 0,037 W/mK. Potrebna debljina izolacije između rogova je 12,00 cm. Sve izvesti prema pravilima struke i prema uputama proizvođača. U stavku uključen sav rad i materijal osnovni i pomoćni, sve do potpune gotovosti. | C42: m2 | D42: 540.9 | F42: =D42*$E42 -> 0
A43: 13.4. | B43: Dobava i ugradnja materijala za izolaciju stropa prizemlja, na način da se ispod veznih greda postavlja višenamjenska izolacijska ploča od kamene vune kaširana s alu folijom s donje strane. Potrebna debljina izolacije ispod rogova je d = 4,0 cm. Karakteristike tražene izolacije su: - gustoća 30 kg/m³ - toplinske provodljivosti λ ≤ 0,037 W/mK prema normi HRN EN 12667 ili jednakovrijednoj - HRN EN 13162: MW-EN13162-T5-DS(TH)-WS-AF5 ili jednakovrijednoj - klasa gorivosti prema normi HRN EN 13501-1: A1 ili jednakovrijednoj Sve izvesti prema pravilima struke i prema uputama proizvođača. U stavku uključen sav rad i materijal osnovni i pomoćni, sve do potpune gotovosti. | C43: m2 | D43: 540.9 | F43: =D43*$E43 -> 0
A44: 13.7. | B44: Dobava i ugradnja ekstrudiranog polistirena (XPS) debljine 10 cm glatke površine i stepenastog ruba, koeficijenta toplinske provodljivosti λ≤0,035W/mK, tlačne čvrstoće 300 kPa. Ploče se postavljaju vertikalno kao toplinska izolacija nadtemeljnog zida i temelja. Izolaciju je potrebno zaljepiti za podlogu koristeći polimer-bitumensko ljepilo (1,6 kg/m²), uključeno u cijenu stavke. Sve izvesti pravilima struke i uputama proizvođača. U stavku uključen sav rad i materijal osnovni i pomoćni, sve do potpune gotovosti. | C44: m2 | D44: 156 | F44: =D44*$E44 -> 0
B45: 13. Termoizolaterski radovi ukupno: | F45: =SUM(F41:F44) -> 0
A50: 23. | B50: FASADERSKI RADOVI
B51: FASADA SVJETLOSNE GRANICE 20≥HBW≥8
A52: 23.1. | B52: Dobava i ugradnja potrebnih materijala za izvedbu sokla fasadnog toplinsko izolacijskog sustava (svjetlosna granica 20≥HBW≥8) sa namjenskim izolacijskim pločama XPS namijenjenih za izolaciju sokla, d= 10 cm, armirnog sloja ojačanog karbonskim vlaknima, završne silikonske žbuke ojačane karbonskim vlaknima, te završnog bojanja fasadnom bojom ojačanom karbonskim vlaknima u tamnoj nijansi (svjetlosna granica HBW≥8). Cijena stavke uključuje dobavu i postavu komponenti prema uputama proizvođača. Sve elemente fasade ponuditi u okviru atestiranog sustava proizvođača fasade. Prije izvođenja dužnost je izvođača i obračunato je u stavci pripremiti i po potrebi očistiti podlogu, provjeriti stanje i nosivost podloge, ukloniti sve nenosive dijelove, ukoniti sve masnoće i tvari koje razdvajaju. Sokl se izvodi u nastavku i ravnini sa gornjim dijelom fasade, bez vidljivog prijelaza, bez izvedbe razvajajuće šine, sa istim slojem završne žbuke ojačane karbonskim vlaknima. Završni sloj žbuke dodtano se zaštićuje na dijelu netom ispod razine tla i 5 cm iznad tla sa vodoodbojnim premazom i premazuje završnom fasadnom bojom ojačanom karbonskim vlaknima. Detalj izvesti prema projektu i prema tipskom detalju odabranog proizvođača fasadnog sustava. Redoslijed izvođenja:
B53: 1) U zoni podnožja, ljepljenje izolacijskih XPS namjenskih ploča za podnožje (do max 20 cm ispod razine tla) iz atestiranog sustava proizvođača fasade isključivo namjenjenih za izolaciju sokla, koeficijenta toplinske provodljivosti λ≤0,035, tlačne čvrstoće CS (10)150≥ 150 kPa, difuzijskog upijanja vode EN12088 WD(V)5≤5%, vodoupojnosti kod potpunog uranjanja EN12087 WL(T)3≤3%. Debljina ploče d= 10 cm. Lijepljenje se izvodi vapno/cementnim suhim mortom, s hidrauličkim vezanjem, namijenjen za lijepljenje fasadnih izolacijskih ploča i ploča za sokl, posebno na bitumenskim podlogama, isključivo iz atestiranog sustava proizvođača fasade, uz ostvarivanje kontaktne površine od min. 40%. Tehničke karakteristike koje mort mora zadovoljit: • gustoća svježeg morta prema EN 1015-10 ili jednakovrijedno: 1,70 g/cm³ • prionjivost prema EN 1015-12 ili jednakovrijedno: 0,5 N/mm²
B54: 2) Mehaničko pričvršćivanje odgovarajućim pričvrsnicama, u iz atestiranog sustava proizvođača, samo u zoni više od 30 cm iznad razine tla, a njihov broj po m² površine potrebno je dokazati statičkim proračunom (u praksi min. 6 kom/m²). Upuštene pričvrsnice zatvoriti odgovarajućim rondelama iz sustava proizvođača. Tip pričvrsnice obavezno uskaditi sa traženom nosivosti i vrstom podloge na koju se postavljaju. Obaveza je izvođača provjeriti razinu izvedene hidroizolacije kako se prilikom izvedbi pričvrsnica hidroizolacija ne bi oštetila.
B55: 3) Kompletno armiranje postavljenih izolacijskih ploča nanošenjem, mineralnog, karbonskim vlaknima ojačanog, bijelog vapnenocementnog morta za armiranje. Debljina prvog sloja je 3 mm u koji se utiskuje tekstilno-staklena, alkalno otporna mrežica, veličine otvora 4×4 mm s preklopom od minimalno 10 cm. Po izvedenom utiskivanje mrežice nanosi se drugi izravnavajući sloj armirne mase. Ukupna debljina armirnog sloja treba biti min 5 mm. Položaj mrežice u gornjoj trećini sloja. Tehničke karakteristike armirne mase: • Gustoća čvrstog morta (ÖN EN 1015-10): 1,40 g/cm³ • Klasa morta ÖN EN 998-1: CS IV • Toplinska provodljivost: λ10, suho EN 1745: 0,464W/(m.K) Tablična srednja vrijednost (P=50%) • Difuzijski otpor μ (H2O): μ=ca. 50 (EN ISO 7783) • Ponašanje u požaru: Klasa A1 • Koeficijent apsorpcije vode: ÖN EN 998-1: Klasa Wc 2 ETAG 004: ≤ 0,15 kg/m²/24h • Konzistentnost: prah • Vlačna čvrstoća: ÖN EN 1015-12: ≥ 0,5 N/mm2, EPS-F / ETAG 004: ≥0,08N/mm² ili lom izolacijskog materijala
B56: 4) Po izvedbi armirnog sloja nakon odgovarajućeg sušenja a prije izvedbe završnih slojeva izvodi se specijalni pigmentirani temeljni premaz iz sustava proizvođača fasadnog sustava. Temeljni premaz protiv IR zraka, namijen je za premazivanje mineralnih i pastoznih armirnih masa – umjesto temeljnih premaza – za smanjenje termičkog zagrijavanja na visokoizoliranim podlogama pod pastoznim strukturnim žbukama. Premaz se nanosi nerazrijeđen.
B57: 5) Nakon adekvatnog sušenja na naneseni temeljni premaz nanosi se sloj završne žbuke, vrlo difuzivne, ojačane karbonskim vlaknima, s istaknutim efektom vodenih perli i fotokatalitičkim djelovanjem, u veličini zrna d=2 mm i tamnoj nijansi (svjetlosna granica HBW≥8) prema izboru projektanta (u nijansi završne boje). • Stopa propusnosti vode w prema ÖN EN 1062-3: ≤ 0,05 [kg/(m2xh0,5)] W3 niska • Difuzijski otpor µ prema EN ISO 7783: 65 V1 visok • Toplinska provodljivost λ10,suho prema EN 1745: 1,09 W/(m.K) Tablična srednja vrijednost (P=50 %) • Reakcija na požar prema ÖN EN 13501-1: Euroklasa A2
B58: 6) Po adekvatnom sušenju, na izvedeni sloj žbuke u podnožju se izvodi zaštitni premaz 2-komponentnom masa za lijepljenje i armiranje, ojačanom karbonskim vlaknima kao zaštitni brtveni premaz u podnožju / području dodira s tlom (izvodi se ispod razine tla dokle seže završna žbuka i 5 cm iznad razine tla). Služi kao prikladna zaštita od vlage u vidu predpremaza ili izravnavajućeg sloja na armirnim masama ispod razine zemlje i 30 cm iznad. Premaz se izvodi 5 cm iznad razine tla. Nanosi se kistom ili četkom razrijeđen s maks. 5% čiste vode. Premazom obavezno temeljito zaštititi završnu površinu žbuke ispod zemlje. Prije upotrebe materijal se miješa sa cementom prema uputi iz tehničke informacije. Karekteristike premaza: • Difuzijski otpor µ (H2 O): 1350 • Difuzivno ekvivalentna debljina zračnog sloja Sd H2O: 2,7 m (DIN 52615 ili jednakovrijedno) • Koeficijent apsorpcije vode: razred III, nizak, prema DIN EN 1062-3 ili jednakovrijedno • Kapilarno upijanje vode:Kapilarno upijanje vode < 0,02 kg/m2 h 0,5 prema DIN EN 1062 ili jednakovrijedno zajamčena granična vrijednost: 0,1 kg/m2 h0,5
B59: 7) Nakon sušenja završne žbuke i izvedenog vodoodbojnog premaza, dodatni zaštitni premaz visokokvalitetnom nanohibridnom fasadnom bojom za optimalnu solarnu refleksiju kod tamnih tonova, ojačanom karbonskim vlaknima hidrofobne, velike paropropusnosti, s efektom vodenih perli, efektom samočišćenja i otporne na atmosferilije i mikroorganizme. Boju tonirati u tamnoj nijansi prema izboru projektanta (svjetlosna granica HBW≥8). • vodoupropusnost (w vrijednost): < 0,06 [kg/(m2 x h0,5 )], razred "niska vodopropusnost” prema normi DIN EN 1062 ili jednakovrijednoj • paropropusnost (sd-H20): < 0,03 m, razred "visoki stupanj difuzije vodene pare” prema normi DIN EN 1062-2 ili jednakovrijednoj
...

Sheet Zgrada 13
A1: stavka | B1: opis stavke | C1: jedin. mjere | D1: količina | E1: jedinična cijena (euro) | F1: ukupno (euro)
A3: III. | B3: ZGRADA 13
A5: A. | B5: GRAĐEVINSKO-OBRNIČKI RADOVI
A7: 1. | B7: SKELA
A8: 1.1. | B8: Dobava, postava, skidanje i otprema cijevne fasadne skele, od bešavnih cijevi. Skelu izvesti prema važećim HTZ propisima. Skelu je potrebno osigurati od prevrtanja, sidrennjem u građevinu, a od udara munje uzemljenjem. Potrebno je izvesti pomične željezne ili drvene ljestve – penjalice u svrhu osiguranja vertikalne komunikacije po skeli. Prije izvedbe skele izvođač je dužan izraditi projekt skele, što je u cijeni stavke. Obračun se vrši po m² vertikalne projekcije površine skele. Stavka uključuje rad i materijal osnovni i pomoćni, sve do potpune funkcionalnosti. | C8: m2 | D8: 698 | E8: 11.55 | F8: =D8*$E8 -> 8061.9
B9: 1. Skela ukupno: | F9: =SUM(F8) -> 8061.9
A11: 3. | B11: RUŠENJE I RAZGRADNJA
A12: 3.36. | B12: Otucanje preostale žbuke fasade prizemlja, zidovi od opeke. U stavci uračunata upotreba radne skele. Stavka uključuje i skidanje keramičkih pločica sa zidova gdje je ista postavljena. U cijenu stavke uračunat utovar i odvoz razgrađenog materijala (razvrstanog po vrstama) na najbližu odgovarajuću deponiju, kao i svi troškovi istovara i korištenja odgovarajuće deponije. | C12: m2 | D12: 501 | F12: =D12*$E12 -> 0
A13: 3.37. | B13: Čišćenje reški fasade prizemlja, do dubine od 5 cm u zidu od opeke sa temeljitim otprašivanjem i ispiranjem, sve uz upotrebu odgovarajuće skele. Uključeno čišćenje spojnica sa otprašivanjem. U cijenu stavke uračunat utovar i odvoz razgrađenog materijala (razvrstanog po vrstama) na najbližu odgovarajuću deponiju, kao i svi troškovi istovara i korištenja odgovarajuće deponije. | C13: m2 | D13: 501 | F13: =D13*$E13 -> 0
A14: 3.38. | B14: Otucanje preostale žbuke sa zidova prostorija prizemlja, zidovi od opeke. U stavci uračunata upotreba radne skele. Stavka uključuje i skidanje keramičkih pločica sa zidova gdje je ista postavljena. U cijenu stavke uračunat utovar i odvoz razgrađenog materijala (razvrstanog po vrstama) na najbližu odgovarajuću deponiju, kao i svi troškovi istovara i korištenja odgovarajuće deponije. | C14: m2 | D14: 987 | F14: =D14*$E14 -> 0
B15: 3. Rušenje i razgradnja ukupno: | F15: =SUM(F12:F14) -> 0
A18: 8. | B18: ZIDARSKI RADOVI
A19: 8.9. | B19: Izrada i ugradnja grube žbuke pročelja zgrade od opeke. Prije žbukanja podlogu špricati rijetkim cementnim mortom. Žbuka se produžnim mortom M-10 debljine do 4 cm. Visina žbukanja do 5,0 m. Stavka uključuje sav materijal, rad i upotrebu radne skele. | C19: m2 | D19: 479.8 | E19: 55 | F19: =D19*$E19 -> 26389
A20: 8.10. | B20: Izrada i ugradnja grube i fine žbuke s vanjske strane temelja i sokla prije postavljanje hidroizolacije. Prije žbukanja podlogu špricati rijetkim cementnim mortom. Žbuka se produžnim mortom M-10 debljine do 4 cm. Visina žbukanja do 5,0 m. Stavka uključuje sav materijal, rad. | C20: m2 | D20: 194.5 | E20: 55 | F20: =D20*$E20 -> 10697.5
B21: 8. Zidarski radovi ukupno: | F21: =SUM(F19:F20) -> 37086.5
A23: 9. | B23: RAZNI ZIDARSKI RADOVI
A24: 9.1. | B24: Brtvljenje fasadnih otvora (prozora, stijena i vrata) samoljepljivom trakom. Dobava i ugradnja samoljepljive gumirane trake za fiksiranje. Tehničke karakteristike koje proizvod mora zadovoljiti: - Širina min. 5cm - Otpornost na trganje: ≥150 N/50 mm - Izduženje do sloma: ≥20% Trake se lijepe na prethodno otprašenu podlogu, otprašivanje uključeno u stavci. Stavka uključuje sav rad i materijal osnovni i pomoćni. Sve izvesti prema pravilima struke i po uputi proizvođača. Obračun po m'.
A25: a) | B25: postava s vanjske strane | C25: m' | D25: 165 | F25: =D25*$E25 -> 0
A26: b) | B26: postava s unutarnje strane | C26: m' | D26: 165 | F26: =D26*$E26 -> 0
A27: 9.2. | B27: Obrada špaleta oko otvora u vanjskom zidu. Krpanje i nanos izravnavajućeg sloja produžnim mortom M-5. Stavka uključuje sav materijal i rad, te upotrebu radne skele.
A28: a) | B28: vanjska obrada špalete | C28: m' | D28: 165 | E28: 16 | F28: =D28*$E28 -> 2640
A29: b) | B29: unutarnja obrada špalete | C29: m' | D29: 165 | E29: 16 | F29: =D29*$E29 -> 2640
B30: 9. Razni zdarski radovi ukupno: | F30: =SUM(F25:F29) -> 5280
A32: 13. | B32: TERMOIZOLACIJSKI RADOVI
B33: NAPOMENA: Kod svih stavaka u cijenu uključiti detaljan pregled površine na koju se hidroizolacija postavlja i njeno eventualno potrebno pranje, odmašćivanje, čišćenje od neravnina.
A34: 13.2. | B34: Dobava i postava rubne trake od kamene vune uz pregradne i nosive zidove u debljini od 2 cm u visini slojeva poda. Tehničke karakteristike koje kamena vuna mora zadovoljiti su: • reakcija na požar: razred A1 prema HRN EN 13501-1 ili jednakovrijednoj • toplinska provodljivost ʎ ≤ 0,038 W/mK prema HRN EN 12667 ili jednakovrijednoj • razina stišljivosti CP2 prema HRN EN 12431 ili jednakovrijednoj • dinamička krutost SD ≤ 48 MN/m³ prema HRN EN 29052-1 ili jednakovrijednoj Stavka uključuje rad i materijal osnovni i pomoćni, sve prema nacrtu projektanta. | C34: m' | D34: 340 | F34: =D34*$E34 -> 0
A35: 13.3. | B35: Dobava i ugradnja materijala za izolaciju stropa prizemlja između veznih greda na način da se između greda ispunjava kompaktnim pločama od kamene mineralne vune specifične gustoće 30 kg/m³, vrijednosti toplinske provodljivosti λ ≤ 0,037 W/mK. Potrebna debljina izolacije između rogova je 12,00 cm. Sve izvesti prema pravilima struke i prema uputama proizvođača. U stavku uključen sav rad i materijal osnovni i pomoćni, sve do potpune gotovosti. | C35: m2 | D35: 540.9 | F35: =D35*$E35 -> 0
A36: 13.4. | B36: Dobava i ugradnja materijala za izolaciju stropa prizemlja, na način da se ispod veznih greda postavlja višenamjenska izolacijska ploča od kamene vune kaširana s alu folijom s donje strane. Potrebna debljina izolacije ispod rogova je d = 4,0 cm. Karakteristike tražene izolacije su: - gustoća 30 kg/m³ - toplinske provodljivosti λ ≤ 0,037 W/mK prema normi HRN EN 12667 ili jednakovrijednoj - HRN EN 13162: MW-EN13162-T5-DS(TH)-WS-AF5 ili jednakovrijednoj - klasa gorivosti prema normi HRN EN 13501-1: A1 ili jednakovrijednoj Sve izvesti prema pravilima struke i prema uputama proizvođača. U stavku uključen sav rad i materijal osnovni i pomoćni, sve do potpune gotovosti. | C36: m2 | D36: 540.9 | F36: =D36*$E36 -> 0
B37: 13. Termoizolaterski radovi ukupno: | F37: =SUM(F34:F36) -> 0
A43: 23. | B43: FASADERSKI RADOVI
B44: FASADA SVJETLOSNE GRANICE 20≥HBW≥8
A45: 23.1. | B45: Dobava i ugradnja potrebnih materijala za izvedbu sokla fasadnog toplinsko izolacijskog sustava (svjetlosna granica 20≥HBW≥8) sa namjenskim izolacijskim pločama XPS namijenjenih za izolaciju sokla, d= 10 cm, armirnog sloja ojačanog karbonskim vlaknima, završne silikonske žbuke ojačane karbonskim vlaknima, te završnog bojanja fasadnom bojom ojačanom karbonskim vlaknima u tamnoj nijansi (svjetlosna granica HBW≥8). Cijena stavke uključuje dobavu i postavu komponenti prema uputama proizvođača. Sve elemente fasade ponuditi u okviru atestiranog sustava proizvođača fasade. Prije izvođenja dužnost je izvođača i obračunato je u stavci pripremiti i po potrebi očistiti podlogu, provjeriti stanje i nosivost podloge, ukloniti sve nenosive dijelove, ukoniti sve masnoće i tvari koje razdvajaju. Sokl se izvodi u nastavku i ravnini sa gornjim dijelom fasade, bez vidljivog prijelaza, bez izvedbe razvajajuće šine, sa istim slojem završne žbuke ojačane karbonskim vlaknima. Završni sloj žbuke dodtano se zaštićuje na dijelu netom ispod razine tla i 5 cm iznad tla sa vodoodbojnim premazom i premazuje završnom fasadnom bojom ojačanom karbonskim vlaknima. Detalj izvesti prema projektu i prema tipskom detalju odabranog proizvođača fasadnog sustava. Redoslijed izvođenja:
B46: 1) U zoni podnožja, ljepljenje izolacijskih XPS namjenskih ploča za podnožje (do max 20 cm ispod razine tla) iz atestiranog sustava proizvođača fasade isključivo namjenjenih za izolaciju sokla, koeficijenta toplinske provodljivosti λ≤0,035, tlačne čvrstoće CS (10)150≥ 150 kPa, difuzijskog upijanja vode EN12088 WD(V)5≤5%, vodoupojnosti kod potpunog uranjanja EN12087 WL(T)3≤3%. Debljina ploče d= 10 cm. Lijepljenje se izvodi vapno/cementnim suhim mortom, s hidrauličkim vezanjem, namijenjen za lijepljenje fasadnih izolacijskih ploča i ploča za sokl, posebno na bitumenskim podlogama, isključivo iz atestiranog sustava proizvođača fasade, uz ostvarivanje kontaktne površine od min. 40%. Tehničke karakteristike koje mort mora zadovoljit: • gustoća svježeg morta prema EN 1015-10 ili jednakovrijedno: 1,70 g/cm³ • prionjivost prema EN 1015-12 ili jednakovrijedno: 0,5 N/mm²
B47: 2) Mehaničko pričvršćivanje odgovarajućim pričvrsnicama, u iz atestiranog sustava proizvođača, samo u zoni više od 30 cm iznad razine tla, a njihov broj po m² površine potrebno je dokazati statičkim proračunom (u praksi min. 6 kom/m²). Upuštene pričvrsnice zatvoriti odgovarajućim rondelama iz sustava proizvođača. Tip pričvrsnice obavezno uskaditi sa traženom nosivosti i vrstom podloge na koju se postavljaju. Obaveza je izvođača provjeriti razinu izvedene hidroizolacije kako se prilikom izvedbi pričvrsnica hidroizolacija ne bi oštetila.
B48: 3) Kompletno armiranje postavljenih izolacijskih ploča nanošenjem, mineralnog, karbonskim vlaknima ojačanog, bijelog vapnenocementnog morta za armiranje. Debljina prvog sloja je 3 mm u koji se utiskuje tekstilno-staklena, alkalno otporna mrežica, veličine otvora 4×4 mm s preklopom od minimalno 10 cm. Po izvedenom utiskivanje mrežice nanosi se drugi izravnavajući sloj armirne mase. Ukupna debljina armirnog sloja treba biti min 5 mm. Položaj mrežice u gornjoj trećini sloja. Tehničke karakteristike armirne mase: • Gustoća čvrstog morta (ÖN EN 1015-10): 1,40 g/cm³ • Klasa morta ÖN EN 998-1: CS IV • Toplinska provodljivost: λ10, suho EN 1745: 0,464W/(m.K) Tablična srednja vrijednost (P=50%) • Difuzijski otpor μ (H2O): μ=ca. 50 (EN ISO 7783) • Ponašanje u požaru: Klasa A1 • Koeficijent apsorpcije vode: ÖN EN 998-1: Klasa Wc 2 ETAG 004: ≤ 0,15 kg/m²/24h • Konzistentnost: prah • Vlačna čvrstoća: ÖN EN 1015-12: ≥ 0,5 N/mm2, EPS-F / ETAG 004: ≥0,08N/mm² ili lom izolacijskog materijala
B49: 4) Po izvedbi armirnog sloja nakon odgovarajućeg sušenja a prije izvedbe završnih slojeva izvodi se specijalni pigmentirani temeljni premaz iz sustava proizvođača fasadnog sustava. Temeljni premaz protiv IR zraka, namijen je za premazivanje mineralnih i pastoznih armirnih masa – umjesto temeljnih premaza – za smanjenje termičkog zagrijavanja na visokoizoliranim podlogama pod pastoznim strukturnim žbukama. Premaz se nanosi nerazrijeđen.
B50: 5) Nakon adekvatnog sušenja na naneseni temeljni premaz nanosi se sloj završne žbuke, vrlo difuzivne, ojačane karbonskim vlaknima, s istaknutim efektom vodenih perli i fotokatalitičkim djelovanjem, u veličini zrna d=2 mm i tamnoj nijansi (svjetlosna granica HBW≥8) prema izboru projektanta (u nijansi završne boje). • Stopa propusnosti vode w prema ÖN EN 1062-3: ≤ 0,05 [kg/(m2xh0,5)] W3 niska • Difuzijski otpor µ prema EN ISO 7783: 65 V1 visok • Toplinska provodljivost λ10,suho prema EN 1745: 1,09 W/(m.K) Tablična srednja vrijednost (P=50 %) • Reakcija na požar prema ÖN EN 13501-1: Euroklasa A2
B51: 6) Po adekvatnom sušenju, na izvedeni sloj žbuke u podnožju se izvodi zaštitni premaz 2-komponentnom masa za lijepljenje i armiranje, ojačanom karbonskim vlaknima kao zaštitni brtveni premaz u podnožju / području dodira s tlom (izvodi se ispod razine tla dokle seže završna žbuka i 5 cm iznad razine tla). Služi kao prikladna zaštita od vlage u vidu predpremaza ili izravnavajućeg sloja na armirnim masama ispod razine zemlje i 30 cm iznad. Premaz se izvodi 5 cm iznad razine tla. Nanosi se kistom ili četkom razrijeđen s maks. 5% čiste vode. Premazom obavezno temeljito zaštititi završnu površinu žbuke ispod zemlje. Prije upotrebe materijal se miješa sa cementom prema uputi iz tehničke informacije. Karekteristike premaza: • Difuzijski otpor µ (H2 O): 1350 • Difuzivno ekvivalentna debljina zračnog sloja Sd H2O: 2,7 m (DIN 52615 ili jednakovrijedno) • Koeficijent apsorpcije vode: razred III, nizak, prema DIN EN 1062-3 ili jednakovrijedno • Kapilarno upijanje vode:Kapilarno upijanje vode < 0,02 kg/m2 h 0,5 prema DIN EN 1062 ili jednakovrijedno zajamčena granična vrijednost: 0,1 kg/m2 h0,5
B52: 7) Nakon sušenja završne žbuke i izvedenog vodoodbojnog premaza, dodatni zaštitni premaz visokokvalitetnom nanohibridnom fasadnom bojom za optimalnu solarnu refleksiju kod tamnih tonova, ojačanom karbonskim vlaknima hidrofobne, velike paropropusnosti, s efektom vodenih perli, efektom samočišćenja i otporne na atmosferilije i mikroorganizme. Boju tonirati u tamnoj nijansi prema izboru projektanta (svjetlosna granica HBW≥8). • vodoupropusnost (w vrijednost): < 0,06 [kg/(m2 x h0,5 )], razred "niska vodopropusnost” prema normi DIN EN 1062 ili jednakovrijednoj • paropropusnost (sd-H20): < 0,03 m, razred "visoki stupanj difuzije vodene pare” prema normi DIN EN 1062-2 ili jednakovrijednoj
B53: U stavci je obračunata dobava i postava svog ostalog pribora iz atestiranog sustava proizvođača (kutni profili, okapni profili, i dr). Obaveza je izvođača sve navedene elemente izvesti u sustavu odabranog proizvođača fasadnog sustava. Sve radove izvesti prema tehničkim uputama proizvođača fasadnog sustava te u skladu s važećim tehničkih propisima i zakonskom regulativom poštujući smjernice za ugradnju fasadnih sustava. Stavka uključuje sav rad i materijal osnovni i pomoćni sve do potpune gotovosti. | C53: m2 | D53: 388.2 | E53: 130 | F53: =D53*$E53 -> 50466
...

Sheet Zgrada 14
A1: stavka | B1: opis stavke | C1: jedin. mjere | D1: količina | E1: jedinična cijena (euro) | F1: ukupno (euro)
A3: IV. | B3: ZGRADA 14
A5: A. | B5: GRAĐEVINSKO-OBRNIČKI RADOVI
A7: 1. | B7: SKELA
A8: 1.1. | B8: Dobava, postava, skidanje i otprema cijevne fasadne skele, od bešavnih cijevi. Skelu izvesti prema važećim HTZ propisima. Skelu je potrebno osigurati od prevrtanja, sidrennjem u građevinu, a od udara munje uzemljenjem. Potrebno je izvesti pomične željezne ili drvene ljestve – penjalice u svrhu osiguranja vertikalne komunikacije po skeli. Prije izvedbe skele izvođač je dužan izraditi projekt skele, što je u cijeni stavke. Obračun se vrši po m² vertikalne projekcije površine skele. Stavka uključuje rad i materijal osnovni i pomoćni, sve do potpune funkcionalnosti. | C8: m2 | D8: 698 | E8: 11.55 | F8: =D8*$E8 -> 8061.9
B9: 1. Skela ukupno: | F9: =SUM(F8) -> 8061.9
A11: 3.37. | B11: Čišćenje reški fasade prizemlja, do dubine od 5 cm u zidu od opeke sa temeljitim otprašivanjem i ispiranjem, sve uz upotrebu odgovarajuće skele. Uključeno čišćenje spojnica sa otprašivanjem. U cijenu stavke uračunat utovar i odvoz razgrađenog materijala (razvrstanog po vrstama) na najbližu odgovarajuću deponiju, kao i svi troškovi istovara i korištenja odgovarajuće deponije. | C11: m2 | D11: 499 | E11: 10.5 | F11: =D11*$E11 -> 5239.5
A14: 8. | B14: ZIDARSKI RADOVI
A15: 8.10. | B15: Izrada i ugradnja grube žbuke pročelja zgrade od opeke. Prije žbukanja podlogu špricati rijetkim cementnim mortom. Žbuka se produžnim mortom M-10 debljine do 4 cm. Visina žbukanja do 5,0 m. Stavka uključuje sav materijal, rad i upotrebu radne skele. | C15: m2 | D15: 479.8 | E15: 55 | F15: =D15*$E15 -> 26389
A16: 8.11. | B16: Izrada i ugradnja grube i fine žbuke s vanjske strane temelja i sokla prije postavljanje hidroizolacije. Prije žbukanja podlogu špricati rijetkim cementnim mortom. Žbuka se produžnim mortom M-10 debljine do 4 cm. Visina žbukanja do 5,0 m. Stavka uključuje sav materijal, rad. | C16: m2 | D16: 194.5 | E16: 55 | F16: =D16*$E16 -> 10697.5
B17: 8. Zidarski radovi ukupno: | F17: =SUM(F15:F16) -> 37086.5
A19: 9. | B19: RAZNI ZIDARSKI RADOVI
A20: 9.1. | B20: Brtvljenje fasadnih otvora (prozora, stijena i vrata) samoljepljivom trakom. Dobava i ugradnja samoljepljive gumirane trake za fiksiranje. Tehničke karakteristike koje proizvod mora zadovoljiti: - Širina min. 5cm - Otpornost na trganje: ≥150 N/50 mm - Izduženje do sloma: ≥20% Trake se lijepe na prethodno otprašenu podlogu, otprašivanje uključeno u stavci. Stavka uključuje sav rad i materijal osnovni i pomoćni. Sve izvesti prema pravilima struke i po uputi proizvođača. Obračun po m'.
A21: a) | B21: postava s vanjske strane | C21: m' | D21: 160.5 | F21: =D21*$E21 -> 0
A22: b) | B22: postava s unutarnje strane | C22: m' | D22: 160.5 | F22: =D22*$E22 -> 0
A23: 9.2. | B23: Obrada špaleta oko otvora u vanjskom zidu. Krpanje i nanos izravnavajućeg sloja produžnim mortom M-5. Stavka uključuje sav materijal i rad, te upotrebu radne skele.
A24: a) | B24: vanjska obrada špalete | C24: m' | D24: 160.5 | E24: 16 | F24: =D24*$E24 -> 2568
A25: b) | B25: unutarnja obrada špalete | C25: m' | D25: 160.5 | E25: 16 | F25: =D25*$E25 -> 2568
B26: 9. Razni zdarski radovi ukupno: | F26: =SUM(F21:F25) -> 5136
A29: 13. | B29: TERMOIZOLACIJSKI RADOVI
B30: NAPOMENA: Kod svih stavaka u cijenu uključiti detaljan pregled površine na koju se hidroizolacija postavlja i njeno eventualno potrebno pranje, odmašćivanje, čišćenje od neravnina.
A31: 13.2. | B31: Dobava i postava rubne trake od kamene vune uz pregradne i nosive zidove u debljini od 2 cm u visini slojeva poda. Tehničke karakteristike koje kamena vuna mora zadovoljiti su: • reakcija na požar: razred A1 prema HRN EN 13501-1 ili jednakovrijednoj • toplinska provodljivost ʎ ≤ 0,038 W/mK prema HRN EN 12667 ili jednakovrijednoj • razina stišljivosti CP2 prema HRN EN 12431 ili jednakovrijednoj • dinamička krutost SD ≤ 48 MN/m³ prema HRN EN 29052-1 ili jednakovrijednoj Stavka uključuje rad i materijal osnovni i pomoćni, sve prema nacrtu projektanta. | C31: m' | D31: 331 | F31: =D31*$E31 -> 0
A32: 13.3. | B32: Dobava i ugradnja materijala za izolaciju stropa prizemlja između veznih greda na način da se između greda ispunjava kompaktnim pločama od kamene mineralne vune specifične gustoće 30 kg/m³, vrijednosti toplinske provodljivosti λ ≤ 0,037 W/mK. Potrebna debljina izolacije između rogova je 12,00 cm. Sve izvesti prema pravilima struke i prema uputama proizvođača. U stavku uključen sav rad i materijal osnovni i pomoćni, sve do potpune gotovosti. | C32: m2 | D32: 504.5 | F32: =D32*$E32 -> 0
A33: 13.4. | B33: Dobava i ugradnja materijala za izolaciju stropa prizemlja, na način da se ispod veznih greda postavlja višenamjenska izolacijska ploča od kamene vune kaširana s alu folijom s donje strane. Potrebna debljina izolacije ispod rogova je d = 4,0 cm. Karakteristike tražene izolacije su: - gustoća 30 kg/m³ - toplinske provodljivosti λ ≤ 0,037 W/mK prema normi HRN EN 12667 ili jednakovrijednoj - HRN EN 13162: MW-EN13162-T5-DS(TH)-WS-AF5 ili jednakovrijednoj - klasa gorivosti prema normi HRN EN 13501-1: A1 ili jednakovrijednoj Sve izvesti prema pravilima struke i prema uputama proizvođača. U stavku uključen sav rad i materijal osnovni i pomoćni, sve do potpune gotovosti. | C33: m2 | D33: 504.5 | F33: =D33*$E33 -> 0
A34: 13.7. | B34: Dobava i ugradnja ekstrudiranog polistirena (XPS) debljine 10 cm glatke površine i stepenastog ruba, koeficijenta toplinske provodljivosti λ≤0,035W/mK, tlačne čvrstoće 300 kPa. Ploče se postavljaju vertikalno kao toplinska izolacija nadtemeljnog zida i temelja. Izolaciju je potrebno zaljepiti za podlogu koristeći polimer-bitumensko ljepilo (1,6 kg/m²), uključeno u cijenu stavke. Sve izvesti pravilima struke i uputama proizvođača. U stavku uključen sav rad i materijal osnovni i pomoćni, sve do potpune gotovosti. | C34: m2 | D34: 153 | F34: =D34*$E34 -> 0
B35: 13. Termoizolaterski radovi ukupno: | F35: =SUM(F31:F34) -> 0
A38: 24. | B38: FASADERSKI RADOVI
B39: FASADA SVJETLOSNE GRANICE 20≥HBW≥8
A40: 24.1. | B40: Dobava i ugradnja potrebnih materijala za izvedbu sokla fasadnog toplinsko izolacijskog sustava (svjetlosna granica 20≥HBW≥8) sa namjenskim izolacijskim pločama XPS namijenjenih za izolaciju sokla, d= 10 cm, armirnog sloja ojačanog karbonskim vlaknima, završne silikonske žbuke ojačane karbonskim vlaknima, te završnog bojanja fasadnom bojom ojačanom karbonskim vlaknima u tamnoj nijansi (svjetlosna granica HBW≥8). Cijena stavke uključuje dobavu i postavu komponenti prema uputama proizvođača. Sve elemente fasade ponuditi u okviru atestiranog sustava proizvođača fasade. Prije izvođenja dužnost je izvođača i obračunato je u stavci pripremiti i po potrebi očistiti podlogu, provjeriti stanje i nosivost podloge, ukloniti sve nenosive dijelove, ukoniti sve masnoće i tvari koje razdvajaju. Sokl se izvodi u nastavku i ravnini sa gornjim dijelom fasade, bez vidljivog prijelaza, bez izvedbe razvajajuće šine, sa istim slojem završne žbuke ojačane karbonskim vlaknima. Završni sloj žbuke dodtano se zaštićuje na dijelu netom ispod razine tla i 5 cm iznad tla sa vodoodbojnim premazom i premazuje završnom fasadnom bojom ojačanom karbonskim vlaknima. Detalj izvesti prema projektu i prema tipskom detalju odabranog proizvođača fasadnog sustava. Redoslijed izvođenja:
B41: 1) U zoni podnožja, ljepljenje izolacijskih XPS namjenskih ploča za podnožje (do max 20 cm ispod razine tla) iz atestiranog sustava proizvođača fasade isključivo namjenjenih za izolaciju sokla, koeficijenta toplinske provodljivosti λ≤0,035, tlačne čvrstoće CS (10)150≥ 150 kPa, difuzijskog upijanja vode EN12088 WD(V)5≤5%, vodoupojnosti kod potpunog uranjanja EN12087 WL(T)3≤3%. Debljina ploče d= 10 cm. Lijepljenje se izvodi vapno/cementnim suhim mortom, s hidrauličkim vezanjem, namijenjen za lijepljenje fasadnih izolacijskih ploča i ploča za sokl, posebno na bitumenskim podlogama, isključivo iz atestiranog sustava proizvođača fasade, uz ostvarivanje kontaktne površine od min. 40%. Tehničke karakteristike koje mort mora zadovoljit: • gustoća svježeg morta prema EN 1015-10 ili jednakovrijedno: 1,70 g/cm³ • prionjivost prema EN 1015-12 ili jednakovrijedno: 0,5 N/mm²
