Workbook

Sheet Opći uvjeti
C1: GRAĐEVINA: Stambeno-poslovna građevina | E1: BR. PROJ. | G1: 5-2026-S
C2: Martićeva 8
C3: NARUČITELJ: GSKG d.o.o. | E3: ZOP | F3: 5-2026-MARTIĆEVA
C5: FAZA PROJEKTA: Glavni projekt | E5: DATUM | G5: veljača 2026.
C8: OPĆI UVJETI IZVOĐENJA I OPĆI UVJETI POJEDINIH VRSTA RADOVA
C9: Prije davanja ponude izvođač treba obavezno pročitati ove opće uvjete. Oni su sastavni dio troškovnika i u svemu ih se treba pridržavati. Troškovnik s općim uvjetima, grafički dijelovi (nacrti) s tehničkim opisom i ev. drugi dijelovi dokumentacije čine cjelinu koju izvođač treba proučiti. Nedovoljno upoznavanje s ostalim dijelovima projekta (grafičkim i tekstualnim) ne može biti razlog za povećanje jediničnih cijena ili greške u izvedbi Projektirani radovi moraju se izvoditi prema odobrenoj projektnoj dokumentaciji. Sve eventualne nejasnoće treba izvoditelj riješiti s projektantom prije davanja ponude, jer se naknadni zahtjevi neće uvažiti.
C10: Izvoditelj treba prije davanja ponude obići i pregledati gradilište/građevinu (zonu izvođenja radova), način i mogućnosti pristupa, montaže skele, mogućnost zauzimanja javne površine za potrebe izvođenja radova i sl. Razna otežanja radova (skučen prostor, male količine, rad noću i pod rasvjetom i slično) treba izvođač utvrditi prije davanja ponude i uračunati ih u jediničnu cijenu za odgovarajuću stavku, jer se nikakvi naknadni zahtjevi neće uvažavati.
C11: Izvođač prilikom uvođenja u posao i formiranja gradilišta, preuzimanja odgovornosti za nekretnini na kojoj izvodi radove i od tog trenutka pa do primopredaje odgovoran je za nju, stvari i osobe unutar gradilišta. U cijenistavke treba predvidjeti obavezno i sve troškove osiguranja uskladištenog materijala, sve do njegove ugradbe ili primopredaje. Izvođač je dužan, u okviru ugovorene cijene, osigurati gradilište od djelovanja više sile i krađe i uključiti sve troškove osiguranja uskladištenog materijala, sve do njegove ugradbe ili primopredaje.
C12: Investitor je dužan tijelu graditeljstva /nadležnim tijelima, najkasnije u roku od osam dana prije početka građenja ili nastavka radova, pismeno prijaviti početak građenja (o otvaranju gradilišta trebaju biti obaviještene nadležne službe). Izvođač treba s nadzornim inženjerom izraditi vremenski plan (gantogram) aktivnosti na gradilištu čime će odrediti dinamiku dobave materijala, opreme i drugog, financiranja itd.
C13: Obaveza izvoditelja radova je uredno voditi dokumentaciju gradilišta propisanu Zakonom o gradnji (NN 153/13, 20/17).
C14: Izvođač na gradilištu, ovisno o vrsti građevine, odnosno radova, mora imati:
C15: - građevinski dnevnik
C16: - dokaz o svojstvima ugrađenih građevnih proizvoda u odnosu na njihove bitne značajke, dokaze o sukladnosti ugrađene opreme i/ili postrojenja prema posebnom zakonu, isprave o sukladnosti određenih dijelova građevine temeljnim zahtjevima za građevinu, kao i dokaze kvalitete (rezultati ispitivanja, zapisi o provedenim procedurama kontrole kvalitete i dr.) za koje je obveza prikupljanja tijekom izvođenja građevinskih i drugih radova za sve izvedene dijelove građevine i za radove koji su u tijeku određena zakonom, posebnim propisom ili projektom
C17: - elaborat iskolčenja građevine, ako isti nije sastavni dio glavnog projekta, odnosno idejnog projekta
C18: - propisanu dokumentaciju o gospodarenju otpadom sukladno posebnim propisima koji uređuju gospodarenje otpadom.
C19: Svu zahtijevanu dokumentaciju dužan je izvoditelj dati na uvid ovlaštenim inspekcijskim službama.
... C193: -zaštite i osiguranja, primjena svih mjera zaštite na radu.

Sheet Dvorišna fasada
D1: ='Opći uvjeti'!C1 -> GRAĐEVINA: Stambeno-poslovna građevina | F1: BR. PROJ. | H1: 5-2026-S
D2: ='Opći uvjeti'!C2 -> Martićeva 8
D3: NARUČITELJ: GSKG d.o.o. | F3: ZOP | H3: 5-2026-MARTIĆEVA
D5: FAZA PROJEKTA: Glavni projekt | F5: DATUM | H5: veljača 2026.
C7: RAr. | D7: Opis stavke | E7: Jed. mjera | F7: Količina | G7: Jed. cijena | H7: Ukupno cijena
D9: NAPOMENA 1: Sve nejasnoće u troškovniku i u izvedbenom projektu treba riješiti s projektantom prije davanje ponude i početka radova.
D11: NAPOMENA 2: Izvođač je dužan u cijenu radova uključiti sve potrebne zaštite dijelova gradilišta koji nisu predmetom radova od oštećenja i prljanja, odvajanje prostora rada od ostatka prostora, izvedba daščanih prijelaza i sl.
C13: A | D13: OBNOVA DVORIŠNIH PROČELJA
C15: A.I | D15: Skele i pripremni radovi
C17: 1. | D17: Fasadna skela
D18: Doprema na gradilište, montaža, demontaža i odvoz fasadne skele od bešavnih cijevi. Izvesti je prema projektu i statičkom računu koji je izvodač dužan napraviti prije izvedbe skele, prema važećim zakonima, propisima, standardima, pravilima struke. Uključivo radne platforme i zaštitne ograde (visine minimalno 1,2 m), sva potrebna ukrućenja i sidrenja. Osigurati je sidrenjem u zgradu i zaštititi od groma uzemljenjem. U jediničnoj cijeni je i zaštitni zastor od jutenih ili PE traka, po cijeloj površini vanjske strane skele, željezne ili drvene ljestve, penjalice i sav pomoćni materijal i pribor. Minimalna širina skele 80 cm, od pročelja udaljena 15-20 cm, tj udaljenosti prikladnoj za izvođenje. Transport materijala, komunikacije i rad se vrše s vanjske strane zgrade preko skele, ne kroz zgradu. Prije davanja ponude izvodač može pregledom situacije utvrditi mogućnosti postave skele (balkoni i dr.), uvjete pristupa, zaštite prostora, vegetacije i ljudi. Potrebno je osigurati prostor za odlaganje materijala i ishoditi odobrenje susjeda za radove na zidu prema susjednim parcelama. Stavka obuhvaća i zaštite svih krovnih, podnih i drugih ploha koje nisu obuhvaćene posebnim stavkama, te Projekt i Dnevnik skele.
D19: Obračun po m2 vertikalne projekcije pročelja. Visina skele 18,92-20,95 m (+ do 1 m iznad krova)
D20: Obračun po površini vertikalne projekcije dijela pročelja.
D21: a) Dvorišno pročelje | E21: m2 | F21: 2166.4047 | H21: =F21*G21 -> 0
C23: 2. | D23: Tunelska skela
D24: Doprema na gradilište, montaža, demontaža i odvoz tipske tunelske skele širine do 1,0 m za prolaz i zaštitu pješaka.
D25: Tunelska skela se izrađuje od čeličnih bešavnih cijevi sa spojnim elementima i sa horizontalnim i kosim ukrućenjima, sidrenjem, gredica, fosni, zaštitnom ogradom po cijeloj visini i pokrovom od dva reda mosnica i nepropusne folije.
D26: Izvedba prema projektu , statičkom računu, važećim zakonima, propisima, standardima i pravilima struke.
D27: Nakon podizanja tunelske skele na skelu je potrebno postaviti svu signalizaciju (rasvjetu, znakovi upozorenja, putokazi), predvidjeti osiguranje ulaza u zgradu i prikladan prostor za odlaganje materijala.
D28: Obračun tunelske skele po m1.
D29: - podizanje i demontaža tunelske skele (2,50 m1) | E29: m1 | F29: 3.3 | H29: =SUM(F29*G29) -> 0
C31: 3. | D31: Konzervatorska ispitivanja
D32: lzvršiti konzervatorska istraživanja materijala i boje pročelja, nakon postave skele, a prije rušenja i demontaža, radi utvrđivanja izvorne obrade i izgleda. Otvoriti konzervatorske sonde na površinama sokla, prizemlja, katova, i drugo, po nalogu konzervatorskog nadzora. Stavka uključuje izradu nacrta istraživanja s ucrtanim opisanim nalazima, fotodok. i prijedlogom za obnovu.
D33: a) Obračun po broju istražnih sondi | E33: kom | F33: 2 | H33: =F33*G33 -> 0
D34: b) Obračun po kompletu elaborata istražnih radova | E34: kompl | F34: 1 | H34: =F34*G34 -> 0
C36: 4. | D36: Zaštita otvora i drugog
D37: Dobava, postave, skidanje i odvoz drevnih dasaka za zaštitu otvora ili drugog na pročeljima. Postavlja se na dovratnike i doprozornike ili slično, tako da ih ne ošteti. Uključiti zaštitu ventilacijskih otvora i drugog i dodatne potkonstrukcje i element (drvene grede - daske, mosnice, panoi i dr.).
D38: Obračun po m2 zaštićenih otvora / ploha na pročeljima.
D39: a) Dvorišno pročelje | E39: m2 | F39: 277.67201 | H39: =F39*G39 -> 0
C41: 5. | D41: Demontaže i blokada instalacija i slično
D42: Prije početka radova potrebno je otpojiti, s privremenom blokadom, elektroinstalacije, provjeriti izvore napajanja, izvode, kutije, poklopce itd. u zoni izvođenja radova, isključiti ih i osigurati za vrijeme radova i pustiti u pogon nakon dovršetka. Demontaža svih instalacijskih kablova i uređaja (antena, gromobrana, kanalica, rasvjetnih tijela i sl.) s nadžbuknih nosača, njihovih pričvrsnica, kuka i drugih elemenata. Nakon provjere, ako više nisu u funkciji, odstraniti iste na gradilišnu deponiju. Ako se koriste, deponirati do dovršetka radova iii vratiti vlasniku i nakon čiśčenja / obnove montirati na mjesto po odobrenju konzervatorskog nadzora i suvlasnika. Uključivo ostale eventualne instalacije osiguranje i zaštita. Radove izvode nadležne stručne osobe. Montiranje instalacijskih kablova (antenskih i sl.) po nalogu suvlasnika i konzervatosrkog nadzora u usjecima i kanalicama ispod žbuke obuhvaćeno je posebnom stavkom.
D43: Obračun po kompletu. | E43: kompl | F43: 1 | H43: =F43*G43 -> 0
C45: A.I | D45: Skele i pripremni radovi | E45: UKUPNO: | H45: =SUM(H18:H44) -> 0
C48: A.II | D48: Rušenja i transporti
C50: 1. | D50: Uklanjanje postojeće žbuke i priprema zida.
D51: Paljivo ručno obijanje postojeće žbuke (3-4 cm) do čiste, ravne, čvrste i suhe podloge, skupljanje šute i odvoz na gradilišnu deponiju. Uključivo žbuka istaka, sokla, špaleta, podgledi balkona, udubljenja i slično. Pri obijanju paziti da se na oštate druge plohe, razni otvori i dr. i da ne dode do prodala vode i vlage u konstrukciju ili unutrašnjost pd ispiranju i vlaženju. Stavka uključuje i: - sva snimanja, evidentiranja, uzimanja otisaka i izrada šablona, priprema uzoraka postojeće žbuke, dostava konzervatorskom nadzoru s ovjerom, sve zaštite i pomoćne konstrukcije - čišćenje čitave otucane površine žičanim četkama, temeljito otprašivanje i višekratno pranje vodom pod pritiskom koji treba utvrditi na probnom polju
D52: - čišćenje sljubnica od morta (do dubine od 2 cm), - sve potrebne popravke zida i profilacija od opeke, zatvaranje sljubnica, pukotina injektiranjem mortom na bazi hldrauličnog vapna velike čvrstoće radi poboljšanja cjelovitosti zidane konstrukcije (a nije izvedeno u B.III.1) - sve potrebne popravke, izravnanja i pripreme gornjih ploha parapeta i ploha špaleta i profilacija za izvedbu klupčica, opšava I RAL ugradnju prozora - provjeru vertikalnosti, izravnanje neravnina i krpanje VC žbukom na prethodno vodom navlaženoj podlozi - pripremu podloge, vlaženja i ostale radove po uputama prolzvodača nove obloge / žbuke - provjeru i zaštitu ventilacijskih otvora, svu zaštitu i osiguranja zgrada, okoliša - ostale radove po uputama proizvodača nove žbuke Obračunati sve koeficijente specifične profilacje (i ogoljelosti pročelja) i uključiti ih u jediničnu cijenu (bez povećanja / smanjenja obračunske površine), kao i otažanost pristupa uvučenim dijelovima pročelja.
D53: Obračunati sve koeficijente specifične profilacije i uključiti ih u jediničnu cijenu (bez povećanja obračunske površine).
D54: Ako se pri obijanju naiđe na ventilacijske otvore bilo koje vrste, treba izuzetno pažIjivo otucati žbuku u zoni tih otvora i zaštititi ih prije čišćenja i ispiranja.
D55: Obračun po površini vertikalne projekcije dijela pročelja.
...

Sheet Ulična fasada 
D1: ='Opći uvjeti'!C1 -> GRAĐEVINA: Stambeno-poslovna građevina | F1: BR. PROJ. | H1: 5-2026-S
D2: ='Opći uvjeti'!C2 -> Martićeva 8
D3: NARUČITELJ: GSKG d.o.o. | F3: ZOP | H3: 5-2026-MARTIĆEVA
D5: FAZA PROJEKTA: Glavni projekt | F5: DATUM | H5: veljača 2026.
C7: RAr. | D7: Opis stavke | E7: Jed. mjera | F7: Količina | G7: Jed. cijena | H7: Ukupno cijena
D25: NAPOMENA 1: Sve nejasnoće u troškovniku i u izvedbenom projektu treba riješiti s projektantom prije davanje ponude i početka radova.
D27: NAPOMENA 2: Izvođač je dužan u cijenu radova uključiti sve potrebne zaštite dijelova gradilišta koji nisu predmetom radova od oštećenja i prljanja, odvajanje prostora rada od ostatka prostora, izvedba daščanih prijelaza i sl.
C29: B | D29: OBNOVA ULIČNOG PROČELJA
C31: B.I | D31: SKELE I PRIPREMNI RADOVI
C33: 1. | D33: Za potrebe obnove pročelja potrebno je podići skelu i provesti istražne radove u suradnji sa predstavnikom Gradskog zavoda za zaštitu spomenika kulture i prirode.
D34: Dovoz i montaža fasadne cijevne skele u svrhu sanacije pročelja, te demontaža i odvoz nakon završetka radova.
D35: Skelu izvesti prema projektu i statičkom računu koji je izvođač dužan napraviti prije podizanja skele.
D36: Skelu je potrebno izraditi prema pravilima struke i važećim zakonima, standardima i propisima, na nju postaviti svu potrebnu signalizaciju prema Zakonu.
D37: Skela u svemu mora odgovarati postojećim propisima zaštite na radu i zaštite prolaznika. Svi materijali za izradu skele moraju odgovarati postojećim tehničkim propisima i standardima.
D38: Skela se izrađuje od čeličnih bešavnih cijevi sa spojnim elementima i sa horizontalnim i kosim ukrućenjima.
D39: Skelu je potrebno osigurati protiv deformacija, udara vjetra, protiv prevrtanja sidrenjem u objekt pomoću kuka za pričvršćenje skele i protiv udara groma.
D40: Skela se oslanja i učvršćuje vijcima M12 preko metalnih podložnih papuča i fosni u čvrstu i stabilnu podlogu.
D41: Radna platforma će se izvesti od dva reda mosnica debljine 4,8 cm i širine 25 cm koje se postavljaju jedna preko druge tako da drugi red pokriva reške prvog reda. Između mosnica postaviti krovnu ljepenku br. 120 sa preklopima min 10 cm ili PVC foliju.
D42: Oko radnih platforma postavlja se zaštitna ograda visine 120 cm koja se sastoji od čeličnog rukohvata i ispune od čelične mreže. Uz podnožje ograde uz radnu platformu postaviti vertikalno mosnicu visine 20 cm.
D43: Unutar skele postaviti željezne ili drvene ljestve za penjanje kako bi se mogao vršiti nadzor i konzervatorski nadzor.
D44: Skelu zaštititi od udara groma uzemljenjem.
D45: U jediničnu cijenu uračunati i zaštitni zastor od jutenih ili PE traka po cijeloj površini vanjske strane skele.
... D52: U cijenu stavke uračunati ishođenje rješenja o zauzimanju javne površine i plaćanje naknade za zauzimanje javne površine, te Projekt i Dnevnik skele.
D53: - podizanje i demontaža skele | E53: m2 | F53: 580.16994 | H53: =SUM(F53*G53) -> 0
D54: - rješenje za zauzimanje javne površine+naknada | E54: komplet | F54: 1 | H54: =SUM(F54*G54) -> 0
C56: 2. | D56: TUNELSKA SKELA
D57: Doprema na gradilište, montaža, demontaža i odvoz tipske tunelske skele širine do 2,0 m za prolaz i zaštitu pješaka.
D58: Tunelska skela se izrađuje od čeličnih bešavnih cijevi sa spojnim elementima i sa horizontalnim i kosim ukrućenjima, sidrenjem, gredica, fosni, zaštitnom ogradom po cijeloj visini i pokrovom od dva reda mosnica i nepropusne folije.
D59: Izvedba prema projektu , statičkom računu, važećim zakonima, propisima, standardima i pravilima struke.
D60: Nakon podizanja tunelske skele na skelu je potrebno postaviti svu signalizaciju (rasvjetu, znakovi upozorenja, putokazi), predvidjeti osiguranje ulaza u zgradu i prikladan prostor za odlaganje materijala.
D61: Obračun tunelske skele po m1.
D62: - podizanje i demontaža tunelske skele (21,67 m1) | E62: m1 | F62: 21.67 | H62: =SUM(F62*G62) -> 0
C64: 3. | D64: PE FOLIJA ZA ZAŠTITU
D65: Dobava i postava, skidanje i zbrinjavanje nakon završenih radova PE folije, OSB ploča za zaštitu prozora i vratiju i ostalog na pročelju (portafona, izvoda plinske peći, elektroormara, susjednih krovnih oluka, ukrasa i ostalog po odredbi konzervatorskog nadzora).
D66: Folija se pričvršćuje na doprozornike i dovratnike pomoću drvenih letvica, ljepljive trake i sl. na način da ne oštećuje prozore i vrata što treba uračunati u cijenu.
D67: U cijenu uključiti eventualno potrebne dodatne potkonstrukcije (daske, mosnice, panoe i sl.), također uključiti i zaštitu ventilacijskih otvora i sl.
D68: Obračun po m2 površine prozora, vratiju i ostalih zaštićenih elemenata.
D69: - OSB PLOČE | E69: m2 | F69: 83.33699 | H69: =SUM(F69*G69) -> 0
C71: 4. | D71: DEMONTAŽA I MONTAŽA
D72: Pažljiva demontaža pločice sa kućnim brojem, portafona i informacijskih ploča, te ponovna montaža istih nakon završetka fasade.
...

Sheet Rekapitulacija
D1: ='Dvorišna fasada'!D1 -> GRAĐEVINA: Stambeno-poslovna građevina | F1: BR. PROJ. | H1: 5-2026-S
D2: ='Dvorišna fasada'!D2 -> Martićeva 8
D3: NARUČITELJ: GSKG d.o.o. | F3: ZOP | H3: 5-2026-MARTIĆEVA
D5: FAZA PROJEKTA: Glavni projekt | F5: DATUM | H5: veljača 2026.
D8: REKAPITULACIJA
C10: ='[1]Građevinsko-obrtnički radovi'!C11 -> A | D10: FASADA - DVORIŠNA | H10: ='Dvorišna fasada'!H335 -> 0
C11: ='[1]Građevinsko-obrtnički radovi'!C1069 -> B | D11: FASADA - ULIČNA | H11: ='Ulična fasada '!H594 -> 0
D13: =D8 -> REKAPITULACIJA | E13: UKUPNO | H13: =SUM(H10:H12) -> 0
G15: PDV 25% | H15: =H13*0.25 -> 0
G17: SVEUKUPNO | H17: =H13+H15 -> 0
