Workbook

Sheet nas
A10: Građevina: | B10: Stambena zgrada u Zagrebu, Sveti Duh 65
A13: Lokacija: | B13: Sveti Duh 65, 10000 Zagreb
B14: k.č.br. 1488, k.o. Črnomerec
A16: Investitor: | B16: Suvlasnici stambene zgrade u Zagrebu
B17: Sveti Duh 65, 10000 Zagreb
A19: Sadržaj: | B19: TROŠKOVNIK GRAĐEVINSKO-OBRTNIČKIH RADOVA
A24: Zajednička oznaka projekta: | B24: Sveti Duh 65
A27: Tehnički dnevnik: | B27: 02-2020
A30: Izrada troškovnika: | B30: Hrvoje Bilandžić, dipl. ing. arh.
A34: Glavni projektant: | B34: Miljenko Kukić, dipl. ing. arh.
A37: Izradio: | B37: S.P.A.C.E. d.o.o.
B38: Miljenko Kukić, direktor
A41: Mjesto i datum: | B41: Zagreb, svibanj 2022.
A55: SADRŽAJ :
A57: 0. SVEUKUPNA REKAPITULACIJA
A59: 1. TROŠKOVNIK GRAĐEVINSKO - OBRTNIČKIH RADOVA

Sheet sve rekap
A5: Građevina: | B5: Stambena zgrada u Zagrebu, Sveti Duh 65
A8: Lokacija: | B8: Sveti Duh 65, 10000 Zagreb
B9: k.č.br. 1488, k.o. Črnomerec
A12: Investitor: | B12: Suvlasnici stambene zgrade u Zagrebu
B13: Sveti Duh 65, 10000 Zagreb
A16: Izradio: | B16: S.P.A.C.E. d.o.o.
B17: Miljenko Kukić, direktor
B20: OBJEDINJENI TROŠKOVNIK SVIH VRSTA RADOVA
A25: SVEUKUPNA REKAPITULACIJA
B27: GRAĐEVINSKI I OBRTNIČKI RADOVI | C27: € | D27: =rekap!F29 -> 0
B30: SVEUKUPNO | C30: € | D30: =SUM(D27:D27) -> 0

Sheet rekap
A5: TROŠKOVNIK GRAĐEVINSKO - OBRTNIČKIH RADOVA
A10: A. | B10: GRAĐEVINSKI RADOVI
A12: A.I. | B12: PRIPREMNI RADOVI ukupno | E12: € | F12: ='A.I.pri'!F36 -> 0
A13: A.II. | B13: RUŠENJA I DEMONTAŽE ukupno | E13: € | F13: ='A.II.dem'!F93 -> 0
A14: A.III. | B14: ZIDARSKI RADOVI ukupno | E14: € | F14: ='A.III.zidarski'!F69 -> 0
A15: A.IV. | B15: IZOLATERSKI RADOVI ukupno | E15: € | F15: ='A.IV.izo'!F78 -> 0
A16: A. | B16: GRAĐEVINSKI RADOVI UKUPNO: | E16: € | F16: =SUM(F12:F15) -> 0
A19: B. | B19: OBRTNIČKI RADOVI
A21: B.I. | B21: LIMARSKI RADOVI ukupno | E21: € | F21: ='B.I.lim'!F73 -> 0
A22: B.II.1 | B22: VANJSKA PVC STOLARIJA ukupno | E22: € | F22: ='B.II.1.PVC'!F65 -> 0
A23: B.II.2 | B23: VANJSKA ALUMINIJSKA STOLARIJA ukupno | E23: € | F23: ='B.II.2.ALU'!F52 -> 0
A24: B.II.3 | B24: ČELIČNA BRAVARIJA ukupno | E24: € | F24: ='B.II.3.ČEL'!F38 -> 0
A25: B.III. | B25: ZAVRŠNI ZIDARSK0 - FASADERSKI RADOVI ukupno | E25: € | F25: ='B.III._zz'!F100 -> 0
A26: B.IV. | B26: SOBOSLIKARSKO - LIČILAČKI RADOVI ukupno | E26: € | F26: ='B.IV.lič'!F72 -> 0
A27: B. | B27: OBRTNIČKI RADOVI UKUPNO: | E27: € | F27: =SUM(F21:F26) -> 0
B29: A+B UKUPNO: | E29: € | F29: =F16+F27 -> 0

Sheet opći
B2: OPĆI UVJETI
B4: OPĆI OPIS UZ TROŠKOVNIK
B6: 1. Glavni projekt energetske obnove i pripadajući troškovnik temelje se na obavljenom uvidu na postojećoj zgradi. Slojevi konstrukcija definirani u postojećoj projektnoj tehničkoj dokumentaciji preuzeti su kao stvarno izvedeni. Nevidljivi slojevi konstrukcija, koji nisu definirani postojećom dokumentacijom, pretpostavljeni su temeljem dosadašnjeg iskustva prema vremenu gradnje zgrade. Prije izvedbe potrebno je izvršiti detaljni uvid na licu mjesta te utvrditi slojeve konstrukcije vizualnim ispitivanjem i otvaranjem konstrukcija koje se rekonstruiraju.
B8: 2. Projekt je napravljen na temelju pravila dobrog zanata i preporuke o cjelovitoj obnovi koju podupire Fond za energetsku učinkovitost. Projekt će se u smislu cjelovite obnove adaptirati na zahtjeve korisnika uz poštivanje ispravnog redoslijeda radova kako bi se tehnički organizirale FAZE koje u konačnici vode cjelovitom rješenju.
B10: 3. Grafički dio (nacrti), tekstualni dio (opći i tehnički), kao i Program kontrole i osiguranja kvalitete dijelovi su arhitektonskog glavnog projekta, koji zajedno s pripadajućim troškovnikom čine cjelinu arhitektonskog projekta energetske obnove zgrade. Projektom energetske obnove dani su osnovni detalji izvedbe.
B12: 4. U fazi izvedbe, zbog činjenice da se radi o obnovi (rekonstrukciji), a ne izgradnji nove zgrade, bit će potrebna dodatna razrada detalja izvedbe u suradnji s izvođačem radova, te ukoliko se nakon uklanjanja pojedinih slojeva i uvida u postojeće slojeve i stanje konstrukcije utvrdi odstupanje odnosno različitost u odnosu na postojeće stanje prikazano projektom obnove, potrebno je napraviti reviziju glavnog projekta. U slučaju nužnosti odstupanja od glavnog projekta prilikom izvođenja radova potrebno je izraditi izmjene i dopune glavnog projekta.
B14: 5. Također je potrebno, prije izvedbe ETICS sustava, napraviti statičku provjeru vanjskih zidova koja mora biti odobrena od strane inženjera konstrukcije i nadzornog inženjera. Odgovarajućim upisom u građevinski dnevnik potrebno je verificirati projektno rješenje ili po potrebi izvršiti korekciju. Izvođač je dužan proučiti sve gore navedene dijelove projekta, te u slučaju nejasnoća ili eventualnih odstupanja od stvarnog stanja na terenu tražiti mišljenje projektanta i nadzornog inženjera. Prije početka radova izvođač je obavezan kontrolirati na postojećoj zgradi sve potrebne mjere za svoj rad.
B16: 6. Preporuka projektanta je izvođenje cjelovitog rješenja energetske obnove zgrade iz sljedećih razloga: 1. tehnički ispravno izvođenje detalja, 2. tehnički ispravan redoslijed izvođenja radova, 3. suzbijanje selektivnih intervencija na pročeljima zgrade, 4. zaštita arhitektonskog djela u smislu estetske i tehničke cjelovitosti oblikovanja, 5. očuvanje i unapređenje bitnih zahtjeva građevine, 6. ušteda sredstava i vremena (u slučaju fazne gradnje pojedini radovi se umnožavaju, kao što su postava skele, limarski radovi i sl.), 7. ostvarivanje tržišnih popusta (cijena pojedinačnog proizvoda manja je što je količina veća), 8. integralna rješenja podupiru se bespovratnim sredstvima Fonda za zaštitu okoliša i energetsku učinkovitost. U slučaju nužnosti odstupanja od glavnog projekta prilikom izvođenja radova potrebno je izraditi izmjene i dopune glavnog projekta te ih uskladiti zahtjevima korisnika sukladno pravilima dobrog zanata i inženjerske etike. U slučaju fazne izgradnje predlaže se tehnički ispravan slijed radova i to: 1. rekonstrukcija ostakljenih konstrukcija vanjske ovojnice grijanih prostora, 2. rekonstrukcija ostakljenih konstrukcija vanjske ovojnice negrijanih prostora, 3. rekonstrukcija ravnog neprohodnog krova, 4. rekonstrukcija zidova pročelja.
B18: 7. Za eventualne promjene pojedinih projektnih rješenja u svrhu ekonomičnosti izvedbe, izvođač je dužan o svom trošku izraditi projekt izvedenog stanja promijenjenog dijela i dati na odobrenje glavnom projektantu i nadzornom inženjeru. Pod izradom dokumentacije smatra se izrada izmjena i dopuna u smislu iskaza FAZA izvedbe i provodi se kroz troškovnički opis.
B20: 8. Izvođač će se pridržavati svih važećih zakona i propisa i to: Zakona o prostornom uređenju (NN 153/13, 65/17, 114/18, 39/19), Zakona o gradnji (NN 153/13, 20/17, 39/19), Zakona o građevinskoj inspekciji (NN 153/13), Zakona o zaštiti na radu (NN 71/14, 118/14, 94/18, 96/18), Zakona o zaštiti od buke (NN 30/09, 55/13, 153/13, 41/16, 114/18), Zakona o zaštiti od požara (NN 92/10), svih pravilnika koji iz tih zakona proizlaze, kao i svih drugih zakona iz područja gradnje, tehničkih propisa, priznatih tehničkih pravila i hrvatskih normi (HRN).
B22: 9. Izvođač će prilikom uvođenja u posao preuzeti nekretninu i obavijestiti nadležne službe o otvaranju gradilišta i početku radova. Od tog trenutka pa do primopredaje zgrade, izvođač je odgovoran za stvari i osobe koje se nalaze unutar gradilišta. Od ulaska na gradilište izvođač je obavezan voditi građevinski dnevnik u kojem bilježi opis radnih procesa i građevinsku knjigu u kojoj bilježi i dokumentira mjerenja, sve faze izvršenog posla prema stavkama troškovnika i projektu. Izvođač će na gradilištu čuvati građevnu dozvolu ukoliko je to zakonom određeno, glavni i izvedbeni projekt i dati ih na uvid ovlaštenim inspekcijskim službama.
B24: 10. Izvođač će ugraditi projektom predviđen i prema hrvatskim normama atestiran materijal. Sve radove izvesti će od kvalitetnog materijala prema opisu, detaljima, pismenim naređenjima, ali sve u okviru ponuđene jedinične cijene. Svi nekvalitetni radovi imaju se otkloniti i zamijeniti ispravnima, bez bilo kakve odštete od strane investitora.
... B50: 24. Izvođač je dužan ponuditi sve stavke po opisu troškovnika, a eventualne alternative posebno opisati i izdvojiti. Promjene pojedinih stavki moguće su samo uz prethodno odobrenje projektanta ili nadzornog inženjera.

Sheet A.I.pri
A2: TROŠKOVNIK GRAĐEVINSKO OBRTNIČKIH RADOVA
A3: A. GRAĐEVINSKI RADOVI / A.I. PRIPREMNI RADOVI
A4: r.b. | B4: opis stavke | C4: jed. | D4: kol. | E4: jed.cijena | F4: ukupno
A6: A. | B6: GRAĐEVINSKI RADOVI
A8: A.I. | B8: PRIPREMNI RADOVI
A10: OPĆI UVJETI
A12: Pri kalkulaciji ponuda ponuđač treba voditi računa o uvjetu investitora da zgrada za vrijeme radova mora biti u funkciji te da se radovi moraju planirati tako da se omogući boravak u svim dijelovima zgrade uz što manje i kraće poremećaje.
A14: Prethodno predaji ponude izvođač može pregledati lokaciju i zgradu, provjeriti snimak zgrade i okolnog terena, pregledati stanje u zgradi, upoznati se sa stanjem postojećih instalacija, uputiti se u funkciju zgrade kako bi mogao dati realnu cijenu za pripremne i ostale radove. Ukoliko izvođač prethodnim uvidom primijeti da je potrebno izvesti još neke pripremne radove, dužan je iste uvrstiti u cijenu koštanja putem obračuna u faktoru, jer se naknadni pripremni radovi neće posebno priznavati.
A16: Pripremni radovi koje je izvođač dužan izvesti bez posebnog iskaza troškova, a koji ulaze u cijenu zgrade kroz faktor nisu prikazani u posebnim stavkama troškovnika. Ovo se odnosi na izradu plana organizacije gradilišta, organizaciju prilaznih i privremenih puteva, staza, gradilišnih nastambi za radnike, upravu, skladišta, nadstrešnice, te privremene priključke i razvode vodovoda, elektrike, telefona i ostalih instalacija na gradilištu, a za potrebe funkcioniranja gradilišta, zatim čuvarske službe, uređenja skladišta, geodetsko snimanje visina i vanjskog terena, radove na osiguranju gradilišta i radnika, za obeštećenja na gradilištu, kao i štete naknade prema trećim osobama, osiguranje prostorija za nadzornu službu, kao i ostale radove koji po pravilu terete režiju uprave izvođača i koji se ne naplaćuju posebno.
A18: U faktor ulaze i troškovi potrebnih ispitivanja materijala i konstrukcija te ishođenje atesta.
A20: Izvođač je dužan pridržavati se svih propisa javnog prometa. Dozvolu za korištenje javnih prometnih površina izvođač je dužan zatražiti od nadležnih službi, prema svojim potrebama za organizaciju gradilišta i platiti eventualne takse za ishođenje odobrenja za korištenje površina. Ovi troškovi su također u faktoru i ne naplaćuju se posebno.
A22: Izvođač građevinskih radova izvodi sve privremene instalacije vode, struje i ostalih potrebnih instalacija. On je dužan dozvoliti priključak ostalim svojim izvođačima (kooperantima) na te vodove. Utrošak vode i električne energije za jedinicu proizvoda uključuje se u analizu cijena proizvoda prema normativima utroška, a utrošak za potrebe ureda, gradilišta, pranje vozila i strojeva, rasvjetu gradilišta i ostalo uključuje se u faktor gradilišta.
A24: * SVI PRIPREMNI RADOVI PREDVIĐENI TROŠKOVNIKOM SU U SKLADU S POPISOM I ODREDBAMA OPRAVDANIH TROŠKOVA .
A26: 1. | B26: Čišćenje i raščišćavanje
B27: Čišćenje i raščišćavanje terena oko zgrade, a prije početka radova na rušenjima i demontaži. Stavka uključuje sva čišćenja od smeća i otpadnog materijala, kao i ostale nespecificirane radove, zajedno s utovarom, odvozom, istovarom i planiranjem otpadnog materijala na odlagalištu.
B28: teren oko zgrade | C28: m2 | D28: 110 | F28: =D28*E28 -> 0
A30: 2. | B30: Priprema gradilišta
B31: Priprema gradilišta koja uključuje zaštitu zgrade na način da tijekom radova ne dođe do oštećenja iste, osiguranje koridora za prolaz korisnika zgrade i njegova zaštita od šute i prašine te osiguranje okoline kojom se sprečava prilaz nezaposlenima tijekom radova. Sav prostor za vrijeme i nakon rušenja i demontaža, te prilikom izvođenja novih konstrukcija zaštititi od vremenskih nepogoda (vlaženja, prokišnjavanja, rashlađivanja) te osigurati i zaštititi od ostalih uvjeta koji bi mogli ometati izvođenje radova vezanih za postojeće instalacije (vodovod, odvodnja, grijanje, ventilacija, elektrika, plin i drugo). Sve radove treba izvoditi sukladno propisanim higijensko tehničkim mjerama zaštite na radu, tj. paziti na rad strojeva i alata, predvidjeti moguća urušavanja te postaviti i održavati zaštitne oplate, ograde i skele, postaviti znakove upozorenja na opasnosti te zaštititi fizičke osobe i zgradu tijekom izvođenja radova.
B32: Stavka obuhvaća pregled, kontrolu mjera i veličina postojećeg stanja građevinske konstrukcije zgrade, pregled postojećeg stanja opreme, instalacija, te utvrđivanje točnih koridora instalacija u objektu i izvan objekta. Pripremne radove je obavezan izvršavati izvođač radova prije nego pristupi izvođenju i za vrijeme izvođenja radova. U pripremne radove uključiti i pregled projektne dokumentacije s pripadajućim troškovnicima, a o svim nejasnoćama ili neusklađenostima pravovremeno izvjestiti investitora i projektanta. Obračun za izvođenje kompletnih pripremnih radove iz opisa stavke, po procjeni.
C33: kom | D33: 1 | F33: =D33*E33 -> 0
A36: A.I. | B36: PRIPREMNI RADOVI UKUPNO: | E36: € | F36: =SUM(F28:F35) -> 0

Sheet A.II.dem
A2: TROŠKOVNIK GRAĐEVINSKO OBRTNIČKIH RADOVA
A3: A. GRAĐEVINSKI RADOVI / A.II. RUŠENJA I DEMONTAŽE
A4: r.b. | B4: opis stavke | C4: jed. | D4: kol. | E4: jed.cijena | F4: ukupno
A6: A.II. | B6: RUŠENJA I DEMONTAŽE
A8: OPĆI UVJETI
A10: Projekt energetske obnove zgrade izrađen je temeljem mogućih izmjera i pretpostavljenih zidnih, stropnih i krovnih slojeva. Dužnost je izvođača da sondiranjem utvrdi stvarni sastav konstrukcija i u slučaju odstupanja sastava upozori nadzornog inženjera i investitora na odstupanje.
A12: Prije početka radova potrebno je konstrukcije u koje ne zadiru radovi zaštititi od mogućeg oštećenja. Sve otvore na pročeljima zgrade treba odmah nakon postave skele zaštititi PVC folijom debljine 0,20 mm kako ne bi došlo do njihovog oštećenja.
A14: Nakon provedenih pripremnih radova, svih potrebnih rasterećenja i potrebnih osiguranja, rušenja na građevini vrše se prema unaprijed utvrđenom redoslijedu dogovorenom s nadzornim inženjerom na način kojim se ne ugrožava stabilnost zgrade, sigurnost radnika i ljudi koji borave u zgradi. Demontaže i rušenja izvode se u pravilu od krova prema podrumu.
A16: Sva rušenja i demontaže konstruktivnih elemenata treba izvršiti pod nadzorom projektanta i statičara. Kod vršenja proboja ili vođenja instalacija u nosivim konstrukcijama zahvat vršiti maksimalno precizno bez narušavanja nosivih svojstava konstrukcije. Prilikom zahvata na nosivim konstrukcijama obavezno je podupiranje. Sva rušenja, probijanja, bušenja i dubljenja treba u pravilu izvoditi ručnim alatom bez upotrebe vibracionih uređaja, s osobitom pažnjom.
A18: Demontažu i ponovnu montažu gromobrana izvođač treba izvoditi prema Tehničkom propisu za sustave zaštite od djelovanja munje na građevinama (NN 87/08, 33/10).
A20: U cijenu radova trebaju biti uključene sve podupore, skele i privremene (zamjenske konstrukcije) koje osiguravaju stabilnost u toku radova, te se zahtjevi za nadoplate radi izvedbe privremenih konstrukcija neće priznavati kao i svi horizontalni i vertikalni prijenosi materijala dobivenih rušenjem i demontažom, odvozom na privremenu gradilišnu deponiju, gradsku planirku ili pohranu elemenata na mjesto po dogovoru s investitorom. To vrijedi i za čišćenje gradilišta i dovođenje javne površine u prvobitno stanje. U cijenu radova je uključeno i sigurno zbrinjavanje opasnih materijala (azbest, freoni). Ukoliko se uklanjaju elementi koji sadrže azbest to se mora učiniti u skladu sa Pravilnikom o građevnom otpadu i otpadu koji sadrži azbest (NN 69/16).
A22: Demontaža i privremeno deponiranje natpisnih ploča i sl. treba pohraniti na gradilištu ili kod korisnika. Izvođač snosi sve troškove ponovne dobave ili izrade pojedinih elemenata u slučaju oštećenja ili otuđenja sa gradilišta. Demontaža postojećih limenih elemenata, uključujući i prozorske klupčice na pročelju obavezno izvodi limar koji je dužan uzeti mjere i uzorke te snimiti detalje izvedbe, što je uključeno u cijenu stavke. Demontažu i ponovnu montažu postojećih vanjskih jedinica rashladnih uređaja na pročelju izvodi ovlašteni serviser. Demontažu i ponovnu montažu postojećeg gromobrana, strujnih ormarića i sl. na pročelju izvodi ovlaštena osoba. Demontaža vanjskih jedinica rashladnih uređaja, gromobrana, strujnih ormarića i sl. uključuje i njihovu sigurnu pohranu.
A23: U slučaju nastalih šteta, radi nepravodobno zaštićene lokacije na kojoj se vrše rušenja i demontaže, sve troškove nastalih šteta snosi izvođač. Izvođač je dužan striktno se držati mjera zaštite na radu.
A24: * SVI RADOVI DEMONTAŽA I RUŠENJA PREDVIĐENI TROŠKOVNIKOM SU U SKLADU S POPISOM I ODREDBAMA OPRAVDANIH TROŠKOVA.
A26: 1. | B26: Demontaža postojećih prozora i vrata
B27: Demontaža postojećih drvenih, aluminijskih i čeličnih prozora i vrata. Stavka uključuje demontažu pripadajućih okvira. Demontaža vanjskih klupčica je obračunata zasebno. Stavka uključuje demontažu i ponovnu montažu postojećih unutrašnjih zastora, ako ih je potrebno ukloniti zbog demontaže postojeće i montaže nove stolarije. Stavka uključuje transport na gradilišnu deponiju. Količinom je iskazan ukupan broj stijena koje se demontiraju. Točne dimenzije i broj komada svake pojedine stijene iskazani su u radovima B.II.1. i B.II.2.
C28: kom | D28: 41 | F28: =D28*E28 -> 0
A30: 2. | B30: Demontaža i ponovna montaža elemenata na pročelju
B31: Demontaža i uklanjanje elemenata na vanjskim zidovima i krovu: - instalacijskih kablova i cijevi - pločice s adresom i sl., te ponovna montaža dijela elemenata u dogovoru s korisnikom. Sve demontirane elemente potrebno je sigurno pohraniti na gradilištu ili kod korisnika. Nakon izvedbe pročelja demontirane elemente potrebno je odvesti na deponij ili predati korisniku. U stavku je uključeno otpajanje i ponovno spajanje svih vodova, uzemljenja i sl.
C32: komplet | D32: 1 | F32: =D32*E32 -> 0
A34: 3. | B34: Demontaža vanjskih klupčica na parapetima prozora
B35: Demontaža postojećih vanjskih limenih klupčica na parapetima prozora, radi izvedbe nove toplinske izolacije. Stavka uključuje transport na građevinsku deponiju.
B36: limenih klupčica | C36: m' | D36: 54 | F36: =D36*E36 -> 0
A38: 4. | B38: Demontaža vanjskih rešetki na parapetima prozora
B39: Demontaža postojećih vanjskih čeličnih rešetki na parapetima prozora, radi izvedbe nove toplinske izolacije. Rešetke potrebno zamijeniti novima, što je opisano u radovima B.III. Stavka uključuje transport na građevinsku deponiju.
B40: rešetke dimenzija cca 60x150 cm | C40: kom | D40: 3 | F40: =D40*E40 -> 0
B41: rešetke dimenzija cca 110x150 cm | C41: kom | D41: 2 | F41: =D41*E41 -> 0
A43: 5. | B43: Demontaža limova na rubovima fasadnih istaka i balkona
B44: Demontaža postojećih limova na rubovima fasadnih istaka i balkona te opšava krova uključivo sav pričvrsni materijal i podkonstrukciju, radi izvedbe toplinske izolacije na zidovima. Širina limova je cca 15 - 35 cm . Stavka uključuje transport na građevinsku deponiju.
B45: opšav balkona, r.š. cca. 30cm | C45: m' | D45: 25 | F45: =D45*E45 -> 0
B46: limovi vjenca zabata, r.š. cca. 40cm | C46: m' | D46: 17 | F46: =D46*E46 -> 0
B47: limovi nadstrešnice, r.š. cca. 50cm | C47: m' | D47: 2 | F47: =D47*E47 -> 0
A49: 6. | B49: Demontaža postojećih ograda balkona
B50: Demontaža postojećih čeličnih ograda balkona visine 100 cm, izrađenih od vertikalnih nosača Č 40x40 mm na razmaku cca 100 cm usidrenih u ab ploču, te ispune ograde od flaha Č 40x5 mm na razmaku od cca 20 cm navarenih na vertikale i horizontalnih nosača za prostiranje rublja od Č L40 x40 cm duljine cca 2.0 m, navarenih bočno na vrh ograde, sve zbog dotrajalosti i dodavanja toplinske izolacije na zidovima. Stavka uključuje transport na građevinsku deponiju.
B51: čelična ograda h=100 cm | C51: m' | D51: 25 | F51: =D51*E51 -> 0
A53: 7. | B53: Demontaža zidne i krovne limene obloge krovne kućice i ulazne nadstrešnice
B54: Demontaža zidne i krovne limene obloge krovne kućice i ulazne nadstrešnice radi izvedbe toplinske izolacije. U stavku je uključena i demontaža dijela potkonstrukcije pokrova. Stavka uključuje transport na građevinsku deponiju. Demontiraju se svi slojevi do drvene nosive konstrukcije kosog krova. Stavka uključuje transport na građevinsku deponiju. Sve radove izvoditi pažljivo i bez velikih vibracija kako se ne bi oštetile okolne konstrukcije. Sve izvoditi u skladu sa propisanim higijensko-tehničkim mjerama zaštite na radu, sa potrebnim radnim skelama i podupiranjima, te pod nadzorom stručne osobe.
B55: falcani lim | C55: m2 | D55: 31 | F55: =D55*E55 -> 0
A57: 8. | B57: Demontaža žljebova i vertikalnih oluka
B58: Demontaža postojećih limenih visećih žljebova i vertikalnih oluka na svim pročeljima, uključivo sav pričvrsni materijal i podkonstrukciju. Stavka uključuje transport na građevinsku deponiju.
...

Sheet A.III.zidarski
A2: TROŠKOVNIK GRAĐEVINSKO OBRTNIČKIH RADOVA
A3: A. GRAĐEVINSKI RADOVI / A.III. ZIDARSKI RADOVI
A4: r.b. | B4: opis stavke | C4: jed. | D4: kol. | E4: jed.cijena | F4: ukupno
A6: A.III. | B6: ZIDARSKI RADOVI
A8: OPĆI UVJETI
A10: Opći uvjeti su sastavni dio svake pojedine stavke. Sve što je navedeno u njima, a nije u pojedinačnom opisu stavke smatra se uključenim u jediničnu cijenu.
A12: Sve radove izvođač mora izvoditi prema troškovniku i glavnom projektu, solidno i stručno, prema pravilima dobrog zanata, Pravilniku o ocjenjivanju sukladnosti, ispravama o sukladnosti i označavanju građevinskih proizvoda (NN 103/08, 147/09, 87/10, 129/11), Pravilniku o tehničkim mjerama i uvjetima za završne radove u zgradarstvu (Sl.list br. 21/90), Tehničkom propisu za zidane konstrukcije (NN 01/07), Tehničkom propisu o racionalnoj upotrebi energije i toplinskoj zaštiti u zgradama (NN 128/15, 70/18, 73/18, 86/18) sa pripadajućim normama, Tehničkom propisu o građevnim proizvodima (NN 35/18), te svim ostalim hrvatskim i europskim tehničkim propisima i normama i priznatim tehničkim pravilima, a osobito:
A13: EN 1015-7, zapreminska masa i poroznost svježeg morta EN 1015-3, konzistencija svježeg morta EN 1015-11, tlačna i savojna vlačna čvrstoča morta EN 771-1, EN 772-1, EN 7723, EN 772-13, EN 772-16, HRN EN 14063-1:2008, tlačna čvrstoća opeke, na mjestu primjene oblikovani proizvodi od lakoagregatne eksp. gline
A14: HRN B.C1.030, B.C8.030, građevinski gips HRN B.C1.020, B.C8.030, građevinsko vapno HRN B.C8.015,022 – 026, cement HRN B.C8.011, portland cement HRN B.C8.030, pijesak HRN U.M2.010, U.M2.012, mortovi HRN U.F2.010, tehički normativi za izvođenje fasaderskih radova
A15: HRN EN 1008, HRN EN 13139;2003+AC;2006, voda i pijesak HRN EN 197-1:2003, cement HRN EN 459-1:2001, vapno
A17: Svi upotrebljeni materijali za izvedbu zidarskih radova moraju odgovarati gore spomenutim standardima i HRN-u. Posebno se skreće pažnja da izvođač mora prije izvedbe izvršiti pregled podloge te prodora u zidu prema nacrtu u prisutnosti nadzornog inženjera, voditi računa o uzidavanju pojedinih građ. elemenata, te upisati napomenu u građevinski dnevnik, kako ne bi kasnije došlo do naknadnih radova. Navedene radnje uključene su u jediničnu cijenu.
A19: Prije uporabe određenih materijala treba predočiti nadzornom inženjeru atest o kakvoći i kvaliteti materijala. Ukoliko ne postoje adekvatni standardi za materijale koji se ugrađuju, obavezno je pribaviti odgovarajući atest kao dokaz kvalitete. Izvoditelj radova mora tijekom izvođenja radova stalno obavljati kontrolu kakvoće rada.
A21: Izvoditelj je dužan osigurati i zaštititi sve dijelove građevine na kojima se izvode radovi, radi sprečavanja oštećenja tijekom izvedbe. Pojava svih oštećenja na dijelovima na kojima se ne izvode radovi ili koji su nastupili nepažnjom izvoditelja isti je dužan otkloniti o vlastitom trošku. Naročitu pažnju treba posvetiti zaštiti prozorskih stakala koje treba zaštititi PVC građevinskom folijom. Ta zaštita ulazi u jediničnu cijenu izvedbe pročelja zgrade.
A23: Sav rad, sve komunikacije i sav transport vrši se isključivo sa vanjske strane građevine, tj. preko skele. Zidarsko-fasaderski radovi se izvode na dobro očišćenoj i otprašenoj površini zida te ih treba izvoditi samo u povoljnim vremenskim uvjetima, uz odgovarajuće osiguranje i zaštitu svježe ožbukanih površina od štetnog utjecaja djelovanja sunca i oborina. Sve detalje izvedbe na pročelju potrebno je dogovoriti i na njih ishoditi suglasnost nadzornog inženjera, a prije pristupanja izvedbi radova. Obračun svih radova vršiti se kako je to naznačeno u opisu stavke.
A25: Prilikom izvođenja zidova zgrada izvođač se mora pridržavati slijedećih mjera: - zidanje se mora izvoditi sa pravilnim zidarskim vezovima, a preklop mora iznositi najmanje jednu četvrtinu dužine zidnog elementa, - debljina ležajnica ne smije biti veća od 15 mm, a širina sudarnica ne smije biti manja od 10 mm niti veća od 15 mm, - ako se zida za vrijeme zime treba zidove zaštiti od mraza, - zidovi čije izvođenje nije završeno prije nastupanja zimskih mrazova moraju se zaštiti na odgovarajući način, - svako naknadno bušenje ili izrada užljebina u zidovima zgrade koje nije bilo predviđeno projektom, može se izvoditi samo ako je prethodnim statičkim proračunom utvrđeno da nosivost zida poslije tog bušenja odnosno izrade žlijeba nije manja od propisane nosivosti. - poprečni i uzdužni zidovi moraju na spoju biti međusobno povezani zidarskim vezom, tj. za pregradne zidove treba ispustiti zupce u masivnom zidu na svaki drugi red za ½ opeke. - zidove uz vertikalni serklaž također zupčasto izvesti. - vanjske fuge ostaviti prazne od 1,5 do 2 cm za vezu žbuke prigodom žbukanja zidova. - za vrijeme zidanja opeku kvasiti vodom, a pri zidanju cementnim mortom opeka mora ležati u vodi neposredno prije zidanja - reške dimnjaka i ventilacionih kanala zagladiti. - prilikom zidanja pravovremeno ostaviti otvore prema zidarskim mjerama, voditi računa o uzidavanju pojedinih građevinskih elemenata, o ostavljanju žljebova za kanalizaciju, za centralno grijanje ako su ucrtani (ne plaća se posebno, ulazi u jediničnu cijenu)
A27: Posebno se ne naplaćuje ni zatvaranje (žbukanje šliceva, žljebova i sl.) iza položene instalacije. Zazidavanje (zatvaranje) žljebova u zidovima ostavljenih za instalacije kanalizacije i grijanja nakon izvođenja tih instalacija, opekom, rabicom ili na drugi način, ne plaća se posebno, ukoliko troškovnikom nije posebno propisano. Obračun nosivih zidova, stupova i dimnjaka je zapreminski (m3), pregradnih zidova i žbuka površinski (m2).
... A45: * SVI ZIDARSKI RADOVI PREDVIĐENI TROŠKOVNIKOM SU U SKLADU S POPISOM I ODREDBAMA OPRAVDANIH TROŠKOVA .
A47: 1. | B47: Popravci unutarnje žbuke
B48: Stavka obuhvaća sve popravke oštećene, dotrajale ili otpale postojeće unutarnje žbuke špaleta oko otvora u prostorima obuhvaćenih rekonstrukcijom koji su oštećeni prilikom izvođenja radova rušenja ili demontaže fasadnih stavki, instalacija i sl, te popravci otpale žbuke, a nakon ugradnje novih stolarskih stavki. Postojeću podlogu potrebno je prethodno impregnirati i obraditi reparaturnim mortom, a vlažne dijelove premazati hidrofobnim sredstvom. Širine unutarnjih špaleta su cca 20 cm.
B49: Sve kuteve i bridove učvrstiti kutnim profilima.Sve spojeve različitih materijala potrebno je rabicirati rabic pletivom. Kod popravaka postojeće žbuke, za zapunjavanje otvora, reški i šliceva upotrijebiti prikladan materijal što je uključeno u stavku. Obračun za kompletan rad, materijal i radnu skelu.
B50: Stavkom je obuhvaćeno žbukanje zidova od opeke i armiranog betona, produžnim mortom M-25 (1:2:6; 1800kg/m³, HRN U.M2.012), a u sanitarijama cementnom žbukom (1:3; HRN U.M2.010). Žbuku izvesti potpuno ravnu, s ravnim bridovima, oštrim i zaštićenim limenim kutnicima. Stavka uključuje:
B51: - čišćenje reški
B52: - cementni špric 1:1 (HRN U.M2.010)
B53: - gruba žbuka M-5 (HRN U.M2.010)
B54: - fina žbuka istog sastava samo prosijani pijesak
C55: m' | D55: 170 | F55: =D55*E55 -> 0
A57: 2. | B57: Dozidavanje unutarnjeg zida blok opekom
B58: Dozidavanje unutarnjeg zida blok opekom debljine 20 cm i visine do 150 cm u prostoru potkrovlja. Blokovi moraju biti I razreda kakvoće, zidani tankoslojnim mortom M10. Zid od opeke sidriti u nosivu konstrukciju pomoću čeličnih ankera - prema preporukama odabranog proizvođača. Obračun po m3 izvedenog zida
C59: m3 | D59: 3 | F59: =D59*E59 -> 0
A61: 3. | B61: Izrada cementnog estriha
B62: Izvedba lagano armiranog cementnog estriha u padu, zaglađene (2000 kg/m³) - debljine 6,0-4,0 cm iznad ab stropne ploče balkona i terase. Gornju površinu fino zagladiti. Rad obuhvaća dobavu materijala, unutrašnji transport. Podloga se izvodi od sitnozrnog betona C12/15 te se armira PP vlakancima. U stavku je uključena i izrada reške na mjestima sudara sa zidovima, i ostalim vertikalnim elementima konstrukcije s umetkom od ekspandiranog polistirena d=1 cm.
C63: m3 | D63: 3 | F63: =D63*E63 -> 0
A65: 4. | B65: Postava podne keramike i hidroizolacijskog premaza
B66: Dobava i polaganje podnih gres protukliznih keramičkih pločica po izboru projektanta na podove balkona i terasa u fleksibilno građevinsko ljepilo za postavljanje podne keramike. Fuge između pločica debljine 1-3 mm, sukladno tipu pločica. Masa za fugiranje sukladna tipu ljepila, u boji po izboru projektanta. U stavku je uključena i postava sokla od keramike te prethodna izvedba hidroizolacijskog premaza podloge i zidova do visine sokla. Iskazane su stvarne podne površine. Obračun po m2 izvedenih radova.
C67: m2 | D67: 16 | F67: =D67*E67 -> 0
A69: A.III. | B69: ZIDARSKI RADOVI UKUPNO: | E69: € | F69: =SUM(F55:F68) -> 0

Sheet A.IV.izo
A2: TROŠKOVNIK GRAĐEVINSKO ZANATSKIH RADOVA
A3: A. GRAĐEVINSKI RADOVI / A.IV. IZOLATERSKI RADOVI
A4: r.b. | B4: opis stavke | C4: jed. | D4: kol. | E4: jed.cijena | F4: ukupno
A6: A.IV. | B6: IZOLATERSKI RADOVI
A8: OPĆI UVJETI
A10: Sve radove izvođač mora izvoditi prema troškovniku i izvedbenoj dokumentaciji, solidno i stručno, prema pravilima dobrog zanata, Pravilniku o ocjenjivanju sukladnosti, ispravama o sukladnosti i označavanju građevinskih proizvoda (NN 103/08, 147/09, 87/10, 129/11), Pravilniku o tehničkim mjerama i uvjetima za završne radove u zgradarstvu (Sl.list br. 21/90), Tehničkom propisu o racionalnoj upotrebi energije i toplinskoj zaštiti u zgradama (NN 128/15, 70/18, 73/18, 86/18) sa pripadajućim normama, Tehničkom propisu o građevnim proizvodima (NN 35/18) i Tehničkim uvjetima za projektiranje i građenje zgrada - Akustika u građevinarstvu (HRN U.J6.201/89), te svim ostalim tehničkim propisima, priznatim tehničkim pravilima i HR normama.
A11: Izvođač radova mora za sve materijale koje će upotrijebiti za izvedbu izolacije pribaviti odgovarajuće ateste ne starije od 6 mjeseci i dostaviti ih nadzornom inženjeru na uvid. Hidroizolaciju, toplinsku ili zvučnu izolaciju treba izvoditi točno prema specifikaciji radova, uputama, preporukama proizvođača, kao i prema tehničkim uvjetima izvođenja.
A12: Površine na koje se polaže izolacija trebaju biti posve ravne, očišćene od prašine ili drugih nečistoća, dovoljno glatke da izolacija dobro prione uz podlogu. Toplinsku ili zvučnu izolaciju potrebno je izvesti kontinuirano bez fuga kako bi se spriječili toplinski ili zvučni mostovi. Horizontalna ili vertikalna izolacija podova ili zidova treba prilegnuti uz površinu ravno, bez nabora ili mjehura. Sve spojeve PE ili PVC traka ili folija treba spajati samoljepivom trakom širine min 4 cm ili po detalju izolacije. U cijenu također treba uključiti obradu slojeva izolacije i izvedbu holkera oko raznih prodora kroz slojeve izolacije (instalacije), kao i ugradnje završnih profila, putz lajsni i sl.
A13: Drvena građa mora biti izrađena su od suhog drveta zaštićenog pokrovnim fungicidnim premazima koji štite drvo od vanjskih utjecaja, a sadržavaju antifungicidna i antiinsekticidna svojstva.
A14: U sklopu slojeva izolacije uz sve bočne vertikalne ili kose plohe treba obavezno izvesti holkere, visine min 15 cm bez posebne naplate. Tako izveden prelazni detalj sa svim slojevima izolacije treba završno zaštititi. Ukoliko nije posebno predviđen detalj holker treba izvesti cem. mortom 1:1 M-10 d= 3-4-cm po HRN – u U.M2.010, armiran pocinč. rabic. mrežicom, dilatiran svaka 2 cm ili po detalju izvedbe izolacije. Nakon izvedbe svakog sloja izolacije nadzorni organ treba izvršiti pregled, a tek nakon pozitivnog mišljenja i upisa u građevinski dnevnik može se nastaviti sa radom.
A15: Skladištenje materijala na gradilištu mora biti stručno kako bi se isključila bilo kakva mogućnost propadanja. Nepravilno i nekvalitetno izvedene radove izvođač mora na svoj trošak ukloniti i izvesti pravilno.
A16: Izvođač će pristupiti izvedbi tek nakon što projektant potpisom potvrdi tehnološku razradu svih detalja. Izrada rješenja neće se posebno naplatiti. Izvođač može predložiti druge proizvode za izolaciju od onih opisanih troškovnikom uz uvjet istih svojstava i kvalitete. Izvođač je dužan sve izvoditi prema uputama proizvođača, isporučitelja materijala te ovjerenih detalja.
A17: Obračun se vrši po m² gotove površine. U cijenu stavke uključena je tehnološka razrada svih detalja, priprema podloga, čišćenje zaprljanih podloga vodom pod tlakom i sredstvima / impregnacijama koja propisuje proizvođač, dobava i ugradnja svih opisanih materijala i elemenata, alat i mehanizacija, troškovi radne snage za kompletan rad propisan troškovnikom, troškovi vertikalnog i horizontalnog prijenosa, postava i skidanje potrebne radne skele sa zaštitnom tkaninom, troškovi deponiranja materijala i alata te čišćenje po završetku rada, odvoz i zbrinjavanje smeća, troškove popravke nastalih zbog nepažljive izvedbe ili učinjene štete drugim izvođačima, troškovi zaštite na radu, troškovi atestiranja.
A19: HIDROIZOLACIJA Sve hidroizolaterske radove treba izvesti solidno i stručno držeći se projektne dokumentacije, propisa, opisa iz troškovnika, uputama proizvođača i pravilima dobrog zanata. Prije početka radova izvođač mora ustanoviti kvalitetu podloge na koju se izvodi izolacija i ako nije pogodna za rad mora o tome izvijestiti naručitelja radova kako bi se podloga na vrijeme popravila i pripremila za izvođenje izolacije.
A20: Sav materijal za izolaciju treba biti prvorazredne kvalitete, te odgovarati tekućim propisima i normativima. Izolacijsku ljepenku i ostale vrste izolacijskih traka i ploča treba rezati ravno i pravokutno. Zaderani i krpani komadi ne smiju se ugrađivati. Svi preklopi moraju biti najmanje 10 cm široki i lijepljeni varenjem. Kod polaganja dvaju ili više slojeva izolacijskih traka ili ploča preklopi ne smiju ležati jedan na drugom, već moraju biti pomaknuti.
A21: Kod hidroizolacije zidova ljepenka treba na svaku stranu zida imati prihvat širine od 10 cm, koji treba spojiti s horizontalnom izolacijom podova. Površine na koje se polaže izolacija, trebaju biti posve ravne, suhe, očišćene od prašine i nečistoće i dovoljno glatke kako bi izolacija dobro prionula. Izolacija treba prilegnuti na površinu ravno, bez nabora i mjehura.
... A37: * SVI IZOLATERSKI RADOVI PREDVIĐENI TROŠKOVNIKOM SU U SKLADU S POPISOM I ODREDBAMA OPRAVDANIH TROŠKOVA.
A40: 1. | B40: Toplinska i hidroizolacija kosog krova i krovnih kućica
B41: Dobava materijala i izvedba toplinske izolacije kosog krova i krovnih kućica izolacijom od mineralne vune d=20,0 cm s λ ≤ 0,035 W/mK. Stavka uključuje dobavu materijala i izvedbu paropropusne i vodonepropusne hidroizolacije iznad toplinske izolacije, te drvenih grednika dim. 10 x 20 cm na razmacima od oko 80 cm. Drveni grednici se preko novih OSB ploča pričvršćuju na postojeću konstrukciju krova. Stavka uključuje OSB ploče, debljine 1,8 cm i parnu kočnicu koja se postavi između OSB ploča i toplinske izolacije. Završni pokrov limom te pripadajuće letvanje su obrađeni u Limarskim radovima B.I. dok je predmet ove stavke i izvedba dvostrukog letvanja (3x5cm i 5x8 cm) te postava glinenog kontinentalnog crijepa, tipa i boje prema izboru projektanta. Skidanje postojećih slojeva krova do konstrukcije je obrađeno u Rušenjima i demontažama. Obaveza izvođača je da nakon uvida u stanje postojeće konstrukcije napravi statičku provjeru za novo opterećenje krova. Dodatna pojačanja konstrukcije treba izvesti u dogovoru s nadzornim inženjerom i projektantom konstrukcije. Izvedba prema detaljima D9, D10, D 11, D 12 i D13.
B42: glineni crijep | C42: m2 | D42: 215 | F42: =D42*E42 -> 0
B43: drvene letve 3x5 cm | C43: m3 | D43: 1 | F43: =D43*E43 -> 0
B44: drvene letve 5x8 cm | C44: m3 | D44: 1.5 | F44: =D44*E44 -> 0
B45: paropropusna i vodonepropusna hidroizolacija | C45: m2 | D45: 250 | F45: =D45*E45 -> 0
B46: toplinska izolacija (MW) d=20,0 cm | C46: m2 | D46: 230 | F46: =D46*E46 -> 0
B47: drveni grednici 10x20cm, na razmacima od cca. 80 cm | C47: m3 | D47: 7 | F47: =D47*E47 -> 0
B48: parna kočnica | C48: m2 | D48: 230 | F48: =D48*E48 -> 0
B49: OSB ploče na krovnoj plohi d=1,8 cm | C49: m2 | D49: 230 | F49: =D49*E49 -> 0
A51: 2. | B51: Toplinska izolacija na neprohodnim ravnim krovovima - ulazna nadstrešnica
B52: Dobava materijala i izvedba toplinske izolacije na neprohodnim ravnim krovovima - ulazna nadstrešnica od mineralne vune d=4,0 cm s λ ≤ 0,036 W/mK kao prekid toplinskog mosta, slobodnom postavom na betonsku konzolnu ploču.
B53: toplinska izolacija (MW) d=4,0 cm | C53: m2 | D53: 2 | F53: =D53*E53 -> 0
A55: 3. | B55: Toplinska izolacija grijanog prostora prema negrijanoj terasi
B56: Dobava materijala i izvedba toplinske izolacije stropa grijanog prostora prema negrijanoj terasi, izolacijom od mineralne vune d=16 cm s λ ≤ 0,035 W/mK. Stavka uključuje ugradnju gipskartonske ploče debljine 1,2 cm na pocinčanoj potkonstrukciji.
B57: Obračun po m2 površine poda, sve komplet.
B58: toplinska izolacija (MW) d=16,0 cm | C58: m2 | D58: 4 | F58: =E58*D58 -> 0
B59: parna brana | C59: m2 | D59: 4 | F59: =E59*D59 -> 0
B60: gipskartonske ploče, 1,2 cm | C60: m2 | D60: 4 | F60: =E60*D60 -> 0
A62: 4. | B62: Toplinska izolacija grijanog prostora prema negrijanom podrumu
B63: Dobava materijala i izvedba toplinske izolacije podgleda stropa negrijanog prostora podruma prema grijanom prostoru u prizemlju, izolacijom od mineralne vune d=16,0 cm s λ ≤ 0,035 W/mK učvršćenjem tipskim pričvrsnicama na drvene štafle sitnorebričastog armiranobetonskog stropa. Stavka uključuje dobavu materijala i izvedbu toplinske izolacije sa svim pričvrsnim sredstvima prema uputi proizvođača. Sve izvesti prema detalju D6.
B64: Obračun po m2 površine stropa, sve komplet.
B65: toplinska izolacija (MW) d=16,0 cm | C65: m2 | D65: 12 | F65: =E65*D65 -> 0
...

Sheet B.I.lim
A2: TROŠKOVNIK GRAĐEVINSKO OBRTNIČKIH RADOVA
A3: B. OBRTNIČKI RADOVI / B.I. LIMARSKI RADOVI
A4: r.b. | B4: opis stavke | C4: jed. | D4: kol. | E4: jed.cijena | F4: ukupno
A6: B. | B6: OBRTNIČKI RADOVI
A8: B.I. | B8: LIMARSKI RADOVI
A10: OPĆI UVJETI
A12: Sve radove izvođač mora izvoditi prema troškovniku i izvedbenoj projektnoj dokumentaciji, solidno i stručno, prema pravilima dobrog zanata, Pravilniku o ocjenjivanju sukladnosti, ispravama o sukladnosti i označavanju građevinskih proizvoda (NN 103/08, 147/09, 87/10, 129/11), Pravilniku o tehničkim mjerama i uvjetima za završne radove u zgradarstvu (Sl.list br. 21/90), Tehničkom propisu o racionalnoj upotrebi energije i toplinskoj zaštiti u zgradama ( 128/15, 70/18, 73/18, 86/18) sa pripadajućim normama, Tehničkom propisu o građevnim proizvodima (NN 35/18) i Tehničkim uvjetima za izvođenje limarskih radova (HRN U.N9.055.), te svim ostalim tehničkim propisima, priznatim tehničkim pravilima i HR normama, a osobito:
A13: HRN C.B4.081, pocinčani lim HRN C.C4.020, 025, 030, 051, 060, 120, 150, aluminijski lim HRN C.D4.020, bakreni lim
A14: Ukoliko ne postoje adekvatni standardi za materijale koji se ugrađuju, obavezno je pribaviti odgovarajući atest kao dokaz kvalitete.
A15: Izvođač je dužan prije početka radova predočiti projektantu detalje izvedbe i savijanja limova. Tek po odobrenju i nakon ovjere istih od strane projektanta izvođač može pristupiti izvedbi radova. Izvođač je dužan prije početka radova provjeriti sve građevinske elemente na koje, ili za koje se pričvršćuje limarija i pismeno dostaviti naručitelju svoje primjedbe u vezi eventualnih nedostataka posebno u slučaju: neodgovarajućeg izbora projektiranog materijala i loše riješenog načina vezivanja limarije za građevinske radove. Izrada rješenja neće se posebno platiti već predstavlja trošak i obvezu izvođača. Prilikom izvođenja limarije izvođač se mora striktno pridržavati usvojenih i od strane projektanta ovjerenih detalja. Izvođač će pristupiti izvedbi tek nakon što projektant potpisom potvrdi radioničke nacrte i tehnološku razradu svih detalja.
A16: Dijelovi različitog materijala ne smiju se dodirivati jer bi uslijed toga moglo doći do korozije. Elementi od čelika za pričvršćivanje cinčanog ili pocinčanog lima moraju se pocinčati, ako u opisu radova nije predviđena neka druga zaštita (postavljanje podmetača od olova ili plastike otpornih na kiseline ili lužine). Za bakreni lim treba primijeniti učvršćivanje od bakra ili bakrenog čelika.
A17: Drvena građa mora biti izrađena su od suhog drveta zaštićenog pokrovnim fungicidnim premazima koji štite drvo od vanjskih utjecaja, a sadržavaju antifungicidna i antiinsekticidna svojstva.
A18: Sastav i učvršćenja moraju biti tako izvedeni da elementi pri toplotnim promjenama mogu nesmetano dilatirati, a da pri tom ostanu nepropusni. Moraju se osigurati od oštećenja koje može izazvati vjetar i sl. Ispod lima koji se postavlja na beton, drvo ili žbuku treba postaviti sloj bitumenske ljepenke, čija su dobava i postava uključene u jediničnu cijenu ako u stavci nije opisano drugačije. Nakon obrade, može se ugraditi samo neoštećeni lim.
A19: Za elemente za učvršćivanje (kuke, zakovice, jahači, čavli, vijci i sl.) treba primijeniti: za čelični lim - čelična spojna sredstva, za pocinčani i olovni lim - dobro pocinčana spojna sredstva, za bakreni lim - bakrena spojna sredstva, za alu lim - alu ili galvanizirana Čn spojna sredstva.
A20: Sve vidljive spojeve lima i betonskih ili ožbukanih ploha pročelja treba brtviti po cijeloj dužini spoja trajno elastičnim (plastičnim) bezbojnim kitom. Sve spojeve lima treba obvezno izvesti nepropusno. Plohe izvedene limom moraju biti izvedene pravilno i u ravnini, po nagibima odvodnje i kosinama definiranim u projektu.
A21: Cijenom izvedbe radova treba obvezno uključiti sve materijale koji se ugrađuju i koriste (osnovne i pomoćne materijale), sav potreban rad (osnovni i pomoćni) na izvedbi radova do potpune gotovosti i funkcionalnosti istih, sve transporte i prijenose do i na gradilištu sve do mjesta ugradnje, sva potrebna skladištenja i zaštite, sav alat i građevinske strojeve, čišćenje tokom rada, odvoz i zbrinjavanje smeća, završno čišćenje prije primopredaje radova, nadoknadu eventualne štete nastale iz nepažnje na svojim ili tuđim radovima, sve potrebne zaštitne konstrukcije i skele, kao i sve drugo predviđeno mjerama zaštite na radu i pravilima struke. U cijeni treba također uključiti izvedbu i obradu raznih detalja limarije kod spojeva, prijelaza, lomova i sudara ploha, završetaka limarije i drugo, sve obvezno usklađeno sa drugim različitim materijalima i radovima uz limariju, do potpune gotovosti i funkcionalnosti.
A22: Jedinična cijena uključuje uzimanje mjera na gradilištu i definiranje ugradbenih dimenzija, tehnološku razradu svih detalja, pripremu podloga, izradu radioničkih nacrta, sav spojni materijal, sve posredne i neposredne troškove za rad, materijal, sva manja potrebna usijecanja utora nužna za ugradnju i savijanje lima i izvedbu detalja, kao i sva sitnija usijecanja ploha te potrebne popravke i zapunjavanja nastalih međuprostora i pukotina cem. mortom.
A23: * SVI LIMARSKI RADOVI PREDVIĐENI TROŠKOVNIKOM SU U SKLADU S POPISOM I ODREDBAMA OPRAVDANIH TROŠKOVA.
A25: 1. | B25: Okapnica na parapetima prozora
B26: Dobava materijala, izrada i montaža limenih okapnica na parapetima prozora, od aluminijskog lima d=0,8 mm plastificiranima u bijeloj boji, na kukama od plosnog čelika. Prosječna razvijena širina lima je 40 cm. Boja lima prema ton karti proizvođača i odabiru projektanta. Izvedba prema detaljima D1 - D6. Obračun po m' limene okapnice.
C27: m' | D27: 54 | F27: =D27*E27 -> 0
A29: 2. | B29: Okapnica na zabatnom zidu
B30: Dobava materijala, izrada i montaža limenih okapnica na zabatnom zidu, od aluminijskog lima d=0,8 mm, na kukama od plosnog čelika. Prosječna razvijena širina lima je 30 cm. Limena okapnica se montira na drvenu potkonsktrukciju ispod pokrova od crijepa. Boja lima prema ton karti proizvođača i odabiru projektanta. Obračun po m' limene okapnice.
C31: m' | D31: 36 | F31: =D31*E31 -> 0
A33: 3. | B33: Okapnica na vijencu kosog krova
B34: Dobava materijala, izrada i montaža limenih okapnica na vijencu kosog krova, od aluminijskog lima d=0,8 mm. Prosječna razvijena širina lima je 15 cm. Limena okapnica je montira na drvene grednike ispod hidroizolacijske folije. Boja lima prema ton karti proizvođača i odabiru projektanta. Stavka uključuje i postavu mrežice za kukce duljine 25 cm. Sve izvesti prema detalju 9. Izvedba prema detaljima D8. Obračun po m' limene okapnice.
C35: m' | D35: 30 | F35: =D35*E35 -> 0
A37: 4. | B37: Limeni opšav ruba balkona i terasa
B38: Dobava materijala, izrada i montaža limenog opšava na rubu balkona i terasa od aluminijskog lima d=1,0 mm, prosječne razvijene širine lima 20 cm, lim se polaže u sloj morta ispod keramičke obloge poda. Boja lima prema ton karti proizvođača i odabiru projektanta. Stavka uključuje sva pričvrsna sredstva. Obračun po m1 opšava.
B39: alu. lim d=1,0mm, razvijena širina 20 cm | C39: m' | D39: 25 | F39: =D39*E39 -> 0
A41: 5. | B41: Limeni opšav krovne uvale
B42: Dobava materijala, izrada i montaža limenog opšava krovne uvale od aluminijskog lima d=1,0 mm, prosječne razvijene širine lima 50 cm, lim se učvršćuje na drvene letve ispod pokrova od crijepa. Stavka uključuje sva pričvrsna sredstva. Obračun po m1 opšava.
B43: alu. lim d=1,0mm, razvijena širina 20 cm | C43: m' | D43: 8 | F43: =D43*E43 -> 0
A45: 6. | B45: Limeni opšav spoja krova i zida
B46: Dobava materijala, izrada i montaža limenog opšava spoja kosog krova i zida kod krovnih kućica i spoja zgrade s krovištem susjedne zgrade od aluminijskog lima d=1,0 mm, prosječne razvijene širine lima 30 cm, lim se učvršćuje na drvene letve ispod pokrova od crijepa. Boja lima prema ton karti proizvođača i odabiru projektanta. Sve izvesti prema detalju 8 i 13. Stavka uključuje sva pričvrsna sredstva i sloj bitumenizirane ljepenke. Obračun po m1 opšava.
B47: alu. lim d=1,0mm, razvijena širina 30 cm | C47: m' | D47: 27 | F47: =D47*E47 -> 0
A49: 7. | B49: Limeni opšav ruba krovne kućice
B50: Dobava materijala, izrada i montaža limenog opšava ruba krovne kućice od aluminijskog lima d=1,0 mm, prosječne razvijene širine lima 40 cm, lim se učvršćuje na daščanu oplatu. Boja lima prema ton karti proizvođača i odabiru projektanta. Sve izvesti prema detalju 11 i 13. Stavka uključuje sva pričvrsna sredstva i sloj bitumenenske membrane. Obračun po m1 opšava.
B51: alu. lim d=1,0mm, razvijena širina 40 cm | C51: m' | D51: 17 | F51: =D51*E51 -> 0
A53: 8. | B53: Nova limena obloga krova od falcanog aluminijskog lima iznad krovnih kućica i nadstrešnice
...

Sheet B.II.1.PVC
A2: TROŠKOVNIK GRAĐEVINSKO OBRTNIČKIH RADOVA
A3: B. OBRTNIČKI RADOVI / B.II.1. VANJSKA PVC STOLARIJA
A4: r.b. | B4: opis stavke | C4: jed. | D4: kol. | E4: jed.cijena | F4: ukupno
A6: B.II.1. | B6: VANJSKA PVC STOLARIJA
B8: OPĆI UVJETI
B10: Sve radove izvođač mora izvoditi prema troškovniku i izvedbenoj projektnoj dokumentaciji, solidno i stručno, prema pravilima dobrog zanata i mjerama uzetima na licu mjesta, Pravilniku o ocjenjivanju sukladnosti, ispravama o sukladnosti i označavanju građevinskih proizvoda (NN 103/08, 147/09, 87/10, 129/11), Pravilniku o tehničkim mjerama i uvjetima za završne radove u zgradarstvu (Sl.list br. 21/90), Tehničkom propisu o racionalnoj upotrebi energije i toplinskoj zaštiti u zgradama (NN 128/15, 70/18, 73/18, 86/18) sa pripadajućim normama, Tehničkom propisu o građevnim proizvodima (NN 35/18), prema Tehničkim propisima za prozore i vrata (NN 69/06) sa pripadajućim noramama i ostalim normama prema Odluci o popisu normi bitnih za primjenu Tehničkog propisa za prozore i vrata, te svim ostalim tehničkim propisima, priznatim tehničkim pravilima i HR normama, a osobito:
B12: HRN EN 14351-1:2006, prozori i vrata - norma za proizvod, izvedbene značajke HRN EN 12207:2001, prozori i vrata - propusnost zraka HRN EN 12208:2001, prozori i vrata - vodonepropusnost HRN EN 12210:2001+AC:2005, prozori i vrata - otpornost na opterećenje vjetrom HRN EN ISO 140-3, akustika - mjerenje razine zvuka u zgradama i elementima zgrada HRN EN ISO 717-1, akustika - određivanje razine zvuka u zgradama HRN EN 410:1998, staklo u graditeljstvu - određivanje svjetlosnih i sunčanih značajka ostakljenja HRN EN 572-9:2005, staklo u graditeljstvu - proizvodi od osnovnog natrij-kalcij-silikatnog stakla HRN D.E1.012, vanjska stolarija HRN D.E8.193. i 235., vodonepropusnost i hermetičnost
B14: Ukoliko ne postoje adekvatni standardi za materijale koji se ugrađuju, obavezno je pribaviti odgovarajući atest kao dokaz kvalitete.
B15: Izvođač radova obavezan je izraditi i ugraditi aluminijske elemente u već provjerenim i certificiranim sustavima te se od njega očekuje visoka kvaliteta izvedbe. Prije početka radova Izvođač je obvezan dostaviti na uvid glavnom projektantu uzorke profila i okova na odobrenje, prihvatit će se isključivo kvalitetni profili i okovi. Nakon prihvaćanja uzoraka izvođač je obvezan nacrtati karakteristične presjeke i detalje ugradnje te i njih dostaviti na odobrenje. Tek nakon što dobije odobrenje glavnog projektanta na uzorke, detalje i presjeke, Izvođač smije započeti s radovima. Izvođač mora dati jamstvo u minimalnom trajanju jamstvenog roka na aluminijske profile, brtve i završnu obradu (plastifikacija ili eloksaža) te na pokretne dijelove (okov). Jamstvo na završnu obradu uključuje ljuštenje boje ili gubitak sjaja, a plastifikacija mora biti debljine najmanje 60 µm. Površinska zaštita mora biti izvršena sukladno Qualicoat i Qualianod smjernicama.
B17: Prije pristupanju izvođenju radova izvoditelj je dužan izvršiti detaljan pregled svih stolarskih elemenata, prozora i vrata koji se mijenjaju. Stolarski elementi ili njihovi dijelovi, kao i pripadajući okov, koji su oštećeni, moraju se zamijeniti novima. Pri izradi novog elementa, u jediničnu cijenu uračunat je gotov stolarski element sa pripadajućim okovom i ugradnjom na građevinu.
B19: Radovi uključuju izradu, dobavu i montažu do potpune gotovosti prozora ili vrata. Brtvljenje i spajanje prema sistemskim rješenjima propisanim od proizvođača sistema. Sav potreban okov za otvaranje potrebno je da je izrađen od INOX-a ili plastificiran u boji profila (prema rješenju projektanata). Odabrani okov prilagoditi težini i geometriji krila, tako da nesmetano zadovoljava funkciju otvaranja (otklopni, zaokretni ili zaokretno otklopni). U cijenu stavaka uključeno je i staklo.
B21: Sve mjere obavezno je provjeriti na licu mjesta prije izrade stolarije.
B23: Prozori i vrata ugrađuju se u građevinski pripremljeni i obrađeni otvor u AB zidu ili zidu od blok opeka pomoću vijaka primjerenih za ovakvu vrstu montaže. U cijenu je uključen sav potreban rubni opšav (vanjski i unutarnji), vanjska hidroizolacija - paropropusna i vodonepropusna folija, unutarnja - paronepropusna folija (parna brana), toplinska izolacija te sav pričvrsni pribor. Kod ugradnje stolarije potrebno je obraditi i toplinski izolirati špalete otvora sa slojem toplinske izolacije minimalno 4 cm (obrađeno u Završnim zidarsko fasaderskim radovima).
B25: U cijenu treba biti uključena i izrada unutarnje klupčice, na potkonstrukciji, prema RAL ton karti-prema odabiru projektanta, osim ako stavkom nije opisano drugačije.
B27: Zbog specifičnosti zadatka - sanacija - sve stavke opisane su zidarskom mjerom. Zidarska mjera je razmak konstruktivnih elemenata. Modularna mjera je razmak modularnih ravnina koji je manji od zidarske mjere. Stolarska mjera je stvarna vanjska mjera stolarskog elementa koja treba biti manja od modularne mjere. Svjetla stolarska mjera koristi se kod vrata i označava čisti razmak između dovratnika, odnosno poda i nadvratnika. Razlika između zidarske i modularne mjere kod mokre gradnje treba biti 1 – 2 cm, a kod montažne može biti i 0,5. Razlika između modularne i stolarske mjere treba biti od 0,3 do 1 cm. Stvake su opisane zidarskim (građevinskim) mjerama.
B29: Zaokretna vrata ili prozorsko krilo je lijevo ako je okovano s lijeve strane, odnosno ako se otvara u smjeru negativne rotacije (kazaljke na satu). Stolarski elementi se izrađuju prema shemama i detaljima, te u dogovoru s projektantom i nadzornim inženjerom, a označavaju brojem troškovničke stavke.
... B35: Jedinična cijena uključuje uzimanje mjera na gradilištu i definiranje ugradbenih dimenzija, tehnološku razradu svih detalja, izradu radioničkih nacrta, sav spojni materijal, sidrene ploče, mort za podlijevanje ležaja, zaštitu od korozije, postavu i skidanje radne skele, striktnu primjenu mjera zaštite od požara, sve posredne i neposredne troškove za rad, materijal, alat i građevinske strojeve, sve transporte, čišćenje tokom rada, odvoz i zbrinjavanje smeća, završno čišćenje prije primopredaje radova, nadoknadu eventualne štete nastale iz nepažnje na svojim ili tuđim radovima.
A37: 1. | B37: Stijena grijanog prostora
B38: Izrada, doprema i ugradnja vanjskih PVC stijena, od tipskih PVC profila prema shemama koje su sastavni dio ove stavke. Ostakljenje trostrukim IZO staklom 33,2+15A+4+15A+44,2 – s vanjske strane laminirano, ispuna između stakala argonom, s proračunskim dokazom koeficijenta prolaska topline stakla jednakog ili nižeg od 0,60 W/m²K i sa proračunskim dokazom koeficijenta prolaska topline prozora jednakog ili nižeg od 0,83 W/m²K - prema projektu racionalne uporabe energije i toplinske zaštite. U stavku je uključena obrada spoja na susjedne plohe zida i druge elemente u sklopu obloge pročelja, kao i sva potrebna prilagođenja i podešavanja kao i izrada radioničke dokumentacije koja se daje na uvid i odobrenje osobi koja vrši nadzor na objektu. Uz dokumentaciju potrebno je dostaviti uzorak profila i ostakljenja koji također treba odobriti nadzorna osoba.
B39: Prostor između zidanog dijela i profila izveden prema normama struke. Svi navedeni spojevi moraju imati vrhunsku hidroizolaciju i termoizolaciju međuprostora kako ne bi došlo do prodora vode, zraka ili prolaza topline. S vanjske strane dodatno izvesti silikoniranje kvalitetnim silikonom otpornim na atmosferske utjecaje i u boji profila.
B40: Stavka uključuje vanjske aluminijske žaluzine boje prema odabiru projektanta, ukoliko u shemama nije drugačije definirano.
B41: Ostale izvedbene detalje dogovoriti s projektantom. U cijenu stavke uračunato je uzimanje mjera na licu mjesta, dobava i ugradnja. Obračun prema kompletno izvedenim i montiranim prozorima.
B42: Bilo kakva ugradnja prije odobrenja uzorka i dokumentacije, nije dozvoljena. Konačan odabir boje prema izboru glavnog projektanta.
B43: Vanjska alu klupčica opisana je u limarskim radovima.
B44: Prije izrade sve mjere kontolirati u naravi. Minimalne visine parapeta prozora nakon ugradnje nove stolarije trebaju biti 100 cm.
B45: Izvesti prema shemi stolarije.
B47: ST.02 - Trokrilni zaokretno otklopni prozor. u građevinskom otvoru 210 x 175 cm. | C47: kom | D47: 5 | F47: =D47*E47 -> 0
B48: ST.04 - Dvokrilni zaokretno otklopni prozor u građevinskom otvoru 120 x 130 cm | C48: kom | D48: 1 | F48: =D48*E48 -> 0
B49: ST.05 - Jednokrilni zaokretno otklopni prozor. u građevinskom otvoru 60 x 160 cm | C49: kom | D49: 2 | F49: =D49*E49 -> 0
B50: ST.06 - Dvokrilni zaokretno otklopni prozor. u građevinskom otvoru 110 x 160 cm | C50: kom | D50: 1 | F50: =D50*E50 -> 0
B51: ST.07 - Jednokrilni zaokretno otklopni prozor. u građevinskom otvoru 40 x 160 cm | C51: kom | D51: 2 | F51: =D51*E51 -> 0
B52: ST.08 - Jednokrilni zaokretno otklopni prozor u građevinskom otvoru 60 x 150 cm | C52: kom | D52: 4 | F52: =D52*E52 -> 0
B53: ST.09 - Jednokrilni zaokretno otklopni prozor u građevinskom otvoru 50 x 150 cm | C53: kom | D53: 4 | F53: =D53*E53 -> 0
B54: ST.10 -Jednokrilna zaokretno otklopna vrata u građevinskom otvoru 90 x 240 cm | C54: kom | D54: 2 | F54: =D54*E54 -> 0
B55: ST.11 - Jednokrilni ovalni otklopni prozor u građevinskom otvoru 120 x 85 cm | C55: kom | D55: 1 | F55: =D55*E55 -> 0
B56: ST.12 - Jednokrilni zaokretno otklopni prozor u građevinskom otvoru 50 x 160 cm | C56: kom | D56: 1 | F56: =D56*E56 -> 0
B57: ST.13 - Dvokrilni zaokretno otklopni prozor. u građevinskom otvoru 120 x 150 cm | C57: kom | D57: 2 | F57: =D57*E57 -> 0
B58: ST.14 - Jednokrilna zaokretno otklopna vrata u građevinskom otvoru 100 x 250 cm | C58: kom | D58: 1 | F58: =D58*E58 -> 0
... B63: ST.19 - Dvokrilni zaokretno otklopni prozor u građevinskom otvoru 200 x 135 cm | C63: kom | D63: 1 | F63: =D63*E63 -> 0
A65: B.II.1. | B65: VANJSKA PVC STOLARIJA UKUPNO: | E65: € | F65: =SUM(F47:F64) -> 0

Sheet B.II.2.ALU
A2: TROŠKOVNIK GRAĐEVINSKO OBRTNIČKIH RADOVA
A3: B. OBRTNIČKI RADOVI / B.II.2. VANJSKA ALUMINIJSKA STOLARIJA
A4: r.b. | B4: opis stavke | C4: jed. | D4: kol. | E4: jed.cijena | F4: ukupno
A6: B.II.2. | B6: VANJSKA ALUMINIJSKA STOLARIJA
B8: OPĆI UVJETI
B10: Sve radove izvođač mora izvoditi prema troškovniku i izvedbenoj projektnoj dokumentaciji, solidno i stručno, prema pravilima dobrog zanata i mjerama uzetima na licu mjesta, Pravilniku o ocjenjivanju sukladnosti, ispravama o sukladnosti i označavanju građevinskih proizvoda (NN 103/08, 147/09, 87/10, 129/11), Pravilniku o tehničkim mjerama i uvjetima za završne radove u zgradarstvu (Sl.list br. 21/90), Tehničkom propisu o racionalnoj upotrebi energije i toplinskoj zaštiti u zgradama (NN 128/15, 70/18, 73/18, 86/18) sa pripadajućim normama, Tehničkom propisu o građevnim proizvodima (NN 35/18), prema Tehničkim propisima za prozore i vrata (NN 69/06) sa pripadajućim noramama i ostalim normama prema Odluci o popisu normi bitnih za primjenu Tehničkog propisa za prozore i vrata, te svim ostalim tehničkim propisima, priznatim tehničkim pravilima i HR normama, a osobito:
B12: HRN EN 14351-1:2006, prozori i vrata - norma za proizvod, izvedbene značajke HRN EN 12207:2001, prozori i vrata - propusnost zraka HRN EN 12208:2001, prozori i vrata - vodonepropusnost HRN EN 12210:2001+AC:2005, prozori i vrata - otpornost na opterećenje vjetrom HRN EN ISO 140-3, akustika - mjerenje razine zvuka u zgradama i elementima zgrada HRN EN ISO 717-1, akustika - određivanje razine zvuka u zgradama HRN EN 410:1998, staklo u graditeljstvu - određivanje svjetlosnih i sunčanih značajka ostakljenja HRN EN 572-9:2005, staklo u graditeljstvu - proizvodi od osnovnog natrij-kalcij-silikatnog stakla HRN D.E1.012, vanjska stolarija HRN D.E8.193. i 235., vodonepropusnost i hermetičnost
B14: Ukoliko ne postoje adekvatni standardi za materijale koji se ugrađuju, obavezno je pribaviti odgovarajući atest kao dokaz kvalitete.
