Workbook

Sheet REKAPITULACIJA_go
A1: INVESTITOR: | B1: EMPWR d.o.o. Industrijska ulica 15, 35400 Nova Gradiška OIB: 60396692377
A2: NAZIV GRAĐEVINE: | B2: REKONSTRUKCIJA, DOGRADNJA I IZGRADNJA TVORNICE ENERGETSKIH PLOČICA EMPWR, Nova Gradiška
A3: LOKACIJA : | B3: k.č.br. 874/2 k.o. Prvča
A4: ADRESA : | B4: Industrijska ulica 15 , 35 400 Nova Gradiška
A5: OZNAKA PROJEKTA EMPWR: | B5: VELEBIT 2
A6: FAZA PROJEKTA: | B6: GLAVNI PROJEKT
A7: STRUKOVNA ODREDNICA: | B7: GRAĐEVINSKO-OBRTNIČKI RADOVI
A8: VRSTA PROJEKTA: | B8: TROŠKOVNIK | C8: T1
B9: TROŠKOVNIK Troškovnik je izrađen za postupak izbora izvođača u fazi izrade glavnog projekta, te su moguća odstupanja (±20%) u opisu i količinama u odnosu na kasnije faze projektne dokumentacije.
A10: DATUM: | B10: listopad 2025.
A11: REVIZIJA: | B11: R0 | D11: rekonstrukcija kata (istraživanje i razvoj (R&D) i multipakiranje) | E11: proširenje parkirališta (zapad) nadstrešnica za bicikle | F11: rekonstrukcija restorana (prizemlje) rekonstrukcija garderoba i ureda (kat) | G11: skladište tekućih sirovina (tankovi) nadstrešnica pretakanja tekućina | H11: skladište poluproizvoda (istok) mokro miješanje 2 (istok) rekonstrukcija dezibarijera (jug i sjever) rekonstrukcija vjetrobrana (jug) | I11: uredska zgrada i spojni mostovi | J11: skladište A (zapad 3) paletni most paletno skladište vanjski prostor za pušače zapadne prometnice | K11: izmiještanje malog WM 1 u mokro miješanje 2 nova sortirnica (Tomra) i povećanje radionice rekonstrukcija skladišta poluproizvoda (WM) | L11: rekonstrukcija zone automatske paletizacije rekonstrukcija kata R&D linije, uredi | M11: skladište B1 (zapad4)
A12: REKAPITULACIJA GRAĐEVINSKO-OBRTNIČKI RADOVI | B12: projekt VELEBIT 2 faznost: REKONSTRUKCIJA, DOGRADNJA I IZGRADNJA TVORNICE ENERGETSKIH PLOČICA EMPWR 2025. | C12: UKUPNO | D12: FAZA I. | E12: FAZA II. | F12: FAZA III. | G12: FAZA IV. | H12: FAZA V. | I12: FAZA VI. | J12: FAZA VII. | K12: FAZA VIII. | L12: FAZA IX. | M12: FAZA X.
A13: poglavlje: | B13: stavka: | C13: cijena bez pdv-a (EUR): | D13: cijena bez pdv-a (EUR): | E13: cijena bez pdv-a (EUR): | F13: cijena bez pdv-a (EUR): | G13: cijena bez pdv-a (EUR): | H13: cijena bez pdv-a (EUR): | I13: cijena bez pdv-a (EUR): | J13: cijena bez pdv-a (EUR): | K13: cijena bez pdv-a (EUR): | L13: cijena bez pdv-a (EUR): | M13: cijena bez pdv-a (EUR):
A14: =#REF! -> #REF! | B14: =#REF! -> #REF! | C14: =SUM(D14:M14) -> #REF! | D14: =#REF! -> #REF! | E14: =#REF! -> #REF! | F14: =#REF! -> #REF! | G14: =#REF! -> #REF! | H14: =#REF! -> #REF! | I14: =#REF! -> #REF! | J14: =#REF! -> #REF! | K14: =#REF! -> #REF! | ... M14: =#REF! -> #REF!
A15: =#REF! -> #REF! | B15: =#REF! -> #REF! | C15: =SUM(D15:M15) -> #REF! | D15: =#REF! -> #REF! | E15: =#REF! -> #REF! | F15: =#REF! -> #REF! | G15: =#REF! -> #REF! | H15: =#REF! -> #REF! | I15: =#REF! -> #REF! | J15: =#REF! -> #REF! | K15: =#REF! -> #REF! | ... M15: =#REF! -> #REF!
A16: =#REF! -> #REF! | B16: =#REF! -> #REF! | C16: =SUM(D16:M16) -> #REF! | D16: =#REF! -> #REF! | E16: =#REF! -> #REF! | F16: =#REF! -> #REF! | G16: =#REF! -> #REF! | H16: =#REF! -> #REF! | I16: =#REF! -> #REF! | J16: =#REF! -> #REF! | K16: =#REF! -> #REF! | ... M16: =#REF! -> #REF!
A17: =#REF! -> #REF! | B17: =#REF! -> #REF! | C17: =SUM(D17:M17) -> #REF! | D17: =#REF! -> #REF! | E17: =#REF! -> #REF! | F17: =#REF! -> #REF! | G17: =#REF! -> #REF! | H17: =#REF! -> #REF! | I17: =#REF! -> #REF! | J17: =#REF! -> #REF! | K17: =#REF! -> #REF! | ... M17: =#REF! -> #REF!
A18: =#REF! -> #REF! | B18: =#REF! -> #REF! | C18: =SUM(D18:M18) -> #REF! | D18: =#REF! -> #REF! | E18: =#REF! -> #REF! | F18: =#REF! -> #REF! | G18: =#REF! -> #REF! | H18: =#REF! -> #REF! | I18: =#REF! -> #REF! | J18: =#REF! -> #REF! | K18: =#REF! -> #REF! | ... M18: =#REF! -> #REF!
A19: ='GO6_ZIDARSKI RADOVI'!A1 -> G06. | B19: ='GO6_ZIDARSKI RADOVI'!B1 -> ZIDARSKI RADOVI | C19: =SUM(D19:M19) -> 190168.8 | D19: ='GO6_ZIDARSKI RADOVI'!$E$1 -> 0 | E19: ='GO6_ZIDARSKI RADOVI'!$G$1 -> 0 | F19: ='GO6_ZIDARSKI RADOVI'!$I$1 -> 234 | G19: ='GO6_ZIDARSKI RADOVI'!$K$1 -> 12060 | H19: ='GO6_ZIDARSKI RADOVI'!$M$1 -> 1256 | I19: ='GO6_ZIDARSKI RADOVI'!$O$1 -> 33300 | J19: ='GO6_ZIDARSKI RADOVI'!$Q$1 -> 85809 | K19: ='GO6_ZIDARSKI RADOVI'!$S$1 -> 65.8 | L19: ='GO6_ZIDARSKI RADOVI'!$U$1 -> 144 | M19: ='GO6_ZIDARSKI RADOVI'!$W$1 -> 57300
A20: =#REF! -> #REF! | B20: =#REF! -> #REF! | C20: =SUM(D20:M20) -> #REF! | D20: =#REF! -> #REF! | E20: =#REF! -> #REF! | F20: =#REF! -> #REF! | G20: =#REF! -> #REF! | H20: =#REF! -> #REF! | I20: =#REF! -> #REF! | J20: =#REF! -> #REF! | K20: =#REF! -> #REF! | ... M20: =#REF! -> #REF!
A21: =#REF! -> #REF! | B21: =#REF! -> #REF! | C21: =SUM(D21:M21) -> #REF! | D21: =#REF! -> #REF! | E21: =#REF! -> #REF! | F21: =#REF! -> #REF! | G21: =#REF! -> #REF! | H21: =#REF! -> #REF! | I21: =#REF! -> #REF! | J21: =#REF! -> #REF! | K21: =#REF! -> #REF! | ... M21: =#REF! -> #REF!
A22: =#REF! -> #REF! | B22: =#REF! -> #REF! | C22: =SUM(D22:M22) -> #REF! | D22: =#REF! -> #REF! | E22: =#REF! -> #REF! | F22: =#REF! -> #REF! | G22: =#REF! -> #REF! | H22: =#REF! -> #REF! | I22: =#REF! -> #REF! | J22: =#REF! -> #REF! | K22: =#REF! -> #REF! | ... M22: =#REF! -> #REF!
A23: =#REF! -> #REF! | B23: =#REF! -> #REF! | C23: =SUM(D23:M23) -> #REF! | D23: =#REF! -> #REF! | E23: =#REF! -> #REF! | F23: =#REF! -> #REF! | G23: =#REF! -> #REF! | H23: =#REF! -> #REF! | I23: =#REF! -> #REF! | J23: =#REF! -> #REF! | K23: =#REF! -> #REF! | ... M23: =#REF! -> #REF!
A24: =#REF! -> #REF! | B24: =#REF! -> #REF! | C24: =SUM(D24:M24) -> #REF! | D24: =#REF! -> #REF! | E24: =#REF! -> #REF! | F24: =#REF! -> #REF! | G24: =#REF! -> #REF! | H24: =#REF! -> #REF! | I24: =#REF! -> #REF! | J24: =#REF! -> #REF! | K24: =#REF! -> #REF! | ... M24: =#REF! -> #REF!
A25: =#REF! -> #REF! | B25: =#REF! -> #REF! | C25: =SUM(D25:M25) -> #REF! | D25: =#REF! -> #REF! | E25: =#REF! -> #REF! | F25: =#REF! -> #REF! | G25: =#REF! -> #REF! | H25: =#REF! -> #REF! | I25: =#REF! -> #REF! | J25: =#REF! -> #REF! | K25: =#REF! -> #REF! | ... M25: =#REF! -> #REF!
A26: =#REF! -> #REF! | B26: =#REF! -> #REF! | C26: =SUM(D26:M26) -> #REF! | D26: =#REF! -> #REF! | E26: =#REF! -> #REF! | F26: =#REF! -> #REF! | G26: =#REF! -> #REF! | H26: =#REF! -> #REF! | I26: =#REF! -> #REF! | J26: =#REF! -> #REF! | K26: =#REF! -> #REF! | ... M26: =#REF! -> #REF!
A27: =#REF! -> #REF! | B27: =#REF! -> #REF! | C27: =SUM(D27:M27) -> #REF! | D27: =#REF! -> #REF! | E27: =#REF! -> #REF! | F27: =#REF! -> #REF! | G27: =#REF! -> #REF! | H27: =#REF! -> #REF! | I27: =#REF! -> #REF! | J27: =#REF! -> #REF! | K27: =#REF! -> #REF! | ... M27: =#REF! -> #REF!
A28: =#REF! -> #REF! | B28: =#REF! -> #REF! | C28: =SUM(D28:M28) -> #REF! | D28: =#REF! -> #REF! | E28: =#REF! -> #REF! | F28: =#REF! -> #REF! | G28: =#REF! -> #REF! | H28: =#REF! -> #REF! | I28: =#REF! -> #REF! | J28: =#REF! -> #REF! | K28: =#REF! -> #REF! | ... M28: =#REF! -> #REF!
A29: =#REF! -> #REF! | B29: =#REF! -> #REF! | C29: =SUM(D29:M29) -> #REF! | D29: =#REF! -> #REF! | E29: =#REF! -> #REF! | F29: =#REF! -> #REF! | G29: =#REF! -> #REF! | H29: =#REF! -> #REF! | I29: =#REF! -> #REF! | J29: =#REF! -> #REF! | K29: =#REF! -> #REF! | ... M29: =#REF! -> #REF!
A30: =#REF! -> #REF! | B30: =#REF! -> #REF! | C30: =SUM(D30:M30) -> #REF! | D30: =#REF! -> #REF! | E30: =#REF! -> #REF! | F30: =#REF! -> #REF! | G30: =#REF! -> #REF! | H30: =#REF! -> #REF! | I30: =#REF! -> #REF! | J30: =#REF! -> #REF! | K30: =#REF! -> #REF! | ... M30: =#REF! -> #REF!
A31: =#REF! -> #REF! | B31: =#REF! -> #REF! | C31: =SUM(D31:M31) -> #REF! | D31: =#REF! -> #REF! | E31: =#REF! -> #REF! | F31: =#REF! -> #REF! | G31: =#REF! -> #REF! | H31: =#REF! -> #REF! | I31: =#REF! -> #REF! | J31: =#REF! -> #REF! | K31: =#REF! -> #REF! | ... M31: =#REF! -> #REF!
... A36: =#REF! -> #REF! | B36: =#REF! -> #REF! | C36: =SUM(D36:M36) -> #REF! | D36: =#REF! -> #REF! | E36: =#REF! -> #REF! | F36: =#REF! -> #REF! | G36: =#REF! -> #REF! | H36: =#REF! -> #REF! | I36: =#REF! -> #REF! | J36: =#REF! -> #REF! | K36: =#REF! -> #REF! | ... M36: =#REF! -> #REF!
A37: T1 | B37: GRAĐEVINSKO OBRTNIČKI RADOVI | C37: =SUM(C14:C36) -> #REF! | D37: =SUM(D14:D36) -> #REF! | E37: =SUM(E14:E36) -> #REF! | F37: =SUM(F14:F36) -> #REF! | G37: =SUM(G14:G36) -> #REF! | H37: =SUM(H14:H36) -> #REF! | I37: =SUM(I14:I36) -> #REF! | J37: =SUM(J14:J36) -> #REF! | ... M37: =SUM(M14:M36) -> #REF!

Sheet općenito
A2: OPĆENITO
A4: * NAPOMENA - vrijedi za sve stavke troškovnika svih radova:
A5: * Općenito Jedinična i ukupna cijena svake stavke Troškovnika moraju biti zaokružene na dvije decimale. Ponuditeljima nije dopušteno mijenjati tekst Troškovnika osim u slučaju nuđenja jednakovrijedne stavke u odnosu na propisanu, gdje je primjenjivo. Sve stavke Troškovnika trebaju biti ispunjene. Cijena stavke izračunava se kao umnožak količine i jedinične cijene stavke. U Troškovniku se ne smiju mijenjati količine u pojedinim stavkama Troškovnika. Cijena Ponude izražava se u kunama i piše brojkama za cjelokupni predmet nabave bez PDV-a. Odredbe o jednakovrijednosti i odredbe o načinu ispunjavanja troškovnika propisane su Dokumentacijom o nabavi, te iste vrijede i primjenjuju se i na ovaj troškovnik koji je sastavni dio Dokumentacije o nabavi. U cijenu Ponude moraju biti uračunati svi troškovi i popusti, te ih nije dopušteno zasebno iskazivati. Ponuditelji će s odgovarajućom pažnjom uvažiti sve informacije koje bi mogle imati utjecaja prilikom formiranja cijene Ponude, ili koje bi mogle imati utjecaja na rok i izvršavanje radova. Ako Ponuditelj ne postupi u skladu sa zahtjevima iz poglavlja DON-a ili promijeni tekst ili količine navedene u Troškovniku, smatrat će se da je takav Troškovnik nepotpun i nevažeći te će Ponuda biti odbijena.
A6: * Jednakovrijednost proizvoda Svi proizvodi koji su u Troškovniku navedeni s imenom proizvođača ili kataloškim brojem ili tržišnim nazivom ili na bilo koji način indiciraju o kojem se proizvođaču radi, ne favoriziraju tog proizvođača ili taj proizvod nego su ti proizvodni nazivi poslužili samo i isključivo da bi se predmetni proizvod mogao bolje opisati. Ponuditelji imaju pravo ponuditi proizvode bilo kojeg proizvođača koji imaju jednakovrijedne karakteristike kao proizvodi koji su naznačeni Troškovnikom. Jednakovrijednost proizvoda dokazuje se prema u stavkama propisanim kriterijima za ocjenu jednakovrijednosti proizvoda. U stavkama u kojima nisu dodatno propisani kriteriji za ocjenu jednakovrijednosti proizvoda, brojčane vrijednosti kriterija jednakovrijednosti bit će određeni vrijednostima navedenog proizvoda.
A7: * Budući da je građevina u kojoj se obavlja uređenje u funkciji, potrebno je pri formiranju ponudbene jedinične cijene voditi računa o faznosti izvođenja radova, te o otežanim uvijetima rada, kao što je rad u 3 smjene i u neradne dane, otežanoj dopremi materijala i dnevnom odnašanju otpadnog materijala na privremeni gradilišni deponij, svakodnevnom čišćenju prostora i sl., te sve to uključiti kod formiranja jedinične cijene za svaku stavku radova, ovisno koje otežavajuće okolnosti na nju utječu.
A8: * RADIONIČKA DOKUMENTACIJA I DOKUMENTACIJA IZVEDENOG STANJA Ugovorna obveza Izvođača je izrada i isporuka radioničke dokumentacije i dokumentacije izvedenog stanja, te ti radovi trebaju biti uključeni u ponudbene cijene, bez obzira da li je isto definirano troškovničkim stavkama ili ne. * radionička dokumentacija dostavlja se Naručitelju u dva (2) tiskana primjerka te u digitalnom (pdf/dwg) formatu * projekti izvedenog stanja dostavljaju se Naručitelju, nakon što su prethodno odobreni od strane Inženjera, u dva (2) tiskana primjerka, i jednom (1) digitalnomformatu (editabilnom i needitabilnom – xls., doc., dwg. i pdf ili slično).
A9: Ponuditelj je obvezan prije dostavljanja ponude proučiti kompletnu dokumentaciju za nadmetanje temeljem koje će ponuditi izvođenje radova koje su predmet nabave. Ponuditelj se treba upoznati s lokacijama kao i s uvjetima za izvođenje radova, jer iz razloga nepoznavanja istih neće imati pravo na kasniju izmjenu svoje ponude.
A10: Kod popunjavanja troškovnika potrebno je popuniti sve elemente troškovnika budući da troškovnik sadrži automatske formule za izračunavanje.
A11: Jedinična cijena sadrži: -sav potreban rad,energiju i materijal za izvršenje stavke a sve do pune funkcije -sve potrebne prijenose i transporte u vertikalnom i horizontalnom smislu -svo potrebno deponiranje na javnu registriranu deponiju sa utovarom ,odvozom i deponiranjem - zapisničku primopredaju materijala i opreme sa deponiranjem na mjesto gdje odredi investitor ili Nadzor za stavku gdje se to zahtjeva -sve potrebno osiguranje okolnih površina I prostora te sva potrebna zaštita u smislu sprečavanja okolnh oštećenja -sve potrebno čišćenje nakon izvršenja stavke,te odvoz šute smeća i otpada sa deponiranjem na za to registriranu deponiju -sav potrebni atestni i certicfikacijski materijal te dokazi o kvaliteti gradivog materijala -sva potrebna ispitivanja kvalitete ugrađenog materijala -sve organizacijske troškove gradilišta -sve troškove zaštite prilazne prometnice,trotoara te privatne i javne površine oko zgrade
A12: Ponuditelj je za svaku od stavki opreme kojoj je u troškovniku omogućen unos u kolonu ponuđeni proizvod (stupac D, prazne bijele ćelije) dužan upisati ime ponuđenog proizvoda (proizvođač / tip / model-šifra / naslov tehničke dokumentacije) te podastrijeti dokaze o jednakovrijednosti s specifikacijom s naslovom tehničke dokumentacije.
A13: Prije izvedbe,narudžbe ili bilo kojeg početka rada izvođač radova obavezno je dužan na licu mjesta uzete sve potrebe mjere kote i svu izmjeru potrebnu za izradu stavke.Naznačene dimenzije i kote u nacrtima treba obavezno provjeriti na licu mjesta.
A14: Radovi po fazama, uz napomenu:
... A36: SPUŠTENI STROPOVI U jedinične cijene stavki obvezno uključiti sav rad, materijal, fasadne i radne skele,strojeve,sve horizontalne i vertikalne transporte te čišćenje gradilišta tijekom i nakon dovršetka pojedinih faza radova.

Sheet GO6_ZIDARSKI RADOVI
A1: G06. | B1: ZIDARSKI RADOVI | E1: =SUM(F4:F111) -> 0 | G1: =SUM(H4:H111) -> 0 | I1: =SUM(J4:J111) -> 234 | K1: =SUM(L4:L111) -> 12060 | M1: =SUM(N4:N111) -> 1256 | O1: =SUM(P4:P111) -> 33300 | Q1: =SUM(R4:R111) -> 85809 | S1: =SUM(T4:T111) -> 65.8 | U1: =SUM(V4:V111) -> 144 | W1: =SUM(X4:X111) -> 57300
A2: REDNI BROJ | B2: STAVKA | C2: JEDINICA MJERE | D2: JEDINIČNA CIJENA JC | E2: UKUPNO FAZA I. | G2: UKUPNO FAZA II. | I2: UKUPNO FAZA III. | K2: UKUPNO FAZA IV. | M2: UKUPNO FAZA V. | O2: UKUPNO FAZA VI. | Q2: UKUPNO FAZA VII. | S2: UKUPNO FAZA VIII. | U2: UKUPNO FAZA IX. | W2: UKUPNO FAZA X.
E3: KOLIČINA faza I. | F3: UKUPNA CIJENA =JCxKfazaI. | G3: KOLIČINA faza II. | H3: UKUPNA CIJENA =JCxKfazaII. | I3: KOLIČINA faza III. | J3: UKUPNA CIJENA =JCxKfazaIII. | K3: KOLIČINA faza IV. | L3: UKUPNA CIJENA =JCxKfazaIV. | M3: KOLIČINA faza V. | N3: UKUPNA CIJENA =JCxKfazaV. | O3: KOLIČINA faza VI. | P3: UKUPNA CIJENA =JCxKfazaVI. | Q3: KOLIČINA faza VII. | R3: UKUPNA CIJENA =JCxKfazaVII. | S3: KOLIČINA faza VIII. | T3: UKUPNA CIJENA =JCxKfazaVIII. | U3: KOLIČINA faza IX. | V3: UKUPNA CIJENA =JCxKfazaIX. | W3: KOLIČINA faza X. | X3: UKUPNA CIJENA =JCxKfazaX.
B4: NAPOMENA: Budući da je proizvodni pogon i pripadajući prostori u kojima se obavlja rekonstrukcija u funkciji, potrebno je pri formiranju ponudbene jedinične cijene voditi računa o faznosti izvođenja radova, te o otežanim uvijetima rada, kao što je rad u 3 smjene i u neradne dane, otežanoj dopremi materijala i dnevnom odnašanju otpadnog materijala na privremeni gradilišni deponij, svakodnevnom čišćenju prostora i sl., te sve to uključiti kod formiranja jedinične cijene za svaku stavku radova, ovisno koje otežavajuće okolnosti na nju utječu.
A6: G06.01. | B6: Dobava materijala i zidanje zidova iz blok opeke debljine 15 cm.
B7: Materijal:šuplja opeka 15/25/19 u produžnom cementnom mortu M - 50 (1:2:6)
B8: Vatrootpornost stijene REI 90
B9: Visina rada do 1200 cm
B10: Uključivo :
B11: Dobavu i pripremu materijala
B12: Potrebne pokretne skele
B13: Obračun po m2 novog zida.
C14: m2
A16: G06.02. | B16: Dobava materijala i zidanje zidova od YTONG blokova debljine:15, 20 i 25 cm.
B17: Materijal:YTONG blokovi 25/60/15 (20) (25) ,kao vezivo koristiti Ytong ljepilo (tankoslojni mort).Stavka uključuje i Ytong blokove s rupama za vertikalne serklaže (15% blokova) te vezne elemente za povezivanje zida sa montažnom AB konstrukcijom stupova i greda.
B18: Vatrootpornost stijene REI 90
B19: Visina rada do 1400 cm
B20: Uključivo :
B21: Dobavu i pripremu materijala
B22: Potrebne pokretne skele
B23: Obračun po m2 novog zida.
B24: d=15 cm | C24: m2 | M24: 95 | N24: =ROUND((D24*M24),2) -> 0
B25: d=20 cm | C25: m2 | K25: 250 | L25: =ROUND((D25*K25),2) -> 0 | M25: 2800 | N25: =ROUND((D14*M25),2) -> 0 | O25: 90 | P25: =ROUND((D25*O25),2) -> 0 | Q25: 2200 | R25: =ROUND((D25*Q25),2) -> 0 | W25: 220 | X25: =ROUND((D25*W25),2) -> 0
B26: d=25 cm | C26: m2 | M26: 18 | N26: =ROUND((D26*M26),2) -> 0
A29: G06.03. | B29: Izvedba produžne žbuke zidova, arm.betona cementnim produžnim mortom M 5.Uključivo čišćenje i vlaženje zida, te priprema za bolje prijanjanje.Izvodi se sloj debljin oko 2 cm.VisIna rada do 10.00 m .
B30: Uključivo:
B31: Dobava, priprema i ugradnja, pokretna skela i podesti za rad.Završna površina mora biti ravna i glatka pripravna za bojanje.U sloj žbuke po potrebi se postavlja rabitz pletivo što je obuhvaćeno posebnom stavkom.
B32: Obračun po m2.
C33: m2 | D33: 26 | O33: 810 | P33: =ROUND((D33*O33),2) -> 21060
A34: G06.04. | B34: Zidarska obrada betonskih zidova, stropova.
B35: Pranje i čišćenje betonskih površina
B36: Nanošanje specijalnog morta za beton (gletanje),brušenje betonskih površina,okno dizala.
B37: Visina rada do 10.00m.
B38: Uključivo:
B39: Dobava, priprema i ugradnja materijala
B40: Postizanje potpuno jednolike, ravne i glatke površine
B41: Potrebne pokretne skele
B42: Obračun po m2 obrađenih površina
B43: a) zidovi | C43: m2 | M43: 220 | N43: =ROUND((D44*M43),2) -> 0 | W43: 11 | X43: =ROUND((D43*W43),2) -> 0
B44: b) stropovi | C44: m2 | I44: 80 | J44: =ROUND((D44*I44),2) -> 0 | K44: 50 | L44: =ROUND((D44*K44),2) -> 0 | M44: 380 | N44: =ROUND((D44*M44),2) -> 0 | O44: 7 | P44: =ROUND((D44*O44),2) -> 0 | Q44: 620 | R44: =ROUND((D44*Q44),2) -> 0 | W44: 320 | X44: =ROUND((D44*W44),2) -> 0
...
