Workbook

Sheet nas
A9: Investitor: | B9: Suvlasnici stambene zgrade Poljana Jurja Andrassya 12, 13 i 14,10000 Zagreb koje zastupaju: Ovlašteni predstavnik suvlasnika: Dunja Mesing, Nova cesta 136, Zagreb, OIB:70205129911 Upravitelj: GSKG d.o.o., Savska cesta 1, Zagreb, OIB: 03744272526
A12: Građevina: | B12: Stambena zgrada Poljana Jurja Andrassya 12, 13 i 14; 10000 Zagreb
A14: Lokacija: | B14: Poljana Jurja Andrassya 12, 13 i 14, 10000 Zagreb; k.č. 5333, k.o. Trešnjevka
A16: Tehnički dnevnik: | B16: 168 - 24
A18: Zajednička oznaka projekta: | B18: SAE - 168 - 2024
A20: Razina razrade projekta: | B20: Glavni projekt
A22: Vrsta projekta: | B22: ARHITEKTONSKI PROJEKT REKONSTRUKCIJE U SVRHU ENERGETSKE OBNOVE
B23: TROŠKOVNIK GRAĐEVINSKO - OBRTNIČKIH RADOVA
A25: Projektant: | B25: Ana Miljan, mag. ing. arch.
A27: Suradnik: | B27: Ivan Čolić, mag. ing. aedif. Andrea Banić, mag. Ing. aedif.
A29: Glavni projektant: | B29: Ana Miljan, mag. ing. arch.
A31: Izradio: | B31: SAEPTUM d.o.o. za savjetovanje, arhitektonske i energetske usluge, Travnička 50/a, Čakovec, Kružna ulica 81, Zagreb
A32: Direktorica: | B32: Željka Hrs Borković, d.i.a., direktor
A35: Mjesto i datum: | B35: Zagreb, svibanj 2024.
A38: SAEPTUM d.o.o. Travnička 50/A, ČK, Kružna ulica 81, ZG, T+385 98 302785, +385 1 5602505, www.saeptum.hr, OIB 00721493603, P.RAČUN HR8623600001102580265 ZABA, Temeljni kapital 50.000,00 HRK/6.636,14 EUR, Uprava Željka Hrs Borković, Toni Borković
A49: SADRŽAJ :
A53: 1. TROŠKOVNIK GRAĐEVINSKO - OBRTNIČKIH RADOVA
A58: Napomena: | B58: 1. Troškovnik obuhvaća cjelovitu obnovu.
B59: 2. U slučaju drugačijeg zahtjeva investitor je dužan naručiti izmjene i dopune predmetne dokumentacije, a projektanti se obvezuju istu i napraviti ukoliko je u skladu sa pravilima dobrog zanata i stručne etike.
B60: U tom slučaju, djelomična obnova i njeni detalji utvrđuju se pisanim zahtjevom u vidu projektnog zadatka koji potpisuje investitor.
B61: 3. U troškovniku su navedene projektantske cijene.

Sheet sve rek
A7: Investitor: | B7: Suvlasnici stambene zgrade Poljana Jurja Andrassya 12, 13 i 14,10000 Zagreb koje zastupaju: Ovlašteni predstavnik suvlasnika: Dunja Mesing, Nova cesta 136, Zagreb, OIB:70205129911 Upravitelj: GSKG d.o.o., Savska cesta 1, Zagreb, OIB: 03744272526
A9: Građevina: | B9: Stambena zgrada Poljana Jurja Andrassya 12, 13 i 14; 10000 Zagreb
A11: Lokacija: | B11: Poljana Jurja Andrassya 12, 13 i 14, 10000 Zagreb; k.č. 5333, k.o. Trešnjevka
A15: Izradio: | B15: SAEPTUM d.o.o. za savjetovanje, arhitektonske i energetske usluge, Travnička 50/a, 40000 Čakovec, Kružna ulica 81, 10000 Zagreb
B18: TROŠKOVNIK GRAĐEVINSKO - OBRTNIČKIH RADOVA (bez zamjene stolarije stanova)
A21: SVEUKUPNA REKAPITULACIJA
A23: 1.2. | B23: GRAĐEVINSKI I OBRTNIČKI RADOVI: | E23: EUR | F23: =rekap!F31 -> 0
C28: SVEUKUPNO: | E28: EUR | F28: =F23 -> 0
C29: PROJEKTANTSKI NADZOR 0,50% (1.) | E29: EUR | F29: =F23*0.005 -> 0
C30: STRUČNI NADZOR 2,00% (1.) | E30: EUR | F30: =F23*0.02 -> 0
C31: KOORDINATOR ZNR TIJEKOM GRAĐ. 0,50 % (1.) | E31: EUR | F31: =F23*0.005 -> 0
C32: SVEUKUPNO S NADZOROM: | E32: EUR | F32: =F28+F31+F30+F29 -> 0
C33: PDV 25% | E33: EUR | F33: =F32*0.25 -> 0
C34: SVEUKUPNO S PDV-OM: | E34: EUR | F34: =F32+F33 -> 0
A37: PONUDITELJ
A38: (naziv i adresa)

Sheet sve rek + stolarija
A7: Investitor: | B7: Suvlasnici stambene zgrade Poljana Jurja Andrassya 12, 13 i 14,10000 Zagreb koje zastupaju: Ovlašteni predstavnik suvlasnika: Dunja Mesing, Nova cesta 136, Zagreb, OIB:70205129911 Upravitelj: GSKG d.o.o., Savska cesta 1, Zagreb, OIB: 03744272526
A10: Građevina: | B10: Stambena zgrada Poljana Jurja Andrassya 12, 13 i 14; 10000 Zagreb
A12: Lokacija: | B12: Poljana Jurja Andrassya 12, 13 i 14, 10000 Zagreb; k.č. 5333, k.o. Trešnjevka
A17: Izradio: | B17: SAEPTUM d.o.o. za savjetovanje, arhitektonske i energetske usluge, Travnička 50/a, 40000 Čakovec, Kružna ulica 81, 10000 Zagreb
B20: TROŠKOVNIK GRAĐEVINSKO - OBRTNIČKIH RADOVA (sa zamjenom stolarije stanova)
A23: SVEUKUPNA REKAPITULACIJA
A25: 1.2. | B25: GRAĐEVINSKI I OBRTNIČKI RADOVI: | E25: EUR | F25: ='rekap+stolarija'!F36 -> 0
C29: SVEUKUPNO: | E29: EUR | F29: =F25 -> 0
C30: PROJEKTANTSKI NADZOR 0,50% (1.) | E30: EUR | F30: =F25*0.005 -> 0
C31: STRUČNI NADZOR 2,00% (1.) | E31: EUR | F31: =F25*0.02 -> 0
C32: KOORDINATOR ZNR TIJEKOM GRAĐ. 0,50 % (1.) | E32: EUR | F32: =F25*0.005 -> 0
C33: SVEUKUPNO S NADZOROM: | E33: EUR | F33: =F29+F30+F31+F32 -> 0
C34: PDV 25% | E34: EUR | F34: =F33*0.25 -> 0
C35: SVEUKUPNO S PDV-OM: | E35: EUR | F35: =F33+F34 -> 0
A38: PONUDITELJ
A39: (naziv i adresa)

Sheet rekap
A5: 1.1. TROŠKOVNIK GRAĐEVINSKO - OBRTNIČKIH RADOVA
A9: REKAPITULACIJA GRAĐEVINSKO - OBRTNIČKIH RADOVA
A12: A. | B12: GRAĐEVINSKI RADOVI
A14: A.I.1. | B14: PRIPREMNI RADOVI I SKELA (zajednički prostori) ukupno | E14: EUR | F14: ='A.I.1. pri+skela'!F70 -> 0
A15: A.II.1. | B15: RUŠENJA I DEMONTAŽE (zajednički prostori) ukupno | E15: EUR | F15: ='A.II.1.dem'!F93 -> 0
A16: A.III.1. | B16: ZIDARSKI RADOVI (zajednički prostori) ukupno | E16: EUR | F16: ='A.III.1.zid'!F55 -> 0
A17: A.IV. | B17: IZOLATERSKI RADOVI ukupno | E17: EUR | F17: ='A.IV.izo'!F93 -> 0
A18: A.V. | B18: ZEMLJANI RADOVI ukupno | E18: EUR | F18: ='A.V.zem'!F40 -> 0
A19: A. | B19: GRAĐEVINSKI RADOVI UKUPNO: | E19: EUR | F19: =SUM(F14:F18) -> 0
A21: B. | B21: OBRTNIČKI RADOVI
A23: B.I. | B23: LIMARSKI RADOVI ukupno | E23: EUR | F23: ='B.I.lim'!F67 -> 0
A24: B.II.1 | B24: VANJSKA PVC STOLARIJA (zajedničkih prostorija) ukupno | E24: EUR | F24: ='B.II.1. sto'!F75 -> 0
A25: B.III. | B25: ZAVRŠNI ZIDARSKO-FASADERSKI RADOVI ukupno | E25: EUR | F25: ='B.III.zz'!F118 -> 0
A26: B.IV.1. | B26: SOBOSLIKARSKO LIČILAČKI RADOVI (zajednički prostori) ukupno | E26: EUR | F26: ='B.IV.1.lič'!F105 -> 0
A27: B.V. | B27: PODOPOLAGAČKI RADOVI ukupno | E27: EUR | F27: ='B.V.podopol.'!F33 -> 0
A28: B.VI. | B28: BRAVARSKI RADOVI ukupno | E28: EUR | F28: =B.brav!F81 -> 0
A29: B. | B29: OBRTNIČKI RADOVI UKUPNO: | E29: EUR | F29: =SUM(F23:F28) -> 0
B31: A+B UKUPNO: | E31: EUR | F31: =SUM(F19+F29) -> 0

Sheet rekap+stolarija
A5: 1.2. TROŠKOVNIK GRAĐEVINSKO - OBRTNIČKIH RADOVA
A9: REKAPITULACIJA GRAĐEVINSKO - OBRTNIČKIH RADOVA
B10: (stambenih i poslovnih prostorija)
A12: A. | B12: GRAĐEVINSKI RADOVI
A14: A.I.1. | B14: PRIPREMNI RADOVI I SKELA (zajednički prostori) ukupno | E14: EUR | F14: ='A.I.1. pri+skela'!F70 -> 0
A15: A.I.2. | B15: PRIPREMNI RADOVI ukupno (stanovi prostori) | E15: EUR | F15: ='A.I.2.pri'!F19 -> 0
A16: A.II.1. | B16: RUŠENJA I DEMONTAŽE ukupno (zajednički prostori) | E16: EUR | F16: ='A.II.1.dem'!F93 -> 0
A17: A.II.2. | B17: RUŠENJA I DEMONTAŽE ukupno (stanovi) | E17: EUR | F17: ='A.II.2.dem'!F18 -> 0
A18: A.III.1. | B18: ZIDARSKI RADOVI ukupno (zajednički prostori) | E18: EUR | F18: ='A.III.1.zid'!F55 -> 0
A19: A.III.2. | B19: ZIDARSKI RADOVI ukupno (stanovi) | E19: EUR | F19: ='A.III.2.zid'!F18 -> 0
A20: A.IV. | B20: IZOLATERSKI RADOVI ukupno | E20: EUR | F20: ='A.IV.izo'!F93 -> 0
A21: A.V. | B21: ZEMLJANI RADOVI ukupno | E21: EUR | F21: ='A.V.zem'!F40 -> 0
A22: A. | B22: GRAĐEVINSKI RADOVI UKUPNO: | E22: EUR | F22: =SUM(F14:F21) -> 0
A24: B. | B24: OBRTNIČKI RADOVI
A26: B.I. | B26: LIMARSKI RADOVI ukupno | E26: EUR | F26: ='B.I.lim'!F67 -> 0
A27: B.II.1. | B27: VANJSKA ALUMINIJSKA STOLARIJA ukupno (zajedničkih prostorija) | E27: EUR | F27: ='B.II.1. sto'!F75 -> 0
A28: B.II.2. | B28: VANJSKA STOLARIJA ukupno (stanovi ) | E28: EUR | F28: ='B.II.2. sto'!F106 -> 0
A29: B.III. | B29: ZAVRŠNI ZIDARSKO-FASADERSKI RADOVI ukupno | E29: EUR | F29: ='B.III.zz'!F118 -> 0
A30: B.IV.1. | B30: SOBOSLIKARSKO LIČILAČKI RADOVI (zajednički prostori) ukupno | E30: EUR | F30: ='B.IV.1.lič'!F105 -> 0
A31: B.IV.2. | B31: SOBOSLIKARSKO LIČILAČKI RADOVI (stanovi i poslovni prostori) ukupno | E31: EUR | F31: ='B.IV.2.lič'!F17 -> 0
A32: B.V. | B32: PODOPOLAGAČKI RADOVI ukupno | E32: EUR | F32: ='B.V.podopol.'!F33 -> 0
A33: B.VI. | B33: OSTALI RADOVI ukupno | E33: EUR | F33: =B.brav!F81 -> 0
A34: B. | B34: OBRTNIČKI RADOVI UKUPNO: | E34: EUR | F34: =SUM(F26:F33) -> 0
B36: A+B UKUPNO: | E36: EUR | F36: =SUM(F22+F34) -> 0

Sheet opći
B3: OPĆI UVJETI
B5: OPĆI OPIS UZ TROŠKOVNIK
B7: 1. Glavni projekt energetske obnove i pripadni troškovnik temelje se na obavljenom uvidu i izmjeri na postojećoj zgradi. Slojevi konstrukcija definirani u postojećoj projektnoj tehničkoj dokumentaciji i prilikom izmjere, preuzeti su kao stvarno izvedeni. Nevidljivi slojevi konstrukcija, koji nisu definirani postojećom dokumentacijom, pretpostavljeni su temeljem dosadašnjeg iskustva prema vremenu gradnje zgrade. Prije izvedbe potrebno je izvršiti detaljni uvid na licu mjesta te utvrditi slojeve konstrukcije vizualnim ispitivanjem i otvaranjem konstrukcija koje se rekonstruiraju.
B9: 2. Projekt je napravljen na temelju zakonske regulative RH, pravila dobrog zanata i preporuke o cjelovitoj obnovi koju podupiru EU fondovi, u skladu sa svim hrvatskim i europskim tehničkim propisima i normama i priznatim tehničkim pravilima, ili jednakovrijedno. Projekt je definiran potpisanim projektnim zadatkom. Svi materijali navedeni u projektu i troškovniku, moraju odgovarati važećim hrvatskim propisima i normama, ili jednakovrijedno.
B11: 3. Grafički dio (nacrti), tekstualni dio (opći i tehnički), Projekt racionalne uporabe energije i toplinske zaštite zgrade, kao i Program kontrole i osiguranja kvalitete dijelovi su arhitektonskog glavnog projekta, koji zajedno s pripadajućim troškovnikom čine cjelinu projekta energetske obnove zgrade. Projektom energetske obnove dani su osnovni detalji izvedbe.
B13: 4. U fazi izvedbe, zbog činjenice da se radi o obnovi (rekonstrukciji), a ne izgradnji nove zgrade, bit će potrebna dodatna razrada detalja izvedbe u suradnji s izvođačem radova, te ukoliko se nakon uklanjanja pojedinih slojeva i uvida u postojeće slojeve i stanje konstrukcije utvrdi odstupanje odnosno različitost u odnosu na postojeće stanje prikazano projektom obnove, potrebno je napraviti reviziju glavnog projekta. Također, u slučaju nužnosti odstupanja od glavnog projekta iz drugih opravdanih razloga prilikom izvođenja radova potrebno je izraditi izmjene i dopune glavnog projekta.
B15: 5. Odgovarajućim upisom u građevinski dnevnik potrebno je verificirati projektno rješenje ili po potrebi izvršiti korekciju, te ukoliko je potrebno, a ovisno o postojećem stanju konstrukcije, prije izvedbe ETICS sustava, napraviti statičku provjeru vanjskih zidova koja mora biti odobrena od strane inženjera konstrukcije i nadzornog inženjera.
B17: 6. Izvođač je dužan proučiti sve gore navedene dijelove projekta, te u slučaju nejasnoća ili eventualnih odstupanja od stvarnog stanja na terenu, tražiti mišljenje projektanta i nadzornog inženjera. Prije početka radova i izrade ponude izvođač je obavezan kontrolirati na postojećoj zgradi sve potrebne mjere za svoj rad, te obavijestiti projektanta u slučaju nedorečenosti ili nejasnoća. Prilikom izvođenja radova treba paziti da svi detalji budu riješeni u skladu s Tehničkim propisom o racionalnoj uporabi energije i toplinskoj zaštiti u zgradama (NN 128/15, NN 70/18, NN 73/18, 86/18, 102/20)
B20: 7. Preporuka projektanta je izvođenje cjelovitog rješenja energetske obnove zgrade iz sljedećih razloga: 1. tehnički ispravno izvođenje detalja, 2. tehnički ispravan redoslijed izvođenja radova, 3. suzbijanje selektivnih intervencija na pročeljima zgrade, 4. zaštita arhitektonskog djela u smislu estetske i tehničke cjelovitosti oblikovanja, 5. očuvanje i unapređenje bitnih zahtjeva građevine, 6. ušteda sredstava i vremena (u slučaju fazne gradnje pojedini radovi se umnožavaju, kao što su postava skele, limarski radovi i sl.), 7. ostvarivanje tržišnih popusta (cijena pojedinačnog proizvoda manja je što je količina veća), 8. integralna rješenja podupiru se bespovratnim sredstvima iz EU fondova. U slučaju nužnosti odstupanja od glavnog projekta prilikom izvođenja radova potrebno je izraditi izmjene i dopune glavnog projekta te ih uskladiti zahtjevima suvlasnika sukladno pravilima dobrog zanata i inženjerske etike.
B22: 8. Izvođač će se pridržavati svih važećih zakona i propisa i to: Zakona o prostornom uređenju (NN 153/13, NN 65/17, NN 114/18, NN 39/19, 98/19), Zakona o gradnji (NN 153/13, 20/17, 39/19, 125/19), Zakona o državnom inspektoratu (NN 115/18, 117/21), Zakona o zaštiti na radu (NN 71/14, 118/14, N 154/14, 94/18, 96/18), Zakon o zaštiti od buke (NN 30/09, 55/13, 153/13, 41/16, 114/18, 41/21), Zakon o zaštiti od požara (NN 92/10), svih pravilnika koji iz tih zakona proizlaze, kao i svih drugih zakona iz područja gradnje, tehničkih propisa, priznatih tehničkih pravila i hrvatskih normi (HRN), ili jednakovrijedno.
B24: 9. Izvođač će prilikom uvođenja u posao preuzeti nekretninu i obavijestiti nadležne službe o otvaranju gradilišta i početku radova. Od tog trenutka pa do primopredaje zgrade, izvođač je odgovoran za stvari i osobe koje se nalaze unutar gradilišta. Od ulaska na gradilište izvođač je obavezan voditi građevinski dnevnik u kojem bilježi opis radnih procesa i građevinsku knjigu u kojoj bilježi i dokumentira mjerenja, sve faze izvršenog posla prema stavkama troškovnika i projektu. Izvođač će na gradilištu čuvati građevnu dozvolu ukoliko je to zakonom određeno, kao i projektnu dokumentaciju i dati ih na uvid ovlaštenim inspekcijskim službama.
B26: 10. Izvođač će ugraditi projektom predviđen i prema hrvatskim i EU normama atestiran materijal. Sve radove izvest će od kvalitetnog materijala prema opisu, detaljima, pismenim naređenjima, ali sve u okviru ponuđene jedinične cijene. Svi nekvalitetni radovi imaju se otkloniti i zamijeniti ispravnima, bez bilo kakve odštete od strane investitora.
... B55: 25. Nakon naplate okončane situacije izvođač će predati zgradu investitoru ili po investitoru određenom korisniku.

Sheet A.I.1. pri+skela
A2: TROŠKOVNIK GRAĐEVINSKO OBRTNIČKIH RADOVA
A3: A. GRAĐEVINSKI RADOVI / A.I.1. PRIPREMNI RADOVI I SKELA
A4: r.b. | B4: opis stavke | C4: jed. | D4: kol. | E4: jed.cijena | F4: ukupno
A6: A. | B6: GRAĐEVINSKI RADOVI
A9: A.I.1. | B9: PRIPREMNI RADOVI I SKELA (ZAJEDNIČKI PROSTORI)
A11: OPĆI UVJETI
A13: Pri kalkulaciji ponuda ponuđač treba voditi računa da zgrada za vrijeme radova mora biti u funkciji te da se radovi moraju planirati tako da se omogući boravak stanara u svim dijelovima zgrade uz što manje i kraće poremećaje.
A15: Izvođač je dužan pregledati projekt i lokaciju, mogućnosti pristupa parceli i organizacije rada na parceli kako bi mogao dati realnu cijenu za pripremne i ostale radove. Ukoliko izvođač prethodnim uvidom primijeti da je potrebno izvesti još neke pripremne radove, dužan ih je uvrstiti u cijenu putem obračuna u faktoru, jer se naknadni pripremni radovi neće posebno priznavati.
A17: Pripremni radovi koje je izvođač dužan izvesti bez posebnog iskaza troškova ulaze u cijenu zgrade kroz faktor i nisu prikazani u posebnim stavkama troškovnika: - izrada plana organizacije gradilišta, - organizacija i uređenje prilaznih i privremenih prometnica na gradilištu - izgradnja gradilišnih nastambi za radnike, upravu, skladišta, nadstrešnice, - privremeni priključci i razvod vodovoda, električne energije, telefona i ostalih instalacija na gradilištu za potrebe funkcioniranja gradilišta, - organizacija čuvarske i nadzorne službe, radovi na osiguranju gradilišta i radnika, osiguranje za obeštećenja na gradilištu i naknade štete prema trećim osobama - geodetsko snimanje visina i vanjskog terena, - ostali radovi koji po pravilu terete režiju uprave izvođača i koji se ne naplaćuju posebno - troškovi potrebnih ispitivanja materijala i konstrukcija, te ishođenje atesta. Utrošak vode i električne energije za jedinicu proizvoda uključuje se u analizu cijena proizvoda prema normativima utroška, a utrošak za potrebe ureda, gradilišta, pranje vozila i strojeva, rasvjetu gradilišta i ostalo uključuje se u faktor gradilišta.
A19: Dozvolu za korištenje javnih prometnih površina izvođač je dužan zatražiti od nadležnih službi, prema potrebama za organizaciju gradilišta i platiti eventualne takse za ishođenje odobrenja za korištenje površina što je uključeno u faktoru. Izvođač je dužan pridržavati se pravila prometa na javnim prometnicama i unutar gradilišta.
B21: SKELA
A23: Prije izrade ponude za skelu izvođač je dužan pregledati građevinu radi ocjene uvjeta za organizaciju izvedbe radova i stanja pojedinih dijelova građevine na kojima se radovi izvode. Cijevna skela izvodi se od čeličnih elemenata. Oslanjanje skele na nosivu podlogu preko metalnih podložnih papuča; podloga na koju se postavlja fasadna skela mora biti čvrsta i stabilna. Minimalna širina skele iznosi 80 cm.
A25: Skelu udaljiti od ravnine gotovog pročelja za 15-20 cm. Visina zaštitne ograde iznosi 100 cm, a elemente ograde postaviti na max. razmak od 35 cm. U razini radne platforme uz zaštitinu ogradu potrebno je postaviti dasku minimalne visine 20 cm. Visinski razmak između radnih platformi treba prilagoditi horizontalnim elementima pročelja.
A27: Skela mora biti opremljena penjalicama max. dužine 4 m u jednom komadu, postavljenih naizmjenično. Fasadnu skelu potrebno je sa vanjske strane prekriti jutenim zastorom, koji se učvršćuje za konstrukciju skele. Skelu treba od podnožja do vrha, kao i na krajevima, dijagonalno ukrutiti kosnicima pod 45°. Skelu je potrebno osigurati od prevrtanja sidrenjem u samu građevinu. Razmak između točki sidrenja mora biti manji od 6,0 m u horizontalnom i vetikalnom smjeru. Izvedena skela ne smije imati visinu stupova veću od 4 m. Skelu je potrebno uzemljiti i osigurati od udara groma.
A29: Izvođač je dužan prije postavljanja skele predočiti nacrt skele sa statičkim računom na odobrenje. Dužan je ishoditi i suglasnosnost za postavljanje skele- zauzimanje javnoprometne površine. Riješiti zaštitu prolaznika i ulaza u građevinu. Ukoliko za pričvršćenje skele bude potrebno koristiti tuđi prostor, izvoditelj je dužan ishoditi suglasnost investitora.
A31: Sva eventualna oštećenja nastala uslijed vezivanja skele na građevinu izvođač je dužan otkloniti o svom trošku.
A33: Pješački prolaz ispod skele treba izvesti u skladu sa potrebama korisnika, odnosno u skladu s dozvolom za zauzeće javne površine. Sa bočnih strana prolaza se postavlja puna zaštitna ograda minimalne visine od 150 cm. Iznad prolaza treba izvesti oblogu od mosnica, a na vanjskom rubu još i kosu zaštitu pod kutem od 60° visine 60 cm. Pješački prolaz treba biti obilježen propisanom signalizacijom (putokazi, rasvjeta).
A34: U jediničnu cijenu treba uključiti : - sav rad oko postave i skidanja skele, - izradu statičkog računa i nacrta montaže skele, - dostavu svog potrebnog materijala za postavu skele te čišćenje i odvoz istog nakon skidanja, - postavu svjetlosne signalizacije i njeno održavanje, - amortizaciju materijala za vrijeme izvođenja svih radova na pročelju, - sve društvene obveze vezane za radnu snagu i materijal, - održavanje skele za vrijeme trajanja radova, - pripremno-završne radove, - naknada za zauzimanje javno-prometne površine. Amortizacija skele obračunava se za vrijeme gradnje, a skelu mogu koristiti svi izvođači bez posebne nadoplate. Potrebno je terminskim planom uskladiti sve aktivnosti da se izbjegne međusobno ometanje pojedinih izvođača. Svi materijali za izradu skele moraju odgovarati važećim hrvatskim propisima i normama, ili jednakovrijedno.
A36: Prilikom izrade fasadnih skela potrebno se pridržavati propisa zaštite na radu po pitanjima radnih ploha, zaštitnih ograda i prilaza. Materijal za izradu skela mora biti potpuno ispravan. Odgovorna osoba dužna je izvršiti pregled materijala prije ugradnje. Skele moraju biti izvedene po mjerama i na način označen u statičkom računu i nacrtima skele. Izvedene skele moraju biti sposobne podnijeti predviđeno opterećenje i moraju biti stabilne. Fasadne skele obračunavaju se po m² projekcije skele u ravnini pročelja, mjereno po vanjskom rubu i 1 m nad najvišom površinom.
A38: 1. | B38: Čišćenje i raščišćavanje terena
B39: Čišćenje i raščišćavanje terena oko zgrade cca 2-3 m kao radno-manipulativne površine, a prije početka radova na rušenjima i demontaži. Stavka uključuje sva čišćenja od smeća i otpadnog materijala, obrezivanje grmlja i stabala koji svojom pozicijom i volumenom ometaju izvođenje planiranih radova, zaštitu popločenih površina staza oko zgrade, kao i ostale nespecificirane radove, zajedno s utovarom, odvozom, istovarom i deponiranjem otpadnog materijala na odlagalištu udaljenom 20 km. Obračun po m² obrađene površine.
B40: teren oko zgrade | C40: m² | D40: 775 | F40: =D40*E40 -> 0
A42: 2. | B42: Priprema gradilišta
B43: Priprema gradilišta uključuje zaštitu zgrade izvana i iznutra od oštećenja tijekom radova, osiguranje koridora za prolaz korisnika zgrade s pripadajućom zaštitom od šute i prašine, te osiguranje okoline kojoj se spriječava prilaz nezaposlenih tijekom radova. Sav prostor za vrijeme i nakon rušenja i demontaža, te prilikom izvođenja novih konstrukcija, zaštititi od vremenskih nepogoda (vlaženja, prokišnjavanja, rashlađivanja), te osigurati i zaštititi od ostalih uvjeta koji bi mogli ometati izvođenje radova vezanih za postojeće instalacije (vodovod, odvodnja, grijanje, ventilacija, elektrika, plin i drugo). Sve radove treba izvoditi sukladno propisanim higijensko tehničkim mjerama zaštite na radu.
B44: Stavka obuhvaća pregled, kontrolu mjera i veličina postojećeg stanja građevinske konstrukcije zgrade, pregled postojećeg stanja opreme, instalacija, te utvrđivanje točnih koridora instalacija u objektu i izvan objekta. Pripremne radove je obavezan izvršavati izvođač radova prije nego pristupi izvođenju i za vrijeme izvođenja radova. U pripremne radove uključiti i pregled projektne dokumentacije s pripadajućim troškovnicima, a o svim nejasnoćama ili neusklađenostima pravovremeno izvjestiti investitora i projektanta. Obračun za izvođenje kompletnih pripremnih radove iz opisa stavke, po paušalnoj procjeni.
C45: komplet | D45: 1 | F45: =D45*E45 -> 0
A47: 3. | B47: Fasadna skela
B48: Doprema, montaža, demontaža i otprema cijevne fasadne skele, visine 1,0 m iznad gornjeg ruba vijenca, odnosno zabata krova. Skelu izraditi prema važećim propisima i općim uvjetima. Skela mora biti izvedena prema pravilima struke; u stavku su uključene radne platforme i zaštitne ograde, sva potrebna ukrućenja i sidrenja, penjalice, te uzemljenje. Cijenom je obuhvaćena dobava i postava jutenih ili plastificiranih traka na vanjski dio skele, kao zaštita od pada predmeta, prašenja i sl., sve fiksirano za konstrukciju skele. Prije izvedbe skele izvođač je dužan izraditi projekt skele, što je u cijeni stavke. Sve u skladu sa važećim propisima ZNR. Obračun po m² ortogonalne projekcije skele.
B49: fasadna skela do 20 metara | C49: m² | D49: 2528 | F49: =D49*E49 -> 0
A51: 4. | B51: Priprema pročelja za izvedbu klasificiranog ETICS sustava
B52: Stavka uključuje pripremu podloge za izradu novog ETICS sustava toplinske izolacije pročelja na bazi mineralne vune: otucanje žbuke koja se odvaja od zidova, krpanje svih pukotina u zidovima i stropovima, izravnavanje većih neravnina i oštećenja fasade reparaturnim polimercementnim mortom, te pranje i paropropusnu impregnaciju žbuke pročelja. Podloga na koju će se nanositi ETICS mora biti čista, čvrsta, nosiva, bez ostataka prljavštine, sipkih dijelova i sl. Prije nanošenja toplinske izolacije potrebno je provjeriti prionjivost morta za lijepljenje na postojeću podlogu. Stavka uključuje zaštitu stolarije i drugih elemenata koji se ne uklanjaju te prostora u zgradi PVC folijom od šute i prašine, horizontalni i vertikalni transport šute i materijala po gradilištu, prijenos i odvoz otpadnog materijala i šute na deponij udaljen 20 km. Obračun za kompletan rad, materijal i sve transporte je po m² kompletno obrađene i pripremljene površine pročelja. Otvori se odbijaju u cijeloj površini.
B53: svi AB zidovi i zabati i žbukana čela zidova | C53: m² | D53: 1910 | F53: =D53*E53 -> 0
A55: 5. | B55: CCTV snimanje postojećih slivničkih vertikala -oborinskih cjevovoda za odvod krovnih voda s postojećeg ravnog krova robot kamerama
B56: Ispitivanje i vizualno kodiranje stanja snimanjem daljinski upravljanom CCTV kamerom – za snimanje kanalizacijskih cjevovoda kamerom Norma: HRN EN 13508-2:2011 ( EN 13508-2:2003+A1:2011 ili jednakovrijedno)
B57: CCTV inspekcija vrši se specijaliziranim digitalnim robot-kamerama u svrhu:
B58: – utvrđivanja stvarnog stanja cjevovoda
B59: – lociranja propuštanja cjevovoda
B60: – traženja uzroka začepljenja cijevi
C61: kom | D61: 6 | F61: =D61*E61 -> 0
A63: 6. | B63: Priprema špaleta za RAL ugradnju zajedničkih prozora i vrata
...

Sheet A.I.2.pri
A2: TROŠKOVNIK GRAĐEVINSKO OBRTNIČKIH RADOVA
A3: A. GRAĐEVINSKI RADOVI / A.I.2. PRIPREMNI RADOVI (STAMBENE PROSTORIJE)
A4: r.b. | B4: opis stavke | C4: jed. | D4: kol. | E4: jed.cijena | F4: ukupno
A6: A. | B6: GRAĐEVINSKI RADOVI
A9: A.I.2. | B9: PRIPREMNI RADOVI (STANOVI)
A11: 1. | B11: Priprema špaleta za RAL ugradnju prozora i vrata loggia
B12: Obrada špaleta prozora i vrata loggia kao priprema za RAL ugradnju nakon demontaže postojeće i prije ugradnje nove stolarije: sanacija pukotina špaleta konstrukcijskim reparaturnim polimercementnim mortom, krpanje oštećenja na zidovima produžnim mortom, te izravnavanje većih neravnina grubom produžnom žbukom, uz adekvatnu pripremu. Špaletu pripremiti i otprašiti za pravilno ljepljenje brtvenih traka za RAL ugradnju prema uputama proizvođača. Stavka uključuje horizontalni i vertikalni transport šute i materijala po gradilištu, prijenos i odvoz otpadnog materijala i šute na deponij. Obračun po komadu otvora.
B13: pozicija stolarske stavke ST4 - dim. 81/157 cm | C13: kom | D13: 18 | F13: =D13*E13 -> 0
B14: pozicija stolarske stavke ST5a/b - dim. 181/157 cm | C14: kom | D14: 8 | F14: =D14*E14 -> 0
B15: pozicija stolarske stavke ST6a/b -dim. 81x237/130x157 cm | C15: kom | D15: 15 | F15: =D15*E15 -> 0
B16: pozicija stolarske stavke ST7a/b -dim. 130x157/141x2,37 cm | C16: kom | D16: 16 | F16: =D16*E16 -> 0
F17: =SUM(F13:F16) -> 0
A19: A.I.2. | B19: PRIPREMNI RADOVI (STANOVI) | E19: EUR | F19: =F17 -> 0

Sheet A.II.1.dem
A2: TROŠKOVNIK GRAĐEVINSKO OBRTNIČKIH RADOVA
A3: A. GRAĐEVINSKI RADOVI / A.II.1. RUŠENJA I DEMONTAŽE
A4: r.b. | B4: opis stavke | C4: jed. | D4: kol. | E4: jed.cijena | F4: ukupno
A7: A.II.1. | B7: RUŠENJA I DEMONTAŽE (ZAJEDNIČKI PROSTORI)
A9: OPĆI UVJETI
A11: Projekt energetske obnove zgrade izrađen je temeljem mogućih izmjera i pretpostavljenih zidnih, stropnih i krovnih slojeva. Dužnost je izvođača da sondiranjem utvrdi stvarni sastav konstrukcija i u slučaju odstupanja sastava upozori nadzornog inženjera i investitora na odstupanje.
A13: Prije početka radova potrebno je konstrukcije u koje ne zadiru radovi zaštititi od mogućeg oštećenja. Sve otvore na pročeljima zgrade treba odmah nakon postave skele zaštititi PVC folijom debljine 0,20 mm kako ne bi došlo do njihovog oštećenja.
A15: Nakon provedenih pripremnih radova, svih potrebnih rasterećenja i potrebnih osiguranja, rušenja na građevini vrše se prema unaprijed utvrđenom redoslijedu dogovorenim s nadzornim inženjerom na način kojim se ne ugrožava stabilnost zgrade, sigurnost radnika i ljudi koji borave u zgradi. Demontaže i rušenja izvode se u pravilu od krova prema podrumu/prizemlju.
A17: Sva rušenja i demontaže konstruktivnih elemenata treba izvršiti pod nadzorom projektanta. Kod vršenja proboja ili vođenja instalacija u nosivim konstrukcijama zahvat vršiti maksimalno precizno bez narušavanja nosivih svojstava konstrukcije. Prilikom zahvata na nosivim konstrukcijama obavezno je podupiranje. Sva rušenja, probijanja, bušenja i dubljenja treba u pravilu izvoditi ručnim alatom bez upotrebe vibracionih uređaja, s osobitom pažnjom.
A19: Demontažu i ponovnu montažu gromobrana, uz atestiranje, izvođač treba izvoditi prema Tehničkom propisu za sustave zaštite od djelovanja munje na građevinama (NN 87/08, 33/10).
A21: U cijenu radova trebaju biti uključene sve podupore, skele i privremene (zamjenske) konstrukcije, koje osiguravaju stabilnost u toku radova, svi horizontalni i vertikalni prijenosi materijala od rušenja i demontaže, i odvoz na gradsku planirku. U cijenu radova je uključeno i sigurno zbrinjavanje opasnih materijala (azbest, freoni). Ukoliko se uklanjaju elementi koji sadrže azbest to se mora učiniti u skladu s Pravilnikom o načinu i postupcima i gospodarenjem otpadom koji sadrži azbest (NN 42/07).
A23: Demontaža i privremeno deponiranje pločica sa kućnim brojem, natpisnih ploča, vanjskih jedinica rashladnih uređaja, gromobrana, strujnih ormarića i sl. uključuje njihovu sigurnu pohranu na gradilištu ili kod vlasnika. Izvođač snosi sve troškove ponovne dobave ili izrade pojedinih elemenata u slučaju oštećenja ili otuđenja sa gradilišta. Demontažu postojećih limenih elemenata, uključujući i prozorske klupčice na pročelju obavezno izvodi limar koji je dužan uzeti mjere i uzorke te snimiti detalje izvedbe, što je uključeno u cijenu stavke. Demontažu i ponovnu montažu postojećih vanjskih jedinica rashladnih uređaja na pročelju izvodi ovlašteni instalater. Demontažu i ponovnu montažu postojećeg gromobrana, strujnih ormarića i sl. na pročelju izvodi ovlaštena osoba.
A25: U slučaju nastalih šteta, radi nepravodobno zaštićene lokacije na kojoj se vrše rušenja i demontaže, sve troškove nastalih šteta snosi izvođač. Izvođač je dužan striktno se držati mjera zaštite na radu.
A27: 1. | B27: Demontaža i ponovna montaža montažnih elemenata na pročelju i krovu
B28: Demontaža, privremeno uklanjanje i ponovna montaža postojećih TV antena, kablova i pripadajućih kanalica, rasvjetnih tijela, razvodnih ormarića, i sl. sa svih pročelja i krova. Sve demontirane elemente potrebno je sigurno pohraniti na gradilištu. Nakon radova rušenja i demontaže kablove je potrebno ugraditi podžbukno u nove kanalice, a nakon izvedbe pročelja upotrebljive demontirane elemente potrebno je ponovno montirati, a neupotrebljive elemente odvesti na deponij udaljen 20 km. Otpajanje i ponovno spajanje svih vodova, uzemljenja i sl. vrši ovlaštena stručna osoba. Provjeriti točan broj prije nuđenja. Obračun po komadu.
C29: kom | D29: 20 | F29: =D29*E29 -> 0
A31: 2. | B31: Demontaža i ponovna montaža instalacijskog ormarića
B32: Demontaža i ponovna montaža strujnih, plinskih i drugih instalacijskih ormarića. radi izvedbe novog pročelja, uključujući otpajanje, prilagodbu i ponovno spajanje svih vodova, uzemljenja i sl. Demontažu i ponovnu montažu vrši ovlaštena osoba. Obračun za izvođenje kompletnih pripremnih radove iz opisa stavke, po komadu.
C33: kom | D33: 3 | F33: =D33*E33 -> 0
A35: 3. | B35: Demontaža limenih i PVC elemenata na pročelju
B36: Demontaža postojećih opšavnih limova nadozida krova, opšavnih limova ograda i PVC okapnica, spuštanje i deponiranje uz građevinu. Demontirati kompletno, uključivo pričvrsno spojni pribor (nosači,"klameri", drvene kajle i sl.), kao i lagano odštemavanje djela žbuke koja prelazi preko limenog opšava. Predvidjeti i odvoz na deponij. U stavku je uključen i prijenos i odvoz otpadnog materijala i šute na deponiju na udaljenosti do 20 km. Demontažu postojećih limenih elemenata obavezno izvodi limar koji je dužan uzeti mjere i uzorke te snimiti detalje izvedbe u skladu s glavnim projektom, što je uključeno u cijenu stavke. Ponovna izrada i montaža, odnosno zamjena dotrajalih dijelova novim, opisana je u limarskim radovima. Obračun po m¹.
B37: kape na parapetu balkona, r.š. cca 15 cm | C37: m¹ | D37: 110 | F37: =D37*E37 -> 0
B38: kape na rubnom zidu neprohodnog ravnog krova, r.š. cca 25 cm | C38: m¹ | D38: 136.5 | F38: =D38*E38 -> 0
F39: =SUM(F37:F38) -> 0
A41: 4. | B41: Demontaža vanjskih limenih i pvc klupčica
B42: Demontaža vanjskih prozorskih pvc klupčica i klupčica od pocinčanog lima 0,55 mm razvijene širine cca 20 cm. Stavka uključuje sav potreban rad, alat, prijenos i odlaganje na deponij na udaljenostid do 20 km. Obračun se vrši po m¹.
C43: m¹ | D43: 367 | F43: =D43*E43 -> 0
A45: 5. | B45: Demontaža vrata i prozora zajedničkih prostora stubišta
B46: Demontaža ulaznih vrata i prozora stubišta. Dimenzije su izražene u zidarskim (građevinskim mjerama). Uključen sav transport i zbrinjavanje otpada na deponiju udaljenom do 20 km. Obračun po komadu stolarske stavke.
B47: pozicija stolarske stavke ST1a/1b - dim. 61/61 cm | C47: kom | D47: 66 | F47: =D47*E47 -> 0
B48: pozicija stolarske stavke ST2 - dim. 271/121 cm | C48: kom | D48: 3 | F48: =D48*E48 -> 0
B49: pozicija stolarske stavke ST3 - dim. 81/221 cm | C49: kom | D49: 6 | F49: =D49*E49 -> 0
F50: =SUM(F47:F49) -> 0
A52: 6. | B52: Demontaža i ponovna montaža postojećeg gromobrana
B53: Demontaža postojeće gromobranske instalacije i ponovna montaža gromobranske instalacije, koja povezuje sustav hvataljki i sustav uzemljenja. Instalacija nakon rekonstrukcije mora zadovoljavati propise koje je zadovoljavala i prije rekonstrukcije (atest). Izložene podzemne segmente gromobranskog profila zaštiti bitumenskim premazom (bitumenskim lakom). U stavku je uključeno prethodno ispitivanje sustava, kompletan vertikalni i horizontalni transport, sva potrebna prilagođavanja i produljenja za potpuno funkcionalnu izvedbu stavke, te kompletno zbrinjavanje otpadnog materijala i šute. Obračun po m¹ ugrađene gromobranske trake.
C54: m¹ | D54: 390 | F54: =D54*E54 -> 0
A56: 7. | B56: Prilagodba sustava zaštite od munje sa ugradnjom ormarića za mjerni spoj
B57: Prilagodba postojeće gromobranske instalacije zbog izvedbe ETICS sustava. Dobava i montaža pocinčanog ormarića za mjerni spoj veličine 230x180x90 namjenjenog za smještaj mjernoga mjesta unutar zida. Sastavljen je od plastične kutije veličine 185x135x50 otporne na atmosferske utjecaje i poklopca ormarića izrađenog od Fe-Zn ili AiSi koji može biti i elektrostatski plastificiran. Kutija se ugrađuje u zid objekta 4-8 cm od površine novoizvedene fasade. Poklopac se montira nakon završetka fasaderskih radova distantnim vijcima. Prošireni okvir pokriva ostavljeni otvor a distantni vijci omogučavaju pritezanje okvira u rasponu od 4-8 cm. Izraditi prema propisima i standardima. Instalacija nakon rekonstrukcije mora zadovoljavati propise koje je zadovoljavala i prije rekonstrukcije (atest). Izložene podzemene segmente gromobranskog profila zaštiti bitumenskim premazom (bitumenskim lakom). U stavku je uključen kompletan vertikalni i horizintalni transport, sva potrebna prilagođavanja i produljenja za potpuno funkcionalnu izvedbu stavke. Obračun po komadu za ugrađene ormariće.
C58: kom | D58: 8 | F58: =E58*D58 -> 0
A60: 8. | B60: Demontaža i ponovna montaža rasvjetnih tijela i instalacija u razizemlju
...

Sheet A.II.2.dem
A2: TROŠKOVNIK GRAĐEVINSKO OBRTNIČKIH RADOVA
A3: A. GRAĐEVINSKI RADOVI / A.II.2. RUŠENJA I DEMONTAŽE (STAMBENE PROSTORIJE)
A4: r.b. | B4: opis stavke | C4: jed. | D4: kol. | E4: jed.cijena | F4: ukupno
A7: A.II.2. | B7: RUŠENJA I DEMONTAŽE (STANOVI)
A10: 1. | B10: Demontaža i zbrinjavanje postojećih prozora grijanih prostorija stanova
B11: Demontaža postojećih prozora i balkonskih vrata u stanovima koji se mijenjaju, uključujući i prozorske klupčice, pragove i kutije za flos ili eslinger roletu. Dimenzije su izražene u zidarskim (građevinskim mjerama). Uključen sav transport i zbrinjavanje otpada na deponiju udaljenom 20 km. Obračun po komadu stolarske stavke.
B12: pozicija stolarske stavke ST7 - dim. 81/157 cm | C12: kom | D12: 18 | F12: =D12*E12 -> 0
B13: pozicija stolarske stavke ST5a/b - dim. 181/157 cm | C13: kom | D13: 8 | F13: =D13*E13 -> 0
B14: pozicija stolarske stavke ST6a/b -dim. 81x237/130x157 cm | C14: kom | D14: 15 | F14: =D14*E14 -> 0
B15: pozicija stolarske stavke ST7a/b -dim. 130x157/141x2,37 cm | C15: kom | D15: 16 | F15: =D15*E15 -> 0
F16: =SUM(F12:F15) -> 0
A18: A.II.2. | B18: RUŠENJA I DEMONTAŽE UKUPNO (STANOVI): | E18: EUR | F18: =F16 -> 0

Sheet A.III.1.zid
A2: TROŠKOVNIK GRAĐEVINSKO OBRTNIČKIH RADOVA
A3: A. GRAĐEVINSKI RADOVI / A.IV.1. ZIDARSKI RADOVI (ZAJEDNIČKE PROSTORIJE)
A4: r.b. | B4: opis stavke | C4: jed. | D4: kol. | E4: jed.cijena | F4: ukupno
A7: A.IV.1 | B7: ZIDARSKI RADOVI (ZAJEDNIČKI PROSTORI)
A9: OPĆI UVJETI
A11: Opći uvjeti su sastavni dio svake pojedine stavke. Sve što je navedeno u njima, a nije u pojedinačnom opisu stavke smatra se uključenim u jediničnu cijenu.
A13: Sve radove izvođač mora izvoditi prema troškovniku i glavnom projektu, solidno i stručno, prema pravilima dobrog zanata, Pravilniku o tijelima, dokumentaciji i postupcima tržišta građevnih proizvoda (NN 118/19), Pravilniku o tehničkim normativima za projektiranje i izvođenje završnih radova u građevinarstvu (Sl.list SFRJ 21/90), Tehničkim propisom za građevinske konstrukcije (NN 17/17, 75/20, 7/22 - uz prikladne norme HRN EN 1990 ili jednakovrijedno _________________,HRN EN 1991 ili jednakovrijedno _________________, HRN EN 1996 ili jednakovrijedno _________________, HRN EN 1997 ili jednakovrijedno _________________ i HRN EN 1998 ili jednakovrijedno _________________, NN 75/20), Tehničkim propisom o racionalnoj uporabi energije i toplinskoj zaštiti u zgradama („Narodne novine“ broj 128/15, 70/18., 73/18, 86/18, 102/20) sa pripadajućim normama, Tehničkim propisom o građevnim proizvodima (NN 35/18, 104/19), te svim ostalim hrvatskim i europskim tehničkim propisima i normama i priznatim tehničkim pravilima, ili jednakovrijedno, a osobito :
A15: EN 1015-7 ili jednakovrijedno _________________, zapreminska masa i poroznost svježeg morta EN 1015-3 ili jednakovrijedno _________________, konzistencija svježeg morta EN 1015-11, tlačna i savojna vlačna čvrstoća morta EN 771-1 ili jednakovrijedno _________________, EN 772-1 ili jednakovrijedno _________________, EN 7723 ili jednakovrijedno _________________, EN 772-13 ili jednakovrijedno _________________, EN 772-16 ili jednakovrijedno _________________, HRN EN 14063-1:2008 ili jednakovrijedno _________________, tlačna čvrstoća opeke, na mjestu primjene oblikovani proizvodi od lakoagregatne eksp. gline
A17: HRN B.C1.030, B.C8.030 ili jednakovrijedno _________________, građevinski gips HRN B.C1.020, B.C8.030 ili jednakovrijedno _________________, građevinsko vapno HRN B.C8.015,022 – 026 ili jednakovrijedno _________________, cement HRN B.C8.011 ili jednakovrijedno _________________, portland cement HRN B.C8.030 ili jednakovrijedno _________________, pijesak HRN U.M2.010, U.M2.012 ili jednakovrijedno _________________, mortovi HRN U.F2.010 ili jednakovrijedno _________________, tehnički normativi za izvođenje fasaderskih radova
A19: HRN EN 1008, HRN EN 13139;2003+AC;2006 ili jednakovrijedno _________________, voda i pijesak HRN EN 197-1:2012 ili jednakovrijedno _________________, cement HRN EN 459-1:2015 ili jednakovrijedno _________________, vapno
A21: Svi upotrebljeni materijali za izvedbu zidarskih radova moraju odgovarati navedenim propisima i normama. Izvođač mora prije izvedbe izvršiti pregled podloge te prodora u zidu prema nacrtu u prisutnosti nadzornog inženjera te upisati napomenu u građevinski dnevnik. Navedene radnje uključene su u jediničnu cijenu.
A23: Izvođač je dužan osigurati i zaštititi sve dijelove građevine na kojima se izvode radovi, radi sprečavanja oštećenja tijekom izvedbe. Sva oštećenja na dijelovima na kojima se ne izvode radovi ili koja su nastala nepažnjom izvođača isti je dužan otkloniti o vlastitom trošku.
A25: Sav rad i transport vrši se isključivo sa vanjske strane građevine, tj. preko skele. Zidarsko-fasaderski radovi se izvode na dobro očišćenoj i otprašenoj površini zida te ih treba izvoditi samo u povoljnim vremenskim uvjetima, uz odgovarajuće osiguranje i zaštitu svježe ožbukanih površina od štetnog utjecaja djelovanja sunca i oborina. Sve detalje izvedbe na pročelju potrebno je dogovoriti i na njih ishoditi suglasnost nadzornog inženjera, a prije pristupanja izvedbi radova. Obračun svih radova vršiti kako je to naznačeno u opisu stavke.
A27: Prilikom izvođenja zidova zgrada izvođač se mora pridržavati slijedećih mjera: - zidanje se mora izvoditi sa pravilnim zidarskim vezovima, a preklop mora iznositi najmanje jednu četvrtinu dužine zidnog elementa, - debljina ležajnica ne smije biti veća od 15 mm, a širina sudarnica ne smije biti manja od 10 mm niti veća od 15 mm, - ako se zida za vrijeme zime treba zidove zaštiti od mraza, - zidovi čije izvođenje nije završeno prije nastupanja zimskih mrazova moraju se zaštiti na odgovarajući način, - svako naknadno bušenje ili izrada užljebina u zidovima zgrade koje nije bilo predviđeno projektom, može se izvoditi samo ako je prethodnim statičkim proračunom utvrđeno da nosivost zida poslije tog bušenja odnosno izrade žlijeba nije manja od propisane nosivosti. - poprečni i uzdužni zidovi moraju na spoju biti međusobno povezani zidarskim vezom, tj. za pregradne zidove treba ispustiti zupce u masivnom zidu na svaki drugi red za ½ opeke. - zidove uz vertikalni serklaž također zupčasto izvesti. - vanjske fuge ostaviti prazne od 1,5 do 2 cm za vezu žbuke prigodom žbukanja zidova. - za vrijeme zidanja opeku kvasiti vodom, a pri zidanju cementnim mortom opeka mora ležati u vodi neposredno prije zidanja - reške dimnjaka i ventilacionih kanala zagladiti. - prilikom zidanja pravovremeno ostaviti otvore prema zidarskim mjerama, voditi računa o uzidavanju pojedinih građevinskih elemenata, o ostavljanju žljebova za kanalizaciju, za centralno grijanje ako su ucrtani (ne plaća se posebno, ulazi u jediničnu cijenu)
A29: Posebno se ne naplaćuje ni zatvaranje (žbukanje šliceva, žljebova i sl.) iza položene instalacije. Zazidavanje (zatvaranje) žljebova u zidovima ostavljenih za instalacije kanalizacije i grijanja nakon izvođenja tih instalacija, opekom, rabicom ili na drugi način, ne plaća se posebno, ukoliko troškovnikom nije posebno propisano. Obračun nosivih zidova, stupova i dimnjaka je zapreminski (m3), pregradnih zidova i žbuka površinski (m2).
A31: Žbukati tek kada se zidovi osuše i slegne zgrada. Ne smije se žbukati kad postoji opasnost od smrzavanja ili ekstremno visokih temperatura 30° ili više. Zidovi moraju biti prije žbukanja čisti, a fuge udubljene, da se žbuka može dobro primiti.
... A38: Izvođač će pristupiti izvedbi završnih zidarskih radova tek nakon što projektant potpisom potvrdi tehnološku razradu svih detalja.
A39: 1. | B39: Popravci žbuke nakon ugradnje nove stolarije
B40: Stavka obuhvaća sve popravke oštećene unutarnje žbuke zidova, stropova i špaleta oko otvora koji su oštećeni prilikom izvođenja radova rušenja i demontaže fasadnih stavki, instalacija i sl, nakon ugradnje novih stolarskih stavki. Postojeću podlogu potrebno je prethodno impregnirati i obraditi reparaturnim mortom.
B41: Sve kuteve i bridove učvrstiti kutnim profilima. Sve betonske površine prethodno premazati sredstvom za povećanje prionjivosti. Sve spojeve različitih materijala potrebno je rabicirati. Kod popravaka postojeće žbuke, za zapunjavanje otvora, reški i šliceva upotrijebiti prikladan materijal (polistiren, gips ploče, opeka, porobeton ili sl.) što je uključeno u stavku.
B42: Stavkom je obuhvaćeno žbukanje površina od opeke i od armiranog betona. Žbukanje se vrši grubom produžnom podložnom žbukom i finom žbukom. Žbuka mora biti potpuno ravna, ukupna debljina žbuke mora biti u istoj ravnini sa postojećom žbukom, a završni sloj fino zaglađen.
B43: pozicija stolarske stavke ST1a/1b - dim. 61/61 cm | C43: kom | D43: 66 | F43: =D43*E43 -> 0
B44: pozicija stolarske stavke ST2 - dim. 271/121 cm | C44: kom | D44: 3 | F44: =D44*E44 -> 0
B45: pozicija stolarske stavke ST3 - dim. 81/221 cm | C45: kom | D45: 6 | F45: =D45*E45 -> 0
F46: =SUM(F43:F45) -> 0
A48: 2. | B48: Uklanjanje oštećenog betona i izvedba lokalnih popravaka sanacijskim mortom
B49: Pregled konstrukcije radi utvrđivanja mjesta oštećenog, nezdravog ili kontaminiranog betona, te uklanajnje oštećenog zaštitnog sloja. Obavezno čišćenje korodirane armature prije postupka sanacije te nanošenje sloja zaštite od daljnjeg razvoja korozije. Nanošenje površinske zaštite od sanacijskog morta. Posebno obratiti pažnju na potpunu sanaciju ulaznih vanjskih stubišta, kao i kapa dimnjaka i ventilacijskih kanala na krovu.
B50: Obračun prema m2 obrađene površine | C50: m2 | D50: 60 | F50: =D50*E50 -> 0
A52: 3. | B52: Zidarski popravci i pripomoć
B53: Razna zidarska pripomoć, krpanja pukotina i popravci žbuke i prodora prilikom izvođenja radova. Obračun po m2 obrađene plohe. | C53: m2 | D53: 60 | F53: =D53*E53 -> 0
A55: A.IV.1. | B55: ZIDARSKI RADOVI UKUPNO (ZAJEDNIČKI PROSTORI): | E55: EUR | F55: =F46+F50+F53 -> 0

Sheet A.III.2.zid
A2: TROŠKOVNIK GRAĐEVINSKO OBRTNIČKIH RADOVA
A3: A. GRAĐEVINSKI RADOVI / A.IV.2. ZIDARSKI RADOVI (STANOVI)
A4: r.b. | B4: opis stavke | C4: jed. | D4: kol. | E4: jed.cijena | F4: ukupno
A6: A.IV.2. | B6: ZIDARSKI RADOVI (STANOVI)
A8: 1. | B8: Popravci žbuke nakon ugradnje nove stolarije
B9: Stavka obuhvaća sve popravke oštećene unutarnje žbuke zidova, stropova i špaleta oko otvora koji su oštećeni prilikom izvođenja radova rušenja i demontaže fasadnih stavki, instalacija i sl, nakon ugradnje novih stolarskih stavki. Postojeću podlogu potrebno je prethodno impregnirati i obraditi reparaturnim mortom.
B10: Sve kuteve i bridove učvrstiti kutnim profilima. Sve betonske površine prethodno premazati sredstvom za povećanje prionjivosti. Sve spojeve različitih materijala potrebno je rabicirati. Kod popravaka postojeće žbuke, za zapunjavanje otvora, reški i šliceva upotrijebiti prikladan materijal (polistiren, gips ploče, opeka, porobeton ili sl.) što je uključeno u stavku.
B11: Stavkom je obuhvaćeno žbukanje površina od opeke i od armiranog betona. Žbukanje se vrši grubom produžnom podložnom žbukom i finom žbukom. Žbuka mora biti potpuno ravna, ukupna debljina žbuke mora biti u istoj ravnini sa postojećom žbukom, a završni sloj fino zaglađen.
B12: pozicija stolarske stavke ST7 - dim. 81/157 cm | C12: kom | D12: 18 | F12: =D12*E12 -> 0
B13: pozicija stolarske stavke ST5a/b - dim. 181/157 cm | C13: kom | D13: 8 | F13: =D13*E13 -> 0
B14: pozicija stolarske stavke ST6a/b -dim. 81x237/130x157 cm | C14: kom | D14: 15 | F14: =D14*E14 -> 0
B15: pozicija stolarske stavke ST7a/b -dim. 130x157/141x2,37 cm | C15: kom | D15: 16 | F15: =D15*E15 -> 0
F16: =SUM(F12:F15) -> 0
A18: A.III.2. | B18: ZIDARSKI RADOVI UKUPNO (STANOVI): | E18: EUR | F18: =F16 -> 0

Sheet A.IV.izo
A2: TROŠKOVNIK GRAĐEVINSKO OBRTNIČKIH RADOVA
A3: A. GRAĐEVINSKI RADOVI / A.V. IZOLATERSKI RADOVI
A4: r.b. | B4: opis stavke | C4: jed. | D4: kol. | E4: jed.cijena | F4: ukupno
A6: A.V. | B6: IZOLATERSKI RADOVI
A8: OPĆI UVJETI
A10: Sve radove izvođač mora izvoditi prema troškovniku i glavnom projektu, solidno i stručno, prema pravilima dobrog zanata, Pravilniku o tijelima, dokumentaciji i postupcima tržišta građevnih proizvoda (NN 118/19), Pravilniku o tehničkim normativima za projektiranje i izvođenje završnih radova u građevinarstvu (Sl.list SFRJ 21/90), Tehničkim propisom za građevinske konstrukcije (NN 17/17, 75/20, 7/22 - uz prikladne norme HRN EN 1990,HRN EN 1991 ili jednakovrijedno _________________, HRN EN 1996, HRN EN 1997 ili jednakovrijedno _________________ i HRN EN 1998 ili jednakovrijedno _________________, NN 75/20), Tehničkim propisom o racionalnoj uporabi energije i toplinskoj zaštiti u zgradama („Narodne novine“ broj 128/15, 70/18., 73/18, 86/18, 102/20) sa pripadajućim normama, Tehničkim propisom o građevnim proizvodima (NN 35/18, 104/19), Tehničkim uvjetima za projektiranje i građenje zgrada - Akustika u građevinarstvu (HRN U.J6.201/89 ili jednakovrijedno _________________), te svim ostalim tehničkim propisima, priznatim tehničkim pravilima i HR normama, ili jednakovrijedno.
A12: Izvođač radova mora za sve materijale koje će upotrijebiti za izvedbu izolacije pribaviti odgovarajuće dokaze o sukladnosti. Hidroizolaciju, toplinsku ili zvučnu izolaciju treba izvoditi prema specifikaciji radova i tehničkim uvjetima izvođenja.
A14: Površine na koje se polaže izolacija trebaju biti ravne i očišćene od prašine ili drugih nečistoća. Toplinsku i zvučnu izolaciju potrebno je izvesti kontinuirano bez reški kako bi se spriječili toplinski ili zvučni mostovi.
A16: Nakon izvedbe svakog sloja izolacije nadzorni organ treba izvršiti pregled, a tek nakon pozitivnog mišljenja i upisa u građevinski dnevnik može se nastaviti sa radom.
A18: Skladištenje materijala na gradilištu mora biti stručno kako bi se isključila bilo kakva mogućnost propadanja. Nepravilno i nekvalitetno izvedene radove izvođač mora na svoj trošak ukloniti i izvesti pravilno.
A20: Izvođač je dužan sve izvoditi prema uputama proizvođača, isporučitelja materijala te ovjerenih detalja. Izvođač će pristupiti izvedbi tek nakon što projektant potpisom potvrdi tehnološku razradu svih detalja. Izrada rješenja neće se posebno naplatiti već predstavlja trošak i obavezu izvođača.
A22: HIDROIZOLACIJA Sve hidroizolaterske radove treba izvesti solidno i stručno držeći se projektne dokumentacije, propisa, opisa iz troškovnika, uputa proizvođača i pravila dobrog zanata. Prije početka radova izvođač mora ustanoviti kvalitetu podloge na kojoj se izvodi izolacija i ako nije pogodna za rad mora o tome izvijestiti naručitelja radova kako bi se podloga na vrijeme popravila i pripremila za izvođenje izolacije.
A24: Sav materijal za izolaciju treba odgovarati propisima i normativima. Izolacijsku ljepenku i ostale vrste izolacijskih traka i ploča treba rezati ravno i pravokutno. Zaderani i krpani komadi ne smiju se ugrađivati. Svi preklopi moraju biti najmanje 10 cm široki i lijepljeni varenjem. Kod polaganja dvaju ili više slojeva izolacijskih traka ili ploča preklopi ne smiju ležati jedan na drugom, već moraju biti pomaknuti.
A26: Kod hidroizolacije zidova ljepenka treba na svaku stranu zida imati prihvat širine od 10 cm, koji treba spojiti s horizontalnom izolacijom podova. Površine na koje se polaže izolacija, trebaju biti posve ravne, suhe, očišćene od prašine i nečistoće i dovoljno glatke kako bi izolacija dobro prionula. Izolacija treba prilegnuti na površinu ravno, bez nabora i mjehura. U cijeni također treba uključiti obradu slojeva izolacije i izvedbu holkera uz vertikalne zidove, oko raznih prodora kroz slojeve izolacije (instalacije), kao i ugradnje završnih profila i sl.
A28: Posebnu pažnju obratiti na zaštitu od požara kod rada s vrućim bitumenskim premazima i varenim ljepenkama zbog velike zapaljivosti bitumena. U slučaju požara gasiti pijeskom ili pjenom. Gašenje vodom je opasno zbog prskanja vrelog bitumena.
A30: Svi materijali za izvedbu hidroizolaterskih radova moraju u pogledu kvalitete odgovarati HR normama koje propisuje Tehnički propis o građevnim proizvodima (NN 35/18), sukladno normi koja se odnosi na određeni proizvod, ili jednakovrijedno, a osobito:
... A50: Ukoliko je to moguće izvršiti provjeru postojećeg stanja konstrukcije prije nuđenja. Nakon demontaže i uvida u postojeće stanje nosive konstrukcije napraviti provjeru opterećenja, izračun opterečenja uklonjenih slojeva u odnosu na slojeve novog krova mora biti odobren od strane inženjera konstrukcije. U slučaju potrebe za odstupanjem od predviđenih slojeva, isti se neće obračunavati kao dodatni rad. U cijeni predvidjeti eventualno potrebne izmjene na licu mjesta zbog specifičnosti zadatka (sanacija). Izvoditelj treba imati radnike s odgovarajućim iskustvom, obučene i ovlaštene od proizvođača materijala.
A51: 1. | B51: Toplinska izolacija stropa negrijanog razizemlja iznad zajedničkih prostora- MK1, iznad garaža -MK2
B52: NAPOMENA: Sve mjere izvedbe, kao i postojeće konstukcije provjeriti na licu mjesta prije planiranja i organizacije radova.
B53: Izvedba toplinske izolacije podgleda stropa negrijanog razizemlja, sa svim potrebnim predradnjama i pripremom podloge. Toplinska izolacija na bazi mineralne (kamene) vune (λ=0,35 W/mK), debljine 16 cm, s jedne strane obložene specijalnim staklenim voalom pogodnim za direktno nanošenje boje. Ploče mineralne (kamene) vune ljepe se i mehanički su učvršćene metalnim držačima s metalnim diskom (min. ø80 mm), sve prema preporuci proizvođača. Montaža bez dodatne podkonstrukcije.
B54: Prije početka radova investitor je dužan raščistiti i omogućiti pristup svim prostorijama podruma kako bi se radovi neometano mogli izvesti.
B55: Sve radove treba izvesti isključivo po uputama, koristeći materijale, alate i način izvođenja po tehnologiji proizvođača, prema gl. arhitektonskom projektu i detaljima, te projektu racionalne uporabe energije i toplinske zaštite z.o.p. SAE 168-2024 Obračun po m² izvedene površine.
B56: MV, deb. 16 cm | C56: m² | D56: 572 | F56: =D56*E56 -> 0
A58: 2. | B58: Izvedba slojeva ravnog neprohodnog krova iznad 4. kata - oznaka RK1,RK1.1
B59: NAPOMENA: Sve mjere izvedbe, kao i postojeće konstukcije provjeriti na licu mjesta prije planiranja i organizacije radova.
B60: Izvođenje slojeva ravnog neprohodnog krova s vertikalnim dizanjem uz konstrukciju vanjskog zida zgrade - vijenca, dimnjake, odzračnike i ventilacijske kanale min 30 cm. Hidroizolacija je mehanički fiksirana te hermetizirana jednokomponentnim poliuretanskim trajnoelastičnim kitom koji čini čvrstu ali visoko elastičnu brtvu niskog modula elastičnosti i prikladan je za horizontalne i vertikalne aplikacije te se može aplicirati na velikom rasponu temperatura. Jediničnom cijenom uključeni svi spojni elementi: otvoreni, zatvoreni i kutni prelazi i završni elementi. Osobitu pažnju posvetiti holkeru i završnom učvršćenju i brtvljenju hidroizolacije.
B61: Postava hidroizolacije prema uputstvima, programu i izvedbenom troškovniku proizvođača, sve komplet u cijeni do pune gotovosti po iskazanim stavkama.
B62: Nakon uklanjanja ostataka sloja šljunka, na očišćenu podlogu postojeće hidroizolacije se sljedeći radovi:
A63: a) | B63: Dobava i polaganje toplinske izolacije - dvoslojne tvrde ploče mineralne (kamene) vune za ravne prohodne krovove (na prethodno postavljenu parnu branu), ploča od dva sloja (12 + 6 cm) različite gustoće (sloj veće gustoće postavljen na gornjoj strani), koeficijent toplinske provodljivosti λ≤0,036 W/mK, klasa negorivosti A1, ukupne debljine 18 cm na horizontalnim odn. 5cm na vertikalnim dijelovima, gustoće 190 kg/m³ gornji sloj, 90 kg/m³ donji sloj. Sve detalje izvesti na način koji propisuje proizvođač toplinske izolacije. Izvoditelj treba imati radnike s odgovarajućim iskustvom, obučene i ovlaštene od proizvođača materijala.
A64: b) | B64: Dobava i polaganje jednoslojnih hidroizolacijskih membrana od sintetičke gume (TPO-a) debljine 1,5 mm, energetski učinkovitih reflektirajuće bijele ili sive boje, trajno otpornih na UV zrake, većinu kemijskih spojeva, mikroorganizme i korijenje. Membrana je punoplošno armirana gustim poliesterskim pletivom, potpuno homogene i trajno stabilne strukture cijelog presjeka. Zadržava trajnu dimenzionalnu stabilnost u ekstremnim temperaturnim rasponima, uz visoke otpornosti na sile vlačnih naprezanja i točkastih proboja. mehanički učvršćena za podlogu. Hidroizolacijske membrane se polažu na geotekstil ili toplinsku izolaciju (sve prema uputama proizvođača) i ugrađuju u sustavu mehanički pričvršćenih membrana. Rubovi membrana se međusobno preklapaju i zavaruju vrućim zrakom kako bi se postigao potpuno homogen spoj (min preklapanje prema uputama proizvođača). Membrana se vertikalno uzdiže uz konstrukciju vanjskog nadozida zgrade, krovnih svjetlika, dimnjaka, odzračnika i ventilacijskih kanala. Na svojim završetcima membrana se vari na TPO limove. Sve spojeve izvesti na način da se osigura vodotijesnost membrane. Izvoditelj treba imati radnike s odgovarajućim iskustvom, obučene i ovlaštene od proizvođača materijala.
A65: c) | B65: Obrada prodora (npr. vertikalna konstrukcija krovnog svjetlika, dimnjaci, odzračnici, ventilacijski kanali) kroz hidroizolaciju nearmiranom TPO membranom ili tipskom TPO prirubnicom. Završetak se kita jednokomponentnim poliuretanskim kitom koji čini čvrstu, ali visoko elastičnu brtvu niskog modula elastičnosti i prikladan je za horizontalne i vertikalne aplikacije te se može aplicirati na velikom rasponu temperatura i priteže obujmicom. Izvesti prema projektu i detalju proizvođača.
A66: d) | B66: Izvedba detalja na mjestu sudara horizontalnih i vertikalnih površina koje se hidroizoliraju. Detalj se izvodi na način da se ugrađuje prefabricirani perforirani Fe/Zn profil povećane krutosti koji se mehanički učvršćuje za podlogu sa min. 4,0 kom/m¹ pričvršćivača. Izvesti prema projektu i detalju proizvođača.
A67: e) | B67: Dobava i ugradnja vertikalnog slivnika od TPO-a u slivničke vertikale (∅kao postojeći, potrebna izmjera prije nuđenja). Slivnici se mehanički pričvršćuju za podlogu, i na njih se vari hidroizolacija. Izvesti prema projektu i detalju proizvođača. Prirubnice krovnih slivnika trebale bi biti upuštene u konstrukciju ispod hidroizolacije (Napomena: Kod termički izolIranih krovnih konstrukcija sa parnom branom trebaju se koristiti dvodijelni termički izolirani krovni slivnici). Tvornički prerađeni krovni slivnici moraju odgovarati DIN EN 1253 „Slivnici za objekte“ ili jednakovrijedno________________.
A68: f) | B68: Dobava i montaža dvostrukih okomitih odzračnika na bazi tvrdog PVC-a, toplinski izoliranih sa ekspandiranim polietilenom (EPE), sa mogućnošću spajanja na parnu branu i na hidroizolaciju, promjera Ǿ110 i visine 500mm. Jedan na svakih 250-350 m2. Obračun po komadu ugrađenog elementa.
A70: 2.1 | B70: Svi navedeni slojevi horizontalne toplinske izolacije od mineralne vune deb. 18 cm i hidroizolacije od TPO membrane (a-c) na horizontalnim dijelovima krova. Izvesti prema projektu i detalju proizvođača. (po potrebi razdjelni slojevi). Detalji D3, D5 .
B71: TPO membrana | C71: m2 | D71: 680 | F71: =D71*E71 -> 0
B72: MV, deb. 18 cm | C72: m2 | D72: 660 | F72: =D72*E72 -> 0
B73: parna brana (PE) | C73: m2 | D73: 690 | F73: =D73*E73 -> 0
A75: 2.2 | B75: Svi navedeni slojevi vertikalne hidroizolacije od TPO membrane, v = 20 cm i toplinske izolacije od kamene vune deb. 5 cm, v = 15 cm uz krovni nadozid. Izvesti prema projektu i detalju proizvođača. Detalj D3.
B76: TPO membrana | C76: m2 | D76: 32 | F76: =D76*E76 -> 0
...

Sheet A.V.zem
A2: TROŠKOVNIK GRAĐEVINSKO OBRTNIČKIH RADOVA
A3: A. GRAĐEVINSKI RADOVI / A.V.ZEMLJANI RADOVI
A4: r.b. | B4: opis stavke | C4: jed. | D4: kol. | E4: jed.cijena | F4: ukupno
A7: A.III. | B7: ZEMLJANI RADOVI UKUPNO:
A9: OPĆI UVJETI
A11: Prije početka radova potrebno je provjeriti da li trase postojećih instalacijskih vodova na gradilištu i u blizini kolidiraju s iskopom ili radnim prostorom potrebne mehanizacije. Prije početka zemljanih radova, teren treba očistiti od šiblja i korova. Ovi radovi kao i radovi oko razmjeravanja terena i obilježavanja zgrade uračunati su u jedinične cijene.
A13: Dužnost je izvođača da utvrdi pravi sastav tla. Ukoliko izvođač prilikom iskopa zemlje naiđe na bilo kakve predmete, objekte ili instalacije, dužan je na tom mjestu obustaviti radove i o tome obavijestiti projektanta i nadzornog inženjera.
A15: Iskopani materijal treba odlagati na dovoljnom odstojanju od ruba iskopa da ne dođe do urušavanja. Podupiranja, razupiranja i zaštita iskopa od oborinskih voda prekrivanjem PVC folijama i izvedbom površinske odvodnje kanalima i muljnim crpkama, obuhvaćena su jediničnim cijenama. Potrebna građa za podupiranje mora biti pripremljena na gradilištu prije početka iskopa. Ako se iskopane jame oštete, odrone ili zatrpaju nepažnjom ili uslijed nedovoljnog podupiranja, izvođač ih dovodi u ispravno stanje bez posebne naknade. Ukoliko je izvođač otkopao tlo ispod projektom predviđene temeljne ravnine obavezan je bez naknade popuniti tako nastale šupljine betonom C 8/10, do projektirane kote. Zabranjeno je popunjavanje prekopa nasipom šljunka.
A17: Količine iskopa, transporta i nasipa zemlje obračunavaju se prema sraslom stanju tla. Iskopani materijal upotrijebiti za nasipavanje i zatrpavanje. Isti treba prevesti na gradilišni deponij, uskladištiti te poslije upotrijebiti. Višak iskopanog materijala odvesti na gradski deponij. U cijenu zbrinjavanja otpadnog materijala uključiti plaćanje svih potrebnih troškova da bi se otpad kompletno zbrinuo.
