Workbook

Sheet Opći uvjeti i napomene
B2: INVESTITOR: MINISTARSTVO UNUTARNJIH POSLOVA RH
B3: LOKACIJA: JASTREBARSKO, ZRINSKI-FRANKOPANSKA ULICA BB
B4: GRAĐEVINA: ZGRADE BR. 11, 12, 13, 14, 15, 20, 21, 61, 62 I VANJSKI PROSTOR
B5: RADOVI: UREĐENJE GRAĐEVINA, VANJ. PROSTORA I INFRASTRUKTURE
B6: PROJEKTANT: APG-INŽENJERING d.o.o. DUGO SELO
B33: TROŠKOVNIK GRAĐEVINSKO-OBRTNIČKIH I INSTALATERSKIH RADOVA
B62: ožujak 2026. godine
A64: stavka | B64: opis stavke | C64: jedin. mjere | D64: količina | E64: edinična cijena (euro) | F64: ukupno (euro)
B66: OPĆI UVJETI I NAPOMENE
B68: JEDINIČNA CIJENA
B69: U jediničnim cijenama za sve stavke troškovnika, ponuda mora sadržavati ukupne troškove materijala i rada do potpunog dovršenja cjelokupnog posla odnosno do pune funkcionalnosti. Jedinična cijena, također, uključuje sva potrebna ispitivanja, kontrole i mjerenja za sve izvedene radove, ugrađene materijale i opremu. Sve predmetno je obuhvaćeno jediničnom cijenom i ne navodi se kao zasebna stavka. Trošak pribavljanja sve atestne dokumentacije uključiti u cijenu nuđenih stavki, jer se posebni troškovi neće priznati. Izvođač treba kvalitetu ugrađenih materijala i stručnosti radnika dokazati odgovarajućim atestima i uvjerenjima izdanim od strane za to ovlaštene organizacije i to uračunati u cijenu pojedinih stavaka. Kod cijene nuđenja voditi računa da je za vrijeme građenja raskriveni dio građevine zaštićen od oborina.
B70: Izvođač je dužan kod nuđenja voditi računa da otpad mora razvrstati i takav razvrstan deponirati na specijaliziranim odlagalištima, pa kod izrade ponude ponuditelj treba voditi računa o udaljenostima za najbliže specijalizirane deponije kao i troškove taksi na njima (deponija metal-staklo-građevinska plastika-stiropor i drugo), uključiti u pojedinoj stavci. Sve navedene radnje uključiti s cijenom u pojedinim stavkama, jer se posebna plaćanja neće priznati. U svim stavkama uključiti i sav potreban horizontalni i vertikalni transport do mjesta ugradnje. Za sve stavke građevinsko-obrtničkih i instalaterskih radova potrebno je uključiti sva gruba i fina čišćenja prilikom i nakon izvođenja radova, jer se dodatni troškovi neće dodatno naplaćivati.
B72: OBILAZAK PREDMETNE LOKACIJE
B73: Ponuditelj može obići i detaljno pregledati lokaciju (građevinsku česticu, građevinu/e, zonu obuhvata). Neovisno o tome je li ponudtitelj obišao lokaciju, naručitelj će smatrati da je ponuditelj obišao i detaljno pregledao lokaciju (građevinsku česticu, građevinu/e, zonu obuhvata), te je dobro upoznat sa svim uvjetima, faktorima i resursima u odnosu i u vezi s lokacijom ili onim koji mogu utjecati na izvršenje radova, te da je na temelju navedenog podnio svoju ponudu. Stoga odabrani ponuditelj nema pravo zahtjevati povećanje cijene ili drugu naknadu, pozivajući se da u vrijeme davanja ponude nije bio upoznat s okolnostima vezanim uz lokaciju (građevnu česticu, građevinu/e, zonu obuhvata). U slučaju kakvih nejasnoća illi ocijene ponuditelja da je neko od rješenja neprihvatljivo, postaviti upit naručitelju radi razrješenja detalja. U protivnom od izvođača će se zahtjevati izvođenje detalja kao što je projektant predložio.
B74: Za pojedine elemente dani su normativi važeći na dan pisanja ovog troškovnika. U slučaju da isti u razdoblju do početka realizacije ovih radova ili u njihovom tijeku budu izmijenjeni, primjenjuju se normativi važeći u vrijeme izvođenja radova. Sav ugrađeni materijal treba odgovarati uvjetima iz opisa troškovnika i nacrta, te odgovarajućim normama ili tehničkim uvjetima za izvođenje istih radova, a ukoliko se to posebno traži opisom i drugim propisima. Ugrađeni materijali se mogu razlikovati od predviđenih tehničkih uvjeta ili normi ukoliko zadovoljavaju tehničke uvjete i norma koje su jednakovrijedne ili slične navedenima. Prije početka izvođenja pojedine vrste radova izvođač mora dokumentacijom dokazati da je ovlašten za izvođenje tih radova odnosno ugradnju materijala odabranog proizvođača.
B75: Prije početka radova potrebno je izvesti pripremne radove sve u skladu sa zakonskom regulativom s područja zaštite na radu i područja kompletne građevinske regulative, a naročito radove niže navedene. Trošak ovih radova potrebno ukalkulirati u cijenu građenja jer se isti neće posebno obračunavati. - Dobava i montaža privremene ograde u svrhu zaštite prostora samoga gradilišta vizualno i sigurnosno od prostora ostatka parcele, koja mora udovoljavati svim uvjetima važećeg zakona o zaštiti na radu - Izrada plana organizacije gradilišta.
B76: Izvođač je sukladno važećem Zakonu o zaštiti na radu dužan poduzimati sve propisane mjere i radnje tijekom izvođenja radova proizašle iz tog zakona i cijelokupne pozitivne regulative s područja zaštite na radu, a naročito sljedeće: 1. Osigurati kontenjere na gradilištu za: a/ kontenjer - garderobni za radnike b/ kontenjer - za odmor radnika c/ kontenjeri - za sanitarne potrebe radnika sa suhim WC-ima d/ kontenjer - za tehničku službu gradilišta e/ kontenjer - za nadzornu službu Kontenjeri moraju biti izrađeni i postavljeni u skladu s regulativom s područja zaštite na radu. 2. Postaviti sve potrebne znakove. 3. Postaviti sve zaštitne ograde u svrhu zaštite prostora gradilišta (vizualna i sigurnosna zaštita). 4. Adekvatno razupirati, osigurati i zaštititi sve iskope. 5. Osigurati i zaštititi sve okolne građevine kao cijeline i pojedine njihove dijelove. 6. Plan organizacije gradilišta. Sve navedeno uključiti u pojedine stavke jer se isto neće posebno naplaćivati.
B77: Za potrebe izvođenja radova izvođač je dužan osigurati privremene priključke na infrastrukturu po na osob niskonaponsku električnu mrežu i vodovodnu mrežu, te isto mora biti uključeno u jediničnu cijenu. Odabir za sve materijale gdje će to biti potrebno odabir dezena boja i slično vršit će projektan uz suglasnost korisnika i odobrenje investitora. Prije nabave i ugradnje svih materijala, proizvoda i opreme, karakteristike istih moraju biti pregledane i odobrene od strane stručnog nadzora (kako bi se utvrdilo da iste odgovaraju traženim karakteristikama u predmetnoj stavci troškovnika).
B79: POPIS PRIMJENJENIH ZAKONA, PRAVILNIKA I TEHNIČKIH PROPISA
B80: 1. Zakon o gradnji (NN 153/13, 20/17, 39/19, 125/19, 145/24) 2. Zakon o prostornom uređenju (NN 153/13, 65/17, 114/18, 39/19, 98/19, 67/23) 3. Zakon o komori arhitekata i komorama inženjera u graditeljstvu i prostornom uređenju (NN 78/15, 114/18, 110/19) 4. Zakon o poslovima i djelatnostima prostornog uređenja i gradnje (NN RH 78/15, 118/18, 110/19) 5. Zakon o građevnim proizvodima (NN 76/13, 30/14, 130/17, 39/19, 118/20) 6. Zakon o normizaciji (NN 80/13) 7. Zakon o tehničkim zahtjevima za proizvode i ocjenjivanju sukladnosti (NN 80/13, 14/14, 32/19) 8. Zakon o zaštiti okoliša (NN 80/13, 153/13, 78/15, 12/18, 118/18) 9. Zakon o zaštiti od požara (NN 92/10) 10. Zakon o energetskoj učinkovitosti (NN 127/14, 116/18, 25/20) 11. Zakon o zaštiti od buke (NN 30/09, 55/13, 153/13, 41/16, 114/18) 12. Zakon o zaštiti na radu (NN 71/14, 118/14, 154/14, 94/18, 96/18) 13. Zakon o zaštiti na radu na privremenim gradilištima (NN 48/18)
... B475: NAČELA DNSH KOJA SE OBAVEZNO MORAJU POŠTIVATI:
A476: 1. | B476: Tijekom gradnje građevine potrebno je posebnu pažnju posvetiti rješenjima za gospodarenje građevnim otpadom. Tijekom građenja građevine izvođač je dužan gospodariti građevnim otpadom nastalim tijekom građenja i/ili pri uklanjanju građevine ili njezinog dijela na gradilištu, te oporabiti i/ili zbrinuti građevni otpad nastao tijekom građenja na gradilištu te o tome na gradilištu imati propisanu dokumentaciju sukladno propisima koji uređuju gospodarenje otpadom. Materijal nastao rušenjem izvođač je dužan privremeno deponirati u neposrednoj blizini objekta, te ga po završetku radova zbrinuti u skladu s hijerarhijom otpada i EU Protokolom o gospodarenju građevinskim otpadom i rušenjem. Izvođač je dužan najmanje 70% neopasnog građevinskog otpada i otpada od rušenja nastalog na gradilištu pripremiti za ponovnu uporabu, recikliranje i korištenje drugog materijala, uključujući operacije zatrpavanja za otpad koji zamjenjuje druge materijale. Prema karakteristikama dijelova građevine koji se uklanjaju, ocjenjuje se da će nakon uklanjanja u najvećoj mjeri nastati neopasni i/ili inertni građevinski materijal. Nakon uklanjanja građevine potrebno je sav nastali otpad od uklanjanja zbrinuti po ključnim brojevima otpada, u skladu s odredbama Zakona o gospodarenju otpadom (NN 84/21). Sav otpad, građevinski i ostali, koji ostaje na lokaciji objekta nakon rušenja potrebno je pohraniti i odložiti na prostorima predviđenim za to. Otpad je potrebno sortirati prema ključnim brojevima. Sve ukalkulirati u jedinične cijene kod nuđenja.
B477: Propisi: Zakon o održivom gospodarenju otpadom (NN 94/13, 73/17, 14/19, 98/19), Pravilnik o gospodarenju otpadom (NN 106/22), Pravilnik o građevinskom otpadu i otpadu koji sadrži azbest (NN 69/16)
A478: 2. | B478: Za ugrađene materijale potrebna je dostava CO2 otiska.
A479: 3. | B479: Kod izvođenja radova gdje god je to moguće koristiti se sivom vodom za koju je potrebno kod organizacije gradilišta predvidjeti spremnike. Sve ukalkulirano u režijske troškove gradilišta.

Sheet Zgrada 11
A1: stavka | B1: opis stavke | C1: jedin. mjere | D1: količina | E1: jedinična cijena (euro) | F1: ukupno (euro)
A3: I. | B3: ZGRADA 11
A5: A. | B5: GRAĐEVINSKO-OBRNIČKI RADOVI
A7: 1. | B7: SKELA
A8: 1.1. | B8: Dobava, postava, skidanje i otprema cijevne fasadne skele, od bešavnih cijevi. Skelu izvesti prema važećim HTZ propisima. Skelu je potrebno osigurati od prevrtanja, sidrennjem u građevinu, a od udara munje uzemljenjem. Potrebno je izvesti pomične željezne ili drvene ljestve – penjalice u svrhu osiguranja vertikalne komunikacije po skeli. Prije izvedbe skele izvođač je dužan izraditi projekt skele, što je u cijeni stavke. Obračun se vrši po m² vertikalne projekcije površine skele. Stavka uključuje rad i materijal osnovni i pomoćni, sve do potpune funkcionalnosti. | C8: m2 | D8: 698 | E8: 11.55 | F8: =D8*$E8
B9: 1. Skela ukupno: | F9: =SUM(F8)
A11: 2. | B11: PRIPREMNI RADOVI
A12: 2.1. | B12: Geodetsko praćenje, iskolčenje građevine, trase svih instalacija, šahtova, upločenje uz građevinu, nanošenje svih potrebnih geodetskih visina unutar i oko građevine, izrada elabotrata iskolčenja, snimanja izvedenih instalacija i geodetski elaborat za potrebe katastra. | C12: kpl | D12: 1 | F12: =D12*$E12
A13: 2.2. | B13: Ispitivanje zrakopropusnosti ovojnice zgrade prema HRN EN ISO 9972-2015 ili jednakovrijednoj, te u skladu sa važećim zahtjevima Tehničkog propisa o racionalnoj uporabi energije i toplinskoj zaštiti zgrada. Ispitivanje se vrši dva puta: prvi puta nakon ugradnje i brtvljenja otvora, ugradnje strojarskih instalacija, ožičenja električnih instalacija, žbukanja zidova i zatvaranja vanjske ovojnice zgrade parnom branom, drugi puta nakon završetka svih radova, a prije tehničkog pregleda zgrade. Ispitivanje se vrši blower-door testom uz otkrivanje mjesta propuštanja zraka termografskim snimanjem, anemometrom ili metodom suhog dima. Prilikom ispitivanja, za razliku tlakova između unutarnjeg i vanjskog zraka od 50 Pa, izmjereni protok zraka, sveden na obujam unutarnjeg zraka ne smije biti veći od vrijednosti n50 = 1,5 h-1 (kod zgrada s mehaničkim uređajem za ventilaciju). Prije ispitivanja, naručitelj treba provesti brtvljenje svih prodora kroz zrakonepropusnu ovojnicu poput kanalizacijskih odvoda, ventilacijskih kanala, kablova od struje, itd. Ispitivanje se ponavlja nakon brtvljenja eventualnih mjesta propuštanja zraka dok se ne zadovolji vrijednost n50 =< 1,5 h-1. Postupak se ponavlja dok vanjska ovojnice ne postigne odgovarajuću zrakonepropusnost. Obračun prema netto grijanom volumenu zgrade. Termografsko ispitivanje provodi certificirana osoba. | C13: m2 | D13: 2113 | F13: =D13*$E13
A14: 2.3. | B14: Čišćenje terena od raslinja oko građevine, siječenje i skupljanje. U stavku uključeno uklanjanje smeća, prepreka, drveća, i sl., košenja trave i korova, te utovar i odvoz otpadnog materijala na gradsku deponiju, uključeno u cijeni stavke. | C14: m2 | D14: 455 | F14: =D14*$E14
A15: 2.4. | B15: Pažljivo skidanje, siječenje i skupljane zelenila (bršljana) koje je obuhvatilo pročelje. Primjenjuje se sigurnosna tehnologija rušenja uz rad s ljestvi i rezanjem odozgo prema dolje (sa kontroliranim spuštanjem). Sve sasječene dijelove potrebno je utovariti i odvesti na za to najbližu odgovarajuću deponiju, uključeno u cijenu stavke. | C15: m2 | D15: 242 | F15: =D15*$E15
B16: 2. Pripremni radovi ukupno: | F16: =SUM(F12:F15)
A18: 3. | B18: RUŠENJE I RAZGRADNJA
A19: 3.1. | B19: Kompletna demontaža svih elektroinstalacija jake i slabe struje nadžbukni i podžbukni dio, što uključuje sve utičnice, prekidače, rasvjetna tijela, elektro ormare, kutije s osiguračina, kablove, nosače projektora i projektore, pametne ploče, zvučnike, zvono, videonadzor, pemetne tv i slično, sve u potpunoj gotovosti. U cijenu stavke uključena izrada šliceva za vađenje postojećih elektroinstalacija, kao i sav potreban rad i materijal te upotreba odgovarajuće skele. U cijenu stavke uračunat utovar i odvoz razgrađenog materijala (razvrstanog po vrstama) na najbližu odgovarajuću deponiju, kao i svi troškovi istovara i korištenja odgovarajuće deponije. a) površine 510 m² | C19: kpl | D19: 1 | F19: =D19*$E19
A20: 3.2. | B20: Otpajanja elektroenergetskog priključka građevine prije početka svih rušenja. Radove izvodi za to ovlaštena osoba. Stavka uključuje sav rad i materijal, kao i upotrebu odgovarajuće skele. Postava gradilišnih GRO. | C20: kom | D20: 1 | F20: =D20*$E20
A21: 3.3. | B21: Kompletna demontaža svih strojarskih instalacija, što uključuje kompletnu demontažu postrojenja kotlovnice, svih radijatora, cijevnog razvoda grijanja i slično, sve u potpunoj gotovosti. U cijenu stavke uključena izrada šliceva i potrebnih prodora za vađenje postojećih instalacija, kao i sav potreban rad i materijal te upotreba odgovarajuće skele. U cijenu stavke uračunat utovar i odvoz razgrađenog materijala (razvrstanog po vrstama) na najbližu odgovarajuću deponiju, kao i svi troškovi istovara i korištenja odgovarajuće deponije. a) površine 510 m² | C21: kpl | D21: 1 | F21: =D21*$E21
A22: 3.4. | B22: Skidanje pokrova od valovitih salonitnih azbesnih ploča krovišta (građevina i nadstrešnica). Stavka uključuje i sljemenjake. Skidanje se izvodi na način da ne dođe do oštećenja i loma ploča koje se moraju slagati na palete i omotati folijom, a polomljeni komadi se moraju posebno prikupiti u spremnike ili vreće u kojima se završni sloj prekriva zemljom kako bi se spriječilo eventualno širenje prašine. Pokrovne salonitne ploče nikako nije dozvoljeno prilikom skidanja bacati s krova već ih je potrebno pažljivo spustiti i složiti na mjesto pristupačno za prijevoz. Za vrijeme skidanja ploča potrebno je ploče prskati vodom i upotrebljavati zaštitnu opremu, te krovnu konstrukciju usisati jer se upravo na krovnoj građi nakupilo dosta prašine koju čovjek može udahnuti. Svako lomljenje, rezanje ili brušenje je najstrože zabranjeno, a mjesto privremenog odlaganja prije odvoza na zbrinjavanje potrebno je ograditi ceradom i smanjiti utjecaj vjetra na prikupljeni otpad. Prilikom rada sa salonitnim pločama obavezno je primjena osobnih zaštitnih sredstva (maske, rukavice, zaštitna odjeća i dr.).
B23: Kompletna opisana demontaža pokrova uračunata u cijeni stavke, kao i odlaganje pokrova na gradilišnu deponiju za čuvanje materijala te zbrinjavanje prema posebnoj Uputi i u skladu s važećim propisima. U stavci uračunata upotreba radne skele i sva potrebna osiguranja. U cijenu stavke uračunat utovar i odvoz na odlagalište kod ovlaštenog pravnog subjekta za zbrinjavanje navedenog otpada kao i svi troškovi istovara i korištenja odgovarajuće deponije. Nakon čišćenja gradilišta i okoliša od azbesta može se pristupiti gradnji novog objekta. Obračun po m² kose krovne površine. | C23: m2 | D23: 746.8 | F23: =D23*$E23
A24: 3.5. | B24: Demontaža letava za pokrov valovitim salonitnim azbesnim pločama krovišta građevine. Kompletna demontaža uračunata u cijeni stavke, kao i upotreba odgovarajuće radne skele i sva potrebna osiguranja građevine kao cjeline i dijelova vezanih za ovu razgradnju te svu zaštitu za sigurnost (oprema) i postupke prilikom skidanja (otprašivanje usisavanjem, kvašenje,...) prema opisu u stavci 3.4. U cijenu stavke uračunat utovar i odvoz razgrađenog materijala (razvrstanog po vrstama) na najbližu odgovarajuću deponiju, kao i svi troškovi istovara i korištenja odgovarajuće deponije. Obračun po m² kose krovne površine. | C24: m2 | D24: 746.8 | F24: =D24*$E24
A25: 3.6. | B25: Demontaža gornje daščane oplate krovišta zgrade. Kompletna demontaža uračunata u cijeni stavke, kao i upotreba odgovarajuće skele i sva potrebna osiguranja građevine kao cjeline i dijelova vezanih za ovu razgradnju te sva zaštita za sigurnost (oprema) i postupke prilikom skidanja (otprašivanje usisavanjem, kvašenje,...) prema opisu u stavci 3.4. U cijenu stavke uračunat utovar i odvoz razgrađenog materijala (razvrstanog po vrstama) na najbližu odgovarajuću deponiju, kao i svi troškovi istovara i korištenja odgovarajuće deponije. Obračun po m² kose krovne površine. | C25: m2 | D25: 746.8 | F25: =D25*$E25
A26: 3.7. | B26: Demontaža drvene nosive konstrukcije radi zamjene novih istovjetnih elemenata - rogova. Kompletna demontaža uračunata u cijeni stavke, kao i upotreba odgovarajuće radne skele i sva potrebna osiguranja građevine kao cjeline i dijelova vezanih za ovu razgradnju te sva zaštita za sigurnost (oprema) i postupke prilikom skidanja (otprašivanje usisavanjem, kvašenje,...) prema opisu u stavci 3.4. U cijenu stavke uračunat utovar i odvoz razgrađenog materijala (razvrstanog po vrstama) na najbližu odgovarajuću deponiju, kao i svi troškovi istovara i korištenja odgovarajuće deponije. | C26: kom | D26: 37 | F26: =D26*$E26
A27: 3.8. | B27: Demontaža postojeće nosive drvene konstrukcije krovišta izvedeno na rasponu od cca 15 m, izvedene od drvenog rešetkastog nosača na rasponu od 4 m, čine ga gornji pojas nosača koji prati kosinu krova, donji pojas nosača izveden s dvije međusobno spojene daske te ispuna kosnicima. Obračun po projekciji na tlocrt. | C27: m2 | D27: 714.2 | F27: =D27*$E27
A28: 3.9. | B28: Demontaža i vađenje slojeva poda potkrovlja do nosive konstrukcije od grednika koji uključuju predpostavljene slojeve (ukupne debljine do 25 cm) kako slijedi: - izravnavajući sloj - slijepi pod - letve - nasip šute Kompletna demontaža uračunata u stavci, kao i sva potrebna osiguranja građevine kao cjeline i dijelova vezanih za ovu razgradnju. te sva zaštita za sigurnost (oprema) i postupke prilikom skidanja (otprašivanje usisavanjem, kvašenje,...) prema opisu u stavci 3.4. U cijenu stavke uračunat utovar i odvoz razgrađenog materijala (razvrstanog po vrstama) na najbližu odgovarajuću deponiju, kao i svi troškovi istovara i korištenja odgovarajuće deponije. | C28: m2 | D28: 599.9 | F28: =D28*$E28
A29: 3.10. | B29: Demontaža daščanog grednika (veznih greda) poda krovišta zgrade. Kompletna demontaža uračunata u cijeni stavke, kao i upotreba odgovarajuće skele i sva potrebna osiguranja građevine kao cjeline i dijelova vezanih za ovu razgradnju te sva zaštita za sigurnost (oprema) i postupke prilikom skidanja (otprašivanje usisavanjem, kvašenje,...) prema opisu u stavci 3.4. U cijenu stavke uračunat utovar i odvoz razgrađenog materijala (razvrstanog po vrstama) na najbližu odgovarajuću deponiju, kao i svi troškovi istovara i korištenja odgovarajuće deponije. | C29: kom | D29: 45 | F29: =D29*$E29
A30: 3.11. | B30: Demontaža daščane oplate postavljene ispod daščanog drvenog grednika stropa prizemlja. Kompletna demontaža uračunata u cijeni stavke, kao i upotreba odgovarajuće skele i sva potrebna osiguranja građevine kao cjeline i dijelova vezanih za ovu razgradnju te sva zaštita za sigurnost (oprema) i postupke prilikom skidanja (otprašivanje usisavanjem, kvašenje,...) prema opisu u stavci 3.4. U cijenu stavke uračunat utovar i odvoz razgrađenog materijala (razvrstanog po vrstama) na najbližu odgovarajuću deponiju, kao i svi troškovi istovara i korištenja odgovarajuće deponije. | C30: m2 | D30: 599.9 | F30: =D30*$E30
A31: 3.12. | B31: Demontaža opšava završetka krovnog vijenca. Kompletna demontaža uračunata u cijeni stavke, kao i upotreba odgovarajuće radne skele i sva potrebna osiguranja građevine kao cjeline i dijelova vezanih za ovu razgradnju te svu zaštitu za sigurnost (oprema) i postupke prilikom skidanja (otprašivanje usisavanjem, kvašenje,...) prema opisu u stavci 3.4. Nakon demontaže opšava ogledni uzorak demontiranog elementa ostaviti na gradilišnoj deponiji da posluži kao uzorak za izradu istovjetnog novog opšava, svi troškovi vezani za deponiranje istog uključeni su u stavku. U cijenu stavke uračunat utovar i odvoz razgrađenog materijala (razvrstanog po vrstama) na najbližu odgovarajuću deponiju, kao i svi troškovi istovara i korištenja odgovarajuće deponije. | C31: m' | D31: 95.2 | F31: =D31*$E31
A32: 3.13. | B32: Demontaža gromobranskih instalacija sa krova i pročelja, izvedenih od pocinčanih traka. Uključivo demontažu pričvrsnica i spojnica. Stavka uključuje upotrebu radne skele i sva potrebna osiguranja građevine kao cjeline i dijelova vezanih za ovu razgradnju te svu zaštitu za sigurnost (oprema) i postupke prilikom skidanja (otprašivanje usisavanjem, kvašenje,...) prema opisu u stavci 3.4. U cijenu stavke uračunat utovar i odvoz razgrađenog materijala (razvrstanog po vrstama) na najbližu odgovarajuću deponiju, kao i svi troškovi istovara i korištenja odgovarajuće deponije. | C32: m' | D32: 99 | F32: =D32*$E32
A33: 3.14. | B33: Demontaža opšava dimnjaka, ventilacija i odzračnih vertikala, prodora krovnih ploha limom. U stavci uključena demontaža svog pričvrsnog i pomoćnog materijala. Stavka uključuje upotrebu radne skele i sva potrebna osiguranja građevine kao cjeline i dijelova vezanih za ovu razgradnju te svu zaštitu za sigurnost (oprema) i postupke prilikom skidanja (otprašivanje usisavanjem, kvašenje,...) prema opisu u stavci 3.4. U cijenu stavke uračunat utovar i odvoz razgrađenog materijala (razvrstanog po vrstama) na najbližu odgovarajuću deponiju, kao i svi troškovi istovara i korištenja odgovarajuće deponije.
B34: a) veličine 44/44 cm | C34: kom | D34: 6 | F34: =D34*$E34
B35: b) veličine 50/50 cm | C35: kom | D35: 5 | F35: =D35*$E35
A36: 3.15. | B36: Demontaža horizontalnog visećeg oluka uključivo podložni lim sa okapnicom. Nakon demontaže potrebno je pohraniti na gradilištu 1m horizontalnog oluka koji će poslužiti kao predložak za izradu novog. Kompletna demontaža uračunata u cijeni stavke, kao i demontaža obujmica (kuka), držača oluka. Stavka uključuje upotrebu radne skele i sva potrebna osiguranja građevine kao cjeline i dijelova vezanih za ovu razgradnju te svu zaštitu za sigurnost (oprema) i postupke prilikom skidanja (otprašivanje usisavanjem, kvašenje,...) prema opisu u stavci 3.4. U cijenu stavke uračunat utovar i odvoz razgrađenog materijala (razvrstanog po vrstama) na najbližu odgovarajuću deponiju, kao i svi troškovi istovara i korištenja odgovarajuće deponije. | C36: m' | D36: 95.2 | F36: =D36*$E36
A37: 3.16. | B37: Demontaža spoja vertikalnog oluka sa horizontalnim (tzv. labuđi vrat). Kompletna demontaža uračunata u cijeni stavke, kao i upotreba odgovarajuće radne skele i sva potrebna osiguranja građevine kao cjeline i dijelova vezanih za ovu razgradnju te sva zaštita za sigurnost (oprema) i postupke prilikom skidanja (otprašivanje usisavanjem, kvašenje,...) prema opisu u stavci 3.4. U cijenu stavke uračunat utovar i odvoz razgrađenog materijala (razvrstanog po vrstama) na najbližu odgovarajuću deponiju, kao i svi troškovi istovara i korištenja odgovarajuće deponije. | C37: kom | D37: 6 | F37: =D37*$E37
A38: 3.17. | B38: Demontaža vertikalnih oluka. Nakon demontaže potrebno je pohraniti na gradilištu 1 m vertikalnog oluka koji će poslužiti kao predložak za izradu novog. Stavka uključuje demontažu obujmica. Kompletna demontaža uračunata u cijeni stavke, kao i upotreba radne skele i sva potrebna osiguranja građevine kao cjeline i dijelova vezanih za ovu razgradnju te sva zaštita za sigurnost (oprema) i postupke prilikom skidanja (otprašivanje usisavanjem, kvašenje,...) prema opisu u stavci 3.4. U cijenu stavke uračunat utovar i odvoz razgrađenog materijala (razvrstanog po vrstama) na najbližu odgovarajuću deponiju, kao i svi troškovi istovara i korištenja odgovarajuće deponije. | C38: m' | D38: 26.4 | F38: =D38*$E38
A39: 3.18. | B39: Demontaža limenog opšava zabata. Kompletna demontaža uračunata u stavci, kao i upotreba odgovarajuće skele. U cijenu stavke uračunat utovar i odvoz razgrađenog materijala (razvrstanog po vrstama) na najbližu odgovarajuću deponiju, kao i svi troškovi istovara i korištenja odgovarajuće deponije. | C39: m' | D39: 33.5 | F39: =D39*$E39
A40: 3.19. | B40: Demontaža i vađenje opšava vanjskih prozorskih klupčica. Kompletna demontaža uračunata u cijenu stavke, kao i upotreba radne skele. U cijenu stavke uračunat utovar i odvoz razgrađenog materijala (razvrstanog po vrstama) na najbližu odgovarajuću deponiju, kao i svi troškovi istovara i korištenja odgovarajuće deponije. a) prozorske klupčice na nivou prizemlja, rad na visini do 2,0 m' | C40: m' | D40: 29 | F40: =D40*$E40
A41: 3.20. | B41: Demontaža i vađenje vanjske stolarije na nivou prizemlja - dvostrukih dvokrilnih zaokretnih ostakljenih prozora i doprozornika na pročeljima. Kompletna demontaža uračunata u cijenu stavke, kao i upotreba radne skele. U cijenu stavke uračunat utovar i odvoz razgrađenog materijala (razvrstanog po vrstama) na najbližu odgovarajuću deponiju, kao i svi troškovi istovara i korištenja odgovarajuće deponije.
B42: a) dvostruki prozor vanjskih dim. 130×193 cm | C42: kom | D42: 16 | F42: =D42*$E42
B43: b) dvostruki prozor vanjskih dim. 134×76 cm | C43: kom | D43: 3 | F43: =D43*$E43
A44: 3.21. | B44: Demontaža i vađenje vanjske stolarije na nivou prizemlja - jednostrukih zaokretnih ostakljenih prozora na pročeljima. Kompletna demontaža uračunata u cijenu stavke, kao i upotreba radne skele. U cijenu stavke uračunat utovar i odvoz razgrađenog materijala (razvrstanog po vrstama) na najbližu odgovarajuću deponiju, kao i svi troškovi istovara i korištenja odgovarajuće deponije.
B45: a) jednostruki prozor vanjskih dim. 77×76 cm | C45: kom | D45: 2 | F45: =D45*$E45
...

Sheet Zgrada 12
A1: stavka | B1: opis stavke | C1: jedin. mjere | D1: količina | E1: jedinična cijena (euro)
A3: II. | B3: ZGRADA 12
A5: A. | B5: GRAĐEVINSKO-OBRNIČKI RADOVI
A7: 1. | B7: SKELA
A8: 1.1. | B8: Dobava, postava, skidanje i otprema cijevne fasadne skele, od bešavnih cijevi. Skelu izvesti prema važećim HTZ propisima. Skelu je potrebno osigurati od prevrtanja, sidrennjem u građevinu, a od udara munje uzemljenjem. Potrebno je izvesti pomične željezne ili drvene ljestve – penjalice u svrhu osiguranja vertikalne komunikacije po skeli. Prije izvedbe skele izvođač je dužan izraditi projekt skele, što je u cijeni stavke. Obračun se vrši po m² vertikalne projekcije površine skele. Stavka uključuje rad i materijal osnovni i pomoćni, sve do potpune funkcionalnosti. | C8: m2 | D8: 698
B9: 1. Skela ukupno:
A11: 2. | B11: PRIPREMNI RADOVI
A12: 2.1. | B12: Geodetsko praćenje, iskolčenje građevine, trase svih instalacija, šahtova, upločenje uz građevinu, nanošenje svih potrebnih geodetskih visina unutar i oko građevine, izrada elabotrata iskolčenja, snimanja izvedenih instalacija i geodetski elaborat za potrebe katastra. | C12: kpl | D12: 1
A13: 2.2. | B13: Ispitivanje zrakopropusnosti ovojnice zgrade prema HRN EN ISO 9972-2015 ili jednakovrijednoj, te u skladu sa važećim zahtjevima Tehničkog propisa o racionalnoj uporabi energije i toplinskoj zaštiti zgrada. Ispitivanje se vrši dva puta: prvi puta nakon ugradnje i brtvljenja otvora, ugradnje strojarskih instalacija, ožičenja električnih instalacija, žbukanja zidova i zatvaranja vanjske ovojnice zgrade parnom branom, drugi puta nakon završetka svih radova, a prije tehničkog pregleda zgrade. Ispitivanje se vrši blower-door testom uz otkrivanje mjesta propuštanja zraka termografskim snimanjem, anemometrom ili metodom suhog dima. Prilikom ispitivanja, za razliku tlakova između unutarnjeg i vanjskog zraka od 50 Pa, izmjereni protok zraka, sveden na obujam unutarnjeg zraka ne smije biti veći od vrijednosti n50 = 1,5 h-1 (kod zgrada s mehaničkim uređajem za ventilaciju). Prije ispitivanja, naručitelj treba provesti brtvljenje svih prodora kroz zrakonepropusnu ovojnicu poput kanalizacijskih odvoda, ventilacijskih kanala, kablova od struje, itd. Ispitivanje se ponavlja nakon brtvljenja eventualnih mjesta propuštanja zraka dok se ne zadovolji vrijednost n50 =< 1,5 h-1. Postupak se ponavlja dok vanjska ovojnice ne postigne odgovarajuću zrakonepropusnost. Obračun prema netto grijanom volumenu zgrade. Termografsko ispitivanje provodi certificirana osoba. | C13: m2 | D13: 2113
A14: 2.3. | B14: Čišćenje terena od raslinja oko građevine, siječenje i skupljanje. U stavku uključeno uklanjanje smeća, prepreka, drveća, i sl., košenja trave i korova, te utovar i odvoz otpadnog materijala na gradsku deponiju, uključeno u cijeni stavke. | C14: m2 | D14: 455
A15: 2.4. | B15: Pažljivo skidanje, siječenje i skupljane zelenila (bršljana) koje je obuhvatilo pročelje. Primjenjuje se sigurnosna tehnologija rušenja uz rad s ljestvi i rezanjem odozgo prema dolje (sa kontroliranim spuštanjem). Sve sasječene dijelove potrebno je utovariti i odvesti na za to najbližu odgovarajuću deponiju, uključeno u cijenu stavke. | C15: m2 | D15: 242
B16: 2. Pripremni radovi ukupno:
A18: 3. | B18: RUŠENJE I RAZGRADNJA
A19: 3.1. | B19: Kompletna demontaža svih elektroinstalacija jake i slabe struje nadžbukni i podžbukni dio, što uključuje sve utičnice, prekidače, rasvjetna tijela, elektro ormare, kutije s osiguračina, kablove, nosače projektora i projektore, pametne ploče, zvučnike, zvono, videonadzor, pemetne tv i slično, sve u potpunoj gotovosti. U cijenu stavke uključena izrada šliceva za vađenje postojećih elektroinstalacija, kao i sav potreban rad i materijal te upotreba odgovarajuće skele. U cijenu stavke uračunat utovar i odvoz razgrađenog materijala (razvrstanog po vrstama) na najbližu odgovarajuću deponiju, kao i svi troškovi istovara i korištenja odgovarajuće deponije. a) površine 510 m² | C19: kpl | D19: 1
A20: 3.2. | B20: Otpajanja elektroenergetskog priključka građevine prije početka svih rušenja. Radove izvodi za to ovlaštena osoba. Stavka uključuje sav rad i materijal, kao i upotrebu odgovarajuće skele. Postava gradilišnih GRO. | C20: kom | D20: 1
A21: 3.3. | B21: Kompletna demontaža svih strojarskih instalacija, što uključuje kompletnu demontažu postrojenja kotlovnice, svih radijatora, cijevnog razvoda grijanja i slično, sve u potpunoj gotovosti. U cijenu stavke uključena izrada šliceva i potrebnih prodora za vađenje postojećih instalacija, kao i sav potreban rad i materijal te upotreba odgovarajuće skele. U cijenu stavke uračunat utovar i odvoz razgrađenog materijala (razvrstanog po vrstama) na najbližu odgovarajuću deponiju, kao i svi troškovi istovara i korištenja odgovarajuće deponije. a) površine 510 m² | C21: kpl | D21: 1
A22: 3.4. | B22: Skidanje pokrova od valovitih salonitnih azbesnih ploča krovišta (građevina i nadstrešnica). Stavka uključuje i sljemenjake. Skidanje se izvodi na način da ne dođe do oštećenja i loma ploča koje se moraju slagati na palete i omotati folijom, a polomljeni komadi se moraju posebno prikupiti u spremnike ili vreće u kojima se završni sloj prekriva zemljom kako bi se spriječilo eventualno širenje prašine. Pokrovne salonitne ploče nikako nije dozvoljeno prilikom skidanja bacati s krova već ih je potrebno pažljivo spustiti i složiti na mjesto pristupačno za prijevoz. Za vrijeme skidanja ploča potrebno je ploče prskati vodom i upotrebljavati zaštitnu opremu, te krovnu konstrukciju usisati jer se upravo na krovnoj građi nakupilo dosta prašine koju čovjek može udahnuti. Svako lomljenje, rezanje ili brušenje je najstrože zabranjeno, a mjesto privremenog odlaganja prije odvoza na zbrinjavanje potrebno je ograditi ceradom i smanjiti utjecaj vjetra na prikupljeni otpad. Prilikom rada sa salonitnim pločama obavezno je primjena osobnih zaštitnih sredstva (maske, rukavice, zaštitna odjeća i dr.).
B23: Kompletna opisana demontaža pokrova uračunata u cijeni stavke, kao i odlaganje pokrova na gradilišnu deponiju za čuvanje materijala te zbrinjavanje prema posebnoj Uputi i u skladu s važećim propisima. U stavci uračunata upotreba radne skele i sva potrebna osiguranja. U cijenu stavke uračunat utovar i odvoz na odlagalište kod ovlaštenog pravnog subjekta za zbrinjavanje navedenog otpada kao i svi troškovi istovara i korištenja odgovarajuće deponije. Nakon čišćenja gradilišta i okoliša od azbesta može se pristupiti gradnji novog objekta. Obračun po m² kose krovne površine. | C23: m2 | D23: 714.2
A24: 3.5. | B24: Demontaža letava za pokrov valovitim salonitnim azbesnim pločama krovišta građevine. Kompletna demontaža uračunata u cijeni stavke, kao i upotreba odgovarajuće radne skele i sva potrebna osiguranja građevine kao cjeline i dijelova vezanih za ovu razgradnju te svu zaštitu za sigurnost (oprema) i postupke prilikom skidanja (otprašivanje usisavanjem, kvašenje,...) prema opisu u stavci 3.4. U cijenu stavke uračunat utovar i odvoz razgrađenog materijala (razvrstanog po vrstama) na najbližu odgovarajuću deponiju, kao i svi troškovi istovara i korištenja odgovarajuće deponije. Obračun po m² kose krovne površine. | C24: m2 | D24: 714.2
A25: 3.6. | B25: Demontaža gornje daščane oplate krovišta zgrade. Kompletna demontaža uračunata u cijeni stavke, kao i upotreba odgovarajuće skele i sva potrebna osiguranja građevine kao cjeline i dijelova vezanih za ovu razgradnju te sva zaštita za sigurnost (oprema) i postupke prilikom skidanja (otprašivanje usisavanjem, kvašenje,...) prema opisu u stavci 3.4. U cijenu stavke uračunat utovar i odvoz razgrađenog materijala (razvrstanog po vrstama) na najbližu odgovarajuću deponiju, kao i svi troškovi istovara i korištenja odgovarajuće deponije. Obračun po m² kose krovne površine. | C25: m2 | D25: 714.2
A26: 3.7. | B26: Demontaža drvene nosive konstrukcije radi zamjene novih istovjetnih elemenata - rogova. Kompletna demontaža uračunata u cijeni stavke, kao i upotreba odgovarajuće radne skele i sva potrebna osiguranja građevine kao cjeline i dijelova vezanih za ovu razgradnju te sva zaštita za sigurnost (oprema) i postupke prilikom skidanja (otprašivanje usisavanjem, kvašenje,...) prema opisu u stavci 3.4. U cijenu stavke uračunat utovar i odvoz razgrađenog materijala (razvrstanog po vrstama) na najbližu odgovarajuću deponiju, kao i svi troškovi istovara i korištenja odgovarajuće deponije. | C26: kom | D26: 37
A27: 3.8. | B27: Demontaža postojeće nosive drvene konstrukcije krovišta izvedeno na rasponu od cca 15 m, izvedene od drvenog rešetkastog nosača na rasponu od 4 m, čine ga gornji pojas nosača koji prati kosinu krova, donji pojas nosača izveden s dvije međusobno spojene daske te ispuna kosnicima. Obračun po projekciji na tlocrt. | C27: m2 | D27: 714.2
A28: 3.9. | B28: Demontaža i vađenje slojeva poda potkrovlja do nosive konstrukcije od grednika koji uključuju predpostavljene slojeve (ukupne debljine do 25 cm) kako slijedi: - izravnavajući sloj - slijepi pod - letve - nasip šute Kompletna demontaža uračunata u stavci, kao i sva potrebna osiguranja građevine kao cjeline i dijelova vezanih za ovu razgradnju. te sva zaštita za sigurnost (oprema) i postupke prilikom skidanja (otprašivanje usisavanjem, kvašenje,...) prema opisu u stavci 3.4. U cijenu stavke uračunat utovar i odvoz razgrađenog materijala (razvrstanog po vrstama) na najbližu odgovarajuću deponiju, kao i svi troškovi istovara i korištenja odgovarajuće deponije. | C28: m2 | D28: 599.9
A29: 3.10. | B29: Demontaža daščanog grednika (veznih greda) poda krovišta zgrade. Kompletna demontaža uračunata u cijeni stavke, kao i upotreba odgovarajuće skele i sva potrebna osiguranja građevine kao cjeline i dijelova vezanih za ovu razgradnju te sva zaštita za sigurnost (oprema) i postupke prilikom skidanja (otprašivanje usisavanjem, kvašenje,...) prema opisu u stavci 3.4. U cijenu stavke uračunat utovar i odvoz razgrađenog materijala (razvrstanog po vrstama) na najbližu odgovarajuću deponiju, kao i svi troškovi istovara i korištenja odgovarajuće deponije. | C29: kom | D29: 45
A30: 3.11. | B30: Demontaža daščane oplate postavljene ispod daščanog drvenog grednika stropa prizemlja. Kompletna demontaža uračunata u cijeni stavke, kao i upotreba odgovarajuće skele i sva potrebna osiguranja građevine kao cjeline i dijelova vezanih za ovu razgradnju te sva zaštita za sigurnost (oprema) i postupke prilikom skidanja (otprašivanje usisavanjem, kvašenje,...) prema opisu u stavci 3.4. U cijenu stavke uračunat utovar i odvoz razgrađenog materijala (razvrstanog po vrstama) na najbližu odgovarajuću deponiju, kao i svi troškovi istovara i korištenja odgovarajuće deponije. | C30: m2 | D30: 599.9
A31: 3.12. | B31: Demontaža opšava završetka krovnog vijenca. Kompletna demontaža uračunata u cijeni stavke, kao i upotreba odgovarajuće radne skele i sva potrebna osiguranja građevine kao cjeline i dijelova vezanih za ovu razgradnju te svu zaštitu za sigurnost (oprema) i postupke prilikom skidanja (otprašivanje usisavanjem, kvašenje,...) prema opisu u stavci 3.4. Nakon demontaže opšava ogledni uzorak demontiranog elementa ostaviti na gradilišnoj deponiji da posluži kao uzorak za izradu istovjetnog novog opšava, svi troškovi vezani za deponiranje istog uključeni su u stavku. U cijenu stavke uračunat utovar i odvoz razgrađenog materijala (razvrstanog po vrstama) na najbližu odgovarajuću deponiju, kao i svi troškovi istovara i korištenja odgovarajuće deponije. | C31: m' | D31: 95.2
A32: 3.13. | B32: Demontaža gromobranskih instalacija sa krova i pročelja, izvedenih od pocinčanih traka. Uključivo demontažu pričvrsnica i spojnica. Stavka uključuje upotrebu radne skele i sva potrebna osiguranja građevine kao cjeline i dijelova vezanih za ovu razgradnju te svu zaštitu za sigurnost (oprema) i postupke prilikom skidanja (otprašivanje usisavanjem, kvašenje,...) prema opisu u stavci 3.4. U cijenu stavke uračunat utovar i odvoz razgrađenog materijala (razvrstanog po vrstama) na najbližu odgovarajuću deponiju, kao i svi troškovi istovara i korištenja odgovarajuće deponije. | C32: m' | D32: 99
A33: 3.14. | B33: Demontaža opšava dimnjaka, ventilacija i odzračnih vertikala, prodora krovnih ploha limom. U stavci uključena demontaža svog pričvrsnog i pomoćnog materijala. Stavka uključuje upotrebu radne skele i sva potrebna osiguranja građevine kao cjeline i dijelova vezanih za ovu razgradnju te svu zaštitu za sigurnost (oprema) i postupke prilikom skidanja (otprašivanje usisavanjem, kvašenje,...) prema opisu u stavci 3.4. U cijenu stavke uračunat utovar i odvoz razgrađenog materijala (razvrstanog po vrstama) na najbližu odgovarajuću deponiju, kao i svi troškovi istovara i korištenja odgovarajuće deponije.
B34: a) veličine 44/44 cm | C34: kom | D34: 6
B35: b) veličine 50/50 cm | C35: kom | D35: 4
B36: c) veličine Ø 15 cm | C36: kom | D36: 4
A37: 3.15. | B37: Demontaža horizontalnog visećeg oluka uključivo podložni lim sa okapnicom. Nakon demontaže potrebno je pohraniti na gradilištu 1m horizontalnog oluka koji će poslužiti kao predložak za izradu novog. Kompletna demontaža uračunata u cijeni stavke, kao i demontaža obujmica (kuka), držača oluka. Stavka uključuje upotrebu radne skele i sva potrebna osiguranja građevine kao cjeline i dijelova vezanih za ovu razgradnju te svu zaštitu za sigurnost (oprema) i postupke prilikom skidanja (otprašivanje usisavanjem, kvašenje,...) prema opisu u stavci 3.4. U cijenu stavke uračunat utovar i odvoz razgrađenog materijala (razvrstanog po vrstama) na najbližu odgovarajuću deponiju, kao i svi troškovi istovara i korištenja odgovarajuće deponije. | C37: m' | D37: 95.2
A38: 3.16. | B38: Demontaža spoja vertikalnog oluka sa horizontalnim (tzv. labuđi vrat). Kompletna demontaža uračunata u cijeni stavke, kao i upotreba odgovarajuće radne skele i sva potrebna osiguranja građevine kao cjeline i dijelova vezanih za ovu razgradnju te sva zaštita za sigurnost (oprema) i postupke prilikom skidanja (otprašivanje usisavanjem, kvašenje,...) prema opisu u stavci 3.4. U cijenu stavke uračunat utovar i odvoz razgrađenog materijala (razvrstanog po vrstama) na najbližu odgovarajuću deponiju, kao i svi troškovi istovara i korištenja odgovarajuće deponije. | C38: kom | D38: 6
A39: 3.17. | B39: Demontaža vertikalnih oluka. Nakon demontaže potrebno je pohraniti na gradilištu 1 m vertikalnog oluka koji će poslužiti kao predložak za izradu novog. Stavka uključuje demontažu obujmica. Kompletna demontaža uračunata u cijeni stavke, kao i upotreba radne skele i sva potrebna osiguranja građevine kao cjeline i dijelova vezanih za ovu razgradnju te sva zaštita za sigurnost (oprema) i postupke prilikom skidanja (otprašivanje usisavanjem, kvašenje,...) prema opisu u stavci 3.4. U cijenu stavke uračunat utovar i odvoz razgrađenog materijala (razvrstanog po vrstama) na najbližu odgovarajuću deponiju, kao i svi troškovi istovara i korištenja odgovarajuće deponije. | C39: m' | D39: 26.4
A40: 3.18. | B40: Demontaža limenog opšava zabata. Kompletna demontaža uračunata u stavci, kao i upotreba odgovarajuće skele. U cijenu stavke uračunat utovar i odvoz razgrađenog materijala (razvrstanog po vrstama) na najbližu odgovarajuću deponiju, kao i svi troškovi istovara i korištenja odgovarajuće deponije. | C40: m' | D40: 33.5
A41: 3.19. | B41: Demontaža i vađenje opšava vanjskih prozorskih klupčica. Kompletna demontaža uračunata u cijenu stavke, kao i upotreba radne skele. U cijenu stavke uračunat utovar i odvoz razgrađenog materijala (razvrstanog po vrstama) na najbližu odgovarajuću deponiju, kao i svi troškovi istovara i korištenja odgovarajuće deponije. a) prozorske klupčice na nivou prizemlja, rad na visini do 2,0 m' | C41: m' | D41: 29
A42: 3.20. | B42: Demontaža i vađenje vanjske stolarije na nivou prizemlja - dvostrukih dvokrilnih zaokretnih ostakljenih prozora i doprozornika na pročeljima. Kompletna demontaža uračunata u cijenu stavke, kao i upotreba radne skele. U cijenu stavke uračunat utovar i odvoz razgrađenog materijala (razvrstanog po vrstama) na najbližu odgovarajuću deponiju, kao i svi troškovi istovara i korištenja odgovarajuće deponije.
B43: a) dvostruki prozor vanjskih dim. 130×193 cm | C43: kom | D43: 17
B44: b) dvostruki prozor vanjskih dim. 134×76 cm | C44: kom | D44: 3
A45: 3.21. | B45: Demontaža i vađenje vanjske stolarije na nivou prizemlja i potkrovlja - jednostrukih zaokretnih ostakljenih prozora na pročeljima. Kompletna demontaža uračunata u cijenu stavke, kao i upotreba radne skele. U cijenu stavke uračunat utovar i odvoz razgrađenog materijala (razvrstanog po vrstama) na najbližu odgovarajuću deponiju, kao i svi troškovi istovara i korištenja odgovarajuće deponije.
...

Sheet Zgrada 13
A1: stavka | B1: opis stavke | C1: jedin. mjere | D1: količina | E1: jedinična cijena (euro)
A3: III. | B3: ZGRADA 13
A5: A. | B5: GRAĐEVINSKO-OBRNIČKI RADOVI
A7: 1. | B7: SKELA
A8: 1.1. | B8: Dobava, postava, skidanje i otprema cijevne fasadne skele, od bešavnih cijevi. Skelu izvesti prema važećim HTZ propisima. Skelu je potrebno osigurati od prevrtanja, sidrennjem u građevinu, a od udara munje uzemljenjem. Potrebno je izvesti pomične željezne ili drvene ljestve – penjalice u svrhu osiguranja vertikalne komunikacije po skeli. Prije izvedbe skele izvođač je dužan izraditi projekt skele, što je u cijeni stavke. Obračun se vrši po m² vertikalne projekcije površine skele. Stavka uključuje rad i materijal osnovni i pomoćni, sve do potpune funkcionalnosti. | C8: m2 | D8: 698 | E8: 11.5 | F8: =E8*D8
B9: 1. Skela ukupno: | F9: =SUM(F8:F8)
A11: 2. | B11: PRIPREMNI RADOVI
A12: 2.1. | B12: Geodetsko praćenje, iskolčenje građevine, trase svih instalacija, šahtova, upločenje uz građevinu, nanošenje svih potrebnih geodetskih visina unutar i oko građevine, izrada elabotrata iskolčenja, snimanja izvedenih instalacija i geodetski elaborat za potrebe katastra. | C12: kpl | D12: 1
A13: 2.2. | B13: Ispitivanje zrakopropusnosti ovojnice zgrade prema HRN EN ISO 9972-2015 ili jednakovrijednoj, te u skladu sa važećim zahtjevima Tehničkog propisa o racionalnoj uporabi energije i toplinskoj zaštiti zgrada. Ispitivanje se vrši dva puta: prvi puta nakon ugradnje i brtvljenja otvora, ugradnje strojarskih instalacija, ožičenja električnih instalacija, žbukanja zidova i zatvaranja vanjske ovojnice zgrade parnom branom, drugi puta nakon završetka svih radova, a prije tehničkog pregleda zgrade. Ispitivanje se vrši blower-door testom uz otkrivanje mjesta propuštanja zraka termografskim snimanjem, anemometrom ili metodom suhog dima. Prilikom ispitivanja, za razliku tlakova između unutarnjeg i vanjskog zraka od 50 Pa, izmjereni protok zraka, sveden na obujam unutarnjeg zraka ne smije biti veći od vrijednosti n50 = 1,5 h-1 (kod zgrada s mehaničkim uređajem za ventilaciju). Prije ispitivanja, naručitelj treba provesti brtvljenje svih prodora kroz zrakonepropusnu ovojnicu poput kanalizacijskih odvoda, ventilacijskih kanala, kablova od struje, itd. Ispitivanje se ponavlja nakon brtvljenja eventualnih mjesta propuštanja zraka dok se ne zadovolji vrijednost n50 =< 1,5 h-1. Postupak se ponavlja dok vanjska ovojnice ne postigne odgovarajuću zrakonepropusnost. Obračun prema netto grijanom volumenu zgrade. Termografsko ispitivanje provodi certificirana osoba. | C13: m2 | D13: 2117
A14: 2.3. | B14: Čišćenje terena od raslinja oko građevine, siječenje i skupljanje. U stavku uključeno uklanjanje smeća, prepreka, drveća, i sl., košenja trave i korova, te utovar i odvoz otpadnog materijala na gradsku deponiju, uključeno u cijeni stavke. | C14: m2 | D14: 486
A15: 2.4. | B15: Pažljivo skidanje, siječenje i skupljane zelenila (bršljana) koje je obuhvatilo pročelje. Primjenjuje se sigurnosna tehnologija rušenja uz rad s ljestvi i rezanjem odozgo prema dolje (sa kontroliranim spuštanjem). Sve sasječene dijelove potrebno je utovariti i odvesti na za to najbližu odgovarajuću deponiju, uključeno u cijenu stavke. | C15: m2 | D15: 242
B16: 2. Pripremni radovi ukupno:
A18: 3. | B18: RUŠENJE I RAZGRADNJA
A19: 3.1. | B19: Kompletna demontaža svih elektroinstalacija jake i slabe struje nadžbukni i podžbukni dio, što uključuje sve utičnice, prekidače, rasvjetna tijela, elektro ormare, kutije s osiguračina, kablove, nosače projektora i projektore, pametne ploče, zvučnike, zvono, videonadzor, pemetne tv i slično, sve u potpunoj gotovosti. U cijenu stavke uključena izrada šliceva za vađenje postojećih elektroinstalacija, kao i sav potreban rad i materijal te upotreba odgovarajuće skele. U cijenu stavke uračunat utovar i odvoz razgrađenog materijala (razvrstanog po vrstama) na najbližu odgovarajuću deponiju, kao i svi troškovi istovara i korištenja odgovarajuće deponije. a) površine 510 m² | C19: kpl | D19: 1
A20: 3.2. | B20: Otpajanja elektroenergetskog priključka građevine prije početka svih rušenja. Radove izvodi za to ovlaštena osoba. Stavka uključuje sav rad i materijal, kao i upotrebu odgovarajuće skele. Postava gradilišnih GRO. | C20: kom | D20: 1
A21: 3.3. | B21: Kompletna demontaža svih strojarskih instalacija, što uključuje kompletnu demontažu postrojenja kotlovnice, svih radijatora, cijevnog razvoda grijanja i slično, sve u potpunoj gotovosti. U cijenu stavke uključena izrada šliceva i potrebnih prodora za vađenje postojećih instalacija, kao i sav potreban rad i materijal te upotreba odgovarajuće skele. U cijenu stavke uračunat utovar i odvoz razgrađenog materijala (razvrstanog po vrstama) na najbližu odgovarajuću deponiju, kao i svi troškovi istovara i korištenja odgovarajuće deponije. a) površine 510 m² | C21: kpl | D21: 1
A22: 3.4. | B22: Skidanje pokrova od valovitih salonitnih azbesnih ploča krovišta (građevina i nadstrešnica). Stavka uključuje i sljemenjake. Skidanje se izvodi na način da ne dođe do oštećenja i loma ploča koje se moraju slagati na palete i omotati folijom, a polomljeni komadi se moraju posebno prikupiti u spremnike ili vreće u kojima se završni sloj prekriva zemljom kako bi se spriječilo eventualno širenje prašine. Pokrovne salonitne ploče nikako nije dozvoljeno prilikom skidanja bacati s krova već ih je potrebno pažljivo spustiti i složiti na mjesto pristupačno za prijevoz. Za vrijeme skidanja ploča potrebno je ploče prskati vodom i upotrebljavati zaštitnu opremu, te krovnu konstrukciju usisati jer se upravo na krovnoj građi nakupilo dosta prašine koju čovjek može udahnuti. Svako lomljenje, rezanje ili brušenje je najstrože zabranjeno, a mjesto privremenog odlaganja prije odvoza na zbrinjavanje potrebno je ograditi ceradom i smanjiti utjecaj vjetra na prikupljeni otpad. Prilikom rada sa salonitnim pločama obavezno je primjena osobnih zaštitnih sredstva (maske, rukavice, zaštitna odjeća i dr.).
B23: Kompletna opisana demontaža pokrova uračunata u cijeni stavke, kao i odlaganje pokrova na gradilišnu deponiju za čuvanje materijala te zbrinjavanje prema posebnoj Uputi i u skladu s važećim propisima. U stavci uračunata upotreba radne skele i sva potrebna osiguranja. U cijenu stavke uračunat utovar i odvoz na odlagalište kod ovlaštenog pravnog subjekta za zbrinjavanje navedenog otpada kao i svi troškovi istovara i korištenja odgovarajuće deponije. Nakon čišćenja gradilišta i okoliša od azbesta može se pristupiti gradnji novog objekta. Obračun po m² kose krovne površine. | C23: m2 | D23: 746.8
A24: 3.5. | B24: Demontaža letava za pokrov valovitim salonitnim azbesnim pločama krovišta građevine. Kompletna demontaža uračunata u cijeni stavke, kao i upotreba odgovarajuće radne skele i sva potrebna osiguranja građevine kao cjeline i dijelova vezanih za ovu razgradnju te svu zaštitu za sigurnost (oprema) i postupke prilikom skidanja (otprašivanje usisavanjem, kvašenje,...) prema opisu u stavci 3.4. U cijenu stavke uračunat utovar i odvoz razgrađenog materijala (razvrstanog po vrstama) na najbližu odgovarajuću deponiju, kao i svi troškovi istovara i korištenja odgovarajuće deponije. Obračun po m² kose krovne površine. | C24: m2 | D24: 746.8
A25: 3.6. | B25: Demontaža gornje daščane oplate krovišta zgrade. Kompletna demontaža uračunata u cijeni stavke, kao i upotreba odgovarajuće skele i sva potrebna osiguranja građevine kao cjeline i dijelova vezanih za ovu razgradnju te sva zaštita za sigurnost (oprema) i postupke prilikom skidanja (otprašivanje usisavanjem, kvašenje,...) prema opisu u stavci 3.4. U cijenu stavke uračunat utovar i odvoz razgrađenog materijala (razvrstanog po vrstama) na najbližu odgovarajuću deponiju, kao i svi troškovi istovara i korištenja odgovarajuće deponije. Obračun po m² kose krovne površine. | C25: m2 | D25: 746.8
A26: 3.7. | B26: Demontaža drvene nosive konstrukcije radi zamjene novih istovjetnih elemenata - rogova. Kompletna demontaža uračunata u cijeni stavke, kao i upotreba odgovarajuće radne skele i sva potrebna osiguranja građevine kao cjeline i dijelova vezanih za ovu razgradnju te sva zaštita za sigurnost (oprema) i postupke prilikom skidanja (otprašivanje usisavanjem, kvašenje,...) prema opisu u stavci 3.4. U cijenu stavke uračunat utovar i odvoz razgrađenog materijala (razvrstanog po vrstama) na najbližu odgovarajuću deponiju, kao i svi troškovi istovara i korištenja odgovarajuće deponije. | C26: kom | D26: 37
A27: 3.8. | B27: Demontaža postojeće nosive drvene konstrukcije krovišta izvedeno na rasponu od cca 15 m, izvedene od drvenog rešetkastog nosača na rasponu od 4 m, čine ga gornji pojas nosača koji prati kosinu krova, donji pojas nosača izveden s dvije međusobno spojene daske te ispuna kosnicima. Obračun po projekciji na tlocrt. | C27: m2 | D27: 715.2
A28: 3.9. | B28: Demontaža i vađenje slojeva poda potkrovlja do nosive konstrukcije od grednika koji uključuju predpostavljene slojeve (ukupne debljine do 25 cm) kako slijedi: - izravnavajući sloj - slijepi pod - letve - nasip šute Kompletna demontaža uračunata u stavci, kao i sva potrebna osiguranja građevine kao cjeline i dijelova vezanih za ovu razgradnju. te sva zaštita za sigurnost (oprema) i postupke prilikom skidanja (otprašivanje usisavanjem, kvašenje,...) prema opisu u stavci 3.4. U cijenu stavke uračunat utovar i odvoz razgrađenog materijala (razvrstanog po vrstama) na najbližu odgovarajuću deponiju, kao i svi troškovi istovara i korištenja odgovarajuće deponije. | C28: m2 | D28: 601
A29: 3.10. | B29: Demontaža daščanog grednika (veznih greda) poda krovišta zgrade. Kompletna demontaža uračunata u cijeni stavke, kao i upotreba odgovarajuće skele i sva potrebna osiguranja građevine kao cjeline i dijelova vezanih za ovu razgradnju te sva zaštita za sigurnost (oprema) i postupke prilikom skidanja (otprašivanje usisavanjem, kvašenje,...) prema opisu u stavci 3.4. U cijenu stavke uračunat utovar i odvoz razgrađenog materijala (razvrstanog po vrstama) na najbližu odgovarajuću deponiju, kao i svi troškovi istovara i korištenja odgovarajuće deponije. | C29: kom | D29: 45
A30: 3.11. | B30: Demontaža daščane oplate postavljene ispod daščanog drvenog grednika stropa prizemlja. Kompletna demontaža uračunata u cijeni stavke, kao i upotreba odgovarajuće skele i sva potrebna osiguranja građevine kao cjeline i dijelova vezanih za ovu razgradnju te sva zaštita za sigurnost (oprema) i postupke prilikom skidanja (otprašivanje usisavanjem, kvašenje,...) prema opisu u stavci 3.4. U cijenu stavke uračunat utovar i odvoz razgrađenog materijala (razvrstanog po vrstama) na najbližu odgovarajuću deponiju, kao i svi troškovi istovara i korištenja odgovarajuće deponije. | C30: m2 | D30: 601
A31: 3.12. | B31: Demontaža opšava završetka krovnog vijenca. Kompletna demontaža uračunata u cijeni stavke, kao i upotreba odgovarajuće radne skele i sva potrebna osiguranja građevine kao cjeline i dijelova vezanih za ovu razgradnju te svu zaštitu za sigurnost (oprema) i postupke prilikom skidanja (otprašivanje usisavanjem, kvašenje,...) prema opisu u stavci 3.4. Nakon demontaže opšava ogledni uzorak demontiranog elementa ostaviti na gradilišnoj deponiji da posluži kao uzorak za izradu istovjetnog novog opšava, svi troškovi vezani za deponiranje istog uključeni su u stavku. U cijenu stavke uračunat utovar i odvoz razgrađenog materijala (razvrstanog po vrstama) na najbližu odgovarajuću deponiju, kao i svi troškovi istovara i korištenja odgovarajuće deponije. | C31: m' | D31: 95.3
A32: 3.13. | B32: Demontaža gromobranskih instalacija sa krova i pročelja, izvedenih od pocinčanih traka. Uključivo demontažu pričvrsnica i spojnica. Stavka uključuje upotrebu radne skele i sva potrebna osiguranja građevine kao cjeline i dijelova vezanih za ovu razgradnju te svu zaštitu za sigurnost (oprema) i postupke prilikom skidanja (otprašivanje usisavanjem, kvašenje,...) prema opisu u stavci 3.4. U cijenu stavke uračunat utovar i odvoz razgrađenog materijala (razvrstanog po vrstama) na najbližu odgovarajuću deponiju, kao i svi troškovi istovara i korištenja odgovarajuće deponije. | C32: m' | D32: 99
A33: 3.14. | B33: Demontaža opšava dimnjaka, ventilacija i odzračnih vertikala, prodora krovnih ploha limom. U stavci uključena demontaža svog pričvrsnog i pomoćnog materijala. Stavka uključuje upotrebu radne skele i sva potrebna osiguranja građevine kao cjeline i dijelova vezanih za ovu razgradnju te svu zaštitu za sigurnost (oprema) i postupke prilikom skidanja (otprašivanje usisavanjem, kvašenje,...) prema opisu u stavci 3.4. U cijenu stavke uračunat utovar i odvoz razgrađenog materijala (razvrstanog po vrstama) na najbližu odgovarajuću deponiju, kao i svi troškovi istovara i korištenja odgovarajuće deponije.
B34: a) veličine 44/44 cm | C34: kom | D34: 6
B35: b) veličine 50/50 cm | C35: kom | D35: 4
B36: c) veličine Ø 15 cm | C36: kom | D36: 4
A37: 3.15. | B37: Demontaža horizontalnog visećeg oluka uključivo podložni lim sa okapnicom. Nakon demontaže potrebno je pohraniti na gradilištu 1m horizontalnog oluka koji će poslužiti kao predložak za izradu novog. Kompletna demontaža uračunata u cijeni stavke, kao i demontaža obujmica (kuka), držača oluka. Stavka uključuje upotrebu radne skele i sva potrebna osiguranja građevine kao cjeline i dijelova vezanih za ovu razgradnju te svu zaštitu za sigurnost (oprema) i postupke prilikom skidanja (otprašivanje usisavanjem, kvašenje,...) prema opisu u stavci 3.4. U cijenu stavke uračunat utovar i odvoz razgrađenog materijala (razvrstanog po vrstama) na najbližu odgovarajuću deponiju, kao i svi troškovi istovara i korištenja odgovarajuće deponije. | C37: m' | D37: 95.3
A38: 3.16. | B38: Demontaža spoja vertikalnog oluka sa horizontalnim (tzv. labuđi vrat). Kompletna demontaža uračunata u cijeni stavke, kao i upotreba odgovarajuće radne skele i sva potrebna osiguranja građevine kao cjeline i dijelova vezanih za ovu razgradnju te sva zaštita za sigurnost (oprema) i postupke prilikom skidanja (otprašivanje usisavanjem, kvašenje,...) prema opisu u stavci 3.4. U cijenu stavke uračunat utovar i odvoz razgrađenog materijala (razvrstanog po vrstama) na najbližu odgovarajuću deponiju, kao i svi troškovi istovara i korištenja odgovarajuće deponije. | C38: kom | D38: 6
A39: 3.17. | B39: Demontaža vertikalnih oluka. Nakon demontaže potrebno je pohraniti na gradilištu 1 m vertikalnog oluka koji će poslužiti kao predložak za izradu novog. Stavka uključuje demontažu obujmica. Kompletna demontaža uračunata u cijeni stavke, kao i upotreba radne skele i sva potrebna osiguranja građevine kao cjeline i dijelova vezanih za ovu razgradnju te sva zaštita za sigurnost (oprema) i postupke prilikom skidanja (otprašivanje usisavanjem, kvašenje,...) prema opisu u stavci 3.4. U cijenu stavke uračunat utovar i odvoz razgrađenog materijala (razvrstanog po vrstama) na najbližu odgovarajuću deponiju, kao i svi troškovi istovara i korištenja odgovarajuće deponije. | C39: m' | D39: 26.4
A40: 3.18. | B40: Demontaža limenog opšava zabata. Kompletna demontaža uračunata u stavci, kao i upotreba odgovarajuće skele. U cijenu stavke uračunat utovar i odvoz razgrađenog materijala (razvrstanog po vrstama) na najbližu odgovarajuću deponiju, kao i svi troškovi istovara i korištenja odgovarajuće deponije. | C40: m' | D40: 33.5
A41: 3.19. | B41: Demontaža i vađenje opšava vanjskih prozorskih klupčica. Kompletna demontaža uračunata u cijenu stavke, kao i upotreba radne skele. U cijenu stavke uračunat utovar i odvoz razgrađenog materijala (razvrstanog po vrstama) na najbližu odgovarajuću deponiju, kao i svi troškovi istovara i korištenja odgovarajuće deponije. a) prozorske klupčice na nivou prizemlja, rad na visini do 2,0 m' | C41: m' | D41: 29
A42: 3.20. | B42: Demontaža i vađenje vanjske stolarije na nivou prizemlja - dvostrukih dvokrilnih zaokretnih ostakljenih prozora i doprozornika na pročeljima. Kompletna demontaža uračunata u cijenu stavke, kao i upotreba radne skele. U cijenu stavke uračunat utovar i odvoz razgrađenog materijala (razvrstanog po vrstama) na najbližu odgovarajuću deponiju, kao i svi troškovi istovara i korištenja odgovarajuće deponije.
B43: a) dvostruki prozor vanjskih dim. 130×193 cm | C43: kom | D43: 17
B44: b) dvostruki prozor vanjskih dim. 134×76 cm | C44: kom | D44: 3
A45: 3.21. | B45: Demontaža i vađenje vanjske stolarije na nivou prizemlja - jednostrukih zaokretnih ostakljenih prozora na pročeljima. Kompletna demontaža uračunata u cijenu stavke, kao i upotreba radne skele. U cijenu stavke uračunat utovar i odvoz razgrađenog materijala (razvrstanog po vrstama) na najbližu odgovarajuću deponiju, kao i svi troškovi istovara i korištenja odgovarajuće deponije.
...

Sheet Zgrada 14
A1: stavka | B1: opis stavke | C1: jedin. mjere | D1: količina | E1: jedinična cijena (euro)
A3: IV. | B3: ZGRADA 14
A5: A. | B5: GRAĐEVINSKO-OBRNIČKI RADOVI
A7: 1. | B7: SKELA
