Workbook

Sheet opći uvjeti
A1: Red. br. | B1: Opis | C1: Jed. mjere | D1: Dokaznica | E1: Kol. | F1: Jedinična cijena | G1: Ukupno
B2: OPĆI UVJETI UZ TROŠKOVNIK
B4: Cijene upisane u ovaj troškovnik sadrže svu odštetu za pojedine radove i dobave u odnosnim stavkama troškovnika i to u potpuno dogotovljenom stanju, tj. sav rad, naknadu za alat, materijal, sve pripremne, sporedne i završne radove, horizontalne i vertikalne prijenose i prijevoze, postavu i skidanje potrebnih skela i razupora, sve sigurnosne mjere po odredbama HTZ mjera i slično. Pod unesenim cijenama podrazumijevaju se također i sva zakonska davanja, kao i pripomoć kod izvedbe obrtničkih radova (zaštita obrtničkih proizvoda: stolarije, bravarije, limarije, restauratorskih elemenata i slično), sva potrebna ispitivanja građevinskog i drugih ugrađenih materijala zbog podizanja kvalitete i čvrstoće pojedinih proizvoda. | C4: Cijene upisane u ovaj troškovnik sadrže svu odštetu za pojedine radove i dobave u odnosnim stavkama troškovnika i to u potpuno dogotovljenom stanju, tj. sav rad, naknadu za alat, materijal, sve pripremne, sporedne i završne radove, horizontalne i vertikalne prijenose i prijevoze, postavu i skidanje potrebnih skela i razupora, sve sigurnosne mjere po odredbama HTZ mjera i slično. Pod unesenim cijenama podrazumijevaju se također i sva zakonska davanja, kao i pripomoć kod izvedbe obrtničkih radova (zaštita obrtničkih proizvoda: stolarije, bravarije, limarije, restauratorskih elemenata i slično), sva potrebna ispitivanja građevinskog i drugih ugrađenih materijala zbog podizanja kvalitete i čvrstoće pojedinih proizvoda. | D4: Cijene upisane u ovaj troškovnik sadrže svu odštetu za pojedine radove i dobave u odnosnim stavkama troškovnika i to u potpuno dogotovljenom stanju, tj. sav rad, naknadu za alat, materijal, sve pripremne, sporedne i završne radove, horizontalne i vertikalne prijenose i prijevoze, postavu i skidanje potrebnih skela i razupora, sve sigurnosne mjere po odredbama HTZ mjera i slično. Pod unesenim cijenama podrazumijevaju se također i sva zakonska davanja, kao i pripomoć kod izvedbe obrtničkih radova (zaštita obrtničkih proizvoda: stolarije, bravarije, limarije, restauratorskih elemenata i slično), sva potrebna ispitivanja građevinskog i drugih ugrađenih materijala zbog podizanja kvalitete i čvrstoće pojedinih proizvoda.
B5: Sav materijal koji se upotrebljava mora odgovarati postojećim tehničkim propisima i normama. Ukoliko se upotrebljava materijal za koji ne postoji odgovarajući standard, njegovu kvalitetu treba dokazati atestima. | C5: Sav materijal koji se upotrebljava mora odgovarati postojećim tehničkim propisima i normama. Ukoliko se upotrebljava materijal za koji ne postoji odgovarajući standard, njegovu kvalitetu treba dokazati atestima. | D5: Sav materijal koji se upotrebljava mora odgovarati postojećim tehničkim propisima i normama. Ukoliko se upotrebljava materijal za koji ne postoji odgovarajući standard, njegovu kvalitetu treba dokazati atestima.
B6: Davanjem ponude izvoditelj se obvezuje da će pravovremeno nabaviti sav materijal opisan u pojedinim stavkama troškovnika. | C6: Davanjem ponude izvoditelj se obvezuje da će pravovremeno nabaviti sav materijal opisan u pojedinim stavkama troškovnika. U slučaju nemogućnosti nabave opisanog materijala tijekom izvođenja radova, za svaku će se izmjenu prikupiti ponude i u prisutnosti naručitelja i nadzornog inžinjera odabrati najpovoljnija. | D6: Davanjem ponude izvoditelj se obvezuje da će pravovremeno nabaviti sav materijal opisan u pojedinim stavkama troškovnika. U slučaju nemogućnosti nabave opisanog materijala tijekom izvođenja radova, za svaku će se izmjenu prikupiti ponude i u prisutnosti naručitelja i nadzornog inžinjera odabrati najpovoljnija.
B7: Pročelje građevine dekorirano je ukrasnim elementima (restauratorski, vučeni profili), za koje je, prije pregleda sa skele i ispitivanja postojećih materijala, teško dovoljno precizno definirati način i veličinu sanacionog zahvata, pa je prilikom uvođenja u posao obavezan detaljan pregled i utvrđivanje pravog stanja elemenata i načina sanacije. | C7: Pročelje građevine dekorirano je ukrasnim elementima (restauratorski, vučeni profili), za koje je, prije pregleda sa skele i ispitivanja postojećih materijala, teško dovoljno precizno definirati način i veličinu sanacionog zahvata, pa je prilikom uvođenja u posao obavezan detaljan pregled i utvrđivanje pravog stanja elemenata i načina sanacije. | D7: Pročelje građevine dekorirano je ukrasnim elementima (restauratorski, vučeni profili), za koje je, prije pregleda sa skele i ispitivanja postojećih materijala, teško dovoljno precizno definirati način i veličinu sanacionog zahvata, pa je prilikom uvođenja u posao obavezan detaljan pregled i utvrđivanje pravog stanja elemenata i načina sanacije.
B8: Ukoliko opis pojedine stavke dovodi izvoditelja u nedoumicu o načinu izvedbe, treba pravovremeno tražiti objašnjenje od naručitelja. Ako tijekom gradnje dođe do promjena, treba prije početka rada tražiti suglasnost nadzornog inžinjera, predstavnika Gradskog zavoda za zaštitu spomenika kulture i prirode, također treba ugovoriti jediničnu cijenu nove stavke na temelju elemenata datih u ponudi i sve to unijeti u građevinski dnevnik uz ovjeru nadzornog inžinjera. Odnosno, sve izmjene trebaju biti ugovorene u skladu sa Zakonom o javnoj nabavi. Sve više radnje do kojih dođe uslijed promjene načina ili opsega izvedbe, a nisu na spomenuti način utvrđene, upisane i ovjerene, neće se priznati u obračunu. | C8: Ukoliko opis pojedine stavke dovodi izvoditelja u nedoumicu o načinu izvedbe ili kalkulacije cijena, treba pravovremeno tražiti objašnjenje od naručitelja i projektanta. Ako tijekom gradnje dođe do promjena, treba prije početka rada tražiti suglasnost nadzornog inžinjera, predstavnika Gradskog zavoda za zaštitu spomenika kulture i prirode, također treba ugovoriti jediničnu cijenu nove stavke na temelju elemenata datih u ponudi i sve to unijeti u građevinski dnevnik uz ovjeru nadzornog inžinjera. Sve više radnje do kojih dođe uslijed promjene načina ili opsega izvedbe, a nisu na spomenuti način utvrđene, upisane i ovjerene, neće se priznati u obračunu. | D8: Ukoliko opis pojedine stavke dovodi izvoditelja u nedoumicu o načinu izvedbe ili kalkulacije cijena, treba pravovremeno tražiti objašnjenje od naručitelja i projektanta. Ako tijekom gradnje dođe do promjena, treba prije početka rada tražiti suglasnost nadzornog inžinjera, predstavnika Gradskog zavoda za zaštitu spomenika kulture i prirode, također treba ugovoriti jediničnu cijenu nove stavke na temelju elemenata datih u ponudi i sve to unijeti u građevinski dnevnik uz ovjeru nadzornog inžinjera. Sve više radnje do kojih dođe uslijed promjene načina ili opsega izvedbe, a nisu na spomenuti način utvrđene, upisane i ovjerene, neće se priznati u obračunu.
B9: Prije izrade ponude izvoditelj može obići i pregledati građevinu zbog ocjene njezinog građevinskog stanja, radova obuhvaćenih troškovnikom, uvjeta organizacije gradilišta, načina i mogućnosti pristupa građevini, mogućnosti zauzimanja javne površine, postave skele, osiguranja ulaza u građevinu i sl. Prema tome, ponuđena cijena je konačna cijena za realizaciju pojedine troškovničke stavke i ne može se mijenjati. Prilikom uvođenja u posao izvoditelj je obvezan dostaviti detaljni operativni plan izvođenja radova i shemu organizacije gradilišta. | C9: Prije izrade ponude izvoditelj je dužan obići i pregledati građevinu zbog ocjene njezinog građevinskog stanja, radova obuhvaćenih troškovnikom, uvjeta organizacije gradilišta, načina i mogućnosti pristupa građevini, mogućnosti zauzimanja javne površine, postave skele, osiguranja ulaza u građevinu i sl. Prema tome, ponuđena cijena je konačna cijena za realizaciju pojedine troškovničke stavke i ne može se mijenjati. Prilikom davanja ponude izvoditelj je obvezan dostaviti detaljni operativni plan izvođenja radova i shemu organizacije gradilišta. | D9: Prije izrade ponude izvoditelj je dužan obići i pregledati građevinu zbog ocjene njezinog građevinskog stanja, radova obuhvaćenih troškovnikom, uvjeta organizacije gradilišta, načina i mogućnosti pristupa građevini, mogućnosti zauzimanja javne površine, postave skele, osiguranja ulaza u građevinu i sl. Prema tome, ponuđena cijena je konačna cijena za realizaciju pojedine troškovničke stavke i ne može se mijenjati. Prilikom davanja ponude izvoditelj je obvezan dostaviti detaljni operativni plan izvođenja radova i shemu organizacije gradilišta.
B10: Bez obzira na vrstu pogodbe, izvoditelj je obvezan svakodnevno voditi građevinski dnevnik u dva primjerka, a također i građevinsku knjigu, koje će redovito kontrolirati i ovjeravati nadzorni inžinjer, kako bi se uvijek mogle ustanoviti stvarne količine izvedenih radova. | C10: Bez obzira na vrstu pogodbe, izvoditelj je obvezan svakodnevno voditi građevinski dnevnik u dva primjerka, a također i građevinsku knjigu, koje će redovito kontrolirati i ovjeravati nadzorni inžinjer, kako bi se uvijek mogle ustanoviti stvarne količine izvedenih radova. | D10: Bez obzira na vrstu pogodbe, izvoditelj je obvezan svakodnevno voditi građevinski dnevnik u dva primjerka, a također i građevinsku knjigu, koje će redovito kontrolirati i ovjeravati nadzorni inžinjer, kako bi se uvijek mogle ustanoviti stvarne količine izvedenih radova.
B11: Sve radove treba izvoditi isključivo s vanjske strane, tj. sa skele. | C11: Sve radove treba izvoditi isključivo s vanjske strane, tj. sa skele. | D11: Sve radove treba izvoditi isključivo s vanjske strane, tj. sa skele.
A13: Ia. | B13: SKELA I PRIPREMNI RADOVI
B14: Prije izvedbe skele izvoclač je dužan izraditi projekt skeie sa svim mjerama zaštite radnika, prolaznika i stanara. Skela u svemu mora odgovarati postojećim propisima zaštite na radu i zaštite prolaznika i stanara. Sav materijal za izradu skele mora odgovarati postojećim tehničkim propisima i standardima. Na skelu je potrebno postaviti svu potrebnu signalizaciju: rasvjetu, putokaze i slično. Nacrt i proračun skele treba predočiti nadzornom inženjeru te ishoditi suglasnost nadležnih službi za postavljanje skele i zauzimanje javno-prometne površine.
B15: Skela mora sadržavati tunel za prolaz pješaka i stanara u kuću. Skela mora ispunjavati slijedeće zahtjeve: - koristiti ispravne čelične cijevi i spojnice - koristiti ispravnu gradu od drveta - fiksirati i učvrstiti skelu za fasadne zidove gradevine na mjestima otvora - osigurati zaštitu od pada predmeta, materijala i alata sa skele, te na skelu postaviti svu potrebnu signalizaciju Skelu izraditi od čeiičnih bešavnih cijevi sa spojnim elementima. Vanjsku stranu skele prekriti jutenim ili PVC prekrivačima i osigurati od udara groma, skelu je potrebno osigurati protiv deformacija, udara vjetra u svakom polju i protiv prevrtanja.
B16: Za ugradene materijale pribaviti potrebne ateste. Amortizacija skele obračunava se za vrijeme kompletne obnove pročelja s tim da skelu mogu koristiti svi sudionici koji izvode radove na pročelju bez posebne nadoplate. U jediničnu cijenu treba uključiti: - sav rad oko postavi i skidanja skele - izradu statičkog računa i nacrta montaže skele - dostavu svog potrebnog materijala za postavu skele, čiščenje i odvoz smeća nakon skidanja skele - postavu signalizacije i njezino održavanje - sve društvene obveze vezane za radnu snagu i materijal - odžavanje skele za vrijeme trajanja radova - pripremno-završne radove - naknadu za zauzimanje javno-prometne površine.
B17: Svi materijali za izradu skele moraju odgovarati važećim propisima i normama: - HRN C.B3.021. - čelik - HRN C.B5.021. - valjani čelični profili - HRN D.C1.021-041. - rezana grada - HRN M.B4.020-100. — čavli
B18: HRN EN 10210 — toplovaljani čelik S235 HRN EN 10025-2:2007 IPE profili ČE 24 (Č.0361) - čelik
B20: RUŠENJA I DEMONTAŽE | C20: RUŠENJA I DEMONTAŽE | D20: RUŠENJA I DEMONTAŽE
B22: Prije početka radova, izvođač je obavezan postaviti i instalirati sve privremene objekte, zaštitne ograde, opremu i instalacije potrebne za normalno izvođenje radova te iste ukloniti s gradilišta nakon završetka radova. | C22: Prije početka radova, izvođač je obavezan postaviti i instalirati sve privremene objekte, zaštitne ograde, opremu i instalacije potrebne za normalno izvođenje radova te iste ukloniti s gradilišta nakon završetka radova. | D22: Prije početka radova, izvođač je obavezan postaviti i instalirati sve privremene objekte, zaštitne ograde, opremu i instalacije potrebne za normalno izvođenje radova te iste ukloniti s gradilišta nakon završetka radova.
B23: Privremeni objekti, ograde, zaštita i oprema pored ostalog obuhvaća uređenje pristupa, privremeno ograđivanje prostora koji mogu poslužiti za odlaganje materijala, doprema i postava građevinskih dizala, ljestvi i penjalice, ograde, zaštitne ograde, skele, platforme, oznake, protupožarnu opremu i sve ostalo potrebno za brzo i sigurno odvijanje rušenja. Izvođač će sve ove radove izvesti bez posebne naplate. | C23: Privremeni objekti, ograde, zaštita i oprema pored ostalog obuhvaća uređenje pristupa, privremeno ograđivanje prostora koji mogu poslužiti za odlaganje materijala, doprema i postava građevinskih dizala, ljestvi i penjalice, ograde, zaštitne ograde, skele, platforme, oznake, protupožarnu opremu i sve ostalo potrebno za brzo i sigurno odvijanje rušenja. Izvođač će sve ove radove izvesti bez posebne naplate. | D23: Privremeni objekti, ograde, zaštita i oprema pored ostalog obuhvaća uređenje pristupa, privremeno ograđivanje prostora koji mogu poslužiti za odlaganje materijala, doprema i postava građevinskih dizala, ljestvi i penjalice, ograde, zaštitne ograde, skele, platforme, oznake, protupožarnu opremu i sve ostalo potrebno za brzo i sigurno odvijanje rušenja. Izvođač će sve ove radove izvesti bez posebne naplate.
B25: Postupak rušenja | C25: Postupak rušenja | D25: Postupak rušenja
B27: U postupku rušenja – uklanjanja postojećih građevina rad mora biti organiziran tako da se poštuju svi propisi zaštite na radu, a izvršioci – djelatnici moraju biti upoznati s njima i primjenjivati ih u potpunosti. | C27: U postupku rušenja – uklanjanja postojećih građevina rad mora biti organiziran tako da se poštuju svi propisi zaštite na radu, a izvršioci – djelatnici moraju biti upoznati s njima i primjenjivati ih u potpunosti. | D27: U postupku rušenja – uklanjanja postojećih građevina rad mora biti organiziran tako da se poštuju svi propisi zaštite na radu, a izvršioci – djelatnici moraju biti upoznati s njima i primjenjivati ih u potpunosti.
B28: Mora se povesti zaštita prema susjednim objektima i prolaznicima. | C28: Mora se povesti zaštita prema susjednim objektima i prolaznicima. | D28: Mora se povesti zaštita prema susjednim objektima i prolaznicima.
B30: Postupak rušenja započet će: | C30: Postupak rušenja započet će: | D30: Postupak rušenja započet će:
B32: a) isključivanjem elektroinstalacija telefona, plinskih instalacija i vodovoda, s tim da se u neposrednoj blizini osigura dobava vode (polijevanje šute). Isključivanje infrastrukturnih priključaka mora izvesti ovlaštena pravna osoba | C32: a) isključivanjem elektroinstalacija telefona, plinskih instalacija i vodovoda, s tim da se u neposrednoj blizini osigura dobava vode (polijevanje šute). Isključivanje infrastrukturnih priključaka mora izvesti ovlaštena pravna osoba, | D32: a) isključivanjem elektroinstalacija telefona, plinskih instalacija i vodovoda, s tim da se u neposrednoj blizini osigura dobava vode (polijevanje šute). Isključivanje infrastrukturnih priključaka mora izvesti ovlaštena pravna osoba,
B33: b) demontažom svih predmeta i opreme, kao prozora, vrata, sanitarne opreme i slično – koja će se eventualno upotrijebiti | C33: b) demontažom svih predmeta i opreme, kao prozora, vrata, sanitarne opreme i slično – koja će se eventualno upotrijebiti, | D33: b) demontažom svih predmeta i opreme, kao prozora, vrata, sanitarne opreme i slično – koja će se eventualno upotrijebiti,
B34: c) rušenju – demontaži pristupit će se odozgo prema dolje | C34: c) rušenju – demontaži pristupit će se odozgo prema dolje, | D34: c) rušenju – demontaži pristupit će se odozgo prema dolje,
B35: d) ručno će se demontirati pokrov sa krovišta građevina, kao i samo krovište | C35: d) ručno će se demontirati pokrov sa krovišta građevina, kao i samo krovište, | D35: d) ručno će se demontirati pokrov sa krovišta građevina, kao i samo krovište,
B36: e) materijal će biti sortiran i složen na privremenu deponiju na parceli | C36: e) materijal će biti sortiran i složen na privremenu deponiju na parceli, | D36: e) materijal će biti sortiran i složen na privremenu deponiju na parceli,
... B58: Sve detalje izvedbe na pročelju potrebno je dogovoriti i na njih ishoditi suglasnost predstavnika GZZSKP i nadzornog inžinjera, a prije pristupanja izvedbi radova. Obračun svih radova vršiti kako je to naznačeno u opisu stavaka. | C58: Sve detalje izvedbe na pročelju potrebno je dogovoriti i na njih ishoditi suglasnost predstavnika nadležnog Konzervatorskog odjelaP i nadzornog inžinjera, a prije pristupanja izvedbi radova. Obračun svih radova vršiti kako je to naznačeno u opisu stavaka. | D58: Sve detalje izvedbe na pročelju potrebno je dogovoriti i na njih ishoditi suglasnost predstavnika nadležnog Konzervatorskog odjelaP i nadzornog inžinjera, a prije pristupanja izvedbi radova. Obračun svih radova vršiti kako je to naznačeno u opisu stavaka.
B60: TOPLINSKA FASADA ETICS i FASADNA ŽBUKA
B61: Svi radovi moraju se izvesti prema:
B62: * Tehničkim uvjetima za izvođenje fasaderskih radova HRN U.F2.010
B63: * Tehničkom propisu o racionalnoj uporabi energije i toplinskoj zaštiti u zgradama
B64: * Pravilniku o zaštiti na radu u građevinarstvu
B65: * Pravilniku o tehničkim mjerama i uvjetima za završne radove u građevinarstvu Sl.list 49/70
B66: Fasaderski radovi izvode se kompletno prema opisu iz pojedine stavke troškovnika, a prema projektu toplinske zaštite zgrade. Ovim radovima obuhvaćena je izrada toplinske fasade sa završnim obradama.
B67: Prilikom rada na fasaderskim radovima treba se pridržavati uputa proizvođača materijala o izradi fasade i pripremi podloge te vremenskim uvjetima izrade.
B68: U jediničnu cijenu je uključen sav rad i materijal, kako je to u pojedinim stavkama troškovnika opisano. U stavku nije uključena fasadna skela jer je obračunata posebno, a služi svim sudionicima u izgradnji.
B70: Toplinska fasada
B71: Izvodi se u slijedećim slojevima prema uputstvu proizvođača na zidu od opeke.
...

Sheet skela i rušenja
B1: ULIČNO PROČELJE - FAZA I
A2: A | B2: GRAĐEVINSKO-OBRTNIČKI RADOVI
A4: Ia | B4: SKELA I PRIPREMNI RADOVI
A5: 1. | B5: Dobava, postava, skidanje i otprema tunelske skele prolaza za pješake, izrađenog od bešavnih cijevi i potrebnih spojnih elemenata, sa svim potrebnim ukrućenjima i sidrenjima. Pokrov tunela izraditi od mosnica položenih jedne do druge, a preko njih postaviti bitumensku ljepenku s preklopom minimalno 10 cm ili alternativno PVC foliju. Projektom skele treba predvidjeti funkcionalnost kolnog ulaza u vežu.
B6: Izvođač radova dužan je u nivou pločnika izvesti ograđeni prostor za odlaganje potrebnih materijala, a u skladu s rješenjem o zauzimanju javno-prometne površine, što je uključeno u cijenu skele. Prije izvedbe skele izvođač je dužan izraditi projekt skele što je u cijeni stavke.
B7: Obračun se vrši po m2 vertikalne projekcije površine skele. U cijenu uračunati i naknadu za zauzimanje javnih površine.
C8: m2 | D8: =_xlfn.FORMULATEXT(E8) -> =(19+2)*3 | E8: =(19+2)*3 -> 63 | G8: =E8*F8 -> 0
A10: 2. | B10: Doprema, postava, skidanje i otprema cijevne fasadne skele od bešavnih cijevi. Skela se postavlja na prethodno postavljenu tunelsku skelu. Skelu izvesti prema postojećim HTZ propisima i u svemu kako je opisano u općim uvjetima.
B11: U jediničnu cijenu uključiti i zaštitni zastor od jutenih ili plastičnih traka, koje se postavljaju s vanjske strane skele po cijeloj površini. Skelu je potrebno osigurati od prevrtanja sidrenjem u objekat na način da se ne oštete profilacije i štuko dekoracije, a od udara groma uzemljenjem.
B12: Potrebno je izvesti pomoćne željezne ili drvene ljestve – penjalice u svrhu osiguranja vertikalne komunikacije po skeli. Prije izvedbe skele izvođač je dužan izraditi projekt skele, što je u cijeni stavke.
B13: Obračun se vrši po m2 vertikalne projekcije površine skele.
B14: a) ulična strana | C14: m2 | D14: =_xlfn.FORMULATEXT(E14) -> =(19+1)*10 | E14: =(19+1)*10 -> 200 | G14: =E14*F14 -> 0
A16: 3. | B16: Dobava i postava PVC folije za zaštitu otvora na pročelju. Folija se pričvršćuje na doprozornike pomoću drvenih letvica, koje su u cijeni stavke. | C16: m2 | D16: =_xlfn.FORMULATEXT(E16) -> =1,2*1,8*8+1,6*1,8*8 | E16: =1.2*1.8*8+1.6*1.8*8 -> 40.32 | G16: =E16*F16 -> 0
A18: 4. | B18: Ispitivanje vertikalnosti pročelja, nakon postave skele uz prisutnost nadzornog inženjera. Na crtežu pročelja označiti uočene neravnine i kotirati njihove veličine. | C18: h | D18: - | E18: 4 | G18: =E18*F18 -> 0
A20: Ia | B20: SKELA I PRIPREMNI RADOVI -UKUPNO: | G20: =SUM(G6:G19) -> 0
A22: Ib | B22: RUŠENJA I DEMONTAŽE
A23: 1. | B23: Demontaža i privremeno deponiranje pločica sa kućnim brojem, natpisnih ploča, držača za zastave, reklame i slično. Sve navedeno pohraniti na gradilištu ili kod vlasnika-zakupca. Izvoditelj snosi sve troškove ponovne dobave ili izrade pojedinih elemenata u slučaju oštećenja ili otuđenja s gradilišta. Ponovna postava nakon izvedbe radova obnove pročelja uključena u stavku. Za ponovnu postavu reklamnih natpisnih ploča koje nemaju prethodno odobrenje GZZSKP potrebno je izraditi projekte te isto. Obračun po komadu. | C23: kom | D23: - | E23: 3 | G23: =E23*F23 -> 0
A25: 2. | B25: Demontaža i premještanje s novom montažom na dvorišnom pročelju vanjskih klima jedinica. | C25: kom | D25: - | E25: 5 | G25: =E25*F25 -> 0
A27: 3. | B27: Demontaža instalacijskih uređaja na pročelju - portafon, zvona, rasvjetna tijela; sa svim pripadajućim električnim kablovima. Demontirane elemente očistiti, te pohraniti na gradilištu ili kod vlasnika-zakupca. Izvoditelj snosi sve troškove ponovne dobave ili izrade pojedinih elemenata u slučaju oštećenja ili otuđenja s gradilišta. Privremena blokada elektroinstalacija, te ponovna postava instalacijskih uređaja nakon izvedbe radova obnove pročelja uz stavljanje instalacija u funkciju. Ponovna postava uređaja samo uz odobrenje i na pozicijama koje odredi predstavnik Gradskog zavoda za zaštitu spomenika kulture i prirode.
B28: a) portafon | C28: kmpl | D28: - | E28: 1 | G28: =E28*F28 -> 0
A30: 4. | B30: Demontaža prozorskih klupčica. Demontažu obavezno izvodi limar koji je dužan uzeti mjere i uzorke te snimiti detalje izvedbe, što je uključeno u cijenu stavke. Također u cijenu stavke uključiti i sav vertikalni i horizontalni prenos do gradilišne deponije. Obračun po m1.
A31: a) | B31: r.š. 45 cm | C31: m1 | D31: =_xlfn.FORMULATEXT(E31) -> =1,8*6+1,2*6 | E31: =1.8*6+1.2*6 -> 18 | G31: =E31*F31 -> 0
A33: 5. | B33: Demontaža limenih olučnih cijevi za odvodnju oborinske vode, zajedno sa izljevnim koljenom i spojem na ležeći žljeb.
B34: Limene oluke pažljivo demontirati, jer će ponovo biti upotrebljeni. Montaža oluka nakon izvedbe radova sanacije pročelja (opisana u limarskim radovima).
B35: Uključivo sav transport i skladištenje
B36: Obračun po m1. | C36: m1 | D36: =_xlfn.FORMULATEXT(E36) -> =13*1 | E36: =13*1 -> 13 | G36: =E36*F36 -> 0
A38: 6. | B38: Demontaža ležećeg žlijeba s krovnog vijenca i opšava ruba krova ispod žljeba. Izvedeno od pocinčanog lima d=0.55mm, razvijene širine 70 cm (žljeb) i 80 cm (podložni lim).
B39: Limene oluke pažljivo demontirati, jer će ponovo biti upotrebljeni. Uključen transport i odlaganje lima i slojeva krova na gradilišnu privremenu deponiju, prenosom kantama i spuštanjem koloturom od mjesta rada na gradilištnu deponiju - H=18 m. Montaža oluka nakon izvedbe radova sanacije pročelja (opisana u limarskim radovima).
A40: - | B40: ležeći žljeb r.š. 70 cm | C40: m1 | D40: =_xlfn.FORMULATEXT(E41) -> =19*1 | E40: =19*1 -> 19 | G40: =E41*F40 -> 0
A41: - | B41: opšav ruba krova r.š. 80 cm | C41: m1 | D41: =_xlfn.FORMULATEXT(E41) -> =19*1 | E41: =19*1 -> 19 | G41: =E42*F41 -> 0
A43: 7. | B43: Demontaža postojećih opšava. Demontažu obavezno izvodi limar koji je dužan uzeti mjere i uzorke te snimiti detalje izvedbe, što je uključeno u cijenu stavke. Također u cijenu stavke uključiti i sav vertikalni i horizontalni prenos do gradilišne deponije. Obračun po m1 r.š.35 cm
B44: a) vijenac između prizemlja i 1.kata od pocinčanog lima | C44: m1 | D44: =_xlfn.FORMULATEXT(E44) -> =19,4*1 | E44: =19.4*1 -> 19.4 | G44: =E44*F44 -> 0
A46: 8. | B46: Ručno obijanje trošne žbuke debljine 2,5-4 cm sa ravnih ploha pročelja, nakon konzervatorskih istraživanja. Rad izvoditi pažljivo naročito u blizini profilacija i dekoracija kako se ne bi oštetili dekorativni elementi od štuka ili žbuke. Ziđe pročelja je od opeke. Nakon obijanja žbuke zid očistiti skobama do dubine 1 cm. Potom cijelu površinu otprašiti i isprati vodom. Uključivo prenos i odlaganje na gradilišnu deponiju šute. Prije obijanja snimiti jednostavne profilacije, uzeti otiske i izraditi gipsane odljeve, te izraditi nacrte u mjerilu 1-1 i dati ih na ovjeru predstavniku GZZSKP. Obračun po m2 ortogonalne projekcije pročelja ne računajući površine prozorskih otvora i složenih profilacija. Obija se kompletna žbuka. Obzirom da je neznatan dio žbuke otpao s pročelja, predviđa se obijanje 100% površine.
A47: 8.1. | B47: ravna ploha 1. i 2.kat-R1 | C47: m2 | D47: =_xlfn.FORMULATEXT(E47) -> =19,6*7,6-4*1,2*1,8*2+4*1,6*1,8 | E47: =19.6*7.6-4*1.2*1.8*2+4*1.6*1.8 -> 143.2 | G47: =E47*F47 -> 0
A48: 8.2. | B48: ravna ploha na klupčici prozora- 2. kat-R2 | C48: m2 | D48: =_xlfn.FORMULATEXT(E48) -> =5*2,2*0,15 | E48: =5*2.2*0.15 -> 1.65 | G48: =E48*F48 -> 0
B49: šablone -Š1 | C49: kmpl | D49: - | E49: 1 | G49: =E49*F49 -> 0
A50: 8.3. | B50: ravna ploha na klupčici prozora- 1. kat-R3 | C50: m2 | D50: =_xlfn.FORMULATEXT(E50) -> =5*2,2*0,15 | E50: =5*2.2*0.15 -> 1.65 | G50: =E50*F50 -> 0
A51: - | B51: šablone -Š2 | C51: kmpl | D51: - | E51: 1 | G51: =E51*F51 -> 0
A52: 8.4. | B52: špaleta prozora na 1. i 2. katu-R4 | C52: m2 | D52: =_xlfn.FORMULATEXT(E52) -> =((1,6+1,8*2)*4+(1,2+1,8*2)*4*2)*0,2 | E52: =((1.6+1.8*2)*4+(1.2+1.8*2)*4*2)*0.2 -> 11.84 | G52: =E52*F52 -> 0
A53: 8.5. | B53: ravni dio razdjelni vijenac prizemlje prvi kat-R5 | C53: m2 | D53: =_xlfn.FORMULATEXT(E53) -> =19,6*0,1*1 | E53: =19.6*0.1*1 -> 1.96 | G53: =E53*F53 -> 0
...

Sheet zidarski
B1: ULIČNO PROČELJE - FAZA I
A2: A | B2: GRAĐEVINSKO-OBRTNIČKI RADOVI
A4: II | B4: ZIDARSKO FASADERSKI RADOVI
A5: 1. | B5: Zidanje oštećenih dijelova zida i istaka nastalih ispadanjem opeke , te oštećenjem kod demontaže čelične konstrukcije. Stavkom je obuhvaćeno vađenje iz ležajeva dotrajale opeke i ponovno zidanje novom punom opekom u produženom mortu. Prilikom zidanja treba poštivati postojeći vez opeke, a kod istaknutih dijelova konstrukcije vijenaca opeku odsjecanjem prilagoditi izvornom obliku. Obračun po m2 saniranog zida i m1 sanirane istake vijenaca, a prema prethodnom pregledu i upisu nadzornog inženjera u građevinski dnevnik.
A6: a) | B6: zid | C6: m2 | D6: =_xlfn.FORMULATEXT(E6) -> =19,6*12*0,1 | E6: =19.6*12*0.1 -> 23.52 | G6: =E6*F6 -> 0
A7: b) | B7: vijenac | C7: m1 | D7: =_xlfn.FORMULATEXT(E7) -> =19*0,3 | E7: =19*0.3 -> 5.7 | G7: =E7*F7 -> 0
A9: 2. | B9: Žbukanje ravnih površina prizemlja zgrade sa linijskim horizontalnim i kosim profilacijama grubom i finom žbukom, debljine 4-4,5 cm. Žbuka se nanosi na ravne površine pročelja gdje je postojeća žbuka otučena, reške očišćene, a površina otprašena i oprana. U cijenu stavke uključene sve faze nanošenja žbuke na ravnu površinu kako bi se postigla žbuka u svemu prema postojećoj. Za kvalitetu žbuke izvoditelj je dužan pribaviti stručni nalaz i mišljenje ovlaštene ustanove za ispitivanje kvalitete žbuke, što je obuhvaćeno jediničnom cijenom ove stavke. Obračun po m2 ortogonalne projekcije ne računajući otvore i kompletu šablona. Adekvatan koeficijent složenosti uračunati u cijenu stavke.
C10: m2 | D10: =14,8*4-1,25*2,45*3-1,13*2,9-2,06*3,4 | E10: =(19.6-2.4)*3 -> 51.6 | G10: =E10*F10 -> 0
B11: šablone-P-R | C11: kmpl | D11: - | E11: 3 | G11: =E11*F11 -> 0
A13: 4. | B13: RAVNE PLOHE PROČELJA:
B14: Žbukanje ravnih površina pročelja produžnom grubom i finom žbukom m-5, omjera 1:3:9 zaglađene završne obrade debljine 3-4,5 cm, uz prethodno pranje površina vodom pod pritiskom. Rad uključuje žbukanje manjih površina uz korištenje jednostavnih šablona.
B15: Žbuka se nanosi na ravne površine pročelja gdje je postojeća žbuka otućena, reške očišćene, a površina otprašena i oprena. Žbuku izvesti prema slijedećim fazama: površinu zida oprati vodom pod pritiskom, na navlaženu površinu zida nanijeti rijetki cementni mort-špric omjera 1:2. Na tako pripremljenu podlogu nanijeti osnovni sloj grube produžne žbuke debljine 2-2,5 cm. Završni sloj fino zagladiti. Za kvalitetu žbuke izvoditelj je dužan pribaviti stručni nalaz i mišljenje ovlaštene ustanove za ispitivanje kvalitete žbuke, što je obuhvaćeno jediničnom cijenom ove stavke.
B16: Stavka uključuje izvedbu ploha s jednostavnim šablonama. Obračun se vrši po m2 ortogonalne projekcije pročelja, ne računajući površine otvora, profilacija i ukrasa i kompletu šablona.
A17: 4.1. | B17: ravna ploha 1. i 2.kat-R1 | C17: m2 | D17: =_xlfn.FORMULATEXT(E17) -> =19,6*7,6-4*1,2*1,8*2+4*1,6*1,8 | E17: =19.6*7.6-4*1.2*1.8*2+4*1.6*1.8 -> 143.2 | G17: =E17*F17 -> 0
A18: 4.2. | B18: ravna ploha na klupčici prozora- 2. kat-R2 | C18: m2 | D18: =_xlfn.FORMULATEXT(E18) -> =5*2,2*0,15 | E18: =5*2.2*0.15 -> 1.65 | G18: =E18*F18 -> 0
B19: šablone -Š1 | C19: kmpl | D19: - | E19: 1 | G19: =E19*F19 -> 0
A20: 4.3. | B20: ravna ploha na klupčici prozora- 1. kat-R3 | C20: m2 | D20: =_xlfn.FORMULATEXT(E20) -> =5*2,2*0,15 | E20: =5*2.2*0.15 -> 1.65 | G20: =E20*F20 -> 0
A21: - | B21: šablone -Š2 | C21: kmpl | D21: - | E21: 1 | G21: =E21*F21 -> 0
A22: 4.4. | B22: špaleta prozora na 1. i 2. katu-R4 | C22: m2 | D22: =_xlfn.FORMULATEXT(E22) -> =((1,6+1,8*2)*4+(1,2+1,8*2)*4*2)*0,2 | E22: =((1.6+1.8*2)*4+(1.2+1.8*2)*4*2)*0.2 -> 11.84 | G22: =E22*F22 -> 0
A23: 4.5. | B23: ravni dio razdjelni vijenac prizemlje prvi kat-R5 | C23: m2 | D23: =_xlfn.FORMULATEXT(E23) -> =19,6*0,1*1 | E23: =19.6*0.1*1 -> 1.96 | G23: =E23*F23 -> 0
A24: - | B24: šablone -Š3 | C24: kmpl | D24: - | E24: 1 | G24: =E24*F24 -> 0
A25: 4.6. | B25: ravni dio- špaleta prozora u prizemlju-R6 | C25: m2 | D25: =_xlfn.FORMULATEXT(E25) -> =5,4*0,3*4 | E25: =5.4*0.3*4 -> 6.48 | G25: =E25*F25 -> 0
B26: šablone -S4 | C26: kmpl | D26: - | E26: 1 | G26: =E26*F26 -> 0
A27: 4.7. | B27: ravna ploha- klupčica prozora u prizemlju- R7 | C27: m2 | D27: =_xlfn.FORMULATEXT(E27) -> =2,3*4*0,12 | E27: =2.3*4*0.12 -> 1.104 | G27: =E27*F27 -> 0
A28: 4.8. | B28: plohe pročelja -podrum- R8 | C28: m2 | D28: =_xlfn.FORMULATEXT(E28) -> =(7,7*2+0,3*4)*1-2*1*0,6 | E28: =(7.7*2+0.3*4)*1-2*1*0.6 -> 15.4 | G28: =E28*F28 -> 0
A30: 5. | B30: Izrada grube žbuke na složenim vučenim profilacijama s obratima, produžnom cementnom žbukom m-5 omjera 1:2:6, debljine 3,5-5,0 cm, sa završnom zaglađenom obradom. Profilacije izvoditi sa šablonama koje je prethodno pregledao i odobrio predstavnik GZZSKP. Šablone upotrebljavati uz obveznu postavu vodilica. Obračun po m1 srednje linije profilacije bez ikakvih drugih dodataka na rubove unutar profilacija, promjene smjera (lomove) i završetke i komadu obrata.
A31: 5.1. | B31: KV-P1
B32: Krovni vijenac
B33: razvijena širina: 60 cm | C33: kmpl | D33: - | E33: 1 | G33: =E33*F33 -> 0
C34: m1 | D34: =_xlfn.FORMULATEXT(E34) -> =19,1+0,2*4 | E34: =19.1+0.2*4 -> 19.9 | G34: =E34*F34 -> 0
A35: 5.2. | B35: KV-P2
B36: Donja profilacija ispod krovnog vijenca
B37: razvijena širina: 60 cm | C37: kmpl | D37: - | E37: 1 | G37: =E37*F37 -> 0
C38: m1 | D38: =_xlfn.FORMULATEXT(E38) -> =19,1+0,2*4 | E38: =19.1+0.2*4 -> 19.9 | G38: =E38*F38 -> 0
A39: 5.3. | B39: 2-P1
B40: Profilacija erta prozora na 2.katu
B41: razvijena širina: 15 cm | C41: kmpl | D41: - | E41: 1 | G41: =E41*F41 -> 0
C42: m1 | D42: =_xlfn.FORMULATEXT(E42) -> =5,8*2+5,3*4 | E42: =5.8*2+5.3*4 -> 32.8 | G42: =E42*F42 -> 0
A43: 5.4. | B43: 2-P2
B44: Profilacija ispod klupčice na 2.katu
...

Sheet limarski
A1: IV | B1: LIMARSKI RADOVI
A3: 1. | B3: Montaža postojećih okruglih olučnih cijevi za odvodnju oborinske vode od pocinčanog lima.
B4: Uključivo obujmice za učvršćenje u zid, spoj na horizontalni ležeći žljeb, prijelazno koljeno, te spoj na izljevno koljeno.
B5: Demontaža postojećih oluka opisana je u radovima 'Demontaža i rušenja'.
B6: Obračun po m1. | C6: m1 | D6: =_xlfn.FORMULATEXT(E6) -> =1*12 | E6: =1*12 -> 12 | G6: =E6*F6 -> 0
A8: 2. | B8: Montaža postojećeg ležećeg žljeba i opšava ruba krova ispod žljeba pocinčanim limom. Lim podvući pod crijep, što obuhvaća prethodno pažljivo raskrivanje crijepa s ruba krova, u širini cca 1 m, te nakon zamjene limarije - ponovna postava postojećeg crijepa.
B9: Uključena sva pričvršćenja i osiguranja, te postava bitumenske ljepenke ispod opšava.
B10: Uključivo spoj na vertikalni oluk.
A11: - | B11: viseći žljeb r.š. 70 cm | C11: m1 | D11: =_xlfn.FORMULATEXT(E11) -> =19*1 | E11: =19*1 -> 19 | G11: =E11*F11 -> 0
A12: - | B12: opšav ruba krova r.š. 80 cm | C12: m1 | D12: =_xlfn.FORMULATEXT(E12) -> =19*1 | E12: =19*1 -> 19 | G12: =E12*F12 -> 0
A14: 3. | B14: Dobava, izrada i postava opšava prozorskih klupčica iz pocinčanog lima. Na vanjskom rubu izvesti okapnicu udaljenu min. 3 cm od žbuke, a na strani do zida lim podvući pod žbuku i uzdići 1 cm. Sva mjesta dodira lima i žbuke ili betona zaštititi razdjelnim parorasteretnim slojem. Jediničnom cijenom obuhvatiti kompletan rad i materijal. Obračun po m1 i razvijenoj širini lima, te m2 folije. Razvijena širina lima 25 cm.
A15: a) | B15: razvijena širina 45 cm | C15: m1 | D15: =_xlfn.FORMULATEXT(E15) -> =1,8*8+8*1,2 | E15: =1.8*8+8*1.2 -> 24 | G15: =E15*F15 -> 0
A16: b) | B16: folija | C16: m2 | D16: =_xlfn.FORMULATEXT(E16) -> =1,8*8+8*1,2 | E16: =1.8*8+8*1.2 -> 24 | G16: =E16*F16 -> 0
A18: 4. | B18: Dobava, izrada i postava opšava razdjelnog vijenca iz pocinčanog lima. Na vanjskom rubu izvesti okapnicu udaljenu min. 2 cm od žbuke, a na strani do zida lim podvući pod žbuku i uzdići 1 cm. Sva mjesta dodira lima i žbuke ili betona zaštititi razdjelnim parorasteretnim slojem. Jediničnom cijenom obuhvatiti kompletan rad i materijal. Obračun po m1 i razvijenoj širini lima, te m2 folije.
A19: a) | B19: razvijena širina 45 cm | C19: m1 | D19: =_xlfn.FORMULATEXT(E19) -> =19*1 | E19: =19*1 -> 19 | G19: =E19*F19 -> 0
A20: b) | B20: folija | C20: m2 | D20: =_xlfn.FORMULATEXT(E20) -> =19*1 | E20: =19*1 -> 19 | G20: =E20*F20 -> 0
A23: 5. | B23: Prilagodba postojećih ili izrada novih vrata plinskog ormarića, kako bi ista bila u fluhti s novom lijinom žbuke | C23: komplet | D23: - | E23: 1
A26: IV | B26: LIMARSKI RADOVI- UKUPNO | G26: =SUM(G4:G25) -> 0

Sheet stolarski
A1: V | B1: STOLARSKI RADOVI
A3: 1. | B3: Detaljan pregled postojeće stolarije kako bi se odredio način i obim sanacije ili zamjene dotrajalih dijelova, odnosno izrade novih prozora u cijelosti, te prikupili podaci o materijalu, detaljima, profilacijama i obradama. Obračun po stvarno utrošenim satima.
C4: h | D4: - | E4: 6 | G4: =E4*F4 -> 0
A5: 2. | B5: Detaljan pregled i popravak dvokrilnih masivnih, uklađenih hrastovih ulaznih vrata. Dimenzije 145/350 cm. Nadsvjetlo vrata je ostakljeno float staklom. Stavka obuhvaća izradu i ugradnju novog sokla od hrastovine, čišćenje brušenjem, zapunjavanje svih reški i raspuklina i oštećenja dvokomponentnim punilom na bazi epoksidnih smola. U cijenu uračunati kompletan materijal, u svemu prema postojećem. Obračun po komadu. | C5: kom | D5: 1
A7: V | B7: STOLARSKI RADOVI- UKUPNO | G7: =SUM(G3:G6) -> 0

Sheet ličilački
A1: VI | B1: STAKLARSKI RADOVI
A2: 1. | B2: Ostakljenje prozora na uličnoj strani
B3: Ostakljenje jednostrukim staklom d=4 mm.
B4: Uključen sav rad, materijal i pribor. Komplet izvedeno.
B5: Obračun po m2 ostakljene površine. | C5: m2 | D5: =_xlfn.FORMULATEXT(E5) -> =2*1 | E5: =2*1 -> 2 | G5: =E5*F5 -> 0
A8: VI | B8: STAKLARSKI RADOVI- UKUPNO | G8: =SUM(G2:G7) -> 0
A10: VII | B10: LIČILAČKI RADOVI
A12: 1. | B12: Izrada tonirane mineralne žbuke veće granulacije u prizemlju, te iste na cijelom pročelju zgrade i profilacijama uz predložene dvije različite završne obrade iste za koje je potrebno predvidjeti izradu uzorka Podloga mora biti suha, čista, čvrsta, građevinski pripremljena te impregnirana.
B13: Jediničnom cijenom obuhvatiti:
B14: Boju i ton određuje predstavnik GZZSKP.
A15: 1.1. | B15: KV-P1
B16: Krovni vijenac
B17: razvijena širina: 60 cm | C17: kmpl | D17: - | E17: 1 | G17: =E17*F17 -> 0
C18: m1 | D18: =_xlfn.FORMULATEXT(E18) -> =19,1+0,2*4 | E18: =19.1+0.2*4 -> 19.9 | G18: =E18*F18 -> 0
A19: 1.2. | B19: KV-P2
B20: Donja profilacija ispod krovnog vijenca
B21: razvijena širina: 60 cm | C21: kmpl | D21: - | E21: 1 | G21: =E21*F21 -> 0
C22: m1 | D22: =_xlfn.FORMULATEXT(E22) -> =19,1+0,2*4 | E22: =19.1+0.2*4 -> 19.9 | G22: =E22*F22 -> 0
A23: 1.3. | B23: 2-P1
B24: Profilacija erta prozora na 2.katu
B25: razvijena širina: 15 cm | C25: kmpl | D25: - | E25: 1 | G25: =E25*F25 -> 0
C26: m1 | D26: =_xlfn.FORMULATEXT(E26) -> =5,8*2+5,3*4 | E26: =5.8*2+5.3*4 -> 32.8 | G26: =E26*F26 -> 0
A27: 1.4. | B27: 2-P2
A28: . | B28: Profilacija ispod klupčice na 2.katu
B29: razvijena širina: 10 cm | C29: kmpl | D29: - | E29: 1 | G29: =E29*F29 -> 0
C30: m1 | D30: =_xlfn.FORMULATEXT(E30) -> =2,2*2+1,6*4 | E30: =2.2*2+1.6*4 -> 10.8 | G30: =E30*F30 -> 0
A31: 1.5. | B31: 1-P1
B32: Profilacija erta prozora na 1.katu
B33: razvijena širina: 15 cm | C33: kmpl | D33: - | E33: 1 | G33: =E33*F33 -> 0
C34: m1 | D34: =_xlfn.FORMULATEXT(E34) -> =5,8*2+5,3*4 | E34: =5.8*2+5.3*4 -> 32.8 | G34: =E34*F34 -> 0
A35: 1.6. | B35: 1-P2
B36: Profilacija ispod klupčice na 1.katu
B37: razvijena širina: 10 cm | C37: kmpl | D37: - | E37: 1 | G37: =E37*F37 -> 0
C38: m1 | D38: =_xlfn.FORMULATEXT(E38) -> =2,2*2+1,6*4 | E38: =2.2*2+1.6*4 -> 10.8 | G38: =E38*F38 -> 0
A39: 1.7. | B39: RV-P1
B40: Profilacija ispod razdjelnog vijenca
B41: razvijena širina: 15 cm | C41: kmpl | D41: - | E41: 1 | G41: =E41*F41 -> 0
C42: m1 | D42: =_xlfn.FORMULATEXT(E42) -> =19,1+0,2*4 | E42: =19.1+0.2*4 -> 19.9 | G42: =E42*F42 -> 0
A43: 1.8. | B43: PR-P1
B44: Profilacija ispod klupčice u prizemlju-okap
...

Sheet restauratorki
A1: B | B1: KONZERVATORSKI I RESTAURATORSKI RADOVI
A2: Ia | B2: KONZERVATORSKA ISTRAŽIVANJA
A3: 1. | B3: Konzervatorska istraživanja žbuke i boje pročelja nakon postave skele, a prije rušenja i demontaža, radi utvrđivanja izgleda pročelja u raznim povijesnim razdobljima, te radi utvrđivanja stanja obrada i konstrukcija. Prema odredbama GZZSKP otvoriti konzervatorske sonde na ravnim površinama kata, prizemlja, u zoni podnožja, na vučenim profilacijama vijenaca, nadprozornika, prozorskih klupčica, kapitela i baza pilastara, kiparskim i kamenim elementima, te stolariji i bravariji. Stavka uključuje izradu nacrta istraživanja s ucrtanim i opisanim nalazima. Obračun po kom sondi i kom elaborat
B4: sonde | C4: kom | D4: - | E4: 10 | G4: =E4*F4 -> 0
B5: elaborat | C5: kom | D5: - | E5: 1 | G5: =E5*F5 -> 0
A7: Ia | B7: KONZERVATORSKA ISTRAŽIVANJA UKUPNO: | G7: =SUM(G4:G6) -> 0
A9: Ib | B9: RESTAURATORSKI RADOVI NA DRVENIM I METALNIM ELEMENTIMA
A10: 1. | B10: Popravak i ličenje ulaznih vrata. Obračun po komadu.
B11: Izvedba na licu mjesta zbog nemogućnosti demontaže. U stavku uključena izvedba dijelova koji nedostaju, te popravak i nadomjestak pripadajućeg okova. Stavka uključuje uklanjanje postojećeg naliča, uklanjanje slabovezanih i natrulih dijelova, kitanje s brušenjem, impregnacije i temeljni premaz, te sve pripremne radnje za konačno ličenje i ličenje. U stavku je uključen sav horizontalni i vertikalni transport , kao i eventualno potrebna radna skela. Ton i boje određuje predstavnik GZZSKP.
B12: Labave dijelove kao i stari nalič, hrđu i nečistoće potrebno je temeljito ukloniti sa žičanom četkom, grubim brusnim papirom ili pjeskarenjem.
B13: Jediničnom cijenom obuhvatiti sve potrebne predradnje, sav materijal i pribor za rad kao i sve zaštite okoline od oštećenja. Obračun po kom vrata. Dim. 150/380
C14: kom | D14: - | E14: 1 | G14: =E14*F14 -> 0
A15: 2. | B15: Izrada novih okova na mjestima gdje nije moguć popravak u svemu prema postojećem. Zamjenu izvršiti uz suglasnost nadzornog inženjera i predstavnika GZZSKP. | C15: kom | D15: - | E15: 2 | G15: =E15*F15 -> 0
A16: 3. | B16: Pregled, preventivna zaštita i konsolidacija in situ te čišćenje i pažljiva restauracija izvornog lijevanog natpisa izvođača radova na pročelju zgrade | C16: kom | D16: - | E16: 1 | G16: =E16*F16 -> 0
A18: 4. | B18: Izvedba nove oznake za sklonište lazurnom, polutransparentnom mineralnom bojom, prema uzoru na izvornu | C18: kom | D18: - | E18: 1 | G18: =E18*F18 -> 0
A20: Ib | B20: RESTAURATORSKI RADOVI NA DRVENIM I METALNIM ELEMENTIMA | G20: =SUM(G13:G16) -> 0

Sheet druga faza
B1: ULIČNO PROČELJE - FAZA II
A2: VIII | B2: STOLARSKI RADOVI
B3: NOVA STOLARIJA
A4: 1. | B4: Izrada i dobava nove stolarije, izrađene od bora ili ariša I. klase vlažnosti do max.18% Dimenzije, profilacije i okov treba odobriti predstavnik GZZSKP.
B5: Obračun po komadu. Izvesti prema izmjeri u naravi.
B6: U cijenu je uračunat sav potreban okov.
B7: Ostakljenje krila je float staklom.
A8: a) | B8: Izrada i dobava novih drvenih, dvostrukih, dvokrilnih prozora sa pošvama širine 20 cm, nadsvjetlom s dekorativnim razdjelnim letvicama, šprljcima i profiliranom sudarnom letvom,u svemu prema postojećim prozorima (U-P1), pazeći da se ponove izvorne dimenzije, profilacije i način ostakljenja. U cijenu je uračunat sav potreban okov u svemu prema izvornom. Vanjska krila otvaraju se prema unutra.
B9: STOLARSKA STAVKA U-P1
B10: dim. 165/185 cm | C10: kom | E10: 7 | G10: =E10*F10 -> 0
B11: STOLARSKA STAVKA U-P2
B12: dim. 115/185 cm | C12: kom | E12: 6 | G12: =E12*F12 -> 0
A13: b) | B13: Izrada i dobava novih drvenih, jednostrukih, dvokrilnih prozora u podrumu pazeći da se ponove izvorne dimenzije, profilacije i način ostakljenja. U cijenu je uračunat sav potreban okov u svemu prema izvornom.
B14: STOLARSKA STAVKA U-P3
B15: dim. 100/60 cm | C15: kom | E15: 2 | G15: =E15*F15 -> 0
A16: VIII | B16: STOLARSKI RADOVI UKUPNO | G16: =SUM(G8:G12) -> 0
A18: IX | B18: BRAVARSKI RADOVI
A19: 1. | B19: Izrada novih fiksnih protuprovalnih rešetki u skladu sa postojećima.
B20: Rešetku čine nosive horizontale i vertikale od kvadratnog čeličnog profila dimenzija 20/20 mm na razmaku od 30 cm, sidrene bočno u zidarski otvor. Ispuna je napravljena od čeličnih kvadratnih profila dimenzija 15/15 mm, dijagonalno postavljenih sa kružnim ukrasnim elementom na mjestu križanja profila. Sav potreban pribor za montažu uključen je u cijenu stavke.
B21: Dimenzije i profilacije treba odobriti predstavnik GZZSKP. Izvesti prema izmjeri u naravi. Obračun po komadu.
A22: a) | B22: ugrađuje se ispred Stolarske stavke U-P2
B23: dim. 100/60cm | C23: kom | E23: 2 | G23: =E23*F23 -> 0
A24: IX | B24: BRAVARSKI RADOVI- UKUPNO | G24: =SUM(G20:G23) -> 0
A26: X | B26: RESTAURATORSKI RADOVI NA DRVENIM I METALNIM ELEMENTIMA | G26: =SUM(G21:G24) -> 0
A27: 1. | B27: Popravak postojećih drvenih, dvostrukih, dvokrilnih prozora sa pošvama širine 20 cm, nadsvjetlom s dekorativnim razdjelnim letvicama, šprljcima i profiliranom sudarnom letvom,u svemu prema postojećim prozorima, pazeći da se ponove izvorne dimenzije, profilacije i način ostakljenja. U cijenu je uračunat sav potreban okov u svemu prema izvornom. Vanjska krila otvaraju se prema unutra.
A28: a) | B28: dim. 165/185 cm | C28: kom | E28: 1 | G28: =E28*F28 -> 0
A29: b) | B29: dim. 115/185 cm | C29: kom | E29: 2 | G29: =E29*F29 -> 0
A31: X | B31: RESTAURATORSKI RADOVI NA DRVENIM I METALNIM ELEMENTIMA

Sheet rekapitulacija
B3: REKAPITULACIJA
B7: ULIČNO PROČELJE - FAZA I
A8: A | B8: GRAĐEVINSKO-OBRTNIČKI RADOVI
A9: Ia | B9: ='skela i rušenja'!B20 -> SKELA I PRIPREMNI RADOVI -UKUPNO: | G9: ='skela i rušenja'!G20 -> 0
A10: Ib | B10: ='skela i rušenja'!B103 -> RUŠENJA I DEMONTAŽE UKUPNO: | G10: ='skela i rušenja'!G103 -> 0
A11: II | B11: =zidarski!B84 -> ZIDARSKO FASADERSKI RADOVI- UKUPNO | G11: =zidarski!G84 -> 0
A12: III | B12: =zidarski!B91 -> RAZNI GRAĐEVINSKI RADOVI- UKUPNO | G12: =zidarski!G91 -> 0
A13: IV | B13: =limarski!B26 -> LIMARSKI RADOVI- UKUPNO | G13: =limarski!G26 -> 0
A14: V | B14: =stolarski!B7 -> STOLARSKI RADOVI- UKUPNO | G14: =stolarski!G7 -> 0
A15: VI | B15: =ličilački!B8 -> STAKLARSKI RADOVI- UKUPNO | G15: =ličilački!G8 -> 0
A16: VII | B16: =ličilački!B70 -> LIČILAČKI RADOVI- UKUPNO | G16: =ličilački!G70 -> 0
A18: B | B18: RESTAURATORSKI RADOVI
A19: Ia | B19: =restauratorki!B7 -> KONZERVATORSKA ISTRAŽIVANJA UKUPNO: | G19: =restauratorki!G7 -> 0
A20: Ib | B20: =restauratorki!B20 -> RESTAURATORSKI RADOVI NA DRVENIM I METALNIM ELEMENTIMA | G20: =restauratorki!G20 -> 0
A21: B | B21: RESTAURATORSKI RADOVI | G21: =SUM(G19:G20) -> 0
A23: A | B23: GRAĐEVINSKO-OBRTNIČKI RADOVI | G23: =G33 -> 0
A24: B | B24: RESTAURATORSKI RADOVI | G24: =G21 -> 0
B25: SVEUKUPNO-bez PDV-A | G25: =SUM(G23:G24) -> 0
B26: PDV | G26: =0.25*G25 -> 0
B27: SVEUKUPNO -s PDV-om | G27: =G25+G26 -> 0
B29: ULIČNO PROČELJE - FAZA II
A30: VIII | B30: ='druga faza'!B16 -> STOLARSKI RADOVI UKUPNO | G30: ='druga faza'!G16 -> 0
A31: IX | B31: ='druga faza'!B24 -> BRAVARSKI RADOVI- UKUPNO | G31: ='druga faza'!G24 -> 0
A32: ='druga faza'!A31 -> X | B32: ='druga faza'!B26 -> RESTAURATORSKI RADOVI NA DRVENIM I METALNIM ELEMENTIMA | G32: =restauratorki!G13 -> 0
A33: A | B33: GRAĐEVINSKO-OBRTNIČKI RADOVI UKUPNO | G33: =SUM(G9:G15) -> 0
