Workbook

Sheet OPĆI UVJETI-NASELJE BLATO ZG
C4: TROŠKOVNIK
C6: STAMBENO - POSLOVNA GRAĐEVINA, BLATO
C9: Projektant: Ivan Vulić, dipl.ing.arh. A855
C11: OPĆI UVJETI
C12: Napomena: opći uvjeti vrijede za sve grupe radova
C14: U skladu sa odredbama čl. 209. i čl. 210. ZJN 2016 daju se sljedeće napomene koje se odnose na sve stavke ovog Troškovnika:
C16: Nacrti, tehnički opisi i troškovnik čine cjelinu projekta i što je makar jednom od njih naznačeno obveza je za ponuditelja. Sve odredbe koji su navedene u njima smatraju se sastavnim dijelom opisa svake pojedine stavke troškovnika.
C17: Ponuditelj podnošenjem ponude potvrđuje da je tehničku dokumentaciju proučio i razumio, da je izvršio provjeru usklađenosti i količina, da u njoj nema nedostataka, te da je prihvaća kao osnov za izgradnju.
C18: Nepoznavanje bilo kojeg od dijelova projekta kojeg je ponuditelj imao na uvid tijekom davanja ponude neće se prihvatiti kao razlog za naknadno povišenje jediničnih cijena ili greške u izvedbi ili produljenja roka.
C19: Ukoliko se stavkom troškovnika navodi materijal ili dr. koji nije obuhvaćen propisima, onda se ima u svemu izvesti prema uputama proizvođača, te priložiti potrebne garancije i ateste od za to ovlaštenih ustanova.
C20: Stavkama su navedene referentne završne obrade i boje.
C21: Pri radu izvoditelj obvezno treba primjenjivati zakonski propisane mjere zaštite na radu i zaštite od požara. U slučaju da se izvoditelj toga ne pridržava, može mu se zabraniti daljnji rad. Također treba pažljivo raditi uz susjedne postojeće građevine ili već izvedene radove kako ne bi prouzročio moguće štete. Eventualno izazvane štete od strane izvoditelja ili njegovog kooperanta, dužan je otkloniti o svom trošku.
... C114: Točan aritmetički izračun troškovnika je odgovornost ponuđača.

Sheet 1-GEODETSKI
B4: TROŠKOVNIK
B6: STAMBENO - POSLOVNA GRAĐEVINA, BLATO
B8: MAPA I.
B9: PROJEKT ARHITEKTURE
B10: GRAĐEVINSKO - ZANATSKI RADOVI
B12: Projektant: Ivan Vulić, dipl.ing.arh. A855
A46: r.br. | B46: OPIS | C46: jed. mj. | D46: Količina ULAZ A | E46: Količina ULAZ B | F46: Količina ULAZ C | G46: Količina ULAZ D | H46: Jedinična cijena (€) | I46: Ukupno (€)
A48: 1. | B48: GEODETSKI RADOVI
B50: Geodetski radovi podrazumijevaju iskolčenje širokog iskopa, iskolčenje građevine te kontrolu osnovnih mjera tokom izvođenja, a sve u skladu s geodetskom situacijom.
A52: 1.1 | B52: ISKOLČENJE ŠIROKOG ISKOPA
B53: Široki iskop iskolčiti uzevši u obzir prostor potreban za rad pri betoniranju obodnih zidova temelja i zidova. Pri određivanju granice iskopa u obzir uzeti nagib pokosa koji će onemogućiti odronjavanje zemlje na ivicama građevinske jame.
B54: Iskolčenje širokog iskopa | C54: sat | D54: 15 | E54: 15 | F54: 15 | G54: 15 | I54: =(D54+E54+F54+G54)*H54 -> 0
A56: 1.2 | B56: KONTROLA OSNOVNIH GABARITA
B57: Pri gradnji geodetskim instrumentima pravovremeno kontrolirati vertikalnost elemenata i osnovne pravce na fasadi objekta. Na visinu etaže dozvoljeno je odstupanje od 1 cm, a za horizontalne pravce 1cm na 10m. Geodetskim instrumentom pravovremeno kontrolirati gornju površinu AB ploča, te horizontalne ivice na fasadi. Dozvoljeno odstupanje 1cm na 10m dužine. Pod pravovremenom kontrolom podrazumijeva se kontrola vertikalnosti i horizontalnosti u fazi izrade oplate za beton.
B58: Konstrola osnovnih gabarita | C58: sat | D58: 50 | E58: 50 | F58: 50 | G58: 50 | I58: =(D58+E58+F58+G58)*H58 -> 0
A60: 1. | B60: GEODETSKI RADOVI UKUPNO | I60: =SUM(I50:I58) -> 0

Sheet 2-ZIDARSKI
A1: r.br. | B1: OPIS | C1: jed. mj. | D1: Količina ULAZ A | E1: Količina ULAZ B | F1: Količina ULAZ C | G1: Količina ULAZ D | H1: Jedinična cijena (€) | I1: Ukupno (€)
A3: 2. | B3: ZIDARSKI RADOVI
B5: Izvođenje radova zidanja, žbukanja, izradu cementnih glazura i namaza, AB estriha, te zidarske pripomoći pri izvođenju ostalih radova.
B6: Radove izvoditi prema: Tehničkim propisima za građevinske konstrukcije (NN 17/17, NN 75/20) Tehničkom propisu o građevnim proizvodima (NN 35/18, 104/19) - te normama koji primjenjeni propisi propisuju za materijale koji se ugrađuju ili njima jednakovrijednim _____________________________). Materijali sukladno: • Voda i pijesak HRN EN 1008:2002 (ili jednakovrijedno: ___________________________) HRN EN 13139:2013 (ili jednakovrijedno: ___________________________) • Cement - HRN EN 197-1:2012 (ili jednakovrijedno:___________________________) • Vapno - HRN EN 459-1:2010 (ili jednakovrijedno: __________________________)
B8: ZIDANJE
B9: Zidanja moraju biti izvedena stručno, po općim pravilima za zidanja i uz poštovanje posebnih pravila i proizvođačkih naputaka za pojedine materijale. Striktno se moraju poštovati dimenzije iz projekta.
B10: Zidanje se mora izvoditi sa pravilnim zidarskim vezovima, a preklop mora iznositi najmanje jednu četvrtinu dužine zidnog elementa, debljina ležajnica iznosi maksimalno 15 mm, a širina sudarnica od 10 mm do 15 mm. Ukoliko se zida za vrijeme zime, zidove treba zaštiti od niskih temperatura ( i mraza), a zidovi čije izvođenje nije završeno prije nastupanja nepovoljnih uvjeta (mraz) moraju se zaštititi na odgovarajući način.
B11: Svako naknadno bušenje ili izrada užljebina u zidovima zgrade koje nije bilo predviđeno projektom, može se izvoditi samo ako je prethodnim statičkim proračunom utvrđeno da nosivost zida poslije tog nije manja od propisane nosivosti.
B12: Poprečni i uzdužni zidovi moraju na spoju biti međusobno povezani zidarskim vezom, tj. za pregradne zidove treba ispustiti zupce u masivnom zidu na svaki drugi red za ½ opeke. Zidove uz vertikalni serklaž također zupčasto izvesti.
B13: Pregradne zidove ankerima / sidrima povezati za nosivu konstrukciju. Ankere postavljati u minimalno svako treći red, te po minimalno 1 na svaki m1 spoja sa stropnom pločom. Vanjske fuge ostaviti prazne od 1,5 cm do 2 cm za vezu žbuke prigodom žbukanja zidova. Za vrijeme zidanja opeku kvasiti vodom, a pri zidanju cementnim mortom opeka mora ležati u vodi neposredno prije zidanja. Reške dimnjaka i ventilacionih kanala zagladiti.
B15: MORT
B16: Mort za zidanje i žbukanje mora biti klase predviđene stavkom troškovnika. Mort se može pripremati na mjestu ugradnje od tvornički predgotovljenih smjes, ili se iste mogu mješati na gradilištu. Ukoliko se mort i žbuka koriste od predgotovljene smjese, strogo poštivati upute proizvođača.
B17: Za pripremu mortova (ako to propisom nije precizirano) može se upotrijebiti prirodni pijesak bez organskih primjesa ili umjetno proizveden, drobljeni pijesak. Morski pijesak treba se prije upotrebe isprati. Isprati i druge prirodne pijeske (riječni i kopani) ako imaju primjesu gline veću od 1,5% težine pijeska. Granulacijska krivulja pijeska mora biti u skladu s propisima, a zrna ne smiju biti veća od 4mm, ni više od 10% zrna promjera manjeg od 1mm. Kao vezivo, ako opisom nije drugačije predviđeno, upotrebljava se hidratizirano vapno ili portland cement, što ovisi o vrsti morta. Mort se u načelu priprema strojno, a izuzetno za manje količine, ručno.
B18: Pregradni zidani zidovi se ne smiju izvoditi prije izvedbe stropne konstrukcije. Kod zidanja montažnih dimnjaka i ventilacija postupati po uputama proizvođača (mort, izolacija, preklopi, unutrašnje i vanjske cijevi itd.). Posebno se ne naplaćuje ni zatvaranje (žbukanje šliceva, žljebova i sl.) iza položene instalacije. Zazidavanje (zatvaranje) žljebova u zidovima ostavljenih za instalacije kanalizacije i grijanja nakon izvođenja tih instalacija, opekom, rabicom ili na drugi način, ne plaća se posebno, ukoliko troškovnikom nije posebno propisano.
... B29: Jedinična cijena uključuje: • tehnološku razradu svih detalja • sav rad, uključivo i pomoćni rad te prijenos, alat i strojevi • mort za zidanje u svemu prema opisu stavke sa potrebnim dodacima (produžni / cementni, marke prema stavkama) • svi potrebni ankeri / sidra kojima se povezuju pregradni zidovi i nosiva konstrukcija (zidovi, stupovi i stropne ploče) • montažni nadvoji dimenzija prema stavkama, komplet sa svim radovima • svu potrebnu radnu skelu, bez obzira na visinu • transportne troškove materijala • zaštitu zidova od utjecaja vrućine, hladnoće, atmosferskih nepogoda • čišćenje prostorija i zidnih površina tokom rada • odvoz i zbrinjavanje smeća i viškova materijala • završno čišćenje prije primopredaje radova • nadoknadu eventualne štete nastale iz nepažnje na svojim ili tuđim radovima • usklađenje organizacije rada s operativnim planom
A30: 2.1 | B30: PLIVAJUĆI POD
B31: Plivajući podovi sastoje se od - zvučno - toplinske izolacije - razdjelnog sloja PE folije - cementne glazure - estriha
A33: 1) | B33: ZVUČNO - TOPLINSKE IZOLACIJE
B34: Materijal mora biti izrađen sukladno normi HR EN 13163 (ili jednakovrijedno ______________________ ).
B35: Prvo se postavlja traka ekspandiranog polistirena debljine 0,6 -1,5 cm, visine do gornje kote finalnog sloja poda, vertikalno oko svih zidova, stupova, dovratnika i ostalih vertikalnih elemenata konstrukcije, te oko elemenata instalacija koji prodiru kroz pod - uračunato u jediničnoj cijeni. Izolacija se izvodi s više slojeva traka koje se polažu u međusobno okomitim smjerovima. Toplinsko - zvučna izolacija mora biti uredno postavljena, bez međurazmaka i krpanja površina otpacima materijala. d = 30mm
A37: 2) | B37: PE FOLIJA
B38: Parna brana izvodi se na očišćenoj podlozi. Izvodi se od PE folije debljine 0,20mm (0,15mm). Polaže se s preklopima od 10cm, a potrebno ju je uz okolne zidove podignuti do razine 2cm iznad estriha (uz trake toplinske izolacije). Preklopi se lijepe samoljepivom trakom širine 5cm. Na krovove se folija učvršćuje sredstvima za učvršćenje, koja ovise o vrsti podloge na koju se folija učvršćuje.
A40: 3) | B40: AB ESTRIH
B41: Tvornički pripremljen suhi materijal za izvedbu cementnih glazura, ručno i strojno obradiv. Može se primjeniti kao plivajući, klizni ili vezani estrih. Cementna glazura je zaglađena i armirana, a izvodi se od sitnofrakcijskog agregata, odnosno pijeska i običnog cementa ili brzoveznog / brzosušećeg cementa.
B42: Prije početka radova potrebno je podlogu ispitati na čvrstoću, ravnost i sadržaj vlage. Podloga treba biti čista, bez cementne košuljice, bez ostatka ulja za odvajanje oplata, bez iscvjetavanja i ne smije biti pjeskovita.
B43: Estrih se može zamiješati ručno u miješalici sa slobodnim padom ili u tlačnoj miješalici, ili automatski u protočnoj miješalici odnosno u postrojenju za estrihe gdje se dozira direktno iz silosa. Kod materijala isporučenog u vrećama potrebno je cca 5l vode po vreći, a kod materijala isporučenog u silosu cca 180-200l vode po m3 (90-100l/t). Smije se primjeniti samo pitka voda.
B45: Estrih se armira: a) pocinčanom mrežom za cem. estrih Ø5mm, okna 50-70mm b) polipropilenskim vlaknima u količini prema recepturi za traženu marku
B46: Armatura (sadržana u cijeni): visoko kvalitetna vlakna (materijal: poliolefin, mrežasta strukturna vlakna, vlak - / čvrstoča na pucanje 400 N/mm2 (+/- 10%), hrapava površina vlakana) Doziranje: 1 kg/m³ Klasa betona: C25/30 CE - certificirana prema EN 14889-2 (ili jednakovrijedno __________________________ ). Završna obrada sukladno: HR EN 13813 (ili jednakovrijedno __________________________ ).
B48: Kod izvedbe estriha za polaganje parketa osigurati potrebno vrijeme sušenja ili koristiti specijalni brzosušeći cement. Zaglađivanje estriha mora biti kvalitetno izvedeno i u skladu sa završnom oblogom (strojnim zaglađivačima ili ručno). Debljinu i nagibe u sanitarijama izvesti prema projektu.
B50: Temperatura zraka, materijala i podloge za vrijeme obrade i vezanja treba biti preko +5°C. Propuh ili direktno sunčevo zračenje kao i prebrzo isušivanje treba izbjegavati. Maksimalno mjestimično odstupanje od zadane ravnine je +(-) 3mm. Gornja površina se strojno zaglađuje.
B51: Površina estriha se dijeli u polja površine a x b = <25m2. Odnos stranica a:b mora biti manji ili jednak odnosu 1:2,5 , a dužina veće stranice ne smije biti veća od 6m.
B52: Estrih se u normalnim uvjetima suši 3-4 tjedna, dok mu vlažnost ne padne ispod 3% . Potom se mogu izvoditi daljnji radovi.
B53: U prostorijama u kojima su predviđeni slivnici i rigalice gornja površina estriha treba biti izvedena u padu. Padove estriha treba precizno izvesti prema podnim slivnicima i rigalicama.
B54: Ukupna debljina, odn. gornja kota estriha pri izvedbi treba biti precizno prilagođena završnim slojevima poda (pri izvedbi estriha obavezno je sagledavanje potrebne debljine završnih slojeva poda).
B55: Estrih se u pravilu zaglađuje strojno.
B57: POD NA TLU
B59: ANT 1 AB ESTRIH ( d = 10cm) | C59: m² | D59: 363.6 | E59: 363.5 | F59: 484.4 | G59: 771.6 | I59: =(D59+E59+F59+G59)*H59 -> 0
B60: AB ESATIH ( d = 10cm) - RAMPA, KANELIRANI ESTRIH | F60: 245 | I60: =(D60+E60+F60+G60)*H60 -> 0
B61: ANT 2 AB ESTRIH U PADU (d = 8cm - 25cm) | C61: m² | F61: 851 | G61: 421 | I61: =(D61+E61+F61+G61)*H61 -> 0
B63: MEĐUKATNA KONSTRUKCIJA
...

Sheet 3-GIPS RADOVI
A1: r.br. | B1: OPIS | C1: jed. mj. | D1: Količina ULAZ A | E1: Količina ULAZ B | F1: Količina ULAZ C | G1: Količina ULAZ D | H1: Jedinična cijena (€) | I1: Ukupno (€)
A3: 3. | B3: GIPSARSKI RADOVI
B5: Ovim radovima obuhvaćeni su svi radovi sa gips kartonskim pločama kao izrada pregradnih zidova uključivši ugradnju dovratnika gdje je to potrebno i podkonstrukcije za ugradnju instalacija vodovoda, kanalizacije i sl. te izrada obloge zidova i izrada spuštenih stropova uključivši izradu otvora za ugradnju instalacijskih elemenata, rasvjetnih tijela, utičnice, ventilacijskih elemenata i sl.
B6: Potrebno je pripraviti HRN ili jednakovrijedne ateste za ponuđeni i ugrađeni materijal, a prema Zakonu o gradnji NN (153/13, 20/17, 39/19, 125/19) i uzancama za ovu vrstu poslova. Gipsane ploče, sukladno: HRN EN 520:2010 (ili jednakovrijedan ____________________________) Materijal za obradbu i zaglađivanje spojeva gipsanih ploča, sukladno: HRN EN 13963:2014 (ili jednakovrijedan ___________________________) Ovješeni stropovi, sukladno: HRN EN 13964:2014 (ili jednakovrijedan ___________________________) Metalni profili podkonstrukcija za sustave s gipsanim pločama: HRN EN 14195:2015:2014 (ili jednakovrijedan ___________________________) Gips elementi za spuštene stropove, sukladno: HRN EN 14246:2006/Ispr.:2008 (ili jednakovrijedan ___________________________)
B8: PRIPREMA PODLOGE
B9: U području spojeva pregradnih zidova s bočnim građevnim elementima na profile je potrebno nanijeti brtveni kit ili PE brtvenu traku. Kod očekivanih progiba međukatnih konstrukcija od > 10mm, potrebno je izvesti klizne spojeve. Ojačanja su uračunata u cijenu.
B11: POTKONSTRUKCIJA
B12: Pri izradi pregradnih zidova, pri oblaganju zidova i stropova, i pri izradi spuštenih stropova, za podkonstrukciju koristiti originalne profile od čeličnog pocinčanog lima proizvođača gips-kartonskih ploča s pripadajućim priborom za međusobnu vezu profila i za učvršćenje profila na osnovnu konstrukciju. Rubni profili potkonstrukcije pričvršćuju se na pod i strop, a okomiti za bočne zidove. Obavezno je držati se sistema jednog proizvođača.
B13: Kod otvora (vrata, prozori), obavezna ugradnja ojačanih metalnih profila, prema uputama proizvođača. Učvršćenje ploča na potkonstrukciju izvoditi originalnim pripadajućim vijcima za brzu montažu i odgovarajuću vrstu ploče uz obvezno upuštanje glave vijka za 2 mm (+/-2%) u odnosu na ravninu vidljive plohe obloge zida ili stropa.
B14: Učvrsna sredstva za bočne masivne građevne elemente su tipli s vijcima. Za građevne elemente koji nisu masivni učvrsna sredstva se određuju prema vrsti podloge.
B16: TERMOIZOLACIJA
B17: Prostor između profila ispunjava se termoizolacijom. Za izradu termoizolacije upotrijebit će se ploče od kamene vune u pločama, proizvedene na bazi dijabaza. Vlakna kamene vune impregnirana su i vezana fenolnom smolom.
B18: Koeficijent toplinske provodljivosti: max 0,041 W/mK, sukladno: HRN EN 13162 (ili jednakovrijedno ____________________________). Razred reakcije na požar: A1 sukladno: HRN EN 13501-1 (ili jednakovrijedno ____________________________).
B20: GIPS - KARTONSKE PLOČE
... B47: Obračun po m² (otvori do 3,00 m² se ne odbijaju).
A50: 3.1 | B50: OBLAGANJE ZIDOVA GIPS-KARTONSKIM PLOČAMA Zidna obloga sa metalnom potkonstrukcijom, jednostrano dvoslojno obložena, direktno pričvršćena Oznaka u nacrtu: ZGG2, ZGN 1
B52: Potkonstrukcija
B53: Profili od čeličnog pocinčanog lima (min debljine 0,60mm) na razmaku od maksimalno 62,50 cm. Podkonstrukcija je širine 5,0/7.50cm.
B55: Termoizolacija + PE folija
B56: Zapreminska težina ploče cca 40 kg/m3. dim. 1000 x 625 x 50 mm / 75mm (+/- 5%) Prije termoizolacije se postavlje PE folija debljine 0,2mm kao parna brana.
B58: Gips-kartonske ploče
B59: Gips-kartonske ploče tipa A / H2 (mokri čvorovi) x2 dim. 2000 x 1250 x 12,5 mm (+/- 5%)
B61: d = 10cm (1,25cm x2 + 7,50cm) h= 268cm
A63: 1) | B63: ZGG 2 (termoizolacija d=5cm) | C63: m² | D63: 342 | E63: 471.6 | F63: 838.8 | G63: 692.4 | I63: =(D63+E63+F63+G63)*H63 -> 0
B64: d = 7,5cm (1,25cm x2 + 5,00cm) h= 268cm
A65: 2) | B65: ZGN 1 (termoizolacija d=7,5cm) | C65: m² | D65: 651.6 | E65: 836.4 | F65: 1206 | G65: 1025 | I65: =(D65+E65+F65+G65)*H65 -> 0
B66: d = 10cm (1,25cm x2 + 7,50cm) h= 268cm
A68: 3.2 | B68: UNUTARNJI ZIDOVI Nenosiv pregradni zid s jednostrukom metalnom potkonstrukcijom, obostrano dvoslojno polaganje Oznaka u nacrtu: ZGG5
B70: Potkonstrukcija
B71: Profili od čeličnog pocinčanog lima (min debljine 0,60mm) na razmaku od maksimalno 62,50 cm. Podkonstrukcija je širine 5cm / 10 cm.
B73: Termoizolacija + PE folija
B74: Zapreminska težina ploče cca 40 kg/m3. dim. 100 x 625 x 50 mm / 100mm (+/- 5%) Prije termoizolacije se postavlje PE folija debljine 0,2mm kao parna brana.
B76: Gips-kartonske ploče
B77: Gips-kartonske ploče tipa A / H2 (mokri čvorovi) x2 dim. 2000 x 1250 x 12,5 mm (+/- 5%)
B79: d=10cm/15cm (2,5+5/10+2,5cm) h= 268cm
A81: 1) | B81: ZGG 5 | C81: m² | D81: 1581.2 | E81: 1810.9 | F81: 2173.75 | G81: 2212.9 | I81: =(D81+E81+F81+G81)*H81 -> 0
A83: 3.3 | B83: UNUTARNJI ZIDOVI INSTALACIJSKIH ŠAHTI Nenosiv pregradni zid s jednostrukom metalnom potkonstrukcijom, jednostrano dvoslojno polaganje Oznaka u nacrtu: ZGG3
B84: * Napomena: kod protupožarnih sklopki na prijelazu između podruma i prizemlja - prijelaza iz jednog u drugi požarni sektor, zaštiti šahtu betonom
B86: Potkonstrukcija
B87: Profili od čeličnog pocinčanog lima (min debljine 0,60mm) na razmaku od maksimalno 62,50 cm. Podkonstrukcija je širine 5 cm.
...

Sheet 4-IZOLATERSKI
A1: r.br. | B1: OPIS | C1: jed. mj. | D1: Količina ULAZ A | E1: Količina ULAZ B | F1: Količina ULAZ C | G1: Količina ULAZ D | H1: Jedinična cijena (€) | I1: Ukupno (€)
A3: 4. | B3: IZOLATERSKI RADOVI
B5: Izrada hidroizolacija, parnih brana, termoizolacija podova i vanjskih zidova i unutarnjih zidova, zvučnih izolacija i postavu raznih folija.
B7: HIDROIZOLACIJE
B8: - HRN U.F2.024/80 (ili jednakovrijedno ____________________________) - Završni radovi u građevinarstvu. Tehnički uvjeti izvođenja izolacijskih radova na ravnim krovovima. - HRN EN 13859-2:2014 (ili jednakovrijedno ____________________________) - Savitljive hidroizolacijske trake - Definicije i značajke podložnih traka - EN 13859-2:2004+A1:2008 (ili jednakovrijedno ____________________________). - HRN EN 13967:2017 (ili jednakovrijedno ____________________________) - Savitljive hidroizolacijske trake - plastične i elastomerne trake za zaštitu od vlage i vode iz tla - HRN EN 13970:2005/A1:2008 (ili jednakovrijedno ____________________________) - Savitljive hidroizolacijske trake - Bitumenske paronepropusne trake - EN 13970:2004/A1:2006 (ili jednakovrijedno ____________________________) - HRN EN 13984:2013 (ili jednakovrijedno ____________________________)
B9: - Savitljive hidroizolacijske trake - Plastične i elastomerne; paronepropusne trake - HRN EN 13859-1:2014 (ili jednakovrijedno ____________________________) - Savitljive hidroizolacijske trake - Definicije i značajke podložnih traka - HRN EN 13956:2012 (ili jednakovrijedno __________________________) - Savitljive hidroizolacijske trake - Plastične i elastomerne hidroizolacijske trake za krovove - EN 13956:2005 (ili jednakovrijedno ______________________________)
B11: TOPLINSKE IZOLACIJE
B12: - mineralna vuna (MW) - HRN EN 14303:2016 (ili jednakovrijedno ___________________________) - ekspandirani polistiren (EPS) - HRN EN 14309:2016 (ili jednakovrijedno ___________________________) - ekstrudirani polistiren (XPS) - HRN EN 14307:2016 (ili jednakovrijedno ___________________________) - tvrda poliuretanska pjena (PUR) - HRN EN 14308:2016 (ili jednakovrijedno ___________________________) - polietilenska pjena (PEF) - HRN EN 14313:2016 (ili jednakovrijedno ___________________________) '- proizvodi od pjenastog stakla (CG) HRN EN 14305:2016 (ili jednakovrijedno __________________________)
B13: - proizvodi od kalcijevog silikata (CS) HRN EN 14306:2016 (ili jednakovrijedno __________________________) - proizvodi od savitljive elastomerne pjene (FEF) HRN EN 14304:2016 (ili jednakovrijedno __________________________)
B15: PRIPREMA PODLOGE
B16: Površine na koje se polaže izolacija, trebaju biti posve ravne, suhe, očišćene od prašine i nečistoće i dovoljno glatke, da izolacija dobro prijanja, te maksimalne vlage koju propisuje proizvođač. Izolacija treba prilegnuti na površinu ravno, bez nabora i mjehura.
B18: Hidroizolacije na bazi bitumena Izvode se kao premazi i kao premazi s izolacionim trakama (ljepenkama) koje mogu biti s: · uloškom od aluminijske ili bakrene folije · uloškom od staklenog voala ili staklene tkanine Izolacionu ljepenku i ostale vrste izolacionih traka i ploča treba rezati ravno i pravokutno. Zaderani i krpani komadi se ne ugrađuju. Svi preklopi moraju biti najmanje 10 cm široki i lijepljeni bitumenom – hladnom bitumenskom masom ili vrućom bitumenskom izolacionom masom. Kod polaganja dvaju ili više slojeva izolacionih traka ili ploča preklopi ne smiju ležati jedan na drugom, već moraju biti pomaknuti.
B20: Kod hidroizolacije zidova ljepenka treba na svaku stranu zida imati prehvat širine od 10 cm, koji treba spojiti s horizontalnom izolacijom podova. Posebnu pažnju obratiti na zaštitu od požara kod rada s vrućim bitumenskim premazima i varenim ljepenkama zbog velike zapaljivosti bitumena. U slučaju požara gasiti pijeskom ili pjenom (gašenje vodom je opasno).
B22: PREMAZI - BITUMENSKE EMULZIJE
... B75: IZOLACIJA KONSTRUKCIJA U TLU
A77: 4.1 | B77: BITUMENSKA HIDROIZOLACIJA TEMELJA I UKOPANIH ZIDOVA - V-4 x2
B79: Oznaka u nacrtu: AOT 1, ANT 1, ANT 2, ZNT 1
B80: Izolacija podruma jednokomponentnim, polimerima modificiranim i vlaknima ojačanim bitumenom. Trajno štiti podzemne građevine od vlage iz tla.
B82: Priprema površine na način da se odštemaju svi labavi djelovi do zdravog sloja i istaknute neravnine uklone
B83: Izrada holkera (gušice) na spojevima reprofilirane AB ploče sa zidovima od reparaturnog morta.
B84: Izvedba hidroizolacije AB ploče: Izvedba temeljnog premaza i dva sloja APP plastomerne bitumenske membrane ojačane poliesterskim platnom. Na očišćenu površinu AB ploče izvodi se hladni bitumenski premaz. Na izvedeni prednamaz ugrađuju se dva sloja punoplošno zavarene polimerbitumenske hidroizolacije. Uz zidove hidroizolacija se uzdiže 10 cm. Karakteristike proizvoda: Tip ojačanja: Poliestersko platno Maksimalna vlačna čvrstoća:prema EN 12311-1 ili jednakovrijedno - uzdužno:500 N/50 mm (- 20%) - poprečno:400 N/50 mm (- 20%) Posmična čvrstoća spojeva: prema EN 12317-1 ili jednakovrijedno - uzdužno:300 N/50 mm (- 20%) - poprečno:400 N/50 mm (- 20%) Izduženje pri slomu: prema EN 12311-1 ili jednakovrijedno - uzdužno: 35% - poprečno:35% Otpornost na udarce: 900 mm, prema EN 12691 ili jednakovrijedno
B86: Obračun po m² kompletno izolirane površine.
B87: AOT 1 | C87: m² | F87: 829.1 | G87: 600 | I87: =(D87+E87+F87+G87)*H87 -> 0
B88: ANT 1 (donja ploha temelja) | C88: m² | D88: 502.6 | E88: 503.1 | F88: 454.7 | G88: 462.6 | I88: =(D88+E88+F88+G88)*H88 -> 0
B89: ANT 1 (gornja ploha temelja) | C89: m² | D89: 43 | E89: 43 | F89: 64.2 | G89: 65.3 | I89: =(D89+E89+F89+G89)*H89 -> 0
B90: ANT 2 (donja ploha temelja) | C90: m² | F90: 1197 | G90: 932.9 | I90: =(D90+E90+F90+G90)*H90 -> 0
B91: ANT 2 (gornja ploha temelja) | C91: m² | F91: 150 | G91: 65.8 | I91: =(D91+E91+F91+G91)*H91 -> 0
B92: ZNT 1 | C92: m² | D92: 162.2 | E92: 161.8 | F92: 407.4 | G92: 265.4 | I92: =(D92+E92+F92+G92)*H92 -> 0
A94: =+MAX($A$1:A93)+0.1 -> 4.2 | B94: VERTIKALNA TERMOIZOLACIJA UKOPANIH ZIDOVA - XPS
B96: Oznaka u arhitektonskom projektu: ZNT 1
B97: Ploče od ekstrudiranog polistirena, XPS. Vanjska toplinska izolacija zidova podzemnih građevinskih površina smještena na vanjskoj strani hidroizolacije jednoslojno postavljena.
B98: Ploče su gustoće >30kg/m3. Ploče se postavljaju nakon postave hidroizolacije vanjskih zidova. Koristiti ploče s preklopom.
B99: Ploče od ekstrudiranog polistirena potrebno je na području podnožja zgrade (cokla) i iznad zemljane površine zaštititi od mehaničkih oštećenja i UV-zračenja. Odgovarajućim mjerama potrebno je osigurati da iza sloja toplinske izolacije ne prodre voda (npr. voda koja teče po površini zemlje ili oborinske vode koje se skupljaju na fasadi). Na podnožju zgrade potrebno je pravilno izvesti spojeve s hidro-izolacijom. Spoj izolacije konstrukcije u zemlji i na zidu iznad zemljane površine potrebno je izvesti tako da ne dođe do pojava neželjenih toplinskih mostova.
B100: d= 5 cm
B101: Obračun po m² kompletno izolirane površine.
B102: ZNT 1 | C102: m² | D102: 162.2 | E102: 161.8 | F102: 407.4 | G102: 265.4 | I102: =(D102+E102+F102+G102)*H102 -> 0
A104: =+MAX($A$1:A103)+0.1 -> 4.3 | B104: ZAŠTITA IZOLACIJE - ČEPASTA FOLIJA
B106: Oznaka u arhitektonskom projektu: ZNT 1
B107: Čepasta drenažna folija na vertikalnoj površini kao zaštita izolacije na bazi polietilena velike gustoće (HDPE) - debljina: 7.5 mm - tlačna čvrstoća: min. 200 kN/m2 Sukladno: ISO 826 (ili jednakovrijedno __________________________) - vlačna čvrstoća, uzdužno/poprečno: min. 250/250 N/5cm - izduženje pri slomu, uzdužno/poprečno: min 20/25% Sukladno: ISO 10319 (ili jednakovrijedno __________________________) Folija se pričvršćuje bez bušenja hidroizolacijske membrane
B108: Obračun po m² postavljene zaštite.
...

Sheet 5-FASADERSKI
A1: r.br. | B1: OPIS | C1: jed. mj. | D1: Količina ULAZ A | E1: Količina ULAZ B | F1: Količina ULAZ C | G1: Količina ULAZ D | H1: Jedinična cijena (€) | I1: Ukupno (€)
A3: 5. | B3: FASADERSKI RADOVI
B5: Fasaderski radovi podrazumijevaju izradu plemenitih žbuka, plastičnih žbuka i radove sa specijalnim tvornički pripremljenim mortovima za žbukanje fasada. Radovi sukladno: HRN U.F2.010 (ili jednakovrijedan ____________________________). Pri upotrebi tvornički pripremljenih mortova pri radu se mora poštovati naputak proizvođača.
B6: Kontaktni sustav fasade uključuje fasadne ploče od kamene vune izabrane debljine, ljepilo, mrežicu, završno dekorativni sloj uz pripadajući predpremaz, granulacije 1,5; 2 ili 3mm, te sav potreban pribor: letvica za podnožje u debljini ploče, zaštitni kutnici za uglove i prozore. U stručnu organizaciju gradilišta ubraja se i propisno skladištenje svih komponenti koji čine sustav za toplinsku izolaciju. Niti u ljepilo, niti u završne slojeve nije dozvoljeno primješavanje bilo kakvih dodataka (npr. sredstvo protiv smrzavanja).
B7: Odvođenje oborinske vode mora biti izvedeno postavljenim strehama, okapnicama itd. Svi unutarnji radovi žbukanja, postavljanje cementne glazure itd. moraju biti izvedeni, a ugrađeni materijali osušeni prema naputku proizvođača. Sva stolarija mora biti ugrađena. Prozorske klupčice moraju biti postavljene tako da budu najmanje 3 cm udaljene od novopostavljene fasade. Sve vanjske instalacije moraju biti postavljene.
B9: Hidroizolacija sokla zidova treba biti izvedena prije termoizolacije.
B10: Temperatura zraka, podloge i materijala ne smije biti ispod +5°C, a kod rada sa silikatnim žbukama ispod + 8°C. Ova temperatura vrijedi kako za radove ugradnje, tako i za vrijeme protvrdnjavanja materijala. Radovi se ne smiju izvoditi pod direktnim sunčevim zračenjem, vjetrom ili oborinama. Pri izvedbi sustava na pročelje treba postaviti odgovarajuću zaštitu: jutu i sl.
B11: Procjena podloge je odgovornost izvođača radova.
B12: Provjeriti valjanost podloge: mora biti čvrsta (nosiva), čista i suha. Podloga mora biti ravna, okomito i vodoravno, provjeriti libelom (neravnine do 1 cm mogu se izravnati ljepilom, a veće od toga podložnom žbukom). Spojnice moraju biti zapunjene. Sa betonskih površina mora biti uklonjeno sredstvo za odvajanje oplata, te sve masnoće.
B14: IZVEDBA SOKLA UZ TEREN
B15: Sokl pročelja uz teren se izvodi od ploča XPS-a. Visina sokla: min.10cm ispod razine terena, 113cm iznad razine terena
B16: Debljina: ista kao i ostatak pročelja Završna obrada: opisano u stavci
B17: Na visini min 25cm iznad razine zemlje XPS se pričvršćuje na zid sa pričvrsnicama sa plastičnim ili čeličnim klinom ovisno o završnom sloju. Sokl se nastavlja min.10cm ispod razine terena, do razine rubnog osnovnog profila (izrađen od perforiranog nekorodirajućeg Al lima, debljine 1mm, dužine 2m). Na XPS se nanosi građevinsko ljepilo u dva sloja s alkalno postojanom staklenom mrežicom ili žičanom mrežicom veličine očica 5x5mm koja treba biti izvedena u dva sloja.
B18: Ispod razine sokla u terenu, nastavlja se XPS termoizolacija ukopanog zida (zasebna stavka).
... B26: Napomena: potrebno je koristiti proizvode iz istog "sustava" proizvođača, u svemu izvoditi prema uputama proizvođača.
A28: 5.1 | B28: ETICS SA PLOČAMA OD KAMENE VUNE
B30: Stavka može obuhvatiti slijedeće radove:
B31: Izvedba kontaktnog fasadnog sustava sa pločama od kamene vune (MW), dimenzije ploča odnosno lamela prema dostupnim dimenzijama na tržištu, debljine određene proračunom građevinske fizike.
B33: PRIPREMA PODLOGE
B34: Otprašivanje i odstranjivanje oštećenih i slabo sraslih dijelova. Impregnacija dubinski predpremazom.
B36: RUBNI PROFILI, DILATACIJE I SL.
B37: Zaštitni kutni profili postavljaju se na sve uglove objekta u prethodno naneseni sloj ljepila. Koristiti profil sa ugrađenom tekstilno staklenom mrežicom. Na nadvojima otvora i strehama koristiti profil s okapom. Pričvršćivanje izvesti nehrđajućim vijcima na razmaku svakih 40 do 60 cm.
B38: Pored ovih profila potrebno je koristiti profile za različite namjene: za izvedbu dilatacija na ravnim površinama ili u uglovima, završni profili za prozore itd. koji se koriste za kvalitetnije i urednije fasaderske radove. Vrsta profila prema preporuci proizvođača.
B40: TERMOIZOLACIJA
B41: kamena vuna predviđena za izolacije vanjskih zidova - kontaktne fasade
B42: Tvrde ploče od kamene vune. Proizvod se odlikuje visokom paropropusnošću, potpuno je negoriv, postojan je na vrlo visoke temperature, vodoodbojan, pravilno ugrađen otporan na starenje te je kemijski neutralan.
B43: razred reakcije na požar A1 - potpuno negoriv
B44: koeficijent toplinske provodljivosti λ = min. 0,035 W/mK
... B53: Napomena: Sve što nije obuhvaćeno ovim opisom, izvesti prema uputama proizvođača komponenti certificiranog sustava, sukladno nacionalnim normama, te smjernicama za izradu ETICS sustava HUPFAS-a (ili jednakovrijedno __________________).
A55: 1) | B55: VANJSKI ZID - ŽBUKA
B56: Završna obloga: ZAVRŠNA SILIKONSKA ŽBUKA Nakon sušenja (od 10 – 14 dana, ovisno o vremenskim uvjetima), suha i čista podloga premazuje se ravnomjerno i temeljito nerazrijeđenim dubinski predpremazom, te se nakon min. 24 sata, nanosi silikonska završna dekorativna žbuka u granulaciji 1,5mm. Obračun po m².
B57: ZOG 1 - RAL 9003 - d termoizolacije = 15cm | C57: m² | D57: 860 | E57: 870 | F57: 1190 | G57: 1200 | I57: =(D57+E57+F57+G57)*H57 -> 0
B58: ZOG 1a - RAL 7016 - d termoizolacije = 10cm | C58: m² | D58: 30 | E58: 15 | F58: 15 | G58: 25 | I58: =(D58+E58+F58+G58)*H58 -> 0
B59: ZOG 1b - RAL 3003 - d termoizolacije = 15cm | C59: m² | D59: 260 | E59: 300 | F59: 450 | G59: 340 | I59: =(D59+E59+F59+G59)*H59 -> 0
B60: ULAZNI PROSTOR (zidovi natkrivenog dijela i strop) ulaz A - RAL 3003 ulaz B - RAL 6017 ulaz C - RAL 1003 ulaz D - RAL 5024 | C60: m² | D60: 36 | E60: 36 | F60: 36 | G60: 36 | I60: =(D60+E60+F60+G60)*H60 -> 0
B61: Zid rezervnog izlaza iz skloništa (bez termoizolacije) - RAL 7016 | C61: m² | G61: 35 | I61: =(D61+E61+F61+G61)*H61 -> 0
B62: GRB, crveno-bijele polja dim 40x40cm, 3d | C62: kom | D62: 1 | I62: =(D62+E62+F62+G62)*H62 -> 0
B63: OZNAKA ULAZA
B64: h= 100cm, font: Kirsten ITC. Obračun po oznaci. | C64: kom | D64: 1 | E64: 1 | F64: 1 | G64: 1 | I64: =(D64+E64+F64+G64)*H64 -> 0
A66: 2) | B66: VANJSKI ZID - KERAMIKA
...

Sheet 6-BRAVARSKI i ČELIČNI
A1: r.br. | B1: OPIS | C1: jed. mj. | D1: Količina ULAZ A | E1: Količina ULAZ B | F1: Količina ULAZ C | G1: Količina ULAZ D | H1: Jedinična cijena (€) | I1: Ukupno (€)
A3: 6. | B3: BRAVARSKI RADOVI
B5: Bravarski radovi podrazumijevaju izradu nosivih čeličnih konstrukcija, izradu vrata i prozora, zaštitnih rešetki i žaluzina, izradu ograda i rukohvata, te izradu ostalih bravarskih elemenata. Osnovni materijali za izradu bravarskih radova su čelični limovi, čelične šipke, čelične cijevi bez šava i čelični profili.
B7: Izvoditi prema: Tehničkim propisima za prozore i vrata (NN 69/06) Tehničkom propisu o racionalnoj upotrebi energije i toplinskoj zaštiti u zgradama (NN 128/15, 70/18, 73/18, 86/18, 102/20), i važećim normama (ili jednakovrijedno ____________________________).
B9: Presjeci čeličnih profila i debljine limova moraju odgovarati zadanim opterećenjima i biti u skladu s projektom. Profili i limovi spajaju se u konstruktivne cjeline spojnim sredstvima (zakovice, vijci i varovi) koja moraju odgovarati važećim standardima, moraju biti pravilno dimenzionirana i ugrađena. Vrsta spoja određena je opisom stavke.
B11: Svi dijelovi konstrukcije i elementi pojedinih pozicija moraju biti proračunati i dimenzionirani tako da sigurno prihvaćaju opterećenja posebice vjetra (tlak, usis) i drugih atmosferskih utjecaja i funkcija elemenata. Sile koje se javljaju u elementima i fasadi u cjelini moraju se prenijeti na monolitni dio zgrade, dok se deformacije i opterećenja (sile) sa zgrade ne smiju nikako prenositi na fasadu i/ili njene elemente. Na spoju raznih kvaliteta lima / metala izvesti potrebno galvansko razdvajanje. Izvedba razdvajanja mora biti otporno i postojano na atmosferilije i smrzavanje.
B12: Troškovi ispitivanja bravarije uključeni u cijenu stavke troškovnika. Ukoliko pojedinom stavkom nije drugačije propisano, ugradba će se izvesti upucavanjem na dozvoljenom broju mjesta, te će se smatrati da je sav materijal i rad za ovakav način ugradbe uračunat u jediničnu cijenu. Okov, kvake i brave odobrava projektant.
B14: Obveza izvođača je izrada izvedbenog projekta i radioničkih nacrta, koji moraju biti ovjereni od projektanta konstrukcije, glavnog projektanta i nadzora.
B16: Prilikom izrade projekta montaže Izvođač se treba pridržavati osnovnih načela za montažu čeličnih konstrukcija, te osigurati stabilnost konstrukcije u svakoj fazi montaže pojedinog dijela konstrukcije.
B18: Sva propisana antikorozivna i protupožarna zaštita te završna obrada čelika obuhvaćena je cijenom stavki.
B19: Popis certifikata potrebnih za izvođenje čelične konstrukcije 1. ISO 9001:2008 (ili jednakovrijedno ___________________________) 2. HRN EN 1090-1 (ili jednakovrijedno ___________________________) 3. EN 1090-2 (ili jednakovrijedno ___________________________) 4. EN ISO 3834-2:2007 (ili jednakovrijedno ___________________________)
B21: Popis certifikata potrebnih za zavarivanje: HRN EN 9606-1:2012 (ili jednakovrijedno ____________________________) HRN EN 9606-2:2007 (ili jednakovrijedno ____________________________) HRN EN 14732:2014 (ili jednakovrijedno ____________________________) HRN EN ISO 4063 (ili jednakovrijedno ____________________________)
B23: OPĆENITO
B24: Prije početka radova izvoditelj je dužan dati na uvid nadzornom inženjeru slijedeće: - certifikate materijala od kojih će biti izrađena čelična konstrukcija - certifikate za spojni materijal (vijke, elektrode i sl.) - certifikate zavarivača koji će raditi na izradi čelične konstrukcije - planove slijeda zavarivanja sa točnim odredbama u pogledu rasporeda i redoslijeda svakog pojedinog zavara - plan montaže konstrukcije u kojem će biti detaljno razrađen način i slijed montaže
... B91: U cijenu je potrebno uključiti i sve eventualno skrivene dijelove, nenabrojene elemente koje proizvođač preporuča. kao i sve opšave fazonske komade i sl. U cijenu obračunato sve u kompletu, do pune gotovosti vrata.
A93: 6.01 | B93: UNUTARNJA VATROOTPORNA VRATA
A95: 1) | B95: ULAZNA VRATA STANOVA Shema: BR 1_01
B96: Jednokrilna, zaokretna, protuprovalna, vatrootporna vrata Vatrootpornost: EI₂ 30-C. Koeficijent prolaska topline: 1,80 W/m2K Otpor prolaza zvuka: Rw > 35dB Oprema: - zurilo - kvaka s kompletom rozeta - češljani inox - zaštita za panel (češljani inox, visine 100mm) - oznaka broja stana (češljani inox, visina 90mm, font: Kristen ITC) - oznaka vlasnika stana (10 cm iznad zurila, pločica dim. 5x15x1 cm sukladno shemi, dio s prezimenom izmjenjiv) Dovratnik: sveobuhvatni, bojani RAL 7016 Krilo: puno, zaokretno, čelično sa MDF drvenom oblogom, svijetli hrast
B97: dimenzija stavke: 110 x 220 cm | C97: kom | D97: 27 | E97: 33 | F97: 49 | G97: 43 | I97: =(D97+E97+F97+G97)*H97 -> 0
A99: 2) | B99: VRATA U PODRUMU - HODNIK Shema: BR 2_01
B100: Jednokrilna, zaokretna, protuprovalna, vatrootporna vrata Vatrootpornost: EI 60. Izlaz za nuždu: HRN EN 179 Dovratnik: sveobuhvatni, bojani RAL 9010 Krilo: puno, zaokretno, čelično, bojano RAL 9010
B101: dimenzija stavke: 110 x 220 cm | C101: kom | D101: 4 | E101: 3 | F101: 3 | G101: 2 | I101: =(D101+E101+F101+G101)*H101 -> 0
A103: 3) | B103: VRATA STUBIŠTA PREMA ZAJEDNIČKOM HODNIKU Shema: BR 2_02
B104: Jednokrilna, zaokretna, protuprovalna, vatrootporna vrata Vatrootpornost: EI₂ 30-C-Sm. Izlaz za nuždu: HRN EN 179 Dovratnik: sveobuhvatni, bojani RAL 9010 Krilo: puno, zaokretno, čelično, bojano RAL 9010
B105: dimenzija stavke: 110 x 220 cm | C105: kom | D105: 1 | E105: 1 | F105: 1 | G105: 1 | I105: =(D105+E105+F105+G105)*H105 -> 0
A107: 4) | B107: VRATA STUBIŠTA PREMA ZAPORNICI Shema: BR 2_03
B108: Jednokriln, zaokretna, vatrootporna vrata Vatrootpornost: EI2 60-C. Izlaz za nuždu: HRN EN 1125 Dovratnik: sveobuhvatni, bojani RAL 9010 Krilo: puno, zaokretno, čelično, bojano RAL 9010
B109: dimenzija stavke: 110 x 210 cm | C109: kom | F109: 1 | G109: 1 | I109: =(D109+E109+F109+G109)*H109 -> 0
A111: 5) | B111: VRATA GARAŽE PREMA ZAPORNICI Shema: BR 2_04
B112: Jednokrilna, zaokretna, protuprovalna, vatrootporna vrata Vatrootpornost: E 60-C. Izlaz za nuždu: HRN EN 1125 Dovratnik: sveobuhvatni, bojani RAL 9010 Krilo: puno, zaokretno, čelično, bojano RAL 9010
B113: dim. 110 x 210 | C113: kom | F113: 1 | G113: 1 | I113: =(D113+E113+F113+G113)*H113 -> 0
A115: 6) | B115: VATROOTPORNA VRATA U PRIZEMLJU Shema: BR 2_05
B116: Jednokrilna zaokretna vatrootporna vrata Vatrootpornost: EI 60. Izlaz za nuždu: HRN EN 179 Dovratnik: sveobuhvatni, bojani RAL 9003 Krilo: puno, zaokretno, čelično, bojano RAL 9003
B117: dim. 100 x 220 | C117: kom | D117: 2 | E117: 2 | F117: 2 | G117: 2 | I117: =(D117+E117+F117+G117)*H117 -> 0
A119: =+MAX($A$1:A110)+0.01 -> 6.02 | B119: ČELIČNA OGRADA
B121: Uključivo svi spojni i prelazni detalji, spojevi sa susjednim stavkama, završetci elemenata ograde. Spojevi elemenata uglavnom vareni, svi varovi fino obrušeni. U cijeni komplet funkcionalna, završno ugrađena i obrađena stavka. Visina ograde: 120cm od poda.
A123: 1) | B123: UNUTARNJA ČELIČNA OGRADA STUBIŠTA
B124: Ograda kontinuirano prati krakove stubišta. Sastoji se od okvira i ispune. Okvir ujedno predstavlja i rukohvat. Okvir i ispune izrađuju se od kvadratnih čeličnih cijevi 50x20x3mm međusobno spojenih varenjem. Svjetli ovor < 14cm. Ograda je preko čeličnih "T" profila sidrena bočno na AB krakove stubišta kemijskim inox sidrima M12. Ograda precizno prati nagib AB kraka, dok donji rub ograde prati podgled AB kraka. Rukohvat ograde je inox cijev (Ø40mm, debljine 3mm) postavljen na visini 90cm. Rukohvat kontinuirano prati krakove i podeste (spajanje varenjem na uglovima), pri čemu su vanjski uglovi savijeni. Završna obrada: vruće pocinčavanje, plastificiranje i bojanje - RAL 7016.
B125: Shema BR_6 - 8 krakova stubišta | C125: kpl | D125: 1 | E125: 1 | I125: =(D125+E125+F125+G125)*H125 -> 0
B126: Shema BR_6a - 9 krakova stubišta | C126: kpl | F126: 1 | G126: 1 | I126: =(D126+E126+F126+G126)*H126 -> 0
...

Sheet 7-ALUMINIJSKI
A1: r.br. | B1: OPIS | C1: jed. mj. | D1: Količina ULAZ A | E1: Količina ULAZ B | F1: Količina ULAZ C | G1: Količina ULAZ D | H1: Jedinična cijena (€) | I1: Ukupno (€)
A3: 7. | B3: ALUMINIJSKI RADOVI
B5: Stavke vanjske i unutarnje bravarije u sistemima aluminijskih profila s ili bez prekida toplinskog mosta. Svi primijenjeni sistemi za vanjsku ugradnju sukladno: "Tehnički propis o racionalnoj uporabi energije i toplinskoj zaštiti u zgradama" (NN 128/15, 70/18, 73/18, 86/18 i 102/20).
B7: Kvaliteta aluminijskih profila sukladno: HRN EN 573: EN AW 6060 T66 (ili jednakovrijedno ____________________________). Smjer otvaranja otvarajućih elemenata sukladno: HRN EN 12519 (ili jednakovrijedno ____________________________). Ugradbene dubine nosivih profila fasade i debljine stakla prema potrebi provjeriti od strane statičara. Opšave i izolacijske radove (RAL ugradnja) na priključcima stavki na nosivu konstrukciju uključiti u ponudu.
B8: Izjava o svojstvima sukladno: - Zakonom o građevinskim proizvodima (NN 76/13, 30/14, 130/17) - HRN EN 14351-1 (ili jednakovrijedno____________________________) - HRN EN 13830 (ili jednakovrijedno____________________________)
B9: Iskaz tolerancija mjera i oblika za profile prema: - HRN EN 12020-2 (ili jednakovrijedno____________________________)
B10: Dokaz o čvrstoći spoja, u skladu s: - HRN EN 14024 (ili jednakovrijedno ____________________________) Dokaz o sigurnosti od ispadanja i izbijanja stakla iz fasadnih i prozorskih okvira, u skladu s: - HRN EN 1999-1-1 (ili jednakovrijedno____________________________) (Eurocode 9 - fasade) - TRAV (prozori) (ili jednakovrijedno____________________________) Proračun koeficijenata Uf i Uw, u skladu s: - HRN EN ISO 10077-2 (ili jednakovrijedno____________________________)
B11: Karakteristike sistema prema: HRN EN 14351 (ili jednakovrijedno ___________________________) - zrakopropusnost prema HRN EN 12207 (ili jednakovrijedno ____________________________) - vodonepropusnost prema HRN EN 12208 (ili jednakovrijedno ____________________________) - zaštita od buke prema HRN EN 4109 (ili jednakovrijedno ____________________________) - otpornost na udar vjetra prema HRN EN 12210 (ili jednakovrijedno ____________________________) - mehanička izdržljivost prema HRN EN 12400 (ili jednakovrijedno ____________________________) - protuprovalnost prema HRN EN 1627 (ili jednakovrijedno ____________________________)
B13: INOX
B14: kvaliteta sukladno: HRN EN 10027-1: 1.4401 X5CrNiMo17-12-2 (AISI 316(A4)) (ili jednakovrijedno ____________________________)
B15: Površinska obrada elemenata od nehrđajućeg čelika je poliranje ili četkanje (dio stavke). Sve kvake, panik kvake, panik letve i rukohvati vrata izvode se od inoxa.
B16: SATIN FINISH
B18: OKOV I OPREMA VRATA
B19: Opšav kontakta dovratnika odnosno doprozornika stavke sa žbukanim zidarskim otvorom, izvodi se tako da žbuka prekriva međuprostor profila i zida. Ukoliko ovakva izvedba nije moguća, stavka uključuje izvedbu alu L profila dimenzije 30x30x3 mm odnosno prilagođene detalju ugradnje. Okov, brave i kvake odobrava projektant.
... B42: Eloksirajući postupci na bazi elektro-kemijskog oplemenjivanja prema DIN 17611 (ili jednakovrijedno____________________) E6/C0
A44: 7.1 | B44: GLAVNA ULAZNA VRATA GRAĐEVINE
B46: Shema AL_1,01 Dvokrilna zaokretna evakuacijska vrata
B47: Karakteristike sistema: - otvaranje sa skrivenim okovom 100º-180º - 3D podešavanje panta - moguća debljina stakla do 50 mm - debljina stijenke profila > 2,00 mm - mogućnost zaštita od buke > 35 db, (uz odg. staklo) - topl. izolacija : Uf < 2,0 W/m2K - mogućnost motornog pogona i automatskog upravljanja, skrivenog okova - Ugradnja sistemskog antipanik i evakuacijskog okova prema normi: HRN EN 1125, funkcija "B" (ili jednakovrijedno __________________________).
B48: - zrakopropusnost: klasa 2 - vodonepropusnost: klasa 5A - zaštita od buke: > 35 dB (ovisno o staklu) - otpornost na udar vjetra: klasa C3 - mehanička izdržljivost: klasa 5 - protuprovalnost: WK 3
B50: Vrata su podijeljena po vertikali u oba krila na 8 jednakih dijelova (ostakljeno).
B51: Dovratnik: aluminijski, sveobuhvatni, bojani RAL 7016 Okvir krila kod kvake - aluminijski, bojani, RAL 3003 Krilo: djelomično ostakljeno sukladno arhitektonskom nacrtu - sigurnosno, laminirano staklo VSG. ESG-H 4.4.2. dim. 210 x 220 cm
B52: OPREMA - Rukohvat je inox cijev Ø50mm izvana, vijcima pričvrćena za okvir; iznutra panik letva. - Brava cilindar, električna, povezana sa parlafonom - Odbojnik u podu, hidraulični zatvarač vrata. - Elektromotorno otvaranje povezano s VDC-om. - Zaustavljači vrata u otvorenom položaju - Broj ključeva - dva po svakom stanu
B53: Napomena: Elektro dio je posebno obrađen u projektu elektroinstalacija.
B54: dimenzija vrata 210 (105x105) x 240cm
B55: Obračun po broju komada. | C55: kom | D55: 1 | E55: 1 | F55: 1 | G55: 1 | I55: =(D55+E55+F55+G55)*H55 -> 0
A57: =+MAX($A$1:A46)+0.1 -> 7.2 | B57: OSTAKLJENJE STUBIŠTA
B59: KARAKTERISTIKE SISTEMA: - kvaliteta materijala AlMgSi 0,5 F22 EN AW – 6060 - moguća debljina stakla 4 - 55 mm - debljina stijenke profila 2,2 mm - moguće vrste otvaranja: otklopno-zaokretno - mogućnost motornog pogona i automatskog upravljanja, skriveni okov - topl. izol., EN ISO 10071-2: Uf=1.9-2.4 W/m2 K - materijal za brtvljenje (EPDM) sukladno: DIN 7863 (ili jednakovrijedno ____________________________)
B60: - zrakopropusnost: klasa 3 - vodonepropusnost: klasa E1200 - zaštita od buke: > 35 dB (ovisno o staklu) - otpornost na udar vjetra: klasa C5/B5 - mehanička izdržljivost: klasa 5 - protuprovalnost: WK 3
B61: Napomena: Elektro dio je posebno obrađen u projektu elektroinstalacija.
B63: debljina profila krila cca 70mm - profil s prekintuim termičkim mostom - izo ostakljenje
B64: unutarnja ivanjska AL klupica - dio stavke
B66: Shema AL_3,01 1 fiksno i 1 otklopno - zaokretno krilo dim. 110 x 250cm | C66: kom | D66: 3 | E66: 3 | F66: 3 | G66: 3 | I66: =(D66+E66+F66+G66)*H66 -> 0
B67: Shema AL_3,02 Jednokrilni, zaokretno otklopni prozor povezan s VDC-om - služi za provjetravanje stubišta dim. 100 x 120cm, parapet 130cm | C67: kom | D67: 1 | E67: 1 | F67: 1 | G67: 1 | I67: =(D67+E67+F67+G67)*H67 -> 0
B68: Shema AL_3,02 Jednokrilni, zaokretno otklopni prozor povezan s VDC-om - služi za provjetravanje stubišta dim. 100 x 120cm, parapet 170cm | C68: kom | D68: 1 | E68: 1 | F68: 1 | G68: 1 | I68: =(D68+E68+F68+G68)*H68 -> 0
A70: =+MAX($A$1:A67)+0.1 -> 7.3 | B70: UNUTARNJA VRATA
A72: 1) | B72: UNUTARNJA VRATA - PODRUM
B73: Jednokrilna zaokretna evakuacijska vrata. HRN EN 179 ili jednakovrijedno __________________. Ispuna: puni izolirani panel (debljine 40mm) sa aluminijskom oblogom.
B74: - zrakopropusnost: klasa 2 - vodonepropusnost: klasa E1200 - zaštita od buke: > 35 dB (ovisno o staklu) - otpornost na udar vjetra: klasa C5/B5 - mehanička izdržljivost: klasa 5 - protuprovalnost: WK 2
B75: Okov vrata: panti, brava, prihvatnik, kvaka sa unutarnje i vanjske strane.
B76: Dovratnik: aluminijski, sveobuhvatni, bojani Krilo: puno, zaokretno, bojano
...

Sheet 8-LIMARSKI
A1: r.br. | B1: OPIS | C1: jed. mj. | D1: Količina ULAZ A | E1: Količina ULAZ B | F1: Količina ULAZ C | G1: Količina ULAZ D | H1: Jedinična cijena (€) | I1: Ukupno (€)
A3: 8. | B3: LIMARSKI RADOVI
B5: Limarski radovi odnose se na: - protukišne žaluzine i rešetke - limene poklopnice pragova i parapeta terasa - limene opšave krovnih ploha - limene opšave prodora kroz krovne plohe i dr.
B7: Elementi limarije profiliraju se i formatiziraju na limarskim strojevima u radionici. Pri profiliranju limarskih elemenata bridovi savijenih limova ne smiju biti oštri, nego pravilno zaobljeni. Profilirani i formatirani elementi mogu se u radionici spajati u sekcije čija je dužina pogodna za transport a ne otežava montažu na objektu. Elementi i sekcije međusobno se spajaju limarskim vezama (jednostruki i dvostruki, ležeći i stojeći prijevoji), varenjem i zakivanjem. Spojevi moraju biti vodonepropusni. Veza limarskih elemenata sa objektom mora omogućavati rad limene konstrukcije pri temperaturnim promjenama. Kako lim ne smije ležati neposredno na betonu ili žbuci, ispod lima se polažu trake krovne ljepenke. Širina traka mora odgovarati širini lima. Prilikom izvođenja potrebno odvojiti različite metale kako ne bi došlo do negativnog utjecaja galvanskih struja.
B8: Prije izrade elemenata izvođač mora provjeriti mjere na gradilištu. Nakon izrade limarije izvođač je dužan u prisutnosti nadzornog organa izvršiti ispitivanje vodonepropusnosti postavljene limarije. Ispitivanje se vrši blagim vodenim mlazom. Limarija ne smije propuštati vodu, oticanje mora biti kontinuirano bez zadržavanja vode u pojedinim segmentima.
B9: Osnovni materijal: plastificirani pocinčani čelični lim d = 0.60mm
A11: 8.1 | B11: LIMENI OPŠAV KROVNOG NADOZIDA
B13: Opšav krovnih nadozida, dimnjak, šaht…..U jediničnu cijenu stavku uključeno zarezivanje utora u zidu, sva spojna sredstva, vodotijesna međusobna brtvljenja i vodotijesna brtvljenja s drugim materijalima.
B14: Razvijena širina lima 15cm
B15: Obračun po kompletno izvedenom m'. | C15: m' | D15: 63 | E15: 73 | F15: 85 | G15: 73 | I15: =(D15+E15+F15+G15)*H15 -> 0
A17: =+MAX($A$1:A15)+0.1 -> 8.2 | B17: LIMENA POKLOPNICA KROVNOG NADOZIDA
B19: Materijal: plastificirani pocinčani čelični lim d = 0,80mm Materijal nosača: čel. trake 40x5mm na razmaku 50cm obrada: vruće pocinčano Završna boja: sivobijela RAL 9002
B20: U jediničnu cijenu stavku uključena su sva spojna sredstva, vodotijesna međusobna brtvljenja i vodotijesna brtvljenja s drugim materijalima.
B21: Obračun po kompletno izvedenom m'.
B22: razvijena širina 50cm | C22: m' | D22: 210 | E22: 250 | F22: 290 | G22: 305 | I22: =(D22+E22+F22+G22)*H22 -> 0
B23: razvijena širina 80cm (dilatacija) | C23: m' | F23: 15 | I23: =(D23+E23+F23+G23)*H23 -> 0
A25: =+MAX($A$1:A24)+0.1 -> 8.3 | B25: ODVODNJA BALKONA
A27: 1) | B27: RIGALICA jedna po balkonu Rigalica za odvodnju oborinske vode s plaštom Ø50 - Inox A2. Dužina izljeva - 250mm | C27: kom | D27: 28 | E27: 31 | F27: 45 | G27: 39 | I27: =(D27+E27+F27+G27)*H27 -> 0
A28: 2) | B28: ISPUST ARLI jedan po arli Ø20 - Inox A2. Dužina izljeva - 250mm
B29: Obračun po kompletu. | C29: kom | D29: 8 | E29: 10 | F29: 14 | G29: 10 | I29: =(D29+E29+F29+G29)*H29 -> 0
A31: 8. | B31: LIMARSKI RADOVI UKUPNO | I31: =SUM(I13:I29) -> 0

Sheet 9-STOLARSKI
A1: r.br. | B1: OPIS | C1: jed. mj. | D1: Količina ULAZ A | E1: Količina ULAZ B | F1: Količina ULAZ C | G1: Količina ULAZ D | H1: Jedinična cijena (€) | I1: Ukupno (€)
A3: 9. | B3: STOLARSKI RADOVI
B5: Stolarski radovi podrazumijevaju izradu i ugradnju građevinske stolarije (vrata, prozori, kombinirane stijene), izradu i ugradnju drvenih obloga, te izradu i ugradnju ostalih stolarskih elemenata definiranih projektom.
B7: Prozore i vrata izvoditi prema: - Tehničkom opisu za prozore i vrata NN 69/06 - Tehničkom propisu o racionalnoj upotrebi energije i toplinskoj zaštiti u zgradama (NN 128/15, 70/18, 73/18, 86/18, 102/20) - Tehničkom propisu za staklene konstrukcije (NN 53/201)
B8: Tehničke karakteristike sukladno: HRN EN 14351-1 (ili jednakovrijedno ____________________________).
B10: Sve mjere obavezno kontrolirati na licu mjesta (mogu biti neznatno različite od onih u shemama, što ne mijenja jediničnu cijenu stavke).
B12: Unutarnja vrata izvode se prema shemama stolarije. U stavku je uključen opšav kontakta dovratnika odnosno doprozornika stavke sa zidarskim otvorom, u vidu opšavne letve dimenzije prilagođene detalju ugradnje. Unutarnja stolarija - izvodi se, osim od vrsta masivnog i lameliranog drveta (bor, jela, smreka, hrast) i od pločastih predgotovljenih materijala materijali – furnira, panel ploča, vlaknatica i iverica, MDF(mediapan) ploča (medium density fibre board), laminata itd.
B14: Dovratnici su obuhvatni, od lameliranog masivnog smrekovog drva ličeno vodenim lakom - bijelo. Pokrovne letve su od smreke drva hrast -masiva. Dizajn dovratnika: "uglasti". Boja: vodeni lak (tonirano, sa vidljivom strukturom drva). Ton: izbijeljeni hrast
B16: Vratno krilo je puno. Okvir je od masivnog smreke s ispunom od kartonskih saća, a s vanjske strane obloženo medijapan pločom debljine 5mm. Furnirano hrastovim furnirom (horizontalna vena, izbijeljenji hrast). Ukupna širina krila iznosi 40-42 mm. Ličeno poliuretanskim lakom u tri sloja sa ostavljenom bojom izbijeljenog hrasta.
B18: Stolarija se ugrađuje suhim postupkom (ugradnjom na slijepe okvire ili ekspandirajućom pjenom). Zidarska mjera je razmak konstruktivnih elemenata.
B19: Prilikom uvođenja u posao podizvođač treba provjeriti točnost izvedbe. Izvođač treba pristupiti izvedbi tek nakon što projektant potpisom potvrdi radioničke nacrte i tehnološku razradu svih detalja.
B20: Prije pristupa izradi stolarije izvođač je obavezan prekontrolirati količine i zidarske veličine otvora na gradilištu. Radioničke nacrte izrađuje izvođač stolarskih radova, te dostavlja na usaglašavanje projektantu. Izvođač je dužan s rukovodiocem gradilišta definirati redosljed izrade i isporuke stolarskih elemenata.
B21: Svi stolarski elementi isporučuju se na gradilištu kao gotov finalni proizvod, osim onog dijela stolarije koji se liči na gradilištu, ukoliko tako određuje odabrani proizvod.
B22: Sva stolarija kod dostave mora biti zaštićena, dok se finalno obrađeni proizvodi zaštićuju i nakon ugradbe od nenamjernog oštećenja (kartonom i PVC folijom), što je sadržano u jediničnoj cijeni.
... B30: Gotovi elementi moraju se u radionici premazati fungicidnom impregnacijom za drvo koja je izrađena na bazi alkidnih smola sa svijetlo stalnim pigmentima i aktivnim fungicidnim dodacima. Bezbojna impregnacija se upotrebljava ako se stavka u konačnici obrađuje bezbojnim lakom ili lazurnom bojom, u ostalim slucajevima može se upotrijebiti blago tonirana impregnacija. Završna obrada se izvodi radionički, popravc nakon montaže nisu prihvatljivi. Izvođač se obavezuje da izradi radioničke nacrte za ključne detalje. Detalji moraju slijediti odrednice date kroz principjelne detalje priložene u projektu.
A31: 9.1 | B31: UNUTARNJA SOBNA VRATA
B33: OPREMA: kvaka izrađena od eloksiranog aluminija (natur) šarke 3 komada po krilu brava sa sobnim ključem gumeni odbojnik u podu Otpor prolaska zvuka: Rw > 25dB
B34: JEDNOKRILNA ZAOKRETNA VRATA Obračun po broju komada.
B35: Shema ST_1,01 - dim 90x210 | C35: kom | D35: 27 | E35: 33 | F35: 42 | G35: 39 | I35: =(D35+E35+F35+G35)*H35 -> 0
B36: Shema ST_1,02 - dim 80x210 (sa "zahodskom"bravom) | C36: kom | D36: 31 | E36: 33 | F36: 49 | G36: 43 | I36: =(D36+E36+F36+G36)*H36 -> 0
B37: Shema ST_1,03 - dim 70x210 | C37: kom | D37: 5 | E37: 1 | I37: =(D37+E37+F37+G37)*H37 -> 0
A39: =+MAX($A$1:A38)+0.1 -> 9.2 | B39: PREGRADNI ZID OD LETVICA
B41: Vertikalne letvice od crnog medijapana i prirodnog furnira u boji hrasta kao pregrada u interijeru – dijele vizualno zone unutar otvorenog prostora.
B42: Vertikalne letvice (7x2cm) u razmacima od 10 - 15 cm, postavljene sukladno arhitektonskom nacrtu, međusobno su povezane horizontalnom letvom na vrhu i dnu jednake debljine koje se učvršćuje u pod i strop. U visini 90cm i 180cm povezje (ukruta) letvice al. cijev promjera 25/5mm Na utor s unutarnje strane lamele nanositi ljepilo i pričvrstiti je na pripremljenu letvu. Točnu visinu utvrditi nakon gotovih obloga zida i poda. Prema stropu osigurati klizni ležaj (dilatacija 2cm)Obračun po komadu.
B43: l= 100cm; h= 268cm | C43: kom | D43: 4 | F43: 4 | G43: 4 | I43: =(D43+E43+F43+G43)*H43 -> 0
B44: l= 120cm; h= 268cm | C44: kom | D44: 4 | I44: =(D44+E44+F44+G44)*H44 -> 0
B45: l= 160cm; h= 268cm | C45: kom | D45: 3 | E45: 7 | F45: 8 | G45: 8 | I45: =(D45+E45+F45+G45)*H45 -> 0
B46: l= 175cm; h= 268cm | C46: kom | E46: 4 | F46: 4 | G46: 4 | I46: =(D46+E46+F46+G46)*H46 -> 0
A48: =+MAX($A$1:A47)+0.1 -> 9.3 | B48: RAZNO
B50: TIPSKA OGLASNA PLOČA
B51: Shema ST _ 2 Bravarica sa tri ključa Vrata od pleksija (d = 6mm), okvir od aluminija. Prostor za oglase: pocinčani lim (d = 1mm) + pluto (d = 5mm). Obavijesti se pričvršćuju magnetima ili pribadačama. Boja: natur aluminij dim. 100x70x7cm
B52: Obračun po komadu. | C52: kom | D52: 1 | E52: 1 | F52: 1 | G52: 1 | I52: =(D52+E52+F52+G52)*H52 -> 0
A56: 9. | B56: STOLARSKI RADOVI UKUPNO | I56: =SUM(I4:I54) -> 0

Sheet 10-PVC STOLARIJA i KROVNA KUPOL
A1: r.br. | B1: OPIS | C1: jed. mj. | D1: Količina ULAZ A | E1: Količina ULAZ B | F1: Količina ULAZ C | G1: Količina ULAZ D | H1: Jedinična cijena (€) | I1: Ukupno (€)
A3: 10. | B3: PVC RADOVI
B5: PVC otvori podrazumijevaju izradu i montažu vrata, prozora i kombiniranih stijena od PVC višekomornih profila.
B6: Prozore i vrata izvoditi prema: - Tehničkom opisu za prozore i vrata NN 69/06 - Tehničkom propisu o racionalnoj upotrebi energije i toplinskoj zaštiti u zgradama (NN 128/15, 70/18, 73/18, 86/18, 102/20)
B7: Tehničke karakteristike sukladno: HRN EN 14351-1 (ili jednakovrijedno ____________________________).
B8: Sve mjere obavezno kontrolirati na licu mjesta (mogu biti neznatno različite od onih u shemama, što ne mijenja jediničnu cijenu stavke).
B9: U stavku je uključen opšav kontakta dovratnika odnosno doprozornika stavke sa zidarskim otvorom, u vidu opšavne letve dimenzije prilagođene detalju ugradnje.
B11: Osnovni materijali za izradu PVC otvora su ekstrudirani profili izrađeni iz umjetnih UV stabiliziranih materijala (PVC praha i aditiva), s čeličnim pocinčanim ojačanjem. Presjeci čeličnih profila i debljine limova moraju odgovarati zadanim opterećenjima i biti u skladu sa detaljima priloženim u projektu. Profili i limovi spajaju se u konstruktivne cjeline spojnim sredstvima (zakovice, vijci i varovi) koja moraju odgovarati važećim standardima, moraju biti pravilno dimenzionirana i ugrađena.
B13: Karakteristike sistema prema HRN EN 14351 (ili jednakovrijedno _______________) - zrakopropusnost: klasa 4 prema HRN EN 12207 (ili jednakovrijedno ____________________________) - vodonepropusnost: klasa E750 prema HRN EN 12208 (ili jednakovrijedno ____________________________) - zaštita od buke: > 35 dB (ovisno o staklu) prema HRN EN 4109 (ili jednakovrijedno ____________________________) - otpornost na udar vjetra: klasa C5/B5 prema HRN EN 12210 (ili jednakovrijedno ____________________________) - mehanička otpornost: klasa 4 prema HRN EN 13115 (ili jednakovrijedno ____________________________) '- kvaliteta prema EN 12608:2004s (ili jednakovrijedno ___________________________ ) - Uf < 1.2 W/m2 K prema EN ISO 10071-2 (ili jednakovrijedno __________________________ )
B14: - materijal za brtvljenje: EPDM prema DIN 7863 (ili jednakovrijedno __________________________ ) - kontrola kvalitete prema DIN EN ISO 9001 (ili jednakovrijedno __________________________ )
B15: - A klase profila, tzv. vidljive stijenke profila moraju biti ≥ 2.8mm, nevidljive ≥ 2.5mm - debljina stakla do 48 mm - vrste otvaranja: otklopno-zaokretno (jednokrilno, dvokrilno), zaokretno-otklopno, otklopno oko donje ili gornje osi, otklopno-klizno, dvokrilno - masa krila (otklopno-klizno) do 180 kg
B17: Dovratnik - doprozornik izrađen je iz kutijastih PVC-profila usidren za bočne betonske ili zidove od opeke, pocinčanim vijkom i plastičnom tiplom. Spajanje elemenata je varenjem. Brtvljenje fiksnih i pokretnih elemenata, te ostakljenja i okvira, gumenim brtvama sa varenim spojevima. Između krila i okvira vrata i prozora potrebno je staviti min 2 brtve od EPDM-a.
